Workbook

Sheet 填寫舉例
A2: 7 | B2: 月別 | C2: 工廠名 | D2: ・・・・・・・・
A4: （１）收支狀況 | E4: ※單位：千元 | G4: （２）ＫＰＩ達成進度 | M4: （３）業績構成比 | S4: （４）訂單數量構成比
B5: 當月 | C5: 前月 | D5: 差異 | E5: 累計 | H5: KPI | I5: 當月 | J5: 前月 | K5: 累計 | L5: ※補充 | N5: 當月 | O5: 比例 | P5: 前月 | Q5: 差異 | T5: 當月 | U5: 比例 | V5: 前月 | W5: 差異
A6: 業績金額 | B6: 500000 | C6: 510000 | D6: =B6-C6 -> -10000 | E6: =B6+C6 -> 1010000 | G6: 人時生產性1 | H6: 110 | I6: 100 | J6: 90 | L6: 個／MH | M6: 飯糰 | N6: 150000 | O6: =IFERROR(N6/$B$6,"") -> 0.3 | P6: 0.4 | Q6: =IFERROR(O6-P6,"") -> -0.1 | S6: 飯糰 | T6: 35000 | U6: =IFERROR(T6/$B$7,"") -> 0.35 | V6: 0.3 | W6: =IFERROR(U6-V6,"") -> 0.05
A7: 訂單數量 | B7: 100000 | C7: 110000 | D7: =B7-C7 -> -10000 | E7: =B7+C7 -> 210000 | G7: 人時生產性2 | H7: 0.8 | I7: 0.85 | J7: 0.81 | K7: 0.84 | L7: 達成率 | M7: 大口飯糰 | N7: 100000 | O7: =IFERROR(N7/$B$6,"") -> 0.2 | P7: 0.15 | Q7: =IFERROR(O7-P7,"") -> 0.05 | S7: 大口飯糰 | T7: 30000 | U7: =IFERROR(T7/$B$7,"") -> 0.3 | V7: 0.15 | W7: =IFERROR(U7-V7,"") -> 0.15
A8: 材料費 | B8: 250000 | C8: 260000 | D8: =B8-C8 -> -10000 | E8: =B8+C8 -> 510000 | G8: 半成品報廢 | H8: 0.0025 | I8: 0.0024 | J8: 0.0023 | K8: 0.00235 | L8: 報廢率 | M8: 便當 | N8: 160000 | O8: =IFERROR(N8/$B$6,"") -> 0.32 | P8: 0.28 | Q8: =IFERROR(O8-P8,"") -> 0.04 | S8: 便當 | T8: 20000 | U8: =IFERROR(T8/$B$7,"") -> 0.2 | V8: 0.28 | W8: =IFERROR(U8-V8,"") -> -0.08
A9: 材料費率 | B9: =B8/B6 -> 0.5 | C9: =C8/C6 -> 0.50980392 | D9: =B9-C9 -> -0.0098039216 | E9: =(B9+C9)/2 -> 0.50490196 | G9: 半成品超用 | H9: 0.006 | I9: 0.009 | J9: 0.0095 | K9: 0.0092 | L9: 超用率 | M9: 調理麵 | N9: 90000 | O9: =IFERROR(N9/$B$6,"") -> 0.18 | P9: 0.17 | Q9: =IFERROR(O9-P9,"") -> 0.01 | S9: 調理麵 | T9: 15000 | U9: =IFERROR(T9/$B$7,"") -> 0.15 | V9: 0.27 | W9: =IFERROR(U9-V9,"") -> -0.12
A10: 勞務成本 | B10: 100000 | C10: 105000 | D10: =B10-C10 -> -5000 | E10: =B10+C10 -> 205000 | G10: 固定產線 | H10: 0.95 | I10: 0.9 | J10: 0.92 | K10: 0.91 | L10: 導入率 | M10: 調理麵包 | N10: - | O10: =IFERROR(N10/$B$6,"") | P10: -% | Q10: =IFERROR(O10-P10,"") | S10: 調理麵包 | T10: - | U10: =IFERROR(T10/$B$7,"") | V10: -% | W10: =IFERROR(U10-V10,"")
A11: 勞務費率 | B11: =B10/B6 -> 0.2 | C11: =C10/C6 -> 0.20588235 | D11: =B11-C11 -> -0.0058823529 | E11: =(B11+C11)/2 -> 0.20294118 | G11: 教育訓練 | H11: 0.8 | I11: 0.85 | J11: 1 | K11: 0.92 | L11: 實施率 | M11: 袋裝調理麵包 | N11: - | O11: =IFERROR(N11/$B$6,"") | P11: -% | Q11: =IFERROR(O11-P11,"") | S11: 袋裝調理麵包 | T11: - | U11: =IFERROR(T11/$B$7,"") | V11: -% | W11: =IFERROR(U11-V11,"")
M12: 義大利麵 | N12: - | O12: =IFERROR(N12/$B$6,"") | P12: -% | Q12: =IFERROR(O12-P12,"") | S12: 義大利麵 | T12: - | U12: =IFERROR(T12/$B$7,"") | V12: -% | W12: =IFERROR(U12-V12,"")
A13: （５）品群別人時生產性 | M13: 調理包 | N13: - | O13: =IFERROR(N13/$B$6,"") | P13: -% | Q13: =IFERROR(O13-P13,"") | S13: 調理包 | T13: - | U13: =IFERROR(T13/$B$7,"") | V13: -% | W13: =IFERROR(U13-V13,"")
B14: 當月 | C14: 前月 | D14: 差異 | E14: 累計 | H14: 當月 | I14: 前月 | J14: 差異 | K14: 累計 | O14: =SUM(O6:O13) -> 1 | P14: =SUM(P6:P13) -> 1 | U14: =SUM(U6:U13) -> 1 | V14: =SUM(V6:V13) -> 1
A15: 飯糰 | B15: 600 | C15: 660 | D15: =B15-C15 -> -60 | E15: =(B15+C15)/2 -> 630 | G15: 調理麵包 | J15: =H15-I15 -> 0 | M15: （７）原因別分析
A16: 大口飯糰 | B16: 800 | C16: 780 | D16: =B16-C16 -> 20 | E16: =(B16+C16)/2 -> 790 | G16: 袋裝調理麵包 | J16: =H16-I16 -> 0 | N16: 合計 | P16: 作業原因 | R16: 規格原因
A17: 便當 | B17: 130 | C17: 111 | D17: =B17-C17 -> 19 | E17: =(B17+C17)/2 -> 120.5 | G17: 義大利麵 | J17: =H17-I17 -> 0 | N17: 金額 | O17: 比例 | P17: 金額 | Q17: 比例 | R17: 金額 | S17: 比例
A18: 調理麵 | B18: 140 | C18: 165 | D18: =B18-C18 -> -25 | E18: =(B18+C18)/2 -> 152.5 | G18: 調理包 | J18: =H18-I18 -> 0 | M18: 半成品報廢 | N18: 1200 | O18: =N18/$B$6 -> 0.0024 | P18: 900 | Q18: =IFERROR(P18/$B$6,"") -> 0.0018 | R18: 300 | S18: =IFERROR(R18/$B$6,"") -> 0.0006
M19: 半成品超用 | N19: 4500 | O19: =N19/$B$6 -> 0.009 | P19: 3500 | Q19: =IFERROR(P19/$B$6,"") -> 0.007 | R19: 1000 | S19: =IFERROR(R19/$B$6,"") -> 0.002
A20: （６）人時生產性前幾名品項
B21: 排名 | C21: 商品名 | F21: 人數 | G21: 產能 | H21: 人時生產性 | I21: 前月比 | J21: 主要原因&對策 | M21: （８）報廢原因別前幾名品項
A22: 飯糰 | B22: 1 | C22: 手巻明太子 | F22: 3 | G22: 3000 | H22: 1000 | I22: 10 | J22: 減少暫時停止生產,人時UP | M22: 半成品報廢 | N22: 排名 | O22: 商品名 | R22: 半成品名 | U22: 單價 | V22: 報廢率 | W22: 數量 | X22: 金額 | Y22: 前月比 | Z22: 主要原因&對策
B23: 2 | M23: 作業原因 | N23: 1 | O23: 明太子海苔便當 | R23: 油炸白身魚 | U23: 10 | V23: 0.15 | W23: 10 | X23: =W23*U23 -> 100 | Y23: 80 | Z23: 油調過多報廢。變更條件。
B24: 3 | N24: 2 | X24: =W24*U24 -> 0
B25: 4 | N25: 3 | X25: =W25*U25 -> 0
B26: 5 | N26: 4 | X26: =W26*U26 -> 0
B27: ▼1 | C27: 手巻卵黄雞絞肉 | F27: 4 | G27: 2800 | H27: 700 | I27: 6/30新商品 | J27: 因組裝2食材,人員增加,產速減少 | N27: 5 | X27: =W27*U27 -> 0
B28: ▼2 | U28: 前幾名合計比例 | V28: =X28/N18 -> 0.083333333 | W28: 前幾名合計金額 | X28: =SUM(X23:X27) -> 100
B29: ▼3 | M29: 規格原因 | N29: 1 | O29: 海老炒飯 | R29: 川燙蝦子拌醬 | U29: 5.55 | V29: 0.21 | W29: 50 | X29: =W29*U29 -> 277.5 | Y29: 35 | Z29: 蝦子入數不足
B30: ▼4 | N30: 2 | X30: =W30*U30 -> 0
B31: ▼5 | N31: 3 | X31: =W31*U31 -> 0
N32: 4 | X32: =W32*U32 -> 0
B33: 排名 | C33: 商品名 | F33: 人數 | G33: 產能 | H33: 人時生產性 | I33: 前月比 | J33: 主要原因&對策 | N33: 5 | X33: =W33*U33 -> 0
A34: 大口飯糰 | B34: 1 | C34: 直巻明太子美奶茲 | F34: 3 | G34: 2500 | H34: 833.33 | I34: 20 | J34: 透由調整速度提升。 | U34: 前幾名合計比例 | V34: =X34/N18 -> 0.23125 | W34: 前幾名合計金額 | X34: =SUM(X29:X33) -> 277.5
B35: 2
B36: 3 | M36: 半成品超用 | N36: 排名 | O36: 商品名 | R36: 半成品名 | U36: 單價 | V36: 報廢率 | W36: 數量 | X36: 金額 | Y36: 前月比 | Z36: 主要原因&對策
B37: 4 | M37: 作業原因 | N37: 1 | O37: 特製醬汁炙燒牛五花便當 | R37: 牛五花醬汁 | U37: 25 | V37: 0.25 | W37: 10 | X37: =W37*U37 -> 250 | Y37: 150 | Z37: 難度有差異。調理指導。
B38: 5 | N38: 2 | X38: =W38*U38 -> 0
B39: ▼1 | C39: 大口飯糰燒肉美奶滋 | F39: 7 | G39: 2200 | H39: 314.29 | I39: -15 | J39: 因摺疊增員。實施教育訓練。 | N39: 3 | X39: =W39*U39 -> 0
B40: ▼2 | N40: 4 | X40: =W40*U40 -> 0
B41: ▼3 | N41: 5 | X41: =W41*U41 -> 0
B42: ▼4 | U42: 前幾名合計比例 | V42: =X42/N19 -> 0.055555556 | W42: 前幾名合計金額 | X42: =SUM(X37:X41) -> 250
...

Sheet 生產管理報表(月)
A1: 生產管理報表
A3: 月別 | B3: 9 | C3: 工廠 | D3: 晉欣廠
A4: （１）收支狀況 | E4: ※單位：千元 | G4: （２）ＫＰＩ達成進度
A5: 項目 | B5: 當月 | C5: 前月 | D5: 差異 | E5: 累計 | G5: 項目 | H5: KPI | I5: 當月 | J5: 前月 | K5: 累計 | L5: ※補充
A6: 業績金額 | B6: ='（１）收支狀況'!H5/1000 -> 0 | C6: 212376.15 | D6: =B6-C6 -> -212376.15 | E6: =B6 -> 0 | G6: 人時性(個/月均) | H6: 266 | I6: ='（２）ＫＰＩ達成進度'!H5 -> 0 | J6: 331.32088 | K6: =I6 -> 0 | L6: 個／MH
A7: 訂單數量 | B7: ='（４）訂單數量構成比'!H7 -> 0 | C7: 6558055 | D7: =B7-C7 -> -6558055 | E7: =B7 -> 0 | G7: 人時達成率(%/月均) | H7: 0.8 | I7: ='（２）ＫＰＩ達成進度'!K5 -> 0 | J7: 0.90524832 | K7: =I7 -> 0 | L7: 達成率
A8: 材料費 | B8: ='（１）收支狀況'!N5/1000 -> 0 | C8: 139088.16 | D8: =B8-C8 -> -139088.16 | E8: =B8 -> 0 | G8: 半成品-報廢(%) | H8: 0.0025 | I8: ='（２）ＫＰＩ達成進度'!N5 -> 0 | J8: 0.0024946244 | K8: =I8 -> 0 | L8: 報廢率
A9: 材料費率 | B9: ='（１）收支狀況'!Q5 -> 0 | C9: 0.65491423 | D9: =B9-C9 -> -0.65491423 | E9: =B9 -> 0 | G9: 半成品-超用(%) | H9: 0.0026 | I9: ='（２）ＫＰＩ達成進度'!Q5 -> 0 | J9: 0.0023789152 | K9: =I9 -> 0 | L9: 超用率
A10: 勞務成本 | B10: ='（１）收支狀況'!T5/1000 -> 0 | C10: 30146.177 | D10: =B10-C10 -> -30146.177 | E10: =B10 -> 0 | G10: 固定產線-導入率(%) | H10: 0.8 | I10: ='（２）ＫＰＩ達成進度'!T5 -> 0 | J10: 0.91666667 | K10: =I10 -> 0 | L10: 導入率
A11: 勞務費率 | B11: ='（１）收支狀況'!W5 -> 0 | C11: 0.14194709 | D11: =B11-C11 -> -0.14194709 | E11: =B11 -> 0 | G11: 教育訓練-實施率(%) | H11: 1 | I11: ='（２）ＫＰＩ達成進度'!W5 -> 0 | J11: 0.67912903 | K11: =I11 -> 0 | L11: 實施率
A13: （３）業績構成比 | G13: （４）訂單數量構成比
B14: 當月 | C14: 比例 | D14: 前月 | E14: 差異 | H14: 當月 | I14: 比例 | J14: 前月 | K14: 差異
A15: 18℃-飯A15:A23糰(061,063) | B15: ='（３）業績構成比'!M46/1000 -> 20292.467 | C15: =IFERROR(B15/$B$6,"") | D15: 0.19048549 | E15: =IFERROR(C15-D15,"") | G15: 18℃-飯A15:A23糰(061,063) | H15: ='（４）訂單數量構成比'!M46 -> 1067935 | I15: =IFERROR(H15/$B$7,"") | J15: 0.33193454 | K15: =IFERROR(I15-J15,"")
A16: 18℃-壽司手卷(071,072,075,076) | B16: ='（３）業績構成比'!S46/1000 -> 4316.271 | C16: =IFERROR(B16/$B$6,"") | D16: 0.04002075 | E16: =IFERROR(C16-D16,"") | G16: 18℃-壽司手卷(071,072,075,076) | H16: ='（４）訂單數量構成比'!S47 -> 186443 | I16: =IFERROR(H16/$B$7,"") | J16: 0.050408543 | K16: =IFERROR(I16-J16,"")
A17: 4℃-飯糰(065) | B17: ='（３）業績構成比'!U46/1000 -> 8063.5793 | C17: =IFERROR(B17/$B$6,"") | D17: 0.098025494 | E17: =IFERROR(C17-D17,"") | G17: 4℃-飯糰(065) | H17: ='（４）訂單數量構成比'!U46 -> 241892 | I17: =IFERROR(H17/$B$7,"") | J17: 0.09754935 | K17: =IFERROR(I17-J17,"")
A18: 4℃-壽司手卷(077) | B18: ='（３）業績構成比'!W46/1000 -> 2417.9571 | C18: =IFERROR(B18/$B$6,"") | D18: 0.0023157871 | E18: =IFERROR(C18-D18,"") | G18: 4℃-壽司手卷(077) | H18: ='（４）訂單數量構成比'!W46 -> 76820 | I18: =IFERROR(H18/$B$7,"") | J18: 0.0027738407 | K18: =IFERROR(I18-J18,"")
A19: 主食(091,092,093,094,095) | B19: ='（３）業績構成比'!AC46/1000 -> 25211.488 | C19: =IFERROR(B19/$B$6,"") | D19: 0.26645165 | E19: =IFERROR(C19-D19,"") | G19: 主食(091,092,093,094,095) | H19: ='（４）訂單數量構成比'!AC46 -> 630660 | I19: =IFERROR(H19/$B$7,"") | J19: 0.20966064 | K19: =IFERROR(I19-J19,"")
A20: 便當(083) | B20: ='（３）業績構成比'!AE46/1000 -> 15228.706 | C20: =IFERROR(B20/$B$6,"") | D20: 0.11880395 | E20: =IFERROR(C20-D20,"") | G20: 便當(083) | H20: ='（４）訂單數量構成比'!AE46 -> 271923 | I20: =IFERROR(H20/$B$7,"") | J20: 0.069473342 | K20: =IFERROR(I20-J20,"")
A21: 熱食義麵(122,123,124,126) | B21: ='（３）業績構成比'!AG46/1000 -> 12011.204 | C21: =IFERROR(B21/$B$6,"") | D21: 0.13107603 | E21: =IFERROR(C21-D21,"") | G21: 熱食義麵(122,123,124,126) | H21: ='（４）訂單數量構成比'!AG46 -> 240808 | I21: =IFERROR(H21/$B$7,"") | J21: 0.087948485 | K21: =IFERROR(I21-J21,"")
A22: 季節調理麵(111,112) | B22: ='（３）業績構成比'!AI46/1000 -> 6015.7257 | C22: =IFERROR(B22/$B$6,"") | D22: 0.091535408 | E22: =IFERROR(C22-D22,"") | G22: 季節調理麵(111,112) | H22: ='（４）訂單數量構成比'!AI46 -> 165583 | I22: =IFERROR(H22/$B$7,"") | J22: 0.079981641 | K22: =IFERROR(I22-J22,"")
A23: 微波小吃(153,154,155) | B23: ='（３）業績構成比'!AK46/1000 -> 8991.5442 | C23: =IFERROR(B23/$B$6,"") | D23: 0.061285436 | E23: =IFERROR(C23-D23,"") | G23: 微波小吃(153,154,155) | H23: ='（４）訂單數量構成比'!AK46 -> 283558 | I23: =IFERROR(H23/$B$7,"") | J23: 0.070269615 | K23: =IFERROR(I23-J23,"")
C24: =SUM(C15:C23) -> 0 | D24: =SUM(D15:D23) -> 1 | I24: =SUM(I15:I23) -> 0 | J24: =SUM(J15:J23) -> 1
A26: （５）品群別人時生產性
A27: 品群 | B27: 當月 | C27: 前月 | D27: 差異 | E27: 累計 | M27: 8月 | N27: 9月 | O27: 10月 | P27: 11月 | Q27: 12月
A28: 18℃-飯A15:A23糰(061,063) | B28: ='（５-1）品群別人時生產性（18℃-飯糰）'!$C$1 -> 756.04671 | C28: 717.52753 | D28: =B28-C28 -> 38.519176 | E28: =R28 -> 736.78712 | M28: 717.52753 | N28: =B28 -> 756.04671 | R28: =AVERAGE(M28:Q28) -> 736.78712
A29: 18℃-壽司手卷(071,072,075,076) | B29: ='（５-2）品群別人時生產性（18-壽司手卷)'!$C$1 -> 182.50775 | C29: 197.63272 | D29: =B29-C29 -> -15.124969 | E29: =R29 -> 190.07023 | M29: 197.63272 | N29: =B29 -> 182.50775 | R29: =AVERAGE(M29:Q29) -> 190.07023
A30: 4℃-飯糰(065) | B30: ='（５-3）品群別人時生產性（4℃-飯糰)'!$C$1 -> 273.59421 | C30: 240.45857 | D30: =B30-C30 -> 33.135638 | E30: =R30 -> 257.02639 | M30: 240.45857 | N30: =B30 -> 273.59421 | R30: =AVERAGE(M30:Q30) -> 257.02639
A31: 4℃-壽司手卷(077) | B31: ='（５-4）品群別人時生產性（4℃-壽司手卷)'!$C$1 -> 118.38412 | C31: 106.86512 | D31: =B31-C31 -> 11.519002 | E31: =R31 -> 112.62462 | M31: 106.86512 | N31: =B31 -> 118.38412 | R31: =AVERAGE(M31:Q31) -> 112.62462
A32: 主食(091,092,093,094,095) | B32: ='（５-5）品群別人時生產性(主食) '!$C$1 -> 87.919975 | C32: 89.310428 | D32: =B32-C32 -> -1.3904536 | E32: =R32 -> 88.615202 | M32: 89.310428 | N32: =B32 -> 87.919975 | R32: =AVERAGE(M32:Q32) -> 88.615202
A33: 便當(083) | B33: ='（５-6）品群別人時生產性(便當)'!$C$1 -> 73.580888 | C33: 65.672742 | D33: =B33-C33 -> 7.9081454 | E33: =R33 -> 69.626815 | M33: 65.672742 | N33: =B33 -> 73.580888 | R33: =AVERAGE(M33:Q33) -> 69.626815
A34: 熱食義麵(122,123,124,126) | B34: ='（５-7）品群別人時生產性(熱食義麵) '!$C$1 -> 76.863036 | C34: 75.478569 | D34: =B34-C34 -> 1.3844673 | E34: =R34 -> 76.170803 | M34: 75.478569 | N34: =B34 -> 76.863036 | R34: =AVERAGE(M34:Q34) -> 76.170803
A35: 季節調理麵(111,112) | B35: ='（５-8）品群別人時生產性(季節調理麵) '!$C$1 -> 119.39118 | C35: 114.50557 | D35: =B35-C35 -> 4.8856047 | E35: =R35 -> 116.94837 | M35: 114.50557 | N35: =B35 -> 119.39118 | R35: =AVERAGE(M35:Q35) -> 116.94837
A36: 微波小吃(153,154,155) | B36: ='（５-9）品群別人時生產性(微波小吃)'!$C$1 -> 110.97011 | C36: 99.648342 | D36: =B36-C36 -> 11.321764 | E36: =R36 -> 105.30922 | M36: 99.648342 | N36: =B36 -> 110.97011 | R36: =AVERAGE(M36:Q36) -> 105.30922

Sheet 生產管理報表(週) 
A1: 生產管理報表
A3: 月別 | B3: 11 | C3: 週別 | D3: W1 | E3: 工廠 | F3: 晉欣廠
A4: （１）收支狀況 | E4: ※單位：千元 | G4: （２）ＫＰＩ達成進度
A5: 項目 | B5: 當週 | C5: 前週 | D5: 差異 | E5: 累計 | G5: 項目 | H5: KPI | I5: 當週 | J5: 前週 | K5: 累計 | L5: ※補充
A6: 業績金額 | B6: ='（１）收支狀況'!G12/1000 -> 49899.447 | C6: 52649.495 | D6: =B6-C6 -> -2750.048 | E6: ='（１）收支狀況'!H9/1000 -> 71561.306 | G6: 人時性(個/月均) | H6: 366 | I6: ='（２）ＫＰＩ達成進度'!G12 -> 336.19882 | J6: 340.19679 | K6: ='（２）ＫＰＩ達成進度'!H9 -> 338.19877 | L6: 個／MH
A7: 訂單數量 | B7: ='（１）收支狀況'!J12 -> 1534159 | C7: 1631463 | D7: =B7-C7 -> -97304 | E7: ='（１）收支狀況'!K9 -> 2204262 | G7: 人時達成率(%/月均) | H7: 0.8 | I7: ='（２）ＫＰＩ達成進度'!J12 -> 0.91857601 | J7: 0.92949941 | K7: ='（２）ＫＰＩ達成進度'!K9 -> 0.30801345 | L7: 達成率
A8: 材料費 | B8: ='（１）收支狀況'!M12/1000 -> 32893.927 | C8: 34902.738 | D8: =B8-C8 -> -2008.811 | E8: ='（１）收支狀況'!N9/1000 -> 47078.484 | G8: 半成品-報廢(%) | H8: 0.0025 | I8: ='（２）ＫＰＩ達成進度'!M12 -> 0.0024537701 | J8: 0.0024552869 | K8: ='（２）ＫＰＩ達成進度'!N9 -> 0.0024516729 | L8: 報廢率
A9: 材料費率 | B9: ='（１）收支狀況'!P12 -> 0.65920424 | C9: 0.66292636 | D9: =B9-C9 -> -0.0037221193 | E9: ='（１）收支狀況'!Q9 -> 0.65787626 | G9: 半成品-超用(%) | H9: 0.0026 | I9: ='（２）ＫＰＩ達成進度'!P12 -> 0.0022225027 | J9: 0.0022768681 | K9: ='（２）ＫＰＩ達成進度'!Q9 -> 0.0022264575 | L9: 超用率
A10: 勞務成本 | B10: ='（１）收支狀況'!S12/1000 -> 6835.2228 | C10: 7231.7426 | D10: =B10-C10 -> -396.51981 | E10: ='（１）收支狀況'!T9/1000 -> 9751.6181 | G10: 固定產線-導入率(%) | H10: 0.8 | I10: 0.917 | J10: 0.917 | K10: 0.917 | L10: 導入率
A11: 勞務費率 | B11: ='（１）收支狀況'!V12 -> 0.13697993 | C11: 0.1377496 | D11: =B11-C11 -> -0.00076966421 | E11: ='（１）收支狀況'!W9 -> 0.13626943 | G11: 教育訓練-實施率(%) | H11: 1 | I11: ='（２）ＫＰＩ達成進度'!V12 -> 0.88342857 | J11: 0.87342857 | K11: ='（２）ＫＰＩ達成進度'!W9 -> 0.8814 | L11: 實施率
A13: （３）業績構成比 | G13: （４）訂單數量構成比
B14: 當週 | C14: 比例 | D14: 前週 | E14: 差異 | H14: 當週 | I14: 比例 | J14: 前週 | K14: 差異
A15: 18℃-飯糰(061,063) | B15: =SUM('（３）業績構成比'!I14:I20,'（３）業績構成比'!K14:K20)/1000 -> 9790.0968 | C15: =IFERROR(B15/$B$6,"") -> 0.1961965 | D15: 0.19947712 | E15: =IFERROR(C15-D15,"") -> -0.0032806245 | G15: 18℃-飯糰(061,063) | H15: =SUM(,'（４）訂單數量構成比'!I14:I20,'（４）訂單數量構成比'!K14:K20) -> 514518 | I15: =IFERROR(H15/$B$7,"") -> 0.33537463 | J15: 0.33921517 | K15: =IFERROR(I15-J15,"") -> -0.0038405452
A16: 18℃-壽司手卷(071,072,075,076) | B16: =SUM('（３）業績構成比'!O14:O20,'（３）業績構成比'!Q14:Q20)/1000 -> 1994.7626 | C16: =IFERROR(B16/$B$6,"") -> 0.039975646 | D16: 0.044093649 | E16: =IFERROR(C16-D16,"") -> -0.0041180038 | G16: 18℃-壽司手卷(071,072,075,076) | H16: =SUM('（４）訂單數量構成比'!O14:O20,'（４）訂單數量構成比'!Q14:Q20) -> 84426 | I16: =IFERROR(H16/$B$7,"") -> 0.055030802 | J16: 0.062530992 | K16: =IFERROR(I16-J16,"") -> -0.0075001902
A17: 4℃-飯糰(065) | B17: =SUM('（３）業績構成比'!U14:U20)/1000 -> 3949.4498 | C17: =IFERROR(B17/$B$6,"") -> 0.079148167 | D17: 0.078141862 | E17: =IFERROR(C17-D17,"") -> 0.0010063057 | G17: 4℃-飯糰(065) | H17: =SUM('（４）訂單數量構成比'!U14:U20) -> 118836 | I17: =IFERROR(H17/$B$7,"") -> 0.077460029 | J17: 0.07542678 | K17: =IFERROR(I17-J17,"") -> 0.0020332491
A18: 4℃-壽司手卷(077) | B18: =SUM('（３）業績構成比'!W14:W20)/1000 -> 1022.2332 | C18: =IFERROR(B18/$B$6,"") -> 0.020485863 | D18: 0.026509729 | E18: =IFERROR(C18-D18,"") -> -0.0060238661 | G18: 4℃-壽司手卷(077) | H18: =SUM('（４）訂單數量構成比'!W14:W20) -> 32774 | I18: =IFERROR(H18/$B$7,"") -> 0.021362844 | J18: 0.026997854 | K18: =IFERROR(I18-J18,"") -> -0.0056350097
A19: 主食(091,092,093,094,095) | B19: =SUM('（３）業績構成比'!Y14:Y20,'（３）業績構成比'!AA14:AA20)/1000 -> 12482.2 | C19: =IFERROR(B19/$B$6,"") -> 0.25014705 | D19: 0.24177418 | E19: =IFERROR(C19-D19,"") -> 0.0083728704 | G19: 主食(091,092,093,094,095) | H19: =SUM('（４）訂單數量構成比'!Y14:Y20,'（４）訂單數量構成比'!AA14:AA20) -> 311156 | I19: =IFERROR(H19/$B$7,"") -> 0.20281861 | J19: 0.19583895 | K19: =IFERROR(I19-J19,"") -> 0.0069796632
A20: 便當(083) | B20: =SUM('（３）業績構成比'!AE14:AE20)/1000 -> 7489.1908 | C20: =IFERROR(B20/$B$6,"") -> 0.15008565 | D20: 0.14700075 | E20: =IFERROR(C20-D20,"") -> 0.0030848971 | G20: 便當(083) | H20: =SUM('（４）訂單數量構成比'!AE14:AE20) -> 133803 | I20: =IFERROR(H20/$B$7,"") -> 0.087215862 | J20: 0.08466021 | K20: =IFERROR(I20-J20,"") -> 0.0025556524
A21: 熱食義麵(122,123,124,126) | B21: =SUM('（３）業績構成比'!AG14:AG20)/1000 -> 5719.4089 | C21: =IFERROR(B21/$B$6,"") -> 0.11461868 | D21: 0.11950342 | E21: =IFERROR(C21-D21,"") -> -0.0048847426 | G21: 熱食義麵(122,123,124,126) | H21: =SUM('（４）訂單數量構成比'!AG14:AG20) -> 115069 | I21: =IFERROR(H21/$B$7,"") -> 0.075004612 | J21: 0.077071316 | K21: =IFERROR(I21-J21,"") -> -0.0020667041
A22: 季節調理麵(111,112) | B22: =SUM('（３）業績構成比'!AI14:AI20)/1000 -> 3145.5163 | C22: =IFERROR(B22/$B$6,"") -> 0.063037098 | D22: 0.05451542 | E22: =IFERROR(C22-D22,"") -> 0.0085216781 | G22: 季節調理麵(111,112) | H22: =SUM('（４）訂單數量構成比'!AI14:AI20) -> 85767 | I22: =IFERROR(H22/$B$7,"") -> 0.055904896 | J22: 0.048922961 | K22: =IFERROR(I22-J22,"") -> 0.0069819359
A23: 微波小吃(153,154,155) | B23: =SUM('（３）業績構成比'!AK14:AK20)/1000 -> 4306.5889 | C23: =IFERROR(B23/$B$6,"") -> 0.086305344 | D23: 0.088983858 | E23: =IFERROR(C23-D23,"") -> -0.0026785142 | G23: 微波小吃(153,154,155) | H23: =SUM('（４）訂單數量構成比'!AK14:AK20) -> 137810 | I23: =IFERROR(H23/$B$7,"") -> 0.089827717 | J23: 0.089335768 | K23: =IFERROR(I23-J23,"") -> 0.00049194873
C24: =SUM(C15:C23) -> 1 | D24: =SUM(D15:D23) -> 1 | I24: =SUM(I15:I23) -> 1 | J24: =SUM(J15:J23) -> 1
A26: （５）品群別人時生產性
A27: 品群 | B27: 當週 | C27: 前週 | D27: 差異 | E27: 累計
A28: 18℃-飯糰(061,063) | B28: ='（５-1）品群別人時生產性（18℃-飯糰）'!L42 -> 748.13358 | C28: 763.95984 | D28: =B28-C28 -> -15.826259 | E28: ='（５-1）品群別人時生產性（18℃-飯糰）'!C1 -> 756.04671
A29: 18℃-壽司手卷(071,072,075,076) | B29: ='（５-2）品群別人時生產性（18-壽司手卷)'!L27 -> 182.18847 | C29: 182.82703 | D29: =B29-C29 -> -0.63855441 | E29: ='（５-2）品群別人時生產性（18-壽司手卷)'!C1 -> 182.50775
A30: 4℃-飯糰(065) | B30: ='（５-3）品群別人時生產性（4℃-飯糰)'!L27 -> 267.92877 | C30: 279.25965 | D30: =B30-C30 -> -11.330879 | E30: ='（５-3）品群別人時生產性（4℃-飯糰)'!C1 -> 273.59421
A31: 4℃-壽司手卷(077) | B31: ='（５-4）品群別人時生產性（4℃-壽司手卷)'!L27 -> 114.89807 | C31: 121.87018 | D31: =B31-C31 -> -6.9721127 | E31: ='（５-4）品群別人時生產性（4℃-壽司手卷)'!C1 -> 118.38412
A32: 主食(091,092,093,094,095) | B32: ='（５-5）品群別人時生產性(主食) '!L42 -> 88.921658 | C32: 86.918291 | D32: =B32-C32 -> 2.0033669 | E32: ='（５-5）品群別人時生產性(主食) '!C1 -> 87.919975
A33: 便當(083) | B33: ='（５-6）品群別人時生產性(便當)'!L27 -> 79.014885 | C33: 68.146891 | D33: =B33-C33 -> 10.867994 | E33: ='（５-6）品群別人時生產性(便當)'!C1 -> 73.580888
A34: 熱食義麵(122,123,124,126) | B34: ='（５-7）品群別人時生產性(熱食義麵) '!L27 -> 79.308428 | C34: 74.417644 | D34: =B34-C34 -> 4.890784 | E34: ='（５-7）品群別人時生產性(熱食義麵) '!C1 -> 76.863036
A35: 季節調理麵(111,112) | B35: ='（５-8）品群別人時生產性(季節調理麵) '!L27 -> 118.96839 | C35: 119.81397 | D35: =B35-C35 -> -0.84558214 | E35: ='（５-8）品群別人時生產性(季節調理麵) '!C1 -> 119.39118
A36: 微波小吃(153,154,155) | B36: ='（５-9）品群別人時生產性(微波小吃)'!L27 -> 109.78167 | C36: 112.15854 | D36: =B36-C36 -> -2.3768729 | E36: ='（５-9）品群別人時生產性(微波小吃)'!C1 -> 110.97011

Sheet （１）收支狀況
B2: （１）收支狀況
C3: 月份 | D3: 日期 | F3: 營業額(元) | I3: 訂單數量(個) | L3: 材料費(元) | O3: 材料費率（材料費／營業額） | R3: 勞務成本（全廠人事成本） | U3: 勞務費率（勞務成本／營業額）
F4: 日 | G4: 週累積 | H4: 月累積 | I4: 日 | J4: 週累積 | K4: 月累積 | L4: 日 | M4: 週累積 | N4: 月累積 | O4: 日 | P4: 週累積 | Q4: 月平均 | R4: 日 | S4: 週累積 | T4: 月累積 | U4: 日 | V4: 週累積 | W4: 月平均
D5: 45958 | E5: 二 | F5: 8874807 | G5: =SUM(F5:F11) -> 52649495 | I5: 271475 | J5: =SUM(I5:I11) -> 1631463 | L5: 5922651 | M5: =SUM(L5:L11) -> 34916411 | O5: =L5/F5 -> 0.66735547 | P5: =M5/G5 -> 0.66318606 | R5: 1123600.9 | S5: =SUM(R5:R11) -> 7252446.6 | U5: =R5/F5 -> 0.12660568 | V5: =S5/G5 -> 0.1377496
D6: 45959 | E6: 三 | F6: 8157355 | I6: 254507 | L6: 5473618 | O6: =L6/F6 -> 0.67100402 | R6: 1100557.1 | U6: =R6/F6 -> 0.13491592
D7: 45960 | E7: 四 | F7: 7556926 | I7: 234639 | L7: 4858313 | O7: =L7/F7 -> 0.6428954 | R7: 1081448.1 | U7: =R7/F7 -> 0.14310687
D8: 45961 | E8: 五 | F8: 6398548 | I8: 200739 | L8: 4477272 | O8: =L8/F8 -> 0.6997325 | R8: 1030445.3 | U8: =R8/F8 -> 0.16104361
D9: 45962 | E9: 六 | F9: 6412266 | H9: =SUM(F9:F38) -> 71561306 | I9: 199982 | K9: =SUM(I9:I38) -> 2204262 | L9: 4385153 | N9: =SUM(L9:L38) -> 47078484 | O9: =L9/F9 -> 0.68386948 | Q9: =N9/H9 -> 0.65787626 | R9: 950256.83 | T9: =SUM(R9:R38) -> 9751618.1 | U9: =R9/F9 -> 0.14819361 | W9: =T9/H9 -> 0.13626943
D10: 45963 | E10: 日 | F10: 7718290 | I10: 239410 | L10: 4849950 | O10: =L10/F10 -> 0.62837105 | R10: 984498.93 | U10: =R10/F10 -> 0.12755402
D11: 45964 | E11: 一 | F11: 7531303 | I11: 230711 | L11: 4949454 | O11: =L11/F11 -> 0.65718429 | R11: 981639.55 | U11: =R11/F11 -> 0.13034126
D12: 45965 | E12: 二 | F12: 7342086 | G12: =SUM(F12:F18) -> 49899447 | I12: 226615 | J12: =SUM(I12:I18) -> 1534159 | L12: 4857460 | M12: =SUM(L12:L18) -> 32893927 | O12: =L12/F12 -> 0.66159127 | P12: =M12/G12 -> 0.65920424 | R12: 955604.38 | S12: =SUM(R12:R18) -> 6835222.8 | U12: =R12/F12 -> 0.13015434 | V12: =S12/G12 -> 0.13697993
D13: 45966 | E13: 三 | F13: 7302439 | I13: 226209 | L13: 4711139 | O13: =L13/F13 -> 0.64514596 | R13: 980946.19 | U13: =R13/F13 -> 0.13433131
D14: 45967 | E14: 四 | F14: 7792203 | I14: 230603 | L14: 5027266 | O14: =L14/F14 -> 0.6451662 | R14: 991870.96 | U14: =R14/F14 -> 0.12729019
D15: 45968 | E15: 五 | F15: 6208479 | I15: 193759 | L15: 4346463 | O15: =L15/F15 -> 0.700085 | R15: 950263.12 | U15: =R15/F15 -> 0.15305893
D16: 45969 | E16: 六 | F16: 6332588 | I16: 197295 | L16: 4319492 | O16: =L16/F16 -> 0.68210533 | R16: 942115.13 | U16: =R16/F16 -> 0.14877253
D17: 45970 | E17: 日 | F17: 7101855 | I17: 224442 | L17: 4667256 | O17: =L17/F17 -> 0.6571883 | R17: 958750.43 | U17: =R17/F17 -> 0.135
D18: 45971 | E18: 一 | F18: 7819797 | I18: 235236 | L18: 4964851 | O18: =L18/F18 -> 0.63490791 | R18: 1055672.6 | U18: =R18/F18 -> 0.135
D19: 45972 | E19: 二 | G19: =SUM(F19:F25) -> 0 | J19: =SUM(I19:I25) -> 0 | M19: =SUM(L19:L25) -> 0 | O19: =L19/F19 -> #DIV/0! | P19: =M19/G19 -> #DIV/0! | S19: =SUM(R19:R25) -> 0 | U19: =R19/F19 -> #DIV/0! | V19: =S19/G19 -> #DIV/0!
D20: 45973 | E20: 三 | O20: =L20/F20 -> #DIV/0! | U20: =R20/F20 -> #DIV/0!
D21: 45974 | E21: 四 | O21: =L21/F21 -> #DIV/0! | U21: =R21/F21 -> #DIV/0!
D22: 45975 | E22: 五 | O22: =L22/F22 -> #DIV/0! | U22: =R22/F22 -> #DIV/0!
D23: 45976 | E23: 六 | O23: =L23/F23 -> #DIV/0! | U23: =R23/F23 -> #DIV/0!
D24: 45977 | E24: 日 | O24: =L24/F24 -> #DIV/0! | U24: =R24/F24 -> #DIV/0!
D25: 45978 | E25: 一 | O25: =L25/F25 -> #DIV/0! | U25: =R25/F25 -> #DIV/0!
D26: 45979 | E26: 二 | G26: =SUM(F26:F32) -> 0 | J26: =SUM(I26:I32) -> 0 | M26: =SUM(L26:L32) -> 0 | O26: =L26/F26 -> #DIV/0! | P26: =M26/G26 -> #DIV/0! | S26: =SUM(R26:R32) -> 0 | U26: =R26/F26 -> #DIV/0! | V26: =S26/G26 -> #DIV/0!
D27: 45980 | E27: 三 | O27: =L27/F27 -> #DIV/0! | U27: =R27/F27 -> #DIV/0!
D28: 45981 | E28: 四 | O28: =L28/F28 -> #DIV/0! | U28: =R28/F28 -> #DIV/0!
D29: 45982 | E29: 五 | O29: =L29/F29 -> #DIV/0! | U29: =R29/F29 -> #DIV/0!
D30: 45983 | E30: 六 | O30: =L30/F30 -> #DIV/0! | U30: =R30/F30 -> #DIV/0!
D31: 45984 | E31: 日 | O31: =L31/F31 -> #DIV/0! | U31: =R31/F31 -> #DIV/0!
D32: 45985 | E32: 一 | O32: =L32/F32 -> #DIV/0! | U32: =R32/F32 -> #DIV/0!
D33: 45986 | E33: 二 | G33: =SUM(F33:F39) -> 0 | J33: =SUM(I33:I39) -> 0 | M33: =SUM(L33:L39) -> 0 | O33: =L33/F33 -> #DIV/0! | P33: =M33/G33 -> #DIV/0! | S33: =SUM(R33:R39) -> 0 | U33: =R33/F33 -> #DIV/0! | V33: =S33/G33 -> #DIV/0!
D34: 45987 | E34: 三 | O34: =L34/F34 -> #DIV/0! | U34: =R34/F34 -> #DIV/0!
D35: 45988 | E35: 四 | O35: =L35/F35 -> #DIV/0! | U35: =R35/F35 -> #DIV/0!
D36: 45989 | E36: 五 | O36: =L36/F36 -> #DIV/0! | U36: =R36/F36 -> #DIV/0!
D37: 45990 | E37: 六 | O37: =L37/F37 -> #DIV/0! | U37: =R37/F37 -> #DIV/0!
D38: 45991 | E38: 日 | O38: =L38/F38 -> #DIV/0! | U38: =R38/F38 -> #DIV/0!
D39: 45992 | E39: 一 | O39: =L39/F39 -> #DIV/0! | U39: =R39/F39 -> #DIV/0!
O40: =L40/F40 -> #DIV/0! | U40: =R40/F40 -> #DIV/0!

Sheet （２）ＫＰＩ達成進度
B1: KPI | C1: 366
B2: （２）ＫＰＩ達成進度
C3: 月份 | D3: 日期 | F3: 人時生產性(個/人) | I3: 人時生產性達成率(%) | L3: 半成品報廢(%) | O3: 半成品超用(%) | R3: 固定產線-導入率(固定產線數/總產線數) | U3: 教育訓練-實施率(進度/計畫)
F4: 日 | G4: 週平均 | H4: 月平均 | I4: 日 | J4: 週平均 | K4: 月平均 | L4: 日 | M4: 週平均 | N4: 月平均 | O4: 日 | P4: 週平均 | Q4: 月平均 | R4: 日 | S4: 週平均 | T4: 月平均 | U4: 日 | V4: 週平均 | W4: 月平均
D5: 45958 | E5: 二 | F5: 337.67255 | G5: =AVERAGE(F5:F11) -> 340.19679 | I5: =F5/$C$1 -> 0.92260259 | J5: =AVERAGE(I5:I11) -> 0.92949941 | L5: 0.0024675466 | M5: =AVERAGE(L5:L11) -> 0.0024552869 | O5: 0.0021732369 | P5: =AVERAGE(O5:O11) -> 0.0022768681 | R5: 0.91666667 | S5: =AVERAGE(R5:R11) -> 0.91666667 | U5: 0.87 | V5: =AVERAGE(U5:U11) -> 0.87342857
D6: 45959 | E6: 三 | F6: 348.68158 | I6: =F6/$C$1 -> 0.95268191 | L6: 0.0024403744 | O6: 0.0022650323 | R6: 0.91666667 | U6: 0.87
D7: 45960 | E7: 四 | F7: 331.92437 | I7: =F7/$C$1 -> 0.90689717 | L7: 0.0024691257 | O7: 0.0022019024 | R7: 0.91666667 | U7: 0.872
D8: 45961 | E8: 五 | F8: 334.50307 | I8: =F8/$C$1 -> 0.91394282 | L8: 0.0024696228 | O8: 0.0025908488 | R8: 0.91666667 | U8: 0.872
D9: 45962 | E9: 六 | F9: 337.32625 | H9: =AVERAGE(F9:F38) -> 338.19877 | I9: =F9/$C$1 -> 0.92165643 | K9: =AVERAGE(I9:I38) -> 0.30801345 | L9: 0.0024398551 | N9: =AVERAGE(L9:L38) -> 0.0024516729 | O9: 0.0025790165 | Q9: =AVERAGE(O9:O38) -> 0.0022264575 | R9: 0.91666667 | T9: =AVERAGE(R9:R38) -> 0.91666667 | U9: 0.875 | W9: =AVERAGE(U9:U38) -> 0.8814
D10: 45963 | E10: 日 | F10: 347.54377 | I10: =F10/$C$1 -> 0.94957315 | L10: 0.0024331814 | O10: 0.0020004283 | R10: 0.91666667 | U10: 0.875
D11: 45964 | E11: 一 | F11: 343.72591 | I11: =F11/$C$1 -> 0.93914183 | L11: 0.0024673021 | O11: 0.0021276117 | R11: 0.91666667 | U11: 0.88
D12: 45965 | E12: 二 | F12: 335.91131 | G12: =AVERAGE(F12:F18) -> 336.19882 | I12: =F12/$C$1 -> 0.91779047 | J12: =AVERAGE(I12:I18) -> 0.91857601 | L12: 0.0024704151 | M12: =AVERAGE(L12:L18) -> 0.0024537701 | O12: 0.0022034514 | P12: =AVERAGE(O12:O18) -> 0.0022225027 | R12: 0.91666667 | S12: =AVERAGE(R12:R18) -> 0.91666667 | U12: 0.88 | V12: =AVERAGE(U12:U18) -> 0.88342857
D13: 45966 | E13: 三 | F13: 337.18721 | I13: =F13/$C$1 -> 0.92127654 | L13: 0.0024442861 | O13: 0.002387131 | R13: 0.91666667 | U13: 0.882
D14: 45967 | E14: 四 | F14: 328.8584 | I14: =F14/$C$1 -> 0.89852022 | L14: 0.0024303205 | O14: 0.0020583738 | R14: 0.91666667 | U14: 0.882
D15: 45968 | E15: 五 | F15: 336.21898 | I15: =F15/$C$1 -> 0.91863109 | L15: 0.0024703313 | O15: 0.0023574055 | R15: 0.91666667 | U15: 0.884
D16: 45969 | E16: 六 | F16: 339.79293 | I16: =F16/$C$1 -> 0.92839599 | L16: 0.0024601316 | O16: 0.0023325595 | R16: 0.91666667 | U16: 0.884
D17: 45970 | E17: 日 | F17: 335.34657 | I17: =F17/$C$1 -> 0.91624747 | L17: 0.0024613288 | O17: 0.0021483472 | R17: 0.91666667 | U17: 0.886
D18: 45971 | E18: 一 | F18: 340.07632 | I18: =F18/$C$1 -> 0.92917027 | L18: 0.0024395774 | O18: 0.0020702505 | R18: 0.91666667 | U18: 0.886
D19: 45972 | E19: 二 | G19: =AVERAGE(F19:F25) -> #DIV/0! | I19: =F19/$C$1 -> 0 | J19: =AVERAGE(I19:I25) -> 0 | M19: =AVERAGE(L19:L25) -> #DIV/0! | P19: =AVERAGE(O19:O25) -> #DIV/0! | S19: =AVERAGE(R19:R25) -> #DIV/0! | V19: =AVERAGE(U19:U25) -> #DIV/0!
D20: 45973 | E20: 三 | I20: =F20/$C$1 -> 0
D21: 45974 | E21: 四 | I21: =F21/$C$1 -> 0
D22: 45975 | E22: 五 | I22: =F22/$C$1 -> 0
D23: 45976 | E23: 六 | I23: =F23/$C$1 -> 0
D24: 45977 | E24: 日 | I24: =F24/$C$1 -> 0
D25: 45978 | E25: 一 | I25: =F25/$C$1 -> 0
D26: 45979 | E26: 二 | G26: =AVERAGE(F26:F32) -> #DIV/0! | I26: =F26/$C$1 -> 0 | J26: =AVERAGE(I26:I32) -> 0 | M26: =AVERAGE(L26:L32) -> #DIV/0! | P26: =AVERAGE(O26:O32) -> #DIV/0! | S26: =AVERAGE(R26:R32) -> #DIV/0! | V26: =AVERAGE(U26:U32) -> #DIV/0!
D27: 45980 | E27: 三 | I27: =F27/$C$1 -> 0
D28: 45981 | E28: 四 | I28: =F28/$C$1 -> 0
D29: 45982 | E29: 五 | I29: =F29/$C$1 -> 0
D30: 45983 | E30: 六 | I30: =F30/$C$1 -> 0
D31: 45984 | E31: 日 | I31: =F31/$C$1 -> 0
D32: 45985 | E32: 一 | I32: =F32/$C$1 -> 0
D33: 45986 | E33: 二 | G33: =AVERAGE(F33:F39) -> #DIV/0! | I33: =F33/$C$1 -> 0 | J33: =AVERAGE(I33:I39) -> 0 | M33: =AVERAGE(L33:L39) -> #DIV/0! | P33: =AVERAGE(O33:O39) -> #DIV/0! | S33: =AVERAGE(R33:R39) -> #DIV/0! | V33: =AVERAGE(U33:U39) -> #DIV/0!
D34: 45987 | E34: 三 | I34: =F34/$C$1 -> 0
D35: 45988 | E35: 四 | I35: =F35/$C$1 -> 0
D36: 45989 | E36: 五 | I36: =F36/$C$1 -> 0
D37: 45990 | E37: 六 | I37: =F37/$C$1 -> 0
D38: 45991 | E38: 日 | I38: =F38/$C$1 -> 0
D39: 45992 | E39: 一 | I39: =F39/$C$1 -> 0

Sheet （３）業績構成比
B2: （3）業績構成比
C3: 月份 | D3: 日期 | F3: 營業額 | I3: 品類業績
I4: 18℃-飯糰 | O4: 18℃-壽司手卷 | U4: 4℃-飯糰 | W4: 4℃-壽司手卷 | Y4: 主食 | AE4: 便當 | AG4: 熱食義麵 | AI4: 季節調理麵 | AK4: 微波小吃
F5: 日 | G5: 週累積 | H5: 月累積 | I5: 一配 | K5: 二配 | M5: 合計 | O5: 一配 | Q5: 二配 | S5: 合計 | U5: 一配 | W5: 一配 | Y5: 一配 | AA5: 二配 | AC5: 合計 | AE5: 一配 | AG5: 一配 | AI5: 一配 | AK5: 一配
I6: 業績(元) | J6: 比例(%) | K6: 業績(元) | L6: 比例(%) | M6: 業績(元) | N6: 比例(%) | O6: 業績(元) | P6: 比例(%) | Q6: 業績(元) | R6: 比例(%) | S6: 業績(元) | T6: 比例(%) | U6: 業績(元) | V6: 比例(%) | W6: 業績(元) | X6: 比例(%) | Y6: 業績(元) | Z6: 比例(%) | AA6: 業績(元) | AB6: 比例(%) | AC6: 業績(元) | AD6: 比例(%) | AE6: 業績(元) | AF6: 比例(%) | AG6: 業績(元) | AH6: 比例(%) | AI6: 業績(元) | AJ6: 比例(%) | AK6: 業績(元) | AL6: 比例(%)
D7: 45958 | E7: 二 | F7: =SUM(M7,S7,U7,W7,AC7,AE7,AG7,AI7,AK7) -> 8874807 | G7: =SUM(F7:F13) -> 52649495 | I7: 780746.64 | J7: =I7/F7 -> 0.087973366 | K7: 911239.32 | L7: =K7/F7 -> 0.10267709 | M7: =SUM(I7+K7) -> 1691986 | N7: =M7/F7 -> 0.19065045 | O7: 271416.89 | P7: =O7/F7 -> 0.030582849 | Q7: 110287.01 | R7: =Q7/$F7 -> 0.012426976 | S7: =SUM(O7+Q7) -> 381703.9 | T7: =S7/F7 -> 0.043009825 | U7: 656894.59 | V7: =U7/F7 -> 0.074017902 | W7: 326083.5 | X7: =W7/F7 -> 0.036742602 | Y7: 700989.34 | Z7: =Y7/F7 -> 0.078986432 | AA7: 1516347.3 | AB7: =AA7/$F7 -> 0.17085975 | AC7: =SUM(Y7+AA7) -> 2217336.7 | AD7: =AC7/F7 -> 0.24984619 | AE7: 1283032.9 | AF7: =AE7/F7 -> 0.14457023 | AG7: 1049488.8 | AH7: =AG7/F7 -> 0.11825483 | AI7: 472206.16 | AJ7: =AI7/F7 -> 0.053207484 | AK7: 796074.54 | AL7: =AK7/F7 -> 0.089700491
D8: 45959 | E8: 三 | F8: =SUM(M8,S8,U8,W8,AC8,AE8,AG8,AI8,AK8) -> 8157355 | I8: 741769.41 | J8: =I8/F8 -> 0.090932589 | K8: 911358.13 | L8: =K8/F8 -> 0.11172226 | M8: =SUM(I8+K8) -> 1653127.5 | N8: =M8/F8 -> 0.20265485 | O8: 268793.45 | P8: =O8/F8 -> 0.032951054 | Q8: 111574.07 | R8: =Q8/$F8 -> 0.013677726 | S8: =SUM(O8+Q8) -> 380367.52 | T8: =S8/F8 -> 0.046628781 | U8: 647363.6 | V8: =U8/F8 -> 0.079359499 | W8: 211714.89 | X8: =W8/F8 -> 0.025953864 | Y8: 676052.95 | Z8: =Y8/F8 -> 0.08287649 | AA8: 1364309 | AB8: =AA8/$F8 -> 0.16724894 | AC8: =SUM(Y8+AA8) -> 2040361.9 | AD8: =AC8/F8 -> 0.25012543 | AE8: 1168977.6 | AF8: =AE8/F8 -> 0.14330351 | AG8: 940949.52 | AH8: =AG8/F8 -> 0.11534983 | AI8: 411972.81 | AJ8: =AI8/F8 -> 0.050503234 | AK8: 702519.62 | AL8: =AK8/F8 -> 0.086121007
D9: 45960 | E9: 四 | F9: =SUM(M9,S9,U9,W9,AC9,AE9,AG9,AI9,AK9) -> 7556926 | I9: 676655.12 | J9: =I9/F9 -> 0.089541054 | K9: 821105.69 | L9: =K9/F9 -> 0.10865605 | M9: =SUM(I9+K9) -> 1497760.8 | N9: =M9/F9 -> 0.1981971 | O9: 239899.99 | P9: =O9/F9 -> 0.031745712 | Q9: 110774.38 | R9: =Q9/$F9 -> 0.014658656 | S9: =SUM(O9+Q9) -> 350674.38 | T9: =S9/F9 -> 0.046404368 | U9: 606522.59 | V9: =U9/F9 -> 0.080260491 | W9: 194750.99 | X9: =W9/F9 -> 0.025771192 | Y9: 642678.45 | Z9: =Y9/F9 -> 0.085044957 | AA9: 1165803.2 | AB9: =AA9/$F9 -> 0.15426951 | AC9: =SUM(Y9+AA9) -> 1808481.7 | AD9: =AC9/F9 -> 0.23931446 | AE9: 1092729.8 | AF9: =AE9/F9 -> 0.14459978 | AG9: 926437.92 | AH9: =AG9/F9 -> 0.12259455 | AI9: 400515.05 | AJ9: =AI9/F9 -> 0.052999732 | AK9: 679052.73 | AL9: =AK9/F9 -> 0.089858327
D10: 45961 | E10: 五 | F10: =SUM(M10,S10,U10,W10,AC10,AE10,AG10,AI10,AK10) -> 6398548 | I10: 572932.73 | J10: =I10/F10 -> 0.089541054 | K10: 695240.92 | L10: =K10/F10 -> 0.10865605 | M10: =SUM(I10+K10) -> 1268173.7 | N10: =M10/F10 -> 0.1981971 | O10: 203126.46 | P10: =O10/F10 -> 0.031745712 | Q10: 93794.117 | R10: =Q10/$F10 -> 0.014658656 | S10: =SUM(O10+Q10) -> 296920.58 | T10: =S10/F10 -> 0.046404368 | U10: 513550.6 | V10: =U10/F10 -> 0.080260491 | W10: 164898.21 | X10: =W10/F10 -> 0.025771192 | Y10: 544164.24 | Z10: =Y10/F10 -> 0.085044957 | AA10: 987100.84 | AB10: =AA10/$F10 -> 0.15426951 | AC10: =SUM(Y10+AA10) -> 1531265.1 | AD10: =AC10/F10 -> 0.23931446 | AE10: 925228.63 | AF10: =AE10/F10 -> 0.14459978 | AG10: 784427.09 | AH10: =AG10/F10 -> 0.12259455 | AI10: 339121.33 | AJ10: =AI10/F10 -> 0.052999732 | AK10: 574962.82 | AL10: =AK10/F10 -> 0.089858327
D11: 45962 | E11: 六 | F11: =SUM(M11,S11,U11,W11,AC11,AE11,AG11,AI11,AK11) -> 6412266 | H11: =SUM(F11:F40) -> 71561306 | I11: 567801.04 | J11: =I11/F11 -> 0.088549203 | K11: 754884.39 | L11: =K11/F11 -> 0.11772506 | M11: =SUM(I11+K11) -> 1322685.4 | N11: =M11/F11 -> 0.20627426 | O11: 177542.94 | P11: =O11/F11 -> 0.027688018 | Q11: 86774.658 | R11: =Q11/$F11 -> 0.013532604 | S11: =SUM(O11+Q11) -> 264317.6 | T11: =S11/F11 -> 0.041220622 | U11: 481081.81 | V11: =U11/F11 -> 0.075025242 | W11: 121515.63 | X11: =W11/F11 -> 0.018950498 | Y11: 510464.55 | Z11: =Y11/F11 -> 0.079607513 | AA11: 1051831.7 | AB11: =AA11/$F11 -> 0.16403433 | AC11: =SUM(Y11+AA11) -> 1562296.3 | AD11: =AC11/F11 -> 0.24364184 | AE11: 950247.3 | AF11: =AE11/F11 -> 0.14819212 | AG11: 756441.55 | AH11: =AG11/F11 -> 0.1179679 | AI11: 395011.7 | AJ11: =AI11/F11 -> 0.061602512 | AK11: 558668.7 | AL11: =AK11/F11 -> 0.087125004
D12: 45963 | E12: 日 | F12: =SUM(M12,S12,U12,W12,AC12,AE12,AG12,AI12,AK12) -> 7718290 | I12: 738673.18 | J12: =I12/F12 -> 0.095704253 | K12: 812138.03 | L12: =K12/F12 -> 0.10522253 | M12: =SUM(I12+K12) -> 1550811.2 | N12: =M12/F12 -> 0.20092679 | O12: 228583.13 | P12: =O12/F12 -> 0.029615774 | Q12: 101174.44 | R12: =Q12/$F12 -> 0.013108401 | S12: =SUM(O12+Q12) -> 329757.57 | T12: =S12/F12 -> 0.042724175 | U12: 600818.62 | V12: =U12/F12 -> 0.077843488 | W12: 221851.07 | X12: =W12/F12 -> 0.028743552 | Y12: 610495.55 | Z12: =Y12/F12 -> 0.079097255 | AA12: 1179022.4 | AB12: =AA12/$F12 -> 0.15275694 | AC12: =SUM(Y12+AA12) -> 1789517.9 | AD12: =AC12/F12 -> 0.2318542 | AE12: 1178674.3 | AF12: =AE12/F12 -> 0.15271184 | AG12: 917428.15 | AH12: =AG12/F12 -> 0.11886417 | AI12: 427097.3 | AJ12: =AI12/F12 -> 0.055335741 | AK12: 702333.85 | AL12: =AK12/F12 -> 0.090996044
D13: 45964 | E13: 一 | F13: =SUM(M13,S13,U13,W13,AC13,AE13,AG13,AI13,AK13) -> 7531303 | I13: 711882.36 | J13: =I13/F13 -> 0.094523134 | K13: 805942.79 | L13: =K13/F13 -> 0.1070124 | M13: =SUM(I13+K13) -> 1517825.2 | N13: =M13/F13 -> 0.20153553 | O13: 214696.8 | P13: =O13/F13 -> 0.028507259 | Q13: 103070.03 | R13: =Q13/$F13 -> 0.013685551 | S13: =SUM(O13+Q13) -> 317766.84 | T13: =S13/F13 -> 0.04219281 | U13: 607897.73 | V13: =U13/F13 -> 0.080716143 | W13: 154909.57 | X13: =W13/F13 -> 0.02056876 | Y13: 587758.51 | Z13: =Y13/F13 -> 0.078042074 | AA13: 1192270.6 | AB13: =AA13/$F13 -> 0.15830867 | AC13: =SUM(Y13+AA13) -> 1780029.1 | AD13: =AC13/F13 -> 0.23635074 | AE13: 1140624.8 | AF13: =AE13/F13 -> 0.15145118 | AG13: 916621.96 | AH13: =AG13/F13 -> 0.12170828 | AI13: 424285 | AJ13: =AI13/F13 -> 0.0563362 | AK13: 671342.93 | AL13: =AK13/F13 -> 0.089140343
D14: 45965 | E14: 二 | F14: =SUM(M14,S14,U14,W14,AC14,AE14,AG14,AI14,AK14) -> 7342086 | G14: =SUM(F14:F20) -> 49899447 | I14: 673504.23 | J14: =I14/F14 -> 0.091732 | K14: 791412.03 | L14: =K14/F14 -> 0.10779117 | M14: =SUM(I14+K14) -> 1464916.3 | N14: =M14/F14 -> 0.19952317 | O14: 209859.11 | P14: =O14/F14 -> 0.028583036 | Q14: 102126.95 | R14: =Q14/$F14 -> 0.0139098 | S14: =SUM(O14+Q14) -> 311986.06 | T14: =S14/F14 -> 0.042492836 | U14: 603739.47 | V14: =U14/F14 -> 0.082229964 | W14: 141811.93 | X14: =W14/F14 -> 0.019314938 | Y14: 594997.27 | Z14: =Y14/F14 -> 0.081039268 | AA14: 1177404.9 | AB14: =AA14/$F14 -> 0.16036381 | AC14: =SUM(Y14+AA14) -> 1772402.2 | AD14: =AC14/F14 -> 0.24140308 | AE14: 1130602.9 | AF14: =AE14/F14 -> 0.15398933 | AG14: 880469.57 | AH14: =AG14/F14 -> 0.1199209 | AI14: 410273.61 | AJ14: =AI14/F14 -> 0.055879706 | AK14: 625884.03 | AL14: =AK14/F14 -> 0.085246077
D15: 45966 | E15: 三 | F15: =SUM(M15,S15,U15,W15,AC15,AE15,AG15,AI15,AK15) -> 7302439 | I15: 671273.38 | J15: =I15/F15 -> 0.091924545 | K15: 787143.19 | L15: =K15/F15 -> 0.10779182 | M15: =SUM(I15+K15) -> 1458416.6 | N15: =M15/F15 -> 0.19971637 | O15: 205452.13 | P15: =O15/F15 -> 0.028134728 | Q15: 103532.05 | R15: =Q15/$F15 -> 0.014177735 | S15: =SUM(O15+Q15) -> 308984.18 | T15: =S15/F15 -> 0.042312463 | U15: 590084.23 | V15: =U15/F15 -> 0.080806458 | W15: 147962.38 | X15: =W15/F15 -> 0.020262049 | Y15: 602219.44 | Z15: =Y15/F15 -> 0.08246826 | AA15: 1149748.3 | AB15: =AA15/$F15 -> 0.15744717 | AC15: =SUM(Y15+AA15) -> 1751967.8 | AD15: =AC15/F15 -> 0.23991543 | AE15: 1104042.2 | AF15: =AE15/F15 -> 0.15118814 | AG15: 867385.09 | AH15: =AG15/F15 -> 0.11878019 | AI15: 439061.16 | AJ15: =AI15/F15 -> 0.060125276 | AK15: 634535.45 | AL15: =AK15/F15 -> 0.086893632
D16: 45967 | E16: 四 | F16: =SUM(M16,S16,U16,W16,AC16,AE16,AG16,AI16,AK16) -> 7792203 | I16: 639847.83 | J16: =I16/F16 -> 0.082113855 | K16: 737767.77 | L16: =K16/F16 -> 0.094680256 | M16: =SUM(I16+K16) -> 1377615.6 | N16: =M16/F16 -> 0.17679411 | O16: 182346.73 | P16: =O16/F16 -> 0.023401178 | Q16: 102698.19 | R16: =Q16/$F16 -> 0.013179609 | S16: =SUM(O16+Q16) -> 285044.92 | T16: =S16/F16 -> 0.036580787 | U16: 565885.32 | V16: =U16/F16 -> 0.072621994 | W16: 165987.31 | X16: =W16/F16 -> 0.021301718 | Y16: 564704.7 | Z16: =Y16/F16 -> 0.072470481 | AA16: 1865678.5 | AB16: =AA16/$F16 -> 0.23942889 | AC16: =SUM(Y16+AA16) -> 2430383.2 | AD16: =AC16/F16 -> 0.31189937 | AE16: 1076925.9 | AF16: =AE16/F16 -> 0.13820558 | AG16: 826737.45 | AH16: =AG16/F16 -> 0.10609804 | AI16: 453248.7 | AJ16: =AI16/F16 -> 0.058166952 | AK16: 610374.6 | AL16: =AK16/F16 -> 0.078331455
D17: 45968 | E17: 五 | F17: =SUM(M17,S17,U17,W17,AC17,AE17,AG17,AI17,AK17) -> 6208479 | I17: 544969.64 | J17: =I17/F17 -> 0.087778286 | K17: 709438.86 | L17: =K17/F17 -> 0.11426935 | M17: =SUM(I17+K17) -> 1254408.5 | N17: =M17/F17 -> 0.20204764 | O17: 164398.56 | P17: =O17/F17 -> 0.026479684 | Q17: 96678.26 | R17: =Q17/$F17 -> 0.015571972 | S17: =SUM(O17+Q17) -> 261076.82 | T17: =S17/F17 -> 0.042051655 | U17: 499063.51 | V17: =U17/F17 -> 0.080384183 | W17: 146789.41 | X17: =W17/F17 -> 0.023643378 | Y17: 530434.64 | Z17: =Y17/F17 -> 0.085437132 | AA17: 860363.67 | AB17: =AA17/$F17 -> 0.13857882 | AC17: =SUM(Y17+AA17) -> 1390798.3 | AD17: =AC17/F17 -> 0.22401595 | AE17: 953583.59 | AF17: =AE17/F17 -> 0.15359375 | AG17: 671689.05 | AH17: =AG17/F17 -> 0.10818899 | AI17: 440097.88 | AJ17: =AI17/F17 -> 0.070886586 | AK17: 590971.93 | AL17: =AK17/F17 -> 0.095187876
D18: 45969 | E18: 六 | F18: =SUM(M18,S18,U18,W18,AC18,AE18,AG18,AI18,AK18) -> 6332588 | I18: 525873.59 | J18: =I18/F18 -> 0.083042445 | K18: 758939.39 | L18: =K18/F18 -> 0.11984664 | M18: =SUM(I18+K18) -> 1284813 | N18: =M18/F18 -> 0.20288908 | O18: 154500.21 | P18: =O18/F18 -> 0.02439764 | Q18: 90902.185 | R18: =Q18/$F18 -> 0.014354666 | S18: =SUM(O18+Q18) -> 245402.39 | T18: =S18/F18 -> 0.038752306 | U18: 528904.55 | V18: =U18/F18 -> 0.083521074 | W18: 133171.32 | X18: =W18/F18 -> 0.021029525 | Y18: 546381.27 | Z18: =Y18/F18 -> 0.086280881 | AA18: 911127.88 | AB18: =AA18/$F18 -> 0.14387923 | AC18: =SUM(Y18+AA18) -> 1457509.2 | AD18: =AC18/F18 -> 0.23016011 | AE18: 946260.11 | AF18: =AE18/F18 -> 0.14942708 | AG18: 720981.83 | AH18: =AG18/F18 -> 0.11385263 | AI18: 444253.16 | AJ18: =AI18/F18 -> 0.070153491 | AK18: 571292.51 | AL18: =AK18/F18 -> 0.090214698
D19: 45970 | E19: 日 | F19: =SUM(M19,S19,U19,W19,AC19,AE19,AG19,AI19,AK19) -> 7101855 | I19: 685774.54 | J19: =I19/F19 -> 0.096562735 | K19: 818212.64 | L19: =K19/F19 -> 0.11521112 | M19: =SUM(I19+K19) -> 1503987.2 | N19: =M19/F19 -> 0.21177385 | O19: 195573.01 | P19: =O19/F19 -> 0.027538299 | Q19: 102486.26 | R19: =Q19/$F19 -> 0.014430914 | S19: =SUM(O19+Q19) -> 298059.26 | T19: =S19/F19 -> 0.041969213 | U19: 589179.1 | V19: =U19/F19 -> 0.082961297 | W19: 145516.13 | X19: =W19/F19 -> 0.020489876 | Y19: 610695.73 | Z19: =Y19/F19 -> 0.085991016 | AA19: 797865.74 | AB19: =AA19/$F19 -> 0.1123461 | AC19: =SUM(Y19+AA19) -> 1408561.5 | AD19: =AC19/F19 -> 0.19833712 | AE19: 1139093.2 | AF19: =AE19/F19 -> 0.16039376 | AG19: 875891.89 | AH19: =AG19/F19 -> 0.12333283 | AI19: 501676.75 | AJ19: =AI19/F19 -> 0.070640241 | AK19: 639889.97 | AL19: =AK19/F19 -> 0.090101807
D20: 45971 | E20: 一 | F20: =SUM(M20,S20,U20,W20,AC20,AE20,AG20,AI20,AK20) -> 7819797 | I20: 653047.44 | J20: =I20/F20 -> 0.083512071 | K20: 792892.22 | L20: =K20/F20 -> 0.1013955 | M20: =SUM(I20+K20) -> 1445939.7 | N20: =M20/F20 -> 0.18490757 | O20: 183067.09 | P20: =O20/F20 -> 0.023410722 | Q20: 101141.88 | R20: =Q20/$F20 -> 0.01293408 | S20: =SUM(O20+Q20) -> 284208.98 | T20: =S20/F20 -> 0.036344803 | U20: 572593.59 | V20: =U20/F20 -> 0.073223588 | W20: 140994.77 | X20: =W20/F20 -> 0.018030489 | Y20: 616118.19 | Z20: =Y20/F20 -> 0.078789538 | AA20: 1654459.4 | AB20: =AA20/$F20 -> 0.21157319 | AC20: =SUM(Y20+AA20) -> 2270577.6 | AD20: =AC20/F20 -> 0.29036273 | AE20: 1138682.9 | AF20: =AE20/F20 -> 0.1456154 | AG20: 876253.98 | AH20: =AG20/F20 -> 0.11205585 | AI20: 456905.08 | AJ20: =AI20/F20 -> 0.058429276 | AK20: 633640.47 | AL20: =AK20/F20 -> 0.081030297
D21: 45972 | E21: 二 | F21: =SUM(M21,S21,U21,W21,AC21,AE21,AG21,AI21,AK21) -> 0 | G21: =SUM(F21:F27) -> 0 | J21: =I21/F21 -> #DIV/0! | L21: =K21/F21 -> #DIV/0! | M21: =SUM(I21+K21) -> 0 | N21: =M21/F21 -> #DIV/0! | P21: =O21/F21 -> #DIV/0! | R21: =Q21/$F21 -> #DIV/0! | S21: =SUM(O21+Q21) -> 0 | T21: =S21/F21 -> #DIV/0! | V21: =U21/F21 -> #DIV/0! | X21: =W21/F21 -> #DIV/0! | Z21: =Y21/F21 -> #DIV/0! | AB21: =AA21/$F21 -> #DIV/0! | AC21: =SUM(Y21+AA21) -> 0 | AD21: =AC21/F21 -> #DIV/0! | AF21: =AE21/F21 -> #DIV/0! | AH21: =AG21/F21 -> #DIV/0! | AJ21: =AI21/F21 -> #DIV/0! | AL21: =AK21/F21 -> #DIV/0!
D22: 45973 | E22: 三 | F22: =SUM(M22,S22,U22,W22,AC22,AE22,AG22,AI22,AK22) -> 0 | J22: =I22/F22 -> #DIV/0! | L22: =K22/F22 -> #DIV/0! | M22: =SUM(I22+K22) -> 0 | N22: =M22/F22 -> #DIV/0! | P22: =O22/F22 -> #DIV/0! | R22: =Q22/$F22 -> #DIV/0! | S22: =SUM(O22+Q22) -> 0 | T22: =S22/F22 -> #DIV/0! | V22: =U22/F22 -> #DIV/0! | X22: =W22/F22 -> #DIV/0! | Z22: =Y22/F22 -> #DIV/0! | AB22: =AA22/$F22 -> #DIV/0! | AC22: =SUM(Y22+AA22) -> 0 | AD22: =AC22/F22 -> #DIV/0! | AF22: =AE22/F22 -> #DIV/0! | AH22: =AG22/F22 -> #DIV/0! | AJ22: =AI22/F22 -> #DIV/0! | AL22: =AK22/F22 -> #DIV/0!
D23: 45974 | E23: 四 | F23: =SUM(M23,S23,U23,W23,AC23,AE23,AG23,AI23,AK23) -> 0 | J23: =I23/F23 -> #DIV/0! | L23: =K23/F23 -> #DIV/0! | M23: =SUM(I23+K23) -> 0 | N23: =M23/F23 -> #DIV/0! | P23: =O23/F23 -> #DIV/0! | R23: =Q23/$F23 -> #DIV/0! | S23: =SUM(O23+Q23) -> 0 | T23: =S23/F23 -> #DIV/0! | V23: =U23/F23 -> #DIV/0! | X23: =W23/F23 -> #DIV/0! | Z23: =Y23/F23 -> #DIV/0! | AB23: =AA23/$F23 -> #DIV/0! | AC23: =SUM(Y23+AA23) -> 0 | AD23: =AC23/F23 -> #DIV/0! | AF23: =AE23/F23 -> #DIV/0! | AH23: =AG23/F23 -> #DIV/0! | AJ23: =AI23/F23 -> #DIV/0! | AL23: =AK23/F23 -> #DIV/0!
D24: 45975 | E24: 五 | F24: =SUM(M24,S24,U24,W24,AC24,AE24,AG24,AI24,AK24) -> 0 | J24: =I24/F24 -> #DIV/0! | L24: =K24/F24 -> #DIV/0! | M24: =SUM(I24+K24) -> 0 | N24: =M24/F24 -> #DIV/0! | P24: =O24/F24 -> #DIV/0! | R24: =Q24/$F24 -> #DIV/0! | S24: =SUM(O24+Q24) -> 0 | T24: =S24/F24 -> #DIV/0! | V24: =U24/F24 -> #DIV/0! | X24: =W24/F24 -> #DIV/0! | Z24: =Y24/F24 -> #DIV/0! | AB24: =AA24/$F24 -> #DIV/0! | AC24: =SUM(Y24+AA24) -> 0 | AD24: =AC24/F24 -> #DIV/0! | AF24: =AE24/F24 -> #DIV/0! | AH24: =AG24/F24 -> #DIV/0! | AJ24: =AI24/F24 -> #DIV/0! | AL24: =AK24/F24 -> #DIV/0!
D25: 45976 | E25: 六 | F25: =SUM(M25,S25,U25,W25,AC25,AE25,AG25,AI25,AK25) -> 0 | J25: =I25/F25 -> #DIV/0! | L25: =K25/F25 -> #DIV/0! | M25: =SUM(I25+K25) -> 0 | N25: =M25/F25 -> #DIV/0! | P25: =O25/F25 -> #DIV/0! | R25: =Q25/$F25 -> #DIV/0! | S25: =SUM(O25+Q25) -> 0 | T25: =S25/F25 -> #DIV/0! | V25: =U25/F25 -> #DIV/0! | X25: =W25/F25 -> #DIV/0! | Z25: =Y25/F25 -> #DIV/0! | AB25: =AA25/$F25 -> #DIV/0! | AC25: =SUM(Y25+AA25) -> 0 | AD25: =AC25/F25 -> #DIV/0! | AF25: =AE25/F25 -> #DIV/0! | AH25: =AG25/F25 -> #DIV/0! | AJ25: =AI25/F25 -> #DIV/0! | AL25: =AK25/F25 -> #DIV/0!
D26: 45977 | E26: 日 | F26: =SUM(M26,S26,U26,W26,AC26,AE26,AG26,AI26,AK26) -> 0 | J26: =I26/F26 -> #DIV/0! | L26: =K26/F26 -> #DIV/0! | M26: =SUM(I26+K26) -> 0 | N26: =M26/F26 -> #DIV/0! | P26: =O26/F26 -> #DIV/0! | R26: =Q26/$F26 -> #DIV/0! | S26: =SUM(O26+Q26) -> 0 | T26: =S26/F26 -> #DIV/0! | V26: =U26/F26 -> #DIV/0! | X26: =W26/F26 -> #DIV/0! | Z26: =Y26/F26 -> #DIV/0! | AB26: =AA26/$F26 -> #DIV/0! | AC26: =SUM(Y26+AA26) -> 0 | AD26: =AC26/F26 -> #DIV/0! | AF26: =AE26/F26 -> #DIV/0! | AH26: =AG26/F26 -> #DIV/0! | AJ26: =AI26/F26 -> #DIV/0! | AL26: =AK26/F26 -> #DIV/0!
D27: 45978 | E27: 一 | F27: =SUM(M27,S27,U27,W27,AC27,AE27,AG27,AI27,AK27) -> 0 | J27: =I27/F27 -> #DIV/0! | L27: =K27/F27 -> #DIV/0! | M27: =SUM(I27+K27) -> 0 | N27: =M27/F27 -> #DIV/0! | P27: =O27/F27 -> #DIV/0! | R27: =Q27/$F27 -> #DIV/0! | S27: =SUM(O27+Q27) -> 0 | T27: =S27/F27 -> #DIV/0! | V27: =U27/F27 -> #DIV/0! | X27: =W27/F27 -> #DIV/0! | Z27: =Y27/F27 -> #DIV/0! | AB27: =AA27/$F27 -> #DIV/0! | AC27: =SUM(Y27+AA27) -> 0 | AD27: =AC27/F27 -> #DIV/0! | AF27: =AE27/F27 -> #DIV/0! | AH27: =AG27/F27 -> #DIV/0! | AJ27: =AI27/F27 -> #DIV/0! | AL27: =AK27/F27 -> #DIV/0!
D28: 45979 | E28: 二 | F28: =SUM(M28,S28,U28,W28,AC28,AE28,AG28,AI28,AK28) -> 0 | G28: =SUM(F28:F34) -> 0 | J28: =I28/F28 -> #DIV/0! | L28: =K28/F28 -> #DIV/0! | M28: =SUM(I28+K28) -> 0 | N28: =M28/F28 -> #DIV/0! | P28: =O28/F28 -> #DIV/0! | R28: =Q28/$F28 -> #DIV/0! | S28: =SUM(O28+Q28) -> 0 | T28: =S28/F28 -> #DIV/0! | V28: =U28/F28 -> #DIV/0! | X28: =W28/F28 -> #DIV/0! | Z28: =Y28/F28 -> #DIV/0! | AB28: =AA28/$F28 -> #DIV/0! | AC28: =SUM(Y28+AA28) -> 0 | AD28: =AC28/F28 -> #DIV/0! | AF28: =AE28/F28 -> #DIV/0! | AH28: =AG28/F28 -> #DIV/0! | AJ28: =AI28/F28 -> #DIV/0! | AL28: =AK28/F28 -> #DIV/0!
D29: 45980 | E29: 三 | F29: =SUM(M29,S29,U29,W29,AC29,AE29,AG29,AI29,AK29) -> 0 | J29: =I29/F29 -> #DIV/0! | L29: =K29/F29 -> #DIV/0! | M29: =SUM(I29+K29) -> 0 | N29: =M29/F29 -> #DIV/0! | P29: =O29/F29 -> #DIV/0! | R29: =Q29/$F29 -> #DIV/0! | S29: =SUM(O29+Q29) -> 0 | T29: =S29/F29 -> #DIV/0! | V29: =U29/F29 -> #DIV/0! | X29: =W29/F29 -> #DIV/0! | Z29: =Y29/F29 -> #DIV/0! | AB29: =AA29/$F29 -> #DIV/0! | AC29: =SUM(Y29+AA29) -> 0 | AD29: =AC29/F29 -> #DIV/0! | AF29: =AE29/F29 -> #DIV/0! | AH29: =AG29/F29 -> #DIV/0! | AJ29: =AI29/F29 -> #DIV/0! | AL29: =AK29/F29 -> #DIV/0!
D30: 45981 | E30: 四 | F30: =SUM(M30,S30,U30,W30,AC30,AE30,AG30,AI30,AK30) -> 0 | J30: =I30/F30 -> #DIV/0! | L30: =K30/F30 -> #DIV/0! | M30: =SUM(I30+K30) -> 0 | N30: =M30/F30 -> #DIV/0! | P30: =O30/F30 -> #DIV/0! | R30: =Q30/$F30 -> #DIV/0! | S30: =SUM(O30+Q30) -> 0 | T30: =S30/F30 -> #DIV/0! | V30: =U30/F30 -> #DIV/0! | X30: =W30/F30 -> #DIV/0! | Z30: =Y30/F30 -> #DIV/0! | AB30: =AA30/$F30 -> #DIV/0! | AC30: =SUM(Y30+AA30) -> 0 | AD30: =AC30/F30 -> #DIV/0! | AF30: =AE30/F30 -> #DIV/0! | AH30: =AG30/F30 -> #DIV/0! | AJ30: =AI30/F30 -> #DIV/0! | AL30: =AK30/F30 -> #DIV/0!
D31: 45982 | E31: 五 | F31: =SUM(M31,S31,U31,W31,AC31,AE31,AG31,AI31,AK31) -> 0 | J31: =I31/F31 -> #DIV/0! | L31: =K31/F31 -> #DIV/0! | M31: =SUM(I31+K31) -> 0 | N31: =M31/F31 -> #DIV/0! | P31: =O31/F31 -> #DIV/0! | R31: =Q31/$F31 -> #DIV/0! | S31: =SUM(O31+Q31) -> 0 | T31: =S31/F31 -> #DIV/0! | V31: =U31/F31 -> #DIV/0! | X31: =W31/F31 -> #DIV/0! | Z31: =Y31/F31 -> #DIV/0! | AB31: =AA31/$F31 -> #DIV/0! | AC31: =SUM(Y31+AA31) -> 0 | AD31: =AC31/F31 -> #DIV/0! | AF31: =AE31/F31 -> #DIV/0! | AH31: =AG31/F31 -> #DIV/0! | AJ31: =AI31/F31 -> #DIV/0! | AL31: =AK31/F31 -> #DIV/0!
D32: 45983 | E32: 六 | F32: =SUM(M32,S32,U32,W32,AC32,AE32,AG32,AI32,AK32) -> 0 | J32: =I32/F32 -> #DIV/0! | L32: =K32/F32 -> #DIV/0! | M32: =SUM(I32+K32) -> 0 | N32: =M32/F32 -> #DIV/0! | P32: =O32/F32 -> #DIV/0! | R32: =Q32/$F32 -> #DIV/0! | S32: =SUM(O32+Q32) -> 0 | T32: =S32/F32 -> #DIV/0! | V32: =U32/F32 -> #DIV/0! | X32: =W32/F32 -> #DIV/0! | Z32: =Y32/F32 -> #DIV/0! | AB32: =AA32/$F32 -> #DIV/0! | AC32: =SUM(Y32+AA32) -> 0 | AD32: =AC32/F32 -> #DIV/0! | AF32: =AE32/F32 -> #DIV/0! | AH32: =AG32/F32 -> #DIV/0! | AJ32: =AI32/F32 -> #DIV/0! | AL32: =AK32/F32 -> #DIV/0!
D33: 45984 | E33: 日 | F33: =SUM(M33,S33,U33,W33,AC33,AE33,AG33,AI33,AK33) -> 0 | J33: =I33/F33 -> #DIV/0! | L33: =K33/F33 -> #DIV/0! | M33: =SUM(I33+K33) -> 0 | N33: =M33/F33 -> #DIV/0! | P33: =O33/F33 -> #DIV/0! | R33: =Q33/$F33 -> #DIV/0! | S33: =SUM(O33+Q33) -> 0 | T33: =S33/F33 -> #DIV/0! | V33: =U33/F33 -> #DIV/0! | X33: =W33/F33 -> #DIV/0! | Z33: =Y33/F33 -> #DIV/0! | AB33: =AA33/$F33 -> #DIV/0! | AC33: =SUM(Y33+AA33) -> 0 | AD33: =AC33/F33 -> #DIV/0! | AF33: =AE33/F33 -> #DIV/0! | AH33: =AG33/F33 -> #DIV/0! | AJ33: =AI33/F33 -> #DIV/0! | AL33: =AK33/F33 -> #DIV/0!
D34: 45985 | E34: 一 | F34: =SUM(M34,S34,U34,W34,AC34,AE34,AG34,AI34,AK34) -> 0 | J34: =I34/F34 -> #DIV/0! | L34: =K34/F34 -> #DIV/0! | M34: =SUM(I34+K34) -> 0 | N34: =M34/F34 -> #DIV/0! | P34: =O34/F34 -> #DIV/0! | R34: =Q34/$F34 -> #DIV/0! | S34: =SUM(O34+Q34) -> 0 | T34: =S34/F34 -> #DIV/0! | V34: =U34/F34 -> #DIV/0! | X34: =W34/F34 -> #DIV/0! | Z34: =Y34/F34 -> #DIV/0! | AB34: =AA34/$F34 -> #DIV/0! | AC34: =SUM(Y34+AA34) -> 0 | AD34: =AC34/F34 -> #DIV/0! | AF34: =AE34/F34 -> #DIV/0! | AH34: =AG34/F34 -> #DIV/0! | AJ34: =AI34/F34 -> #DIV/0! | AL34: =AK34/F34 -> #DIV/0!
D35: 45986 | E35: 二 | F35: =SUM(M35,S35,U35,W35,AC35,AE35,AG35,AI35,AK35) -> 0 | G35: =SUM(F35:F41) -> 0 | J35: =I35/F35 -> #DIV/0! | L35: =K35/F35 -> #DIV/0! | M35: =SUM(I35+K35) -> 0 | N35: =M35/F35 -> #DIV/0! | P35: =O35/F35 -> #DIV/0! | R35: =Q35/$F35 -> #DIV/0! | S35: =SUM(O35+Q35) -> 0 | T35: =S35/F35 -> #DIV/0! | V35: =U35/F35 -> #DIV/0! | X35: =W35/F35 -> #DIV/0! | Z35: =Y35/F35 -> #DIV/0! | AB35: =AA35/$F35 -> #DIV/0! | AC35: =SUM(Y35+AA35) -> 0 | AD35: =AC35/F35 -> #DIV/0! | AF35: =AE35/F35 -> #DIV/0! | AH35: =AG35/F35 -> #DIV/0! | AJ35: =AI35/F35 -> #DIV/0! | AL35: =AK35/F35 -> #DIV/0!
D36: 45987 | E36: 三 | F36: =SUM(M36,S36,U36,W36,AC36,AE36,AG36,AI36,AK36) -> 0 | J36: =I36/F36 -> #DIV/0! | L36: =K36/F36 -> #DIV/0! | M36: =SUM(I36+K36) -> 0 | N36: =M36/F36 -> #DIV/0! | P36: =O36/F36 -> #DIV/0! | R36: =Q36/$F36 -> #DIV/0! | S36: =SUM(O36+Q36) -> 0 | T36: =S36/F36 -> #DIV/0! | V36: =U36/F36 -> #DIV/0! | X36: =W36/F36 -> #DIV/0! | Z36: =Y36/F36 -> #DIV/0! | AB36: =AA36/$F36 -> #DIV/0! | AC36: =SUM(Y36+AA36) -> 0 | AD36: =AC36/F36 -> #DIV/0! | AF36: =AE36/F36 -> #DIV/0! | AH36: =AG36/F36 -> #DIV/0! | AJ36: =AI36/F36 -> #DIV/0! | AL36: =AK36/F36 -> #DIV/0!
D37: 45988 | E37: 四 | F37: =SUM(M37,S37,U37,W37,AC37,AE37,AG37,AI37,AK37) -> 0 | J37: =I37/F37 -> #DIV/0! | L37: =K37/F37 -> #DIV/0! | M37: =SUM(I37+K37) -> 0 | N37: =M37/F37 -> #DIV/0! | P37: =O37/F37 -> #DIV/0! | R37: =Q37/$F37 -> #DIV/0! | S37: =SUM(O37+Q37) -> 0 | T37: =S37/F37 -> #DIV/0! | V37: =U37/F37 -> #DIV/0! | X37: =W37/F37 -> #DIV/0! | Z37: =Y37/F37 -> #DIV/0! | AB37: =AA37/$F37 -> #DIV/0! | AC37: =SUM(Y37+AA37) -> 0 | AD37: =AC37/F37 -> #DIV/0! | AF37: =AE37/F37 -> #DIV/0! | AH37: =AG37/F37 -> #DIV/0! | AJ37: =AI37/F37 -> #DIV/0! | AL37: =AK37/F37 -> #DIV/0!
D38: 45989 | E38: 五 | F38: =SUM(M38,S38,U38,W38,AC38,AE38,AG38,AI38,AK38) -> 0 | J38: =I38/F38 -> #DIV/0! | L38: =K38/F38 -> #DIV/0! | M38: =SUM(I38+K38) -> 0 | N38: =M38/F38 -> #DIV/0! | P38: =O38/F38 -> #DIV/0! | R38: =Q38/$F38 -> #DIV/0! | S38: =SUM(O38+Q38) -> 0 | T38: =S38/F38 -> #DIV/0! | V38: =U38/F38 -> #DIV/0! | X38: =W38/F38 -> #DIV/0! | Z38: =Y38/F38 -> #DIV/0! | AB38: =AA38/$F38 -> #DIV/0! | AC38: =SUM(Y38+AA38) -> 0 | AD38: =AC38/F38 -> #DIV/0! | AF38: =AE38/F38 -> #DIV/0! | AH38: =AG38/F38 -> #DIV/0! | AJ38: =AI38/F38 -> #DIV/0! | AL38: =AK38/F38 -> #DIV/0!
D39: 45990 | E39: 六 | F39: =SUM(M39,S39,U39,W39,AC39,AE39,AG39,AI39,AK39) -> 0 | J39: =I39/F39 -> #DIV/0! | L39: =K39/F39 -> #DIV/0! | M39: =SUM(I39+K39) -> 0 | N39: =M39/F39 -> #DIV/0! | P39: =O39/F39 -> #DIV/0! | R39: =Q39/$F39 -> #DIV/0! | S39: =SUM(O39+Q39) -> 0 | T39: =S39/F39 -> #DIV/0! | V39: =U39/F39 -> #DIV/0! | X39: =W39/F39 -> #DIV/0! | Z39: =Y39/F39 -> #DIV/0! | AB39: =AA39/$F39 -> #DIV/0! | AC39: =SUM(Y39+AA39) -> 0 | AD39: =AC39/F39 -> #DIV/0! | AF39: =AE39/F39 -> #DIV/0! | AH39: =AG39/F39 -> #DIV/0! | AJ39: =AI39/F39 -> #DIV/0! | AL39: =AK39/F39 -> #DIV/0!
D40: 45991 | E40: 日 | F40: =SUM(M40,S40,U40,W40,AC40,AE40,AG40,AI40,AK40) -> 0 | J40: =I40/F40 -> #DIV/0! | L40: =K40/F40 -> #DIV/0! | M40: =SUM(I40+K40) -> 0 | N40: =M40/F40 -> #DIV/0! | P40: =O40/F40 -> #DIV/0! | R40: =Q40/$F40 -> #DIV/0! | S40: =SUM(O40+Q40) -> 0 | T40: =S40/F40 -> #DIV/0! | V40: =U40/F40 -> #DIV/0! | X40: =W40/F40 -> #DIV/0! | Z40: =Y40/F40 -> #DIV/0! | AB40: =AA40/$F40 -> #DIV/0! | AC40: =SUM(Y40+AA40) -> 0 | AD40: =AC40/F40 -> #DIV/0! | AF40: =AE40/F40 -> #DIV/0! | AH40: =AG40/F40 -> #DIV/0! | AJ40: =AI40/F40 -> #DIV/0! | AL40: =AK40/F40 -> #DIV/0!
D41: 45992 | E41: 一 | F41: =SUM(M41,S41,U41,W41,AC41,AE41,AG41,AI41,AK41) -> 0 | J41: =I41/F41 -> #DIV/0! | L41: =K41/F41 -> #DIV/0! | M41: =SUM(I41+K41) -> 0 | N41: =M41/F41 -> #DIV/0! | P41: =O41/F41 -> #DIV/0! | R41: =Q41/$F41 -> #DIV/0! | S41: =SUM(O41+Q41) -> 0 | T41: =S41/F41 -> #DIV/0! | V41: =U41/F41 -> #DIV/0! | X41: =W41/F41 -> #DIV/0! | Z41: =Y41/F41 -> #DIV/0! | AB41: =AA41/$F41 -> #DIV/0! | AC41: =SUM(Y41+AA41) -> 0 | AD41: =AC41/F41 -> #DIV/0! | AF41: =AE41/F41 -> #DIV/0! | AH41: =AG41/F41 -> #DIV/0! | AJ41: =AI41/F41 -> #DIV/0! | AL41: =AK41/F41 -> #DIV/0!
...

Sheet （４）訂單數量構成比
B2: （4）訂單數量構成比
C3: 月份 | D3: 日期 | F3: 訂單量 | I3: 品類訂單量
I4: 18℃-飯糰 | O4: 18℃-壽司手卷 | U4: 4℃-飯糰 | W4: 4℃-壽司手卷 | Y4: 主食 | AE4: 便當 | AG4: 熱食義麵 | AI4: 季節調理麵 | AK4: 微波小吃
F5: 日 | G5: 週累積 | H5: 月累積 | I5: 一配 | K5: 二配 | M5: 合計 | O5: 一配 | Q5: 二配 | S5: 合計 | U5: 一配 | W5: 一配 | Y5: 一配 | AA5: 二配 | AC5: 合計 | AE5: 一配 | AG5: 一配 | AI5: 一配 | AK5: 一配
I6: 訂單數 | J6: 比例(%) | K6: 訂單數 | L6: 比例(%) | M6: 訂單數 | N6: 比例(%) | O6: 訂單數 | P6: 比例(%) | Q6: 訂單數 | R6: 比例(%) | S6: 訂單數 | T6: 比例(%) | U6: 訂單數 | V6: 比例(%) | W6: 訂單數 | X6: 比例(%) | Y6: 訂單數 | Z6: 比例(%) | AA6: 訂單數 | AB6: 比例(%) | AC6: 訂單數 | AD6: 比例(%) | AE6: 訂單數 | AF6: 比例(%) | AG6: 訂單數 | AH6: 比例(%) | AI6: 訂單數 | AJ6: 比例(%) | AK6: 訂單數 | AL6: 比例(%)
D7: 45958 | E7: 二 | F7: =SUM(M7,S7,U7,W7,AC7,AE7,AG7,AI7,AK7) -> 271475 | G7: =SUM(F7:F13) -> 1631463 | I7: 39611 | J7: =I7/F7 -> 0.1459103 | K7: 48686 | L7: =K7/F7 -> 0.1793388 | M7: =SUM(I7+K7) -> 88297 | N7: =M7/F7 -> 0.3252491 | O7: 13319 | P7: =O7/F7 -> 0.049061608 | Q7: 3833 | R7: =Q7/D7 -> 0.083402237 | S7: =SUM(O7+Q7) -> 17152 | T7: =S7/F7 -> 0.063180772 | U7: 19724 | V7: =U7/F7 -> 0.072654941 | W7: 10654 | X7: =W7/F7 -> 0.039244866 | Y7: 25133 | Z7: =Y7/F7 -> 0.092579427 | AA7: 29209 | AB7: =AA7/D7 -> 0.63555855 | AC7: =SUM(Y7+AA7) -> 54342 | AD7: =AC7/F7 -> 0.20017313 | AE7: 23182 | AF7: =AE7/F7 -> 0.085392762 | AG7: 21121 | AH7: =AG7/F7 -> 0.077800902 | AI7: 12873 | AJ7: =AI7/F7 -> 0.047418731 | AK7: 24130 | AL7: =AK7/F7 -> 0.088884796
D8: 45959 | E8: 三 | F8: =SUM(M8,S8,U8,W8,AC8,AE8,AG8,AI8,AK8) -> 254507 | I8: 38040 | J8: =I8/F8 -> 0.14946544 | K8: 48933 | L8: =K8/F8 -> 0.19226583 | M8: =SUM(I8+K8) -> 86973 | N8: =M8/F8 -> 0.34173127 | O8: 13181 | P8: =O8/F8 -> 0.051790324 | Q8: 3880 | R8: =Q8/D8 -> 0.084423073 | S8: =SUM(O8+Q8) -> 17061 | T8: =S8/F8 -> 0.067035484 | U8: 19460 | V8: =U8/F8 -> 0.076461551 | W8: 7036 | X8: =W8/F8 -> 0.027645605 | Y8: 24276 | Z8: =Y8/F8 -> 0.09538441 | AA8: 26287 | AB8: =AA8/D8 -> 0.57196632 | AC8: =SUM(Y8+AA8) -> 50563 | AD8: =AC8/F8 -> 0.19867037 | AE8: 20957 | AF8: =AE8/F8 -> 0.082343511 | AG8: 18916 | AH8: =AG8/F8 -> 0.074324085 | AI8: 11229 | AJ8: =AI8/F8 -> 0.044120594 | AK8: 22312 | AL8: =AK8/F8 -> 0.08766753
D9: 45960 | E9: 四 | F9: =SUM(M9,S9,U9,W9,AC9,AE9,AG9,AI9,AK9) -> 234639 | I9: 34492 | J9: =I9/F9 -> 0.14700029 | K9: 43753 | L9: =K9/F9 -> 0.18646943 | M9: =SUM(I9+K9) -> 78245 | N9: =M9/F9 -> 0.33346971 | O9: 11424 | P9: =O9/F9 -> 0.048687558 | Q9: 3838 | R9: =Q9/D9 -> 0.083507398 | S9: =SUM(O9+Q9) -> 15262 | T9: =S9/F9 -> 0.0650446 | U9: 18215 | V9: =U9/F9 -> 0.077629891 | W9: 6482 | X9: =W9/F9 -> 0.027625416 | Y9: 23435 | Z9: =Y9/F9 -> 0.099876832 | AA9: 22410 | AB9: =AA9/D9 -> 0.48759791 | AC9: =SUM(Y9+AA9) -> 45845 | AD9: =AC9/F9 -> 0.19538525 | AE9: 19538 | AF9: =AE9/F9 -> 0.08326834 | AG9: 18659 | AH9: =AG9/F9 -> 0.07952216 | AI9: 10892 | AJ9: =AI9/F9 -> 0.046420246 | AK9: 21501 | AL9: =AK9/F9 -> 0.091634383
D10: 45961 | E10: 五 | F10: =SUM(M10,S10,U10,W10,AC10,AE10,AG10,AI10,AK10) -> 200739 | I10: 29694 | J10: =I10/F10 -> 0.14792342 | K10: 40162 | L10: =K10/F10 -> 0.20007074 | M10: =SUM(I10+K10) -> 69856 | N10: =M10/F10 -> 0.34799416 | O10: 9868 | P10: =O10/F10 -> 0.04915836 | Q10: 3220 | R10: =Q10/D10 -> 0.070059398 | S10: =SUM(O10+Q10) -> 13088 | T10: =S10/F10 -> 0.065199089 | U10: 14842 | V10: =U10/F10 -> 0.073936804 | W10: 3927 | X10: =W10/F10 -> 0.019562716 | Y10: 20835 | Z10: =Y10/F10 -> 0.10379149 | AA10: 19274 | AB10: =AA10/D10 -> 0.41935554 | AC10: =SUM(Y10+AA10) -> 40109 | AD10: =AC10/F10 -> 0.19980671 | AE10: 16017 | AF10: =AE10/F10 -> 0.079790175 | AG10: 14964 | AH10: =AG10/F10 -> 0.074544558 | AI10: 10827 | AJ10: =AI10/F10 -> 0.053935708 | AK10: 17109 | AL10: =AK10/F10 -> 0.085230075
D11: 45962 | E11: 六 | F11: =SUM(M11,S11,U11,W11,AC11,AE11,AG11,AI11,AK11) -> 199982 | H11: =SUM(F11:F40) -> 2204262 | I11: 28452 | J11: =I11/F11 -> 0.1422728 | K11: 40897 | L11: =K11/F11 -> 0.20450341 | M11: =SUM(I11+K11) -> 69349 | N11: =M11/F11 -> 0.34677621 | O11: 8441 | P11: =O11/F11 -> 0.042208799 | Q11: 3019 | R11: =Q11/D11 -> 0.065684696 | S11: =SUM(O11+Q11) -> 11460 | T11: =S11/F11 -> 0.057305157 | U11: 14533 | V11: =U11/F11 -> 0.07267154 | W11: 3967 | X11: =W11/F11 -> 0.019836785 | Y11: 20037 | Z11: =Y11/F11 -> 0.10019402 | AA11: 20083 | AB11: =AA11/D11 -> 0.43694791 | AC11: =SUM(Y11+AA11) -> 40120 | AD11: =AC11/F11 -> 0.20061806 | AE11: 16927 | AF11: =AE11/F11 -> 0.084642618 | AG11: 15181 | AH11: =AG11/F11 -> 0.075911832 | AI11: 10780 | AJ11: =AI11/F11 -> 0.053904851 | AK11: 17665 | AL11: =AK11/F11 -> 0.08833295
D12: 45963 | E12: 日 | F12: =SUM(M12,S12,U12,W12,AC12,AE12,AG12,AI12,AK12) -> 239410 | I12: 37061 | J12: =I12/F12 -> 0.15480139 | K12: 44045 | L12: =K12/F12 -> 0.1839731 | M12: =SUM(I12+K12) -> 81106 | N12: =M12/F12 -> 0.33877449 | O12: 10789 | P12: =O12/F12 -> 0.045064951 | Q12: 3520 | R12: =Q12/D12 -> 0.076583339 | S12: =SUM(O12+Q12) -> 14309 | T12: =S12/F12 -> 0.059767762 | U12: 18035 | V12: =U12/F12 -> 0.075331022 | W12: 7001 | X12: =W12/F12 -> 0.029242722 | Y12: 23595 | Z12: =Y12/F12 -> 0.098554781 | AA12: 22513 | AB12: =AA12/D12 -> 0.48980702 | AC12: =SUM(Y12+AA12) -> 46108 | AD12: =AC12/F12 -> 0.19259012 | AE12: 21075 | AF12: =AE12/F12 -> 0.088028904 | AG12: 18470 | AH12: =AG12/F12 -> 0.077147989 | AI12: 11644 | AJ12: =AI12/F12 -> 0.048636231 | AK12: 21662 | AL12: =AK12/F12 -> 0.090480765
D13: 45964 | E13: 一 | F13: =SUM(M13,S13,U13,W13,AC13,AE13,AG13,AI13,AK13) -> 230711 | I13: 35896 | J13: =I13/F13 -> 0.15558859 | K13: 43695 | L13: =K13/F13 -> 0.18939279 | M13: =SUM(I13+K13) -> 79591 | N13: =M13/F13 -> 0.34498138 | O13: 10101 | P13: =O13/F13 -> 0.043782048 | Q13: 3584 | R13: =Q13/D13 -> 0.077974067 | S13: =SUM(O13+Q13) -> 13685 | T13: =S13/F13 -> 0.059316634 | U13: 18247 | V13: =U13/F13 -> 0.07909029 | W13: 4979 | X13: =W13/F13 -> 0.021581112 | Y13: 19668 | Z13: =Y13/F13 -> 0.085249511 | AA13: 22749 | AB13: =AA13/D13 -> 0.49493082 | AC13: =SUM(Y13+AA13) -> 42417 | AD13: =AC13/F13 -> 0.18385339 | AE13: 20424 | AF13: =AE13/F13 -> 0.088526338 | AG13: 18428 | AH13: =AG13/F13 -> 0.079874822 | AI13: 11571 | AJ13: =AI13/F13 -> 0.050153655 | AK13: 21369 | AL13: =AK13/F13 -> 0.092622372
D14: 45965 | E14: 二 | F14: =SUM(M14,S14,U14,W14,AC14,AE14,AG14,AI14,AK14) -> 226615 | G14: =SUM(F14:F20) -> 1534159 | I14: 34133 | J14: =I14/F14 -> 0.1506211 | K14: 42907 | L14: =K14/F14 -> 0.18933875 | M14: =SUM(I14+K14) -> 77040 | N14: =M14/F14 -> 0.33995984 | O14: 9896 | P14: =O14/F14 -> 0.043668777 | Q14: 3549 | R14: =Q14/D14 -> 0.077210921 | S14: =SUM(O14+Q14) -> 13445 | T14: =S14/F14 -> 0.0593297 | U14: 18133 | V14: =U14/F14 -> 0.080016769 | W14: 4554 | X14: =W14/F14 -> 0.020095757 | Y14: 21740 | Z14: =Y14/F14 -> 0.095933632 | AA14: 22476 | AB14: =AA14/D14 -> 0.48898075 | AC14: =SUM(Y14+AA14) -> 44216 | AD14: =AC14/F14 -> 0.19511506 | AE14: 20219 | AF14: =AE14/F14 -> 0.089221808 | AG14: 17728 | AH14: =AG14/F14 -> 0.078229596 | AI14: 11185 | AJ14: =AI14/F14 -> 0.049356839 | AK14: 20095 | AL14: =AK14/F14 -> 0.088674624
