Workbook

Sheet 填寫舉例
A2: 7 | B2: 月別 | C2: 工廠名 | D2: ・・・・・・・・
A4: （１）收支狀況 | E4: ※單位：千元 | G4: （２）ＫＰＩ達成進度 | M4: （３）業績構成比 | S4: （４）訂單數量構成比
B5: 當月 | C5: 前月 | D5: 差異 | E5: 累計 | H5: KPI | I5: 當月 | J5: 前月 | K5: 累計 | L5: ※補充 | N5: 當月 | O5: 比例 | P5: 前月 | Q5: 差異 | T5: 當月 | U5: 比例 | V5: 前月 | W5: 差異
A6: 業績金額 | B6: 500000 | C6: 510000 | D6: =B6-C6 -> -10000 | E6: =B6+C6 -> 1010000 | G6: 人時生產性1 | H6: 110 | I6: 100 | J6: 90 | L6: 個／MH | M6: 飯糰 | N6: 150000 | O6: =IFERROR(N6/$B$6,"") -> 0.3 | P6: 0.4 | Q6: =IFERROR(O6-P6,"") -> -0.1 | S6: 飯糰 | T6: 35000 | U6: =IFERROR(T6/$B$7,"") -> 0.35 | V6: 0.3 | W6: =IFERROR(U6-V6,"") -> 0.05
A7: 訂單數量 | B7: 100000 | C7: 110000 | D7: =B7-C7 -> -10000 | E7: =B7+C7 -> 210000 | G7: 人時生產性2 | H7: 0.8 | I7: 0.85 | J7: 0.81 | K7: 0.84 | L7: 達成率 | M7: 大口飯糰 | N7: 100000 | O7: =IFERROR(N7/$B$6,"") -> 0.2 | P7: 0.15 | Q7: =IFERROR(O7-P7,"") -> 0.05 | S7: 大口飯糰 | T7: 30000 | U7: =IFERROR(T7/$B$7,"") -> 0.3 | V7: 0.15 | W7: =IFERROR(U7-V7,"") -> 0.15
A8: 材料費 | B8: 250000 | C8: 260000 | D8: =B8-C8 -> -10000 | E8: =B8+C8 -> 510000 | G8: 半成品報廢 | H8: 0.0025 | I8: 0.0024 | J8: 0.0023 | K8: 0.00235 | L8: 報廢率 | M8: 便當 | N8: 160000 | O8: =IFERROR(N8/$B$6,"") -> 0.32 | P8: 0.28 | Q8: =IFERROR(O8-P8,"") -> 0.04 | S8: 便當 | T8: 20000 | U8: =IFERROR(T8/$B$7,"") -> 0.2 | V8: 0.28 | W8: =IFERROR(U8-V8,"") -> -0.08
A9: 材料費率 | B9: =B8/B6 -> 0.5 | C9: =C8/C6 -> 0.50980392 | D9: =B9-C9 -> -0.0098039216 | E9: =(B9+C9)/2 -> 0.50490196 | G9: 半成品超用 | H9: 0.006 | I9: 0.009 | J9: 0.0095 | K9: 0.0092 | L9: 超用率 | M9: 調理麵 | N9: 90000 | O9: =IFERROR(N9/$B$6,"") -> 0.18 | P9: 0.17 | Q9: =IFERROR(O9-P9,"") -> 0.01 | S9: 調理麵 | T9: 15000 | U9: =IFERROR(T9/$B$7,"") -> 0.15 | V9: 0.27 | W9: =IFERROR(U9-V9,"") -> -0.12
A10: 勞務成本 | B10: 100000 | C10: 105000 | D10: =B10-C10 -> -5000 | E10: =B10+C10 -> 205000 | G10: 固定產線 | H10: 0.95 | I10: 0.9 | J10: 0.92 | K10: 0.91 | L10: 導入率 | M10: 調理麵包 | N10: - | O10: =IFERROR(N10/$B$6,"") | P10: -% | Q10: =IFERROR(O10-P10,"") | S10: 調理麵包 | T10: - | U10: =IFERROR(T10/$B$7,"") | V10: -% | W10: =IFERROR(U10-V10,"")
A11: 勞務費率 | B11: =B10/B6 -> 0.2 | C11: =C10/C6 -> 0.20588235 | D11: =B11-C11 -> -0.0058823529 | E11: =(B11+C11)/2 -> 0.20294118 | G11: 教育訓練 | H11: 0.8 | I11: 0.85 | J11: 1 | K11: 0.92 | L11: 實施率 | M11: 袋裝調理麵包 | N11: - | O11: =IFERROR(N11/$B$6,"") | P11: -% | Q11: =IFERROR(O11-P11,"") | S11: 袋裝調理麵包 | T11: - | U11: =IFERROR(T11/$B$7,"") | V11: -% | W11: =IFERROR(U11-V11,"")
M12: 義大利麵 | N12: - | O12: =IFERROR(N12/$B$6,"") | P12: -% | Q12: =IFERROR(O12-P12,"") | S12: 義大利麵 | T12: - | U12: =IFERROR(T12/$B$7,"") | V12: -% | W12: =IFERROR(U12-V12,"")
A13: （５）品群別人時生產性 | M13: 調理包 | N13: - | O13: =IFERROR(N13/$B$6,"") | P13: -% | Q13: =IFERROR(O13-P13,"") | S13: 調理包 | T13: - | U13: =IFERROR(T13/$B$7,"") | V13: -% | W13: =IFERROR(U13-V13,"")
B14: 當月 | C14: 前月 | D14: 差異 | E14: 累計 | H14: 當月 | I14: 前月 | J14: 差異 | K14: 累計 | O14: =SUM(O6:O13) -> 1 | P14: =SUM(P6:P13) -> 1 | U14: =SUM(U6:U13) -> 1 | V14: =SUM(V6:V13) -> 1
A15: 飯糰 | B15: 600 | C15: 660 | D15: =B15-C15 -> -60 | E15: =(B15+C15)/2 -> 630 | G15: 調理麵包 | J15: =H15-I15 -> 0 | M15: （７）原因別分析
A16: 大口飯糰 | B16: 800 | C16: 780 | D16: =B16-C16 -> 20 | E16: =(B16+C16)/2 -> 790 | G16: 袋裝調理麵包 | J16: =H16-I16 -> 0 | N16: 合計 | P16: 作業原因 | R16: 規格原因
A17: 便當 | B17: 130 | C17: 111 | D17: =B17-C17 -> 19 | E17: =(B17+C17)/2 -> 120.5 | G17: 義大利麵 | J17: =H17-I17 -> 0 | N17: 金額 | O17: 比例 | P17: 金額 | Q17: 比例 | R17: 金額 | S17: 比例
A18: 調理麵 | B18: 140 | C18: 165 | D18: =B18-C18 -> -25 | E18: =(B18+C18)/2 -> 152.5 | G18: 調理包 | J18: =H18-I18 -> 0 | M18: 半成品報廢 | N18: 1200 | O18: =N18/$B$6 -> 0.0024 | P18: 900 | Q18: =IFERROR(P18/$B$6,"") -> 0.0018 | R18: 300 | S18: =IFERROR(R18/$B$6,"") -> 0.0006
M19: 半成品超用 | N19: 4500 | O19: =N19/$B$6 -> 0.009 | P19: 3500 | Q19: =IFERROR(P19/$B$6,"") -> 0.007 | R19: 1000 | S19: =IFERROR(R19/$B$6,"") -> 0.002
A20: （６）人時生產性前幾名品項
B21: 排名 | C21: 商品名 | F21: 人數 | G21: 產能 | H21: 人時生產性 | I21: 前月比 | J21: 主要原因&對策 | M21: （８）報廢原因別前幾名品項
A22: 飯糰 | B22: 1 | C22: 手巻明太子 | F22: 3 | G22: 3000 | H22: 1000 | I22: 10 | J22: 減少暫時停止生產,人時UP | M22: 半成品報廢 | N22: 排名 | O22: 商品名 | R22: 半成品名 | U22: 單價 | V22: 報廢率 | W22: 數量 | X22: 金額 | Y22: 前月比 | Z22: 主要原因&對策
B23: 2 | M23: 作業原因 | N23: 1 | O23: 明太子海苔便當 | R23: 油炸白身魚 | U23: 10 | V23: 0.15 | W23: 10 | X23: =W23*U23 -> 100 | Y23: 80 | Z23: 油調過多報廢。變更條件。
B24: 3 | N24: 2 | X24: =W24*U24 -> 0
B25: 4 | N25: 3 | X25: =W25*U25 -> 0
B26: 5 | N26: 4 | X26: =W26*U26 -> 0
B27: ▼1 | C27: 手巻卵黄雞絞肉 | F27: 4 | G27: 2800 | H27: 700 | I27: 6/30新商品 | J27: 因組裝2食材,人員增加,產速減少 | N27: 5 | X27: =W27*U27 -> 0
B28: ▼2 | U28: 前幾名合計比例 | V28: =X28/N18 -> 0.083333333 | W28: 前幾名合計金額 | X28: =SUM(X23:X27) -> 100
B29: ▼3 | M29: 規格原因 | N29: 1 | O29: 海老炒飯 | R29: 川燙蝦子拌醬 | U29: 5.55 | V29: 0.21 | W29: 50 | X29: =W29*U29 -> 277.5 | Y29: 35 | Z29: 蝦子入數不足
B30: ▼4 | N30: 2 | X30: =W30*U30 -> 0
B31: ▼5 | N31: 3 | X31: =W31*U31 -> 0
N32: 4 | X32: =W32*U32 -> 0
B33: 排名 | C33: 商品名 | F33: 人數 | G33: 產能 | H33: 人時生產性 | I33: 前月比 | J33: 主要原因&對策 | N33: 5 | X33: =W33*U33 -> 0
A34: 大口飯糰 | B34: 1 | C34: 直巻明太子美奶茲 | F34: 3 | G34: 2500 | H34: 833.33 | I34: 20 | J34: 透由調整速度提升。 | U34: 前幾名合計比例 | V34: =X34/N18 -> 0.23125 | W34: 前幾名合計金額 | X34: =SUM(X29:X33) -> 277.5
B35: 2
B36: 3 | M36: 半成品超用 | N36: 排名 | O36: 商品名 | R36: 半成品名 | U36: 單價 | V36: 報廢率 | W36: 數量 | X36: 金額 | Y36: 前月比 | Z36: 主要原因&對策
B37: 4 | M37: 作業原因 | N37: 1 | O37: 特製醬汁炙燒牛五花便當 | R37: 牛五花醬汁 | U37: 25 | V37: 0.25 | W37: 10 | X37: =W37*U37 -> 250 | Y37: 150 | Z37: 難度有差異。調理指導。
B38: 5 | N38: 2 | X38: =W38*U38 -> 0
B39: ▼1 | C39: 大口飯糰燒肉美奶滋 | F39: 7 | G39: 2200 | H39: 314.29 | I39: -15 | J39: 因摺疊增員。實施教育訓練。 | N39: 3 | X39: =W39*U39 -> 0
B40: ▼2 | N40: 4 | X40: =W40*U40 -> 0
B41: ▼3 | N41: 5 | X41: =W41*U41 -> 0
B42: ▼4 | U42: 前幾名合計比例 | V42: =X42/N19 -> 0.055555556 | W42: 前幾名合計金額 | X42: =SUM(X37:X41) -> 250
...

Sheet 生產管理報表(月)
A1: 生產管理報表
A3: 月別 | B3: 9 | C3: 工廠 | D3: 晉欣廠
A4: （１）收支狀況 | E4: ※單位：千元 | G4: （２）ＫＰＩ達成進度
A5: 項目 | B5: 當月 | C5: 前月 | D5: 差異 | E5: 累計 | G5: 項目 | H5: KPI | I5: 當月 | J5: 前月 | K5: 累計 | L5: ※補充
A6: 業績金額 | B6: ='（１）收支狀況'!H5/1000 -> 105939.26 | C6: 212376.15 | D6: =B6-C6 -> -106436.89 | E6: =B6 -> 105939.26 | G6: 人時性(個/月均) | H6: 266 | I6: ='（２）ＫＰＩ達成進度'!H5 -> 335.43289 | J6: 331.32088 | K6: =I6 -> 335.43289 | L6: 個／MH
A7: 訂單數量 | B7: ='（４）訂單數量構成比'!H7 -> 3326414 | C7: 6558055 | D7: =B7-C7 -> -3231641 | E7: =B7 -> 3326414 | G7: 人時達成率(%/月均) | H7: 0.8 | I7: ='（２）ＫＰＩ達成進度'!K5 -> 0.9164833 | J7: 0.90524832 | K7: =I7 -> 0.9164833 | L7: 達成率
A8: 材料費 | B8: ='（１）收支狀況'!N5/1000 -> 70366.504 | C8: 139088.16 | D8: =B8-C8 -> -68721.659 | E8: =B8 -> 70366.504 | G8: 半成品-報廢(%) | H8: 0.0025 | I8: ='（２）ＫＰＩ達成進度'!N5 -> 0.0024784031 | J8: 0.0024946244 | K8: =I8 -> 0.0024784031 | L8: 報廢率
A9: 材料費率 | B9: ='（１）收支狀況'!Q5 -> 0.66421554 | C9: 0.65491423 | D9: =B9-C9 -> 0.0093013077 | E9: =B9 -> 0.66421554 | G9: 半成品-超用(%) | H9: 0.0026 | I9: ='（２）ＫＰＩ達成進度'!Q5 -> 0.0026021344 | J9: 0.0023789152 | K9: =I9 -> 0.0026021344 | L9: 超用率
A10: 勞務成本 | B10: ='（１）收支狀況'!T5/1000 -> 14484.047 | C10: 30146.177 | D10: =B10-C10 -> -15662.13 | E10: =B10 -> 14484.047 | G10: 固定產線-導入率(%) | H10: 0.8 | I10: ='（２）ＫＰＩ達成進度'!T5 -> 0.91666667 | J10: 0.91666667 | K10: =I10 -> 0.91666667 | L10: 導入率
A11: 勞務費率 | B11: ='（１）收支狀況'!W5 -> 0.13672029 | C11: 0.14194709 | D11: =B11-C11 -> -0.0052267981 | E11: =B11 -> 0.13672029 | G11: 教育訓練-實施率(%) | H11: 1 | I11: ='（２）ＫＰＩ達成進度'!W5 -> 0.74253333 | J11: 0.67912903 | K11: =I11 -> 0.74253333 | L11: 實施率
A13: （３）業績構成比 | G13: （４）訂單數量構成比
B14: 當月 | C14: 比例 | D14: 前月 | E14: 差異 | H14: 當月 | I14: 比例 | J14: 前月 | K14: 差異
A15: 18℃-飯A15:A23糰(061,063) | B15: ='（３）業績構成比'!M46/1000 -> 24381.955 | C15: =IFERROR(B15/$B$6,"") -> 0.23015032 | D15: 0.19048549 | E15: =IFERROR(C15-D15,"") -> 0.039664825 | G15: 18℃-飯A15:A23糰(061,063) | H15: ='（４）訂單數量構成比'!M46 -> 1256001 | I15: =IFERROR(H15/$B$7,"") -> 0.37758409 | J15: 0.33193454 | K15: =IFERROR(I15-J15,"") -> 0.045649544
A16: 18℃-壽司手卷(071,072,075,076) | B16: ='（３）業績構成比'!S46/1000 -> 3773.1786 | C16: =IFERROR(B16/$B$6,"") -> 0.035616433 | D16: 0.04002075 | E16: =IFERROR(C16-D16,"") -> -0.0044043176 | G16: 18℃-壽司手卷(071,072,075,076) | H16: ='（４）訂單數量構成比'!S47 -> 143766 | I16: =IFERROR(H16/$B$7,"") -> 0.043219515 | J16: 0.050408543 | K16: =IFERROR(I16-J16,"") -> -0.0071890283
A17: 4℃-飯糰(065) | B17: ='（３）業績構成比'!U46/1000 -> 9157.8177 | C17: =IFERROR(B17/$B$6,"") -> 0.086444039 | D17: 0.098025494 | E17: =IFERROR(C17-D17,"") -> -0.011581455 | G17: 4℃-飯糰(065) | H17: ='（４）訂單數量構成比'!U46 -> 275702 | I17: =IFERROR(H17/$B$7,"") -> 0.082882648 | J17: 0.09754935 | K17: =IFERROR(I17-J17,"") -> -0.014666702
A18: 4℃-壽司手卷(077) | B18: ='（３）業績構成比'!W46/1000 -> 178.54856 | C18: =IFERROR(B18/$B$6,"") -> 0.0016853861 | D18: 0.0023157871 | E18: =IFERROR(C18-D18,"") -> -0.00063040102 | G18: 4℃-壽司手卷(077) | H18: ='（４）訂單數量構成比'!W46 -> 6732 | I18: =IFERROR(H18/$B$7,"") -> 0.002023801 | J18: 0.0027738407 | K18: =IFERROR(I18-J18,"") -> -0.00075003971
A19: 主食(091,092,093,094,095) | B19: ='（３）業績構成比'!AC46/1000 -> 26279.241 | C19: =IFERROR(B19/$B$6,"") -> 0.24805951 | D19: 0.26645165 | E19: =IFERROR(C19-D19,"") -> -0.018392144 | G19: 主食(091,092,093,094,095) | H19: ='（４）訂單數量構成比'!AC46 -> 647461 | I19: =IFERROR(H19/$B$7,"") -> 0.19464234 | J19: 0.20966064 | K19: =IFERROR(I19-J19,"") -> -0.0150183
A20: 便當(083) | B20: ='（３）業績構成比'!AE46/1000 -> 11097.284 | C20: =IFERROR(B20/$B$6,"") -> 0.10475138 | D20: 0.11880395 | E20: =IFERROR(C20-D20,"") -> -0.014052566 | G20: 便當(083) | H20: ='（４）訂單數量構成比'!AE46 -> 202259 | I20: =IFERROR(H20/$B$7,"") -> 0.060803917 | J20: 0.069473342 | K20: =IFERROR(I20-J20,"") -> -0.0086694256
A21: 熱食義麵(122,123,124,126) | B21: ='（３）業績構成比'!AG46/1000 -> 16124.897 | C21: =IFERROR(B21/$B$6,"") -> 0.15220889 | D21: 0.13107603 | E21: =IFERROR(C21-D21,"") -> 0.021132858 | G21: 熱食義麵(122,123,124,126) | H21: ='（４）訂單數量構成比'!AG46 -> 328032 | I21: =IFERROR(H21/$B$7,"") -> 0.098614304 | J21: 0.087948485 | K21: =IFERROR(I21-J21,"") -> 0.010665819
A22: 季節調理麵(111,112) | B22: ='（３）業績構成比'!AI46/1000 -> 8914.3269 | C22: =IFERROR(B22/$B$6,"") -> 0.084145639 | D22: 0.091535408 | E22: =IFERROR(C22-D22,"") -> -0.0073897691 | G22: 季節調理麵(111,112) | H22: ='（４）訂單數量構成比'!AI46 -> 242894 | I22: =IFERROR(H22/$B$7,"") -> 0.073019774 | J22: 0.079981641 | K22: =IFERROR(I22-J22,"") -> -0.0069618665
A23: 微波小吃(153,154,155) | B23: ='（３）業績構成比'!AK46/1000 -> 6032.0126 | C23: =IFERROR(B23/$B$6,"") -> 0.056938405 | D23: 0.061285436 | E23: =IFERROR(C23-D23,"") -> -0.0043470313 | G23: 微波小吃(153,154,155) | H23: ='（４）訂單數量構成比'!AK46 -> 223567 | I23: =IFERROR(H23/$B$7,"") -> 0.067209614 | J23: 0.070269615 | K23: =IFERROR(I23-J23,"") -> -0.0030600013
C24: =SUM(C15:C23) -> 1 | D24: =SUM(D15:D23) -> 1 | I24: =SUM(I15:I23) -> 1 | J24: =SUM(J15:J23) -> 1
A26: （５）品群別人時生產性
A27: 品群 | B27: 當月 | C27: 前月 | D27: 差異 | E27: 累計 | M27: 8月 | N27: 9月 | O27: 10月 | P27: 11月 | Q27: 12月
A28: 18℃-飯A15:A23糰(061,063) | B28: ='（５-1）品群別人時生產性（18℃-飯糰）'!$C$1 -> 715.75052 | C28: 717.52753 | D28: =B28-C28 -> -1.7770121 | E28: =R28 -> 716.63903 | M28: 717.52753 | N28: =B28 -> 715.75052 | R28: =AVERAGE(M28:Q28) -> 716.63903
A29: 18℃-壽司手卷(071,072,075,076) | B29: ='（５-2）品群別人時生產性（18-壽司手卷)'!$C$1 -> 200.71732 | C29: 197.63272 | D29: =B29-C29 -> 3.0846026 | E29: =R29 -> 199.17502 | M29: 197.63272 | N29: =B29 -> 200.71732 | R29: =AVERAGE(M29:Q29) -> 199.17502
A30: 4℃-飯糰(065) | B30: ='（５-3）品群別人時生產性（4℃-飯糰)'!$C$1 -> 251.93838 | C30: 240.45857 | D30: =B30-C30 -> 11.479813 | E30: =R30 -> 246.19848 | M30: 240.45857 | N30: =B30 -> 251.93838 | R30: =AVERAGE(M30:Q30) -> 246.19848
A31: 4℃-壽司手卷(077) | B31: ='（５-4）品群別人時生產性（4℃-壽司手卷)'!$C$1 -> 109.06374 | C31: 106.86512 | D31: =B31-C31 -> 2.1986134 | E31: =R31 -> 107.96443 | M31: 106.86512 | N31: =B31 -> 109.06374 | R31: =AVERAGE(M31:Q31) -> 107.96443
A32: 主食(091,092,093,094,095) | B32: ='（５-5）品群別人時生產性(主食) '!$C$1 -> 91.961257 | C32: 89.310428 | D32: =B32-C32 -> 2.6508287 | E32: =R32 -> 90.635843 | M32: 89.310428 | N32: =B32 -> 91.961257 | R32: =AVERAGE(M32:Q32) -> 90.635843
A33: 便當(083) | B33: ='（５-6）品群別人時生產性(便當)'!$C$1 -> 66.929844 | C33: 65.672742 | D33: =B33-C33 -> 1.2571018 | E33: =R33 -> 66.301293 | M33: 65.672742 | N33: =B33 -> 66.929844 | R33: =AVERAGE(M33:Q33) -> 66.301293
A34: 熱食義麵(122,123,124,126) | B34: ='（５-7）品群別人時生產性(熱食義麵) '!$C$1 -> 87.393165 | C34: 75.478569 | D34: =B34-C34 -> 11.914596 | E34: =R34 -> 81.435867 | M34: 75.478569 | N34: =B34 -> 87.393165 | R34: =AVERAGE(M34:Q34) -> 81.435867
A35: 季節調理麵(111,112) | B35: ='（５-8）品群別人時生產性(季節調理麵) '!$C$1 -> 117.40789 | C35: 114.50557 | D35: =B35-C35 -> 2.9023154 | E35: =R35 -> 115.95673 | M35: 114.50557 | N35: =B35 -> 117.40789 | R35: =AVERAGE(M35:Q35) -> 115.95673
A36: 微波小吃(153,154,155) | B36: ='（５-9）品群別人時生產性(微波小吃)'!$C$1 -> 112.09351 | C36: 99.648342 | D36: =B36-C36 -> 12.44517 | E36: =R36 -> 105.87093 | M36: 99.648342 | N36: =B36 -> 112.09351 | R36: =AVERAGE(M36:Q36) -> 105.87093

Sheet 生產管理報表(週) 
A1: 生產管理報表
A3: 月別 | B3: 9 | C3: 週別 | D3: W2 | E3: 工廠 | F3: 晉欣廠
A4: （１）收支狀況 | E4: ※單位：千元 | G4: （２）ＫＰＩ達成進度
A5: 項目 | B5: 當週 | C5: 前週 | D5: 差異 | E5: 累計 | G5: 項目 | H5: KPI | I5: 當週 | J5: 前週 | K5: 累計 | L5: ※補充
A6: 業績金額 | B6: ='（１）收支狀況'!G13/1000 -> 50470.102 | C6: 48362.935 | D6: =B6-C6 -> 2107.167 | E6: ='（１）收支狀況'!H5/1000 -> 105939.26 | G6: 人時性(個/月均) | H6: 266 | I6: ='（２）ＫＰＩ達成進度'!G13 -> 335.39905 | J6: 335.12857 | K6: ='（２）ＫＰＩ達成進度'!H5 -> 335.43289 | L6: 個／MH
A7: 訂單數量 | B7: ='（１）收支狀況'!J13 -> 1578863 | C7: 1525242 | D7: =B7-C7 -> 53621 | E7: ='（１）收支狀況'!K5 -> 3326414 | G7: 人時達成率(%/月均) | H7: 0.8 | I7: ='（２）ＫＰＩ達成進度'!J13 -> 0.91639084 | J7: 0.91565183 | K7: ='（２）ＫＰＩ達成進度'!K5 -> 0.9164833 | L7: 達成率
A8: 材料費 | B8: ='（１）收支狀況'!M13/1000 -> 33568.313 | C8: 32188.662 | D8: =B8-C8 -> 1379.651 | E8: ='（１）收支狀況'!N5/1000 -> 70366.504 | G8: 半成品-報廢(%) | H8: 0.0025 | I8: ='（２）ＫＰＩ達成進度'!M13 -> 0.0024800025 | J8: 0.0024809019 | K8: ='（２）ＫＰＩ達成進度'!N5 -> 0.0024784031 | L8: 報廢率
A9: 材料費率 | B9: ='（１）收支狀況'!P13 -> 0.66511284 | C9: 0.66556469 | D9: =B9-C9 -> -0.00045185084 | E9: ='（１）收支狀況'!Q5 -> 0.66421554 | G9: 半成品-超用(%) | H9: 0.0026 | I9: ='（２）ＫＰＩ達成進度'!P13 -> 0.0025266112 | J9: 0.0027407836 | K9: ='（２）ＫＰＩ達成進度'!Q5 -> 0.0026021344 | L9: 超用率
A10: 勞務成本 | B10: ='（１）收支狀況'!S13/1000 -> 6793.9917 | C10: 6652.0226 | D10: =B10-C10 -> 141.96919 | E10: ='（１）收支狀況'!T5/1000 -> 14484.047 | G10: 固定產線-導入率(%) | H10: 0.8 | I10: 0.917 | J10: 0.917 | K10: 0.917 | L10: 導入率
A11: 勞務費率 | B11: ='（１）收支狀況'!V13 -> 0.13461419 | C11: 0.13754381 | D11: =B11-C11 -> -0.0029296274 | E11: ='（１）收支狀況'!W5 -> 0.13672029 | G11: 教育訓練-實施率(%) | H11: 1 | I11: ='（２）ＫＰＩ達成進度'!V13 -> 0.75442857 | J11: 0.73357143 | K11: ='（２）ＫＰＩ達成進度'!W5 -> 0.74253333 | L11: 實施率
A13: （３）業績構成比 | G13: （４）訂單數量構成比
B14: 當週 | C14: 比例 | D14: 前週 | E14: 差異 | H14: 當週 | I14: 比例 | J14: 前週 | K14: 差異
A15: 18℃-飯糰(061,063) | B15: =SUM('（３）業績構成比'!I15:I21,'（３）業績構成比'!K15:K21)/1000 -> 11625.107 | C15: =IFERROR(B15/$B$6,"") -> 0.23033651 | D15: 0.23463288 | E15: =IFERROR(C15-D15,"") -> -0.0042963686 | G15: 18℃-飯糰(061,063) | H15: =SUM(,'（４）訂單數量構成比'!I15:I21,'（４）訂單數量構成比'!K15:K21) -> 595580 | I15: =IFERROR(H15/$B$7,"") -> 0.37722082 | J15: 0.38257339 | K15: =IFERROR(I15-J15,"") -> -0.0053525655
A16: 18℃-壽司手卷(071,072,075,076) | B16: =SUM('（３）業績構成比'!O15:O21,'（３）業績構成比'!Q15:Q21)/1000 -> 1660.858 | C16: =IFERROR(B16/$B$6,"") -> 0.032907759 | D16: 0.037563947 | E16: =IFERROR(C16-D16,"") -> -0.0046561878 | G16: 18℃-壽司手卷(071,072,075,076) | H16: =SUM('（４）訂單數量構成比'!O15:O21,'（４）訂單數量構成比'!Q15:Q21) -> 63181 | I16: =IFERROR(H16/$B$7,"") -> 0.040016772 | J16: 0.045363293 | K16: =IFERROR(I16-J16,"") -> -0.0053465216
A17: 4℃-飯糰(065) | B17: =SUM('（３）業績構成比'!U15:U21)/1000 -> 4278.5418 | C17: =IFERROR(B17/$B$6,"") -> 0.08477379 | D17: 0.08714125 | E17: =IFERROR(C17-D17,"") -> -0.0023674599 | G17: 4℃-飯糰(065) | H17: =SUM('（４）訂單數量構成比'!U15:U21) -> 128755 | I17: =IFERROR(H17/$B$7,"") -> 0.081549191 | J17: 0.08321827 | K17: =IFERROR(I17-J17,"") -> -0.0016690788
A18: 4℃-壽司手卷(077) | B18: =SUM('（３）業績構成比'!W15:W21)/1000 -> 83.359841 | C18: =IFERROR(B18/$B$6,"") -> 0.0016516678 | D18: 0.0017380731 | E18: =IFERROR(C18-D18,"") -> -8.6405303e-05 | G18: 4℃-壽司手卷(077) | H18: =SUM('（４）訂單數量構成比'!W15:W21) -> 3141 | I18: =IFERROR(H18/$B$7,"") -> 0.0019894063 | J18: 0.0020790143 | K18: =IFERROR(I18-J18,"") -> -8.9608046e-05
A19: 主食(091,092,093,094,095) | B19: =SUM('（３）業績構成比'!Y15:Y21,'（３）業績構成比'!AA15:AA21)/1000 -> 12262.595 | C19: =IFERROR(B19/$B$6,"") -> 0.24296752 | D19: 0.24894814 | E19: =IFERROR(C19-D19,"") -> -0.0059806181 | G19: 主食(091,092,093,094,095) | H19: =SUM('（４）訂單數量構成比'!Y15:Y21,'（４）訂單數量構成比'!AA15:AA21) -> 304518 | I19: =IFERROR(H19/$B$7,"") -> 0.19287171 | J19: 0.19363485 | K19: =IFERROR(I19-J19,"") -> -0.00076314036
A20: 便當(083) | B20: =SUM('（３）業績構成比'!AE15:AE21)/1000 -> 5361.974 | C20: =IFERROR(B20/$B$6,"") -> 0.1062406 | D20: 0.10285315 | E20: =IFERROR(C20-D20,"") -> 0.0033874517 | G20: 便當(083) | H20: =SUM('（４）訂單數量構成比'!AE15:AE21) -> 97515 | I20: =IFERROR(H20/$B$7,"") -> 0.0617628 | J20: 0.059496132 | K20: =IFERROR(I20-J20,"") -> 0.0022666678
A21: 熱食義麵(122,123,124,126) | B21: =SUM('（３）業績構成比'!AG15:AG21)/1000 -> 8185.3202 | C21: =IFERROR(B21/$B$6,"") -> 0.16218157 | D21: 0.14585419 | E21: =IFERROR(C21-D21,"") -> 0.016327379 | G21: 熱食義麵(122,123,124,126) | H21: =SUM('（４）訂單數量構成比'!AG15:AG21) -> 166802 | I21: =IFERROR(H21/$B$7,"") -> 0.10564691 | J21: 0.093981152 | K21: =IFERROR(I21-J21,"") -> 0.01166576
A22: 季節調理麵(111,112) | B22: =SUM('（３）業績構成比'!AI15:AI21)/1000 -> 4335.4141 | C22: =IFERROR(B22/$B$6,"") -> 0.08590064 | D22: 0.082077871 | E22: =IFERROR(C22-D22,"") -> 0.0038227692 | G22: 季節調理麵(111,112) | H22: =SUM('（４）訂單數量構成比'!AI15:AI21) -> 118035 | I22: =IFERROR(H22/$B$7,"") -> 0.074759495 | J22: 0.070960543 | K22: =IFERROR(I22-J22,"") -> 0.003798952
A23: 微波小吃(153,154,155) | B23: =SUM('（３）業績構成比'!AK15:AK21)/1000 -> 2676.9312 | C23: =IFERROR(B23/$B$6,"") -> 0.053039941 | D23: 0.059190501 | E23: =IFERROR(C23-D23,"") -> -0.0061505607 | G23: 微波小吃(153,154,155) | H23: =SUM('（４）訂單數量構成比'!AK15:AK21) -> 101336 | I23: =IFERROR(H23/$B$7,"") -> 0.064182896 | J23: 0.068693361 | K23: =IFERROR(I23-J23,"") -> -0.0045104653
C24: =SUM(C15:C23) -> 1 | D24: =SUM(D15:D23) -> 1 | I24: =SUM(I15:I23) -> 1 | J24: =SUM(J15:J23) -> 1
A26: （５）品群別人時生產性
A27: 品群 | B27: 當週 | C27: 前週 | D27: 差異 | E27: 累計
A28: 18℃-飯糰(061,063) | B28: ='（５-1）品群別人時生產性（18℃-飯糰）'!L77 -> 719.25018 | C28: 714.86008 | D28: =B28-C28 -> 4.3900961 | E28: ='（５-1）品群別人時生產性（18℃-飯糰）'!C1 -> 715.75052
A29: 18℃-壽司手卷(071,072,075,076) | B29: ='（５-2）品群別人時生產性（18-壽司手卷)'!L47 -> 209.23229 | C29: 202.12384 | D29: =B29-C29 -> 7.1084488 | E29: ='（５-2）品群別人時生產性（18-壽司手卷)'!C1 -> 200.71732
A30: 4℃-飯糰(065) | B30: ='（５-3）品群別人時生產性（4℃-飯糰)'!L47 -> 247.44189 | C30: 259.1052 | D30: =B30-C30 -> -11.663309 | E30: ='（５-3）品群別人時生產性（4℃-飯糰)'!C1 -> 251.93838
A31: 4℃-壽司手卷(077) | B31: ='（５-4）品群別人時生產性（4℃-壽司手卷)'!L47 -> 119.14286 | C31: 105.24615 | D31: =B31-C31 -> 13.896703 | E31: ='（５-4）品群別人時生產性（4℃-壽司手卷)'!C1 -> 109.06374
A32: 主食(091,092,093,094,095) | B32: ='（５-5）品群別人時生產性(主食) '!L77 -> 91.678334 | C32: 91.8 | D32: =B32-C32 -> -0.12166592 | E32: ='（５-5）品群別人時生產性(主食) '!C1 -> 91.961257
A33: 便當(083) | B33: ='（５-6）品群別人時生產性(便當)'!L47 -> 68.062871 | C33: 68.168322 | D33: =B33-C33 -> -0.10545126 | E33: ='（５-6）品群別人時生產性(便當)'!C1 -> 66.929844
A34: 熱食義麵(122,123,124,126) | B34: ='（５-7）品群別人時生產性(熱食義麵) '!L47 -> 86.793498 | C34: 87.833649 | D34: =B34-C34 -> -1.0401509 | E34: ='（５-7）品群別人時生產性(熱食義麵) '!C1 -> 87.393165
A35: 季節調理麵(111,112) | B35: ='（５-8）品群別人時生產性(季節調理麵) '!L47 -> 117.87986 | C35: 117.39386 | D35: =B35-C35 -> 0.48600074 | E35: ='（５-8）品群別人時生產性(季節調理麵) '!C1 -> 117.40789
A36: 微波小吃(153,154,155) | B36: ='（５-9）品群別人時生產性(微波小吃)'!L47 -> 119.41587 | C36: 111.59972 | D36: =B36-C36 -> 7.8161565 | E36: ='（５-9）品群別人時生產性(微波小吃)'!C1 -> 112.09351
D37: =SUM(D28:D36) -> 20.766828

Sheet （１）收支狀況
B2: （１）收支狀況
C3: 月份 | D3: 日期 | F3: 營業額(元) | I3: 訂單數量(個) | L3: 材料費(元) | O3: 材料費率（材料費／營業額） | R3: 勞務成本（全廠人事成本） | U3: 勞務費率（勞務成本／營業額）
F4: 日 | G4: 週累積 | H4: 月累積 | I4: 日 | J4: 週累積 | K4: 月累積 | L4: 日 | M4: 週累積 | N4: 月累積 | O4: 日 | P4: 週累積 | Q4: 月平均 | R4: 日 | S4: 週累積 | T4: 月累積 | U4: 日 | V4: 週累積 | W4: 月平均
C5: 八 | D5: 45901 | E5: 一 | F5: 7106225 | G5: =SUM(F5) -> 7106225 | H5: =SUM(F5:F35) -> 105939262 | I5: 222309 | J5: =SUM(I5) -> 222309 | K5: =SUM(I5:I35) -> 3326414 | L5: 4609529 | M5: =SUM(L5) -> 4609529 | N5: =SUM(L5:L35) -> 70366504 | O5: =L5/F5 -> 0.64866072 | P5: =M5/G5 -> 0.64866072 | Q5: =N5/H5 -> 0.66421554 | R5: 1024189.2 | S5: =SUM(R5) -> 1024189.2 | T5: =SUM(R5:R35) -> 14484047 | U5: =R5/F5 -> 0.14412564 | V5: =S5/G5 -> 0.14412564 | W5: =T5/H5 -> 0.13672029
D6: 45902 | E6: 二 | F6: 7727458 | G6: =SUM(F6:F12) -> 48362935 | I6: 240560 | J6: =SUM(I6:I12) -> 1525242 | L6: 5103169 | M6: =SUM(L6:L12) -> 32188662 | O6: =L6/F6 -> 0.66039427 | P6: =M6/G6 -> 0.66556469 | R6: 989533.97 | S6: =SUM(R6:R12) -> 6665865.9 | U6: =R6/F6 -> 0.12805427 | V6: =S6/G6 -> 0.13783005
D7: 45903 | E7: 三 | F7: 7254649 | I7: 228856 | L7: 4720340 | O7: =L7/F7 -> 0.65066415 | R7: 938665.89 | U7: =R7/F7 -> 0.12938819
D8: 45904 | E8: 四 | F8: 6602059 | I8: 210018 | L8: 4415001 | O8: =L8/F8 -> 0.66873092 | R8: 919769.24 | U8: =R8/F8 -> 0.13931551
D9: 45905 | E9: 五 | F9: 5807177 | I9: 186157 | L9: 3985603 | O9: =L9/F9 -> 0.68632366 | R9: 905930.65 | U9: =R9/F9 -> 0.1560019
D10: 45906 | E10: 六 | F10: 6167669 | I10: 195008 | L10: 4414886 | O10: =L10/F10 -> 0.71581111 | R10: 930400.33 | U10: =R10/F10 -> 0.15085121
D11: 45907 | E11: 日 | F11: 7394780 | I11: 233163 | L11: 4702113 | O11: =L11/F11 -> 0.63586922 | R11: 984509.09 | U11: =R11/F11 -> 0.13313568
D12: 45908 | E12: 一 | F12: 7409143 | I12: 231480 | L12: 4847550 | O12: =L12/F12 -> 0.65426595 | R12: 997056.71 | U12: =R12/F12 -> 0.13457113
D13: 45909 | E13: 二 | F13: 7807316 | G13: =SUM(F13:F19) -> 50470102 | I13: 241607 | J13: =SUM(I13:I19) -> 1578863 | L13: 5235930 | M13: =SUM(L13:L19) -> 33568313 | O13: =L13/F13 -> 0.67064405 | P13: =M13/G13 -> 0.66511284 | R13: 1006709.7 | S13: =SUM(R13:R19) -> 6793991.7 | U13: =R13/F13 -> 0.1289444 | V13: =S13/G13 -> 0.13461419
D14: 45910 | E14: 三 | F14: 7436383 | I14: 233099 | L14: 5094455 | O14: =L14/F14 -> 0.68507163 | R14: 989558.91 | U14: =R14/F14 -> 0.13306992
D15: 45911 | E15: 四 | F15: 6919680 | I15: 217145 | L15: 4537974 | O15: =L15/F15 -> 0.65580692 | R15: 967553.37 | U15: =R15/F15 -> 0.13982632
D16: 45912 | E16: 五 | F16: 6171958 | I16: 194357 | L16: 4204918 | O16: =L16/F16 -> 0.68129401 | R16: 981357.16 | U16: =R16/F16 -> 0.15900257
D17: 45913 | E17: 六 | F17: 6541355 | I17: 204761 | L17: 4415445 | O17: =L17/F17 -> 0.67500464 | R17: 950165.87 | U17: =R17/F17 -> 0.14525521
D18: 45914 | E18: 日 | F18: 7771753 | I18: 242926 | L18: 4858553 | O18: =L18/F18 -> 0.62515535 | R18: 910192.4 | U18: =R18/F18 -> 0.11711546
D19: 45915 | E19: 一 | F19: 7821657 | I19: 244968 | L19: 5221038 | O19: =L19/F19 -> 0.66751048 | R19: 988454.37 | U19: =R19/F19 -> 0.12637404
D20: 45916 | E20: 二 | G20: =SUM(F20:F26) -> 0 | J20: =SUM(I20:I26) -> 0 | M20: =SUM(L20:L26) -> 0 | O20: =L20/F20 -> #DIV/0! | P20: =M20/G20 -> #DIV/0! | S20: =SUM(R20:R26) -> 0 | U20: =R20/F20 -> #DIV/0! | V20: =S20/G20 -> #DIV/0!
D21: 45917 | E21: 三 | O21: =L21/F21 -> #DIV/0! | U21: =R21/F21 -> #DIV/0!
D22: 45918 | E22: 四 | O22: =L22/F22 -> #DIV/0! | U22: =R22/F22 -> #DIV/0!
D23: 45919 | E23: 五 | O23: =L23/F23 -> #DIV/0! | U23: =R23/F23 -> #DIV/0!
D24: 45920 | E24: 六 | O24: =L24/F24 -> #DIV/0! | U24: =R24/F24 -> #DIV/0!
D25: 45921 | E25: 日 | O25: =L25/F25 -> #DIV/0! | U25: =R25/F25 -> #DIV/0!
D26: 45922 | E26: 一 | O26: =L26/F26 -> #DIV/0! | U26: =R26/F26 -> #DIV/0!
D27: 45923 | E27: 二 | G27: =SUM(F27:F33) -> 0 | J27: =SUM(I27:I33) -> 0 | M27: =SUM(L27:L33) -> 0 | O27: =L27/F27 -> #DIV/0! | P27: =M27/G27 -> #DIV/0! | S27: =SUM(R27:R33) -> 0 | U27: =R27/F27 -> #DIV/0! | V27: =S27/G27 -> #DIV/0!
D28: 45924 | E28: 三 | O28: =L28/F28 -> #DIV/0! | U28: =R28/F28 -> #DIV/0!
D29: 45925 | E29: 四 | O29: =L29/F29 -> #DIV/0! | U29: =R29/F29 -> #DIV/0!
D30: 45926 | E30: 五 | O30: =L30/F30 -> #DIV/0! | U30: =R30/F30 -> #DIV/0!
D31: 45927 | E31: 六 | O31: =L31/F31 -> #DIV/0! | U31: =R31/F31 -> #DIV/0!
D32: 45928 | E32: 日 | O32: =L32/F32 -> #DIV/0! | U32: =R32/F32 -> #DIV/0!
D33: 45929 | E33: 一 | O33: =L33/F33 -> #DIV/0! | U33: =R33/F33 -> #DIV/0!
D34: 45930 | E34: 二 | G34: =SUM(F34:F40) -> 0 | J34: =SUM(I34:I40) -> 0 | M34: =SUM(L34:L40) -> 0 | O34: =L34/F34 -> #DIV/0! | P34: =M34/G34 -> #DIV/0! | S34: =SUM(R34:R40) -> 0 | U34: =R34/F34 -> #DIV/0! | V34: =S34/G34 -> #DIV/0!
D35: 45931 | E35: 三 | O35: =L35/F35 -> #DIV/0! | U35: =R35/F35 -> #DIV/0!
D36: 45932 | E36: 四 | O36: =L36/F36 -> #DIV/0! | U36: =R36/F36 -> #DIV/0!
D37: 45933 | E37: 五 | O37: =L37/F37 -> #DIV/0! | U37: =R37/F37 -> #DIV/0!
D38: 45934 | E38: 六 | O38: =L38/F38 -> #DIV/0! | U38: =R38/F38 -> #DIV/0!
D39: 45935 | E39: 日 | O39: =L39/F39 -> #DIV/0! | U39: =R39/F39 -> #DIV/0!
D40: 45936 | E40: 一 | O40: =L40/F40 -> #DIV/0! | U40: =R40/F40 -> #DIV/0!
O41: =L41/F41 -> #DIV/0! | U41: =R41/F41 -> #DIV/0!
...

Sheet （２）ＫＰＩ達成進度
B1: KPI | C1: 366
B2: （２）ＫＰＩ達成進度
C3: 月份 | D3: 日期 | F3: 人時生產性(個/人) | I3: 人時生產性達成率(%) | L3: 半成品報廢(%) | O3: 半成品超用(%) | R3: 固定產線-導入率(固定產線數/總產線數) | U3: 教育訓練-實施率(進度/計畫)
F4: 日 | G4: 週平均 | H4: 月平均 | I4: 日 | J4: 週平均 | K4: 月平均 | L4: 日 | M4: 週平均 | N4: 月平均 | O4: 日 | P4: 週平均 | Q4: 月平均 | R4: 日 | S4: 週平均 | T4: 月平均 | U4: 日 | V4: 週平均 | W4: 月平均
C5: 八 | D5: 45901 | E5: 一 | F5: 337.8 | G5: =AVERAGE(F5) -> 337.8 | H5: =AVERAGE(F5:F99) -> 335.43289 | I5: =F5/$C$1 -> 0.92295082 | J5: =AVERAGE(I5) -> 0.92295082 | K5: =AVERAGE(I5:I99) -> 0.9164833 | L5: 0.0024497152 | M5: =AVERAGE(L5) -> 0.0024497152 | N5: =AVERAGE(L5:L99) -> 0.0024784031 | O5: 0.0021602518 | P5: =AVERAGE(O5) -> 0.0021602518 | Q5: =AVERAGE(O5:O99) -> 0.0026021344 | R5: 0.91666667 | S5: =AVERAGE(R5) -> 0.91666667 | T5: =AVERAGE(R5:R99) -> 0.91666667 | U5: 0.722 | V5: =AVERAGE(U5) -> 0.722 | W5: =AVERAGE(U5:U99) -> 0.74253333
D6: 45902 | E6: 二 | F6: 331.8 | G6: =AVERAGE(F6:F12) -> 335.12857 | I6: =F6/$C$1 -> 0.90655738 | J6: =AVERAGE(I6:I12) -> 0.91565183 | L6: 0.0025081702 | M6: =AVERAGE(L6:L12) -> 0.0024809019 | O6: 0.002987586 | P6: =AVERAGE(O6:O12) -> 0.0027407836 | R6: 0.91666667 | S6: =AVERAGE(R6:R12) -> 0.91666667 | U6: 0.723 | V6: =AVERAGE(U6:U12) -> 0.73357143
D7: 45903 | E7: 三 | F7: 331.8 | I7: =F7/$C$1 -> 0.90655738 | L7: 0.0024356035 | O7: 0.0025976289 | R7: 0.91666667 | U7: 0.723
D8: 45904 | E8: 四 | F8: 333.6 | I8: =F8/$C$1 -> 0.91147541 | L8: 0.0025008066 | O8: 0.0030613899 | R8: 0.91666667 | U8: 0.73
D9: 45905 | E9: 五 | F9: 339 | I9: =F9/$C$1 -> 0.92622951 | L9: 0.0025111788 | O9: 0.0028302524 | R9: 0.91666667 | U9: 0.735
D10: 45906 | E10: 六 | F10: 335.7 | I10: =F10/$C$1 -> 0.91721311 | L10: 0.0024919395 | O10: 0.0028965379 | R10: 0.91666667 | U10: 0.74
D11: 45907 | E11: 日 | F11: 335.9 | I11: =F11/$C$1 -> 0.91775956 | L11: 0.0024817889 | O11: 0.0025248926 | R11: 0.91666667 | U11: 0.742
D12: 45908 | E12: 一 | F12: 338.1 | I12: =F12/$C$1 -> 0.92377049 | L12: 0.0024368258 | O12: 0.0022871979 | R12: 0.91666667 | U12: 0.742
D13: 45909 | E13: 二 | F13: 331.71014 | G13: =AVERAGE(F13:F19) -> 335.39905 | I13: =F13/$C$1 -> 0.90631186 | J13: =AVERAGE(I13:I19) -> 0.91639084 | L13: 0.0025045689 | M13: =AVERAGE(L13:L19) -> 0.0024800025 | O13: 0.0023343102 | P13: =AVERAGE(O13:O19) -> 0.0025266112 | R13: 0.91666667 | S13: =AVERAGE(R13:R19) -> 0.91666667 | U13: 0.742 | V13: =AVERAGE(U13:U19) -> 0.75442857
D14: 45910 | E14: 三 | F14: 331.26961 | I14: =F14/$C$1 -> 0.90510822 | L14: 0.0024909689 | O14: 0.0023768167 | R14: 0.91666667 | U14: 0.75
D15: 45911 | E15: 四 | F15: 338.07294 | I15: =F15/$C$1 -> 0.92369657 | L15: 0.0024512522 | O15: 0.0026160352 | R15: 0.91666667 | U15: 0.753
D16: 45912 | E16: 五 | F16: 337.65312 | I16: =F16/$C$1 -> 0.92254951 | L16: 0.0024700455 | O16: 0.0026182966 | R16: 0.91666667 | U16: 0.754
D17: 45913 | E17: 六 | F17: 329.85969 | I17: =F17/$C$1 -> 0.901256 | L17: 0.0024422647 | O17: 0.0028518211 | R17: 0.91666667 | U17: 0.76
D18: 45914 | E18: 日 | F18: 335.39869 | I18: =F18/$C$1 -> 0.91638987 | L18: 0.0025045835 | O18: 0.0023273418 | R18: 0.91666667 | U18: 0.76
D19: 45915 | E19: 一 | F19: 343.82912 | I19: =F19/$C$1 -> 0.93942384 | L19: 0.0024963341 | O19: 0.0025616565 | R19: 0.91666667 | U19: 0.762
D20: 45916 | E20: 二 | G20: =AVERAGE(F20:F26) -> #DIV/0! | J20: =AVERAGE(I20:I26) -> #DIV/0! | M20: =AVERAGE(L20:L26) -> #DIV/0! | P20: =AVERAGE(O20:O26) -> #DIV/0! | S20: =AVERAGE(R20:R26) -> #DIV/0! | V20: =AVERAGE(U20:U26) -> #DIV/0!
D21: 45917 | E21: 三
D22: 45918 | E22: 四
D23: 45919 | E23: 五
D24: 45920 | E24: 六
D25: 45921 | E25: 日
D26: 45922 | E26: 一
D27: 45923 | E27: 二 | G27: =AVERAGE(F27:F33) -> #DIV/0! | J27: =AVERAGE(I27:I33) -> #DIV/0! | M27: =AVERAGE(L27:L33) -> #DIV/0! | P27: =AVERAGE(O27:O33) -> #DIV/0! | S27: =AVERAGE(R27:R33) -> #DIV/0! | V27: =AVERAGE(U27:U33) -> #DIV/0!
D28: 45924 | E28: 三
D29: 45925 | E29: 四
D30: 45926 | E30: 五
D31: 45927 | E31: 六
D32: 45928 | E32: 日
D33: 45929 | E33: 一
D34: 45930 | E34: 二 | G34: =AVERAGE(F34:F40) -> #DIV/0! | J34: =AVERAGE(I34:I40) -> #DIV/0! | M34: =AVERAGE(L34:L40) -> #DIV/0! | P34: =AVERAGE(O34:O40) -> #DIV/0! | S34: =AVERAGE(R34:R40) -> #DIV/0! | V34: =AVERAGE(U34:U40) -> #DIV/0!
D35: 45931 | E35: 三
D36: 45932 | E36: 四
D37: 45933 | E37: 五
D38: 45934 | E38: 六
D39: 45935 | E39: 日
D40: 45936 | E40: 一

Sheet （３）業績構成比
B2: （3）業績構成比
C3: 月份 | D3: 日期 | F3: 營業額 | I3: 品類業績
I4: 18℃-飯糰 | O4: 18℃-壽司手卷 | U4: 4℃-飯糰 | W4: 4℃-壽司手卷 | Y4: 主食 | AE4: 便當 | AG4: 熱食義麵 | AI4: 季節調理麵 | AK4: 微波小吃
F5: 日 | G5: 週累積 | H5: 月累積 | I5: 一配 | K5: 二配 | M5: 合計 | O5: 一配 | Q5: 二配 | S5: 合計 | U5: 一配 | W5: 一配 | Y5: 一配 | AA5: 二配 | AC5: 合計 | AE5: 一配 | AG5: 一配 | AI5: 一配 | AK5: 一配
I6: 業績(元) | J6: 比例(%) | K6: 業績(元) | L6: 比例(%) | M6: 業績(元) | N6: 比例(%) | O6: 業績(元) | P6: 比例(%) | Q6: 業績(元) | R6: 比例(%) | S6: 業績(元) | T6: 比例(%) | U6: 業績(元) | V6: 比例(%) | W6: 業績(元) | X6: 比例(%) | Y6: 業績(元) | Z6: 比例(%) | AA6: 業績(元) | AB6: 比例(%) | AC6: 業績(元) | AD6: 比例(%) | AE6: 業績(元) | AF6: 比例(%) | AG6: 業績(元) | AH6: 比例(%) | AI6: 業績(元) | AJ6: 比例(%) | AK6: 業績(元) | AL6: 比例(%)
C7: 八 | D7: 45901 | E7: 一 | F7: =SUM(M7,S7,U7,W7,AC7,AE7,AG7,AI7,AK7) -> 7106225 | G7: =SUM(F7) -> 7106225 | H7: =SUM(F7:F37) -> 105939262 | I7: 564796.27 | J7: =I7/F7 -> 0.079479086 | K7: 844516.54 | L7: =K7/F7 -> 0.1188418 | M7: =SUM(I7+K7) -> 1409312.8 | N7: =M7/F7 -> 0.19832088 | O7: 178305.27 | P7: =O7/F7 -> 0.025091419 | Q7: 117312.6 | R7: =Q7/$F7 -> 0.016508427 | S7: =SUM(O7+Q7) -> 295617.87 | T7: =S7/F7 -> 0.041599846 | U7: 664869.3 | V7: =U7/F7 -> 0.093561533 | W7: 11130.398 | X7: =W7/F7 -> 0.0015662885 | Y7: 724213.71 | Z7: =Y7/F7 -> 0.10191258 | AA7: 1252569.5 | AB7: =AA7/$F7 -> 0.1762637 | AC7: =SUM(Y7+AA7) -> 1976783.2 | AD7: =AC7/F7 -> 0.27817628 | AE7: 761029.94 | AF7: =AE7/F7 -> 0.10709342 | AG7: 885640.41 | AH7: =AG7/F7 -> 0.12462882 | AI7: 609386.06 | AJ7: =AI7/F7 -> 0.085753837 | AK7: 492455 | AL7: =AK7/F7 -> 0.0692991
D8: 45902 | E8: 二 | F8: =SUM(M8,S8,U8,W8,AC8,AE8,AG8,AI8,AK8) -> 7727458 | G8: =SUM(F8:F14) -> 48362935 | I8: 895945.02 | J8: =I8/F8 -> 0.11594305 | K8: 864483.49 | L8: =K8/F8 -> 0.11187165 | M8: =SUM(I8+K8) -> 1760428.5 | N8: =M8/F8 -> 0.2278147 | O8: 173390.16 | P8: =O8/F8 -> 0.022438188 | Q8: 117719.68 | R8: =Q8/$F8 -> 0.015233946 | S8: =SUM(O8+Q8) -> 291109.84 | T8: =S8/F8 -> 0.037672135 | U8: 654432.77 | V8: =U8/F8 -> 0.084689269 | W8: 12158.137 | X8: =W8/F8 -> 0.0015733682 | Y8: 698241.88 | Z8: =Y8/F8 -> 0.090358547 | AA8: 1229944.2 | AB8: =AA8/$F8 -> 0.15916543 | AC8: =SUM(Y8+AA8) -> 1928186.1 | AD8: =AC8/F8 -> 0.24952398 | AE8: 774796.36 | AF8: =AE8/F8 -> 0.10026536 | AG8: 1240057.7 | AH8: =AG8/F8 -> 0.1604742 | AI8: 592076.67 | AJ8: =AI8/F8 -> 0.076619849 | AK8: 474211.97 | AL8: =AK8/F8 -> 0.061367136
D9: 45903 | E9: 三 | F9: =SUM(M9,S9,U9,W9,AC9,AE9,AG9,AI9,AK9) -> 7254649 | I9: 853934.48 | J9: =I9/F9 -> 0.11770859 | K9: 849068.34 | L9: =K9/F9 -> 0.11703783 | M9: =SUM(I9+K9) -> 1703002.8 | N9: =M9/F9 -> 0.23474641 | O9: 161410.07 | P9: =O9/F9 -> 0.022249191 | Q9: 115119.31 | R9: =Q9/$F9 -> 0.015868349 | S9: =SUM(O9+Q9) -> 276529.38 | T9: =S9/F9 -> 0.038117541 | U9: 629174.45 | V9: =U9/F9 -> 0.08672707 | W9: 11437.042 | X9: =W9/F9 -> 0.0015765121 | Y9: 665754.82 | Z9: =Y9/F9 -> 0.091769405 | AA9: 1124097.9 | AB9: =AA9/$F9 -> 0.15494863 | AC9: =SUM(Y9+AA9) -> 1789852.8 | AD9: =AC9/F9 -> 0.24671804 | AE9: 742015.94 | AF9: =AE9/F9 -> 0.10228144 | AG9: 1057877.5 | AH9: =AG9/F9 -> 0.14582063 | AI9: 574185.36 | AJ9: =AI9/F9 -> 0.079147228 | AK9: 470573.8 | AL9: =AK9/F9 -> 0.064865137
D10: 45904 | E10: 四 | F10: =SUM(M10,S10,U10,W10,AC10,AE10,AG10,AI10,AK10) -> 6602059 | I10: 766879.83 | J10: =I10/F10 -> 0.11615768 | K10: 783941.33 | L10: =K10/F10 -> 0.11874194 | M10: =SUM(I10+K10) -> 1550821.2 | N10: =M10/F10 -> 0.23489962 | O10: 152373.36 | P10: =O10/F10 -> 0.023079673 | Q10: 116613.79 | R10: =Q10/$F10 -> 0.017663246 | S10: =SUM(O10+Q10) -> 268987.16 | T10: =S10/F10 -> 0.040742919 | U10: 592627.72 | V10: =U10/F10 -> 0.089764076 | W10: 11154.125 | X10: =W10/F10 -> 0.0016894919 | Y10: 623826.76 | Z10: =Y10/F10 -> 0.094489729 | AA10: 912090.6 | AB10: =AA10/$F10 -> 0.13815245 | AC10: =SUM(Y10+AA10) -> 1535917.4 | AD10: =AC10/F10 -> 0.23264218 | AE10: 686539.58 | AF10: =AE10/F10 -> 0.10398871 | AG10: 974352.73 | AH10: =AG10/F10 -> 0.14758316 | AI10: 542486.9 | AJ10: =AI10/F10 -> 0.08216935 | AK10: 439172.26 | AL10: =AK10/F10 -> 0.066520499
D11: 45905 | E11: 五 | F11: =SUM(M11,S11,U11,W11,AC11,AE11,AG11,AI11,AK11) -> 5807177 | I11: 700967.78 | J11: =I11/F11 -> 0.12070715 | K11: 734957.29 | L11: =K11/F11 -> 0.12656017 | M11: =SUM(I11+K11) -> 1435925.1 | N11: =M11/F11 -> 0.24726732 | O11: 119243.52 | P11: =O11/F11 -> 0.020533818 | Q11: 97402.177 | R11: =Q11/$F11 -> 0.016772724 | S11: =SUM(O11+Q11) -> 216645.69 | T11: =S11/F11 -> 0.037306542 | U11: 509402.49 | V11: =U11/F11 -> 0.08771947 | W11: 9800.5843 | X11: =W11/F11 -> 0.0016876676 | Y11: 552530 | Z11: =Y11/F11 -> 0.095146058 | AA11: 872926.26 | AB11: =AA11/$F11 -> 0.15031852 | AC11: =SUM(Y11+AA11) -> 1425456.3 | AD11: =AC11/F11 -> 0.24546458 | AE11: 565244.9 | AF11: =AE11/F11 -> 0.097335573 | AG11: 792265.17 | AH11: =AG11/F11 -> 0.13642862 | AI11: 534404.31 | AJ11: =AI11/F11 -> 0.092024801 | AK11: 318032.52 | AL11: =AK11/F11 -> 0.054765425
D12: 45906 | E12: 六 | F12: =SUM(M12,S12,U12,W12,AC12,AE12,AG12,AI12,AK12) -> 6167669 | I12: 686612.5 | J12: =I12/F12 -> 0.11132447 | K12: 794389.29 | L12: =K12/F12 -> 0.12879895 | M12: =SUM(I12+K12) -> 1481001.8 | N12: =M12/F12 -> 0.24012342 | O12: 117355.57 | P12: =O12/F12 -> 0.019027541 | Q12: 97295.734 | R12: =Q12/$F12 -> 0.015775123 | S12: =SUM(O12+Q12) -> 214651.31 | T12: =S12/F12 -> 0.034802663 | U12: 510856.35 | V12: =U12/F12 -> 0.082828108 | W12: 10781.211 | X12: =W12/F12 -> 0.0017480203 | Y12: 593184.79 | Z12: =Y12/F12 -> 0.096176496 | AA12: 1000410.8 | AB12: =AA12/$F12 -> 0.16220242 | AC12: =SUM(Y12+AA12) -> 1593595.6 | AD12: =AC12/F12 -> 0.25837891 | AE12: 611938.27 | AF12: =AE12/F12 -> 0.099217106 | AG12: 879693.66 | AH12: =AG12/F12 -> 0.14262984 | AI12: 526676.21 | AJ12: =AI12/F12 -> 0.085393074 | AK12: 338474.57 | AL12: =AK12/F12 -> 0.054878848
D13: 45907 | E13: 日 | F13: =SUM(M13,S13,U13,W13,AC13,AE13,AG13,AI13,AK13) -> 7394780 | I13: 869357.49 | J13: =I13/F13 -> 0.11756367 | K13: 860695.51 | L13: =K13/F13 -> 0.11639231 | M13: =SUM(I13+K13) -> 1730053 | N13: =M13/F13 -> 0.23395598 | O13: 167431.93 | P13: =O13/F13 -> 0.022641908 | Q13: 114451.35 | R13: =Q13/$F13 -> 0.015477316 | S13: =SUM(O13+Q13) -> 281883.28 | T13: =S13/F13 -> 0.038119225 | U13: 662934.92 | V13: =U13/F13 -> 0.089649038 | W13: 14838.643 | X13: =W13/F13 -> 0.0020066375 | Y13: 707930.82 | Z13: =Y13/F13 -> 0.095733858 | AA13: 1130952.4 | AB13: =AA13/$F13 -> 0.15293928 | AC13: =SUM(Y13+AA13) -> 1838883.2 | AD13: =AC13/F13 -> 0.24867314 | AE13: 778191.06 | AF13: =AE13/F13 -> 0.10523519 | AG13: 1065808.8 | AH13: =AG13/F13 -> 0.14412989 | AI13: 611514.13 | AJ13: =AI13/F13 -> 0.082695378 | AK13: 410672.99 | AL13: =AK13/F13 -> 0.055535525
D14: 45908 | E14: 一 | F14: =SUM(M14,S14,U14,W14,AC14,AE14,AG14,AI14,AK14) -> 7409143 | I14: 814238.04 | J14: =I14/F14 -> 0.10989639 | K14: 872064.47 | L14: =K14/F14 -> 0.11770113 | M14: =SUM(I14+K14) -> 1686302.5 | N14: =M14/F14 -> 0.22759751 | O14: 153939.38 | P14: =O14/F14 -> 0.020776948 | Q14: 112956.71 | R14: =Q14/$F14 -> 0.015245584 | S14: =SUM(O14+Q14) -> 266896.09 | T14: =S14/F14 -> 0.036022531 | U14: 654977.91 | V14: =U14/F14 -> 0.088401305 | W14: 13888.573 | X14: =W14/F14 -> 0.0018745182 | Y14: 727257.57 | Z14: =Y14/F14 -> 0.098156774 | AA14: 1200713.7 | AB14: =AA14/$F14 -> 0.16205838 | AC14: =SUM(Y14+AA14) -> 1927971.3 | AD14: =AC14/F14 -> 0.26021516 | AE14: 815554.07 | AF14: =AE14/F14 -> 0.11007401 | AG14: 1043881.1 | AH14: =AG14/F14 -> 0.14089094 | AI14: 588183.16 | AJ14: =AI14/F14 -> 0.079386126 | AK14: 411488.28 | AL14: =AK14/F14 -> 0.055537905
D15: 45909 | E15: 二 | F15: =SUM(M15,S15,U15,W15,AC15,AE15,AG15,AI15,AK15) -> 7807316 | G15: =SUM(F15:F21) -> 50470102 | I15: 935505.98 | J15: =I15/F15 -> 0.11982428 | K15: 859055.75 | L15: =K15/F15 -> 0.11003215 | M15: =SUM(I15+K15) -> 1794561.7 | N15: =M15/F15 -> 0.22985642 | O15: 145071.42 | P15: =O15/F15 -> 0.018581471 | Q15: 109329.74 | R15: =Q15/$F15 -> 0.014003498 | S15: =SUM(O15+Q15) -> 254401.16 | T15: =S15/F15 -> 0.03258497 | U15: 640272.05 | V15: =U15/F15 -> 0.08200924 | W15: 12461.269 | X15: =W15/F15 -> 0.0015961015 | Y15: 723855.47 | Z15: =Y15/F15 -> 0.092715021 | AA15: 1170755.2 | AB15: =AA15/$F15 -> 0.14995617 | AC15: =SUM(Y15+AA15) -> 1894610.7 | AD15: =AC15/F15 -> 0.2426712 | AE15: 818962.88 | AF15: =AE15/F15 -> 0.10489685 | AG15: 1405614.6 | AH15: =AG15/F15 -> 0.18003813 | AI15: 589547.65 | AJ15: =AI15/F15 -> 0.075512205 | AK15: 396883.98 | AL15: =AK15/F15 -> 0.050834881
D16: 45910 | E16: 三 | F16: =SUM(M16,S16,U16,W16,AC16,AE16,AG16,AI16,AK16) -> 7436383 | I16: 922704.54 | J16: =I16/F16 -> 0.12407975 | K16: 846234.4 | L16: =K16/F16 -> 0.11379651 | M16: =SUM(I16+K16) -> 1768938.9 | N16: =M16/F16 -> 0.23787626 | O16: 137693.85 | P16: =O16/F16 -> 0.01851624 | Q16: 106359.16 | R16: =Q16/$F16 -> 0.014302539 | S16: =SUM(O16+Q16) -> 244053.01 | T16: =S16/F16 -> 0.032818778 | U16: 637306.64 | V16: =U16/F16 -> 0.085701159 | W16: 10391.165 | X16: =W16/F16 -> 0.0013973413 | Y16: 672768.71 | Z16: =Y16/F16 -> 0.090469885 | AA16: 1063595 | AB16: =AA16/$F16 -> 0.14302585 | AC16: =SUM(Y16+AA16) -> 1736363.7 | AD16: =AC16/F16 -> 0.23349574 | AE16: 803252.37 | AF16: =AE16/F16 -> 0.10801654 | AG16: 1211034.6 | AH16: =AG16/F16 -> 0.16285265 | AI16: 636227.29 | AJ16: =AI16/F16 -> 0.085556014 | AK16: 388815.22 | AL16: =AK16/F16 -> 0.052285529
D17: 45911 | E17: 四 | F17: =SUM(M17,S17,U17,W17,AC17,AE17,AG17,AI17,AK17) -> 6919680 | I17: 856747.59 | J17: =I17/F17 -> 0.12381318 | K17: 758956.03 | L17: =K17/F17 -> 0.1096808 | M17: =SUM(I17+K17) -> 1615703.6 | N17: =M17/F17 -> 0.23349398 | O17: 132525.74 | P17: =O17/F17 -> 0.019152004 | Q17: 103770.66 | R17: =Q17/$F17 -> 0.014996454 | S17: =SUM(O17+Q17) -> 236296.4 | T17: =S17/F17 -> 0.034148458 | U17: 594283.82 | V17: =U17/F17 -> 0.085883136 | W17: 9754.9126 | X17: =W17/F17 -> 0.0014097346 | Y17: 621366.49 | Z17: =Y17/F17 -> 0.089796998 | AA17: 945266.21 | AB17: =AA17/$F17 -> 0.13660548 | AC17: =SUM(Y17+AA17) -> 1566632.7 | AD17: =AC17/F17 -> 0.22640248 | AE17: 748334.75 | AF17: =AE17/F17 -> 0.10814586 | AG17: 1159449.9 | AH17: =AG17/F17 -> 0.16755831 | AI17: 610362.09 | AJ17: =AI17/F17 -> 0.088206693 | AK17: 378861.8 | AL17: =AK17/F17 -> 0.054751347
D18: 45912 | E18: 五 | F18: =SUM(M18,S18,U18,W18,AC18,AE18,AG18,AI18,AK18) -> 6171958 | I18: 693224.03 | J18: =I18/F18 -> 0.11231833 | K18: 724669.14 | L18: =K18/F18 -> 0.11741317 | M18: =SUM(I18+K18) -> 1417893.2 | N18: =M18/F18 -> 0.2297315 | O18: 110826.64 | P18: =O18/F18 -> 0.01795648 | Q18: 94817.97 | R18: =Q18/$F18 -> 0.015362705 | S18: =SUM(O18+Q18) -> 205644.61 | T18: =S18/F18 -> 0.033319185 | U18: 514506.04 | V18: =U18/F18 -> 0.083361883 | W18: 10097.029 | X18: =W18/F18 -> 0.0016359523 | Y18: 584650.52 | Z18: =Y18/F18 -> 0.094726911 | AA18: 979449.85 | AB18: =AA18/$F18 -> 0.15869354 | AC18: =SUM(Y18+AA18) -> 1564100.4 | AD18: =AC18/F18 -> 0.25342045 | AE18: 617366.96 | AF18: =AE18/F18 -> 0.10002773 | AG18: 932111.64 | AH18: =AG18/F18 -> 0.15102365 | AI18: 573858.18 | AJ18: =AI18/F18 -> 0.092978302 | AK18: 336380.01 | AL18: =AK18/F18 -> 0.054501345
D19: 45913 | E19: 六 | F19: =SUM(M19,S19,U19,W19,AC19,AE19,AG19,AI19,AK19) -> 6541355 | I19: 683125.9 | J19: =I19/F19 -> 0.10443186 | K19: 808299.2 | L19: =K19/F19 -> 0.12356755 | M19: =SUM(I19+K19) -> 1491425.1 | N19: =M19/F19 -> 0.22799941 | O19: 111249.55 | P19: =O19/F19 -> 0.017007111 | Q19: 93680.304 | R19: =Q19/$F19 -> 0.014321238 | S19: =SUM(O19+Q19) -> 204929.85 | T19: =S19/F19 -> 0.031328349 | U19: 543330.7 | V19: =U19/F19 -> 0.08306088 | W19: 12455.071 | X19: =W19/F19 -> 0.0019040506 | Y19: 630925.73 | Z19: =Y19/F19 -> 0.096451841 | AA19: 1060648.8 | AB19: =AA19/$F19 -> 0.16214512 | AC19: =SUM(Y19+AA19) -> 1691574.5 | AD19: =AC19/F19 -> 0.25859696 | AE19: 651474.25 | AF19: =AE19/F19 -> 0.099593165 | AG19: 1016529.4 | AH19: =AG19/F19 -> 0.15540043 | AI19: 582194.15 | AJ19: =AI19/F19 -> 0.089002073 | AK19: 347441.94 | AL19: =AK19/F19 -> 0.053114674
D20: 45914 | E20: 日 | F20: =SUM(M20,S20,U20,W20,AC20,AE20,AG20,AI20,AK20) -> 7771753 | I20: 935689.61 | J20: =I20/F20 -> 0.12039621 | K20: 866163.8 | L20: =K20/F20 -> 0.11145025 | M20: =SUM(I20+K20) -> 1801853.4 | N20: =M20/F20 -> 0.23184646 | O20: 151097.51 | P20: =O20/F20 -> 0.019441882 | Q20: 109222.7 | R20: =Q20/$F20 -> 0.014053805 | S20: =SUM(O20+Q20) -> 260320.21 | T20: =S20/F20 -> 0.033495687 | U20: 669570.65 | V20: =U20/F20 -> 0.086154391 | W20: 13837.593 | X20: =W20/F20 -> 0.0017804983 | Y20: 724732.36 | Z20: =Y20/F20 -> 0.093252109 | AA20: 1141094.4 | AB20: =AA20/$F20 -> 0.14682587 | AC20: =SUM(Y20+AA20) -> 1865826.7 | AD20: =AC20/F20 -> 0.24007797 | AE20: 855937.57 | AF20: =AE20/F20 -> 0.11013443 | AG20: 1235869.7 | AH20: =AG20/F20 -> 0.15902072 | AI20: 658283.11 | AJ20: =AI20/F20 -> 0.084702011 | AK20: 410254.01 | AL20: =AK20/F20 -> 0.052787835
D21: 45915 | E21: 一 | F21: =SUM(M21,S21,U21,W21,AC21,AE21,AG21,AI21,AK21) -> 7821657 | I21: 884810.27 | J21: =I21/F21 -> 0.11312312 | K21: 849921.16 | L21: =K21/F21 -> 0.10866255 | M21: =SUM(I21+K21) -> 1734731.4 | N21: =M21/F21 -> 0.22178567 | O21: 142123.06 | P21: =O21/F21 -> 0.018170455 | Q21: 113089.68 | R21: =Q21/$F21 -> 0.014458532 | S21: =SUM(O21+Q21) -> 255212.75 | T21: =S21/F21 -> 0.032628987 | U21: 679271.93 | V21: =U21/F21 -> 0.086845017 | W21: 14362.801 | X21: =W21/F21 -> 0.0018362863 | Y21: 743337.31 | Z21: =Y21/F21 -> 0.095035784 | AA21: 1200149.4 | AB21: =AA21/$F21 -> 0.15343927 | AC21: =SUM(Y21+AA21) -> 1943486.7 | AD21: =AC21/F21 -> 0.24847506 | AE21: 866645.2 | AF21: =AE21/F21 -> 0.11080072 | AG21: 1224710.4 | AH21: =AG21/F21 -> 0.1565794 | AI21: 684941.6 | AJ21: =AI21/F21 -> 0.087569884 | AK21: 418294.26 | AL21: =AK21/F21 -> 0.053478983
D22: 45916 | E22: 二 | F22: =SUM(M22,S22,U22,W22,AC22,AE22,AG22,AI22,AK22) -> 0 | G22: =SUM(F22:F28) -> 0 | J22: =I22/F22 -> #DIV/0! | L22: =K22/F22 -> #DIV/0! | M22: =SUM(I22+K22) -> 0 | N22: =M22/F22 -> #DIV/0! | P22: =O22/F22 -> #DIV/0! | R22: =Q22/$F22 -> #DIV/0! | S22: =SUM(O22+Q22) -> 0 | T22: =S22/F22 -> #DIV/0! | V22: =U22/F22 -> #DIV/0! | X22: =W22/F22 -> #DIV/0! | Z22: =Y22/F22 -> #DIV/0! | AB22: =AA22/$F22 -> #DIV/0! | AC22: =SUM(Y22+AA22) -> 0 | AD22: =AC22/F22 -> #DIV/0! | AF22: =AE22/F22 -> #DIV/0! | AH22: =AG22/F22 -> #DIV/0! | AJ22: =AI22/F22 -> #DIV/0! | AL22: =AK22/F22 -> #DIV/0!
D23: 45917 | E23: 三 | F23: =SUM(M23,S23,U23,W23,AC23,AE23,AG23,AI23,AK23) -> 0 | J23: =I23/F23 -> #DIV/0! | L23: =K23/F23 -> #DIV/0! | M23: =SUM(I23+K23) -> 0 | N23: =M23/F23 -> #DIV/0! | P23: =O23/F23 -> #DIV/0! | R23: =Q23/$F23 -> #DIV/0! | S23: =SUM(O23+Q23) -> 0 | T23: =S23/F23 -> #DIV/0! | V23: =U23/F23 -> #DIV/0! | X23: =W23/F23 -> #DIV/0! | Z23: =Y23/F23 -> #DIV/0! | AB23: =AA23/$F23 -> #DIV/0! | AC23: =SUM(Y23+AA23) -> 0 | AD23: =AC23/F23 -> #DIV/0! | AF23: =AE23/F23 -> #DIV/0! | AH23: =AG23/F23 -> #DIV/0! | AJ23: =AI23/F23 -> #DIV/0! | AL23: =AK23/F23 -> #DIV/0!
D24: 45918 | E24: 四 | F24: =SUM(M24,S24,U24,W24,AC24,AE24,AG24,AI24,AK24) -> 0 | J24: =I24/F24 -> #DIV/0! | L24: =K24/F24 -> #DIV/0! | M24: =SUM(I24+K24) -> 0 | N24: =M24/F24 -> #DIV/0! | P24: =O24/F24 -> #DIV/0! | R24: =Q24/$F24 -> #DIV/0! | S24: =SUM(O24+Q24) -> 0 | T24: =S24/F24 -> #DIV/0! | V24: =U24/F24 -> #DIV/0! | X24: =W24/F24 -> #DIV/0! | Z24: =Y24/F24 -> #DIV/0! | AB24: =AA24/$F24 -> #DIV/0! | AC24: =SUM(Y24+AA24) -> 0 | AD24: =AC24/F24 -> #DIV/0! | AF24: =AE24/F24 -> #DIV/0! | AH24: =AG24/F24 -> #DIV/0! | AJ24: =AI24/F24 -> #DIV/0! | AL24: =AK24/F24 -> #DIV/0!
D25: 45919 | E25: 五 | F25: =SUM(M25,S25,U25,W25,AC25,AE25,AG25,AI25,AK25) -> 0 | J25: =I25/F25 -> #DIV/0! | L25: =K25/F25 -> #DIV/0! | M25: =SUM(I25+K25) -> 0 | N25: =M25/F25 -> #DIV/0! | P25: =O25/F25 -> #DIV/0! | R25: =Q25/$F25 -> #DIV/0! | S25: =SUM(O25+Q25) -> 0 | T25: =S25/F25 -> #DIV/0! | V25: =U25/F25 -> #DIV/0! | X25: =W25/F25 -> #DIV/0! | Z25: =Y25/F25 -> #DIV/0! | AB25: =AA25/$F25 -> #DIV/0! | AC25: =SUM(Y25+AA25) -> 0 | AD25: =AC25/F25 -> #DIV/0! | AF25: =AE25/F25 -> #DIV/0! | AH25: =AG25/F25 -> #DIV/0! | AJ25: =AI25/F25 -> #DIV/0! | AL25: =AK25/F25 -> #DIV/0!
D26: 45920 | E26: 六 | F26: =SUM(M26,S26,U26,W26,AC26,AE26,AG26,AI26,AK26) -> 0 | J26: =I26/F26 -> #DIV/0! | L26: =K26/F26 -> #DIV/0! | M26: =SUM(I26+K26) -> 0 | N26: =M26/F26 -> #DIV/0! | P26: =O26/F26 -> #DIV/0! | R26: =Q26/$F26 -> #DIV/0! | S26: =SUM(O26+Q26) -> 0 | T26: =S26/F26 -> #DIV/0! | V26: =U26/F26 -> #DIV/0! | X26: =W26/F26 -> #DIV/0! | Z26: =Y26/F26 -> #DIV/0! | AB26: =AA26/$F26 -> #DIV/0! | AC26: =SUM(Y26+AA26) -> 0 | AD26: =AC26/F26 -> #DIV/0! | AF26: =AE26/F26 -> #DIV/0! | AH26: =AG26/F26 -> #DIV/0! | AJ26: =AI26/F26 -> #DIV/0! | AL26: =AK26/F26 -> #DIV/0!
D27: 45921 | E27: 日 | F27: =SUM(M27,S27,U27,W27,AC27,AE27,AG27,AI27,AK27) -> 0 | J27: =I27/F27 -> #DIV/0! | L27: =K27/F27 -> #DIV/0! | M27: =SUM(I27+K27) -> 0 | N27: =M27/F27 -> #DIV/0! | P27: =O27/F27 -> #DIV/0! | R27: =Q27/$F27 -> #DIV/0! | S27: =SUM(O27+Q27) -> 0 | T27: =S27/F27 -> #DIV/0! | V27: =U27/F27 -> #DIV/0! | X27: =W27/F27 -> #DIV/0! | Z27: =Y27/F27 -> #DIV/0! | AB27: =AA27/$F27 -> #DIV/0! | AC27: =SUM(Y27+AA27) -> 0 | AD27: =AC27/F27 -> #DIV/0! | AF27: =AE27/F27 -> #DIV/0! | AH27: =AG27/F27 -> #DIV/0! | AJ27: =AI27/F27 -> #DIV/0! | AL27: =AK27/F27 -> #DIV/0!
D28: 45922 | E28: 一 | F28: =SUM(M28,S28,U28,W28,AC28,AE28,AG28,AI28,AK28) -> 0 | J28: =I28/F28 -> #DIV/0! | L28: =K28/F28 -> #DIV/0! | M28: =SUM(I28+K28) -> 0 | N28: =M28/F28 -> #DIV/0! | P28: =O28/F28 -> #DIV/0! | R28: =Q28/$F28 -> #DIV/0! | S28: =SUM(O28+Q28) -> 0 | T28: =S28/F28 -> #DIV/0! | V28: =U28/F28 -> #DIV/0! | X28: =W28/F28 -> #DIV/0! | Z28: =Y28/F28 -> #DIV/0! | AB28: =AA28/$F28 -> #DIV/0! | AC28: =SUM(Y28+AA28) -> 0 | AD28: =AC28/F28 -> #DIV/0! | AF28: =AE28/F28 -> #DIV/0! | AH28: =AG28/F28 -> #DIV/0! | AJ28: =AI28/F28 -> #DIV/0! | AL28: =AK28/F28 -> #DIV/0!
D29: 45923 | E29: 二 | F29: =SUM(M29,S29,U29,W29,AC29,AE29,AG29,AI29,AK29) -> 0 | G29: =SUM(F29:F35) -> 0 | J29: =I29/F29 -> #DIV/0! | L29: =K29/F29 -> #DIV/0! | M29: =SUM(I29+K29) -> 0 | N29: =M29/F29 -> #DIV/0! | P29: =O29/F29 -> #DIV/0! | R29: =Q29/$F29 -> #DIV/0! | S29: =SUM(O29+Q29) -> 0 | T29: =S29/F29 -> #DIV/0! | V29: =U29/F29 -> #DIV/0! | X29: =W29/F29 -> #DIV/0! | Z29: =Y29/F29 -> #DIV/0! | AB29: =AA29/$F29 -> #DIV/0! | AC29: =SUM(Y29+AA29) -> 0 | AD29: =AC29/F29 -> #DIV/0! | AF29: =AE29/F29 -> #DIV/0! | AH29: =AG29/F29 -> #DIV/0! | AJ29: =AI29/F29 -> #DIV/0! | AL29: =AK29/F29 -> #DIV/0!
D30: 45924 | E30: 三 | F30: =SUM(M30,S30,U30,W30,AC30,AE30,AG30,AI30,AK30) -> 0 | J30: =I30/F30 -> #DIV/0! | L30: =K30/F30 -> #DIV/0! | M30: =SUM(I30+K30) -> 0 | N30: =M30/F30 -> #DIV/0! | P30: =O30/F30 -> #DIV/0! | R30: =Q30/$F30 -> #DIV/0! | S30: =SUM(O30+Q30) -> 0 | T30: =S30/F30 -> #DIV/0! | V30: =U30/F30 -> #DIV/0! | X30: =W30/F30 -> #DIV/0! | Z30: =Y30/F30 -> #DIV/0! | AB30: =AA30/$F30 -> #DIV/0! | AC30: =SUM(Y30+AA30) -> 0 | AD30: =AC30/F30 -> #DIV/0! | AF30: =AE30/F30 -> #DIV/0! | AH30: =AG30/F30 -> #DIV/0! | AJ30: =AI30/F30 -> #DIV/0! | AL30: =AK30/F30 -> #DIV/0!
D31: 45925 | E31: 四 | F31: =SUM(M31,S31,U31,W31,AC31,AE31,AG31,AI31,AK31) -> 0 | J31: =I31/F31 -> #DIV/0! | L31: =K31/F31 -> #DIV/0! | M31: =SUM(I31+K31) -> 0 | N31: =M31/F31 -> #DIV/0! | P31: =O31/F31 -> #DIV/0! | R31: =Q31/$F31 -> #DIV/0! | S31: =SUM(O31+Q31) -> 0 | T31: =S31/F31 -> #DIV/0! | V31: =U31/F31 -> #DIV/0! | X31: =W31/F31 -> #DIV/0! | Z31: =Y31/F31 -> #DIV/0! | AB31: =AA31/$F31 -> #DIV/0! | AC31: =SUM(Y31+AA31) -> 0 | AD31: =AC31/F31 -> #DIV/0! | AF31: =AE31/F31 -> #DIV/0! | AH31: =AG31/F31 -> #DIV/0! | AJ31: =AI31/F31 -> #DIV/0! | AL31: =AK31/F31 -> #DIV/0!
D32: 45926 | E32: 五 | F32: =SUM(M32,S32,U32,W32,AC32,AE32,AG32,AI32,AK32) -> 0 | J32: =I32/F32 -> #DIV/0! | L32: =K32/F32 -> #DIV/0! | M32: =SUM(I32+K32) -> 0 | N32: =M32/F32 -> #DIV/0! | P32: =O32/F32 -> #DIV/0! | R32: =Q32/$F32 -> #DIV/0! | S32: =SUM(O32+Q32) -> 0 | T32: =S32/F32 -> #DIV/0! | V32: =U32/F32 -> #DIV/0! | X32: =W32/F32 -> #DIV/0! | Z32: =Y32/F32 -> #DIV/0! | AB32: =AA32/$F32 -> #DIV/0! | AC32: =SUM(Y32+AA32) -> 0 | AD32: =AC32/F32 -> #DIV/0! | AF32: =AE32/F32 -> #DIV/0! | AH32: =AG32/F32 -> #DIV/0! | AJ32: =AI32/F32 -> #DIV/0! | AL32: =AK32/F32 -> #DIV/0!
D33: 45927 | E33: 六 | F33: =SUM(M33,S33,U33,W33,AC33,AE33,AG33,AI33,AK33) -> 0 | J33: =I33/F33 -> #DIV/0! | L33: =K33/F33 -> #DIV/0! | M33: =SUM(I33+K33) -> 0 | N33: =M33/F33 -> #DIV/0! | P33: =O33/F33 -> #DIV/0! | R33: =Q33/$F33 -> #DIV/0! | S33: =SUM(O33+Q33) -> 0 | T33: =S33/F33 -> #DIV/0! | V33: =U33/F33 -> #DIV/0! | X33: =W33/F33 -> #DIV/0! | Z33: =Y33/F33 -> #DIV/0! | AB33: =AA33/$F33 -> #DIV/0! | AC33: =SUM(Y33+AA33) -> 0 | AD33: =AC33/F33 -> #DIV/0! | AF33: =AE33/F33 -> #DIV/0! | AH33: =AG33/F33 -> #DIV/0! | AJ33: =AI33/F33 -> #DIV/0! | AL33: =AK33/F33 -> #DIV/0!
D34: 45928 | E34: 日 | F34: =SUM(M34,S34,U34,W34,AC34,AE34,AG34,AI34,AK34) -> 0 | J34: =I34/F34 -> #DIV/0! | L34: =K34/F34 -> #DIV/0! | M34: =SUM(I34+K34) -> 0 | N34: =M34/F34 -> #DIV/0! | P34: =O34/F34 -> #DIV/0! | R34: =Q34/$F34 -> #DIV/0! | S34: =SUM(O34+Q34) -> 0 | T34: =S34/F34 -> #DIV/0! | V34: =U34/F34 -> #DIV/0! | X34: =W34/F34 -> #DIV/0! | Z34: =Y34/F34 -> #DIV/0! | AB34: =AA34/$F34 -> #DIV/0! | AC34: =SUM(Y34+AA34) -> 0 | AD34: =AC34/F34 -> #DIV/0! | AF34: =AE34/F34 -> #DIV/0! | AH34: =AG34/F34 -> #DIV/0! | AJ34: =AI34/F34 -> #DIV/0! | AL34: =AK34/F34 -> #DIV/0!
D35: 45929 | E35: 一 | F35: =SUM(M35,S35,U35,W35,AC35,AE35,AG35,AI35,AK35) -> 0 | J35: =I35/F35 -> #DIV/0! | L35: =K35/F35 -> #DIV/0! | M35: =SUM(I35+K35) -> 0 | N35: =M35/F35 -> #DIV/0! | P35: =O35/F35 -> #DIV/0! | R35: =Q35/$F35 -> #DIV/0! | S35: =SUM(O35+Q35) -> 0 | T35: =S35/F35 -> #DIV/0! | V35: =U35/F35 -> #DIV/0! | X35: =W35/F35 -> #DIV/0! | Z35: =Y35/F35 -> #DIV/0! | AB35: =AA35/$F35 -> #DIV/0! | AC35: =SUM(Y35+AA35) -> 0 | AD35: =AC35/F35 -> #DIV/0! | AF35: =AE35/F35 -> #DIV/0! | AH35: =AG35/F35 -> #DIV/0! | AJ35: =AI35/F35 -> #DIV/0! | AL35: =AK35/F35 -> #DIV/0!
D36: 45930 | E36: 二 | F36: =SUM(M36,S36,U36,W36,AC36,AE36,AG36,AI36,AK36) -> 0 | G36: =SUM(F36:F42) -> 0 | J36: =I36/F36 -> #DIV/0! | L36: =K36/F36 -> #DIV/0! | M36: =SUM(I36+K36) -> 0 | N36: =M36/F36 -> #DIV/0! | P36: =O36/F36 -> #DIV/0! | R36: =Q36/$F36 -> #DIV/0! | S36: =SUM(O36+Q36) -> 0 | T36: =S36/F36 -> #DIV/0! | V36: =U36/F36 -> #DIV/0! | X36: =W36/F36 -> #DIV/0! | Z36: =Y36/F36 -> #DIV/0! | AB36: =AA36/$F36 -> #DIV/0! | AC36: =SUM(Y36+AA36) -> 0 | AD36: =AC36/F36 -> #DIV/0! | AF36: =AE36/F36 -> #DIV/0! | AH36: =AG36/F36 -> #DIV/0! | AJ36: =AI36/F36 -> #DIV/0! | AL36: =AK36/F36 -> #DIV/0!
D37: 45931 | E37: 三 | F37: =SUM(M37,S37,U37,W37,AC37,AE37,AG37,AI37,AK37) -> 0 | J37: =I37/F37 -> #DIV/0! | L37: =K37/F37 -> #DIV/0! | M37: =SUM(I37+K37) -> 0 | N37: =M37/F37 -> #DIV/0! | P37: =O37/F37 -> #DIV/0! | R37: =Q37/$F37 -> #DIV/0! | S37: =SUM(O37+Q37) -> 0 | T37: =S37/F37 -> #DIV/0! | V37: =U37/F37 -> #DIV/0! | X37: =W37/F37 -> #DIV/0! | Z37: =Y37/F37 -> #DIV/0! | AB37: =AA37/$F37 -> #DIV/0! | AC37: =SUM(Y37+AA37) -> 0 | AD37: =AC37/F37 -> #DIV/0! | AF37: =AE37/F37 -> #DIV/0! | AH37: =AG37/F37 -> #DIV/0! | AJ37: =AI37/F37 -> #DIV/0! | AL37: =AK37/F37 -> #DIV/0!
D38: 45932 | E38: 四 | F38: =SUM(M38,S38,U38,W38,AC38,AE38,AG38,AI38,AK38) -> 0 | J38: =I38/F38 -> #DIV/0! | L38: =K38/F38 -> #DIV/0! | M38: =SUM(I38+K38) -> 0 | N38: =M38/F38 -> #DIV/0! | P38: =O38/F38 -> #DIV/0! | R38: =Q38/$F38 -> #DIV/0! | S38: =SUM(O38+Q38) -> 0 | T38: =S38/F38 -> #DIV/0! | V38: =U38/F38 -> #DIV/0! | X38: =W38/F38 -> #DIV/0! | Z38: =Y38/F38 -> #DIV/0! | AB38: =AA38/$F38 -> #DIV/0! | AC38: =SUM(Y38+AA38) -> 0 | AD38: =AC38/F38 -> #DIV/0! | AF38: =AE38/F38 -> #DIV/0! | AH38: =AG38/F38 -> #DIV/0! | AJ38: =AI38/F38 -> #DIV/0! | AL38: =AK38/F38 -> #DIV/0!
D39: 45933 | E39: 五 | F39: =SUM(M39,S39,U39,W39,AC39,AE39,AG39,AI39,AK39) -> 0 | J39: =I39/F39 -> #DIV/0! | L39: =K39/F39 -> #DIV/0! | M39: =SUM(I39+K39) -> 0 | N39: =M39/F39 -> #DIV/0! | P39: =O39/F39 -> #DIV/0! | R39: =Q39/$F39 -> #DIV/0! | S39: =SUM(O39+Q39) -> 0 | T39: =S39/F39 -> #DIV/0! | V39: =U39/F39 -> #DIV/0! | X39: =W39/F39 -> #DIV/0! | Z39: =Y39/F39 -> #DIV/0! | AB39: =AA39/$F39 -> #DIV/0! | AC39: =SUM(Y39+AA39) -> 0 | AD39: =AC39/F39 -> #DIV/0! | AF39: =AE39/F39 -> #DIV/0! | AH39: =AG39/F39 -> #DIV/0! | AJ39: =AI39/F39 -> #DIV/0! | AL39: =AK39/F39 -> #DIV/0!
D40: 45934 | E40: 六 | F40: =SUM(M40,S40,U40,W40,AC40,AE40,AG40,AI40,AK40) -> 0 | J40: =I40/F40 -> #DIV/0! | L40: =K40/F40 -> #DIV/0! | M40: =SUM(I40+K40) -> 0 | N40: =M40/F40 -> #DIV/0! | P40: =O40/F40 -> #DIV/0! | R40: =Q40/$F40 -> #DIV/0! | S40: =SUM(O40+Q40) -> 0 | T40: =S40/F40 -> #DIV/0! | V40: =U40/F40 -> #DIV/0! | X40: =W40/F40 -> #DIV/0! | Z40: =Y40/F40 -> #DIV/0! | AB40: =AA40/$F40 -> #DIV/0! | AC40: =SUM(Y40+AA40) -> 0 | AD40: =AC40/F40 -> #DIV/0! | AF40: =AE40/F40 -> #DIV/0! | AH40: =AG40/F40 -> #DIV/0! | AJ40: =AI40/F40 -> #DIV/0! | AL40: =AK40/F40 -> #DIV/0!
D41: 45935 | E41: 日 | F41: =SUM(M41,S41,U41,W41,AC41,AE41,AG41,AI41,AK41) -> 0 | J41: =I41/F41 -> #DIV/0! | L41: =K41/F41 -> #DIV/0! | M41: =SUM(I41+K41) -> 0 | N41: =M41/F41 -> #DIV/0! | P41: =O41/F41 -> #DIV/0! | R41: =Q41/$F41 -> #DIV/0! | S41: =SUM(O41+Q41) -> 0 | T41: =S41/F41 -> #DIV/0! | V41: =U41/F41 -> #DIV/0! | X41: =W41/F41 -> #DIV/0! | Z41: =Y41/F41 -> #DIV/0! | AB41: =AA41/$F41 -> #DIV/0! | AC41: =SUM(Y41+AA41) -> 0 | AD41: =AC41/F41 -> #DIV/0! | AF41: =AE41/F41 -> #DIV/0! | AH41: =AG41/F41 -> #DIV/0! | AJ41: =AI41/F41 -> #DIV/0! | AL41: =AK41/F41 -> #DIV/0!
...

Sheet （４）訂單數量構成比
B2: （4）訂單數量構成比
C3: 月份 | D3: 日期 | F3: 訂單量 | I3: 品類訂單量
I4: 18℃-飯糰 | O4: 18℃-壽司手卷 | U4: 4℃-飯糰 | W4: 4℃-壽司手卷 | Y4: 主食 | AE4: 便當 | AG4: 熱食義麵 | AI4: 季節調理麵 | AK4: 微波小吃
F5: 日 | G5: 週累積 | H5: 月累積 | I5: 一配 | K5: 二配 | M5: 合計 | O5: 一配 | Q5: 二配 | S5: 合計 | U5: 一配 | W5: 一配 | Y5: 一配 | AA5: 二配 | AC5: 合計 | AE5: 一配 | AG5: 一配 | AI5: 一配 | AK5: 一配
I6: 訂單數 | J6: 比例(%) | K6: 訂單數 | L6: 比例(%) | M6: 訂單數 | N6: 比例(%) | O6: 訂單數 | P6: 比例(%) | Q6: 訂單數 | R6: 比例(%) | S6: 訂單數 | T6: 比例(%) | U6: 訂單數 | V6: 比例(%) | W6: 訂單數 | X6: 比例(%) | Y6: 訂單數 | Z6: 比例(%) | AA6: 訂單數 | AB6: 比例(%) | AC6: 訂單數 | AD6: 比例(%) | AE6: 訂單數 | AF6: 比例(%) | AG6: 訂單數 | AH6: 比例(%) | AI6: 訂單數 | AJ6: 比例(%) | AK6: 訂單數 | AL6: 比例(%)
C7: 八 | D7: 45901 | E7: 一 | F7: =SUM(M7,S7,U7,W7,AC7,AE7,AG7,AI7,AK7) -> 222309 | G7: =SUM(F7:F10) -> 901743 | H7: =SUM(F7:F37) -> 3326414 | I7: 31188 | J7: =I7/F7 -> 0.14029122 | K7: 45716 | L7: =K7/F7 -> 0.2056417 | M7: =SUM(I7+K7) -> 76904 | N7: =M7/F7 -> 0.34593291 | O7: 7283 | P7: =O7/F7 -> 0.032760707 | Q7: 4112 | R7: =Q7/D7 -> 0.089584105 | S7: =SUM(O7+Q7) -> 11395 | T7: =S7/F7 -> 0.051257484 | U7: 20019 | V7: =U7/F7 -> 0.090050335 | W7: 420 | X7: =W7/F7 -> 0.0018892622 | Y7: 23192 | Z7: =Y7/F7 -> 0.10432326 | AA7: 24411 | AB7: =AA7/D7 -> 0.53181848 | AC7: =SUM(Y7+AA7) -> 47603 | AD7: =AC7/F7 -> 0.21412988 | AE7: 13998 | AF7: =AE7/F7 -> 0.062966412 | AG7: 17886 | AH7: =AG7/F7 -> 0.080455582 | AI7: 16627 | AJ7: =AI7/F7 -> 0.074792294 | AK7: 17457 | AL7: =AK7/F7 -> 0.078525836
D8: 45902 | E8: 二 | F8: =SUM(M8,S8,U8,W8,AC8,AE8,AG8,AI8,AK8) -> 240560 | I8: 43708 | J8: =I8/F8 -> 0.18169272 | K8: 46366 | L8: =K8/F8 -> 0.19274194 | M8: =SUM(I8+K8) -> 90074 | N8: =M8/F8 -> 0.37443465 | O8: 7078 | P8: =O8/F8 -> 0.029423013 | Q8: 4101 | R8: =Q8/D8 -> 0.089342512 | S8: =SUM(O8+Q8) -> 11179 | T8: =S8/F8 -> 0.046470735 | U8: 19657 | V8: =U8/F8 -> 0.081713502 | W8: 458 | X8: =W8/F8 -> 0.0019038909 | Y8: 22718 | Z8: =Y8/F8 -> 0.094437978 | AA8: 23992 | AB8: =AA8/D8 -> 0.52267875 | AC8: =SUM(Y8+AA8) -> 46710 | AD8: =AC8/F8 -> 0.19417193 | AE8: 14199 | AF8: =AE8/F8 -> 0.059024776 | AG8: 25447 | AH8: =AG8/F8 -> 0.10578234 | AI8: 16117 | AJ8: =AI8/F8 -> 0.066997838 | AK8: 16719 | AL8: =AK8/F8 -> 0.069500333
D9: 45903 | E9: 三 | F9: =SUM(M9,S9,U9,W9,AC9,AE9,AG9,AI9,AK9) -> 228856 | I9: 41906 | J9: =I9/F9 -> 0.18311078 | K9: 45666 | L9: =K9/F9 -> 0.19954032 | M9: =SUM(I9+K9) -> 87572 | N9: =M9/F9 -> 0.3826511 | O9: 6487 | P9: =O9/F9 -> 0.028345335 | Q9: 4013 | R9: =Q9/D9 -> 0.08742348 | S9: =SUM(O9+Q9) -> 10500 | T9: =S9/F9 -> 0.045880379 | U9: 18908 | V9: =U9/F9 -> 0.082619639 | W9: 431 | X9: =W9/F9 -> 0.0018832803 | Y9: 22068 | Z9: =Y9/F9 -> 0.096427448 | AA9: 21947 | AB9: =AA9/D9 -> 0.4781169 | AC9: =SUM(Y9+AA9) -> 44015 | AD9: =AC9/F9 -> 0.19232618 | AE9: 13526 | AF9: =AE9/F9 -> 0.059102667 | AG9: 21626 | AH9: =AG9/F9 -> 0.094496102 | AI9: 15647 | AJ9: =AI9/F9 -> 0.068370504 | AK9: 16631 | AL9: =AK9/F9 -> 0.072670151
D10: 45904 | E10: 四 | F10: =SUM(M10,S10,U10,W10,AC10,AE10,AG10,AI10,AK10) -> 210018 | I10: 38090 | J10: =I10/F10 -> 0.18136541 | K10: 42384 | L10: =K10/F10 -> 0.20181127 | M10: =SUM(I10+K10) -> 80474 | N10: =M10/F10 -> 0.38317668 | O10: 6155 | P10: =O10/F10 -> 0.029307012 | Q10: 4074 | R10: =Q10/D10 -> 0.088750436 | S10: =SUM(O10+Q10) -> 10229 | T10: =S10/F10 -> 0.048705349 | U10: 17869 | V10: =U10/F10 -> 0.085083183 | W10: 421 | X10: =W10/F10 -> 0.0020045901 | Y10: 20720 | Z10: =Y10/F10 -> 0.09865821 | AA10: 17620 | AB10: =AA10/D10 -> 0.38384455 | AC10: =SUM(Y10+AA10) -> 38340 | AD10: =AC10/F10 -> 0.18255578 | AE10: 12515 | AF10: =AE10/F10 -> 0.05959013 | AG10: 19930 | AH10: =AG10/F10 -> 0.094896628 | AI10: 14795 | AJ10: =AI10/F10 -> 0.070446343 | AK10: 15445 | AL10: =AK10/F10 -> 0.073541316
D11: 45905 | E11: 五 | F11: =SUM(M11,S11,U11,W11,AC11,AE11,AG11,AI11,AK11) -> 186157 | G11: =SUM(F11:F17) -> 1537659 | I11: 33916 | J11: =I11/F11 -> 0.1821903 | K11: 39665 | L11: =K11/F11 -> 0.21307284 | M11: =SUM(I11+K11) -> 73581 | N11: =M11/F11 -> 0.39526314 | O11: 4809 | P11: =O11/F11 -> 0.025833033 | Q11: 3410 | R11: =Q11/D11 -> 0.074283847 | S11: =SUM(O11+Q11) -> 8219 | T11: =S11/F11 -> 0.044150905 | U11: 15369 | V11: =U11/F11 -> 0.082559345 | W11: 370 | X11: =W11/F11 -> 0.0019875696 | Y11: 18830 | Z11: =Y11/F11 -> 0.10115118 | AA11: 16836 | AB11: =AA11/D11 -> 0.36675743 | AC11: =SUM(Y11+AA11) -> 35666 | AD11: =AC11/F11 -> 0.19159097 | AE11: 10286 | AF11: =AE11/F11 -> 0.055254436 | AG11: 15953 | AH11: =AG11/F11 -> 0.085696482 | AI11: 14584 | AJ11: =AI11/F11 -> 0.078342474 | AK11: 12129 | AL11: =AK11/F11 -> 0.065154681
D12: 45906 | E12: 六 | F12: =SUM(M12,S12,U12,W12,AC12,AE12,AG12,AI12,AK12) -> 195008 | I12: 33111 | J12: =I12/F12 -> 0.16979303 | K12: 42836 | L12: =K12/F12 -> 0.21966278 | M12: =SUM(I12+K12) -> 75947 | N12: =M12/F12 -> 0.38945582 | O12: 4715 | P12: =O12/F12 -> 0.024178495 | Q12: 3410 | R12: =Q12/D12 -> 0.074282229 | S12: =SUM(O12+Q12) -> 8125 | T12: =S12/F12 -> 0.041664957 | U12: 15452 | V12: =U12/F12 -> 0.079237775 | W12: 407 | X12: =W12/F12 -> 0.0020870939 | Y12: 19650 | Z12: =Y12/F12 -> 0.1007651 | AA12: 19314 | AB12: =AA12/D12 -> 0.42072932 | AC12: =SUM(Y12+AA12) -> 38964 | AD12: =AC12/F12 -> 0.19980719 | AE12: 11158 | AF12: =AE12/F12 -> 0.057218165 | AG12: 17712 | AH12: =AG12/F12 -> 0.090827043 | AI12: 14371 | AJ12: =AI12/F12 -> 0.073694413 | AK12: 12872 | AL12: =AK12/F12 -> 0.066007548
