Workbook

Sheet 填寫舉例
A2: 7 | B2: 月別 | C2: 工廠名 | D2: ・・・・・・・・
A4: （１）收支狀況 | E4: ※單位：千元 | G4: （２）ＫＰＩ達成進度 | M4: （３）業績構成比 | S4: （４）訂單數量構成比
B5: 當月 | C5: 前月 | D5: 差異 | E5: 累計 | H5: KPI | I5: 當月 | J5: 前月 | K5: 累計 | L5: ※補充 | N5: 當月 | O5: 比例 | P5: 前月 | Q5: 差異 | T5: 當月 | U5: 比例 | V5: 前月 | W5: 差異
A6: 業績金額 | B6: 500000 | C6: 510000 | D6: =B6-C6 -> -10000 | E6: =B6+C6 -> 1010000 | G6: 人時生產性1 | H6: 110 | I6: 100 | J6: 90 | L6: 個／MH | M6: 飯糰 | N6: 150000 | O6: =IFERROR(N6/$B$6,"") -> 0.3 | P6: 0.4 | Q6: =IFERROR(O6-P6,"") -> -0.1 | S6: 飯糰 | T6: 35000 | U6: =IFERROR(T6/$B$7,"") -> 0.35 | V6: 0.3 | W6: =IFERROR(U6-V6,"") -> 0.05
A7: 訂單數量 | B7: 100000 | C7: 110000 | D7: =B7-C7 -> -10000 | E7: =B7+C7 -> 210000 | G7: 人時生產性2 | H7: 0.8 | I7: 0.85 | J7: 0.81 | K7: 0.84 | L7: 達成率 | M7: 大口飯糰 | N7: 100000 | O7: =IFERROR(N7/$B$6,"") -> 0.2 | P7: 0.15 | Q7: =IFERROR(O7-P7,"") -> 0.05 | S7: 大口飯糰 | T7: 30000 | U7: =IFERROR(T7/$B$7,"") -> 0.3 | V7: 0.15 | W7: =IFERROR(U7-V7,"") -> 0.15
A8: 材料費 | B8: 250000 | C8: 260000 | D8: =B8-C8 -> -10000 | E8: =B8+C8 -> 510000 | G8: 半成品報廢 | H8: 0.0025 | I8: 0.0024 | J8: 0.0023 | K8: 0.00235 | L8: 報廢率 | M8: 便當 | N8: 160000 | O8: =IFERROR(N8/$B$6,"") -> 0.32 | P8: 0.28 | Q8: =IFERROR(O8-P8,"") -> 0.04 | S8: 便當 | T8: 20000 | U8: =IFERROR(T8/$B$7,"") -> 0.2 | V8: 0.28 | W8: =IFERROR(U8-V8,"") -> -0.08
A9: 材料費率 | B9: =B8/B6 -> 0.5 | C9: =C8/C6 -> 0.50980392 | D9: =B9-C9 -> -0.0098039216 | E9: =(B9+C9)/2 -> 0.50490196 | G9: 半成品超用 | H9: 0.006 | I9: 0.009 | J9: 0.0095 | K9: 0.0092 | L9: 超用率 | M9: 調理麵 | N9: 90000 | O9: =IFERROR(N9/$B$6,"") -> 0.18 | P9: 0.17 | Q9: =IFERROR(O9-P9,"") -> 0.01 | S9: 調理麵 | T9: 15000 | U9: =IFERROR(T9/$B$7,"") -> 0.15 | V9: 0.27 | W9: =IFERROR(U9-V9,"") -> -0.12
A10: 勞務成本 | B10: 100000 | C10: 105000 | D10: =B10-C10 -> -5000 | E10: =B10+C10 -> 205000 | G10: 固定產線 | H10: 0.95 | I10: 0.9 | J10: 0.92 | K10: 0.91 | L10: 導入率 | M10: 調理麵包 | N10: - | O10: =IFERROR(N10/$B$6,"") | P10: -% | Q10: =IFERROR(O10-P10,"") | S10: 調理麵包 | T10: - | U10: =IFERROR(T10/$B$7,"") | V10: -% | W10: =IFERROR(U10-V10,"")
A11: 勞務費率 | B11: =B10/B6 -> 0.2 | C11: =C10/C6 -> 0.20588235 | D11: =B11-C11 -> -0.0058823529 | E11: =(B11+C11)/2 -> 0.20294118 | G11: 教育訓練 | H11: 0.8 | I11: 0.85 | J11: 1 | K11: 0.92 | L11: 實施率 | M11: 袋裝調理麵包 | N11: - | O11: =IFERROR(N11/$B$6,"") | P11: -% | Q11: =IFERROR(O11-P11,"") | S11: 袋裝調理麵包 | T11: - | U11: =IFERROR(T11/$B$7,"") | V11: -% | W11: =IFERROR(U11-V11,"")
M12: 義大利麵 | N12: - | O12: =IFERROR(N12/$B$6,"") | P12: -% | Q12: =IFERROR(O12-P12,"") | S12: 義大利麵 | T12: - | U12: =IFERROR(T12/$B$7,"") | V12: -% | W12: =IFERROR(U12-V12,"")
A13: （５）品群別人時生產性 | M13: 調理包 | N13: - | O13: =IFERROR(N13/$B$6,"") | P13: -% | Q13: =IFERROR(O13-P13,"") | S13: 調理包 | T13: - | U13: =IFERROR(T13/$B$7,"") | V13: -% | W13: =IFERROR(U13-V13,"")
B14: 當月 | C14: 前月 | D14: 差異 | E14: 累計 | H14: 當月 | I14: 前月 | J14: 差異 | K14: 累計 | O14: =SUM(O6:O13) -> 1 | P14: =SUM(P6:P13) -> 1 | U14: =SUM(U6:U13) -> 1 | V14: =SUM(V6:V13) -> 1
A15: 飯糰 | B15: 600 | C15: 660 | D15: =B15-C15 -> -60 | E15: =(B15+C15)/2 -> 630 | G15: 調理麵包 | J15: =H15-I15 -> 0 | M15: （７）原因別分析
A16: 大口飯糰 | B16: 800 | C16: 780 | D16: =B16-C16 -> 20 | E16: =(B16+C16)/2 -> 790 | G16: 袋裝調理麵包 | J16: =H16-I16 -> 0 | N16: 合計 | P16: 作業原因 | R16: 規格原因
A17: 便當 | B17: 130 | C17: 111 | D17: =B17-C17 -> 19 | E17: =(B17+C17)/2 -> 120.5 | G17: 義大利麵 | J17: =H17-I17 -> 0 | N17: 金額 | O17: 比例 | P17: 金額 | Q17: 比例 | R17: 金額 | S17: 比例
A18: 調理麵 | B18: 140 | C18: 165 | D18: =B18-C18 -> -25 | E18: =(B18+C18)/2 -> 152.5 | G18: 調理包 | J18: =H18-I18 -> 0 | M18: 半成品報廢 | N18: 1200 | O18: =N18/$B$6 -> 0.0024 | P18: 900 | Q18: =IFERROR(P18/$B$6,"") -> 0.0018 | R18: 300 | S18: =IFERROR(R18/$B$6,"") -> 0.0006
M19: 半成品超用 | N19: 4500 | O19: =N19/$B$6 -> 0.009 | P19: 3500 | Q19: =IFERROR(P19/$B$6,"") -> 0.007 | R19: 1000 | S19: =IFERROR(R19/$B$6,"") -> 0.002
A20: （６）人時生產性前幾名品項
B21: 排名 | C21: 商品名 | F21: 人數 | G21: 產能 | H21: 人時生產性 | I21: 前月比 | J21: 主要原因&對策 | M21: （８）報廢原因別前幾名品項
A22: 飯糰 | B22: 1 | C22: 手巻明太子 | F22: 3 | G22: 3000 | H22: 1000 | I22: 10 | J22: 減少暫時停止生產,人時UP | M22: 半成品報廢 | N22: 排名 | O22: 商品名 | R22: 半成品名 | U22: 單價 | V22: 報廢率 | W22: 數量 | X22: 金額 | Y22: 前月比 | Z22: 主要原因&對策
B23: 2 | M23: 作業原因 | N23: 1 | O23: 明太子海苔便當 | R23: 油炸白身魚 | U23: 10 | V23: 0.15 | W23: 10 | X23: =W23*U23 -> 100 | Y23: 80 | Z23: 油調過多報廢。變更條件。
B24: 3 | N24: 2 | X24: =W24*U24 -> 0
B25: 4 | N25: 3 | X25: =W25*U25 -> 0
B26: 5 | N26: 4 | X26: =W26*U26 -> 0
B27: ▼1 | C27: 手巻卵黄雞絞肉 | F27: 4 | G27: 2800 | H27: 700 | I27: 6/30新商品 | J27: 因組裝2食材,人員增加,產速減少 | N27: 5 | X27: =W27*U27 -> 0
B28: ▼2 | U28: 前幾名合計比例 | V28: =X28/N18 -> 0.083333333 | W28: 前幾名合計金額 | X28: =SUM(X23:X27) -> 100
B29: ▼3 | M29: 規格原因 | N29: 1 | O29: 海老炒飯 | R29: 川燙蝦子拌醬 | U29: 5.55 | V29: 0.21 | W29: 50 | X29: =W29*U29 -> 277.5 | Y29: 35 | Z29: 蝦子入數不足
B30: ▼4 | N30: 2 | X30: =W30*U30 -> 0
B31: ▼5 | N31: 3 | X31: =W31*U31 -> 0
N32: 4 | X32: =W32*U32 -> 0
B33: 排名 | C33: 商品名 | F33: 人數 | G33: 產能 | H33: 人時生產性 | I33: 前月比 | J33: 主要原因&對策 | N33: 5 | X33: =W33*U33 -> 0
A34: 大口飯糰 | B34: 1 | C34: 直巻明太子美奶茲 | F34: 3 | G34: 2500 | H34: 833.33 | I34: 20 | J34: 透由調整速度提升。 | U34: 前幾名合計比例 | V34: =X34/N18 -> 0.23125 | W34: 前幾名合計金額 | X34: =SUM(X29:X33) -> 277.5
B35: 2
B36: 3 | M36: 半成品超用 | N36: 排名 | O36: 商品名 | R36: 半成品名 | U36: 單價 | V36: 報廢率 | W36: 數量 | X36: 金額 | Y36: 前月比 | Z36: 主要原因&對策
B37: 4 | M37: 作業原因 | N37: 1 | O37: 特製醬汁炙燒牛五花便當 | R37: 牛五花醬汁 | U37: 25 | V37: 0.25 | W37: 10 | X37: =W37*U37 -> 250 | Y37: 150 | Z37: 難度有差異。調理指導。
B38: 5 | N38: 2 | X38: =W38*U38 -> 0
B39: ▼1 | C39: 大口飯糰燒肉美奶滋 | F39: 7 | G39: 2200 | H39: 314.29 | I39: -15 | J39: 因摺疊增員。實施教育訓練。 | N39: 3 | X39: =W39*U39 -> 0
B40: ▼2 | N40: 4 | X40: =W40*U40 -> 0
B41: ▼3 | N41: 5 | X41: =W41*U41 -> 0
B42: ▼4 | U42: 前幾名合計比例 | V42: =X42/N19 -> 0.055555556 | W42: 前幾名合計金額 | X42: =SUM(X37:X41) -> 250
...

Sheet 生產管理報表(月)
A1: 生產管理報表
A3: 月別 | B3: 10 | C3: 工廠 | D3: 晉欣廠
A4: （１）收支狀況 | E4: ※單位：千元 | G4: （２）ＫＰＩ達成進度
A5: 項目 | B5: 當月 | C5: 前月 | D5: 差異 | E5: 累計 | G5: 項目 | H5: KPI | I5: 當月 | J5: 前月 | K5: 累計 | L5: ※補充
A6: 業績金額 | B6: ='（１）收支狀況'!H10/1000 -> 141939.04 | C6: 224463.49 | D6: =B6-C6 -> -82524.45 | E6: =B6 -> 141939.04 | G6: 人時性(個/月均) | H6: 266 | I6: ='（２）ＫＰＩ達成進度'!H6 -> 0 | J6: 330.21458 | K6: =I6 -> 0 | L6: 個／MH
A7: 訂單數量 | B7: ='（１）收支狀況'!K10 -> 4205423 | C7: 6964636 | D7: =B7-C7 -> -2759213 | E7: =B7 -> 4205423 | G7: 人時達成率(%/月均) | H7: 0.8 | I7: ='（２）ＫＰＩ達成進度'!K6 -> 0 | J7: 0.90222562 | K7: =I7 -> 0 | L7: 達成率
A8: 材料費 | B8: ='（１）收支狀況'!N10/1000 -> 94063.857 | C8: 150244.29 | D8: =B8-C8 -> -56180.435 | E8: =B8 -> 94063.857 | G8: 半成品-報廢(%) | H8: 0.0025 | I8: ='（２）ＫＰＩ達成進度'!N6 -> 0 | J8: 0.0024646257 | K8: =I8 -> 0 | L8: 報廢率
A9: 材料費率 | B9: ='（１）收支狀況'!Q10 -> 0.66270604 | C9: 0.66934847 | D9: =B9-C9 -> -0.0066424327 | E9: =B9 -> 0.66270604 | G9: 半成品-超用(%) | H9: 0.0026 | I9: ='（２）ＫＰＩ達成進度'!Q6 -> 0 | J9: 0.0023405371 | K9: =I9 -> 0 | L9: 超用率
A10: 勞務成本 | B10: ='（１）收支狀況'!T10/1000 -> 15900.74 | C10: 32105.787 | D10: =B10-C10 -> -16205.047 | E10: =B10 -> 15900.74 | G10: 固定產線-導入率(%) | H10: 0.8 | I10: ='（２）ＫＰＩ達成進度'!T6 -> 0 | J10: 0.91666667 | K10: =I10 -> 0 | L10: 導入率
A11: 勞務費率 | B11: ='（１）收支狀況'!W10 -> 0.11202513 | C11: 0.14303345 | D11: =B11-C11 -> -0.031008315 | E11: =B11 -> 0.11202513 | G11: 教育訓練-實施率(%) | H11: 1 | I11: ='（２）ＫＰＩ達成進度'!W6 -> 0 | J11: 0.84941935 | K11: =I11 -> 0 | L11: 實施率
A13: （３）業績構成比 | G13: （４）訂單數量構成比
B14: 當月 | C14: 比例 | D14: 前月 | E14: 差異 | H14: 當月 | I14: 比例 | J14: 前月 | K14: 差異
A15: 18℃-飯A15:A23糰(061,063) | B15: ='（３）業績構成比'!M50/1000 -> 30762.097 | C15: =IFERROR(B15/$B$6,"") -> 0.21672753 | D15: 0.19061186 | E15: =IFERROR(C15-D15,"") -> 0.026115674 | G15: 18℃-飯A15:A23糰(061,063) | H15: ='（４）訂單數量構成比'!M50 -> 1693416 | I15: =IFERROR(H15/$B$7,"") -> 0.40267436 | J15: 0.33067557 | K15: =IFERROR(I15-J15,"") -> 0.071998783
A16: 18℃-壽司手卷(071,072,075,076) | B16: ='（３）業績構成比'!S50/1000 -> 2988.5558 | C16: =IFERROR(B16/$B$6,"") -> 0.021055207 | D16: 0.042789234 | E16: =IFERROR(C16-D16,"") -> -0.021734026 | G16: 18℃-壽司手卷(071,072,075,076) | H16: ='（４）訂單數量構成比'!S51 -> 108663 | I16: =IFERROR(H16/$B$7,"") -> 0.02583878 | J16: 0.061681041 | K16: =IFERROR(I16-J16,"") -> -0.035842261
A17: 4℃-飯糰(065) | B17: ='（３）業績構成比'!U50/1000 -> 21763.54 | C17: =IFERROR(B17/$B$6,"") -> 0.1533302 | D17: 0.086938303 | E17: =IFERROR(C17-D17,"") -> 0.066391892 | G17: 4℃-飯糰(065) | H17: ='（４）訂單數量構成比'!U50 -> 656719 | I17: =IFERROR(H17/$B$7,"") -> 0.15616003 | J17: 0.082530228 | K17: =IFERROR(I17-J17,"") -> 0.073629806
A18: 4℃-壽司手卷(077) | B18: ='（３）業績構成比'!W50/1000 -> 1392.3218 | C18: =IFERROR(B18/$B$6,"") -> 0.0098092941 | D18: 0.014659146 | E18: =IFERROR(C18-D18,"") -> -0.0048498519 | G18: 4℃-壽司手卷(077) | H18: ='（４）訂單數量構成比'!W50 -> 38407 | I18: =IFERROR(H18/$B$7,"") -> 0.0091327317 | J18: 0.016773741 | K18: =IFERROR(I18-J18,"") -> -0.0076410092
A19: 主食(091,092,093,094,095) | B19: ='（３）業績構成比'!AC50/1000 -> 36336.604 | C19: =IFERROR(B19/$B$6,"") -> 0.25600148 | D19: 0.24409178 | E19: =IFERROR(C19-D19,"") -> 0.011909705 | G19: 主食(091,092,093,094,095) | H19: ='（４）訂單數量構成比'!AC50 -> 972316 | I19: =IFERROR(H19/$B$7,"") -> 0.23120528 | J19: 0.1967306 | K19: =IFERROR(I19-J19,"") -> 0.034474682
A20: 便當(083) | B20: ='（３）業績構成比'!AE50/1000 -> 29516.542 | C20: =IFERROR(B20/$B$6,"") -> 0.20795225 | D20: 0.13979724 | E20: =IFERROR(C20-D20,"") -> 0.068155011 | G20: 便當(083) | H20: ='（４）訂單數量構成比'!AE50 -> 516380 | I20: =IFERROR(H20/$B$7,"") -> 0.12278907 | J20: 0.079797709 | K20: =IFERROR(I20-J20,"") -> 0.042991366
A21: 熱食義麵(122,123,124,126) | B21: ='（３）業績構成比'!AG50/1000 -> 21833.2 | C21: =IFERROR(B21/$B$6,"") -> 0.15382097 | D21: 0.13619627 | E21: =IFERROR(C21-D21,"") -> 0.017624701 | G21: 熱食義麵(122,123,124,126) | H21: ='（４）訂單數量構成比'!AG50 -> 443539 | I21: =IFERROR(H21/$B$7,"") -> 0.10546834 | J21: 0.090009011 | K21: =IFERROR(I21-J21,"") -> 0.015459333
A22: 季節調理麵(111,112) | B22: ='（３）業績構成比'!AI50/1000 -> 32273.064 | C22: =IFERROR(B22/$B$6,"") -> 0.22737271 | D22: 0.068175374 | E22: =IFERROR(C22-D22,"") -> 0.15919734 | G22: 季節調理麵(111,112) | H22: ='（４）訂單數量構成比'!AI50 -> 857175 | I22: =IFERROR(H22/$B$7,"") -> 0.20382611 | J22: 0.05972114 | K22: =IFERROR(I22-J22,"") -> 0.14410497
A23: 微波小吃(153,154,155) | B23: ='（３）業績構成比'!AK50/1000 -> 17558.118 | C23: =IFERROR(B23/$B$6,"") -> 0.12370183 | D23: 0.076740802 | E23: =IFERROR(C23-D23,"") -> 0.046961023 | G23: 微波小吃(153,154,155) | H23: ='（４）訂單數量構成比'!AK50 -> 598238 | I23: =IFERROR(H23/$B$7,"") -> 0.14225394 | J23: 0.082080959 | K23: =IFERROR(I23-J23,"") -> 0.060172983
C24: =SUM(C15:C23) -> 1.3697715 | D24: =SUM(D15:D23) -> 1 | I24: =SUM(I15:I23) -> 1.3993487 | J24: =SUM(J15:J23) -> 1
A26: （５）品群別人時生產性
A27: 品群 | B27: 當月 | C27: 前月 | D27: 差異 | E27: 累計 | M27: 8月 | N27: 9月 | O27: 10月 | P27: 11月 | Q27: 12月
A28: 18℃-飯A15:A23糰(061,063) | B28: ='（５-1）品群別人時生產性（18℃-飯糰）'!$C$1 -> 839.68042 | C28: 756.20247 | D28: =B28-C28 -> 83.477945 | E28: =R28 -> 778.60397 | M28: 717.52753 | N28: =B28 -> 839.68042 | R28: =AVERAGE(M28:Q28) -> 778.60397
A29: 18℃-壽司手卷(071,072,075,076) | B29: ='（５-2）品群別人時生產性（18-壽司手卷)'!$C$1 -> 145.48598 | C29: 198.82982 | D29: =B29-C29 -> -53.34384 | E29: =R29 -> 171.55935 | M29: 197.63272 | N29: =B29 -> 145.48598 | R29: =AVERAGE(M29:Q29) -> 171.55935
A30: 4℃-飯糰(065) | B30: ='（５-3）品群別人時生產性（4℃-飯糰)'!$C$1 -> 222.80935 | C30: 253.36933 | D30: =B30-C30 -> -30.559982 | E30: =R30 -> 231.63396 | M30: 240.45857 | N30: =B30 -> 222.80935 | R30: =AVERAGE(M30:Q30) -> 231.63396
A31: 4℃-壽司手卷(077) | B31: ='（５-4）品群別人時生產性（4℃-壽司手卷)'!$C$1 -> 115.68224 | C31: 112.99131 | D31: =B31-C31 -> 2.6909279 | E31: =R31 -> 111.27368 | M31: 106.86512 | N31: =B31 -> 115.68224 | R31: =AVERAGE(M31:Q31) -> 111.27368
A32: 主食(091,092,093,094,095) | B32: ='（５-5）品群別人時生產性(主食) '!$C$1 -> 89.013864 | C32: 85.495684 | D32: =B32-C32 -> 3.5181792 | E32: =R32 -> 89.162146 | M32: 89.310428 | N32: =B32 -> 89.013864 | R32: =AVERAGE(M32:Q32) -> 89.162146
A33: 便當(083) | B33: ='（５-6）品群別人時生產性(便當)'!$C$1 -> 71.849726 | C33: 66.943614 | D33: =B33-C33 -> 4.9061125 | E33: =R33 -> 68.761234 | M33: 65.672742 | N33: =B33 -> 71.849726 | R33: =AVERAGE(M33:Q33) -> 68.761234
A34: 熱食義麵(122,123,124,126) | B34: ='（５-7）品群別人時生產性(熱食義麵) '!$C$1 -> 84.276739 | C34: 80.555861 | D34: =B34-C34 -> 3.7208778 | E34: =R34 -> 79.877654 | M34: 75.478569 | N34: =B34 -> 84.276739 | R34: =AVERAGE(M34:Q34) -> 79.877654
A35: 季節調理麵(111,112) | B35: ='（５-8）品群別人時生產性(季節調理麵) '!$C$1 -> 128.82778 | C35: 121.13263 | D35: =B35-C35 -> 7.6951531 | E35: =R35 -> 121.66668 | M35: 114.50557 | N35: =B35 -> 128.82778 | R35: =AVERAGE(M35:Q35) -> 121.66668
A36: 微波小吃(153,154,155) | B36: ='（５-9）品群別人時生產性(微波小吃)'!$C$1 -> 147.50807 | C36: 115.36623 | D36: =B36-C36 -> 32.141842 | E36: =R36 -> 123.5782 | M36: 99.648342 | N36: =B36 -> 147.50807 | R36: =AVERAGE(M36:Q36) -> 123.5782

Sheet 生產管理報表(週) 
A1: 生產管理報表
A3: 月別 | B3: 6 | C3: 週別 | D3: W2 | E3: 工廠 | F3: 晉欣廠
A4: （１）收支狀況 | E4: ※單位：千元 | G4: （２）ＫＰＩ達成進度
A5: 項目 | B5: 當週 | C5: 前週 | D5: 差異 | E5: 累計 | G5: 項目 | H5: KPI | I5: 當週 | J5: 前週 | K5: 累計 | L5: ※補充
A6: 業績金額 | B6: ='（１）收支狀況'!G19/1000 -> 67337.724 | C6: 65024.924 | D6: =B6-C6 -> 2312.8 | E6: ='（１）收支狀況'!H10/1000 -> 141939.04 | G6: 人時性(個/月均) | H6: 366 | I6: ='（２）ＫＰＩ達成進度'!G19 -> 363.48965 | J6: 364.54238 | K6: ='（２）ＫＰＩ達成進度'!H10 -> 364.52604 | L6: 個／MH
A7: 訂單數量 | B7: ='（１）收支狀況'!J19 -> 1972746 | C7: 1939291 | D7: =B7-C7 -> 33455 | E7: ='（１）收支狀況'!K10 -> 4205423 | G7: 人時達成率(%/月均) | H7: 0.8 | I7: ='（２）ＫＰＩ達成進度'!J19 -> 0.99314112 | J7: 0.99601743 | K7: ='（２）ＫＰＩ達成進度'!K10 -> 0.49798639 | L7: 達成率
A8: 材料費 | B8: ='（１）收支狀況'!M19/1000 -> 44459.108 | C8: =43241268/1000 -> 43241.268 | D8: =B8-C8 -> 1217.84 | E8: ='（１）收支狀況'!N10/1000 -> 94063.857 | G8: 半成品-報廢(%) | H8: 0.0025 | I8: ='（２）ＫＰＩ達成進度'!M19 -> 0.0024261464 | J8: 0.0024182194 | K8: ='（２）ＫＰＩ達成進度'!N10 -> 0.0024212211 | L8: 報廢率
A9: 材料費率 | B9: ='（１）收支狀況'!P19 -> 0.66024073 | C9: 0.66499529 | D9: =B9-C9 -> -0.0047545578 | E9: ='（１）收支狀況'!Q10 -> 0.66270604 | G9: 半成品-超用(%) | H9: 0.0026 | I9: ='（２）ＫＰＩ達成進度'!P19 -> 0.0039141798 | J9: 0.0040596366 | K9: ='（２）ＫＰＩ達成進度'!Q10 -> 0.0039869992 | L9: 超用率
A10: 勞務成本 | B10: ='（１）收支狀況'!S19/1000 -> 7500.351 | C10: 7317.7016 | D10: =B10-C10 -> 182.64936 | E10: ='（１）收支狀況'!T10/1000 -> 15900.74 | G10: 固定產線-導入率(%) | H10: 0.8 | I10: 0.9119 | J10: 0.9112 | K10: 0.917 | L10: 導入率
A11: 勞務費率 | B11: ='（１）收支狀況'!V19 -> 0.11138409 | C11: 0.11253687 | D11: =B11-C11 -> -0.001152785 | E11: ='（１）收支狀況'!W10 -> 0.11202513 | G11: 教育訓練-實施率(%) | H11: 1 | I11: ='（２）ＫＰＩ達成進度'!V19 -> 0.42914286 | J11: 0.41571429 | K11: ='（２）ＫＰＩ達成進度'!W10 -> 0.42133333 | L11: 實施率
A13: （３）業績構成比 | G13: （４）訂單數量構成比
B14: 當週 | C14: 比例 | D14: 前週 | E14: 差異 | H14: 當週 | I14: 比例 | J14: 前週 | K14: 差異
A15: 18℃-飯糰(061,063) | B15: =SUM('（３）業績構成比'!I21:I48,'（３）業績構成比'!K21:K48)/1000 -> 10330.654 | C15: =IFERROR(B15/$B$6,"") -> 0.15341556 | D15: 0.16621154 | E15: =IFERROR(C15-D15,"") -> -0.012795983 | G15: 18℃-飯糰(061,063) | H15: =SUM(,'（４）訂單數量構成比'!I21:I48,'（４）訂單數量構成比'!K21:K48) -> 540219 | I15: =IFERROR(H15/$B$7,"") -> 0.27384113 | J15: 0.29034322 | K15: =IFERROR(I15-J15,"") -> -0.01650209
A16: 18℃-壽司手卷(071,072,075,076) | B16: =SUM('（３）業績構成比'!O21:O48,'（３）業績構成比'!Q21:Q48)/1000 -> 1053.3089 | C16: =IFERROR(B16/$B$6,"") -> 0.015642181 | D16: 0.016103389 | E16: =IFERROR(C16-D16,"") -> -0.00046120755 | G16: 18℃-壽司手卷(071,072,075,076) | H16: =SUM('（４）訂單數量構成比'!O21:O48,'（４）訂單數量構成比'!Q21:Q48) -> 36405 | I16: =IFERROR(H16/$B$7,"") -> 0.018453972 | J16: 0.018619691 | K16: =IFERROR(I16-J16,"") -> -0.00016571914
A17: 4℃-飯糰(065) | B17: =SUM('（３）業績構成比'!U21:U48)/1000 -> 8189.4134 | C17: =IFERROR(B17/$B$6,"") -> 0.12161702 | D17: 0.10291392 | E17: =IFERROR(C17-D17,"") -> 0.018703107 | G17: 4℃-飯糰(065) | H17: =SUM('（４）訂單數量構成比'!U21:U48) -> 249379 | I17: =IFERROR(H17/$B$7,"") -> 0.12641212 | J17: 0.10332075 | K17: =IFERROR(I17-J17,"") -> 0.023091368
A18: 4℃-壽司手卷(077) | B18: =SUM('（３）業績構成比'!W21:W48)/1000 -> 409.14086 | C18: =IFERROR(B18/$B$6,"") -> 0.0060759532 | D18: 0.006730736 | E18: =IFERROR(C18-D18,"") -> -0.00065478279 | G18: 4℃-壽司手卷(077) | H18: =SUM('（４）訂單數量構成比'!W21:W48) -> 11263 | I18: =IFERROR(H18/$B$7,"") -> 0.0057093006 | J18: 0.0062141267 | K18: =IFERROR(I18-J18,"") -> -0.00050482607
A19: 主食(091,092,093,094,095) | B19: =SUM('（３）業績構成比'!Y21:Y48,'（３）業績構成比'!AA21:AA48)/1000 -> 13489.058 | C19: =IFERROR(B19/$B$6,"") -> 0.20031948 | D19: 0.19090511 | E19: =IFERROR(C19-D19,"") -> 0.0094143746 | G19: 主食(091,092,093,094,095) | H19: =SUM('（４）訂單數量構成比'!Y21:Y48,'（４）訂單數量構成比'!AA21:AA48) -> 339001 | I19: =IFERROR(H19/$B$7,"") -> 0.17184219 | J19: 0.1620716 | K19: =IFERROR(I19-J19,"") -> 0.0097705911
A20: 便當(083) | B20: =SUM('（３）業績構成比'!AE21:AE48)/1000 -> 9666.6292 | C20: =IFERROR(B20/$B$6,"") -> 0.14355444 | D20: 0.15122734 | E20: =IFERROR(C20-D20,"") -> -0.0076728972 | G20: 便當(083) | H20: =SUM('（４）訂單數量構成比'!AE21:AE48) -> 167384 | I20: =IFERROR(H20/$B$7,"") -> 0.084848227 | J20: 0.089038726 | K20: =IFERROR(I20-J20,"") -> -0.0041904992
A21: 熱食義麵(122,123,124,126) | B21: =SUM('（３）業績構成比'!AG21:AG48)/1000 -> 7849.4712 | C21: =IFERROR(B21/$B$6,"") -> 0.1165687 | D21: 0.10052517 | E21: =IFERROR(C21-D21,"") -> 0.01604353 | G21: 熱食義麵(122,123,124,126) | H21: =SUM('（４）訂單數量構成比'!AG21:AG48) -> 159573 | I21: =IFERROR(H21/$B$7,"") -> 0.080888771 | J21: 0.068319814 | K21: =IFERROR(I21-J21,"") -> 0.012568957
A22: 季節調理麵(111,112) | B22: =SUM('（３）業績構成比'!AI21:AI48)/1000 -> 10375.067 | C22: =IFERROR(B22/$B$6,"") -> 0.15407511 | D22: 0.1681122 | E22: =IFERROR(C22-D22,"") -> -0.014037096 | G22: 季節調理麵(111,112) | H22: =SUM('（４）訂單數量構成比'!AI21:AI48) -> 266668 | I22: =IFERROR(H22/$B$7,"") -> 0.13517604 | J22: 0.15075561 | K22: =IFERROR(I22-J22,"") -> -0.015579567
A23: 微波小吃(153,154,155) | B23: =SUM('（３）業績構成比'!AK21:AK48)/1000 -> 5974.981 | C23: =IFERROR(B23/$B$6,"") -> 0.088731556 | D23: 0.0972706 | E23: =IFERROR(C23-D23,"") -> -0.0085390449 | G23: 微波小吃(153,154,155) | H23: =SUM('（４）訂單數量構成比'!AK21:AK48) -> 202854 | I23: =IFERROR(H23/$B$7,"") -> 0.10282824 | J23: 0.11131646 | K23: =IFERROR(I23-J23,"") -> -0.0084882149
C24: =SUM(C15:C23) -> 1 | D24: =SUM(D15:D23) -> 1 | I24: =SUM(I15:I23) -> 1 | J24: =SUM(J15:J23) -> 1
A26: （５）品群別人時生產性
A27: 品群 | B27: 當週 | C27: 前週 | D27: 差異 | E27: 累計
A28: 18℃-飯糰(061,063) | B28: ='（５-1）品群別人時生產性（18℃-飯糰）'!L77 -> 839.18138 | C28: 840.02598 | D28: =B28-C28 -> -0.84460154 | E28: ='（５-1）品群別人時生產性（18℃-飯糰）'!C1 -> 839.68042
A29: 18℃-壽司手卷(071,072,075,076) | B29: ='（５-2）品群別人時生產性（18-壽司手卷)'!L47 -> 137.8998 | C29: 147.47154 | D29: =B29-C29 -> -9.5717407 | E29: ='（５-2）品群別人時生產性（18-壽司手卷)'!C1 -> 145.48598
A30: 4℃-飯糰(065) | B30: ='（５-3）品群別人時生產性（4℃-飯糰)'!L47 -> 207.11565 | C30: 229.24447 | D30: =B30-C30 -> -22.128825 | E30: ='（５-3）品群別人時生產性（4℃-飯糰)'!C1 -> 222.80935
A31: 4℃-壽司手卷(077) | B31: ='（５-4）品群別人時生產性（4℃-壽司手卷)'!L47 -> 111.5543 | C31: 117.78208 | D31: =B31-C31 -> -6.2277795 | E31: ='（５-4）品群別人時生產性（4℃-壽司手卷)'!C1 -> 115.68224
A32: 主食(091,092,093,094,095) | B32: ='（５-5）品群別人時生產性(主食) '!L77 -> 88.755236 | C32: 89.042978 | D32: =B32-C32 -> -0.28774247 | E32: ='（５-5）品群別人時生產性(主食) '!C1 -> 89.013864
A33: 便當(083) | B33: ='（５-6）品群別人時生產性(便當)'!L47 -> 71.08539 | C33: 71.995438 | D33: =B33-C33 -> -0.91004779 | E33: ='（５-6）品群別人時生產性(便當)'!C1 -> 71.849726
A34: 熱食義麵(122,123,124,126) | B34: ='（５-7）品群別人時生產性(熱食義麵) '!L47 -> 83.032083 | C34: 84.277715 | D34: =B34-C34 -> -1.2456315 | E34: ='（５-7）品群別人時生產性(熱食義麵) '!C1 -> 84.276739
A35: 季節調理麵(111,112) | B35: ='（５-8）品群別人時生產性(季節調理麵) '!L47 -> 127.10791 | C35: 129.428 | D35: =B35-C35 -> -2.320091 | E35: ='（５-8）品群別人時生產性(季節調理麵) '!C1 -> 128.82778
A36: 微波小吃(153,154,155) | B36: ='（５-9）品群別人時生產性(微波小吃)'!L47 -> 150.29771 | C36: 148.81056 | D36: =B36-C36 -> 1.4871478 | E36: ='（５-9）品群別人時生產性(微波小吃)'!C1 -> 147.50807

Sheet （１）收支狀況
B2: （１）收支狀況
C3: 月份 | D3: 日期 | F3: 營業額(元) | I3: 訂單數量(個) | L3: 材料費(元) | O3: 材料費率（材料費／營業額） | R3: 勞務成本（全廠人事成本） | U3: 勞務費率（勞務成本／營業額）
F4: 日 | G4: 週累積 | H4: 月累積 | I4: 日 | J4: 週累積 | K4: 月累積 | L4: 日 | M4: 週累積 | N4: 月累積 | O4: 日 | P4: 週累積 | Q4: 月平均 | R4: 日 | S4: 週累積 | T4: 月累積 | U4: 日 | V4: 週累積 | W4: 月平均
D5: 46168 | E5: 二 | F5: 9911969 | I5: 293602 | L5: 6374930 | O5: =L5/F5 -> 0.64315476 | R5: 1112117.7 | U5: =R5/F5 -> 0.11219947
D6: =D5+1 -> 46169 | E6: 三 | F6: 9723654 | G6: =SUM(F5:F11) -> 65939025 | I6: 289569 | J6: =SUM(I5:I11) -> 1972816 | L6: 6417155 | M6: =SUM(L5:L11) -> 43902368 | O6: =L6/F6 -> 0.65995304 | P6: =M6/G6 -> 0.6658025 | R6: 1109096.6 | S6: =SUM(R5:R11) -> 7722861.6 | U6: =R6/F6 -> 0.11406171 | V6: =S6/G6 -> 0.11712126
D7: =D6+1 -> 46170 | E7: 四 | F7: 9072400 | I7: 272954 | L7: 6318977 | O7: =L7/F7 -> 0.69650556 | R7: 1092100 | U7: =R7/F7 -> 0.12037609
D8: =D7+1 -> 46171 | E8: 五 | F8: 8447568 | I8: 253473 | L8: 5651856 | O8: =L8/F8 -> 0.66905126 | R8: 1098880 | U8: =R8/F8 -> 0.13008241
D9: =D8+1 -> 46172 | E9: 六 | F9: 8820596 | I9: 262061 | L9: 6178518 | O9: =L9/F9 -> 0.70046491 | R9: 1087933.1 | U9: =R9/F9 -> 0.12334009
D10: =D9+1 -> 46173 | E10: 日 | F10: 10386449 | H10: =SUM(F11:F40) -> 141939037 | I10: 307771 | K10: =SUM(I11:I40) -> 4205423 | L10: 6597451 | N10: =SUM(L11:L40) -> 94063857 | O10: =L10/F10 -> 0.63519794 | Q10: =N10/H10 -> 0.66270604 | R10: 1140047.1 | T10: =SUM(R11:R40) -> 15900740 | U10: =R10/F10 -> 0.10976293 | W10: =T10/H10 -> 0.11202513
D11: =D10+1 -> 46174 | E11: 一 | F11: 9576389 | I11: 293386 | L11: 6363481 | O11: =L11/F11 -> 0.66449692 | R11: 1082687 | U11: =R11/F11 -> 0.11305796
D12: =D11+1 -> 46175 | E12: 二 | F12: 10050370 | G12: =SUM(F12:F18) -> 65024924 | I12: 300488 | J12: =SUM(I12:I18) -> 1939291 | L12: 6856363 | M12: =SUM(L12:L18) -> 43241268 | O12: =L12/F12 -> 0.68220006 | P12: =M12/G12 -> 0.66499529 | R12: 1044240.8 | S12: =SUM(R12:R18) -> 7317701.6 | U12: =R12/F12 -> 0.10390073 | V12: =S12/G12 -> 0.11253687
D13: =D12+1 -> 46176 | E13: 三 | F13: 9327317 | I13: 281796 | L13: 6164696 | O13: =L13/F13 -> 0.66092918 | R13: 1042886.6 | U13: =R13/F13 -> 0.11180993
D14: =D13+1 -> 46177 | E14: 四 | F14: 8845232 | I14: 268178 | L14: 6263259 | O14: =L14/F14 -> 0.70809437 | R14: 1038657.2 | U14: =R14/F14 -> 0.11742566
D15: =D14+1 -> 46178 | E15: 五 | F15: 7987767 | I15: 238249 | L15: 5445047 | O15: =L15/F15 -> 0.68167324 | R15: 1029297.8 | U15: =R15/F15 -> 0.12885927
D16: =D15+1 -> 46179 | E16: 六 | F16: 8617242 | I16: 254956 | L16: 5396723 | O16: =L16/F16 -> 0.62627033 | R16: 1010559 | U16: =R16/F16 -> 0.11727174
D17: =D16+1 -> 46180 | E17: 日 | F17: 10141059 | I17: 300446 | L17: 6588739 | O17: =L17/F17 -> 0.64970917 | R17: 1066733 | U17: =R17/F17 -> 0.10518951
D18: =D17+1 -> 46181 | E18: 一 | F18: 10055937 | I18: 295178 | L18: 6526441 | O18: =L18/F18 -> 0.64901371 | R18: 1085327.2 | U18: =R18/F18 -> 0.107929
D19: =D18+1 -> 46182 | E19: 二 | F19: 10760813 | G19: =SUM(F19:F25) -> 67337724 | I19: 310985 | J19: =SUM(I19:I25) -> 1972746 | L19: 6868993 | M19: =SUM(L19:L25) -> 44459108 | O19: =L19/F19 -> 0.63833402 | P19: =M19/G19 -> 0.66024073 | R19: 1093226.5 | S19: =SUM(R19:R25) -> 7500351 | U19: =R19/F19 -> 0.1015933 | V19: =S19/G19 -> 0.11138409
D20: =D19+1 -> 46183 | E20: 三 | F20: 10128071 | I20: 294581 | L20: 6710507 | O20: =L20/F20 -> 0.66256516 | R20: 1099151.4 | U20: =R20/F20 -> 0.10852524
D21: =D20+1 -> 46184 | E21: 四 | F21: 9476070 | I21: 277313 | L21: 6182007 | O21: =L21/F21 -> 0.65238089 | R21: 1066363.7 | U21: =R21/F21 -> 0.11253227
D22: =D21+1 -> 46185 | E22: 五 | F22: 8134246 | I22: 242704 | L22: 5946608 | O22: =L22/F22 -> 0.73105829 | R22: 1054301.7 | U22: =R22/F22 -> 0.12961271
D23: =D22+1 -> 46186 | E23: 六 | F23: 8644943 | I23: 255973 | L23: 5579659 | O23: =L23/F23 -> 0.64542461 | R23: 1039399.8 | U23: =R23/F23 -> 0.12023212
D24: =D23+1 -> 46187 | E24: 日 | F24: 10278251 | I24: 301170 | L24: 6634444 | O24: =L24/F24 -> 0.64548375 | R24: 1072512.6 | U24: =R24/F24 -> 0.10434777
D25: =D24+1 -> 46188 | E25: 一 | F25: 9915330 | I25: 290020 | L25: 6536890 | O25: =L25/F25 -> 0.65927105 | R25: 1075395.4 | U25: =R25/F25 -> 0.10845785
D26: =D25+1 -> 46189 | E26: 二 | G26: =SUM(F26:F32) -> 0 | J26: =SUM(I26:I32) -> 0 | M26: =SUM(L26:L32) -> 0 | O26: =L26/F26 -> #DIV/0! | P26: =M26/G26 -> #DIV/0! | S26: =SUM(R26:R32) -> 0 | U26: =R26/F26 -> #DIV/0! | V26: =S26/G26 -> #DIV/0!
D27: =D26+1 -> 46190 | E27: 三 | O27: =L27/F27 -> #DIV/0! | U27: =R27/F27 -> #DIV/0!
D28: =D27+1 -> 46191 | E28: 四 | O28: =L28/F28 -> #DIV/0! | U28: =R28/F28 -> #DIV/0!
D29: =D28+1 -> 46192 | E29: 五 | O29: =L29/F29 -> #DIV/0! | U29: =R29/F29 -> #DIV/0!
D30: =D29+1 -> 46193 | E30: 六 | O30: =L30/F30 -> #DIV/0! | U30: =R30/F30 -> #DIV/0!
D31: =D30+1 -> 46194 | E31: 日 | O31: =L31/F31 -> #DIV/0! | U31: =R31/F31 -> #DIV/0!
D32: =D31+1 -> 46195 | E32: 一 | O32: =L32/F32 -> #DIV/0! | U32: =R32/F32 -> #DIV/0!
D33: =D32+1 -> 46196 | E33: 二 | G33: =SUM(F33:F39) -> 0 | J33: =SUM(I33:I39) -> 0 | M33: =SUM(L33:L39) -> 0 | O33: =L33/F33 -> #DIV/0! | P33: =M33/G33 -> #DIV/0! | S33: =SUM(R33:R39) -> 0 | U33: =R33/F33 -> #DIV/0! | V33: =S33/G33 -> #DIV/0!
D34: =D33+1 -> 46197 | E34: 三 | O34: =L34/F34 -> #DIV/0! | U34: =R34/F34 -> #DIV/0!
D35: =D34+1 -> 46198 | E35: 四 | O35: =L35/F35 -> #DIV/0! | U35: =R35/F35 -> #DIV/0!
D36: =D35+1 -> 46199 | E36: 五 | O36: =L36/F36 -> #DIV/0! | U36: =R36/F36 -> #DIV/0!
D37: =D36+1 -> 46200 | E37: 六 | O37: =L37/F37 -> #DIV/0! | U37: =R37/F37 -> #DIV/0!
D38: =D37+1 -> 46201 | E38: 日 | O38: =L38/F38 -> #DIV/0! | U38: =R38/F38 -> #DIV/0!
D39: =D38+1 -> 46202 | E39: 一 | O39: =L39/F39 -> #DIV/0! | U39: =R39/F39 -> #DIV/0!
D40: =D39+1 -> 46203 | E40: 二 | O40: =L40/F40 -> #DIV/0! | U40: =R40/F40 -> #DIV/0!
D41: =D40+1 -> 46204 | E41: 三 | O41: =L41/F41 -> #DIV/0! | U41: =R41/F41 -> #DIV/0!
...

Sheet （２）ＫＰＩ達成進度
B1: KPI | C1: 366
B2: （２）ＫＰＩ達成進度
C3: 月份 | D3: 日期 | F3: 人時生產性(個/人) | I3: 人時生產性達成率(%) | L3: 半成品報廢(%) | O3: 半成品超用(%) | R3: 固定產線-導入率(固定產線數/總產線數) | U3: 教育訓練-實施率(進度/計畫)
F4: 日 | G4: 週平均 | H4: 月平均 | I4: 日 | J4: 週平均 | K4: 月平均 | L4: 日 | M4: 週平均 | N4: 月平均 | O4: 日 | P4: 週平均 | Q4: 月平均 | R4: 日 | S4: 週平均 | T4: 月平均 | U4: 日 | V4: 週平均 | W4: 月平均
D5: 46168 | E5: 二 | F5: 365.46905 | I5: =F5/$C$1 -> 0.99854932 | L5: 0.0024291591 | O5: 0.0041233462 | R5: 0.917 | U5: 0.39
D6: =D5+1 -> 46169 | E6: 三 | F6: 366.33394 | G6: =AVERAGE(F5:F11) -> 367.41016 | I6: =F6/$C$1 -> 1.0009124 | J6: =AVERAGE(I5:I11) -> 1.0038529 | L6: 0.0024428817 | M6: =AVERAGE(L5:L11) -> 0.0024230796 | O6: 0.0042721649 | P6: =AVERAGE(O5:O11) -> 0.0042109245 | R6: 0.917 | S6: =AVERAGE(R5:R11) -> 0.917 | U6: 0.39 | V6: =AVERAGE(U5:U11) -> 0.39885714
D7: =D6+1 -> 46170 | E7: 四 | F7: 364.47071 | I7: =F7/$C$1 -> 0.99582162 | L7: 0.0024289743 | O7: 0.004299641 | R7: 0.917 | U7: 0.394
D8: =D7+1 -> 46171 | E8: 五 | F8: 368.63145 | I8: =F8/$C$1 -> 1.0071898 | L8: 0.0024027455 | O8: 0.0043797814 | R8: 0.917 | U8: 0.4
D9: =D8+1 -> 46172 | E9: 六 | F9: 368.64391 | I9: =F9/$C$1 -> 1.0072238 | L9: 0.0024216396 | O9: 0.0043383676 | R9: 0.917 | U9: 0.406
D10: =D9+1 -> 46173 | E10: 日 | F10: 366.65571 | H10: =AVERAGE(F11:F40) -> 364.52604 | I10: =F10/$C$1 -> 1.0017916 | K10: =AVERAGE(I11:I40) -> 0.49798639 | L10: 0.0024284001 | N10: =AVERAGE(L11:L40) -> 0.0024212211 | O10: 0.0040748978 | Q10: =AVERAGE(O11:O40) -> 0.0039869992 | R10: 0.917 | T10: =AVERAGE(R11:R40) -> 0.917 | U10: 0.406 | W10: =AVERAGE(U11:U40) -> 0.42133333
D11: =D10+1 -> 46174 | E11: 一 | F11: 371.66632 | I11: =F11/$C$1 -> 1.0154818 | L11: 0.0024077567 | O11: 0.0039882727 | R11: 0.917 | U11: 0.406
D12: =D11+1 -> 46175 | E12: 二 | F12: 370.67658 | G12: =AVERAGE(F12:F18) -> 364.54238 | I12: =F12/$C$1 -> 1.0127775 | J12: =AVERAGE(I12:I18) -> 0.99601743 | L12: 0.0024227496 | M12: =AVERAGE(L12:L18) -> 0.0024182194 | O12: 0.0040124284 | P12: =AVERAGE(O12:O18) -> 0.0040596366 | R12: 0.917 | S12: =AVERAGE(R12:R18) -> 0.917 | U12: 0.41 | V12: =AVERAGE(U12:U18) -> 0.41571429
D13: =D12+1 -> 46176 | E13: 三 | F13: 366.86756 | I13: =F13/$C$1 -> 1.0023704 | L13: 0.0024102441 | O13: 0.003959373 | R13: 0.917 | U13: 0.412
D14: =D13+1 -> 46177 | E14: 四 | F14: 359.41814 | I14: =F14/$C$1 -> 0.98201677 | L14: 0.0024276129 | O14: 0.0041764268 | R14: 0.917 | U14: 0.414
D15: =D14+1 -> 46178 | E15: 五 | F15: 369.02787 | I15: =F15/$C$1 -> 1.0082729 | L15: 0.0024222502 | O15: 0.0040923192 | R15: 0.917 | U15: 0.414
D16: =D15+1 -> 46179 | E16: 六 | F16: 363.33291 | I16: =F16/$C$1 -> 0.99271287 | L16: 0.0024053682 | O16: 0.0041366707 | R16: 0.917 | U16: 0.418
D17: =D16+1 -> 46180 | E17: 日 | F17: 365.40695 | I17: =F17/$C$1 -> 0.99837964 | L17: 0.0024270319 | O17: 0.0039796121 | R17: 0.917 | U17: 0.42
D18: =D17+1 -> 46181 | E18: 一 | F18: 357.06665 | I18: =F18/$C$1 -> 0.97559194 | L18: 0.0024122789 | O18: 0.0040606261 | R18: 0.917 | U18: 0.422
D19: =D18+1 -> 46182 | E19: 二 | F19: 361.77347 | G19: =AVERAGE(F19:F25) -> 363.48965 | I19: =F19/$C$1 -> 0.98845209 | J19: =AVERAGE(I19:I25) -> 0.99314112 | L19: 0.0024178961 | M19: =AVERAGE(L19:L25) -> 0.0024261464 | O19: 0.0038961241 | P19: =AVERAGE(O19:O25) -> 0.0039141798 | R19: 0.917 | S19: =AVERAGE(R19:R25) -> 0.917 | U19: 0.424 | V19: =AVERAGE(U19:U25) -> 0.42914286
D20: =D19+1 -> 46183 | E20: 三 | F20: 363.43751 | I20: =F20/$C$1 -> 0.99299865 | L20: 0.0024195332 | O20: 0.0039686323 | R20: 0.917 | U20: 0.426
D21: =D20+1 -> 46184 | E21: 四 | F21: 367.04822 | I21: =F21/$C$1 -> 1.002864 | L21: 0.0024165413 | O21: 0.0037696861 | R21: 0.917 | U21: 0.428
D22: =D21+1 -> 46185 | E22: 五 | F22: 367.0058 | I22: =F22/$C$1 -> 1.0027481 | L22: 0.0024410848 | O22: 0.0040311016 | R22: 0.917 | U22: 0.43
D23: =D22+1 -> 46186 | E23: 六 | F23: 370.92054 | I23: =F23/$C$1 -> 1.0134441 | L23: 0.0024391534 | O23: 0.0039348356 | R23: 0.917 | U23: 0.43
D24: =D23+1 -> 46187 | E24: 日 | F24: 357.56454 | I24: =F24/$C$1 -> 0.97695231 | L24: 0.0024313741 | O24: 0.0038621291 | R24: 0.917 | U24: 0.432
D25: =D24+1 -> 46188 | E25: 一 | F25: 356.67748 | I25: =F25/$C$1 -> 0.97452863 | L25: 0.0024174418 | O25: 0.0039367498 | R25: 0.917 | U25: 0.434
D26: =D25+1 -> 46189 | E26: 二 | G26: =AVERAGE(F26:F32) -> #DIV/0! | I26: =F26/$C$1 -> 0 | J26: =AVERAGE(I26:I32) -> 0 | M26: =AVERAGE(L26:L32) -> #DIV/0! | P26: =AVERAGE(O26:O32) -> #DIV/0! | S26: =AVERAGE(R26:R32) -> #DIV/0! | V26: =AVERAGE(U26:U32) -> #DIV/0!
D27: =D26+1 -> 46190 | E27: 三 | I27: =F27/$C$1 -> 0
D28: =D27+1 -> 46191 | E28: 四 | I28: =F28/$C$1 -> 0
D29: =D28+1 -> 46192 | E29: 五 | I29: =F29/$C$1 -> 0
D30: =D29+1 -> 46193 | E30: 六 | I30: =F30/$C$1 -> 0
D31: =D30+1 -> 46194 | E31: 日 | I31: =F31/$C$1 -> 0
D32: =D31+1 -> 46195 | E32: 一 | I32: =F32/$C$1 -> 0
D33: =D32+1 -> 46196 | E33: 二 | G33: =AVERAGE(F33:F39) -> #DIV/0! | I33: =F33/$C$1 -> 0 | J33: =AVERAGE(I33:I39) -> 0 | M33: =AVERAGE(L33:L39) -> #DIV/0! | P33: =AVERAGE(O33:O39) -> #DIV/0! | S33: =AVERAGE(R33:R39) -> #DIV/0! | V33: =AVERAGE(U33:U39) -> #DIV/0!
D34: =D33+1 -> 46197 | E34: 三 | I34: =F34/$C$1 -> 0
D35: =D34+1 -> 46198 | E35: 四 | I35: =F35/$C$1 -> 0
D36: =D35+1 -> 46199 | E36: 五 | I36: =F36/$C$1 -> 0
D37: =D36+1 -> 46200 | E37: 六 | I37: =F37/$C$1 -> 0
D38: =D37+1 -> 46201 | E38: 日 | I38: =F38/$C$1 -> 0
D39: =D38+1 -> 46202 | E39: 一 | I39: =F39/$C$1 -> 0
D40: =D39+1 -> 46203 | E40: 二 | I40: =F40/$C$1 -> 0
...

Sheet （３）業績構成比
B2: （3）業績構成比
C3: 月份 | D3: 日期 | F3: 營業額 | I3: 品類業績
I4: 18℃-飯糰 | O4: 18℃-壽司手卷 | U4: 4℃-飯糰 | W4: 4℃-壽司手卷 | Y4: 主食 | AE4: 便當 | AG4: 熱食義麵 | AI4: 季節調理麵 | AK4: 微波小吃
F5: 日 | G5: 週累積 | H5: 月累積 | I5: 一配 | K5: 二配 | M5: 合計 | O5: 一配 | Q5: 二配 | S5: 合計 | U5: 一配 | W5: 一配 | Y5: 一配 | AA5: 二配 | AC5: 合計 | AE5: 一配 | AG5: 一配 | AI5: 一配 | AK5: 一配
I6: 業績(元) | J6: 比例(%) | K6: 業績(元) | L6: 比例(%) | M6: 業績(元) | N6: 比例(%) | O6: 業績(元) | P6: 比例(%) | Q6: 業績(元) | R6: 比例(%) | S6: 業績(元) | T6: 比例(%) | U6: 業績(元) | V6: 比例(%) | W6: 業績(元) | X6: 比例(%) | Y6: 業績(元) | Z6: 比例(%) | AA6: 業績(元) | AB6: 比例(%) | AC6: 業績(元) | AD6: 比例(%) | AE6: 業績(元) | AF6: 比例(%) | AG6: 業績(元) | AH6: 比例(%) | AI6: 業績(元) | AJ6: 比例(%) | AK6: 業績(元) | AL6: 比例(%)
D7: 46168 | E7: 二 | F7: =SUM(M7,S7,U7,W7,AC7,AE7,AG7,AI7,AK7) -> 9911969 | I7: 871356.86 | J7: =I7/F7 -> 0.087909563 | K7: 893565.51 | L7: =K7/F7 -> 0.090150151 | M7: =SUM(I7+K7) -> 1764922.4 | N7: =M7/F7 -> 0.17805971 | O7: 155000.81 | P7: =O7/F7 -> 0.015637742 | R7: =Q7/$F7 -> 0 | S7: =SUM(O7+Q7) -> 155000.81 | T7: =S7/F7 -> 0.015637742 | U7: 1032613.9 | V7: =U7/F7 -> 0.10417848 | W7: 90946.693 | X7: =W7/F7 -> 0.0091754416 | Y7: 715867.99 | Z7: =Y7/F7 -> 0.072222581 | AA7: 1241839.1 | AB7: =AA7/$F7 -> 0.12528682 | AC7: =SUM(Y7+AA7) -> 1957707.1 | AD7: =AC7/F7 -> 0.1975094 | AE7: 1474753.3 | AF7: =AE7/F7 -> 0.1487851 | AG7: 1325583.4 | AH7: =AG7/F7 -> 0.13373563 | AI7: 1340614.2 | AJ7: =AI7/F7 -> 0.13525206 | AK7: 769827.26 | AL7: =AK7/F7 -> 0.077666432
D8: =D7+1 -> 46169 | E8: 三 | F8: =SUM(M8,S8,U8,W8,AC8,AE8,AG8,AI8,AK8) -> 9723654 | G8: =SUM(F7:F13) -> 65939025 | I8: 834226.4 | J8: =I8/F8 -> 0.085793509 | K8: 880855.44 | L8: =K8/F8 -> 0.090588933 | M8: =SUM(I8+K8) -> 1715081.8 | N8: =M8/F8 -> 0.17638244 | O8: 155740.6 | P8: =O8/F8 -> 0.016016675 | R8: =Q8/$F8 -> 0 | S8: =SUM(O8+Q8) -> 155740.6 | T8: =S8/F8 -> 0.016016675 | U8: 1021176.4 | V8: =U8/F8 -> 0.10501982 | W8: 91019.339 | X8: =W8/F8 -> 0.0093606106 | Y8: 712653.02 | Z8: =Y8/F8 -> 0.07329066 | AA8: 1161243.8 | AB8: =AA8/$F8 -> 0.11942463 | AC8: =SUM(Y8+AA8) -> 1873896.8 | AD8: =AC8/F8 -> 0.19271529 | AE8: 1479080.4 | AF8: =AE8/F8 -> 0.15211158 | AG8: 1013065.2 | AH8: =AG8/F8 -> 0.10418565 | AI8: 1617802.8 | AJ8: =AI8/F8 -> 0.16637807 | AK8: 756790.67 | AL8: =AK8/F8 -> 0.077829864
D9: =D8+1 -> 46170 | E9: 四 | F9: =SUM(M9,S9,U9,W9,AC9,AE9,AG9,AI9,AK9) -> 9072400 | I9: 796967.55 | J9: =I9/F9 -> 0.087845284 | K9: 802490.73 | L9: =K9/F9 -> 0.088454073 | M9: =SUM(I9+K9) -> 1599458.3 | N9: =M9/F9 -> 0.17629936 | O9: 156572.69 | P9: =O9/F9 -> 0.017258133 | R9: =Q9/$F9 -> 0 | S9: =SUM(O9+Q9) -> 156572.69 | T9: =S9/F9 -> 0.017258133 | U9: 919622.63 | V9: =U9/F9 -> 0.10136487 | W9: 80701.499 | X9: =W9/F9 -> 0.0088952757 | Y9: 684780.21 | Z9: =Y9/F9 -> 0.075479499 | AA9: 910019.21 | AB9: =AA9/$F9 -> 0.10030634 | AC9: =SUM(Y9+AA9) -> 1594799.4 | AD9: =AC9/F9 -> 0.17578584 | AE9: 1371164.7 | AF9: =AE9/F9 -> 0.15113583 | AG9: 953952.6 | AH9: =AG9/F9 -> 0.10514887 | AI9: 1655180.2 | AJ9: =AI9/F9 -> 0.18244127 | AK9: 740947.98 | AL9: =AK9/F9 -> 0.081670559
D10: =D9+1 -> 46171 | E10: 五 | F10: =SUM(M10,S10,U10,W10,AC10,AE10,AG10,AI10,AK10) -> 8447568 | I10: 717668.83 | J10: =I10/F10 -> 0.084955674 | K10: 754001.26 | L10: =K10/F10 -> 0.089256607 | M10: =SUM(I10+K10) -> 1471670.1 | N10: =M10/F10 -> 0.17421228 | O10: 131174.99 | P10: =O10/F10 -> 0.015528137 | R10: =Q10/$F10 -> 0 | S10: =SUM(O10+Q10) -> 131174.99 | T10: =S10/F10 -> 0.015528137 | U10: 827052.82 | V10: =U10/F10 -> 0.097904251 | W10: 57382.901 | X10: =W10/F10 -> 0.0067928309 | Y10: 602253.05 | Z10: =Y10/F10 -> 0.071293069 | AA10: 925631.31 | AB10: =AA10/$F10 -> 0.1095737 | AC10: =SUM(Y10+AA10) -> 1527884.4 | AD10: =AC10/F10 -> 0.18086677 | AE10: 1186754.4 | AF10: =AE10/F10 -> 0.14048475 | AG10: 870174.15 | AH10: =AG10/F10 -> 0.10300884 | AI10: 1740638.1 | AJ10: =AI10/F10 -> 0.20605198 | AK10: 634836.12 | AL10: =AK10/F10 -> 0.075150164
D11: =D10+1 -> 46172 | E11: 六 | F11: =SUM(M11,S11,U11,W11,AC11,AE11,AG11,AI11,AK11) -> 8820596 | I11: 648392.84 | J11: =I11/F11 -> 0.07350896 | K11: 833488.46 | L11: =K11/F11 -> 0.09449344 | M11: =SUM(I11+K11) -> 1481881.3 | N11: =M11/F11 -> 0.1680024 | O11: 131347.2 | P11: =O11/F11 -> 0.014890966 | R11: =Q11/$F11 -> 0 | S11: =SUM(O11+Q11) -> 131347.2 | T11: =S11/F11 -> 0.014890966 | U11: 890786.35 | V11: =U11/F11 -> 0.10098936 | W11: 66013.288 | X11: =W11/F11 -> 0.007483994 | Y11: 662404.95 | Z11: =Y11/F11 -> 0.075097527 | AA11: 1013745.6 | AB11: =AA11/$F11 -> 0.11492937 | AC11: =SUM(Y11+AA11) -> 1676150.5 | AD11: =AC11/F11 -> 0.1900269 | AE11: 1325867.2 | AF11: =AE11/F11 -> 0.15031492 | AG11: 1014306.6 | AH11: =AG11/F11 -> 0.11499297 | AI11: 1536567.2 | AJ11: =AI11/F11 -> 0.1742022 | AK11: 697676.39 | AL11: =AK11/F11 -> 0.079096287
D12: =D11+1 -> 46173 | E12: 日 | F12: =SUM(M12,S12,U12,W12,AC12,AE12,AG12,AI12,AK12) -> 10386449 | H12: =SUM(F13:F42) -> 141939037 | I12: 803405.44 | J12: =I12/F12 -> 0.077351311 | K12: 920092.35 | L12: =K12/F12 -> 0.088585844 | M12: =SUM(I12+K12) -> 1723497.8 | N12: =M12/F12 -> 0.16593715 | O12: 159681.46 | P12: =O12/F12 -> 0.015374019 | R12: =Q12/$F12 -> 0 | S12: =SUM(O12+Q12) -> 159681.46 | T12: =S12/F12 -> 0.015374019 | U12: 1123376.7 | V12: =U12/F12 -> 0.10815792 | W12: 78012.345 | X12: =W12/F12 -> 0.0075109737 | Y12: 760064.26 | Z12: =Y12/F12 -> 0.073178452 | AA12: 1143849.7 | AB12: =AA12/$F12 -> 0.11012904 | AC12: =SUM(Y12+AA12) -> 1903913.9 | AD12: =AC12/F12 -> 0.18330749 | AE12: 1637466.4 | AF12: =AE12/F12 -> 0.15765411 | AG12: 1228518.7 | AH12: =AG12/F12 -> 0.11828091 | AI12: 1703467.5 | AJ12: =AI12/F12 -> 0.16400865 | AK12: 828514.16 | AL12: =AK12/F12 -> 0.07976876
D13: =D12+1 -> 46174 | E13: 一 | F13: =SUM(M13,S13,U13,W13,AC13,AE13,AG13,AI13,AK13) -> 9576389 | I13: 758567.62 | J13: =I13/F13 -> 0.079212282 | K13: 873393.03 | L13: =K13/F13 -> 0.091202752 | M13: =SUM(I13+K13) -> 1631960.7 | N13: =M13/F13 -> 0.17041503 | O13: 153608.36 | P13: =O13/F13 -> 0.016040322 | R13: =Q13/$F13 -> 0 | S13: =SUM(O13+Q13) -> 153608.36 | T13: =S13/F13 -> 0.016040322 | U13: 1067528.5 | V13: =U13/F13 -> 0.11147505 | W13: 81439.235 | X13: =W13/F13 -> 0.0085041695 | Y13: 738854.28 | Z13: =Y13/F13 -> 0.077153745 | AA13: 1118456.8 | AB13: =AA13/$F13 -> 0.11679317 | AC13: =SUM(Y13+AA13) -> 1857311.1 | AD13: =AC13/F13 -> 0.19394691 | AE13: 1541280.3 | AF13: =AE13/F13 -> 0.16094587 | AG13: 1041486.2 | AH13: =AG13/F13 -> 0.10875563 | AI13: 1372243.6 | AJ13: =AI13/F13 -> 0.14329447 | AK13: 829531.06 | AL13: =AK13/F13 -> 0.086622531
D14: =D13+1 -> 46175 | E14: 二 | F14: =SUM(M14,S14,U14,W14,AC14,AE14,AG14,AI14,AK14) -> 10050370 | G14: =SUM(F14:F20) -> 65024924 | I14: 776227.97 | J14: =I14/F14 -> 0.077233771 | K14: 874306.95 | L14: =K14/F14 -> 0.086992513 | M14: =SUM(I14+K14) -> 1650534.9 | N14: =M14/F14 -> 0.16422628 | O14: 157334.02 | P14: =O14/F14 -> 0.01565455 | R14: =Q14/$F14 -> 0 | S14: =SUM(O14+Q14) -> 157334.02 | T14: =S14/F14 -> 0.01565455 | U14: 1066987.2 | V14: =U14/F14 -> 0.10616397 | W14: 70828.108 | X14: =W14/F14 -> 0.0070473134 | Y14: 745103.6 | Z14: =Y14/F14 -> 0.074136932 | AA14: 1115672.5 | AB14: =AA14/$F14 -> 0.1110081 | AC14: =SUM(Y14+AA14) -> 1860776.1 | AD14: =AC14/F14 -> 0.18514503 | AE14: 1522372 | AF14: =AE14/F14 -> 0.15147423 | AG14: 983263.57 | AH14: =AG14/F14 -> 0.097833569 | AI14: 1653856 | AJ14: =AI14/F14 -> 0.16455672 | AK14: 1084418.2 | AL14: =AK14/F14 -> 0.10789833
D15: =D14+1 -> 46176 | E15: 三 | F15: =SUM(M15,S15,U15,W15,AC15,AE15,AG15,AI15,AK15) -> 9327317 | I15: 768978.49 | J15: =I15/F15 -> 0.082443696 | K15: 854550.85 | L15: =K15/F15 -> 0.091618078 | M15: =SUM(I15+K15) -> 1623529.3 | N15: =M15/F15 -> 0.17406177 | O15: 157836.06 | P15: =O15/F15 -> 0.016921914 | R15: =Q15/$F15 -> 0 | S15: =SUM(O15+Q15) -> 157836.06 | T15: =S15/F15 -> 0.016921914 | U15: 963305.63 | V15: =U15/F15 -> 0.10327789 | W15: 66246.106 | X15: =W15/F15 -> 0.0071023753 | Y15: 684220.49 | Z15: =Y15/F15 -> 0.073356624 | AA15: 1013653.9 | AB15: =AA15/$F15 -> 0.10867582 | AC15: =SUM(Y15+AA15) -> 1697874.3 | AD15: =AC15/F15 -> 0.18203245 | AE15: 1400738 | AF15: =AE15/F15 -> 0.15017587 | AG15: 902576.83 | AH15: =AG15/F15 -> 0.096767037 | AI15: 1582861.6 | AJ15: =AI15/F15 -> 0.1697017 | AK15: 932349.12 | AL15: =AK15/F15 -> 0.099958983
D16: =D15+1 -> 46177 | E16: 四 | F16: =SUM(M16,S16,U16,W16,AC16,AE16,AG16,AI16,AK16) -> 8845232 | I16: 735925.14 | J16: =I16/F16 -> 0.083200208 | K16: 785898.54 | L16: =K16/F16 -> 0.088849963 | M16: =SUM(I16+K16) -> 1521823.7 | N16: =M16/F16 -> 0.17205017 | O16: 155084.37 | P16: =O16/F16 -> 0.017533104 | R16: =Q16/$F16 -> 0 | S16: =SUM(O16+Q16) -> 155084.37 | T16: =S16/F16 -> 0.017533104 | U16: 836907.06 | V16: =U16/F16 -> 0.094616744 | W16: 65483.383 | X16: =W16/F16 -> 0.0074032409 | Y16: 648023.46 | Z16: =Y16/F16 -> 0.073262461 | AA16: 845764.07 | AB16: =AA16/$F16 -> 0.095618077 | AC16: =SUM(Y16+AA16) -> 1493787.5 | AD16: =AC16/F16 -> 0.16888054 | AE16: 1297292 | AF16: =AE16/F16 -> 0.14666568 | AG16: 911147.41 | AH16: =AG16/F16 -> 0.10301001 | AI16: 1684698.7 | AJ16: =AI16/F16 -> 0.19046405 | AK16: 879007.88 | AL16: =AK16/F16 -> 0.099376464
D17: =D16+1 -> 46178 | E17: 五 | F17: =SUM(M17,S17,U17,W17,AC17,AE17,AG17,AI17,AK17) -> 7987767 | I17: 623153.88 | J17: =I17/F17 -> 0.078013527 | K17: 731322.57 | L17: =K17/F17 -> 0.09155532 | M17: =SUM(I17+K17) -> 1354476.4 | N17: =M17/F17 -> 0.16956885 | O17: 131304.09 | P17: =O17/F17 -> 0.016438147 | R17: =Q17/$F17 -> 0 | S17: =SUM(O17+Q17) -> 131304.09 | T17: =S17/F17 -> 0.016438147 | U17: 742630.2 | V17: =U17/F17 -> 0.092970939 | W17: 44629.247 | X17: =W17/F17 -> 0.0055871994 | Y17: 541834.81 | Z17: =Y17/F17 -> 0.067833077 | AA17: 938200.47 | AB17: =AA17/$F17 -> 0.11745466 | AC17: =SUM(Y17+AA17) -> 1480035.3 | AD17: =AC17/F17 -> 0.18528774 | AE17: 1075180.8 | AF17: =AE17/F17 -> 0.13460343 | AG17: 860019 | AH17: =AG17/F17 -> 0.10766701 | AI17: 1584901.5 | AJ17: =AI17/F17 -> 0.19841609 | AK17: 714590.43 | AL17: =AK17/F17 -> 0.0894606
D18: =D17+1 -> 46179 | E18: 六 | F18: =SUM(M18,S18,U18,W18,AC18,AE18,AG18,AI18,AK18) -> 8617242 | I18: 598521.23 | J18: =I18/F18 -> 0.06945624 | K18: 817046.42 | L18: =K18/F18 -> 0.094815304 | M18: =SUM(I18+K18) -> 1415567.6 | N18: =M18/F18 -> 0.16427154 | O18: 128955.43 | P18: =O18/F18 -> 0.014964815 | R18: =Q18/$F18 -> 0 | S18: =SUM(O18+Q18) -> 128955.43 | T18: =S18/F18 -> 0.014964815 | U18: 864995.16 | V18: =U18/F18 -> 0.10037958 | W18: 55585.292 | X18: =W18/F18 -> 0.0064504736 | Y18: 645360.4 | Z18: =Y18/F18 -> 0.074891757 | AA18: 1119176.9 | AB18: =AA18/$F18 -> 0.12987646 | AC18: =SUM(Y18+AA18) -> 1764537.3 | AD18: =AC18/F18 -> 0.20476822 | AE18: 1272716.7 | AF18: =AE18/F18 -> 0.1476942 | AG18: 838470.5 | AH18: =AG18/F18 -> 0.097301492 | AI18: 1474850.4 | AJ18: =AI18/F18 -> 0.17115109 | AK18: 801563.63 | AL18: =AK18/F18 -> 0.093018582
D19: =D18+1 -> 46180 | E19: 日 | F19: =SUM(M19,S19,U19,W19,AC19,AE19,AG19,AI19,AK19) -> 10141059 | I19: 742266.92 | J19: =I19/F19 -> 0.073194221 | K19: 889983.3 | L19: =K19/F19 -> 0.08776039 | M19: =SUM(I19+K19) -> 1632250.2 | N19: =M19/F19 -> 0.16095461 | O19: 159070.5 | P19: =O19/F19 -> 0.015685788 | R19: =Q19/$F19 -> 0 | S19: =SUM(O19+Q19) -> 159070.5 | T19: =S19/F19 -> 0.015685788 | U19: 1112996.8 | V19: =U19/F19 -> 0.10975154 | W19: 64975.337 | X19: =W19/F19 -> 0.006407155 | Y19: 764878.71 | Z19: =Y19/F19 -> 0.075423948 | AA19: 1179982.2 | AB19: =AA19/$F19 -> 0.1163569 | AC19: =SUM(Y19+AA19) -> 1944860.9 | AD19: =AC19/F19 -> 0.19178085 | AE19: 1631844.8 | AF19: =AE19/F19 -> 0.16091463 | AG19: 1028677.6 | AH19: =AG19/F19 -> 0.1014369 | AI19: 1578374.1 | AJ19: =AI19/F19 -> 0.15564195 | AK19: 988008.73 | AL19: =AK19/F19 -> 0.097426583
D20: =D19+1 -> 46181 | E20: 一 | F20: =SUM(M20,S20,U20,W20,AC20,AE20,AG20,AI20,AK20) -> 10055937 | I20: 728725.8 | J20: =I20/F20 -> 0.07246722 | K20: 880984.73 | L20: =K20/F20 -> 0.087608418 | M20: =SUM(I20+K20) -> 1609710.5 | N20: =M20/F20 -> 0.16007564 | O20: 157537.16 | P20: =O20/F20 -> 0.015666085 | R20: =Q20/$F20 -> 0 | S20: =SUM(O20+Q20) -> 157537.16 | T20: =S20/F20 -> 0.015666085 | U20: 1104147.5 | V20: =U20/F20 -> 0.10980056 | W20: 69918.126 | X20: =W20/F20 -> 0.00695292 | Y20: 793317.63 | Z20: =Y20/F20 -> 0.078890474 | AA20: 1378400.9 | AB20: =AA20/$F20 -> 0.13707335 | AC20: =SUM(Y20+AA20) -> 2171718.6 | AD20: =AC20/F20 -> 0.21596382 | AE20: 1633401.8 | AF20: =AE20/F20 -> 0.16243158 | AG20: 1012486.9 | AH20: =AG20/F20 -> 0.10068549 | AI20: 1371941 | AJ20: =AI20/F20 -> 0.13643094 | AK20: 925075.46 | AL20: =AK20/F20 -> 0.091992964
D21: =D20+1 -> 46182 | E21: 二 | F21: =SUM(M21,S21,U21,W21,AC21,AE21,AG21,AI21,AK21) -> 10760813 | G21: =SUM(F21:F27) -> 67337724 | I21: 731597.53 | J21: =I21/F21 -> 0.067987199 | K21: 873065.73 | L21: =K21/F21 -> 0.081133808 | M21: =SUM(I21+K21) -> 1604663.3 | N21: =M21/F21 -> 0.14912101 | O21: 162056.59 | P21: =O21/F21 -> 0.015059884 | R21: =Q21/$F21 -> 0 | S21: =SUM(O21+Q21) -> 162056.59 | T21: =S21/F21 -> 0.015059884 | U21: 1343373.4 | V21: =U21/F21 -> 0.1248394 | W21: 68083.912 | X21: =W21/F21 -> 0.006327023 | Y21: 792049.07 | Z21: =Y21/F21 -> 0.073604947 | AA21: 1389427.7 | AB21: =AA21/$F21 -> 0.12911921 | AC21: =SUM(Y21+AA21) -> 2181476.7 | AD21: =AC21/F21 -> 0.20272416 | AE21: 1507267.7 | AF21: =AE21/F21 -> 0.14007006 | AG21: 1371957.6 | AH21: =AG21/F21 -> 0.12749572 | AI21: 1604553.7 | AJ21: =AI21/F21 -> 0.14911082 | AK21: 917380.06 | AL21: =AK21/F21 -> 0.085251928
D22: =D21+1 -> 46183 | E22: 三 | F22: =SUM(M22,S22,U22,W22,AC22,AE22,AG22,AI22,AK22) -> 10128071 | I22: 721784.17 | J22: =I22/F22 -> 0.07126571 | K22: 865555.91 | L22: =K22/F22 -> 0.085461083 | M22: =SUM(I22+K22) -> 1587340.1 | N22: =M22/F22 -> 0.15672679 | O22: 159910.08 | P22: =O22/F22 -> 0.015788799 | R22: =Q22/$F22 -> 0 | S22: =SUM(O22+Q22) -> 159910.08 | T22: =S22/F22 -> 0.015788799 | U22: 1134784 | V22: =U22/F22 -> 0.11204345 | W22: 67387.273 | X22: =W22/F22 -> 0.0066535151 | Y22: 738847.64 | Z22: =Y22/F22 -> 0.07295048 | AA22: 1370461.3 | AB22: =AA22/$F22 -> 0.13531316 | AC22: =SUM(Y22+AA22) -> 2109308.9 | AD22: =AC22/F22 -> 0.20826364 | AE22: 1438696.7 | AF22: =AE22/F22 -> 0.14205042 | AG22: 1173531.1 | AH22: =AG22/F22 -> 0.11586916 | AI22: 1614063.2 | AJ22: =AI22/F22 -> 0.15936531 | AK22: 843049.65 | AL22: =AK22/F22 -> 0.083238916
D23: =D22+1 -> 46184 | E23: 四 | F23: =SUM(M23,S23,U23,W23,AC23,AE23,AG23,AI23,AK23) -> 9476070 | I23: 690623.3 | J23: =I23/F23 -> 0.072880773 | K23: 774563.22 | L23: =K23/F23 -> 0.081738866 | M23: =SUM(I23+K23) -> 1465186.5 | N23: =M23/F23 -> 0.15461964 | O23: 157961.93 | P23: =O23/F23 -> 0.016669562 | R23: =Q23/$F23 -> 0 | S23: =SUM(O23+Q23) -> 157961.93 | T23: =S23/F23 -> 0.016669562 | U23: 1108135.7 | V23: =U23/F23 -> 0.11694043 | W23: 63980.776 | X23: =W23/F23 -> 0.006751826 | Y23: 743743.29 | Z23: =Y23/F23 -> 0.078486471 | AA23: 1068438.3 | AB23: =AA23/$F23 -> 0.1127512 | AC23: =SUM(Y23+AA23) -> 1812181.6 | AD23: =AC23/F23 -> 0.19123767 | AE23: 1392928.8 | AF23: =AE23/F23 -> 0.14699435 | AG23: 1098717.3 | AH23: =AG23/F23 -> 0.11594651 | AI23: 1529675.9 | AJ23: =AI23/F23 -> 0.16142513 | AK23: 847301.64 | AL23: =AK23/F23 -> 0.089414877
D24: =D23+1 -> 46185 | E24: 五 | F24: =SUM(M24,S24,U24,W24,AC24,AE24,AG24,AI24,AK24) -> 8134246 | I24: 573992.55 | J24: =I24/F24 -> 0.070564936 | K24: 714240.01 | L24: =K24/F24 -> 0.087806541 | M24: =SUM(I24+K24) -> 1288232.6 | N24: =M24/F24 -> 0.15837148 | O24: 132727.03 | P24: =O24/F24 -> 0.016317066 | R24: =Q24/$F24 -> 0 | S24: =SUM(O24+Q24) -> 132727.03 | T24: =S24/F24 -> 0.016317066 | U24: 944461.44 | V24: =U24/F24 -> 0.11610928 | W24: 42606.531 | X24: =W24/F24 -> 0.0052379202 | Y24: 622126.8 | Z24: =Y24/F24 -> 0.076482417 | AA24: 1044519 | AB24: =AA24/$F24 -> 0.12841006 | AC24: =SUM(Y24+AA24) -> 1666645.8 | AD24: =AC24/F24 -> 0.20489248 | AE24: 1090541.4 | AF24: =AE24/F24 -> 0.13406792 | AG24: 838731.79 | AH24: =AG24/F24 -> 0.10311119 | AI24: 1382199.6 | AJ24: =AI24/F24 -> 0.16992351 | AK24: 748099.77 | AL24: =AK24/F24 -> 0.09196916
D25: =D24+1 -> 46186 | E25: 六 | F25: =SUM(M25,S25,U25,W25,AC25,AE25,AG25,AI25,AK25) -> 8644943 | I25: 545428 | J25: =I25/F25 -> 0.063092146 | K25: 780158.43 | L25: =K25/F25 -> 0.090244486 | M25: =SUM(I25+K25) -> 1325586.4 | N25: =M25/F25 -> 0.15333663 | O25: 126833.9 | P25: =O25/F25 -> 0.014671456 | R25: =Q25/$F25 -> 0 | S25: =SUM(O25+Q25) -> 126833.9 | T25: =S25/F25 -> 0.014671456 | U25: 1133479.2 | V25: =U25/F25 -> 0.13111471 | W25: 47866.833 | X25: =W25/F25 -> 0.005536975 | Y25: 685334.66 | Z25: =Y25/F25 -> 0.079275787 | AA25: 1073485.1 | AB25: =AA25/$F25 -> 0.12417492 | AC25: =SUM(Y25+AA25) -> 1758819.8 | AD25: =AC25/F25 -> 0.20345071 | AE25: 1203487.3 | AF25: =AE25/F25 -> 0.13921287 | AG25: 961887.66 | AH25: =AG25/F25 -> 0.11126593 | AI25: 1288693.2 | AJ25: =AI25/F25 -> 0.14906902 | AK25: 798288.65 | AL25: =AK25/F25 -> 0.09234169
D26: =D25+1 -> 46187 | E26: 日 | F26: =SUM(M26,S26,U26,W26,AC26,AE26,AG26,AI26,AK26) -> 10278251 | I26: 681825.49 | J26: =I26/F26 -> 0.066336723 | K26: 861821.96 | L26: =K26/F26 -> 0.083849087 | M26: =SUM(I26+K26) -> 1543647.4 | N26: =M26/F26 -> 0.15018581 | O26: 159603.96 | P26: =O26/F26 -> 0.015528319 | R26: =Q26/$F26 -> 0 | S26: =SUM(O26+Q26) -> 159603.96 | T26: =S26/F26 -> 0.015528319 | U26: 1315784.1 | V26: =U26/F26 -> 0.12801635 | W26: 54814.128 | X26: =W26/F26 -> 0.005333021 | Y26: 740901.05 | Z26: =Y26/F26 -> 0.072084351 | AA26: 1139778.8 | AB26: =AA26/$F26 -> 0.11089229 | AC26: =SUM(Y26+AA26) -> 1880679.8 | AD26: =AC26/F26 -> 0.18297664 | AE26: 1552956.9 | AF26: =AE26/F26 -> 0.15109155 | AG26: 1283550.4 | AH26: =AG26/F26 -> 0.12488024 | AI26: 1587096.8 | AJ26: =AI26/F26 -> 0.15441312 | AK26: 900117.36 | AL26: =AK26/F26 -> 0.087574955
D27: =D26+1 -> 46188 | E27: 一 | F27: =SUM(M27,S27,U27,W27,AC27,AE27,AG27,AI27,AK27) -> 9915330 | I27: 667985.81 | J27: =I27/F27 -> 0.067368994 | K27: 848012.36 | L27: =K27/F27 -> 0.085525379 | M27: =SUM(I27+K27) -> 1515998.2 | N27: =M27/F27 -> 0.15289437 | O27: 154215.39 | P27: =O27/F27 -> 0.015553228 | R27: =Q27/$F27 -> 0 | S27: =SUM(O27+Q27) -> 154215.39 | T27: =S27/F27 -> 0.015553228 | U27: 1209395.5 | V27: =U27/F27 -> 0.12197229 | W27: 64401.408 | X27: =W27/F27 -> 0.0064951351 | Y27: 733553.35 | Z27: =Y27/F27 -> 0.073981739 | AA27: 1346391.9 | AB27: =AA27/$F27 -> 0.13578891 | AC27: =SUM(Y27+AA27) -> 2079945.2 | AD27: =AC27/F27 -> 0.20977065 | AE27: 1480750.4 | AF27: =AE27/F27 -> 0.14933949 | AG27: 1121095.4 | AH27: =AG27/F27 -> 0.11306688 | AI27: 1368784.7 | AJ27: =AI27/F27 -> 0.13804731 | AK27: 920743.86 | AL27: =AK27/F27 -> 0.092860637
D28: =D27+1 -> 46189 | E28: 二 | F28: =SUM(M28,S28,U28,W28,AC28,AE28,AG28,AI28,AK28) -> 0 | G28: =SUM(F28:F34) -> 0 | J28: =I28/F28 -> #DIV/0! | L28: =K28/F28 -> #DIV/0! | M28: =SUM(I28+K28) -> 0 | N28: =M28/F28 -> #DIV/0! | P28: =O28/F28 -> #DIV/0! | R28: =Q28/$F28 -> #DIV/0! | S28: =SUM(O28+Q28) -> 0 | T28: =S28/F28 -> #DIV/0! | V28: =U28/F28 -> #DIV/0! | X28: =W28/F28 -> #DIV/0! | Z28: =Y28/F28 -> #DIV/0! | AB28: =AA28/$F28 -> #DIV/0! | AC28: =SUM(Y28+AA28) -> 0 | AD28: =AC28/F28 -> #DIV/0! | AF28: =AE28/F28 -> #DIV/0! | AH28: =AG28/F28 -> #DIV/0! | AJ28: =AI28/F28 -> #DIV/0! | AL28: =AK28/F28 -> #DIV/0!
D29: =D28+1 -> 46190 | E29: 三 | F29: =SUM(M29,S29,U29,W29,AC29,AE29,AG29,AI29,AK29) -> 0 | J29: =I29/F29 -> #DIV/0! | L29: =K29/F29 -> #DIV/0! | M29: =SUM(I29+K29) -> 0 | N29: =M29/F29 -> #DIV/0! | P29: =O29/F29 -> #DIV/0! | R29: =Q29/$F29 -> #DIV/0! | S29: =SUM(O29+Q29) -> 0 | T29: =S29/F29 -> #DIV/0! | V29: =U29/F29 -> #DIV/0! | X29: =W29/F29 -> #DIV/0! | Z29: =Y29/F29 -> #DIV/0! | AB29: =AA29/$F29 -> #DIV/0! | AC29: =SUM(Y29+AA29) -> 0 | AD29: =AC29/F29 -> #DIV/0! | AF29: =AE29/F29 -> #DIV/0! | AH29: =AG29/F29 -> #DIV/0! | AJ29: =AI29/F29 -> #DIV/0! | AL29: =AK29/F29 -> #DIV/0!
D30: =D29+1 -> 46191 | E30: 四 | F30: =SUM(M30,S30,U30,W30,AC30,AE30,AG30,AI30,AK30) -> 0 | J30: =I30/F30 -> #DIV/0! | L30: =K30/F30 -> #DIV/0! | M30: =SUM(I30+K30) -> 0 | N30: =M30/F30 -> #DIV/0! | P30: =O30/F30 -> #DIV/0! | R30: =Q30/$F30 -> #DIV/0! | S30: =SUM(O30+Q30) -> 0 | T30: =S30/F30 -> #DIV/0! | V30: =U30/F30 -> #DIV/0! | X30: =W30/F30 -> #DIV/0! | Z30: =Y30/F30 -> #DIV/0! | AB30: =AA30/$F30 -> #DIV/0! | AC30: =SUM(Y30+AA30) -> 0 | AD30: =AC30/F30 -> #DIV/0! | AF30: =AE30/F30 -> #DIV/0! | AH30: =AG30/F30 -> #DIV/0! | AJ30: =AI30/F30 -> #DIV/0! | AL30: =AK30/F30 -> #DIV/0!
D31: =D30+1 -> 46192 | E31: 五 | F31: =SUM(M31,S31,U31,W31,AC31,AE31,AG31,AI31,AK31) -> 0 | J31: =I31/F31 -> #DIV/0! | L31: =K31/F31 -> #DIV/0! | M31: =SUM(I31+K31) -> 0 | N31: =M31/F31 -> #DIV/0! | P31: =O31/F31 -> #DIV/0! | R31: =Q31/$F31 -> #DIV/0! | S31: =SUM(O31+Q31) -> 0 | T31: =S31/F31 -> #DIV/0! | V31: =U31/F31 -> #DIV/0! | X31: =W31/F31 -> #DIV/0! | Z31: =Y31/F31 -> #DIV/0! | AB31: =AA31/$F31 -> #DIV/0! | AC31: =SUM(Y31+AA31) -> 0 | AD31: =AC31/F31 -> #DIV/0! | AF31: =AE31/F31 -> #DIV/0! | AH31: =AG31/F31 -> #DIV/0! | AJ31: =AI31/F31 -> #DIV/0! | AL31: =AK31/F31 -> #DIV/0!
D32: =D31+1 -> 46193 | E32: 六 | F32: =SUM(M32,S32,U32,W32,AC32,AE32,AG32,AI32,AK32) -> 0 | J32: =I32/F32 -> #DIV/0! | L32: =K32/F32 -> #DIV/0! | M32: =SUM(I32+K32) -> 0 | N32: =M32/F32 -> #DIV/0! | P32: =O32/F32 -> #DIV/0! | R32: =Q32/$F32 -> #DIV/0! | S32: =SUM(O32+Q32) -> 0 | T32: =S32/F32 -> #DIV/0! | V32: =U32/F32 -> #DIV/0! | X32: =W32/F32 -> #DIV/0! | Z32: =Y32/F32 -> #DIV/0! | AB32: =AA32/$F32 -> #DIV/0! | AC32: =SUM(Y32+AA32) -> 0 | AD32: =AC32/F32 -> #DIV/0! | AF32: =AE32/F32 -> #DIV/0! | AH32: =AG32/F32 -> #DIV/0! | AJ32: =AI32/F32 -> #DIV/0! | AL32: =AK32/F32 -> #DIV/0!
D33: =D32+1 -> 46194 | E33: 日 | F33: =SUM(M33,S33,U33,W33,AC33,AE33,AG33,AI33,AK33) -> 0 | J33: =I33/F33 -> #DIV/0! | L33: =K33/F33 -> #DIV/0! | M33: =SUM(I33+K33) -> 0 | N33: =M33/F33 -> #DIV/0! | P33: =O33/F33 -> #DIV/0! | R33: =Q33/$F33 -> #DIV/0! | S33: =SUM(O33+Q33) -> 0 | T33: =S33/F33 -> #DIV/0! | V33: =U33/F33 -> #DIV/0! | X33: =W33/F33 -> #DIV/0! | Z33: =Y33/F33 -> #DIV/0! | AB33: =AA33/$F33 -> #DIV/0! | AC33: =SUM(Y33+AA33) -> 0 | AD33: =AC33/F33 -> #DIV/0! | AF33: =AE33/F33 -> #DIV/0! | AH33: =AG33/F33 -> #DIV/0! | AJ33: =AI33/F33 -> #DIV/0! | AL33: =AK33/F33 -> #DIV/0!
D34: =D33+1 -> 46195 | E34: 一 | F34: =SUM(M34,S34,U34,W34,AC34,AE34,AG34,AI34,AK34) -> 0 | J34: =I34/F34 -> #DIV/0! | L34: =K34/F34 -> #DIV/0! | M34: =SUM(I34+K34) -> 0 | N34: =M34/F34 -> #DIV/0! | P34: =O34/F34 -> #DIV/0! | R34: =Q34/$F34 -> #DIV/0! | S34: =SUM(O34+Q34) -> 0 | T34: =S34/F34 -> #DIV/0! | V34: =U34/F34 -> #DIV/0! | X34: =W34/F34 -> #DIV/0! | Z34: =Y34/F34 -> #DIV/0! | AB34: =AA34/$F34 -> #DIV/0! | AC34: =SUM(Y34+AA34) -> 0 | AD34: =AC34/F34 -> #DIV/0! | AF34: =AE34/F34 -> #DIV/0! | AH34: =AG34/F34 -> #DIV/0! | AJ34: =AI34/F34 -> #DIV/0! | AL34: =AK34/F34 -> #DIV/0!
D35: =D34+1 -> 46196 | E35: 二 | F35: =SUM(M35,S35,U35,W35,AC35,AE35,AG35,AI35,AK35) -> 0 | G35: =SUM(F35:F41) -> 0 | J35: =I35/F35 -> #DIV/0! | L35: =K35/F35 -> #DIV/0! | M35: =SUM(I35+K35) -> 0 | N35: =M35/F35 -> #DIV/0! | P35: =O35/F35 -> #DIV/0! | R35: =Q35/$F35 -> #DIV/0! | S35: =SUM(O35+Q35) -> 0 | T35: =S35/F35 -> #DIV/0! | V35: =U35/F35 -> #DIV/0! | X35: =W35/F35 -> #DIV/0! | Z35: =Y35/F35 -> #DIV/0! | AB35: =AA35/$F35 -> #DIV/0! | AC35: =SUM(Y35+AA35) -> 0 | AD35: =AC35/F35 -> #DIV/0! | AF35: =AE35/F35 -> #DIV/0! | AH35: =AG35/F35 -> #DIV/0! | AJ35: =AI35/F35 -> #DIV/0! | AL35: =AK35/F35 -> #DIV/0!
D36: =D35+1 -> 46197 | E36: 三 | F36: =SUM(M36,S36,U36,W36,AC36,AE36,AG36,AI36,AK36) -> 0 | J36: =I36/F36 -> #DIV/0! | L36: =K36/F36 -> #DIV/0! | M36: =SUM(I36+K36) -> 0 | N36: =M36/F36 -> #DIV/0! | P36: =O36/F36 -> #DIV/0! | R36: =Q36/$F36 -> #DIV/0! | S36: =SUM(O36+Q36) -> 0 | T36: =S36/F36 -> #DIV/0! | V36: =U36/F36 -> #DIV/0! | X36: =W36/F36 -> #DIV/0! | Z36: =Y36/F36 -> #DIV/0! | AB36: =AA36/$F36 -> #DIV/0! | AC36: =SUM(Y36+AA36) -> 0 | AD36: =AC36/F36 -> #DIV/0! | AF36: =AE36/F36 -> #DIV/0! | AH36: =AG36/F36 -> #DIV/0! | AJ36: =AI36/F36 -> #DIV/0! | AL36: =AK36/F36 -> #DIV/0!
D37: =D36+1 -> 46198 | E37: 四 | F37: =SUM(M37,S37,U37,W37,AC37,AE37,AG37,AI37,AK37) -> 0 | J37: =I37/F37 -> #DIV/0! | L37: =K37/F37 -> #DIV/0! | M37: =SUM(I37+K37) -> 0 | N37: =M37/F37 -> #DIV/0! | P37: =O37/F37 -> #DIV/0! | R37: =Q37/$F37 -> #DIV/0! | S37: =SUM(O37+Q37) -> 0 | T37: =S37/F37 -> #DIV/0! | V37: =U37/F37 -> #DIV/0! | X37: =W37/F37 -> #DIV/0! | Z37: =Y37/F37 -> #DIV/0! | AB37: =AA37/$F37 -> #DIV/0! | AC37: =SUM(Y37+AA37) -> 0 | AD37: =AC37/F37 -> #DIV/0! | AF37: =AE37/F37 -> #DIV/0! | AH37: =AG37/F37 -> #DIV/0! | AJ37: =AI37/F37 -> #DIV/0! | AL37: =AK37/F37 -> #DIV/0!
D38: =D37+1 -> 46199 | E38: 五 | F38: =SUM(M38,S38,U38,W38,AC38,AE38,AG38,AI38,AK38) -> 0 | J38: =I38/F38 -> #DIV/0! | L38: =K38/F38 -> #DIV/0! | M38: =SUM(I38+K38) -> 0 | N38: =M38/F38 -> #DIV/0! | P38: =O38/F38 -> #DIV/0! | R38: =Q38/$F38 -> #DIV/0! | S38: =SUM(O38+Q38) -> 0 | T38: =S38/F38 -> #DIV/0! | V38: =U38/F38 -> #DIV/0! | X38: =W38/F38 -> #DIV/0! | Z38: =Y38/F38 -> #DIV/0! | AB38: =AA38/$F38 -> #DIV/0! | AC38: =SUM(Y38+AA38) -> 0 | AD38: =AC38/F38 -> #DIV/0! | AF38: =AE38/F38 -> #DIV/0! | AH38: =AG38/F38 -> #DIV/0! | AJ38: =AI38/F38 -> #DIV/0! | AL38: =AK38/F38 -> #DIV/0!
D39: =D38+1 -> 46200 | E39: 六 | F39: =SUM(M39,S39,U39,W39,AC39,AE39,AG39,AI39,AK39) -> 0 | J39: =I39/F39 -> #DIV/0! | L39: =K39/F39 -> #DIV/0! | M39: =SUM(I39+K39) -> 0 | N39: =M39/F39 -> #DIV/0! | P39: =O39/F39 -> #DIV/0! | R39: =Q39/$F39 -> #DIV/0! | S39: =SUM(O39+Q39) -> 0 | T39: =S39/F39 -> #DIV/0! | V39: =U39/F39 -> #DIV/0! | X39: =W39/F39 -> #DIV/0! | Z39: =Y39/F39 -> #DIV/0! | AB39: =AA39/$F39 -> #DIV/0! | AC39: =SUM(Y39+AA39) -> 0 | AD39: =AC39/F39 -> #DIV/0! | AF39: =AE39/F39 -> #DIV/0! | AH39: =AG39/F39 -> #DIV/0! | AJ39: =AI39/F39 -> #DIV/0! | AL39: =AK39/F39 -> #DIV/0!
D40: =D39+1 -> 46201 | E40: 日 | F40: =SUM(M40,S40,U40,W40,AC40,AE40,AG40,AI40,AK40) -> 0 | J40: =I40/F40 -> #DIV/0! | L40: =K40/F40 -> #DIV/0! | M40: =SUM(I40+K40) -> 0 | N40: =M40/F40 -> #DIV/0! | P40: =O40/F40 -> #DIV/0! | R40: =Q40/$F40 -> #DIV/0! | S40: =SUM(O40+Q40) -> 0 | T40: =S40/F40 -> #DIV/0! | V40: =U40/F40 -> #DIV/0! | X40: =W40/F40 -> #DIV/0! | Z40: =Y40/F40 -> #DIV/0! | AB40: =AA40/$F40 -> #DIV/0! | AC40: =SUM(Y40+AA40) -> 0 | AD40: =AC40/F40 -> #DIV/0! | AF40: =AE40/F40 -> #DIV/0! | AH40: =AG40/F40 -> #DIV/0! | AJ40: =AI40/F40 -> #DIV/0! | AL40: =AK40/F40 -> #DIV/0!
D41: =D40+1 -> 46202 | E41: 一 | F41: =SUM(M41,S41,U41,W41,AC41,AE41,AG41,AI41,AK41) -> 0 | J41: =I41/F41 -> #DIV/0! | L41: =K41/F41 -> #DIV/0! | M41: =SUM(I41+K41) -> 0 | N41: =M41/F41 -> #DIV/0! | P41: =O41/F41 -> #DIV/0! | R41: =Q41/$F41 -> #DIV/0! | S41: =SUM(O41+Q41) -> 0 | T41: =S41/F41 -> #DIV/0! | V41: =U41/F41 -> #DIV/0! | X41: =W41/F41 -> #DIV/0! | Z41: =Y41/F41 -> #DIV/0! | AB41: =AA41/$F41 -> #DIV/0! | AC41: =SUM(Y41+AA41) -> 0 | AD41: =AC41/F41 -> #DIV/0! | AF41: =AE41/F41 -> #DIV/0! | AH41: =AG41/F41 -> #DIV/0! | AJ41: =AI41/F41 -> #DIV/0! | AL41: =AK41/F41 -> #DIV/0!
...

Sheet （４）訂單數量構成比
B2: （4）訂單數量構成比
C3: 月份 | D3: 日期 | F3: 訂單量 | I3: 品類訂單量
I4: 18℃-飯糰 | O4: 18℃-壽司手卷 | U4: 4℃-飯糰 | W4: 4℃-壽司手卷 | Y4: 主食 | AE4: 便當 | AG4: 熱食義麵 | AI4: 季節調理麵 | AK4: 微波小吃
F5: 日 | G5: 週累積 | H5: 月累積 | I5: 一配 | K5: 二配 | M5: 合計 | O5: 一配 | Q5: 二配 | S5: 合計 | U5: 一配 | W5: 一配 | Y5: 一配 | AA5: 二配 | AC5: 合計 | AE5: 一配 | AG5: 一配 | AI5: 一配 | AK5: 一配
I6: 訂單數 | J6: 比例(%) | K6: 訂單數 | L6: 比例(%) | M6: 訂單數 | N6: 比例(%) | O6: 訂單數 | P6: 比例(%) | Q6: 訂單數 | R6: 比例(%) | S6: 訂單數 | T6: 比例(%) | U6: 訂單數 | V6: 比例(%) | W6: 訂單數 | X6: 比例(%) | Y6: 訂單數 | Z6: 比例(%) | AA6: 訂單數 | AB6: 比例(%) | AC6: 訂單數 | AD6: 比例(%) | AE6: 訂單數 | AF6: 比例(%) | AG6: 訂單數 | AH6: 比例(%) | AI6: 訂單數 | AJ6: 比例(%) | AK6: 訂單數 | AL6: 比例(%)
D7: 46168 | E7: 二 | F7: =SUM(M7,S7,U7,W7,AC7,AE7,AG7,AI7,AK7) -> 293602 | I7: 43490 | J7: =I7/F7 -> 0.14812569 | K7: 46868 | L7: =K7/F7 -> 0.15963107 | M7: =SUM(I7+K7) -> 90358 | N7: =M7/F7 -> 0.30775676 | O7: 5346 | P7: =O7/F7 -> 0.018208323 | R7: =Q7/F7 -> 0 | S7: =SUM(O7+Q7) -> 5346 | T7: =S7/F7 -> 0.018208323 | U7: 31003 | V7: =U7/F7 -> 0.10559533 | W7: 2504 | X7: =W7/F7 -> 0.0085285523 | Y7: 24706 | Z7: =Y7/F7 -> 0.084147928 | AA7: 23664 | AB7: =AA7/F7 -> 0.080598906 | AC7: =SUM(Y7+AA7) -> 48370 | AD7: =AC7/F7 -> 0.16474683 | AE7: 25848 | AF7: =AE7/F7 -> 0.088037547 | AG7: 27750 | AH7: =AG7/F7 -> 0.094515705 | AI7: 36353 | AJ7: =AI7/F7 -> 0.12381728 | AK7: 26070 | AL7: =AK7/F7 -> 0.088793673
D8: =D7+1 -> 46169 | E8: 三 | F8: =SUM(M8,S8,U8,W8,AC8,AE8,AG8,AI8,AK8) -> 289569 | G8: =SUM(F7:F13) -> 1972816 | I8: 42001 | J8: =I8/F8 -> 0.1450466 | K8: 46176 | L8: =K8/F8 -> 0.15946458 | M8: =SUM(I8+K8) -> 88177 | N8: =M8/F8 -> 0.30451119 | O8: 5367 | P8: =O8/F8 -> 0.018534443 | R8: =Q8/F8 -> 0 | S8: =SUM(O8+Q8) -> 5367 | T8: =S8/F8 -> 0.018534443 | U8: 30526 | V8: =U8/F8 -> 0.10541874 | W8: 2506 | X8: =W8/F8 -> 0.0086542413 | Y8: 25020 | Z8: =Y8/F8 -> 0.086404277 | AA8: 22141 | AB8: =AA8/F8 -> 0.076461914 | AC8: =SUM(Y8+AA8) -> 47161 | AD8: =AC8/F8 -> 0.16286619 | AE8: 25845 | AF8: =AE8/F8 -> 0.089253339 | AG8: 20373 | AH8: =AG8/F8 -> 0.070356288 | AI8: 43870 | AJ8: =AI8/F8 -> 0.15150102 | AK8: 25744 | AL8: =AK8/F8 -> 0.088904544
