Workbook

Sheet 填寫舉例
A2: 7 | B2: 月別 | C2: 工廠名 | D2: ・・・・・・・・
A4: （１）收支狀況 | E4: ※單位：千元 | G4: （２）ＫＰＩ達成進度 | M4: （３）業績構成比 | S4: （４）訂單數量構成比
B5: 當月 | C5: 前月 | D5: 差異 | E5: 累計 | H5: KPI | I5: 當月 | J5: 前月 | K5: 累計 | L5: ※補充 | N5: 當月 | O5: 比例 | P5: 前月 | Q5: 差異 | T5: 當月 | U5: 比例 | V5: 前月 | W5: 差異
A6: 業績金額 | B6: 500000 | C6: 510000 | D6: =B6-C6 -> -10000 | E6: =B6+C6 -> 1010000 | G6: 人時生產性1 | H6: 110 | I6: 100 | J6: 90 | L6: 個／MH | M6: 飯糰 | N6: 150000 | O6: =IFERROR(N6/$B$6,"") -> 0.3 | P6: 0.4 | Q6: =IFERROR(O6-P6,"") -> -0.1 | S6: 飯糰 | T6: 35000 | U6: =IFERROR(T6/$B$7,"") -> 0.35 | V6: 0.3 | W6: =IFERROR(U6-V6,"") -> 0.05
A7: 訂單數量 | B7: 100000 | C7: 110000 | D7: =B7-C7 -> -10000 | E7: =B7+C7 -> 210000 | G7: 人時生產性2 | H7: 0.8 | I7: 0.85 | J7: 0.81 | K7: 0.84 | L7: 達成率 | M7: 大口飯糰 | N7: 100000 | O7: =IFERROR(N7/$B$6,"") -> 0.2 | P7: 0.15 | Q7: =IFERROR(O7-P7,"") -> 0.05 | S7: 大口飯糰 | T7: 30000 | U7: =IFERROR(T7/$B$7,"") -> 0.3 | V7: 0.15 | W7: =IFERROR(U7-V7,"") -> 0.15
A8: 材料費 | B8: 250000 | C8: 260000 | D8: =B8-C8 -> -10000 | E8: =B8+C8 -> 510000 | G8: 半成品報廢 | H8: 0.0025 | I8: 0.0024 | J8: 0.0023 | K8: 0.00235 | L8: 報廢率 | M8: 便當 | N8: 160000 | O8: =IFERROR(N8/$B$6,"") -> 0.32 | P8: 0.28 | Q8: =IFERROR(O8-P8,"") -> 0.04 | S8: 便當 | T8: 20000 | U8: =IFERROR(T8/$B$7,"") -> 0.2 | V8: 0.28 | W8: =IFERROR(U8-V8,"") -> -0.08
A9: 材料費率 | B9: =B8/B6 -> 0.5 | C9: =C8/C6 -> 0.50980392 | D9: =B9-C9 -> -0.0098039216 | E9: =(B9+C9)/2 -> 0.50490196 | G9: 半成品超用 | H9: 0.006 | I9: 0.009 | J9: 0.0095 | K9: 0.0092 | L9: 超用率 | M9: 調理麵 | N9: 90000 | O9: =IFERROR(N9/$B$6,"") -> 0.18 | P9: 0.17 | Q9: =IFERROR(O9-P9,"") -> 0.01 | S9: 調理麵 | T9: 15000 | U9: =IFERROR(T9/$B$7,"") -> 0.15 | V9: 0.27 | W9: =IFERROR(U9-V9,"") -> -0.12
A10: 勞務成本 | B10: 100000 | C10: 105000 | D10: =B10-C10 -> -5000 | E10: =B10+C10 -> 205000 | G10: 固定產線 | H10: 0.95 | I10: 0.9 | J10: 0.92 | K10: 0.91 | L10: 導入率 | M10: 調理麵包 | N10: - | O10: =IFERROR(N10/$B$6,"") | P10: -% | Q10: =IFERROR(O10-P10,"") | S10: 調理麵包 | T10: - | U10: =IFERROR(T10/$B$7,"") | V10: -% | W10: =IFERROR(U10-V10,"")
A11: 勞務費率 | B11: =B10/B6 -> 0.2 | C11: =C10/C6 -> 0.20588235 | D11: =B11-C11 -> -0.0058823529 | E11: =(B11+C11)/2 -> 0.20294118 | G11: 教育訓練 | H11: 0.8 | I11: 0.85 | J11: 1 | K11: 0.92 | L11: 實施率 | M11: 袋裝調理麵包 | N11: - | O11: =IFERROR(N11/$B$6,"") | P11: -% | Q11: =IFERROR(O11-P11,"") | S11: 袋裝調理麵包 | T11: - | U11: =IFERROR(T11/$B$7,"") | V11: -% | W11: =IFERROR(U11-V11,"")
M12: 義大利麵 | N12: - | O12: =IFERROR(N12/$B$6,"") | P12: -% | Q12: =IFERROR(O12-P12,"") | S12: 義大利麵 | T12: - | U12: =IFERROR(T12/$B$7,"") | V12: -% | W12: =IFERROR(U12-V12,"")
A13: （５）品群別人時生產性 | M13: 調理包 | N13: - | O13: =IFERROR(N13/$B$6,"") | P13: -% | Q13: =IFERROR(O13-P13,"") | S13: 調理包 | T13: - | U13: =IFERROR(T13/$B$7,"") | V13: -% | W13: =IFERROR(U13-V13,"")
B14: 當月 | C14: 前月 | D14: 差異 | E14: 累計 | H14: 當月 | I14: 前月 | J14: 差異 | K14: 累計 | O14: =SUM(O6:O13) -> 1 | P14: =SUM(P6:P13) -> 1 | U14: =SUM(U6:U13) -> 1 | V14: =SUM(V6:V13) -> 1
A15: 飯糰 | B15: 600 | C15: 660 | D15: =B15-C15 -> -60 | E15: =(B15+C15)/2 -> 630 | G15: 調理麵包 | J15: =H15-I15 -> 0 | M15: （７）原因別分析
A16: 大口飯糰 | B16: 800 | C16: 780 | D16: =B16-C16 -> 20 | E16: =(B16+C16)/2 -> 790 | G16: 袋裝調理麵包 | J16: =H16-I16 -> 0 | N16: 合計 | P16: 作業原因 | R16: 規格原因
A17: 便當 | B17: 130 | C17: 111 | D17: =B17-C17 -> 19 | E17: =(B17+C17)/2 -> 120.5 | G17: 義大利麵 | J17: =H17-I17 -> 0 | N17: 金額 | O17: 比例 | P17: 金額 | Q17: 比例 | R17: 金額 | S17: 比例
A18: 調理麵 | B18: 140 | C18: 165 | D18: =B18-C18 -> -25 | E18: =(B18+C18)/2 -> 152.5 | G18: 調理包 | J18: =H18-I18 -> 0 | M18: 半成品報廢 | N18: 1200 | O18: =N18/$B$6 -> 0.0024 | P18: 900 | Q18: =IFERROR(P18/$B$6,"") -> 0.0018 | R18: 300 | S18: =IFERROR(R18/$B$6,"") -> 0.0006
M19: 半成品超用 | N19: 4500 | O19: =N19/$B$6 -> 0.009 | P19: 3500 | Q19: =IFERROR(P19/$B$6,"") -> 0.007 | R19: 1000 | S19: =IFERROR(R19/$B$6,"") -> 0.002
A20: （６）人時生產性前幾名品項
B21: 排名 | C21: 商品名 | F21: 人數 | G21: 產能 | H21: 人時生產性 | I21: 前月比 | J21: 主要原因&對策 | M21: （８）報廢原因別前幾名品項
A22: 飯糰 | B22: 1 | C22: 手巻明太子 | F22: 3 | G22: 3000 | H22: 1000 | I22: 10 | J22: 減少暫時停止生產,人時UP | M22: 半成品報廢 | N22: 排名 | O22: 商品名 | R22: 半成品名 | U22: 單價 | V22: 報廢率 | W22: 數量 | X22: 金額 | Y22: 前月比 | Z22: 主要原因&對策
B23: 2 | M23: 作業原因 | N23: 1 | O23: 明太子海苔便當 | R23: 油炸白身魚 | U23: 10 | V23: 0.15 | W23: 10 | X23: =W23*U23 -> 100 | Y23: 80 | Z23: 油調過多報廢。變更條件。
B24: 3 | N24: 2 | X24: =W24*U24 -> 0
B25: 4 | N25: 3 | X25: =W25*U25 -> 0
B26: 5 | N26: 4 | X26: =W26*U26 -> 0
B27: ▼1 | C27: 手巻卵黄雞絞肉 | F27: 4 | G27: 2800 | H27: 700 | I27: 6/30新商品 | J27: 因組裝2食材,人員增加,產速減少 | N27: 5 | X27: =W27*U27 -> 0
B28: ▼2 | U28: 前幾名合計比例 | V28: =X28/N18 -> 0.083333333 | W28: 前幾名合計金額 | X28: =SUM(X23:X27) -> 100
B29: ▼3 | M29: 規格原因 | N29: 1 | O29: 海老炒飯 | R29: 川燙蝦子拌醬 | U29: 5.55 | V29: 0.21 | W29: 50 | X29: =W29*U29 -> 277.5 | Y29: 35 | Z29: 蝦子入數不足
B30: ▼4 | N30: 2 | X30: =W30*U30 -> 0
B31: ▼5 | N31: 3 | X31: =W31*U31 -> 0
N32: 4 | X32: =W32*U32 -> 0
B33: 排名 | C33: 商品名 | F33: 人數 | G33: 產能 | H33: 人時生產性 | I33: 前月比 | J33: 主要原因&對策 | N33: 5 | X33: =W33*U33 -> 0
A34: 大口飯糰 | B34: 1 | C34: 直巻明太子美奶茲 | F34: 3 | G34: 2500 | H34: 833.33 | I34: 20 | J34: 透由調整速度提升。 | U34: 前幾名合計比例 | V34: =X34/N18 -> 0.23125 | W34: 前幾名合計金額 | X34: =SUM(X29:X33) -> 277.5
B35: 2
B36: 3 | M36: 半成品超用 | N36: 排名 | O36: 商品名 | R36: 半成品名 | U36: 單價 | V36: 報廢率 | W36: 數量 | X36: 金額 | Y36: 前月比 | Z36: 主要原因&對策
B37: 4 | M37: 作業原因 | N37: 1 | O37: 特製醬汁炙燒牛五花便當 | R37: 牛五花醬汁 | U37: 25 | V37: 0.25 | W37: 10 | X37: =W37*U37 -> 250 | Y37: 150 | Z37: 難度有差異。調理指導。
B38: 5 | N38: 2 | X38: =W38*U38 -> 0
B39: ▼1 | C39: 大口飯糰燒肉美奶滋 | F39: 7 | G39: 2200 | H39: 314.29 | I39: -15 | J39: 因摺疊增員。實施教育訓練。 | N39: 3 | X39: =W39*U39 -> 0
B40: ▼2 | N40: 4 | X40: =W40*U40 -> 0
B41: ▼3 | N41: 5 | X41: =W41*U41 -> 0
B42: ▼4 | U42: 前幾名合計比例 | V42: =X42/N19 -> 0.055555556 | W42: 前幾名合計金額 | X42: =SUM(X37:X41) -> 250
...

Sheet 生產管理報表(月)
A1: 生產管理報表
A3: 月別 | B3: 10 | C3: 工廠 | D3: 晉欣廠
A4: （１）收支狀況 | E4: ※單位：千元 | G4: （２）ＫＰＩ達成進度
A5: 項目 | B5: 當月 | C5: 前月 | D5: 差異 | E5: 累計 | G5: 項目 | H5: KPI | I5: 當月 | J5: 前月 | K5: 累計 | L5: ※補充
A6: 業績金額 | B6: ='（１）收支狀況'!H10/1000 -> 102477.25 | C6: 224463.49 | D6: =B6-C6 -> -121986.24 | E6: =B6 -> 102477.25 | G6: 人時性(個/月均) | H6: 266 | I6: ='（２）ＫＰＩ達成進度'!H6 -> 0 | J6: 330.21458 | K6: =I6 -> 0 | L6: 個／MH
A7: 訂單數量 | B7: ='（１）收支狀況'!K10 -> 3104723 | C7: 6964636 | D7: =B7-C7 -> -3859913 | E7: =B7 -> 3104723 | G7: 人時達成率(%/月均) | H7: 0.8 | I7: ='（２）ＫＰＩ達成進度'!K6 -> 0 | J7: 0.90222562 | K7: =I7 -> 0 | L7: 達成率
A8: 材料費 | B8: ='（１）收支狀況'!N10/1000 -> 68368.101 | C8: 150244.29 | D8: =B8-C8 -> -81876.191 | E8: =B8 -> 68368.101 | G8: 半成品-報廢(%) | H8: 0.0025 | I8: ='（２）ＫＰＩ達成進度'!N6 -> 0 | J8: 0.0024646257 | K8: =I8 -> 0 | L8: 報廢率
A9: 材料費率 | B9: ='（１）收支狀況'!Q10 -> 0.66715396 | C9: 0.66934847 | D9: =B9-C9 -> -0.0021945132 | E9: =B9 -> 0.66715396 | G9: 半成品-超用(%) | H9: 0.0026 | I9: ='（２）ＫＰＩ達成進度'!Q6 -> 0 | J9: 0.0023405371 | K9: =I9 -> 0 | L9: 超用率
A10: 勞務成本 | B10: ='（１）收支狀況'!T10/1000 -> 13356.389 | C10: 32105.787 | D10: =B10-C10 -> -18749.397 | E10: =B10 -> 13356.389 | G10: 固定產線-導入率(%) | H10: 0.8 | I10: ='（２）ＫＰＩ達成進度'!T6 -> 0 | J10: 0.91666667 | K10: =I10 -> 0 | L10: 導入率
A11: 勞務費率 | B11: ='（１）收支狀況'!W10 -> 0.13033517 | C11: 0.14303345 | D11: =B11-C11 -> -0.01269828 | E11: =B11 -> 0.13033517 | G11: 教育訓練-實施率(%) | H11: 1 | I11: ='（２）ＫＰＩ達成進度'!W6 -> 0 | J11: 0.84941935 | K11: =I11 -> 0 | L11: 實施率
A13: （３）業績構成比 | G13: （４）訂單數量構成比
B14: 當月 | C14: 比例 | D14: 前月 | E14: 差異 | H14: 當月 | I14: 比例 | J14: 前月 | K14: 差異
A15: 18℃-飯A15:A23糰(061,063) | B15: ='（３）業績構成比'!M46/1000 -> 14877.133 | C15: =IFERROR(B15/$B$6,"") -> 0.14517499 | D15: 0.19061186 | E15: =IFERROR(C15-D15,"") -> -0.045436867 | G15: 18℃-飯A15:A23糰(061,063) | H15: ='（４）訂單數量構成比'!M46 -> 857877 | I15: =IFERROR(H15/$B$7,"") -> 0.27631354 | J15: 0.33067557 | K15: =IFERROR(I15-J15,"") -> -0.054362034
A16: 18℃-壽司手卷(071,072,075,076) | B16: ='（３）業績構成比'!S46/1000 -> 3178.9754 | C16: =IFERROR(B16/$B$6,"") -> 0.03102128 | D16: 0.042789234 | E16: =IFERROR(C16-D16,"") -> -0.011767953 | G16: 18℃-壽司手卷(071,072,075,076) | H16: ='（４）訂單數量構成比'!S47 -> 142109 | I16: =IFERROR(H16/$B$7,"") -> 0.045771877 | J16: 0.061681041 | K16: =IFERROR(I16-J16,"") -> -0.015909164
A17: 4℃-飯糰(065) | B17: ='（３）業績構成比'!U46/1000 -> 12922.478 | C17: =IFERROR(B17/$B$6,"") -> 0.12610095 | D17: 0.086938303 | E17: =IFERROR(C17-D17,"") -> 0.039162646 | G17: 4℃-飯糰(065) | H17: ='（４）訂單數量構成比'!U46 -> 390858 | I17: =IFERROR(H17/$B$7,"") -> 0.12589142 | J17: 0.082530228 | K17: =IFERROR(I17-J17,"") -> 0.043361196
A18: 4℃-壽司手卷(077) | B18: ='（３）業績構成比'!W46/1000 -> 738.85392 | C18: =IFERROR(B18/$B$6,"") -> 0.0072099314 | D18: 0.014659146 | E18: =IFERROR(C18-D18,"") -> -0.0074492146 | G18: 4℃-壽司手卷(077) | H18: ='（４）訂單數量構成比'!W46 -> 21594 | I18: =IFERROR(H18/$B$7,"") -> 0.0069552099 | J18: 0.016773741 | K18: =IFERROR(I18-J18,"") -> -0.0098185311
A19: 主食(091,092,093,094,095) | B19: ='（３）業績構成比'!AC46/1000 -> 23714.558 | C19: =IFERROR(B19/$B$6,"") -> 0.23141291 | D19: 0.24409178 | E19: =IFERROR(C19-D19,"") -> -0.01267887 | G19: 主食(091,092,093,094,095) | H19: ='（４）訂單數量構成比'!AC46 -> 625553 | I19: =IFERROR(H19/$B$7,"") -> 0.20148432 | J19: 0.1967306 | K19: =IFERROR(I19-J19,"") -> 0.0047537219
A20: 便當(083) | B20: ='（３）業績構成比'!AE46/1000 -> 16880.541 | C20: =IFERROR(B20/$B$6,"") -> 0.16472477 | D20: 0.13979724 | E20: =IFERROR(C20-D20,"") -> 0.02492753 | G20: 便當(083) | H20: ='（４）訂單數量構成比'!AE46 -> 297631 | I20: =IFERROR(H20/$B$7,"") -> 0.095863947 | J20: 0.079797709 | K20: =IFERROR(I20-J20,"") -> 0.016066237
A21: 熱食義麵(122,123,124,126) | B21: ='（３）業績構成比'!AG46/1000 -> 4886.2339 | C21: =IFERROR(B21/$B$6,"") -> 0.047681159 | D21: 0.13619627 | E21: =IFERROR(C21-D21,"") -> -0.088515107 | G21: 熱食義麵(122,123,124,126) | H21: ='（４）訂單數量構成比'!AG46 -> 107724 | I21: =IFERROR(H21/$B$7,"") -> 0.034696815 | J21: 0.090009011 | K21: =IFERROR(I21-J21,"") -> -0.055312196
A22: 季節調理麵(111,112) | B22: ='（３）業績構成比'!AI46/1000 -> 13959.106 | C22: =IFERROR(B22/$B$6,"") -> 0.13621664 | D22: 0.068175374 | E22: =IFERROR(C22-D22,"") -> 0.068041263 | G22: 季節調理麵(111,112) | H22: ='（４）訂單數量構成比'!AI46 -> 378237 | I22: =IFERROR(H22/$B$7,"") -> 0.12182633 | J22: 0.05972114 | K22: =IFERROR(I22-J22,"") -> 0.062105187
A23: 微波小吃(153,154,155) | B23: ='（３）業績構成比'!AK46/1000 -> 7885.6864 | C23: =IFERROR(B23/$B$6,"") -> 0.076950608 | D23: 0.076740802 | E23: =IFERROR(C23-D23,"") -> 0.00020980537 | G23: 微波小吃(153,154,155) | H23: ='（４）訂單數量構成比'!AK46 -> 283140 | I23: =IFERROR(H23/$B$7,"") -> 0.091196542 | J23: 0.082080959 | K23: =IFERROR(I23-J23,"") -> 0.0091155828
C24: =SUM(C15:C23) -> 0.96649323 | D24: =SUM(D15:D23) -> 1 | I24: =SUM(I15:I23) -> 1 | J24: =SUM(J15:J23) -> 1
A26: （５）品群別人時生產性
A27: 品群 | B27: 當月 | C27: 前月 | D27: 差異 | E27: 累計 | M27: 8月 | N27: 9月 | O27: 10月 | P27: 11月 | Q27: 12月
A28: 18℃-飯A15:A23糰(061,063) | B28: ='（５-1）品群別人時生產性（18℃-飯糰）'!$C$1 -> 753.9018 | C28: 756.20247 | D28: =B28-C28 -> -2.3006712 | E28: =R28 -> 735.71467 | M28: 717.52753 | N28: =B28 -> 753.9018 | R28: =AVERAGE(M28:Q28) -> 735.71467
A29: 18℃-壽司手卷(071,072,075,076) | B29: ='（５-2）品群別人時生產性（18-壽司手卷)'!$C$1 -> 175.26729 | C29: 198.82982 | D29: =B29-C29 -> -23.562533 | E29: =R29 -> 186.45 | M29: 197.63272 | N29: =B29 -> 175.26729 | R29: =AVERAGE(M29:Q29) -> 186.45
A30: 4℃-飯糰(065) | B30: ='（５-3）品群別人時生產性（4℃-飯糰)'!$C$1 -> 252.90143 | C30: 253.36933 | D30: =B30-C30 -> -0.46789865 | E30: =R30 -> 246.68 | M30: 240.45857 | N30: =B30 -> 252.90143 | R30: =AVERAGE(M30:Q30) -> 246.68
A31: 4℃-壽司手卷(077) | B31: ='（５-4）品群別人時生產性（4℃-壽司手卷)'!$C$1 -> 111.8163 | C31: 112.99131 | D31: =B31-C31 -> -1.1750111 | E31: =R31 -> 109.34071 | M31: 106.86512 | N31: =B31 -> 111.8163 | R31: =AVERAGE(M31:Q31) -> 109.34071
A32: 主食(091,092,093,094,095) | B32: ='（５-5）品群別人時生產性(主食) '!$C$1 -> 87.340599 | C32: 85.495684 | D32: =B32-C32 -> 1.8449143 | E32: =R32 -> 88.325514 | M32: 89.310428 | N32: =B32 -> 87.340599 | R32: =AVERAGE(M32:Q32) -> 88.325514
A33: 便當(083) | B33: ='（５-6）品群別人時生產性(便當)'!$C$1 -> 72.510018 | C33: 66.943614 | D33: =B33-C33 -> 5.5664042 | E33: =R33 -> 69.09138 | M33: 65.672742 | N33: =B33 -> 72.510018 | R33: =AVERAGE(M33:Q33) -> 69.09138
A34: 熱食義麵(122,123,124,126) | B34: ='（５-7）品群別人時生產性(熱食義麵) '!$C$1 -> 86.002697 | C34: 80.555861 | D34: =B34-C34 -> 5.4468356 | E34: =R34 -> 80.740633 | M34: 75.478569 | N34: =B34 -> 86.002697 | R34: =AVERAGE(M34:Q34) -> 80.740633
A35: 季節調理麵(111,112) | B35: ='（５-8）品群別人時生產性(季節調理麵) '!$C$1 -> 124.02871 | C35: 121.13263 | D35: =B35-C35 -> 2.8960884 | E35: =R35 -> 119.26714 | M35: 114.50557 | N35: =B35 -> 124.02871 | R35: =AVERAGE(M35:Q35) -> 119.26714
A36: 微波小吃(153,154,155) | B36: ='（５-9）品群別人時生產性(微波小吃)'!$C$1 -> 177.97086 | C36: 115.36623 | D36: =B36-C36 -> 62.604633 | E36: =R36 -> 138.8096 | M36: 99.648342 | N36: =B36 -> 177.97086 | R36: =AVERAGE(M36:Q36) -> 138.8096

Sheet 生產管理報表(週) 
A1: 生產管理報表
A3: 月別 | B3: 4 | C3: 週別 | D3: W2 | E3: 工廠 | F3: 晉欣廠
A4: （１）收支狀況 | E4: ※單位：千元 | G4: （２）ＫＰＩ達成進度
A5: 項目 | B5: 當週 | C5: 前週 | D5: 差異 | E5: 累計 | G5: 項目 | H5: KPI | I5: 當週 | J5: 前週 | K5: 累計 | L5: ※補充
A6: 業績金額 | B6: ='（１）收支狀況'!G11/1000 -> 58053.442 | C6: 52952.468 | D6: =B6-C6 -> 5100.974 | E6: ='（１）收支狀況'!H10/1000 -> 102477.25 | G6: 人時性(個/月均) | H6: 366 | I6: ='（２）ＫＰＩ達成進度'!G11 -> 341.49684 | J6: 353.49823 | K6: ='（２）ＫＰＩ達成進度'!H10 -> 347.36685 | L6: 個／MH
A7: 訂單數量 | B7: ='（１）收支狀況'!J11 -> 1752697 | C7: 1615819 | D7: =B7-C7 -> 136878 | E7: ='（１）收支狀況'!K10 -> 3104723 | G7: 人時達成率(%/月均) | H7: 0.8 | I7: ='（２）ＫＰＩ達成進度'!J11 -> 0.93305147 | J7: 0.97453068 | K7: ='（２）ＫＰＩ達成進度'!K10 -> 0.41127223 | L7: 達成率
A8: 材料費 | B8: ='（１）收支狀況'!M11/1000 -> 38350.673 | C8: 35685.182 | D8: =B8-C8 -> 2665.491 | E8: ='（１）收支狀況'!N10/1000 -> 68368.101 | G8: 半成品-報廢(%) | H8: 0.0025 | I8: ='（２）ＫＰＩ達成進度'!M11 -> 0.0024328571 | J8: 0.0024406424 | K8: ='（２）ＫＰＩ達成進度'!N10 -> 0.0024366345 | L8: 報廢率
A9: 材料費率 | B9: ='（１）收支狀況'!P11 -> 0.66060981 | C9: 0.6739097 | D9: =B9-C9 -> -0.013299898 | E9: ='（１）收支狀況'!Q10 -> 0.66715396 | G9: 半成品-超用(%) | H9: 0.0026 | I9: ='（２）ＫＰＩ達成進度'!P11 -> 0.0017039516 | J9: 0.0018040733 | K9: ='（２）ＫＰＩ達成進度'!Q10 -> 0.0017536547 | L9: 超用率
A10: 勞務成本 | B10: ='（１）收支狀況'!S11/1000 -> 7316.8547 | C10: =7053342/1000 -> 7053.342 | D10: =B10-C10 -> 263.51266 | E10: ='（１）收支狀況'!T10/1000 -> 13356.389 | G10: 固定產線-導入率(%) | H10: 0.8 | I10: 0.9111 | J10: 0.9135 | K10: 0.917 | L10: 導入率
A11: 勞務費率 | B11: ='（１）收支狀況'!V11 -> 0.12603653 | C11: 0.1332 | D11: =B11-C11 -> -0.0071634652 | E11: ='（１）收支狀況'!W10 -> 0.13033517 | G11: 教育訓練-實施率(%) | H11: 1 | I11: ='（２）ＫＰＩ達成進度'!V11 -> 0.25257143 | J11: 0.22542857 | K11: ='（２）ＫＰＩ達成進度'!W10 -> 0.24076923 | L11: 實施率
A13: （３）業績構成比 | G13: （４）訂單數量構成比
B14: 當週 | C14: 比例 | D14: 前週 | E14: 差異 | H14: 當週 | I14: 比例 | J14: 前週 | K14: 差異
A15: 18℃-飯糰(061,063) | B15: =SUM('（３）業績構成比'!I13:I19,'（３）業績構成比'!K13:K19)/1000 -> 9244.4578 | C15: =IFERROR(B15/$B$6,"") -> 0.15924048 | D15: 0.15559681 | E15: =IFERROR(C15-D15,"") -> 0.0036436633 | G15: 18℃-飯糰(061,063) | H15: =SUM(,'（４）訂單數量構成比'!I13:I19,'（４）訂單數量構成比'!K13:K19) -> 490036 | I15: =IFERROR(H15/$B$7,"") -> 0.27958968 | J15: 0.2736736 | K15: =IFERROR(I15-J15,"") -> 0.0059160854
A16: 18℃-壽司手卷(071,072,075,076) | B16: =SUM('（３）業績構成比'!O13:O19,'（３）業績構成比'!Q13:Q19)/1000 -> 1969.5632 | C16: =IFERROR(B16/$B$6,"") -> 0.033926726 | D16: 0.03367305 | E16: =IFERROR(C16-D16,"") -> 0.00025367519 | G16: 18℃-壽司手卷(071,072,075,076) | H16: =SUM('（４）訂單數量構成比'!O13:O19,'（４）訂單數量構成比'!Q13:Q19) -> 78044 | I16: =IFERROR(H16/$B$7,"") -> 0.044527948 | J16: 0.046029908 | K16: =IFERROR(I16-J16,"") -> -0.0015019606
A17: 4℃-飯糰(065) | B17: =SUM('（３）業績構成比'!U13:U19)/1000 -> 7297.2272 | C17: =IFERROR(B17/$B$6,"") -> 0.12569844 | D17: 0.1273697 | E17: =IFERROR(C17-D17,"") -> -0.0016712618 | G17: 4℃-飯糰(065) | H17: =SUM('（４）訂單數量構成比'!U13:U19) -> 220640 | I17: =IFERROR(H17/$B$7,"") -> 0.12588599 | J17: 0.12632046 | K17: =IFERROR(I17-J17,"") -> -0.0004344687
A18: 4℃-壽司手卷(077) | B18: =SUM('（３）業績構成比'!W13:W19)/1000 -> 391.57974 | C18: =IFERROR(B18/$B$6,"") -> 0.0067451597 | D18: 0.0078544147 | E18: =IFERROR(C18-D18,"") -> -0.001109255 | G18: 4℃-壽司手卷(077) | H18: =SUM('（４）訂單數量構成比'!W13:W19) -> 11435 | I18: =IFERROR(H18/$B$7,"") -> 0.0065242309 | J18: 0.0075194066 | K18: =IFERROR(I18-J18,"") -> -0.00099517562
A19: 主食(091,092,093,094,095) | B19: =SUM('（３）業績構成比'!Y13:Y19,'（３）業績構成比'!AA13:AA19)/1000 -> 14225.82 | C19: =IFERROR(B19/$B$6,"") -> 0.24504697 | D19: 0.25413807 | E19: =IFERROR(C19-D19,"") -> -0.0090910996 | G19: 主食(091,092,093,094,095) | H19: =SUM('（４）訂單數量構成比'!Y13:Y19,'（４）訂單數量構成比'!AA13:AA19) -> 348342 | I19: =IFERROR(H19/$B$7,"") -> 0.19874628 | J19: 0.20333651 | K19: =IFERROR(I19-J19,"") -> -0.0045902373
A20: 便當(083) | B20: =SUM('（３）業績構成比'!AE13:AE19)/1000 -> 9553.7182 | C20: =IFERROR(B20/$B$6,"") -> 0.16456764 | D20: 0.16920595 | E20: =IFERROR(C20-D20,"") -> -0.0046383067 | G20: 便當(083) | H20: =SUM('（４）訂單數量構成比'!AE13:AE19) -> 169490 | I20: =IFERROR(H20/$B$7,"") -> 0.096702396 | J20: 0.096640775 | K20: =IFERROR(I20-J20,"") -> 6.1621624e-05
A21: 熱食義麵(122,123,124,126) | B21: =SUM('（３）業績構成比'!AG13:AG19)/1000 -> 2907.4806 | C21: =IFERROR(B21/$B$6,"") -> 0.050082828 | D21: 0.040852663 | E21: =IFERROR(C21-D21,"") -> 0.0092301655 | G21: 熱食義麵(122,123,124,126) | H21: =SUM('（４）訂單數量構成比'!AG13:AG19) -> 63766 | I21: =IFERROR(H21/$B$7,"") -> 0.036381645 | J21: 0.030008312 | K21: =IFERROR(I21-J21,"") -> 0.0063733334
A22: 季節調理麵(111,112) | B22: =SUM('（３）業績構成比'!AI13:AI19)/1000 -> 8082.3765 | C22: =IFERROR(B22/$B$6,"") -> 0.13922304 | D22: 0.13128237 | E22: =IFERROR(C22-D22,"") -> 0.0079406694 | G22: 季節調理麵(111,112) | H22: =SUM('（４）訂單數量構成比'!AI13:AI19) -> 219074 | I22: =IFERROR(H22/$B$7,"") -> 0.12499251 | J22: 0.11649634 | K22: =IFERROR(I22-J22,"") -> 0.0084961713
A23: 微波小吃(153,154,155) | B23: =SUM('（３）業績構成比'!AK13:AK19)/1000 -> 4381.2188 | C23: =IFERROR(B23/$B$6,"") -> 0.075468717 | D23: 0.080026967 | E23: =IFERROR(C23-D23,"") -> -0.0045582503 | G23: 微波小吃(153,154,155) | H23: =SUM('（４）訂單數量構成比'!AK13:AK19) -> 151870 | I23: =IFERROR(H23/$B$7,"") -> 0.086649318 | J23: 0.099974688 | K23: =IFERROR(I23-J23,"") -> -0.01332537
C24: =SUM(C15:C23) -> 1 | D24: =SUM(D15:D23) -> 1 | I24: =SUM(I15:I23) -> 1 | J24: =SUM(J15:J23) -> 1
A26: （５）品群別人時生產性
A27: 品群 | B27: 當週 | C27: 前週 | D27: 差異 | E27: 累計
A28: 18℃-飯糰(061,063) | B28: ='（５-1）品群別人時生產性（18℃-飯糰）'!L42 -> 762.06763 | C28: 745.73597 | D28: =B28-C28 -> 16.331655 | E28: ='（５-1）品群別人時生產性（18℃-飯糰）'!C1 -> 753.9018
A29: 18℃-壽司手卷(071,072,075,076) | B29: ='（５-2）品群別人時生產性（18-壽司手卷)'!L27 -> 179.6039 | C29: 170.93068 | D29: =B29-C29 -> 8.6732222 | E29: ='（５-2）品群別人時生產性（18-壽司手卷)'!C1 -> 175.26729
A30: 4℃-飯糰(065) | B30: ='（５-3）品群別人時生產性（4℃-飯糰)'!L27 -> 245.86202 | C30: 259.94085 | D30: =B30-C30 -> -14.078836 | E30: ='（５-3）品群別人時生產性（4℃-飯糰)'!C1 -> 252.90143
A31: 4℃-壽司手卷(077) | B31: ='（５-4）品群別人時生產性（4℃-壽司手卷)'!L27 -> 111.40783 | C31: 112.22478 | D31: =B31-C31 -> -0.81694972 | E31: ='（５-4）品群別人時生產性（4℃-壽司手卷)'!C1 -> 111.8163
A32: 主食(091,092,093,094,095) | B32: ='（５-5）品群別人時生產性(主食) '!L42 -> 87.318765 | C32: 87.362433 | D32: =B32-C32 -> -0.043667893 | E32: ='（５-5）品群別人時生產性(主食) '!C1 -> 87.340599
A33: 便當(083) | B33: ='（５-6）品群別人時生產性(便當)'!L27 -> 72.335991 | C33: 72.684045 | D33: =B33-C33 -> -0.3480542 | E33: ='（５-6）品群別人時生產性(便當)'!C1 -> 72.510018
A34: 熱食義麵(122,123,124,126) | B34: ='（５-7）品群別人時生產性(熱食義麵) '!L27 -> 85.588968 | C34: 86.416426 | D34: =B34-C34 -> -0.82745877 | E34: ='（５-7）品群別人時生產性(熱食義麵) '!C1 -> 86.002697
A35: 季節調理麵(111,112) | B35: ='（５-8）品群別人時生產性(季節調理麵) '!L27 -> 124.46114 | C35: 123.59628 | D35: =B35-C35 -> 0.86486046 | E35: ='（５-8）品群別人時生產性(季節調理麵) '!C1 -> 124.02871
A36: 微波小吃(153,154,155) | B36: ='（５-9）品群別人時生產性(微波小吃)'!L27 -> 177.45558 | C36: 178.48614 | D36: =B36-C36 -> -1.0305632 | E36: ='（５-9）品群別人時生產性(微波小吃)'!C1 -> 177.97086

Sheet （１）收支狀況
B2: （１）收支狀況
C3: 月份 | D3: 日期 | F3: 營業額(元) | I3: 訂單數量(個) | L3: 材料費(元) | O3: 材料費率（材料費／營業額） | R3: 勞務成本（全廠人事成本） | U3: 勞務費率（勞務成本／營業額）
F4: 日 | G4: 週累積 | H4: 月累積 | I4: 日 | J4: 週累積 | K4: 月累積 | L4: 日 | M4: 週累積 | N4: 月累積 | O4: 日 | P4: 週累積 | Q4: 月平均 | R4: 日 | S4: 週累積 | T4: 月累積 | U4: 日 | V4: 週累積 | W4: 月平均
D5: 46113 | E5: 三 | F5: 7706722 | I5: 240873 | L5: 5520414 | O5: =L5/F5 -> 0.71631155 | R5: 1030119.2 | U5: =R5/F5 -> 0.13366503
D6: =D5+1 -> 46114 | E6: 四 | F6: 7008581 | G6: =SUM(F5:F10) -> 44423805 | I6: 219733 | J6: =SUM(I5:I10) -> 1352026 | L6: 5014165 | M6: =SUM(L5:L10) -> 30017428 | O6: =L6/F6 -> 0.71543227 | P6: =M6/G6 -> 0.67570592 | R6: 1007333.1 | S6: =SUM(R5:R10) -> 6039534.7 | U6: =R6/F6 -> 0.14372854 | V6: =S6/G6 -> 0.13595266
D7: =D6+1 -> 46115 | E7: 五 | F7: 6828155 | I7: 208291 | L7: 4573820 | O7: =L7/F7 -> 0.66984713 | R7: 970568.31 | U7: =R7/F7 -> 0.1421421
D8: =D7+1 -> 46116 | E8: 六 | F8: 6946481 | I8: 206015 | L8: 4682963 | O8: =L8/F8 -> 0.67414897 | R8: 965055.55 | U8: =R8/F8 -> 0.13892726
D9: =D8+1 -> 46117 | E9: 日 | F9: 7261197 | I9: 218068 | L9: 4774537 | O9: =L9/F9 -> 0.65754131 | R9: 973359.31 | U9: =R9/F9 -> 0.13404943
D10: =D9+1 -> 46118 | E10: 一 | F10: 8672669 | H10: =SUM(F5:F34) -> 102477247 | I10: 259046 | K10: =SUM(I5:I34) -> 3104723 | L10: 5451529 | N10: =SUM(L5:L34) -> 68368101 | O10: =L10/F10 -> 0.62858723 | Q10: =N10/H10 -> 0.66715396 | R10: 1093099.2 | T10: =SUM(R5:R35) -> 13356389 | U10: =R10/F10 -> 0.12603954 | W10: =T10/H10 -> 0.13033517
D11: =D10+1 -> 46119 | E11: 二 | F11: 8371655 | G11: =SUM(F11:F17) -> 58053442 | I11: 253131 | J11: =SUM(I11:I17) -> 1752697 | L11: 5622332 | M11: =SUM(L11:L17) -> 38350673 | O11: =L11/F11 -> 0.67159146 | P11: =M11/G11 -> 0.66060981 | R11: 1059039 | S11: =SUM(R11:R17) -> 7316854.7 | U11: =R11/F11 -> 0.12650294 | V11: =S11/G11 -> 0.12603653
D12: =D11+1 -> 46120 | E12: 三 | F12: 8123789 | I12: 245780 | L12: 5359721 | O12: =L12/F12 -> 0.6597563 | R12: 1028044.6 | U12: =R12/F12 -> 0.12654743
D13: =D12+1 -> 46121 | E13: 四 | F13: 7630691 | I13: 232518 | L13: 4997232 | O13: =L13/F13 -> 0.65488591 | R13: 1013463.3 | U13: =R13/F13 -> 0.13281409
D14: =D13+1 -> 46122 | E14: 五 | F14: 7424675 | I14: 224499 | L14: 4893396 | O14: =L14/F14 -> 0.65907208 | R14: 1020067.5 | U14: =R14/F14 -> 0.13738885
D15: =D14+1 -> 46123 | E15: 六 | F15: 7969209 | I15: 237989 | L15: 5337220 | O15: =L15/F15 -> 0.66973021 | R15: 1016548.3 | U15: =R15/F15 -> 0.1275595
D16: =D15+1 -> 46124 | E16: 日 | F16: 9249267 | I16: 277628 | L16: 6159720 | O16: =L16/F16 -> 0.66596845 | R16: 1076807.9 | U16: =R16/F16 -> 0.11642089
D17: =D16+1 -> 46125 | E17: 一 | F17: 9284156 | I17: 281152 | L17: 5981052 | O17: =L17/F17 -> 0.6442214 | R17: 1102884.1 | U17: =R17/F17 -> 0.11879206
D18: =D17+1 -> 46126 | E18: 二 | G18: =SUM(F18:F24) -> 0 | J18: =SUM(I18:I24) -> 0 | M18: =SUM(L18:L24) -> 0 | O18: =L18/F18 -> #DIV/0! | P18: =M18/G18 -> #DIV/0! | S18: =SUM(R18:R24) -> 0 | U18: =R18/F18 -> #DIV/0! | V18: =S18/M18 -> #DIV/0!
D19: =D18+1 -> 46127 | E19: 三 | O19: =L19/F19 -> #DIV/0! | U19: =R19/F19 -> #DIV/0!
D20: =D19+1 -> 46128 | E20: 四 | O20: =L20/F20 -> #DIV/0! | U20: =R20/F20 -> #DIV/0!
D21: =D20+1 -> 46129 | E21: 五 | O21: =L21/F21 -> #DIV/0! | U21: =R21/F21 -> #DIV/0!
D22: =D21+1 -> 46130 | E22: 六 | O22: =L22/F22 -> #DIV/0! | U22: =R22/F22 -> #DIV/0!
D23: =D22+1 -> 46131 | E23: 日 | O23: =L23/F23 -> #DIV/0! | U23: =R23/F23 -> #DIV/0!
D24: =D23+1 -> 46132 | E24: 一 | O24: =L24/F24 -> #DIV/0! | U24: =R24/F24 -> #DIV/0!
D25: =D24+1 -> 46133 | E25: 二 | G25: =SUM(F25:F31) -> 0 | J25: =SUM(I25:I31) -> 0 | M25: =SUM(L25:L31) -> 0 | O25: =L25/F25 -> #DIV/0! | P25: =M25/G25 -> #DIV/0! | S25: =SUM(R25:R31) -> 0 | U25: =R25/F25 -> #DIV/0! | V25: =S25/M25 -> #DIV/0!
D26: =D25+1 -> 46134 | E26: 三 | O26: =L26/F26 -> #DIV/0! | U26: =R26/F26 -> #DIV/0!
D27: =D26+1 -> 46135 | E27: 四 | O27: =L27/F27 -> #DIV/0! | U27: =R27/F27 -> #DIV/0!
D28: =D27+1 -> 46136 | E28: 五 | O28: =L28/F28 -> #DIV/0! | U28: =R28/F28 -> #DIV/0!
D29: =D28+1 -> 46137 | E29: 六 | O29: =L29/F29 -> #DIV/0! | U29: =R29/F29 -> #DIV/0!
D30: =D29+1 -> 46138 | E30: 日 | O30: =L30/F30 -> #DIV/0! | U30: =R30/F30 -> #DIV/0!
D31: =D30+1 -> 46139 | E31: 一 | O31: =L31/F31 -> #DIV/0! | U31: =R31/F31 -> #DIV/0!
D32: =D31+1 -> 46140 | E32: 二 | G32: =SUM(F32:F38) -> 0 | J32: =SUM(I32:I38) -> 0 | M32: =SUM(L32:L38) -> 0 | O32: =L32/F32 -> #DIV/0! | P32: =M32/G32 -> #DIV/0! | S32: =SUM(R32:R38) -> 0 | U32: =R32/F32 -> #DIV/0! | V32: =S32/M32 -> #DIV/0!
D33: =D32+1 -> 46141 | E33: 三 | O33: =L33/F33 -> #DIV/0! | U33: =R33/F33 -> #DIV/0!
D34: =D33+1 -> 46142 | E34: 四 | O34: =L34/F34 -> #DIV/0! | U34: =R34/F34 -> #DIV/0!
D35: =D34+1 -> 46143 | E35: 五 | O35: =L35/F35 -> #DIV/0! | U35: =R35/F35 -> #DIV/0!
D36: =D35+1 -> 46144 | E36: 六 | O36: =L36/F36 -> #DIV/0! | U36: =R36/F36 -> #DIV/0!
D37: =D36+1 -> 46145 | E37: 日 | O37: =L37/F37 -> #DIV/0! | U37: =R37/F37 -> #DIV/0!
D38: =D37+1 -> 46146 | E38: 一 | O38: =L38/F38 -> #DIV/0! | U38: =R38/F38 -> #DIV/0!
O39: =L39/F39 -> #DIV/0! | U39: =R39/F39 -> #DIV/0!
O40: =L40/F40 -> #DIV/0! | U40: =R40/F40 -> #DIV/0!
O41: =L41/F41 -> #DIV/0! | U41: =R41/F41 -> #DIV/0!
...

Sheet （２）ＫＰＩ達成進度
B1: KPI | C1: 366
B2: （２）ＫＰＩ達成進度
C3: 月份 | D3: 日期 | F3: 人時生產性(個/人) | I3: 人時生產性達成率(%) | L3: 半成品報廢(%) | O3: 半成品超用(%) | R3: 固定產線-導入率(固定產線數/總產線數) | U3: 教育訓練-實施率(進度/計畫)
F4: 日 | G4: 週平均 | H4: 月平均 | I4: 日 | J4: 週平均 | K4: 月平均 | L4: 日 | M4: 週平均 | N4: 月平均 | O4: 日 | P4: 週平均 | Q4: 月平均 | R4: 日 | S4: 週平均 | T4: 月平均 | U4: 日 | V4: 週平均 | W4: 月平均
D5: 46113 | E5: 三 | F5: 363.4615 | I5: =F5/$C$1 -> 0.9930642 | L5: 0.0024438406 | O5: 0.001716269 | R5: 0.917 | U5: 0.22
D6: =D5+1 -> 46114 | E6: 四 | F6: 356.08261 | G6: =AVERAGE(F5:F10) -> 354.21521 | I6: =F6/$C$1 -> 0.97290332 | J6: =AVERAGE(I5:I10) -> 0.96780111 | L6: 0.0024211748 | M6: =AVERAGE(L5:L10) -> 0.0024410414 | O6: 0.002014793 | P6: =AVERAGE(O5:O10) -> 0.0018116416 | R6: 0.917 | S6: =AVERAGE(R5:R10) -> 0.917 | U6: 0.224 | V6: =AVERAGE(U5:U10) -> 0.227
D7: =D6+1 -> 46115 | E7: 五 | F7: 357.47134 | I7: =F7/$C$1 -> 0.97669764 | L7: 0.0024401907 | O7: 0.0019703956 | R7: 0.917 | U7: 0.226
D8: =D7+1 -> 46116 | E8: 六 | F8: 358.65605 | I8: =F8/$C$1 -> 0.97993456 | L8: 0.0024577912 | O8: 0.0017291779 | R8: 0.917 | U8: 0.23
D9: =D8+1 -> 46117 | E9: 日 | F9: 355.20151 | I9: =F9/$C$1 -> 0.97049593 | L9: 0.0024377523 | O9: 0.001723556 | R9: 0.917 | U9: 0.23
D10: =D9+1 -> 46118 | E10: 一 | F10: 334.41823 | H10: =AVERAGE(F5:F34) -> 347.36685 | I10: =F10/$C$1 -> 0.913711 | K10: =AVERAGE(I5:I34) -> 0.41127223 | L10: 0.0024454986 | N10: =AVERAGE(L5:L34) -> 0.0024366345 | O10: 0.001715658 | Q10: =AVERAGE(O5:O34) -> 0.0017536547 | R10: 0.917 | T10: =AVERAGE(R5:R34) -> 0.917 | U10: 0.232 | W10: =AVERAGE(U5:U34) -> 0.24076923
D11: =D10+1 -> 46119 | E11: 二 | F11: 341.21025 | G11: =AVERAGE(F11:F17) -> 341.49684 | I11: =F11/$C$1 -> 0.93226845 | J11: =AVERAGE(I11:I17) -> 0.93305147 | L11: 0.00243 | M11: =AVERAGE(L11:L17) -> 0.0024328571 | O11: 0.0015793354 | P11: =AVERAGE(O11:O17) -> 0.0017039516 | R11: 0.917 | S11: =AVERAGE(R11:R17) -> 0.917 | U11: 0.238 | V11: =AVERAGE(U11:U17) -> 0.25257143
D12: =D11+1 -> 46120 | E12: 三 | F12: 340.85386 | I12: =F12/$C$1 -> 0.93129471 | L12: 0.00242 | O12: 0.0016664692 | R12: 0.917 | U12: 0.246
D13: =D12+1 -> 46121 | E13: 四 | F13: 343.26629 | I13: =F13/$C$1 -> 0.93788605 | L13: 0.00243 | O13: 0.0018566746 | R13: 0.917 | U13: 0.248
D14: =D13+1 -> 46122 | E14: 五 | F14: 345.26214 | I14: =F14/$C$1 -> 0.94333918 | L14: 0.00243 | O14: 0.0017921196 | R14: 0.917 | U14: 0.256
D15: =D14+1 -> 46123 | E15: 六 | F15: 334.999 | I15: =F15/$C$1 -> 0.91529781 | L15: 0.00245 | O15: 0.001669923 | R15: 0.917 | U15: 0.26
D16: =D15+1 -> 46124 | E16: 日 | F16: 339.93589 | I16: =F16/$C$1 -> 0.92878658 | L16: 0.00243 | O16: 0.0017437675 | R16: 0.917 | U16: 0.26
D17: =D16+1 -> 46125 | E17: 一 | F17: 344.95042 | I17: =F17/$C$1 -> 0.94248749 | L17: 0.00244 | O17: 0.0016193718 | R17: 0.917 | U17: 0.26
D18: =D17+1 -> 46126 | E18: 二 | G18: =AVERAGE(F18:F24) -> #DIV/0! | I18: =F18/$C$1 -> 0 | J18: =AVERAGE(I18:I24) -> 0 | M18: =AVERAGE(L18:L24) -> #DIV/0! | P18: =AVERAGE(O18:O24) -> #DIV/0! | S18: =AVERAGE(R18:R24) -> #DIV/0! | V18: =AVERAGE(U18:U24) -> #DIV/0!
D19: =D18+1 -> 46127 | E19: 三 | I19: =F19/$C$1 -> 0
D20: =D19+1 -> 46128 | E20: 四 | I20: =F20/$C$1 -> 0
D21: =D20+1 -> 46129 | E21: 五 | I21: =F21/$C$1 -> 0
D22: =D21+1 -> 46130 | E22: 六 | I22: =F22/$C$1 -> 0
D23: =D22+1 -> 46131 | E23: 日 | I23: =F23/$C$1 -> 0
D24: =D23+1 -> 46132 | E24: 一 | I24: =F24/$C$1 -> 0
D25: =D24+1 -> 46133 | E25: 二 | G25: =AVERAGE(F25:F31) -> #DIV/0! | I25: =F25/$C$1 -> 0 | J25: =AVERAGE(I25:I31) -> 0 | M25: =AVERAGE(L25:L31) -> #DIV/0! | P25: =AVERAGE(O25:O31) -> #DIV/0! | S25: =AVERAGE(R25:R31) -> #DIV/0! | V25: =AVERAGE(U25:U31) -> #DIV/0!
D26: =D25+1 -> 46134 | E26: 三 | I26: =F26/$C$1 -> 0
D27: =D26+1 -> 46135 | E27: 四 | I27: =F27/$C$1 -> 0
D28: =D27+1 -> 46136 | E28: 五 | I28: =F28/$C$1 -> 0
D29: =D28+1 -> 46137 | E29: 六 | I29: =F29/$C$1 -> 0
D30: =D29+1 -> 46138 | E30: 日 | I30: =F30/$C$1 -> 0
D31: =D30+1 -> 46139 | E31: 一 | I31: =F31/$C$1 -> 0
D32: =D31+1 -> 46140 | E32: 二 | G32: =AVERAGE(F32:F38) -> #DIV/0! | I32: =F32/$C$1 -> 0 | J32: =AVERAGE(I32:I38) -> 0 | M32: =AVERAGE(L32:L38) -> #DIV/0! | P32: =AVERAGE(O32:O38) -> #DIV/0! | S32: =AVERAGE(R32:R38) -> #DIV/0! | V32: =AVERAGE(U32:U38) -> #DIV/0!
D33: =D32+1 -> 46141 | E33: 三 | I33: =F33/$C$1 -> 0
D34: =D33+1 -> 46142 | E34: 四 | I34: =F34/$C$1 -> 0
D35: =D34+1 -> 46143 | E35: 五 | I35: =F35/$C$1 -> 0
D36: =D35+1 -> 46144 | E36: 六 | I36: =F36/$C$1 -> 0
D37: =D36+1 -> 46145 | E37: 日 | I37: =F37/$C$1 -> 0
D38: =D37+1 -> 46146 | E38: 一 | I38: =F38/$C$1 -> 0
I39: =F39/$C$1 -> 0
I40: =F40/$C$1 -> 0

Sheet （３）業績構成比
B2: （3）業績構成比
C3: 月份 | D3: 日期 | F3: 營業額 | I3: 品類業績
I4: 18℃-飯糰 | O4: 18℃-壽司手卷 | U4: 4℃-飯糰 | W4: 4℃-壽司手卷 | Y4: 主食 | AE4: 便當 | AG4: 熱食義麵 | AI4: 季節調理麵 | AK4: 微波小吃
F5: 日 | G5: 週累積 | H5: 月累積 | I5: 一配 | K5: 二配 | M5: 合計 | O5: 一配 | Q5: 二配 | S5: 合計 | U5: 一配 | W5: 一配 | Y5: 一配 | AA5: 二配 | AC5: 合計 | AE5: 一配 | AG5: 一配 | AI5: 一配 | AK5: 一配
I6: 業績(元) | J6: 比例(%) | K6: 業績(元) | L6: 比例(%) | M6: 業績(元) | N6: 比例(%) | O6: 業績(元) | P6: 比例(%) | Q6: 業績(元) | R6: 比例(%) | S6: 業績(元) | T6: 比例(%) | U6: 業績(元) | V6: 比例(%) | W6: 業績(元) | X6: 比例(%) | Y6: 業績(元) | Z6: 比例(%) | AA6: 業績(元) | AB6: 比例(%) | AC6: 業績(元) | AD6: 比例(%) | AE6: 業績(元) | AF6: 比例(%) | AG6: 業績(元) | AH6: 比例(%) | AI6: 業績(元) | AJ6: 比例(%) | AK6: 業績(元) | AL6: 比例(%)
D7: 46113 | E7: 三 | F7: =SUM(M7,S7,U7,W7,AC7,AE7,AG7,AI7,AK7) -> 7706722 | I7: 508211.28 | J7: =I7/F7 -> 0.065943897 | K7: 711524.56 | L7: =K7/F7 -> 0.092325189 | M7: =SUM(I7+K7) -> 1219735.8 | N7: =M7/F7 -> 0.15826909 | O7: 150820.06 | P7: =O7/F7 -> 0.019569936 | Q7: 168715.45 | R7: =Q7/$F7 -> 0.021891986 | S7: =SUM(O7+Q7) -> 319535.51 | T7: =S7/F7 -> 0.041461923 | U7: 980045.62 | V7: =U7/F7 -> 0.12716764 | W7: 63147.078 | X7: =W7/F7 -> 0.0081937662 | Y7: 836834.77 | Z7: =Y7/F7 -> 0.10858505 | AA7: 1057575.2 | AB7: =AA7/$F7 -> 0.13722763 | AC7: =SUM(Y7+AA7) -> 1894410 | AD7: =AC7/F7 -> 0.24581268 | AE7: 1362045.7 | AF7: =AE7/F7 -> 0.17673476 | AG7: 172357.17 | AH7: =AG7/F7 -> 0.022364524 | AI7: 1045807.4 | AJ7: =AI7/F7 -> 0.13570068 | AK7: 649637.66 | AL7: =AK7/F7 -> 0.084294939
D8: =D7+1 -> 46114 | E8: 四 | F8: =SUM(M8,S8,U8,W8,AC8,AE8,AG8,AI8,AK8) -> 7008581 | G8: =SUM(F7:F12) -> 44423805 | I8: 437785.03 | J8: =I8/F8 -> 0.062464146 | K8: 663898.18 | L8: =K8/F8 -> 0.094726476 | M8: =SUM(I8+K8) -> 1101683.2 | N8: =M8/F8 -> 0.15719062 | O8: 125690 | P8: =O8/F8 -> 0.017933731 | Q8: 152153.58 | R8: =Q8/$F8 -> 0.021709613 | S8: =SUM(O8+Q8) -> 277843.59 | T8: =S8/F8 -> 0.039643344 | U8: 908987.52 | V8: =U8/F8 -> 0.12969637 | W8: 61165.378 | X8: =W8/F8 -> 0.0087272128 | Y8: 730280.97 | Z8: =Y8/F8 -> 0.10419812 | AA8: 966710.09 | AB8: =AA8/$F8 -> 0.13793236 | AC8: =SUM(Y8+AA8) -> 1696991.1 | AD8: =AC8/F8 -> 0.24213048 | AE8: 1223747 | AF8: =AE8/F8 -> 0.17460695 | AG8: 134891.56 | AH8: =AG8/F8 -> 0.019246629 | AI8: 1020442.3 | AJ8: =AI8/F8 -> 0.14559898 | AK8: 582829.46 | AL8: =AK8/F8 -> 0.08315941
D9: =D8+1 -> 46115 | E9: 五 | F9: =SUM(M9,S9,U9,W9,AC9,AE9,AG9,AI9,AK9) -> 6828155 | I9: 425390.98 | J9: =I9/F9 -> 0.06229955 | K9: 629847.29 | L9: =K9/F9 -> 0.092242675 | M9: =SUM(I9+K9) -> 1055238.3 | N9: =M9/F9 -> 0.15454223 | O9: 122096.7 | P9: =O9/F9 -> 0.017881361 | Q9: 135963.33 | R9: =Q9/$F9 -> 0.019912163 | S9: =SUM(O9+Q9) -> 258060.04 | T9: =S9/F9 -> 0.037793524 | U9: 803416.94 | V9: =U9/F9 -> 0.11766238 | W9: 50207.735 | X9: =W9/F9 -> 0.0073530456 | Y9: 756788.97 | Z9: =Y9/F9 -> 0.1108336 | AA9: 1086098.4 | AB9: =AA9/$F9 -> 0.15906177 | AC9: =SUM(Y9+AA9) -> 1842887.4 | AD9: =AC9/F9 -> 0.26989536 | AE9: 1018337.6 | AF9: =AE9/F9 -> 0.14913804 | AG9: 426278.27 | AH9: =AG9/F9 -> 0.062429495 | AI9: 855513.16 | AJ9: =AI9/F9 -> 0.12529199 | AK9: 518215.59 | AL9: =AK9/F9 -> 0.075893941
D10: =D9+1 -> 46116 | E10: 六 | F10: =SUM(M10,S10,U10,W10,AC10,AE10,AG10,AI10,AK10) -> 6946481 | I10: 401887.35 | J10: =I10/F10 -> 0.057854811 | K10: 626066.04 | L10: =K10/F10 -> 0.090127079 | M10: =SUM(I10+K10) -> 1027953.4 | N10: =M10/F10 -> 0.14798189 | O10: 114028.51 | P10: =O10/F10 -> 0.016415292 | Q10: 111923.95 | R10: =Q10/$F10 -> 0.016112323 | S10: =SUM(O10+Q10) -> 225952.46 | T10: =S10/F10 -> 0.032527615 | U10: 884196.27 | V10: =U10/F10 -> 0.12728693 | W10: 58359.136 | X10: =W10/F10 -> 0.0084012518 | Y10: 712258.39 | Z10: =Y10/F10 -> 0.10253514 | AA10: 1074264.6 | AB10: =AA10/$F10 -> 0.15464875 | AC10: =SUM(Y10+AA10) -> 1786523 | AD10: =AC10/F10 -> 0.25718389 | AE10: 1085694.3 | AF10: =AE10/F10 -> 0.15629414 | AG10: 430137.27 | AH10: =AG10/F10 -> 0.061921608 | AI10: 919325.8 | AJ10: =AI10/F10 -> 0.1323441 | AK10: 528339.38 | AL10: =AK10/F10 -> 0.076058565
D11: =D10+1 -> 46117 | E11: 日 | F11: =SUM(M11,S11,U11,W11,AC11,AE11,AG11,AI11,AK11) -> 7261197 | I11: 410942.65 | J11: =I11/F11 -> 0.05659434 | K11: 691236.96 | L11: =K11/F11 -> 0.095196007 | M11: =SUM(I11+K11) -> 1102179.6 | N11: =M11/F11 -> 0.15179035 | O11: 120096.85 | P11: =O11/F11 -> 0.016539539 | Q11: 129151.28 | R11: =Q11/$F11 -> 0.017786499 | S11: =SUM(O11+Q11) -> 249248.13 | T11: =S11/F11 -> 0.034326039 | U11: 907910.33 | V11: =U11/F11 -> 0.1250359 | W11: 49371.834 | X11: =W11/F11 -> 0.0067994071 | Y11: 748469.44 | Z11: =Y11/F11 -> 0.10307797 | AA11: 1182295.9 | AB11: =AA11/$F11 -> 0.16282383 | AC11: =SUM(Y11+AA11) -> 1930765.3 | AD11: =AC11/F11 -> 0.2659018 | AE11: 1197457.8 | AF11: =AE11/F11 -> 0.1649119 | AG11: 407178.53 | AH11: =AG11/F11 -> 0.056075952 | AI11: 863728.04 | AJ11: =AI11/F11 -> 0.11895119 | AK11: 553357.37 | AL11: =AK11/F11 -> 0.076207458
D12: =D11+1 -> 46118 | E12: 一 | F12: =SUM(M12,S12,U12,W12,AC12,AE12,AG12,AI12,AK12) -> 8672669 | H12: =SUM(F7:F36) -> 102477247 | I12: 509201.12 | J12: =I12/F12 -> 0.058713312 | K12: 836419.97 | L12: =K12/F12 -> 0.096443202 | M12: =SUM(I12+K12) -> 1345621.1 | N12: =M12/F12 -> 0.15515651 | O12: 138987.32 | P12: =O12/F12 -> 0.016025899 | Q12: 59320.695 | R12: =Q12/$F12 -> 0.0068399584 | S12: =SUM(O12+Q12) -> 198308.01 | T12: =S12/F12 -> 0.022865857 | U12: 1140694.3 | V12: =U12/F12 -> 0.13152748 | W12: 65023.021 | X12: =W12/F12 -> 0.0074974636 | Y12: 922650.15 | Z12: =Y12/F12 -> 0.10638595 | AA12: 1308920.9 | AB12: =AA12/$F12 -> 0.1509248 | AC12: =SUM(Y12+AA12) -> 2231571 | AD12: =AC12/F12 -> 0.25731075 | AE12: 1439540.1 | AF12: =AE12/F12 -> 0.16598582 | AG12: 407910.55 | AH12: =AG12/F12 -> 0.047034028 | AI12: 1171912.7 | AJ12: =AI12/F12 -> 0.13512711 | AK12: 672088.22 | AL12: =AK12/F12 -> 0.07749497
D13: =D12+1 -> 46119 | E13: 二 | F13: =SUM(M13,S13,U13,W13,AC13,AE13,AG13,AI13,AK13) -> 8371655 | G13: =SUM(F13:F19) -> 58053442 | I13: 506993.67 | J13: =I13/F13 -> 0.060560746 | K13: 809303.05 | L13: =K13/F13 -> 0.096671811 | M13: =SUM(I13+K13) -> 1316296.7 | N13: =M13/F13 -> 0.15723256 | O13: 275335.79 | P13: =O13/F13 -> 0.032889052 | Q13: 58798.286 | R13: =Q13/$F13 -> 0.0070234961 | S13: =SUM(O13+Q13) -> 334134.08 | T13: =S13/F13 -> 0.039912548 | U13: 1058724 | V13: =U13/F13 -> 0.12646531 | W13: 54387.797 | X13: =W13/F13 -> 0.0064966601 | Y13: 901539.76 | Z13: =Y13/F13 -> 0.10768955 | AA13: 1217251 | AB13: =AA13/$F13 -> 0.14540148 | AC13: =SUM(Y13+AA13) -> 2118790.8 | AD13: =AC13/F13 -> 0.25309103 | AE13: 1352157 | AF13: =AE13/F13 -> 0.1615161 | AG13: 372338.55 | AH13: =AG13/F13 -> 0.044476098 | AI13: 1128164.6 | AJ13: =AI13/F13 -> 0.13476004 | AK13: 636661.49 | AL13: =AK13/F13 -> 0.076049656
D14: =D13+1 -> 46120 | E14: 三 | F14: =SUM(M14,S14,U14,W14,AC14,AE14,AG14,AI14,AK14) -> 8123789 | I14: 521067.04 | J14: =I14/F14 -> 0.064140888 | K14: 794108.91 | L14: =K14/F14 -> 0.097751051 | M14: =SUM(I14+K14) -> 1315176 | N14: =M14/F14 -> 0.16189194 | O14: 178259.42 | P14: =O14/F14 -> 0.021942892 | Q14: 56536.595 | R14: =Q14/$F14 -> 0.0069593875 | S14: =SUM(O14+Q14) -> 234796.02 | T14: =S14/F14 -> 0.028902279 | U14: 1006926.2 | V14: =U14/F14 -> 0.12394785 | W14: 57641.153 | X14: =W14/F14 -> 0.0070953533 | Y14: 856392.64 | Z14: =Y14/F14 -> 0.10541788 | AA14: 1172121.8 | AB14: =AA14/$F14 -> 0.14428264 | AC14: =SUM(Y14+AA14) -> 2028514.4 | AD14: =AC14/F14 -> 0.24970053 | AE14: 1345371.7 | AF14: =AE14/F14 -> 0.16560889 | AG14: 407692.11 | AH14: =AG14/F14 -> 0.05018497 | AI14: 1102749.6 | AJ14: =AI14/F14 -> 0.13574326 | AK14: 624921.95 | AL14: =AK14/F14 -> 0.076924936
D15: =D14+1 -> 46121 | E15: 四 | F15: =SUM(M15,S15,U15,W15,AC15,AE15,AG15,AI15,AK15) -> 7630691 | I15: 508340.47 | J15: =I15/F15 -> 0.066617881 | K15: 752145.91 | L15: =K15/F15 -> 0.098568518 | M15: =SUM(I15+K15) -> 1260486.4 | N15: =M15/F15 -> 0.1651864 | O15: 178130.69 | P15: =O15/F15 -> 0.023343979 | Q15: 50806.845 | R15: =Q15/$F15 -> 0.0066582233 | S15: =SUM(O15+Q15) -> 228937.53 | T15: =S15/F15 -> 0.030002202 | U15: 982445.34 | V15: =U15/F15 -> 0.1287492 | W15: 62421.896 | X15: =W15/F15 -> 0.0081803727 | Y15: 818538.25 | Z15: =Y15/F15 -> 0.10726922 | AA15: 1059296.3 | AB15: =AA15/$F15 -> 0.13882049 | AC15: =SUM(Y15+AA15) -> 1877834.5 | AD15: =AC15/F15 -> 0.24608971 | AE15: 1276773.1 | AF15: =AE15/F15 -> 0.16732077 | AG15: 421800.87 | AH15: =AG15/F15 -> 0.05527689 | AI15: 894767.9 | AJ15: =AI15/F15 -> 0.11725909 | AK15: 625223.45 | AL15: =AK15/F15 -> 0.081935364
D16: =D15+1 -> 46122 | E16: 五 | F16: =SUM(M16,S16,U16,W16,AC16,AE16,AG16,AI16,AK16) -> 7424675 | I16: 454230.02 | J16: =I16/F16 -> 0.061178438 | K16: 733396.33 | L16: =K16/F16 -> 0.09877824 | M16: =SUM(I16+K16) -> 1187626.3 | N16: =M16/F16 -> 0.15995668 | O16: 234481.93 | P16: =O16/F16 -> 0.031581441 | Q16: 45475.983 | R16: =Q16/$F16 -> 0.0061249796 | S16: =SUM(O16+Q16) -> 279957.92 | T16: =S16/F16 -> 0.03770642 | U16: 925813.65 | V16: =U16/F16 -> 0.12469417 | W16: 48153.086 | X16: =W16/F16 -> 0.006485548 | Y16: 761966.72 | Z16: =Y16/F16 -> 0.10262627 | AA16: 1148215.3 | AB16: =AA16/$F16 -> 0.15464856 | AC16: =SUM(Y16+AA16) -> 1910182 | AD16: =AC16/F16 -> 0.25727483 | AE16: 1210919.3 | AF16: =AE16/F16 -> 0.16309391 | AG16: 372985.47 | AH16: =AG16/F16 -> 0.050235932 | AI16: 927192.71 | AJ16: =AI16/F16 -> 0.12487991 | AK16: 561844.52 | AL16: =AK16/F16 -> 0.075672607
D17: =D16+1 -> 46123 | E17: 六 | F17: =SUM(M17,S17,U17,W17,AC17,AE17,AG17,AI17,AK17) -> 7969209 | I17: 432950.88 | J17: =I17/F17 -> 0.054327962 | K17: 781773.88 | L17: =K17/F17 -> 0.098099307 | M17: =SUM(I17+K17) -> 1214724.8 | N17: =M17/F17 -> 0.15242727 | O17: 219292.52 | P17: =O17/F17 -> 0.027517476 | Q17: 39897.302 | R17: =Q17/$F17 -> 0.0050064318 | S17: =SUM(O17+Q17) -> 259189.82 | T17: =S17/F17 -> 0.032523908 | U17: 985373.24 | V17: =U17/F17 -> 0.12364756 | W17: 56704.846 | X17: =W17/F17 -> 0.0071154924 | Y17: 813386.83 | Z17: =Y17/F17 -> 0.10206619 | AA17: 1177693.8 | AB17: =AA17/$F17 -> 0.14778052 | AC17: =SUM(Y17+AA17) -> 1991080.6 | AD17: =AC17/F17 -> 0.24984671 | AE17: 1311751.9 | AF17: =AE17/F17 -> 0.16460252 | AG17: 394301.34 | AH17: =AG17/F17 -> 0.049478103 | AI17: 1162975.7 | AJ17: =AI17/F17 -> 0.14593364 | AK17: 593106.71 | AL17: =AK17/F17 -> 0.07442479
D18: =D17+1 -> 46124 | E18: 日 | F18: =SUM(M18,S18,U18,W18,AC18,AE18,AG18,AI18,AK18) -> 9249267 | I18: 541521.79 | J18: =I18/F18 -> 0.058547536 | K18: 834009.36 | L18: =K18/F18 -> 0.09017032 | M18: =SUM(I18+K18) -> 1375531.2 | N18: =M18/F18 -> 0.14871786 | O18: 314715.62 | P18: =O18/F18 -> 0.034026007 | Q18: 49580.097 | R18: =Q18/$F18 -> 0.0053604352 | S18: =SUM(O18+Q18) -> 364295.72 | T18: =S18/F18 -> 0.039386442 | U18: 1184490.6 | V18: =U18/F18 -> 0.12806319 | W18: 50043.702 | X18: =W18/F18 -> 0.0054105587 | Y18: 921054.84 | Z18: =Y18/F18 -> 0.099581387 | AA18: 1257470.3 | AB18: =AA18/$F18 -> 0.13595351 | AC18: =SUM(Y18+AA18) -> 2178525.1 | AD18: =AC18/F18 -> 0.2355349 | AE18: 1567817.2 | AF18: =AE18/F18 -> 0.16950719 | AG18: 467145 | AH18: =AG18/F18 -> 0.050506164 | AI18: 1400365.9 | AJ18: =AI18/F18 -> 0.15140291 | AK18: 661052.54 | AL18: =AK18/F18 -> 0.071470803
D19: =D18+1 -> 46125 | E19: 一 | F19: =SUM(M19,S19,U19,W19,AC19,AE19,AG19,AI19,AK19) -> 9284156 | I19: 541394.72 | J19: =I19/F19 -> 0.058313833 | K19: 1033221.8 | L19: =K19/F19 -> 0.11128872 | M19: =SUM(I19+K19) -> 1574616.5 | N19: =M19/F19 -> 0.16960255 | O19: 231549.12 | P19: =O19/F19 -> 0.024940245 | Q19: 36702.99 | R19: =Q19/$F19 -> 0.0039532931 | S19: =SUM(O19+Q19) -> 268252.11 | T19: =S19/F19 -> 0.028893538 | U19: 1153454.2 | V19: =U19/F19 -> 0.12423899 | W19: 62227.259 | X19: =W19/F19 -> 0.006702522 | Y19: 902877.52 | Z19: =Y19/F19 -> 0.097249284 | AA19: 1218015 | AB19: =AA19/$F19 -> 0.13119286 | AC19: =SUM(Y19+AA19) -> 2120892.5 | AD19: =AC19/F19 -> 0.22844214 | AE19: 1488927.9 | AF19: =AE19/F19 -> 0.160373 | AG19: 471217.23 | AH19: =AG19/F19 -> 0.050754989 | AI19: 1466160.1 | AJ19: =AI19/F19 -> 0.15792067 | AK19: 678408.12 | AL19: =AK19/F19 -> 0.073071598
D20: =D19+1 -> 46126 | E20: 二 | F20: =SUM(M20,S20,U20,W20,AC20,AE20,AG20,AI20,AK20) -> 0 | G20: =SUM(F20:F26) -> 0 | J20: =I20/F20 -> #DIV/0! | L20: =K20/F20 -> #DIV/0! | M20: =SUM(I20+K20) -> 0 | N20: =M20/F20 -> #DIV/0! | P20: =O20/F20 -> #DIV/0! | R20: =Q20/$F20 -> #DIV/0! | S20: =SUM(O20+Q20) -> 0 | T20: =S20/F20 -> #DIV/0! | V20: =U20/F20 -> #DIV/0! | X20: =W20/F20 -> #DIV/0! | Z20: =Y20/F20 -> #DIV/0! | AB20: =AA20/$F20 -> #DIV/0! | AC20: =SUM(Y20+AA20) -> 0 | AD20: =AC20/F20 -> #DIV/0! | AF20: =AE20/F20 -> #DIV/0! | AH20: =AG20/F20 -> #DIV/0! | AJ20: =AI20/F20 -> #DIV/0! | AL20: =AK20/F20 -> #DIV/0!
D21: =D20+1 -> 46127 | E21: 三 | F21: =SUM(M21,S21,U21,W21,AC21,AE21,AG21,AI21,AK21) -> 0 | J21: =I21/F21 -> #DIV/0! | L21: =K21/F21 -> #DIV/0! | M21: =SUM(I21+K21) -> 0 | N21: =M21/F21 -> #DIV/0! | P21: =O21/F21 -> #DIV/0! | R21: =Q21/$F21 -> #DIV/0! | S21: =SUM(O21+Q21) -> 0 | T21: =S21/F21 -> #DIV/0! | V21: =U21/F21 -> #DIV/0! | X21: =W21/F21 -> #DIV/0! | Z21: =Y21/F21 -> #DIV/0! | AB21: =AA21/$F21 -> #DIV/0! | AC21: =SUM(Y21+AA21) -> 0 | AD21: =AC21/F21 -> #DIV/0! | AF21: =AE21/F21 -> #DIV/0! | AH21: =AG21/F21 -> #DIV/0! | AJ21: =AI21/F21 -> #DIV/0! | AL21: =AK21/F21 -> #DIV/0!
D22: =D21+1 -> 46128 | E22: 四 | F22: =SUM(M22,S22,U22,W22,AC22,AE22,AG22,AI22,AK22) -> 0 | J22: =I22/F22 -> #DIV/0! | L22: =K22/F22 -> #DIV/0! | M22: =SUM(I22+K22) -> 0 | N22: =M22/F22 -> #DIV/0! | P22: =O22/F22 -> #DIV/0! | R22: =Q22/$F22 -> #DIV/0! | S22: =SUM(O22+Q22) -> 0 | T22: =S22/F22 -> #DIV/0! | V22: =U22/F22 -> #DIV/0! | X22: =W22/F22 -> #DIV/0! | Z22: =Y22/F22 -> #DIV/0! | AB22: =AA22/$F22 -> #DIV/0! | AC22: =SUM(Y22+AA22) -> 0 | AD22: =AC22/F22 -> #DIV/0! | AF22: =AE22/F22 -> #DIV/0! | AH22: =AG22/F22 -> #DIV/0! | AJ22: =AI22/F22 -> #DIV/0! | AL22: =AK22/F22 -> #DIV/0!
D23: =D22+1 -> 46129 | E23: 五 | F23: =SUM(M23,S23,U23,W23,AC23,AE23,AG23,AI23,AK23) -> 0 | J23: =I23/F23 -> #DIV/0! | L23: =K23/F23 -> #DIV/0! | M23: =SUM(I23+K23) -> 0 | N23: =M23/F23 -> #DIV/0! | P23: =O23/F23 -> #DIV/0! | R23: =Q23/$F23 -> #DIV/0! | S23: =SUM(O23+Q23) -> 0 | T23: =S23/F23 -> #DIV/0! | V23: =U23/F23 -> #DIV/0! | X23: =W23/F23 -> #DIV/0! | Z23: =Y23/F23 -> #DIV/0! | AB23: =AA23/$F23 -> #DIV/0! | AC23: =SUM(Y23+AA23) -> 0 | AD23: =AC23/F23 -> #DIV/0! | AF23: =AE23/F23 -> #DIV/0! | AH23: =AG23/F23 -> #DIV/0! | AJ23: =AI23/F23 -> #DIV/0! | AL23: =AK23/F23 -> #DIV/0!
D24: =D23+1 -> 46130 | E24: 六 | F24: =SUM(M24,S24,U24,W24,AC24,AE24,AG24,AI24,AK24) -> 0 | J24: =I24/F24 -> #DIV/0! | L24: =K24/F24 -> #DIV/0! | M24: =SUM(I24+K24) -> 0 | N24: =M24/F24 -> #DIV/0! | P24: =O24/F24 -> #DIV/0! | R24: =Q24/$F24 -> #DIV/0! | S24: =SUM(O24+Q24) -> 0 | T24: =S24/F24 -> #DIV/0! | V24: =U24/F24 -> #DIV/0! | X24: =W24/F24 -> #DIV/0! | Z24: =Y24/F24 -> #DIV/0! | AB24: =AA24/$F24 -> #DIV/0! | AC24: =SUM(Y24+AA24) -> 0 | AD24: =AC24/F24 -> #DIV/0! | AF24: =AE24/F24 -> #DIV/0! | AH24: =AG24/F24 -> #DIV/0! | AJ24: =AI24/F24 -> #DIV/0! | AL24: =AK24/F24 -> #DIV/0!
D25: =D24+1 -> 46131 | E25: 日 | F25: =SUM(M25,S25,U25,W25,AC25,AE25,AG25,AI25,AK25) -> 0 | J25: =I25/F25 -> #DIV/0! | L25: =K25/F25 -> #DIV/0! | M25: =SUM(I25+K25) -> 0 | N25: =M25/F25 -> #DIV/0! | P25: =O25/F25 -> #DIV/0! | R25: =Q25/$F25 -> #DIV/0! | S25: =SUM(O25+Q25) -> 0 | T25: =S25/F25 -> #DIV/0! | V25: =U25/F25 -> #DIV/0! | X25: =W25/F25 -> #DIV/0! | Z25: =Y25/F25 -> #DIV/0! | AB25: =AA25/$F25 -> #DIV/0! | AC25: =SUM(Y25+AA25) -> 0 | AD25: =AC25/F25 -> #DIV/0! | AF25: =AE25/F25 -> #DIV/0! | AH25: =AG25/F25 -> #DIV/0! | AJ25: =AI25/F25 -> #DIV/0! | AL25: =AK25/F25 -> #DIV/0!
D26: =D25+1 -> 46132 | E26: 一 | F26: =SUM(M26,S26,U26,W26,AC26,AE26,AG26,AI26,AK26) -> 0 | J26: =I26/F26 -> #DIV/0! | L26: =K26/F26 -> #DIV/0! | M26: =SUM(I26+K26) -> 0 | N26: =M26/F26 -> #DIV/0! | P26: =O26/F26 -> #DIV/0! | R26: =Q26/$F26 -> #DIV/0! | S26: =SUM(O26+Q26) -> 0 | T26: =S26/F26 -> #DIV/0! | V26: =U26/F26 -> #DIV/0! | X26: =W26/F26 -> #DIV/0! | Z26: =Y26/F26 -> #DIV/0! | AB26: =AA26/$F26 -> #DIV/0! | AC26: =SUM(Y26+AA26) -> 0 | AD26: =AC26/F26 -> #DIV/0! | AF26: =AE26/F26 -> #DIV/0! | AH26: =AG26/F26 -> #DIV/0! | AJ26: =AI26/F26 -> #DIV/0! | AL26: =AK26/F26 -> #DIV/0!
D27: =D26+1 -> 46133 | E27: 二 | F27: =SUM(M27,S27,U27,W27,AC27,AE27,AG27,AI27,AK27) -> 0 | G27: =SUM(F27:F33) -> 0 | J27: =I27/F27 -> #DIV/0! | L27: =K27/F27 -> #DIV/0! | M27: =SUM(I27+K27) -> 0 | N27: =M27/F27 -> #DIV/0! | P27: =O27/F27 -> #DIV/0! | R27: =Q27/$F27 -> #DIV/0! | S27: =SUM(O27+Q27) -> 0 | T27: =S27/F27 -> #DIV/0! | V27: =U27/F27 -> #DIV/0! | X27: =W27/F27 -> #DIV/0! | Z27: =Y27/F27 -> #DIV/0! | AB27: =AA27/$F27 -> #DIV/0! | AC27: =SUM(Y27+AA27) -> 0 | AD27: =AC27/F27 -> #DIV/0! | AF27: =AE27/F27 -> #DIV/0! | AH27: =AG27/F27 -> #DIV/0! | AJ27: =AI27/F27 -> #DIV/0! | AL27: =AK27/F27 -> #DIV/0!
D28: =D27+1 -> 46134 | E28: 三 | F28: =SUM(M28,S28,U28,W28,AC28,AE28,AG28,AI28,AK28) -> 0 | J28: =I28/F28 -> #DIV/0! | L28: =K28/F28 -> #DIV/0! | M28: =SUM(I28+K28) -> 0 | N28: =M28/F28 -> #DIV/0! | P28: =O28/F28 -> #DIV/0! | R28: =Q28/$F28 -> #DIV/0! | S28: =SUM(O28+Q28) -> 0 | T28: =S28/F28 -> #DIV/0! | V28: =U28/F28 -> #DIV/0! | X28: =W28/F28 -> #DIV/0! | Z28: =Y28/F28 -> #DIV/0! | AB28: =AA28/$F28 -> #DIV/0! | AC28: =SUM(Y28+AA28) -> 0 | AD28: =AC28/F28 -> #DIV/0! | AF28: =AE28/F28 -> #DIV/0! | AH28: =AG28/F28 -> #DIV/0! | AJ28: =AI28/F28 -> #DIV/0! | AL28: =AK28/F28 -> #DIV/0!
D29: =D28+1 -> 46135 | E29: 四 | F29: =SUM(M29,S29,U29,W29,AC29,AE29,AG29,AI29,AK29) -> 0 | J29: =I29/F29 -> #DIV/0! | L29: =K29/F29 -> #DIV/0! | M29: =SUM(I29+K29) -> 0 | N29: =M29/F29 -> #DIV/0! | P29: =O29/F29 -> #DIV/0! | R29: =Q29/$F29 -> #DIV/0! | S29: =SUM(O29+Q29) -> 0 | T29: =S29/F29 -> #DIV/0! | V29: =U29/F29 -> #DIV/0! | X29: =W29/F29 -> #DIV/0! | Z29: =Y29/F29 -> #DIV/0! | AB29: =AA29/$F29 -> #DIV/0! | AC29: =SUM(Y29+AA29) -> 0 | AD29: =AC29/F29 -> #DIV/0! | AF29: =AE29/F29 -> #DIV/0! | AH29: =AG29/F29 -> #DIV/0! | AJ29: =AI29/F29 -> #DIV/0! | AL29: =AK29/F29 -> #DIV/0!
D30: =D29+1 -> 46136 | E30: 五 | F30: =SUM(M30,S30,U30,W30,AC30,AE30,AG30,AI30,AK30) -> 0 | J30: =I30/F30 -> #DIV/0! | L30: =K30/F30 -> #DIV/0! | M30: =SUM(I30+K30) -> 0 | N30: =M30/F30 -> #DIV/0! | P30: =O30/F30 -> #DIV/0! | R30: =Q30/$F30 -> #DIV/0! | S30: =SUM(O30+Q30) -> 0 | T30: =S30/F30 -> #DIV/0! | V30: =U30/F30 -> #DIV/0! | X30: =W30/F30 -> #DIV/0! | Z30: =Y30/F30 -> #DIV/0! | AB30: =AA30/$F30 -> #DIV/0! | AC30: =SUM(Y30+AA30) -> 0 | AD30: =AC30/F30 -> #DIV/0! | AF30: =AE30/F30 -> #DIV/0! | AH30: =AG30/F30 -> #DIV/0! | AJ30: =AI30/F30 -> #DIV/0! | AL30: =AK30/F30 -> #DIV/0!
D31: =D30+1 -> 46137 | E31: 六 | F31: =SUM(M31,S31,U31,W31,AC31,AE31,AG31,AI31,AK31) -> 0 | J31: =I31/F31 -> #DIV/0! | L31: =K31/F31 -> #DIV/0! | M31: =SUM(I31+K31) -> 0 | N31: =M31/F31 -> #DIV/0! | P31: =O31/F31 -> #DIV/0! | R31: =Q31/$F31 -> #DIV/0! | S31: =SUM(O31+Q31) -> 0 | T31: =S31/F31 -> #DIV/0! | V31: =U31/F31 -> #DIV/0! | X31: =W31/F31 -> #DIV/0! | Z31: =Y31/F31 -> #DIV/0! | AB31: =AA31/$F31 -> #DIV/0! | AC31: =SUM(Y31+AA31) -> 0 | AD31: =AC31/F31 -> #DIV/0! | AF31: =AE31/F31 -> #DIV/0! | AH31: =AG31/F31 -> #DIV/0! | AJ31: =AI31/F31 -> #DIV/0! | AL31: =AK31/F31 -> #DIV/0!
D32: =D31+1 -> 46138 | E32: 日 | F32: =SUM(M32,S32,U32,W32,AC32,AE32,AG32,AI32,AK32) -> 0 | J32: =I32/F32 -> #DIV/0! | L32: =K32/F32 -> #DIV/0! | M32: =SUM(I32+K32) -> 0 | N32: =M32/F32 -> #DIV/0! | P32: =O32/F32 -> #DIV/0! | R32: =Q32/$F32 -> #DIV/0! | S32: =SUM(O32+Q32) -> 0 | T32: =S32/F32 -> #DIV/0! | V32: =U32/F32 -> #DIV/0! | X32: =W32/F32 -> #DIV/0! | Z32: =Y32/F32 -> #DIV/0! | AB32: =AA32/$F32 -> #DIV/0! | AC32: =SUM(Y32+AA32) -> 0 | AD32: =AC32/F32 -> #DIV/0! | AF32: =AE32/F32 -> #DIV/0! | AH32: =AG32/F32 -> #DIV/0! | AJ32: =AI32/F32 -> #DIV/0! | AL32: =AK32/F32 -> #DIV/0!
D33: =D32+1 -> 46139 | E33: 一 | F33: =SUM(M33,S33,U33,W33,AC33,AE33,AG33,AI33,AK33) -> 0 | J33: =I33/F33 -> #DIV/0! | L33: =K33/F33 -> #DIV/0! | M33: =SUM(I33+K33) -> 0 | N33: =M33/F33 -> #DIV/0! | P33: =O33/F33 -> #DIV/0! | R33: =Q33/$F33 -> #DIV/0! | S33: =SUM(O33+Q33) -> 0 | T33: =S33/F33 -> #DIV/0! | V33: =U33/F33 -> #DIV/0! | X33: =W33/F33 -> #DIV/0! | Z33: =Y33/F33 -> #DIV/0! | AB33: =AA33/$F33 -> #DIV/0! | AC33: =SUM(Y33+AA33) -> 0 | AD33: =AC33/F33 -> #DIV/0! | AF33: =AE33/F33 -> #DIV/0! | AH33: =AG33/F33 -> #DIV/0! | AJ33: =AI33/F33 -> #DIV/0! | AL33: =AK33/F33 -> #DIV/0!
D34: =D33+1 -> 46140 | E34: 二 | F34: =SUM(M34,S34,U34,W34,AC34,AE34,AG34,AI34,AK34) -> 0 | G34: =SUM(F34:F40) -> 0 | J34: =I34/F34 -> #DIV/0! | L34: =K34/F34 -> #DIV/0! | M34: =SUM(I34+K34) -> 0 | N34: =M34/F34 -> #DIV/0! | P34: =O34/F34 -> #DIV/0! | R34: =Q34/$F34 -> #DIV/0! | S34: =SUM(O34+Q34) -> 0 | T34: =S34/F34 -> #DIV/0! | V34: =U34/F34 -> #DIV/0! | X34: =W34/F34 -> #DIV/0! | Z34: =Y34/F34 -> #DIV/0! | AB34: =AA34/$F34 -> #DIV/0! | AC34: =SUM(Y34+AA34) -> 0 | AD34: =AC34/F34 -> #DIV/0! | AF34: =AE34/F34 -> #DIV/0! | AH34: =AG34/F34 -> #DIV/0! | AJ34: =AI34/F34 -> #DIV/0! | AL34: =AK34/F34 -> #DIV/0!
D35: =D34+1 -> 46141 | E35: 三 | F35: =SUM(M35,S35,U35,W35,AC35,AE35,AG35,AI35,AK35) -> 0 | J35: =I35/F35 -> #DIV/0! | L35: =K35/F35 -> #DIV/0! | M35: =SUM(I35+K35) -> 0 | N35: =M35/F35 -> #DIV/0! | P35: =O35/F35 -> #DIV/0! | R35: =Q35/$F35 -> #DIV/0! | S35: =SUM(O35+Q35) -> 0 | T35: =S35/F35 -> #DIV/0! | V35: =U35/F35 -> #DIV/0! | X35: =W35/F35 -> #DIV/0! | Z35: =Y35/F35 -> #DIV/0! | AB35: =AA35/$F35 -> #DIV/0! | AC35: =SUM(Y35+AA35) -> 0 | AD35: =AC35/F35 -> #DIV/0! | AF35: =AE35/F35 -> #DIV/0! | AH35: =AG35/F35 -> #DIV/0! | AJ35: =AI35/F35 -> #DIV/0! | AL35: =AK35/F35 -> #DIV/0!
D36: =D35+1 -> 46142 | E36: 四 | F36: =SUM(M36,S36,U36,W36,AC36,AE36,AG36,AI36,AK36) -> 0 | J36: =I36/F36 -> #DIV/0! | L36: =K36/F36 -> #DIV/0! | M36: =SUM(I36+K36) -> 0 | N36: =M36/F36 -> #DIV/0! | P36: =O36/F36 -> #DIV/0! | R36: =Q36/$F36 -> #DIV/0! | S36: =SUM(O36+Q36) -> 0 | T36: =S36/F36 -> #DIV/0! | V36: =U36/F36 -> #DIV/0! | X36: =W36/F36 -> #DIV/0! | Z36: =Y36/F36 -> #DIV/0! | AB36: =AA36/$F36 -> #DIV/0! | AC36: =SUM(Y36+AA36) -> 0 | AD36: =AC36/F36 -> #DIV/0! | AF36: =AE36/F36 -> #DIV/0! | AH36: =AG36/F36 -> #DIV/0! | AJ36: =AI36/F36 -> #DIV/0! | AL36: =AK36/F36 -> #DIV/0!
D37: =D36+1 -> 46143 | E37: 五 | F37: =SUM(M37,S37,U37,W37,AC37,AE37,AG37,AI37,AK37) -> 0 | J37: =I37/F37 -> #DIV/0! | L37: =K37/F37 -> #DIV/0! | M37: =SUM(I37+K37) -> 0 | N37: =M37/F37 -> #DIV/0! | P37: =O37/F37 -> #DIV/0! | R37: =Q37/$F37 -> #DIV/0! | S37: =SUM(O37+Q37) -> 0 | T37: =S37/F37 -> #DIV/0! | V37: =U37/F37 -> #DIV/0! | X37: =W37/F37 -> #DIV/0! | Z37: =Y37/F37 -> #DIV/0! | AB37: =AA37/$F37 -> #DIV/0! | AC37: =SUM(Y37+AA37) -> 0 | AD37: =AC37/F37 -> #DIV/0! | AF37: =AE37/F37 -> #DIV/0! | AH37: =AG37/F37 -> #DIV/0! | AJ37: =AI37/F37 -> #DIV/0! | AL37: =AK37/F37 -> #DIV/0!
D38: =D37+1 -> 46144 | E38: 六 | F38: =SUM(M38,S38,U38,W38,AC38,AE38,AG38,AI38,AK38) -> 0 | J38: =I38/F38 -> #DIV/0! | L38: =K38/F38 -> #DIV/0! | M38: =SUM(I38+K38) -> 0 | N38: =M38/F38 -> #DIV/0! | P38: =O38/F38 -> #DIV/0! | R38: =Q38/$F38 -> #DIV/0! | S38: =SUM(O38+Q38) -> 0 | T38: =S38/F38 -> #DIV/0! | V38: =U38/F38 -> #DIV/0! | X38: =W38/F38 -> #DIV/0! | Z38: =Y38/F38 -> #DIV/0! | AB38: =AA38/$F38 -> #DIV/0! | AC38: =SUM(Y38+AA38) -> 0 | AD38: =AC38/F38 -> #DIV/0! | AF38: =AE38/F38 -> #DIV/0! | AH38: =AG38/F38 -> #DIV/0! | AJ38: =AI38/F38 -> #DIV/0! | AL38: =AK38/F38 -> #DIV/0!
D39: =D38+1 -> 46145 | E39: 日 | F39: =SUM(M39,S39,U39,W39,AC39,AE39,AG39,AI39,AK39) -> 0 | J39: =I39/F39 -> #DIV/0! | L39: =K39/F39 -> #DIV/0! | M39: =SUM(I39+K39) -> 0 | N39: =M39/F39 -> #DIV/0! | P39: =O39/F39 -> #DIV/0! | R39: =Q39/$F39 -> #DIV/0! | S39: =SUM(O39+Q39) -> 0 | T39: =S39/F39 -> #DIV/0! | V39: =U39/F39 -> #DIV/0! | X39: =W39/F39 -> #DIV/0! | Z39: =Y39/F39 -> #DIV/0! | AB39: =AA39/$F39 -> #DIV/0! | AC39: =SUM(Y39+AA39) -> 0 | AD39: =AC39/F39 -> #DIV/0! | AF39: =AE39/F39 -> #DIV/0! | AH39: =AG39/F39 -> #DIV/0! | AJ39: =AI39/F39 -> #DIV/0! | AL39: =AK39/F39 -> #DIV/0!
D40: =D39+1 -> 46146 | E40: 一 | F40: =SUM(M40,S40,U40,W40,AC40,AE40,AG40,AI40,AK40) -> 0 | J40: =I40/F40 -> #DIV/0! | L40: =K40/F40 -> #DIV/0! | M40: =SUM(I40+K40) -> 0 | N40: =M40/F40 -> #DIV/0! | P40: =O40/F40 -> #DIV/0! | R40: =Q40/$F40 -> #DIV/0! | S40: =SUM(O40+Q40) -> 0 | T40: =S40/F40 -> #DIV/0! | V40: =U40/F40 -> #DIV/0! | X40: =W40/F40 -> #DIV/0! | Z40: =Y40/F40 -> #DIV/0! | AB40: =AA40/$F40 -> #DIV/0! | AC40: =SUM(Y40+AA40) -> 0 | AD40: =AC40/F40 -> #DIV/0! | AF40: =AE40/F40 -> #DIV/0! | AH40: =AG40/F40 -> #DIV/0! | AJ40: =AI40/F40 -> #DIV/0! | AL40: =AK40/F40 -> #DIV/0!
F41: =SUM(M41,S41,U41,W41,AC41,AE41,AG41,AI41,AK41) -> 0 | J41: =I41/F41 -> #DIV/0! | L41: =K41/F41 -> #DIV/0! | M41: =SUM(I41+K41) -> 0 | N41: =M41/F41 -> #DIV/0! | P41: =O41/F41 -> #DIV/0! | R41: =Q41/$F41 -> #DIV/0! | S41: =SUM(O41+Q41) -> 0 | T41: =S41/F41 -> #DIV/0! | V41: =U41/F41 -> #DIV/0! | X41: =W41/F41 -> #DIV/0! | Z41: =Y41/F41 -> #DIV/0! | AB41: =AA41/$F41 -> #DIV/0! | AC41: =SUM(Y41+AA41) -> 0 | AD41: =AC41/F41 -> #DIV/0! | AF41: =AE41/F41 -> #DIV/0! | AH41: =AG41/F41 -> #DIV/0! | AJ41: =AI41/F41 -> #DIV/0! | AL41: =AK41/F41 -> #DIV/0!
...

Sheet （４）訂單數量構成比
B2: （4）訂單數量構成比
C3: 月份 | D3: 日期 | F3: 訂單量 | I3: 品類訂單量
I4: 18℃-飯糰 | O4: 18℃-壽司手卷 | U4: 4℃-飯糰 | W4: 4℃-壽司手卷 | Y4: 主食 | AE4: 便當 | AG4: 熱食義麵 | AI4: 季節調理麵 | AK4: 微波小吃
F5: 日 | G5: 週累積 | H5: 月累積 | I5: 一配 | K5: 二配 | M5: 合計 | O5: 一配 | Q5: 二配 | S5: 合計 | U5: 一配 | W5: 一配 | Y5: 一配 | AA5: 二配 | AC5: 合計 | AE5: 一配 | AG5: 一配 | AI5: 一配 | AK5: 一配
I6: 訂單數 | J6: 比例(%) | K6: 訂單數 | L6: 比例(%) | M6: 訂單數 | N6: 比例(%) | O6: 訂單數 | P6: 比例(%) | Q6: 訂單數 | R6: 比例(%) | S6: 訂單數 | T6: 比例(%) | U6: 訂單數 | V6: 比例(%) | W6: 訂單數 | X6: 比例(%) | Y6: 訂單數 | Z6: 比例(%) | AA6: 訂單數 | AB6: 比例(%) | AC6: 訂單數 | AD6: 比例(%) | AE6: 訂單數 | AF6: 比例(%) | AG6: 訂單數 | AH6: 比例(%) | AI6: 訂單數 | AJ6: 比例(%) | AK6: 訂單數 | AL6: 比例(%)
D7: 46113 | E7: 三 | F7: =SUM(M7,S7,U7,W7,AC7,AE7,AG7,AI7,AK7) -> 240873 | I7: 27460 | J7: =I7/F7 -> 0.11400198 | K7: 38156 | L7: =K7/F7 -> 0.15840713 | M7: =SUM(I7+K7) -> 65616 | N7: =M7/F7 -> 0.27240911 | O7: 6597 | P7: =O7/F7 -> 0.027387877 | Q7: 7172 | R7: =Q7/F7 -> 0.029775027 | S7: =SUM(O7+Q7) -> 13769 | T7: =S7/F7 -> 0.057162903 | U7: 29598 | V7: =U7/F7 -> 0.12287803 | W7: 1833 | X7: =W7/F7 -> 0.0076098193 | Y7: 27449 | Z7: =Y7/F7 -> 0.11395632 | AA7: 20133 | AB7: =AA7/F7 -> 0.083583465 | AC7: =SUM(Y7+AA7) -> 47582 | AD7: =AC7/F7 -> 0.19753978 | AE7: 23653 | AF7: =AE7/F7 -> 0.098196975 | AG7: 4262 | AH7: =AG7/F7 -> 0.017693972 | AI7: 28294 | AJ7: =AI7/F7 -> 0.11746439 | AK7: 26266 | AL7: =AK7/F7 -> 0.10904502
D8: =D7+1 -> 46114 | E8: 四 | F8: =SUM(M8,S8,U8,W8,AC8,AE8,AG8,AI8,AK8) -> 219733 | G8: =SUM(F7:F12) -> 1352026 | I8: 23616 | J8: =I8/F8 -> 0.10747589 | K8: 35584 | L8: =K8/F8 -> 0.16194199 | M8: =SUM(I8+K8) -> 59200 | N8: =M8/F8 -> 0.26941788 | O8: 5301 | P8: =O8/F8 -> 0.024124733 | Q8: 6378 | R8: =Q8/F8 -> 0.029026136 | S8: =SUM(O8+Q8) -> 11679 | T8: =S8/F8 -> 0.053150869 | U8: 27498 | V8: =U8/F8 -> 0.12514279 | W8: 1787 | X8: =W8/F8 -> 0.0081325973 | Y8: 25089 | Z8: =Y8/F8 -> 0.11417948 | AA8: 18412 | AB8: =AA8/F8 -> 0.083792603 | AC8: =SUM(Y8+AA8) -> 43501 | AD8: =AC8/F8 -> 0.19797208 | AE8: 21227 | AF8: =AE8/F8 -> 0.096603605 | AG8: 3324 | AH8: =AG8/F8 -> 0.01512745 | AI8: 27623 | AJ8: =AI8/F8 -> 0.12571166 | AK8: 23894 | AL8: =AK8/F8 -> 0.10874106
D9: =D8+1 -> 46115 | E9: 五 | F9: =SUM(M9,S9,U9,W9,AC9,AE9,AG9,AI9,AK9) -> 208291 | I9: 22988 | J9: =I9/F9 -> 0.11036483 | K9: 33784 | L9: =K9/F9 -> 0.16219616 | M9: =SUM(I9+K9) -> 56772 | N9: =M9/F9 -> 0.27256098 | O9: 5121 | P9: =O9/F9 -> 0.024585796 | Q9: 5531 | R9: =Q9/F9 -> 0.026554196 | S9: =SUM(O9+Q9) -> 10652 | T9: =S9/F9 -> 0.051139992 | U9: 24463 | V9: =U9/F9 -> 0.11744627 | W9: 1480 | X9: =W9/F9 -> 0.0071054438 | Y9: 25119 | Z9: =Y9/F9 -> 0.12059571 | AA9: 20726 | AB9: =AA9/F9 -> 0.099505019 | AC9: =SUM(Y9+AA9) -> 45845 | AD9: =AC9/F9 -> 0.22010072 | AE9: 17761 | AF9: =AE9/F9 -> 0.085270127 | AG9: 9153 | AH9: =AG9/F9 -> 0.043943329 | AI9: 23207 | AJ9: =AI9/F9 -> 0.11141624 | AK9: 18958 | AL9: =AK9/F9 -> 0.091016895
D10: =D9+1 -> 46116 | E10: 六 | F10: =SUM(M10,S10,U10,W10,AC10,AE10,AG10,AI10,AK10) -> 206015 | I10: 21763 | J10: =I10/F10 -> 0.10563794 | K10: 33619 | L10: =K10/F10 -> 0.16318715 | M10: =SUM(I10+K10) -> 55382 | N10: =M10/F10 -> 0.26882509 | O10: 4728 | P10: =O10/F10 -> 0.022949785 | Q10: 4419 | R10: =Q10/F10 -> 0.021449894 | S10: =SUM(O10+Q10) -> 9147 | T10: =S10/F10 -> 0.04439968 | U10: 26817 | V10: =U10/F10 -> 0.13017013 | W10: 1708 | X10: =W10/F10 -> 0.0082906584 | Y10: 20756 | Z10: =Y10/F10 -> 0.10074995 | AA10: 20544 | AB10: =AA10/F10 -> 0.099720894 | AC10: =SUM(Y10+AA10) -> 41300 | AD10: =AC10/F10 -> 0.20047084 | AE10: 19003 | AF10: =AE10/F10 -> 0.092240856 | AG10: 9325 | AH10: =AG10/F10 -> 0.045263694 | AI10: 24907 | AJ10: =AI10/F10 -> 0.12089896 | AK10: 18426 | AL10: =AK10/F10 -> 0.089440089
D11: =D10+1 -> 46117 | E11: 日 | F11: =SUM(M11,S11,U11,W11,AC11,AE11,AG11,AI11,AK11) -> 218068 | I11: 22161 | J11: =I11/F11 -> 0.10162426 | K11: 37099 | L11: =K11/F11 -> 0.17012583 | M11: =SUM(I11+K11) -> 59260 | N11: =M11/F11 -> 0.2717501 | O11: 5045 | P11: =O11/F11 -> 0.023134985 | Q11: 5098 | R11: =Q11/F11 -> 0.023378029 | S11: =SUM(O11+Q11) -> 10143 | T11: =S11/F11 -> 0.046513014 | U11: 27397 | V11: =U11/F11 -> 0.12563512 | W11: 1448 | X11: =W11/F11 -> 0.0066401306 | Y11: 23545 | Z11: =Y11/F11 -> 0.10797091 | AA11: 22582 | AB11: =AA11/F11 -> 0.10355485 | AC11: =SUM(Y11+AA11) -> 46127 | AD11: =AC11/F11 -> 0.21152576 | AE11: 20817 | AF11: =AE11/F11 -> 0.095461049 | AG11: 8797 | AH11: =AG11/F11 -> 0.040340628 | AI11: 23399 | AJ11: =AI11/F11 -> 0.10730139 | AK11: 20680 | AL11: =AK11/F11 -> 0.094832804
D12: =D11+1 -> 46118 | E12: 一 | F12: =SUM(M12,S12,U12,W12,AC12,AE12,AG12,AI12,AK12) -> 259046 | H12: =SUM(F7:F36) -> 3104723 | I12: 27562 | J12: =I12/F12 -> 0.10639809 | K12: 44049 | L12: =K12/F12 -> 0.17004316 | M12: =SUM(I12+K12) -> 71611 | N12: =M12/F12 -> 0.27644125 | O12: 5906 | P12: =O12/F12 -> 0.02279904 | Q12: 2769 | R12: =Q12/F12 -> 0.010689221 | S12: =SUM(O12+Q12) -> 8675 | T12: =S12/F12 -> 0.033488261 | U12: 34445 | V12: =U12/F12 -> 0.13296866 | W12: 1903 | X12: =W12/F12 -> 0.0073461856 | Y12: 27831 | Z12: =Y12/F12 -> 0.10743652 | AA12: 25025 | AB12: =AA12/F12 -> 0.096604464 | AC12: =SUM(Y12+AA12) -> 52856 | AD12: =AC12/F12 -> 0.20404098 | AE12: 25680 | AF12: =AE12/F12 -> 0.099132973 | AG12: 9097 | AH12: =AG12/F12 -> 0.035117315 | AI12: 31733 | AJ12: =AI12/F12 -> 0.12249948 | AK12: 23046 | AL12: =AK12/F12 -> 0.088964894
