Workbook

Sheet 填寫舉例
A2: 7 | B2: 月別 | C2: 工廠名 | D2: ・・・・・・・・
A4: （１）收支狀況 | E4: ※單位：千元 | G4: （２）ＫＰＩ達成進度 | M4: （３）業績構成比 | S4: （４）訂單數量構成比
B5: 當月 | C5: 前月 | D5: 差異 | E5: 累計 | H5: KPI | I5: 當月 | J5: 前月 | K5: 累計 | L5: ※補充 | N5: 當月 | O5: 比例 | P5: 前月 | Q5: 差異 | T5: 當月 | U5: 比例 | V5: 前月 | W5: 差異
A6: 業績金額 | B6: 500000 | C6: 510000 | D6: =B6-C6 -> -10000 | E6: =B6+C6 -> 1010000 | G6: 人時生產性1 | H6: 110 | I6: 100 | J6: 90 | L6: 個／MH | M6: 飯糰 | N6: 150000 | O6: =IFERROR(N6/$B$6,"") -> 0.3 | P6: 0.4 | Q6: =IFERROR(O6-P6,"") -> -0.1 | S6: 飯糰 | T6: 35000 | U6: =IFERROR(T6/$B$7,"") -> 0.35 | V6: 0.3 | W6: =IFERROR(U6-V6,"") -> 0.05
A7: 訂單數量 | B7: 100000 | C7: 110000 | D7: =B7-C7 -> -10000 | E7: =B7+C7 -> 210000 | G7: 人時生產性2 | H7: 0.8 | I7: 0.85 | J7: 0.81 | K7: 0.84 | L7: 達成率 | M7: 大口飯糰 | N7: 100000 | O7: =IFERROR(N7/$B$6,"") -> 0.2 | P7: 0.15 | Q7: =IFERROR(O7-P7,"") -> 0.05 | S7: 大口飯糰 | T7: 30000 | U7: =IFERROR(T7/$B$7,"") -> 0.3 | V7: 0.15 | W7: =IFERROR(U7-V7,"") -> 0.15
A8: 材料費 | B8: 250000 | C8: 260000 | D8: =B8-C8 -> -10000 | E8: =B8+C8 -> 510000 | G8: 半成品報廢 | H8: 0.0025 | I8: 0.0024 | J8: 0.0023 | K8: 0.00235 | L8: 報廢率 | M8: 便當 | N8: 160000 | O8: =IFERROR(N8/$B$6,"") -> 0.32 | P8: 0.28 | Q8: =IFERROR(O8-P8,"") -> 0.04 | S8: 便當 | T8: 20000 | U8: =IFERROR(T8/$B$7,"") -> 0.2 | V8: 0.28 | W8: =IFERROR(U8-V8,"") -> -0.08
A9: 材料費率 | B9: =B8/B6 -> 0.5 | C9: =C8/C6 -> 0.50980392 | D9: =B9-C9 -> -0.0098039216 | E9: =(B9+C9)/2 -> 0.50490196 | G9: 半成品超用 | H9: 0.006 | I9: 0.009 | J9: 0.0095 | K9: 0.0092 | L9: 超用率 | M9: 調理麵 | N9: 90000 | O9: =IFERROR(N9/$B$6,"") -> 0.18 | P9: 0.17 | Q9: =IFERROR(O9-P9,"") -> 0.01 | S9: 調理麵 | T9: 15000 | U9: =IFERROR(T9/$B$7,"") -> 0.15 | V9: 0.27 | W9: =IFERROR(U9-V9,"") -> -0.12
A10: 勞務成本 | B10: 100000 | C10: 105000 | D10: =B10-C10 -> -5000 | E10: =B10+C10 -> 205000 | G10: 固定產線 | H10: 0.95 | I10: 0.9 | J10: 0.92 | K10: 0.91 | L10: 導入率 | M10: 調理麵包 | N10: - | O10: =IFERROR(N10/$B$6,"") | P10: -% | Q10: =IFERROR(O10-P10,"") | S10: 調理麵包 | T10: - | U10: =IFERROR(T10/$B$7,"") | V10: -% | W10: =IFERROR(U10-V10,"")
A11: 勞務費率 | B11: =B10/B6 -> 0.2 | C11: =C10/C6 -> 0.20588235 | D11: =B11-C11 -> -0.0058823529 | E11: =(B11+C11)/2 -> 0.20294118 | G11: 教育訓練 | H11: 0.8 | I11: 0.85 | J11: 1 | K11: 0.92 | L11: 實施率 | M11: 袋裝調理麵包 | N11: - | O11: =IFERROR(N11/$B$6,"") | P11: -% | Q11: =IFERROR(O11-P11,"") | S11: 袋裝調理麵包 | T11: - | U11: =IFERROR(T11/$B$7,"") | V11: -% | W11: =IFERROR(U11-V11,"")
M12: 義大利麵 | N12: - | O12: =IFERROR(N12/$B$6,"") | P12: -% | Q12: =IFERROR(O12-P12,"") | S12: 義大利麵 | T12: - | U12: =IFERROR(T12/$B$7,"") | V12: -% | W12: =IFERROR(U12-V12,"")
A13: （５）品群別人時生產性 | M13: 調理包 | N13: - | O13: =IFERROR(N13/$B$6,"") | P13: -% | Q13: =IFERROR(O13-P13,"") | S13: 調理包 | T13: - | U13: =IFERROR(T13/$B$7,"") | V13: -% | W13: =IFERROR(U13-V13,"")
B14: 當月 | C14: 前月 | D14: 差異 | E14: 累計 | H14: 當月 | I14: 前月 | J14: 差異 | K14: 累計 | O14: =SUM(O6:O13) -> 1 | P14: =SUM(P6:P13) -> 1 | U14: =SUM(U6:U13) -> 1 | V14: =SUM(V6:V13) -> 1
A15: 飯糰 | B15: 600 | C15: 660 | D15: =B15-C15 -> -60 | E15: =(B15+C15)/2 -> 630 | G15: 調理麵包 | J15: =H15-I15 -> 0 | M15: （７）原因別分析
A16: 大口飯糰 | B16: 800 | C16: 780 | D16: =B16-C16 -> 20 | E16: =(B16+C16)/2 -> 790 | G16: 袋裝調理麵包 | J16: =H16-I16 -> 0 | N16: 合計 | P16: 作業原因 | R16: 規格原因
A17: 便當 | B17: 130 | C17: 111 | D17: =B17-C17 -> 19 | E17: =(B17+C17)/2 -> 120.5 | G17: 義大利麵 | J17: =H17-I17 -> 0 | N17: 金額 | O17: 比例 | P17: 金額 | Q17: 比例 | R17: 金額 | S17: 比例
A18: 調理麵 | B18: 140 | C18: 165 | D18: =B18-C18 -> -25 | E18: =(B18+C18)/2 -> 152.5 | G18: 調理包 | J18: =H18-I18 -> 0 | M18: 半成品報廢 | N18: 1200 | O18: =N18/$B$6 -> 0.0024 | P18: 900 | Q18: =IFERROR(P18/$B$6,"") -> 0.0018 | R18: 300 | S18: =IFERROR(R18/$B$6,"") -> 0.0006
M19: 半成品超用 | N19: 4500 | O19: =N19/$B$6 -> 0.009 | P19: 3500 | Q19: =IFERROR(P19/$B$6,"") -> 0.007 | R19: 1000 | S19: =IFERROR(R19/$B$6,"") -> 0.002
A20: （６）人時生產性前幾名品項
B21: 排名 | C21: 商品名 | F21: 人數 | G21: 產能 | H21: 人時生產性 | I21: 前月比 | J21: 主要原因&對策 | M21: （８）報廢原因別前幾名品項
A22: 飯糰 | B22: 1 | C22: 手巻明太子 | F22: 3 | G22: 3000 | H22: 1000 | I22: 10 | J22: 減少暫時停止生產,人時UP | M22: 半成品報廢 | N22: 排名 | O22: 商品名 | R22: 半成品名 | U22: 單價 | V22: 報廢率 | W22: 數量 | X22: 金額 | Y22: 前月比 | Z22: 主要原因&對策
B23: 2 | M23: 作業原因 | N23: 1 | O23: 明太子海苔便當 | R23: 油炸白身魚 | U23: 10 | V23: 0.15 | W23: 10 | X23: =W23*U23 -> 100 | Y23: 80 | Z23: 油調過多報廢。變更條件。
B24: 3 | N24: 2 | X24: =W24*U24 -> 0
B25: 4 | N25: 3 | X25: =W25*U25 -> 0
B26: 5 | N26: 4 | X26: =W26*U26 -> 0
B27: ▼1 | C27: 手巻卵黄雞絞肉 | F27: 4 | G27: 2800 | H27: 700 | I27: 6/30新商品 | J27: 因組裝2食材,人員增加,產速減少 | N27: 5 | X27: =W27*U27 -> 0
B28: ▼2 | U28: 前幾名合計比例 | V28: =X28/N18 -> 0.083333333 | W28: 前幾名合計金額 | X28: =SUM(X23:X27) -> 100
B29: ▼3 | M29: 規格原因 | N29: 1 | O29: 海老炒飯 | R29: 川燙蝦子拌醬 | U29: 5.55 | V29: 0.21 | W29: 50 | X29: =W29*U29 -> 277.5 | Y29: 35 | Z29: 蝦子入數不足
B30: ▼4 | N30: 2 | X30: =W30*U30 -> 0
B31: ▼5 | N31: 3 | X31: =W31*U31 -> 0
N32: 4 | X32: =W32*U32 -> 0
B33: 排名 | C33: 商品名 | F33: 人數 | G33: 產能 | H33: 人時生產性 | I33: 前月比 | J33: 主要原因&對策 | N33: 5 | X33: =W33*U33 -> 0
A34: 大口飯糰 | B34: 1 | C34: 直巻明太子美奶茲 | F34: 3 | G34: 2500 | H34: 833.33 | I34: 20 | J34: 透由調整速度提升。 | U34: 前幾名合計比例 | V34: =X34/N18 -> 0.23125 | W34: 前幾名合計金額 | X34: =SUM(X29:X33) -> 277.5
B35: 2
B36: 3 | M36: 半成品超用 | N36: 排名 | O36: 商品名 | R36: 半成品名 | U36: 單價 | V36: 報廢率 | W36: 數量 | X36: 金額 | Y36: 前月比 | Z36: 主要原因&對策
B37: 4 | M37: 作業原因 | N37: 1 | O37: 特製醬汁炙燒牛五花便當 | R37: 牛五花醬汁 | U37: 25 | V37: 0.25 | W37: 10 | X37: =W37*U37 -> 250 | Y37: 150 | Z37: 難度有差異。調理指導。
B38: 5 | N38: 2 | X38: =W38*U38 -> 0
B39: ▼1 | C39: 大口飯糰燒肉美奶滋 | F39: 7 | G39: 2200 | H39: 314.29 | I39: -15 | J39: 因摺疊增員。實施教育訓練。 | N39: 3 | X39: =W39*U39 -> 0
B40: ▼2 | N40: 4 | X40: =W40*U40 -> 0
B41: ▼3 | N41: 5 | X41: =W41*U41 -> 0
B42: ▼4 | U42: 前幾名合計比例 | V42: =X42/N19 -> 0.055555556 | W42: 前幾名合計金額 | X42: =SUM(X37:X41) -> 250
...

Sheet 生產管理報表(月)
A1: 生產管理報表
A3: 月別 | B3: 7 | C3: 工廠 | D3: 晉欣廠
A4: （１）收支狀況 | E4: ※單位：千元 | G4: （２）ＫＰＩ達成進度
A5: 項目 | B5: 當月 | C5: 前月 | D5: 差異 | E5: 累計 | G5: 項目 | H5: KPI | I5: 當月 | J5: 前月 | K5: 累計 | L5: ※補充
A6: 業績金額 | B6: ='（１）收支狀況'!H9/1000 -> 263724.31 | C6: 274410.13 | D6: =B6-C6 -> -10685.82 | E6: =每月數值累積總表!N6 -> 1707955.1 | G6: 人時性(個/月均) | H6: 366 | I6: ='（２）ＫＰＩ達成進度'!H9 -> 337.18177 | J6: 364.12856 | K6: =每月數值累積總表!N10/COUNT(每月數值累積總表!B10:M10) -> 349.46518 | L6: 個／MH
A7: 訂單數量 | B7: ='（１）收支狀況'!K9 -> 7772845 | C7: 8119475 | D7: =B7-C7 -> -346630 | E7: =每月數值累積總表!N7 -> 51394584 | G7: 人時達成率(%/月均) | H7: 0.8 | I7: ='（２）ＫＰＩ達成進度'!K9 -> 0.92126167 | J7: 0.99488676 | K7: =每月數值累積總表!N11/COUNT(每月數值累積總表!B11:M11) -> 0.94585843 | L7: 達成率
A8: 材料費 | B8: ='（１）收支狀況'!N9/1000 -> 177945.76 | C8: 182460.31 | D8: =B8-C8 -> -4514.548 | E8: =每月數值累積總表!N8 -> 1139182.1 | G8: 半成品-報廢(%) | H8: 0.0025 | I8: ='（２）ＫＰＩ達成進度'!N9 -> 0.0024201878 | J8: 0.0024197983 | K8: =每月數值累積總表!N12/COUNT(每月數值累積總表!B12:M12) -> 0.0024316814 | L8: 報廢率
A9: 材料費率 | B9: ='（１）收支狀況'!Q9 -> 0.6747416 | C9: 0.66491827 | D9: =B9-C9 -> 0.0098233228 | E9: =E8/E6 -> 0.66698598 | G9: 半成品-超用(%) | H9: 0.0026 | I9: ='（２）ＫＰＩ達成進度'!Q9 -> 0.0040165064 | J9: 0.0040384937 | K9: =每月數值累積總表!N13/COUNT(每月數值累積總表!B13:M13) -> 0.0028303802 | L9: 超用率
A10: 勞務成本 | B10: ='（１）收支狀況'!T9/1000 -> 31544.632 | C10: 31252.824 | D10: =B10-C10 -> 291.80758 | E10: =每月數值累積總表!N9 -> 221895.5 | G10: 固定產線-導入率(%) | H10: 0.8 | I10: ='（２）ＫＰＩ達成進度'!T9 -> 0.91666667 | J10: 0.91666667 | L10: 導入率
A11: 勞務費率 | B11: ='（１）收支狀況'!W9 -> 0.11961215 | C11: 0.11389093 | D11: =B11-C11 -> 0.0057212229 | E11: =E10/E6 -> 0.12991881 | G11: 教育訓練-實施率(%) | H11: 1 | I11: ='（２）ＫＰＩ達成進度'!W9 -> 0.58341935 | J11: 0.455 | L11: 實施率
A13: （３）業績構成比 | G13: （４）訂單數量構成比
B14: 當月 | C14: 比例 | D14: 前月 | E14: 差異 | H14: 當月 | I14: 比例 | J14: 前月 | K14: 差異
A15: 18℃-飯糰(061,063) | B15: ='（３）業績構成比'!M46/1000 -> 41290.454 | C15: =IFERROR(B15/$B$6,"") -> 0.15656673 | D15: 0.15909621 | E15: =IFERROR(C15-D15,"") -> -0.002529471 | G15: 18℃-飯糰(061,063) | H15: ='（４）訂單數量構成比'!M46 -> 2146526 | I15: =IFERROR(H15/$B$7,"") -> 0.27615706 | J15: 0.30377646 | K15: =IFERROR(I15-J15,"") -> -0.027619401
A16: 18℃-壽司手卷(071,072,075,076) | B16: ='（３）業績構成比'!S46/1000 -> 5040.4588 | C16: =IFERROR(B16/$B$6,"") -> 0.019112606 | D16: 0.015745696 | E16: =IFERROR(C16-D16,"") -> 0.0033669099 | G16: 18℃-壽司手卷(071,072,075,076) | H16: ='（４）訂單數量構成比'!S47 -> 173357 | I16: =IFERROR(H16/$B$7,"") -> 0.022302902 | J16: 0.020374566 | K16: =IFERROR(I16-J16,"") -> 0.0019283365
A17: 4℃-飯糰(065) | B17: ='（３）業績構成比'!U46/1000 -> 28134.506 | C17: =IFERROR(B17/$B$6,"") -> 0.10668151 | D17: 0.11227378 | E17: =IFERROR(C17-D17,"") -> -0.0055922714 | G17: 4℃-飯糰(065) | H17: ='（４）訂單數量構成比'!U46 -> 858013 | I17: =IFERROR(H17/$B$7,"") -> 0.11038597 | J17: 0.11176422 | K17: =IFERROR(I17-J17,"") -> -0.0013782496
A18: 4℃-壽司手卷(077) | B18: ='（３）業績構成比'!W46/1000 -> 3984.3017 | C18: =IFERROR(B18/$B$6,"") -> 0.015107829 | D18: 0.0064057099 | E18: =IFERROR(C18-D18,"") -> 0.0087021191 | G18: 4℃-壽司手卷(077) | H18: ='（４）訂單數量構成比'!W46 -> 142429 | I18: =IFERROR(H18/$B$7,"") -> 0.018323921 | J18: 0.014028245 | K18: =IFERROR(I18-J18,"") -> 0.0042956764
A19: 主食(091,092,093,094,095) | B19: ='（３）業績構成比'!AC46/1000 -> 56285.119 | C19: =IFERROR(B19/$B$6,"") -> 0.21342409 | D19: 0.20463247 | E19: =IFERROR(C19-D19,"") -> 0.0087916132 | G19: 主食(091,092,093,094,095) | H19: ='（４）訂單數量構成比'!AC46 -> 1432842 | I19: =IFERROR(H19/$B$7,"") -> 0.18433945 | J19: 0.17144617 | K19: =IFERROR(I19-J19,"") -> 0.012893284
A20: 便當(083) | B20: ='（３）業績構成比'!AE46/1000 -> 42995.922 | C20: =IFERROR(B20/$B$6,"") -> 0.1630336 | D20: 0.14537346 | E20: =IFERROR(C20-D20,"") -> 0.017660137 | G20: 便當(083) | H20: ='（４）訂單數量構成比'!AE46 -> 734871 | I20: =IFERROR(H20/$B$7,"") -> 0.094543375 | J20: 0.095125017 | K20: =IFERROR(I20-J20,"") -> -0.00058164172
A21: 熱食義麵(122,123,124,126) | B21: ='（３）業績構成比'!AG46/1000 -> 22151.653 | C21: =IFERROR(B21/$B$6,"") -> 0.083995491 | D21: 0.10428795 | E21: =IFERROR(C21-D21,"") -> -0.020292459 | G21: 熱食義麵(122,123,124,126) | H21: ='（４）訂單數量構成比'!AG46 -> 447236 | I21: =IFERROR(H21/$B$7,"") -> 0.057538263 | J21: 0.072103515 | K21: =IFERROR(I21-J21,"") -> -0.014565252
A22: 季節調理麵(111,112) | B22: ='（３）業績構成比'!AI46/1000 -> 41622.926 | C22: =IFERROR(B22/$B$6,"") -> 0.15782742 | D22: 0.16305945 | E22: =IFERROR(C22-D22,"") -> -0.0052320317 | G22: 季節調理麵(111,112) | H22: ='（４）訂單數量構成比'!AI46 -> 1087177 | I22: =IFERROR(H22/$B$7,"") -> 0.13986861 | J22: 0.11777111 | K22: =IFERROR(I22-J22,"") -> 0.022097496
A23: 微波小吃(153,154,155) | B23: ='（３）業績構成比'!AK46/1000 -> 22218.965 | C23: =IFERROR(B23/$B$6,"") -> 0.08425073 | D23: 0.089125276 | E23: =IFERROR(C23-D23,"") -> -0.004874546 | G23: 微波小吃(153,154,155) | H23: ='（４）訂單數量構成比'!AK46 -> 750394 | I23: =IFERROR(H23/$B$7,"") -> 0.096540456 | J23: 0.093610705 | K23: =IFERROR(I23-J23,"") -> 0.0029297511
C24: =SUM(C15:C23) -> 1 | D24: =SUM(D15:D23) -> 1 | I24: =SUM(I15:I23) -> 1 | J24: =SUM(J15:J23) -> 1
A26: （５）品群別人時生產性
A27: 品群 | B27: 當月 | C27: 前月 | D27: 差異 | E27: 累計
A28: 18℃-飯糰(061,063) | B28: ='（５-1）品群別人時生產性（18℃-飯糰）'!$C$1 -> 792.17451 | C28: 834.38108 | D28: =B28-C28 -> -42.206564 | E28: =每月數值累積總表!N14/COUNT(每月數值累積總表!B14:M14) -> 794.11388
A29: 18℃-壽司手卷(071,072,075,076) | B29: ='（５-2）品群別人時生產性（18-壽司手卷)'!$C$1 -> 144.15973 | C29: 142.53525 | D29: =B29-C29 -> 1.6244838 | E29: =每月數值累積總表!N15/COUNT(每月數值累積總表!B15:M15) -> 168.32118
A30: 4℃-飯糰(065) | B30: ='（５-3）品群別人時生產性（4℃-飯糰)'!$C$1 -> 222.59953 | C30: 222.12794 | D30: =B30-C30 -> 0.4715885 | E30: =每月數值累積總表!N16/COUNT(每月數值累積總表!B16:M16) -> 241.74759
A31: 4℃-壽司手卷(077) | B31: ='（５-4）品群別人時生產性（4℃-壽司手卷)'!$C$1 -> 152.24309 | C31: 115.07894 | D31: =B31-C31 -> 37.164145 | E31: =每月數值累積總表!N17/COUNT(每月數值累積總表!B17:M17) -> 119.17131
A32: 主食(091,092,093,094,095) | B32: ='（５-5）品群別人時生產性(主食) '!$C$1 -> 90.172954 | C32: 89.027946 | D32: =B32-C32 -> 1.1450083 | E32: =每月數值累積總表!N18/COUNT(每月數值累積總表!B18:M18) -> 86.379555
A33: 便當(083) | B33: ='（５-6）品群別人時生產性(便當)'!$C$1 -> 71.358623 | C33: 72.154394 | D33: =B33-C33 -> -0.79577028 | E33: =每月數值累積總表!N19/COUNT(每月數值累積總表!B19:M19) -> 70.717581
A34: 熱食義麵(122,123,124,126) | B34: ='（５-7）品群別人時生產性(熱食義麵) '!$C$1 -> 78.155524 | C34: 82.547283 | D34: =B34-C34 -> -4.3917594 | E34: =每月數值累積總表!N20/COUNT(每月數值累積總表!B20:M20) -> 80.430495
A35: 季節調理麵(111,112) | B35: ='（５-8）品群別人時生產性(季節調理麵) '!$C$1 -> 121.70792 | C35: 126.04328 | D35: =B35-C35 -> -4.3353547 | E35: =每月數值累積總表!N21/COUNT(每月數值累積總表!B21:M21) -> 124.6714
A36: 微波小吃(153,154,155) | B36: ='（５-9）品群別人時生產性(微波小吃)'!$C$1 -> 151.27705 | C36: 148.12872 | D36: =B36-C36 -> 3.1483307 | E36: =每月數值累積總表!N22/COUNT(每月數值累積總表!B22:M22) -> 156.58706

Sheet 生產管理報表(週) 
A1: 生產管理報表
A3: 月別 | B3: 11 | C3: 週別 | D3: W4 | E3: 工廠 | F3: 晉欣廠
A4: （１）收支狀況 | E4: ※單位：千元 | G4: （２）ＫＰＩ達成進度
A5: 項目 | B5: 當週 | C5: 前週 | D5: 差異 | E5: 累計 | G5: 項目 | H5: KPI | I5: 當週 | J5: 前週 | K5: 累計 | L5: ※補充
A6: 業績金額 | B6: ='（１）收支狀況'!G33/1000 -> 0 | C6: 48568.543 | D6: =B6-C6 -> -48568.543 | E6: ='（１）收支狀況'!H9/1000 -> 263724.31 | G6: 人時性(個/月均) | H6: 366 | I6: ='（２）ＫＰＩ達成進度'!G33 -> 0 | J6: 342.32011 | K6: ='（２）ＫＰＩ達成進度'!H9 -> 337.18177 | L6: 個／MH
A7: 訂單數量 | B7: ='（１）收支狀況'!J33 -> 0 | C7: 1467152 | D7: =B7-C7 -> -1467152 | E7: ='（１）收支狀況'!K9 -> 7772845 | G7: 人時達成率(%/月均) | H7: 0.8 | I7: ='（２）ＫＰＩ達成進度'!J33 -> 0 | J7: 0.93530086 | K7: ='（２）ＫＰＩ達成進度'!K9 -> 0.92126167 | L7: 達成率
A8: 材料費 | B8: ='（１）收支狀況'!M33/1000 -> 0 | C8: 32511.103 | D8: =B8-C8 -> -32511.103 | E8: ='（１）收支狀況'!N9/1000 -> 177945.76 | G8: 半成品-報廢(%) | H8: 0.0025 | I8: ='（２）ＫＰＩ達成進度'!M33 -> 0 | J8: 0.002449927 | K8: ='（２）ＫＰＩ達成進度'!N9 -> 0.0024201878 | L8: 報廢率
A9: 材料費率 | B9: ='（１）收支狀況'!P33 -> 0 | C9: 0.66938601 | D9: =B9-C9 -> -0.66938601 | E9: ='（１）收支狀況'!Q9 -> 0.6747416 | G9: 半成品-超用(%) | H9: 0.0026 | I9: ='（２）ＫＰＩ達成進度'!P33 -> 0 | J9: 0.0022296455 | K9: ='（２）ＫＰＩ達成進度'!Q9 -> 0.0040165064 | L9: 超用率
A10: 勞務成本 | B10: ='（１）收支狀況'!S33/1000 -> 0 | C10: =7059638.28/1000 -> 7059.6383 | D10: =B10-C10 -> -7059.6383 | E10: ='（１）收支狀況'!T9/1000 -> 31544.632 | G10: 固定產線-導入率(%) | H10: 0.8 | I10: 0.917 | J10: 0.917 | K10: 0.917 | L10: 導入率
A11: 勞務費率 | B11: ='（１）收支狀況'!V33 -> 0 | C11: 0.14535413 | D11: =B11-C11 -> -0.14535413 | E11: ='（１）收支狀況'!W9 -> 0.11961215 | G11: 教育訓練-實施率(%) | H11: 1 | I11: ='（２）ＫＰＩ達成進度'!V33 -> 0 | J11: 0.90285714 | K11: ='（２）ＫＰＩ達成進度'!W9 -> 0.58341935 | L11: 實施率
A13: （３）業績構成比 | G13: （４）訂單數量構成比
B14: 當週 | C14: 比例 | D14: 前週 | E14: 差異 | H14: 當週 | I14: 比例 | J14: 前週 | K14: 差異
A15: 18℃-飯糰(061,063) | B15: =SUM('（３）業績構成比'!I35:I41,'（３）業績構成比'!K35:K41)/1000 -> 3666.5456 | C15: =IFERROR(B15/$B$6,"") | D15: 0.18934668 | E15: =IFERROR(C15-D15,"") | G15: 18℃-飯糰(061,063) | H15: =SUM(,'（４）訂單數量構成比'!I35:I41,'（４）訂單數量構成比'!K35:K41) -> 189828 | I15: =IFERROR(H15/$B$7,"") | J15: 0.32807712 | K15: =IFERROR(I15-J15,"")
A16: 18℃-壽司手卷(071,072,075,076) | B16: =SUM('（３）業績構成比'!O35:O41,'（３）業績構成比'!Q35:Q41)/1000 -> 604.51297 | C16: =IFERROR(B16/$B$6,"") | D16: 0.035232688 | E16: =IFERROR(C16-D16,"") | G16: 18℃-壽司手卷(071,072,075,076) | H16: =SUM('（４）訂單數量構成比'!O35:O41,'（４）訂單數量構成比'!Q35:Q41) -> 20650 | I16: =IFERROR(H16/$B$7,"") | J16: 0.046813145 | K16: =IFERROR(I16-J16,"")
A17: 4℃-飯糰(065) | B17: =SUM('（３）業績構成比'!U35:U41)/1000 -> 2644.9825 | C17: =IFERROR(B17/$B$6,"") | D17: 0.090034972 | E17: =IFERROR(C17-D17,"") | G17: 4℃-飯糰(065) | H17: =SUM('（４）訂單數量構成比'!U35:U41) -> 80485 | I17: =IFERROR(H17/$B$7,"") | J17: 0.084512034 | K17: =IFERROR(I17-J17,"")
A18: 4℃-壽司手卷(077) | B18: =SUM('（３）業績構成比'!W35:W41)/1000 -> 258.41465 | C18: =IFERROR(B18/$B$6,"") | D18: 0.011775084 | E18: =IFERROR(C18-D18,"") | G18: 4℃-壽司手卷(077) | H18: =SUM('（４）訂單數量構成比'!W35:W41) -> 8533 | I18: =IFERROR(H18/$B$7,"") | J18: 0.019178654 | K18: =IFERROR(I18-J18,"")
A19: 主食(091,092,093,094,095) | B19: =SUM('（３）業績構成比'!Y35:Y41,'（３）業績構成比'!AA35:AA41)/1000 -> 4974.4863 | C19: =IFERROR(B19/$B$6,"") | D19: 0.2832898 | E19: =IFERROR(C19-D19,"") | G19: 主食(091,092,093,094,095) | H19: =SUM('（４）訂單數量構成比'!Y35:Y41,'（４）訂單數量構成比'!AA35:AA41) -> 131088 | I19: =IFERROR(H19/$B$7,"") | J19: 0.22873431 | K19: =IFERROR(I19-J19,"")
A20: 便當(083) | B20: =SUM('（３）業績構成比'!AE35:AE41)/1000 -> 3604.6295 | C20: =IFERROR(B20/$B$6,"") | D20: 0.15040468 | E20: =IFERROR(C20-D20,"") | G20: 便當(083) | H20: =SUM('（４）訂單數量構成比'!AE35:AE41) -> 61922 | I20: =IFERROR(H20/$B$7,"") | J20: 0.089526511 | K20: =IFERROR(I20-J20,"")
A21: 熱食義麵(122,123,124,126) | B21: =SUM('（３）業績構成比'!AG35:AG41)/1000 -> 2142.0921 | C21: =IFERROR(B21/$B$6,"") | D21: 0.11116644 | E21: =IFERROR(C21-D21,"") | G21: 熱食義麵(122,123,124,126) | H21: =SUM('（４）訂單數量構成比'!AG35:AG41) -> 42664 | I21: =IFERROR(H21/$B$7,"") | J21: 0.073652219 | K21: =IFERROR(I21-J21,"")
A22: 季節調理麵(111,112) | B22: =SUM('（３）業績構成比'!AI35:AI41)/1000 -> 3374.8586 | C22: =IFERROR(B22/$B$6,"") | D22: 0.046912394 | E22: =IFERROR(C22-D22,"") | G22: 季節調理麵(111,112) | H22: =SUM('（４）訂單數量構成比'!AI35:AI41) -> 87650 | I22: =IFERROR(H22/$B$7,"") | J22: 0.041703245 | K22: =IFERROR(I22-J22,"")
A23: 微波小吃(153,154,155) | B23: =SUM('（３）業績構成比'!AK35:AK41)/1000 -> 2024.747 | C23: =IFERROR(B23/$B$6,"") | D23: 0.081837257 | E23: =IFERROR(C23-D23,"") | G23: 微波小吃(153,154,155) | H23: =SUM('（４）訂單數量構成比'!AK35:AK41) -> 68700 | I23: =IFERROR(H23/$B$7,"") | J23: 0.087802763 | K23: =IFERROR(I23-J23,"")
C24: =SUM(C15:C23) -> 0 | D24: =SUM(D15:D23) -> 1 | I24: =SUM(I15:I23) -> 0 | J24: =SUM(J15:J23) -> 1
A26: （５）品群別人時生產性
A27: 品群 | B27: 當週 | C27: 前週 | D27: 差異 | E27: 累計
A28: 18℃-飯糰(061,063) | B28: ='（５-1）品群別人時生產性（18℃-飯糰）'!L147 -> 818.60878 | C28: 773.28751 | D28: =B28-C28 -> 45.321267 | E28: ='（５-1）品群別人時生產性（18℃-飯糰）'!C1 -> 792.17451 | F28: 147
A29: 18℃-壽司手卷(071,072,075,076) | B29: ='（５-2）品群別人時生產性（18-壽司手卷)'!L87 -> 139.65315 | C29: 182.60764 | D29: =B29-C29 -> -42.954489 | E29: ='（５-2）品群別人時生產性（18-壽司手卷)'!C1 -> 144.15973 | F29: 87
A30: 4℃-飯糰(065) | B30: ='（５-3）品群別人時生產性（4℃-飯糰)'!L87 -> 217.42697 | C30: 272.74109 | D30: =B30-C30 -> -55.314115 | E30: ='（５-3）品群別人時生產性（4℃-飯糰)'!C1 -> 222.59953
A31: 4℃-壽司手卷(077) | B31: ='（５-4）品群別人時生產性（4℃-壽司手卷)'!L87 -> 150.71346 | C31: 113.81516 | D31: =B31-C31 -> 36.898298 | E31: ='（５-4）品群別人時生產性（4℃-壽司手卷)'!C1 -> 152.24309
A32: 主食(091,092,093,094,095) | B32: ='（５-5）品群別人時生產性(主食) '!L147 -> 88.564619 | C32: 86.027649 | D32: =B32-C32 -> 2.5369701 | E32: ='（５-5）品群別人時生產性(主食) '!C1 -> 90.172954
A33: 便當(083) | B33: ='（５-6）品群別人時生產性(便當)'!L87 -> 70.867635 | C33: 67.317863 | D33: =B33-C33 -> 3.5497722 | E33: ='（５-6）品群別人時生產性(便當)'!C1 -> 71.358623
A34: 熱食義麵(122,123,124,126) | B34: ='（５-7）品群別人時生產性(熱食義麵) '!L87 -> 78.019854 | C34: 77.43651 | D34: =B34-C34 -> 0.58334388 | E34: ='（５-7）品群別人時生產性(熱食義麵) '!C1 -> 78.155524
A35: 季節調理麵(111,112) | B35: ='（５-8）品群別人時生產性(季節調理麵) '!L87 -> 121.59002 | C35: 121.87281 | D35: =B35-C35 -> -0.28278116 | E35: ='（５-8）品群別人時生產性(季節調理麵) '!C1 -> 121.70792
A36: 微波小吃(153,154,155) | B36: ='（５-9）品群別人時生產性(微波小吃)'!L87 -> 146.53651 | C36: 115.15834 | D36: =B36-C36 -> 31.378163 | E36: ='（５-9）品群別人時生產性(微波小吃)'!C1 -> 151.27705
D37: =SUM(D28:D36) -> 21.716428

Sheet 每月數值累積總表
A5: 項目 | B5: 2026/1月 | C5: 2026/2月 | D5: 2026/3月 | E5: 2026/4月 | F5: 2026/5月 | G5: 2026/6月 | H5: 2026/7月 | I5: 2026/8月 | J5: 2026/9月 | K5: 2026/10月 | L5: 2026/11月 | M5: 2026/12月 | N5: 合計/平均
A6: 業績金額(千元) | B6: 204598.72 | C6: 192546.05 | D6: 236658.24 | E6: 256837.25 | F6: 279180.38 | G6: 274410.13 | H6: ='生產管理報表(月)'!$B6 -> 263724.31 | N6: =SUM(B6:M6) -> 1707955.1
A7: 訂單數量 | B7: 6333014 | C7: 5860836 | D7: 7295467 | E7: 7731298 | F7: 8281649 | G7: 8119475 | H7: ='生產管理報表(月)'!$B7 -> 7772845 | N7: =SUM(B7:M7) -> 51394584
A8: 材料費(千元) | B8: 138760.36 | C8: 127549.68 | D8: 157257.77 | E8: 171758.91 | F8: 183449.3 | G8: 182460.31 | H8: ='生產管理報表(月)'!$B8 -> 177945.76 | N8: =SUM(B8:M8) -> 1139182.1
A9: 勞務成本(千元) | B9: 30102.782 | C9: 30046.481 | D9: 31852.551 | E9: 33551.595 | F9: 33544.634 | G9: 31252.824 | H9: ='生產管理報表(月)'!$B10 -> 31544.632 | N9: =SUM(B9:M9) -> 221895.5
A10: 人時性(個/月均) | B10: 325.42302 | C10: 348.55662 | D10: 353.52749 | E10: 355.30918 | F10: 362.12961 | G10: 364.12856 | H10: ='生產管理報表(月)'!$I6 -> 337.18177 | N10: =SUM(B10:M10) -> 2446.2563
A11: 人時達成率(%/月均) | B11: 0.88947795 | C11: 0.88885114 | D11: 0.96631623 | E11: 0.9707901 | F11: 0.98942517 | G11: 0.99488676 | H11: ='生產管理報表(月)'!$I7 -> 0.92126167 | N11: =SUM(B11:M11) -> 6.621009
A12: 半成品-報廢(%) | B12: 0.0024547774 | C12: 0.002435211 | D12: 0.0024375052 | E12: 0.002430752 | F12: 0.0024235378 | G12: 0.0024197983 | H12: ='生產管理報表(月)'!$I8 -> 0.0024201878 | N12: =SUM(B12:M12) -> 0.01702177
A13: 半成品-超用(%) | B13: 0.0022346306 | C13: 0.0019856446 | D13: 0.0018458045 | E13: 0.0017845321 | F13: 0.0039070494 | G13: 0.0040384937 | H13: ='生產管理報表(月)'!$I9 -> 0.0040165064 | N13: =SUM(B13:M13) -> 0.019812661
A14: 18℃-飯糰(061,063) | B14: 793.68171 | C14: 793.91003 | D14: 775.10369 | E14: 767.22195 | F14: 802.32418 | G14: 834.38108 | H14: ='生產管理報表(月)'!$B28 -> 792.17451 | N14: =SUM(B14:M14) -> 5558.7971
A15: 18℃-壽司手卷(071,072,075,076) | B15: 171.43329 | C15: 188.87834 | D15: 177.92885 | E15: 186.63001 | F15: 166.68277 | G15: 142.53525 | H15: ='生產管理報表(月)'!$B29 -> 144.15973 | N15: =SUM(B15:M15) -> 1178.2482
A16: 4℃-飯糰(065) | B16: 255.36298 | C16: 249.81281 | D16: 259.7814 | E16: 246.49126 | F16: 236.05722 | G16: 222.12794 | H16: ='生產管理報表(月)'!$B30 -> 222.59953 | N16: =SUM(B16:M16) -> 1692.2331
A17: 4℃-壽司手卷(077) | B17: 118.36197 | C17: 122.98264 | D17: 118.7225 | E17: 103.71565 | F17: 103.0944 | G17: 115.07894 | H17: ='生產管理報表(月)'!$B31 -> 152.24309 | N17: =SUM(B17:M17) -> 834.1992
A18: 主食(091,092,093,094,095) | B18: 82.894643 | C18: 82.248072 | D18: 84.21327 | E18: 87.4 | F18: 88.7 | G18: 89.027946 | H18: ='生產管理報表(月)'!$B32 -> 90.172954 | N18: =SUM(B18:M18) -> 604.65689
A19: 便當(083) | B19: 68.391795 | C19: 66.758428 | D19: 71.676669 | E19: 72.067082 | F19: 72.616079 | G19: 72.154394 | H19: ='生產管理報表(月)'!$B33 -> 71.358623 | N19: =SUM(B19:M19) -> 495.02307
A20: 熱食義麵(122,123,124,126) | B20: 70.145845 | C20: 74.884977 | D20: 86.627336 | E20: 84.932134 | F20: 85.720364 | G20: 82.547283 | H20: ='生產管理報表(月)'!$B34 -> 78.155524 | N20: =SUM(B20:M20) -> 563.01346
A21: 季節調理麵(111,112) | B21: 122.33833 | C21: 120.92496 | D21: 124.40029 | E21: 126.33665 | F21: 130.94835 | G21: 126.04328 | H21: ='生產管理報表(月)'!$B35 -> 121.70792 | N21: =SUM(B21:M21) -> 872.69978
A22: 微波小吃(153,154,155) | B22: 124.77438 | C22: 162.89468 | D22: 174.62095 | E22: 176.89316 | F22: 157.5205 | G22: 148.12872 | H22: ='生產管理報表(月)'!$B36 -> 151.27705 | N22: =SUM(B22:M22) -> 1096.1094

Sheet （１）收支狀況
B2: （１）收支狀況
C3: 月份 | D3: 日期 | F3: 營業額(元) | I3: 訂單數量(個) | L3: 材料費(元) | O3: 材料費率（材料費／營業額） | R3: 勞務成本（全廠人事成本） | U3: 勞務費率（勞務成本／營業額）
F4: 日 | G4: 週累積 | H4: 月累積 | I4: 日 | J4: 週累積 | K4: 月累積 | L4: 日 | M4: 週累積 | N4: 月累積 | O4: 日 | P4: 週累積 | Q4: 月平均 | R4: 日 | S4: 週累積 | T4: 月累積 | U4: 日 | V4: 週累積 | W4: 月平均
D9: 46204 | E9: 三 | F9: 8773103 | H9: =SUM(F9:F39) -> 263724306 | I9: 266041 | K9: =SUM(I9:I39) -> 7772845 | L9: 6521226 | N9: =SUM(L9:L39) -> 177945759 | O9: =L9/F9 -> 0.74332035 | Q9: =N9/H9 -> 0.6747416 | R9: 1037983.4 | T9: =SUM(R9:R39) -> 31544632 | U9: =R9/F9 -> 0.11831429 | W9: =T9/H9 -> 0.11961215
D10: =D9+1 -> 46205 | E10: 四 | F10: 8177093 | I10: 250642 | L10: 5803676 | O10: =L10/F10 -> 0.70974807 | R10: 1007943.3 | U10: =R10/F10 -> 0.12326426
D11: =D10+1 -> 46206 | E11: 五 | F11: 7340175 | I11: 225060 | L11: 4734117 | O11: =L11/F11 -> 0.64495969 | R11: 1012657.3 | U11: =R11/F11 -> 0.13796092
D12: =D11+1 -> 46207 | E12: 六 | F12: 8235605 | I12: 244678 | L12: 5628385 | O12: =L12/F12 -> 0.68342095 | R12: 1023634.1 | U12: =R12/F12 -> 0.12429374
D13: =D12+1 -> 46208 | E13: 日 | F13: 9197911 | I13: 275484 | L13: 6061424 | O13: =L13/F13 -> 0.65900007 | R13: 1056786.7 | U13: =R13/F13 -> 0.11489421
D14: =D13+1 -> 46209 | E14: 一 | F14: 9363255 | I14: 277705 | L14: 6157076 | O14: =L14/F14 -> 0.65757859 | R14: 1042989.7 | U14: =R14/F14 -> 0.11139178
D15: =D14+1 -> 46210 | E15: 二 | F15: 10402844 | I15: 299940 | L15: 6702398 | O15: =L15/F15 -> 0.64428516 | R15: 1056838.2 | U15: =R15/F15 -> 0.10159127
D16: =D15+1 -> 46211 | E16: 三 | F16: 9579033 | I16: 281251 | L16: 6361914 | O16: =L16/F16 -> 0.66414992 | R16: 1049236.3 | U16: =R16/F16 -> 0.10953468
D17: =D16+1 -> 46212 | E17: 四 | F17: 9159433 | I17: 269872 | L17: 6160391 | O17: =L17/F17 -> 0.6725734 | R17: 1048394.8 | U17: =R17/F17 -> 0.11446067
D18: =D17+1 -> 46213 | E18: 五 | F18: 7382110 | I18: 221106 | L18: 4945405 | O18: =L18/F18 -> 0.66991754 | R18: 996977.16 | U18: =R18/F18 -> 0.13505314
D19: =D18+1 -> 46214 | E19: 六 | F19: 7919116 | I19: 233330 | L19: 5252637 | O19: =L19/F19 -> 0.66328578 | R19: 1005335.1 | U19: =R19/F19 -> 0.12695043
D20: =D19+1 -> 46215 | E20: 日 | F20: 9570480 | I20: 277272 | L20: 6155234 | O20: =L20/F20 -> 0.64314789 | R20: 1048548.6 | U20: =R20/F20 -> 0.10956072
D21: =D20+1 -> 46216 | E21: 一 | F21: 9554533 | I21: 274460 | L21: 6263212 | O21: =L21/F21 -> 0.65552257 | R21: 1038063.1 | U21: =R21/F21 -> 0.10864614
... D39: =D38+1 -> 46234 | E39: 五 | F39: 7084934 | I39: 211184 | L39: 4712463 | O39: =L39/F39 -> 0.66513859 | R39: 999698.19 | U39: =R39/F39 -> 0.14110198
O40: =L40/F40 -> #DIV/0! | U40: =R40/F40 -> #DIV/0!

Sheet （２）ＫＰＩ達成進度
B1: KPI | C1: 366
B2: （２）ＫＰＩ達成進度
C3: 月份 | D3: 日期 | F3: 人時生產性(個/人) | I3: 人時生產性達成率(%) | L3: 半成品報廢(%) | O3: 半成品超用(%) | R3: 固定產線-導入率(固定產線數/總產線數) | U3: 教育訓練-實施率(進度/計畫)
F4: 日 | G4: 週平均 | H4: 月平均 | I4: 日 | J4: 週平均 | K4: 月平均 | L4: 日 | M4: 週平均 | N4: 月平均 | O4: 日 | P4: 週平均 | Q4: 月平均 | R4: 日 | S4: 週平均 | T4: 月平均 | U4: 日 | V4: 週平均 | W4: 月平均
D9: 46204 | E9: 三 | F9: 364.8 | H9: =AVERAGE(F9:F39) -> 337.18177 | I9: =F9/$C$1 -> 0.99672131 | K9: =AVERAGE(I9:I39) -> 0.92126167 | L9: 0.0024330243 | N9: =AVERAGE(L9:L39) -> 0.0024201878 | O9: 0.0041871246 | Q9: =AVERAGE(O9:O39) -> 0.0040165064 | R9: 0.91666667 | T9: =AVERAGE(R9:R39) -> 0.91666667 | U9: 0.532 | W9: =AVERAGE(U9:U39) -> 0.58341935
D10: =D9+1 -> 46205 | E10: 四 | F10: 362.7 | I10: =F10/$C$1 -> 0.99098361 | L10: 0.0024023279 | O10: 0.0039076528 | R10: 0.91666667 | U10: 0.534
D11: =D10+1 -> 46206 | E11: 五 | F11: 365.8 | I11: =F11/$C$1 -> 0.99945355 | L11: 0.0024222664 | O11: 0.0041228686 | R11: 0.91666667 | U11: 0.536
D12: =D11+1 -> 46207 | E12: 六 | F12: 362.8 | I12: =F12/$C$1 -> 0.99125683 | L12: 0.0024292961 | O12: 0.0040008175 | R12: 0.91666667 | U12: 0.538
D13: =D12+1 -> 46208 | E13: 日 | F13: 368.3 | I13: =F13/$C$1 -> 1.0062842 | L13: 0.0024165581 | O13: 0.0041168916 | R13: 0.91666667 | U13: 0.54
D14: =D13+1 -> 46209 | E14: 一 | F14: 357.2 | I14: =F14/$C$1 -> 0.97595628 | L14: 0.002431182 | O14: 0.0038485231 | R14: 0.91666667 | U14: 0.54
D15: =D14+1 -> 46210 | E15: 二 | F15: 322.35036 | I15: =F15/$C$1 -> 0.88073869 | L15: 0.0024040166 | O15: 0.0038556381 | R15: 0.91666667 | U15: 0.542
D16: =D15+1 -> 46211 | E16: 三 | F16: 320.02862 | I16: =F16/$C$1 -> 0.87439512 | L16: 0.0024062558 | O16: 0.003756309 | R16: 0.91666667 | U16: 0.542
D17: =D16+1 -> 46212 | E17: 四 | F17: 320.9024 | I17: =F17/$C$1 -> 0.87678253 | L17: 0.0024082651 | O17: 0.003873816 | R17: 0.91666667 | U17: 0.544
D18: =D17+1 -> 46213 | E18: 五 | F18: 321.88914 | I18: =F18/$C$1 -> 0.87947854 | L18: 0.0024428605 | O18: 0.0040445005 | R18: 0.91666667 | U18: 0.548
D19: =D18+1 -> 46214 | E19: 六 | F19: 327.04085 | I19: =F19/$C$1 -> 0.89355423 | L19: 0.0024336637 | O19: 0.0040593259 | R19: 0.91666667 | U19: 0.55
D20: =D19+1 -> 46215 | E20: 日 | F20: 326.16637 | I20: =F20/$C$1 -> 0.89116494 | L20: 0.0024191679 | O20: 0.0038031417 | R20: 0.91666667 | U20: 0.56
D21: =D20+1 -> 46216 | E21: 一 | F21: 323.11422 | I21: =F21/$C$1 -> 0.88282573 | L21: 0.0024299257 | O21: 0.0038911987 | R21: 0.91666667 | U21: 0.562
... D39: =D38+1 -> 46234 | E39: 五 | F39: 340.37943 | I39: =F39/$C$1 -> 0.92999843 | L39: 0.0024203802 | O39: 0.0041277675 | R39: 0.91666667 | U39: 0.634

Sheet （３）業績構成比
B2: （3）業績構成比
C3: 月份 | D3: 日期 | F3: 營業額 | I3: 品類業績
I4: 18℃-飯糰 | O4: 18℃-壽司手卷 | U4: 4℃-飯糰 | W4: 4℃-壽司手卷 | Y4: 主食 | AE4: 便當 | AG4: 熱食義麵 | AI4: 季節調理麵 | AK4: 微波小吃
F5: 日 | G5: 週累積 | H5: 月累積 | I5: 一配 | K5: 二配 | M5: 合計 | O5: 一配 | Q5: 二配 | S5: 合計 | U5: 一配 | W5: 一配 | Y5: 一配 | AA5: 二配 | AC5: 合計 | AE5: 一配 | AG5: 一配 | AI5: 一配 | AK5: 一配
I6: 業績(元) | J6: 比例(%) | K6: 業績(元) | L6: 比例(%) | M6: 業績(元) | N6: 比例(%) | O6: 業績(元) | P6: 比例(%) | Q6: 業績(元) | R6: 比例(%) | S6: 業績(元) | T6: 比例(%) | U6: 業績(元) | V6: 比例(%) | W6: 業績(元) | X6: 比例(%) | Y6: 業績(元) | Z6: 比例(%) | AA6: 業績(元) | AB6: 比例(%) | AC6: 業績(元) | AD6: 比例(%) | AE6: 業績(元) | AF6: 比例(%) | AG6: 業績(元) | AH6: 比例(%) | AI6: 業績(元) | AJ6: 比例(%) | AK6: 業績(元) | AL6: 比例(%)
D7: 46204 | E7: 三 | F7: =SUM(M7,S7,U7,W7,AC7,AE7,AG7,AI7,AK7) -> 8773103 | H7: =SUM($F$7:$F$37) -> 263724306 | I7: 585584.43 | J7: =I7/F7 -> 0.066747698 | K7: 926345.85 | L7: =K7/F7 -> 0.1055893 | M7: =SUM(I7+K7) -> 1511930.3 | N7: =M7/F7 -> 0.172337 | O7: 146097.44 | P7: =O7/F7 -> 0.016652881 | R7: =Q7/$F7 -> 0 | S7: =SUM(O7+Q7) -> 146097.44 | T7: =S7/F7 -> 0.016652881 | U7: 1025972.1 | V7: =U7/F7 -> 0.11694518 | W7: 96911.017 | X7: =W7/F7 -> 0.011046379 | Y7: 663881.69 | Z7: =Y7/F7 -> 0.075672392 | AA7: 1059308.2 | AB7: =AA7/$F7 -> 0.12074498 | AC7: =SUM(Y7+AA7) -> 1723189.9 | AD7: =AC7/F7 -> 0.19641737 | AE7: 1371712.6 | AF7: =AE7/F7 -> 0.15635432 | AG7: 751307.6 | AH7: =AG7/F7 -> 0.085637613 | AI7: 1390227.6 | AJ7: =AI7/F7 -> 0.15846475 | AK7: 755754.53 | AL7: =AK7/F7 -> 0.086144496
D8: =D7+1 -> 46205 | E8: 四 | F8: =SUM(M8,S8,U8,W8,AC8,AE8,AG8,AI8,AK8) -> 8177093 | I8: 575114.81 | J8: =I8/F8 -> 0.070332429 | K8: 860849.37 | L8: =K8/F8 -> 0.10527572 | M8: =SUM(I8+K8) -> 1435964.2 | N8: =M8/F8 -> 0.17560815 | O8: 149474.57 | P8: =O8/F8 -> 0.018279671 | R8: =Q8/$F8 -> 0 | S8: =SUM(O8+Q8) -> 149474.57 | T8: =S8/F8 -> 0.018279671 | U8: 925718.71 | V8: =U8/F8 -> 0.11320878 | W8: 86523.696 | X8: =W8/F8 -> 0.010581229 | Y8: 620467.91 | Z8: =Y8/F8 -> 0.075878789 | AA8: 878967.94 | AB8: =AA8/$F8 -> 0.10749149 | AC8: =SUM(Y8+AA8) -> 1499435.8 | AD8: =AC8/F8 -> 0.18337028 | AE8: 1271362.5 | AF8: =AE8/F8 -> 0.15547854 | AG8: 683768.59 | AH8: =AG8/F8 -> 0.083620008 | AI8: 1397996.8 | AJ8: =AI8/F8 -> 0.17096501 | AK8: 726848.14 | AL8: =AK8/F8 -> 0.08888833
D9: =D8+1 -> 46206 | E9: 五 | F9: =SUM(M9,S9,U9,W9,AC9,AE9,AG9,AI9,AK9) -> 7340175 | I9: 502386.01 | J9: =I9/F9 -> 0.068443328 | K9: 791842.53 | L9: =K9/F9 -> 0.10787788 | M9: =SUM(I9+K9) -> 1294228.5 | N9: =M9/F9 -> 0.17632121 | O9: 126093.23 | P9: =O9/F9 -> 0.017178504 | R9: =Q9/$F9 -> 0 | S9: =SUM(O9+Q9) -> 126093.23 | T9: =S9/F9 -> 0.017178504 | U9: 815623.07 | V9: =U9/F9 -> 0.11111766 | W9: 69452.719 | X9: =W9/F9 -> 0.0094619977 | Y9: 570858.45 | Z9: =Y9/F9 -> 0.077771777 | AA9: 988937.62 | AB9: =AA9/$F9 -> 0.13472943 | AC9: =SUM(Y9+AA9) -> 1559796.1 | AD9: =AC9/F9 -> 0.21250121 | AE9: 1023526.6 | AF9: =AE9/F9 -> 0.13944171 | AG9: 487853.51 | AH9: =AG9/F9 -> 0.066463471 | AI9: 1351860.7 | AJ9: =AI9/F9 -> 0.18417282 | AK9: 611740.59 | AL9: =AK9/F9 -> 0.083341417
D10: =D9+1 -> 46207 | E10: 六 | F10: =SUM(M10,S10,U10,W10,AC10,AE10,AG10,AI10,AK10) -> 8235605 | I10: 487575.22 | J10: =I10/F10 -> 0.059203327 | K10: 832130.11 | L10: =K10/F10 -> 0.10104056 | M10: =SUM(I10+K10) -> 1319705.3 | N10: =M10/F10 -> 0.16024388 | O10: 119675.28 | P10: =O10/F10 -> 0.01453145 | R10: =Q10/$F10 -> 0 | S10: =SUM(O10+Q10) -> 119675.28 | T10: =S10/F10 -> 0.01453145 | U10: 950603.24 | V10: =U10/F10 -> 0.11542604 | W10: 82949.303 | X10: =W10/F10 -> 0.010072035 | Y10: 617616.14 | Z10: =Y10/F10 -> 0.074993414 | AA10: 1103588.9 | AB10: =AA10/$F10 -> 0.13400216 | AC10: =SUM(Y10+AA10) -> 1721205 | AD10: =AC10/F10 -> 0.20899558 | AE10: 1240739.6 | AF10: =AE10/F10 -> 0.15065555 | AG10: 607209.44 | AH10: =AG10/F10 -> 0.073729792 | AI10: 1485915.6 | AJ10: =AI10/F10 -> 0.1804258 | AK10: 707602.19 | AL10: =AK10/F10 -> 0.08591988
D11: =D10+1 -> 46208 | E11: 日 | F11: =SUM(M11,S11,U11,W11,AC11,AE11,AG11,AI11,AK11) -> 9197911 | I11: 587245.11 | J11: =I11/F11 -> 0.063845487 | K11: 904227.19 | L11: =K11/F11 -> 0.098307886 | M11: =SUM(I11+K11) -> 1491472.3 | N11: =M11/F11 -> 0.16215337 | O11: 150097.51 | P11: =O11/F11 -> 0.016318653 | R11: =Q11/$F11 -> 0 | S11: =SUM(O11+Q11) -> 150097.51 | T11: =S11/F11 -> 0.016318653 | U11: 1139386.4 | V11: =U11/F11 -> 0.12387447 | W11: 100986.86 | X11: =W11/F11 -> 0.010979326 | Y11: 687503.18 | Z11: =Y11/F11 -> 0.074745579 | AA11: 1142201.5 | AB11: =AA11/$F11 -> 0.12418054 | AC11: =SUM(Y11+AA11) -> 1829704.7 | AD11: =AC11/F11 -> 0.19892612 | AE11: 1461187.4 | AF11: =AE11/F11 -> 0.15886078 | AG11: 747956.2 | AH11: =AG11/F11 -> 0.081318051 | AI11: 1518256 | AJ11: =AI11/F11 -> 0.16506531 | AK11: 758863.64 | AL11: =AK11/F11 -> 0.082503912
D12: =D11+1 -> 46209 | E12: 一 | F12: =SUM(M12,S12,U12,W12,AC12,AE12,AG12,AI12,AK12) -> 9363255 | I12: 582448.09 | J12: =I12/F12 -> 0.062205728 | K12: 893437.27 | L12: =K12/F12 -> 0.095419517 | M12: =SUM(I12+K12) -> 1475885.4 | N12: =M12/F12 -> 0.15762525 | O12: 148647.22 | P12: =O12/F12 -> 0.015875592 | R12: =Q12/$F12 -> 0 | S12: =SUM(O12+Q12) -> 148647.22 | T12: =S12/F12 -> 0.015875592 | U12: 1140636.5 | V12: =U12/F12 -> 0.12182051 | W12: 73225.826 | X12: =W12/F12 -> 0.0078205523 | Y12: 712903.77 | Z12: =Y12/F12 -> 0.076138456 | AA12: 1373132.4 | AB12: =AA12/$F12 -> 0.14665118 | AC12: =SUM(Y12+AA12) -> 2086036.2 | AD12: =AC12/F12 -> 0.22278963 | AE12: 1372438.1 | AF12: =AE12/F12 -> 0.14657703 | AG12: 753905.55 | AH12: =AG12/F12 -> 0.080517464 | AI12: 1504926.4 | AJ12: =AI12/F12 -> 0.16072684 | AK12: 807553.84 | AL12: =AK12/F12 -> 0.086247127
D13: =D12+1 -> 46210 | E13: 二 | F13: =SUM(M13,S13,U13,W13,AC13,AE13,AG13,AI13,AK13) -> 10402844 | I13: 593435.7 | J13: =I13/F13 -> 0.057045525 | K13: 890030.64 | L13: =K13/F13 -> 0.085556473 | M13: =SUM(I13+K13) -> 1483466.3 | N13: =M13/F13 -> 0.142602 | O13: 149791.71 | P13: =O13/F13 -> 0.014399112 | R13: =Q13/$F13 -> 0 | S13: =SUM(O13+Q13) -> 149791.71 | T13: =S13/F13 -> 0.014399112 | U13: 1092598.1 | V13: =U13/F13 -> 0.10502878 | W13: 361990.62 | X13: =W13/F13 -> 0.034797274 | Y13: 683930.26 | Z13: =Y13/F13 -> 0.065744546 | AA13: 1289177 | AB13: =AA13/$F13 -> 0.12392544 | AC13: =SUM(Y13+AA13) -> 1973107.2 | AD13: =AC13/F13 -> 0.18966998 | AE13: 1889345.1 | AF13: =AE13/F13 -> 0.18161814 | AG13: 696363.11 | AH13: =AG13/F13 -> 0.066939686 | AI13: 1944634.6 | AJ13: =AI13/F13 -> 0.18693297 | AK13: 811547.23 | AL13: =AK13/F13 -> 0.078012054
D14: =D13+1 -> 46211 | E14: 三 | F14: =SUM(M14,S14,U14,W14,AC14,AE14,AG14,AI14,AK14) -> 9579033 | I14: 582733.78 | J14: =I14/F14 -> 0.060834301 | K14: 864415.43 | L14: =K14/F14 -> 0.090240364 | M14: =SUM(I14+K14) -> 1447149.2 | N14: =M14/F14 -> 0.15107467 | O14: 149764.58 | P14: =O14/F14 -> 0.015634624 | R14: =Q14/$F14 -> 0 | S14: =SUM(O14+Q14) -> 149764.58 | T14: =S14/F14 -> 0.015634624 | U14: 967320.14 | V14: =U14/F14 -> 0.10098307 | W14: 228848.57 | X14: =W14/F14 -> 0.023890571 | Y14: 662393.12 | Z14: =Y14/F14 -> 0.069150312 | AA14: 1264015.6 | AB14: =AA14/$F14 -> 0.13195649 | AC14: =SUM(Y14+AA14) -> 1926408.7 | AD14: =AC14/F14 -> 0.2011068 | AE14: 1621356.8 | AF14: =AE14/F14 -> 0.16926101 | AG14: 660044.56 | AH14: =AG14/F14 -> 0.068905134 | AI14: 1768129 | AJ14: =AI14/F14 -> 0.18458325 | AK14: 810011.44 | AL14: =AK14/F14 -> 0.084560878
D15: =D14+1 -> 46212 | E15: 四 | F15: =SUM(M15,S15,U15,W15,AC15,AE15,AG15,AI15,AK15) -> 9159433 | I15: 550579.75 | J15: =I15/F15 -> 0.06011068 | K15: 785786.18 | L15: =K15/F15 -> 0.085789828 | M15: =SUM(I15+K15) -> 1336365.9 | N15: =M15/F15 -> 0.14590051 | O15: 146784.78 | P15: =O15/F15 -> 0.016025531 | R15: =Q15/$F15 -> 0 | S15: =SUM(O15+Q15) -> 146784.78 | T15: =S15/F15 -> 0.016025531 | U15: 861554.53 | V15: =U15/F15 -> 0.094061994 | W15: 217569.65 | X15: =W15/F15 -> 0.023753615 | Y15: 678881.24 | Z15: =Y15/F15 -> 0.074118261 | AA15: 1073459.7 | AB15: =AA15/$F15 -> 0.11719718 | AC15: =SUM(Y15+AA15) -> 1752340.9 | AD15: =AC15/F15 -> 0.19131544 | AE15: 1585947.8 | AF15: =AE15/F15 -> 0.17314912 | AG15: 741403.82 | AH15: =AG15/F15 -> 0.080944292 | AI15: 1652100.5 | AJ15: =AI15/F15 -> 0.18037148 | AK15: 865365.08 | AL15: =AK15/F15 -> 0.094478018
D16: =D15+1 -> 46213 | E16: 五 | F16: =SUM(M16,S16,U16,W16,AC16,AE16,AG16,AI16,AK16) -> 7382110 | I16: 460120.37 | J16: =I16/F16 -> 0.062329114 | K16: 709347.8 | L16: =K16/F16 -> 0.096090116 | M16: =SUM(I16+K16) -> 1169468.2 | N16: =M16/F16 -> 0.15841923 | O16: 121775.96 | P16: =O16/F16 -> 0.016496092 | R16: =Q16/$F16 -> 0 | S16: =SUM(O16+Q16) -> 121775.96 | T16: =S16/F16 -> 0.016496092 | U16: 741304.92 | V16: =U16/F16 -> 0.10041911 | W16: 88855.566 | X16: =W16/F16 -> 0.012036608 | Y16: 575865.51 | Z16: =Y16/F16 -> 0.078008254 | AA16: 956824.03 | AB16: =AA16/$F16 -> 0.12961389 | AC16: =SUM(Y16+AA16) -> 1532689.5 | AD16: =AC16/F16 -> 0.20762215 | AE16: 1241395.9 | AF16: =AE16/F16 -> 0.16816275 | AG16: 517502.6 | AH16: =AG16/F16 -> 0.07010226 | AI16: 1355671.6 | AJ16: =AI16/F16 -> 0.18364283 | AK16: 613445.79 | AL16: =AK16/F16 -> 0.083098977
D17: =D16+1 -> 46214 | E17: 六 | F17: =SUM(M17,S17,U17,W17,AC17,AE17,AG17,AI17,AK17) -> 7919116 | I17: 433945.27 | J17: =I17/F17 -> 0.054797186 | K17: 777548.26 | L17: =K17/F17 -> 0.098186244 | M17: =SUM(I17+K17) -> 1211493.5 | N17: =M17/F17 -> 0.15298343 | O17: 114353.47 | P17: =O17/F17 -> 0.014440182 | R17: =Q17/$F17 -> 0 | S17: =SUM(O17+Q17) -> 114353.47 | T17: =S17/F17 -> 0.014440182 | U17: 737706.68 | V17: =U17/F17 -> 0.093155181 | W17: 123313.18 | X17: =W17/F17 -> 0.015571584 | Y17: 624159.75 | Z17: =Y17/F17 -> 0.078816847 | AA17: 1033867.7 | AB17: =AA17/$F17 -> 0.13055342 | AC17: =SUM(Y17+AA17) -> 1658027.5 | AD17: =AC17/F17 -> 0.20937027 | AE17: 1389337.1 | AF17: =AE17/F17 -> 0.17544093 | AG17: 592446.52 | AH17: =AG17/F17 -> 0.074812203 | AI17: 1475253.5 | AJ17: =AI17/F17 -> 0.18629017 | AK17: 617184.58 | AL17: =AK17/F17 -> 0.077936045
D18: =D17+1 -> 46215 | E18: 日 | F18: =SUM(M18,S18,U18,W18,AC18,AE18,AG18,AI18,AK18) -> 9570480 | I18: 545372.17 | J18: =I18/F18 -> 0.056984829 | K18: 839966.68 | L18: =K18/F18 -> 0.08776641 | M18: =SUM(I18+K18) -> 1385338.8 | N18: =M18/F18 -> 0.14475124 | O18: 149015.17 | P18: =O18/F18 -> 0.015570292 | R18: =Q18/$F18 -> 0 | S18: =SUM(O18+Q18) -> 149015.17 | T18: =S18/F18 -> 0.015570292 | U18: 922765.74 | V18: =U18/F18 -> 0.096417916 | W18: 230490.71 | X18: =W18/F18 -> 0.024083506 | Y18: 730263.05 | Z18: =Y18/F18 -> 0.076303701 | AA18: 1217729 | AB18: =AA18/$F18 -> 0.12723802 | AC18: =SUM(Y18+AA18) -> 1947992 | AD18: =AC18/F18 -> 0.20354173 | AE18: 1830222.1 | AF18: =AE18/F18 -> 0.19123618 | AG18: 757703.6 | AH18: =AG18/F18 -> 0.079170909 | AI18: 1633188 | AJ18: =AI18/F18 -> 0.1706485 | AK18: 713763.81 | AL18: =AK18/F18 -> 0.07457973
D19: =D18+1 -> 46216 | E19: 一 | F19: =SUM(M19,S19,U19,W19,AC19,AE19,AG19,AI19,AK19) -> 9554533 | I19: 529486.83 | J19: =I19/F19 -> 0.055417343 | K19: 814268.37 | L19: =K19/F19 -> 0.085223252 | M19: =SUM(I19+K19) -> 1343755.2 | N19: =M19/F19 -> 0.14064059 | O19: 143809.3 | P19: =O19/F19 -> 0.015051421 | R19: =Q19/$F19 -> 0 | S19: =SUM(O19+Q19) -> 143809.3 | T19: =S19/F19 -> 0.015051421 | U19: 962800.35 | V19: =U19/F19 -> 0.10076896 | W19: 199074.14 | X19: =W19/F19 -> 0.02083557 | Y19: 763056.3 | Z19: =Y19/F19 -> 0.079863275 | AA19: 1498349.2 | AB19: =AA19/$F19 -> 0.15682076 | AC19: =SUM(Y19+AA19) -> 2261405.5 | AD19: =AC19/F19 -> 0.23668404 | AE19: 1661603 | AF19: =AE19/F19 -> 0.1739073 | AG19: 759555.4 | AH19: =AG19/F19 -> 0.079496863 | AI19: 1428891.9 | AJ19: =AI19/F19 -> 0.1495512 | AK19: 793638.19 | AL19: =AK19/F19 -> 0.083064049
... D37: =D36+1 -> 46234 | E37: 五 | F37: =SUM(M37,S37,U37,W37,AC37,AE37,AG37,AI37,AK37) -> 7084934 | I37: 481892.85 | J37: =I37/F37 -> 0.068016561 | K37: 635062.51 | L37: =K37/F37 -> 0.089635629 | M37: =SUM(I37+K37) -> 1116955.4 | N37: =M37/F37 -> 0.15765219 | O37: 179741.44 | P37: =O37/F37 -> 0.025369529 | R37: =Q37/$F37 -> 0 | S37: =SUM(O37+Q37) -> 179741.44 | T37: =S37/F37 -> 0.025369529 | U37: 777229.12 | V37: =U37/F37 -> 0.10970167 | W37: 68175.969 | X37: =W37/F37 -> 0.0096226681 | Y37: 545390.3 | Z37: =Y37/F37 -> 0.076978882 | AA37: 961827.26 | AB37: =AA37/$F37 -> 0.1357567 | AC37: =SUM(Y37+AA37) -> 1507217.6 | AD37: =AC37/F37 -> 0.21273558 | AE37: 1019224 | AF37: =AE37/F37 -> 0.14385793 | AG37: 668505.43 | AH37: =AG37/F37 -> 0.094355915 | AI37: 1151947.4 | AJ37: =AI37/F37 -> 0.16259112 | AK37: 595937.81 | AL37: =AK37/F37 -> 0.084113389
J38: =I38/F38 -> #DIV/0! | L38: =K38/F38 -> #DIV/0! | M38: =SUM(I38+K38) -> 0 | N38: =M38/F38 -> #DIV/0! | P38: =O38/F38 -> #DIV/0! | R38: =Q38/$F38 -> #DIV/0! | S38: =SUM(O38+Q38) -> 0 | T38: =S38/F38 -> #DIV/0! | V38: =U38/F38 -> #DIV/0! | X38: =W38/F38 -> #DIV/0! | Z38: =Y38/F38 -> #DIV/0! | AB38: =AA38/$F38 -> #DIV/0! | AC38: =SUM(Y38+AA38) -> 0 | AD38: =AC38/F38 -> #DIV/0! | AF38: =AE38/F38 -> #DIV/0! | AH38: =AG38/F38 -> #DIV/0! | AJ38: =AI38/F38 -> #DIV/0! | AL38: =AK38/F38 -> #DIV/0!
J39: =I39/F39 -> #DIV/0! | L39: =K39/F39 -> #DIV/0! | M39: =SUM(I39+K39) -> 0 | N39: =M39/F39 -> #DIV/0! | P39: =O39/F39 -> #DIV/0! | R39: =Q39/$F39 -> #DIV/0! | S39: =SUM(O39+Q39) -> 0 | T39: =S39/F39 -> #DIV/0! | V39: =U39/F39 -> #DIV/0! | X39: =W39/F39 -> #DIV/0! | Z39: =Y39/F39 -> #DIV/0! | AB39: =AA39/$F39 -> #DIV/0! | AC39: =SUM(Y39+AA39) -> 0 | AD39: =AC39/F39 -> #DIV/0! | AF39: =AE39/F39 -> #DIV/0! | AH39: =AG39/F39 -> #DIV/0! | AJ39: =AI39/F39 -> #DIV/0! | AL39: =AK39/F39 -> #DIV/0!
J40: =I40/F40 -> #DIV/0! | L40: =K40/F40 -> #DIV/0! | M40: =SUM(I40+K40) -> 0 | N40: =M40/F40 -> #DIV/0! | P40: =O40/F40 -> #DIV/0! | R40: =Q40/$F40 -> #DIV/0! | S40: =SUM(O40+Q40) -> 0 | T40: =S40/F40 -> #DIV/0! | V40: =U40/F40 -> #DIV/0! | X40: =W40/F40 -> #DIV/0! | Z40: =Y40/F40 -> #DIV/0! | AB40: =AA40/$F40 -> #DIV/0! | AC40: =SUM(Y40+AA40) -> 0 | AD40: =AC40/F40 -> #DIV/0! | AF40: =AE40/F40 -> #DIV/0! | AH40: =AG40/F40 -> #DIV/0! | AJ40: =AI40/F40 -> #DIV/0! | AL40: =AK40/F40 -> #DIV/0!
J41: =I41/F41 -> #DIV/0! | L41: =K41/F41 -> #DIV/0! | M41: =SUM(I41+K41) -> 0 | N41: =M41/F41 -> #DIV/0! | P41: =O41/F41 -> #DIV/0! | R41: =Q41/$F41 -> #DIV/0! | S41: =SUM(O41+Q41) -> 0 | T41: =S41/F41 -> #DIV/0! | V41: =U41/F41 -> #DIV/0! | X41: =W41/F41 -> #DIV/0! | Z41: =Y41/F41 -> #DIV/0! | AB41: =AA41/$F41 -> #DIV/0! | AC41: =SUM(Y41+AA41) -> 0 | AD41: =AC41/F41 -> #DIV/0! | AF41: =AE41/F41 -> #DIV/0! | AH41: =AG41/F41 -> #DIV/0! | AJ41: =AI41/F41 -> #DIV/0! | AL41: =AK41/F41 -> #DIV/0!
J42: =I42/F42 -> #DIV/0! | L42: =K42/F42 -> #DIV/0! | M42: =SUM(I42+K42) -> 0 | N42: =M42/F42 -> #DIV/0! | P42: =O42/F42 -> #DIV/0! | R42: =Q42/$F42 -> #DIV/0! | S42: =SUM(O42+Q42) -> 0 | T42: =S42/F42 -> #DIV/0! | V42: =U42/F42 -> #DIV/0! | X42: =W42/F42 -> #DIV/0! | Z42: =Y42/F42 -> #DIV/0! | AB42: =AA42/$F42 -> #DIV/0! | AC42: =SUM(Y42+AA42) -> 0 | AD42: =AC42/F42 -> #DIV/0! | AF42: =AE42/F42 -> #DIV/0! | AH42: =AG42/F42 -> #DIV/0! | AJ42: =AI42/F42 -> #DIV/0! | AL42: =AK42/F42 -> #DIV/0!
J43: =I43/F43 -> #DIV/0! | L43: =K43/F43 -> #DIV/0! | M43: =SUM(I43+K43) -> 0 | N43: =M43/F43 -> #DIV/0! | P43: =O43/F43 -> #DIV/0! | R43: =Q43/$F43 -> #DIV/0! | S43: =SUM(O43+Q43) -> 0 | T43: =S43/F43 -> #DIV/0! | V43: =U43/F43 -> #DIV/0! | X43: =W43/F43 -> #DIV/0! | Z43: =Y43/F43 -> #DIV/0! | AB43: =AA43/$F43 -> #DIV/0! | AC43: =SUM(Y43+AA43) -> 0 | AD43: =AC43/F43 -> #DIV/0! | AF43: =AE43/F43 -> #DIV/0! | AH43: =AG43/F43 -> #DIV/0! | AJ43: =AI43/F43 -> #DIV/0! | AL43: =AK43/F43 -> #DIV/0!
J44: =I44/F44 -> #DIV/0! | L44: =K44/F44 -> #DIV/0! | M44: =SUM(I44+K44) -> 0 | N44: =M44/F44 -> #DIV/0! | P44: =O44/F44 -> #DIV/0! | R44: =Q44/$F44 -> #DIV/0! | S44: =SUM(O44+Q44) -> 0 | T44: =S44/F44 -> #DIV/0! | V44: =U44/F44 -> #DIV/0! | X44: =W44/F44 -> #DIV/0! | Z44: =Y44/F44 -> #DIV/0! | AB44: =AA44/$F44 -> #DIV/0! | AC44: =SUM(Y44+AA44) -> 0 | AD44: =AC44/F44 -> #DIV/0! | AF44: =AE44/F44 -> #DIV/0! | AH44: =AG44/F44 -> #DIV/0! | AJ44: =AI44/F44 -> #DIV/0! | AL44: =AK44/F44 -> #DIV/0!
J45: =I45/F45 -> #DIV/0! | L45: =K45/F45 -> #DIV/0! | M45: =SUM(I45+K45) -> 0 | N45: =M45/F45 -> #DIV/0! | P45: =O45/F45 -> #DIV/0! | R45: =Q45/$F45 -> #DIV/0! | S45: =SUM(O45+Q45) -> 0 | T45: =S45/F45 -> #DIV/0! | V45: =U45/F45 -> #DIV/0! | X45: =W45/F45 -> #DIV/0! | Z45: =Y45/F45 -> #DIV/0! | AB45: =AA45/$F45 -> #DIV/0! | AC45: =SUM(Y45+AA45) -> 0 | AD45: =AC45/F45 -> #DIV/0! | AF45: =AE45/F45 -> #DIV/0! | AH45: =AG45/F45 -> #DIV/0! | AJ45: =AI45/F45 -> #DIV/0! | AL45: =AK45/F45 -> #DIV/0!
I46: =SUM(I7:I45) -> 17316600 | J46: =I46/$H$7 -> 0.065661752 | K46: =SUM(K7:K45) -> 23973853 | L46: =K46/$H$7 -> 0.090904983 | M46: =SUM(M7:M45) -> 41290454 | N46: =M46/$H$7 -> 0.15656673 | O46: =SUM(O7:O45) -> 5040458.8 | P46: =O46/$H$7 -> 0.019112606 | Q46: =SUM(Q7:Q45) -> 0 | R46: =Q46/$H$7 -> 0 | S46: =SUM(S7:S45) -> 5040458.8 | T46: =S46/$H$7 -> 0.019112606 | U46: =SUM(U7:U45) -> 28134506 | V46: =U46/$H$7 -> 0.10668151 | W46: =SUM(W7:W45) -> 3984301.7 | X46: =W46/$H$7 -> 0.015107829 | Y46: =SUM(Y7:Y45) -> 20387439 | Z46: =Y46/$H$7 -> 0.077305877 | AA46: =SUM(AA7:AA45) -> 35897681 | AB46: =AA46/$H$7 -> 0.13611821 | AC46: =SUM(AC7:AC45) -> 56285119 | AD46: =AC46/$H$7 -> 0.21342409 | AE46: =SUM(AE7:AE45) -> 42995922 | AF46: =AE46/$H$7 -> 0.1630336 | AG46: =SUM(AG7:AG45) -> 22151653 | AH46: =AG46/$H$7 -> 0.083995491 | AI46: =SUM(AI7:AI45) -> 41622926 | AJ46: =AI46/$H$7 -> 0.15782742 | AK46: =SUM(AK7:AK45) -> 22218965 | AL46: =AK46/$H$7 -> 0.08425073
M47: =M46 -> 41290454 | S47: =S46 -> 5040458.8 | U47: =U46 -> 28134506 | W47: =W46 -> 3984301.7 | AC47: =AC46 -> 56285119 | AE47: =AE46 -> 42995922 | AG47: =AG46 -> 22151653 | AI47: =AI46 -> 41622926 | AK47: =AK46 -> 22218965

Sheet （４）訂單數量構成比
B2: （4）訂單數量構成比
C3: 月份 | D3: 日期 | F3: 訂單量 | I3: 品類訂單量
I4: 18℃-飯糰 | O4: 18℃-壽司手卷 | U4: 4℃-飯糰 | W4: 4℃-壽司手卷 | Y4: 主食 | AE4: 便當 | AG4: 熱食義麵 | AI4: 季節調理麵 | AK4: 微波小吃
F5: 日 | G5: 週累積 | H5: 月累積 | I5: 一配 | K5: 二配 | M5: 合計 | O5: 一配 | Q5: 二配 | S5: 合計 | U5: 一配 | W5: 一配 | Y5: 一配 | AA5: 二配 | AC5: 合計 | AE5: 一配 | AG5: 一配 | AI5: 一配 | AK5: 一配
I6: 訂單數 | J6: 比例(%) | K6: 訂單數 | L6: 比例(%) | M6: 訂單數 | N6: 比例(%) | O6: 訂單數 | P6: 比例(%) | Q6: 訂單數 | R6: 比例(%) | S6: 訂單數 | T6: 比例(%) | U6: 訂單數 | V6: 比例(%) | W6: 訂單數 | X6: 比例(%) | Y6: 訂單數 | Z6: 比例(%) | AA6: 訂單數 | AB6: 比例(%) | AC6: 訂單數 | AD6: 比例(%) | AE6: 訂單數 | AF6: 比例(%) | AG6: 訂單數 | AH6: 比例(%) | AI6: 訂單數 | AJ6: 比例(%) | AK6: 訂單數 | AL6: 比例(%)
D7: 46204 | E7: 三 | F7: =SUM(M7,S7,U7,W7,AC7,AE7,AG7,AI7,AK7) -> 266041 | H7: =SUM($F$7:$F$37) -> 7772845 | I7: 30799 | J7: =I7/F7 -> 0.11576787 | K7: 48363 | L7: =K7/F7 -> 0.18178777 | M7: =SUM(I7+K7) -> 79162 | N7: =M7/F7 -> 0.29755564 | O7: 5051 | P7: =O7/F7 -> 0.018985795 | R7: =Q7/F7 -> 0 | S7: =SUM(O7+Q7) -> 5051 | T7: =S7/F7 -> 0.018985795 | U7: 31085 | V7: =U7/F7 -> 0.11684289 | W7: 4955 | X7: =W7/F7 -> 0.018624949 | Y7: 24565 | Z7: =Y7/F7 -> 0.092335392 | AA7: 20001 | AB7: =AA7/F7 -> 0.075180141 | AC7: =SUM(Y7+AA7) -> 44566 | AD7: =AC7/F7 -> 0.16751553 | AE7: 23645 | AF7: =AE7/F7 -> 0.088877278 | AG7: 15204 | AH7: =AG7/F7 -> 0.057149086 | AI7: 36664 | AJ7: =AI7/F7 -> 0.13781334 | AK7: 25709 | AL7: =AK7/F7 -> 0.096635481
D8: =D7+1 -> 46205 | E8: 四 | F8: =SUM(M8,S8,U8,W8,AC8,AE8,AG8,AI8,AK8) -> 250642 | I8: 30282 | J8: =I8/F8 -> 0.12081774 | K8: 45042 | L8: =K8/F8 -> 0.17970651 | M8: =SUM(I8+K8) -> 75324 | N8: =M8/F8 -> 0.30052425 | O8: 5158 | P8: =O8/F8 -> 0.020579153 | R8: =Q8/F8 -> 0 | S8: =SUM(O8+Q8) -> 5158 | T8: =S8/F8 -> 0.020579153 | U8: 28211 | V8: =U8/F8 -> 0.11255496 | W8: 4424 | X8: =W8/F8 -> 0.017650673 | Y8: 23481 | Z8: =Y8/F8 -> 0.093683421 | AA8: 16614 | AB8: =AA8/F8 -> 0.066285778 | AC8: =SUM(Y8+AA8) -> 40095 | AD8: =AC8/F8 -> 0.1599692 | AE8: 21867 | AF8: =AE8/F8 -> 0.087243958 | AG8: 13965 | AH8: =AG8/F8 -> 0.055716919 | AI8: 36867 | AJ8: =AI8/F8 -> 0.14709027 | AK8: 24731 | AL8: =AK8/F8 -> 0.098670614
D9: =D8+1 -> 46206 | E9: 五 | F9: =SUM(M9,S9,U9,W9,AC9,AE9,AG9,AI9,AK9) -> 225060 | I9: 26488 | J9: =I9/F9 -> 0.11769306 | K9: 41510 | L9: =K9/F9 -> 0.1844397 | M9: =SUM(I9+K9) -> 67998 | N9: =M9/F9 -> 0.30213276 | O9: 4366 | P9: =O9/F9 -> 0.019399271 | R9: =Q9/F9 -> 0 | S9: =SUM(O9+Q9) -> 4366 | T9: =S9/F9 -> 0.019399271 | U9: 24706 | V9: =U9/F9 -> 0.10977517 | W9: 3552 | X9: =W9/F9 -> 0.015782458 | Y9: 21695 | Z9: =Y9/F9 -> 0.096396516 | AA9: 18698 | AB9: =AA9/F9 -> 0.083080068 | AC9: =SUM(Y9+AA9) -> 40393 | AD9: =AC9/F9 -> 0.17947658 | AE9: 17683 | AF9: =AE9/F9 -> 0.078570159 | AG9: 10006 | AH9: =AG9/F9 -> 0.044459255 | AI9: 35581 | AJ9: =AI9/F9 -> 0.15809562 | AK9: 20775 | AL9: =AK9/F9 -> 0.092308718
D10: =D9+1 -> 46207 | E10: 六 | F10: =SUM(M10,S10,U10,W10,AC10,AE10,AG10,AI10,AK10) -> 244678 | I10: 25810 | J10: =I10/F10 -> 0.10548558 | K10: 43807 | L10: =K10/F10 -> 0.17903939 | M10: =SUM(I10+K10) -> 69617 | N10: =M10/F10 -> 0.28452497 | O10: 4139 | P10: =O10/F10 -> 0.01691611 | R10: =Q10/F10 -> 0 | S10: =SUM(O10+Q10) -> 4139 | T10: =S10/F10 -> 0.01691611 | U10: 28764 | V10: =U10/F10 -> 0.11755859 | W10: 4242 | X10: =W10/F10 -> 0.017337072 | Y10: 20098 | Z10: =Y10/F10 -> 0.082140609 | AA10: 20867 | AB10: =AA10/F10 -> 0.085283515 | AC10: =SUM(Y10+AA10) -> 40965 | AD10: =AC10/F10 -> 0.16742412 | AE10: 21388 | AF10: =AE10/F10 -> 0.087412845 | AG10: 12423 | AH10: =AG10/F10 -> 0.050772852 | AI10: 39278 | AJ10: =AI10/F10 -> 0.16052935 | AK10: 23862 | AL10: =AK10/F10 -> 0.097524093
D11: =D10+1 -> 46208 | E11: 日 | F11: =SUM(M11,S11,U11,W11,AC11,AE11,AG11,AI11,AK11) -> 275484 | I11: 31053 | J11: =I11/F11 -> 0.11272161 | K11: 47550 | L11: =K11/F11 -> 0.17260531 | M11: =SUM(I11+K11) -> 78603 | N11: =M11/F11 -> 0.28532692 | O11: 5189 | P11: =O11/F11 -> 0.01883594 | R11: =Q11/F11 -> 0 | S11: =SUM(O11+Q11) -> 5189 | T11: =S11/F11 -> 0.01883594 | U11: 34498 | V11: =U11/F11 -> 0.12522687 | W11: 5164 | X11: =W11/F11 -> 0.01874519 | Y11: 23893 | Z11: =Y11/F11 -> 0.08673099 | AA11: 21595 | AB11: =AA11/F11 -> 0.078389308 | AC11: =SUM(Y11+AA11) -> 45488 | AD11: =AC11/F11 -> 0.1651203 | AE11: 25274 | AF11: =AE11/F11 -> 0.091743985 | AG11: 15287 | AH11: =AG11/F11 -> 0.055491426 | AI11: 40194 | AJ11: =AI11/F11 -> 0.14590321 | AK11: 25787 | AL11: =AK11/F11 -> 0.093606162
D12: =D11+1 -> 46209 | E12: 一 | F12: =SUM(M12,S12,U12,W12,AC12,AE12,AG12,AI12,AK12) -> 277705 | I12: 30810 | J12: =I12/F12 -> 0.11094507 | K12: 46954 | L12: =K12/F12 -> 0.1690787 | M12: =SUM(I12+K12) -> 77764 | N12: =M12/F12 -> 0.28002377 | O12: 5140 | P12: =O12/F12 -> 0.018508849 | R12: =Q12/F12 -> 0 | S12: =SUM(O12+Q12) -> 5140 | T12: =S12/F12 -> 0.018508849 | U12: 34501 | V12: =U12/F12 -> 0.12423615 | W12: 3744 | X12: =W12/F12 -> 0.013481932 | Y12: 24268 | Z12: =Y12/F12 -> 0.087387696 | AA12: 25885 | AB12: =AA12/F12 -> 0.093210421 | AC12: =SUM(Y12+AA12) -> 50153 | AD12: =AC12/F12 -> 0.18059812 | AE12: 23823 | AF12: =AE12/F12 -> 0.085785276 | AG12: 15413 | AH12: =AG12/F12 -> 0.055501341 | AI12: 39832 | AJ12: =AI12/F12 -> 0.14343278 | AK12: 27335 | AL12: =AK12/F12 -> 0.098431789
D13: =D12+1 -> 46210 | E13: 二 | F13: =SUM(M13,S13,U13,W13,AC13,AE13,AG13,AI13,AK13) -> 299940 | I13: 31385 | J13: =I13/F13 -> 0.10463759 | K13: 46625 | L13: =K13/F13 -> 0.15544776 | M13: =SUM(I13+K13) -> 78010 | N13: =M13/F13 -> 0.26008535 | O13: 5185 | P13: =O13/F13 -> 0.017286791 | R13: =Q13/F13 -> 0 | S13: =SUM(O13+Q13) -> 5185 | T13: =S13/F13 -> 0.017286791 | U13: 33107 | V13: =U13/F13 -> 0.11037874 | W13: 11009 | X13: =W13/F13 -> 0.036704007 | Y13: 24596 | Z13: =Y13/F13 -> 0.082003067 | AA13: 24316 | AB13: =AA13/F13 -> 0.081069547 | AC13: =SUM(Y13+AA13) -> 48912 | AD13: =AC13/F13 -> 0.16307261 | AE13: 31543 | AF13: =AE13/F13 -> 0.10516437 | AG13: 14226 | AH13: =AG13/F13 -> 0.047429486 | AI13: 50502 | AJ13: =AI13/F13 -> 0.16837367 | AK13: 27446 | AL13: =AK13/F13 -> 0.091504968
D14: =D13+1 -> 46211 | E14: 三 | F14: =SUM(M14,S14,U14,W14,AC14,AE14,AG14,AI14,AK14) -> 281251 | I14: 30846 | J14: =I14/F14 -> 0.10967428 | K14: 45332 | L14: =K14/F14 -> 0.16117987 | M14: =SUM(I14+K14) -> 76178 | N14: =M14/F14 -> 0.27085415 | O14: 5180 | P14: =O14/F14 -> 0.018417712 | R14: =Q14/F14 -> 0 | S14: =SUM(O14+Q14) -> 5180 | T14: =S14/F14 -> 0.018417712 | U14: 29243 | V14: =U14/F14 -> 0.10397474 | W14: 7605 | X14: =W14/F14 -> 0.027039904 | Y14: 24759 | Z14: =Y14/F14 -> 0.088031687 | AA14: 23840 | AB14: =AA14/F14 -> 0.084764143 | AC14: =SUM(Y14+AA14) -> 48599 | AD14: =AC14/F14 -> 0.17279583 | AE14: 27372 | AF14: =AE14/F14 -> 0.097322321 | AG14: 13493 | AH14: =AG14/F14 -> 0.047974941 | AI14: 46093 | AJ14: =AI14/F14 -> 0.16388564 | AK14: 27488 | AL14: =AK14/F14 -> 0.097734764
D15: =D14+1 -> 46212 | E15: 四 | F15: =SUM(M15,S15,U15,W15,AC15,AE15,AG15,AI15,AK15) -> 269872 | I15: 29074 | J15: =I15/F15 -> 0.10773255 | K15: 41191 | L15: =K15/F15 -> 0.15263162 | M15: =SUM(I15+K15) -> 70265 | N15: =M15/F15 -> 0.26036417 | O15: 5078 | P15: =O15/F15 -> 0.018816328 | R15: =Q15/F15 -> 0 | S15: =SUM(O15+Q15) -> 5078 | T15: =S15/F15 -> 0.018816328 | U15: 26242 | V15: =U15/F15 -> 0.097238691 | W15: 7555 | X15: =W15/F15 -> 0.027994753 | Y15: 26089 | Z15: =Y15/F15 -> 0.096671755 | AA15: 20289 | AB15: =AA15/F15 -> 0.075180085 | AC15: =SUM(Y15+AA15) -> 46378 | AD15: =AC15/F15 -> 0.17185184 | AE15: 26647 | AF15: =AE15/F15 -> 0.098739402 | AG15: 15152 | AH15: =AG15/F15 -> 0.056145135 | AI15: 43111 | AJ15: =AI15/F15 -> 0.1597461 | AK15: 29444 | AL15: =AK15/F15 -> 0.10910358
D16: =D15+1 -> 46213 | E16: 五 | F16: =SUM(M16,S16,U16,W16,AC16,AE16,AG16,AI16,AK16) -> 221106 | I16: 24363 | J16: =I16/F16 -> 0.11018697 | K16: 37252 | L16: =K16/F16 -> 0.16848028 | M16: =SUM(I16+K16) -> 61615 | N16: =M16/F16 -> 0.27866725 | O16: 4218 | P16: =O16/F16 -> 0.019076823 | R16: =Q16/F16 -> 0 | S16: =SUM(O16+Q16) -> 4218 | T16: =S16/F16 -> 0.019076823 | U16: 22465 | V16: =U16/F16 -> 0.10160285 | W16: 3234 | X16: =W16/F16 -> 0.014626469 | Y16: 23399 | Z16: =Y16/F16 -> 0.10582707 | AA16: 18132 | AB16: =AA16/F16 -> 0.082005916 | AC16: =SUM(Y16+AA16) -> 41531 | AD16: =AC16/F16 -> 0.18783299 | AE16: 21121 | AF16: =AE16/F16 -> 0.095524319 | AG16: 10563 | AH16: =AG16/F16 -> 0.047773466 | AI16: 35531 | AJ16: =AI16/F16 -> 0.16069668 | AK16: 20828 | AL16: =AK16/F16 -> 0.094199162
D17: =D16+1 -> 46214 | E17: 六 | F17: =SUM(M17,S17,U17,W17,AC17,AE17,AG17,AI17,AK17) -> 233330 | I17: 23194 | J17: =I17/F17 -> 0.099404277 | K17: 40889 | L17: =K17/F17 -> 0.17524107 | M17: =SUM(I17+K17) -> 64083 | N17: =M17/F17 -> 0.27464535 | O17: 3957 | P17: =O17/F17 -> 0.016958814 | R17: =Q17/F17 -> 0 | S17: =SUM(O17+Q17) -> 3957 | T17: =S17/F17 -> 0.016958814 | U17: 21974 | V17: =U17/F17 -> 0.094175631 | W17: 4725 | X17: =W17/F17 -> 0.020250289 | Y17: 23874 | Z17: =Y17/F17 -> 0.1023186 | AA17: 19591 | AB17: =AA17/F17 -> 0.083962628 | AC17: =SUM(Y17+AA17) -> 43465 | AD17: =AC17/F17 -> 0.18628123 | AE17: 23515 | AF17: =AE17/F17 -> 0.10078001 | AG17: 12094 | AH17: =AG17/F17 -> 0.051832169 | AI17: 38679 | AJ17: =AI17/F17 -> 0.16576951 | AK17: 20838 | AL17: =AK17/F17 -> 0.08930699
D18: =D17+1 -> 46215 | E18: 日 | F18: =SUM(M18,S18,U18,W18,AC18,AE18,AG18,AI18,AK18) -> 277272 | I18: 29004 | J18: =I18/F18 -> 0.10460486 | K18: 44094 | L18: =K18/F18 -> 0.15902796 | M18: =SUM(I18+K18) -> 73098 | N18: =M18/F18 -> 0.26363282 | O18: 5159 | P18: =O18/F18 -> 0.018606278 | R18: =Q18/F18 -> 0 | S18: =SUM(O18+Q18) -> 5159 | T18: =S18/F18 -> 0.018606278 | U18: 27419 | V18: =U18/F18 -> 0.098888456 | W18: 7599 | X18: =W18/F18 -> 0.027406301 | Y18: 27686 | Z18: =Y18/F18 -> 0.099851409 | AA18: 23091 | AB18: =AA18/F18 -> 0.083279235 | AC18: =SUM(Y18+AA18) -> 50777 | AD18: =AC18/F18 -> 0.18313064 | AE18: 31015 | AF18: =AE18/F18 -> 0.11185767 | AG18: 15442 | AH18: =AG18/F18 -> 0.055692605 | AI18: 42764 | AJ18: =AI18/F18 -> 0.15423122 | AK18: 23999 | AL18: =AK18/F18 -> 0.086553998
D19: =D18+1 -> 46216 | E19: 一 | F19: =SUM(M19,S19,U19,W19,AC19,AE19,AG19,AI19,AK19) -> 274460 | I19: 28132 | J19: =I19/F19 -> 0.10249945 | K19: 42677 | L19: =K19/F19 -> 0.15549443 | M19: =SUM(I19+K19) -> 70809 | N19: =M19/F19 -> 0.25799388 | O19: 4976 | P19: =O19/F19 -> 0.018130146 | R19: =Q19/F19 -> 0 | S19: =SUM(O19+Q19) -> 4976 | T19: =S19/F19 -> 0.018130146 | U19: 28620 | V19: =U19/F19 -> 0.10427749 | W19: 6824 | X19: =W19/F19 -> 0.024863368 | Y19: 27054 | Z19: =Y19/F19 -> 0.098571741 | AA19: 28320 | AB19: =AA19/F19 -> 0.10318443 | AC19: =SUM(Y19+AA19) -> 55374 | AD19: =AC19/F19 -> 0.20175618 | AE19: 28265 | AF19: =AE19/F19 -> 0.10298404 | AG19: 15507 | AH19: =AG19/F19 -> 0.056500036 | AI19: 37505 | AJ19: =AI19/F19 -> 0.13665015 | AK19: 26580 | AL19: =AK19/F19 -> 0.096844713
... D37: =D36+1 -> 46234 | E37: 五 | F37: =SUM(M37,S37,U37,W37,AC37,AE37,AG37,AI37,AK37) -> 211184 | I37: 24286 | J37: =I37/F37 -> 0.11499924 | K37: 33754 | L37: =K37/F37 -> 0.15983218 | M37: =SUM(I37+K37) -> 58040 | N37: =M37/F37 -> 0.27483143 | O37: 6143 | P37: =O37/F37 -> 0.029088378 | R37: =Q37/F37 -> 0 | S37: =SUM(O37+Q37) -> 6143 | T37: =S37/F37 -> 0.029088378 | U37: 23700 | V37: =U37/F37 -> 0.11222441 | W37: 2220 | X37: =W37/F37 -> 0.01051216 | Y37: 22188 | Z37: =Y37/F37 -> 0.10506478 | AA37: 18084 | AB37: =AA37/F37 -> 0.085631487 | AC37: =SUM(Y37+AA37) -> 40272 | AD37: =AC37/F37 -> 0.19069626 | AE37: 17553 | AF37: =AE37/F37 -> 0.083117092 | AG37: 13238 | AH37: =AG37/F37 -> 0.062684673 | AI37: 29849 | AJ37: =AI37/F37 -> 0.1413412 | AK37: 20169 | AL37: =AK37/F37 -> 0.095504394
I46: =SUM(I7:I45) -> 885235 | J46: =I46/$H$7 -> 0.11388816 | K46: =SUM(K7:K45) -> 1261291 | L46: =K46/$H$7 -> 0.1622689 | M46: =SUM(M7:M45) -> 2146526 | N46: =M46/$H$7 -> 0.27615706 | O46: =SUM(O7:O45) -> 173357 | P46: =O46/$H$7 -> 0.022302902 | Q46: =SUM(Q7:Q45) -> 0 | R46: =Q46/$H$7 -> 0 | S46: =SUM(S7:S45) -> 173357 | T46: =S46/$H$7 -> 0.022302902 | U46: =SUM(U7:U45) -> 858013 | V46: =U46/$H$7 -> 0.11038597 | W46: =SUM(W7:W45) -> 142429 | X46: =W46/$H$7 -> 0.018323921 | Y46: =SUM(Y7:Y45) -> 756326 | Z46: =Y46/$H$7 -> 0.097303626 | AA46: =SUM(AA7:AA45) -> 676516 | AB46: =AA46/$H$7 -> 0.087035828 | AC46: =SUM(AC7:AC45) -> 1432842 | AD46: =AC46/$H$7 -> 0.18433945 | AE46: =SUM(AE7:AE45) -> 734871 | AF46: =AE46/$H$7 -> 0.094543375 | AG46: =SUM(AG7:AG45) -> 447236 | AH46: =AG46/$H$7 -> 0.057538263 | AI46: =SUM(AI7:AI45) -> 1087177 | AJ46: =AI46/$H$7 -> 0.13986861 | AK46: =SUM(AK7:AK45) -> 750394 | AL46: =AK46/$H$7 -> 0.096540456
M47: =M46 -> 2146526 | S47: =S46 -> 173357 | U47: =U46 -> 858013 | W47: =W46 -> 142429 | AC47: =AC46 -> 1432842 | AE47: =AE46 -> 734871 | AG47: =AG46 -> 447236 | AI47: =AI46 -> 1087177 | AK47: =AK46 -> 750394

Sheet （５-1）品群別人時生產性（18℃-飯糰）
B1: 月平均人時性 | C1: =AVERAGE(L7,L42,L77,L112,L147,L182) -> 792.17451
B2: 產線配置圖－每週更新 | N2: 資料繳交 | O2: 日期 | U2: 46204 | Z2: =U2+1 -> 46205 | AE2: =Z2+1 -> 46206 | AJ2: =AE2+1 -> 46207 | AO2: =AJ2+1 -> 46208 | AT2: =AO2+1 -> 46209
P3: 二 | U3: 三 | Z3: 四 | AE3: 五 | AJ3: 六 | AO3: 日 | AT3: 一
B4: 品群 | C4: 商品名稱 | E4: 計畫 | H4: 平均人時性 | I4: 實績 | L4: 平均人時性 | M4: 排名 | O4: 日報 | P4: 實際 | T4: 平均人時性 | U4: 實際 | Y4: 平均人時性 | Z4: 實際 | AD4: 平均人時性 | AE4: 實際 | AI4: 平均人時性 | AJ4: 實際 | AN4: 平均人時性 | AO4: 實際 | AS4: 平均人時性 | AT4: 實際 | AX4: 平均人時性
E5: 產線配置圖 | I5: 產線配置圖 | P5: 生產實績 | U5: 生產實績 | Z5: 生產實績 | AE5: 生產實績 | AJ5: 生產實績 | AO5: 生產實績 | AT5: 生產實績
E6: 人數 | F6: 產能／時 | G6: 人時性 | I6: 人數 | J6: 產能／時 | K6: 人時性 | P6: 人數 | Q6: 產能／時 | R6: 人時性 | S6: 排名 | U6: 人數 | V6: 產能／時 | W6: 人時性 | X6: 排名 | Z6: 人數 | AA6: 產能／時 | AB6: 人時性 | AC6: 排名 | AE6: 人數 | AF6: 產能／時 | AG6: 人時性 | AH6: 排名 | AJ6: 人數 | AK6: 產能／時 | AL6: 人時性 | AM6: 排名 | AO6: 人數 | AP6: 產能／時 | AQ6: 人時性 | AR6: 排名 | AT6: 人數 | AU6: 產能／時 | AV6: 人時性 | AW6: 排名
B7: 18℃-飯糰 | C7: 1 | D7: 經典肉鬆飯糰 | E7: 3 | F7: 3200 | G7: 1066.6667 | H7: =AVERAGE(G7:G36) -> 779.47531 | I7: =IFERROR(AVERAGE(P7,U7,Z7,AE7,AJ7,AO7,AT7),"-") -> 3 | J7: =IFERROR(AVERAGE(Q7,V7,AA7,AF7,AK7,AP7,AU7),"-") -> 3183.0634 | K7: =IFERROR(AVERAGE(R7,W7,AB7,AG7,AL7,AQ7,AV7),"-") -> 1061.0211 | L7: =IFERROR(AVERAGE(K7:K36),"-") -> 784.29241 | M7: 1 | U7: 3 | V7: 3176.6667 | W7: 1058.8889 | X7: 4 | Y7: 787.11647 | Z7: 3 | AA7: 3194.1818 | AB7: 1064.7273 | AC7: 1 | AD7: 785.90307 | AE7: 3 | AF7: 3195.3191 | AG7: 1065.1064 | AH7: 3 | AI7: 786.14849 | AJ7: 3 | AK7: 3190.2128 | AL7: 1063.4043 | AM7: 1 | AN7: 778.97211 | AO7: 3 | AP7: 3150 | AQ7: 1050 | AR7: 3 | AS7: 787.0862 | AT7: 3 | AU7: 3192 | AV7: 1064 | AW7: 3 | AX7: 780.52811 | AZ7: =RANK(AX7, $K$7:AX$36) -> #VALUE! | BB7: =RANK(BA7, BA$7:BA$36) -> #N/A
C8: 2 | D8: 蔬食鮪魚飯糰 | E8: 3 | F8: 3200 | G8: 1066.6667 | I8: =IFERROR(AVERAGE(P8,U8,Z8,AE8,AJ8,AO8,AT8),"-") -> 3 | J8: =IFERROR(AVERAGE(Q8,V8,AA8,AF8,AK8,AP8,AU8),"-") -> 3121.4709 | K8: =IFERROR(AVERAGE(R8,W8,AB8,AG8,AL8,AQ8,AV8),"-") -> 1040.4903 | M8: 5 | U8: 3 | V8: 3200 | W8: 1066.6667 | X8: 1 | Z8: 3 | AA8: 3133.3333 | AB8: 1044.4444 | AC8: 6 | AE8: 3 | AF8: 3021.1765 | AG8: 1007.0588 | AH8: 8 | AJ8: 3 | AK8: 3188 | AL8: 1062.6667 | AM8: 4 | AO8: 3 | AP8: 3110.5263 | AQ8: 1036.8421 | AR8: 7 | AT8: 3 | AU8: 3075.7895 | AV8: 1025.2632 | AW8: 8 | AZ8: =RANK(AX8, $K$7:AX$36) -> #VALUE! | BB8: =RANK(BA8, BA$7:BA$36) -> #N/A
