Workbook

Sheet 填寫舉例
A2: 7 | B2: 月別 | C2: 工廠名 | D2: ・・・・・・・・
A4: （１）收支狀況 | E4: ※單位：千元 | G4: （２）ＫＰＩ達成進度 | M4: （３）業績構成比 | S4: （４）訂單數量構成比
B5: 當月 | C5: 前月 | D5: 差異 | E5: 累計 | H5: KPI | I5: 當月 | J5: 前月 | K5: 累計 | L5: ※補充 | N5: 當月 | O5: 比例 | P5: 前月 | Q5: 差異 | T5: 當月 | U5: 比例 | V5: 前月 | W5: 差異
A6: 業績金額 | B6: 500000 | C6: 510000 | D6: =B6-C6 -> -10000 | E6: =B6+C6 -> 1010000 | G6: 人時生產性1 | H6: 110 | I6: 100 | J6: 90 | L6: 個／MH | M6: 飯糰 | N6: 150000 | O6: =IFERROR(N6/$B$6,"") -> 0.3 | P6: 0.4 | Q6: =IFERROR(O6-P6,"") -> -0.1 | S6: 飯糰 | T6: 35000 | U6: =IFERROR(T6/$B$7,"") -> 0.35 | V6: 0.3 | W6: =IFERROR(U6-V6,"") -> 0.05
A7: 訂單數量 | B7: 100000 | C7: 110000 | D7: =B7-C7 -> -10000 | E7: =B7+C7 -> 210000 | G7: 人時生產性2 | H7: 0.8 | I7: 0.85 | J7: 0.81 | K7: 0.84 | L7: 達成率 | M7: 大口飯糰 | N7: 100000 | O7: =IFERROR(N7/$B$6,"") -> 0.2 | P7: 0.15 | Q7: =IFERROR(O7-P7,"") -> 0.05 | S7: 大口飯糰 | T7: 30000 | U7: =IFERROR(T7/$B$7,"") -> 0.3 | V7: 0.15 | W7: =IFERROR(U7-V7,"") -> 0.15
A8: 材料費 | B8: 250000 | C8: 260000 | D8: =B8-C8 -> -10000 | E8: =B8+C8 -> 510000 | G8: 半成品報廢 | H8: 0.0025 | I8: 0.0024 | J8: 0.0023 | K8: 0.00235 | L8: 報廢率 | M8: 便當 | N8: 160000 | O8: =IFERROR(N8/$B$6,"") -> 0.32 | P8: 0.28 | Q8: =IFERROR(O8-P8,"") -> 0.04 | S8: 便當 | T8: 20000 | U8: =IFERROR(T8/$B$7,"") -> 0.2 | V8: 0.28 | W8: =IFERROR(U8-V8,"") -> -0.08
A9: 材料費率 | B9: =B8/B6 -> 0.5 | C9: =C8/C6 -> 0.50980392 | D9: =B9-C9 -> -0.0098039216 | E9: =(B9+C9)/2 -> 0.50490196 | G9: 半成品超用 | H9: 0.006 | I9: 0.009 | J9: 0.0095 | K9: 0.0092 | L9: 超用率 | M9: 調理麵 | N9: 90000 | O9: =IFERROR(N9/$B$6,"") -> 0.18 | P9: 0.17 | Q9: =IFERROR(O9-P9,"") -> 0.01 | S9: 調理麵 | T9: 15000 | U9: =IFERROR(T9/$B$7,"") -> 0.15 | V9: 0.27 | W9: =IFERROR(U9-V9,"") -> -0.12
A10: 勞務成本 | B10: 100000 | C10: 105000 | D10: =B10-C10 -> -5000 | E10: =B10+C10 -> 205000 | G10: 固定產線 | H10: 0.95 | I10: 0.9 | J10: 0.92 | K10: 0.91 | L10: 導入率 | M10: 調理麵包 | N10: - | O10: =IFERROR(N10/$B$6,"") | P10: -% | Q10: =IFERROR(O10-P10,"") | S10: 調理麵包 | T10: - | U10: =IFERROR(T10/$B$7,"") | V10: -% | W10: =IFERROR(U10-V10,"")
A11: 勞務費率 | B11: =B10/B6 -> 0.2 | C11: =C10/C6 -> 0.20588235 | D11: =B11-C11 -> -0.0058823529 | E11: =(B11+C11)/2 -> 0.20294118 | G11: 教育訓練 | H11: 0.8 | I11: 0.85 | J11: 1 | K11: 0.92 | L11: 實施率 | M11: 袋裝調理麵包 | N11: - | O11: =IFERROR(N11/$B$6,"") | P11: -% | Q11: =IFERROR(O11-P11,"") | S11: 袋裝調理麵包 | T11: - | U11: =IFERROR(T11/$B$7,"") | V11: -% | W11: =IFERROR(U11-V11,"")
M12: 義大利麵 | N12: - | O12: =IFERROR(N12/$B$6,"") | P12: -% | Q12: =IFERROR(O12-P12,"") | S12: 義大利麵 | T12: - | U12: =IFERROR(T12/$B$7,"") | V12: -% | W12: =IFERROR(U12-V12,"")
A13: （５）品群別人時生產性 | M13: 調理包 | N13: - | O13: =IFERROR(N13/$B$6,"") | P13: -% | Q13: =IFERROR(O13-P13,"") | S13: 調理包 | T13: - | U13: =IFERROR(T13/$B$7,"") | V13: -% | W13: =IFERROR(U13-V13,"")
B14: 當月 | C14: 前月 | D14: 差異 | E14: 累計 | H14: 當月 | I14: 前月 | J14: 差異 | K14: 累計 | O14: =SUM(O6:O13) -> 1 | P14: =SUM(P6:P13) -> 1 | U14: =SUM(U6:U13) -> 1 | V14: =SUM(V6:V13) -> 1
A15: 飯糰 | B15: 600 | C15: 660 | D15: =B15-C15 -> -60 | E15: =(B15+C15)/2 -> 630 | G15: 調理麵包 | J15: =H15-I15 -> 0 | M15: （７）原因別分析
A16: 大口飯糰 | B16: 800 | C16: 780 | D16: =B16-C16 -> 20 | E16: =(B16+C16)/2 -> 790 | G16: 袋裝調理麵包 | J16: =H16-I16 -> 0 | N16: 合計 | P16: 作業原因 | R16: 規格原因
A17: 便當 | B17: 130 | C17: 111 | D17: =B17-C17 -> 19 | E17: =(B17+C17)/2 -> 120.5 | G17: 義大利麵 | J17: =H17-I17 -> 0 | N17: 金額 | O17: 比例 | P17: 金額 | Q17: 比例 | R17: 金額 | S17: 比例
A18: 調理麵 | B18: 140 | C18: 165 | D18: =B18-C18 -> -25 | E18: =(B18+C18)/2 -> 152.5 | G18: 調理包 | J18: =H18-I18 -> 0 | M18: 半成品報廢 | N18: 1200 | O18: =N18/$B$6 -> 0.0024 | P18: 900 | Q18: =IFERROR(P18/$B$6,"") -> 0.0018 | R18: 300 | S18: =IFERROR(R18/$B$6,"") -> 0.0006
M19: 半成品超用 | N19: 4500 | O19: =N19/$B$6 -> 0.009 | P19: 3500 | Q19: =IFERROR(P19/$B$6,"") -> 0.007 | R19: 1000 | S19: =IFERROR(R19/$B$6,"") -> 0.002
A20: （６）人時生產性前幾名品項
B21: 排名 | C21: 商品名 | F21: 人數 | G21: 產能 | H21: 人時生產性 | I21: 前月比 | J21: 主要原因&對策 | M21: （８）報廢原因別前幾名品項
A22: 飯糰 | B22: 1 | C22: 手巻明太子 | F22: 3 | G22: 3000 | H22: 1000 | I22: 10 | J22: 減少暫時停止生產,人時UP | M22: 半成品報廢 | N22: 排名 | O22: 商品名 | R22: 半成品名 | U22: 單價 | V22: 報廢率 | W22: 數量 | X22: 金額 | Y22: 前月比 | Z22: 主要原因&對策
B23: 2 | M23: 作業原因 | N23: 1 | O23: 明太子海苔便當 | R23: 油炸白身魚 | U23: 10 | V23: 0.15 | W23: 10 | X23: =W23*U23 -> 100 | Y23: 80 | Z23: 油調過多報廢。變更條件。
B24: 3 | N24: 2 | X24: =W24*U24 -> 0
B25: 4 | N25: 3 | X25: =W25*U25 -> 0
B26: 5 | N26: 4 | X26: =W26*U26 -> 0
B27: ▼1 | C27: 手巻卵黄雞絞肉 | F27: 4 | G27: 2800 | H27: 700 | I27: 6/30新商品 | J27: 因組裝2食材,人員增加,產速減少 | N27: 5 | X27: =W27*U27 -> 0
B28: ▼2 | U28: 前幾名合計比例 | V28: =X28/N18 -> 0.083333333 | W28: 前幾名合計金額 | X28: =SUM(X23:X27) -> 100
B29: ▼3 | M29: 規格原因 | N29: 1 | O29: 海老炒飯 | R29: 川燙蝦子拌醬 | U29: 5.55 | V29: 0.21 | W29: 50 | X29: =W29*U29 -> 277.5 | Y29: 35 | Z29: 蝦子入數不足
B30: ▼4 | N30: 2 | X30: =W30*U30 -> 0
B31: ▼5 | N31: 3 | X31: =W31*U31 -> 0
N32: 4 | X32: =W32*U32 -> 0
B33: 排名 | C33: 商品名 | F33: 人數 | G33: 產能 | H33: 人時生產性 | I33: 前月比 | J33: 主要原因&對策 | N33: 5 | X33: =W33*U33 -> 0
A34: 大口飯糰 | B34: 1 | C34: 直巻明太子美奶茲 | F34: 3 | G34: 2500 | H34: 833.33 | I34: 20 | J34: 透由調整速度提升。 | U34: 前幾名合計比例 | V34: =X34/N18 -> 0.23125 | W34: 前幾名合計金額 | X34: =SUM(X29:X33) -> 277.5
B35: 2
B36: 3 | M36: 半成品超用 | N36: 排名 | O36: 商品名 | R36: 半成品名 | U36: 單價 | V36: 報廢率 | W36: 數量 | X36: 金額 | Y36: 前月比 | Z36: 主要原因&對策
B37: 4 | M37: 作業原因 | N37: 1 | O37: 特製醬汁炙燒牛五花便當 | R37: 牛五花醬汁 | U37: 25 | V37: 0.25 | W37: 10 | X37: =W37*U37 -> 250 | Y37: 150 | Z37: 難度有差異。調理指導。
B38: 5 | N38: 2 | X38: =W38*U38 -> 0
B39: ▼1 | C39: 大口飯糰燒肉美奶滋 | F39: 7 | G39: 2200 | H39: 314.29 | I39: -15 | J39: 因摺疊增員。實施教育訓練。 | N39: 3 | X39: =W39*U39 -> 0
B40: ▼2 | N40: 4 | X40: =W40*U40 -> 0
B41: ▼3 | N41: 5 | X41: =W41*U41 -> 0
B42: ▼4 | U42: 前幾名合計比例 | V42: =X42/N19 -> 0.055555556 | W42: 前幾名合計金額 | X42: =SUM(X37:X41) -> 250
...

Sheet 生產管理報表(月)
A1: 生產管理報表
A3: 月別 | B3: 9 | C3: 工廠 | D3: 晉欣廠
A4: （１）收支狀況 | E4: ※單位：千元 | G4: （２）ＫＰＩ達成進度
A5: 項目 | B5: 當月 | C5: 前月 | D5: 差異 | E5: 累計 | G5: 項目 | H5: KPI | I5: 當月 | J5: 前月 | K5: 累計 | L5: ※補充
A6: 業績金額 | B6: ='（１）收支狀況'!H5/1000 -> 0 | C6: 212376.15 | D6: =B6-C6 -> -212376.15 | E6: =B6 -> 0 | G6: 人時性(個/月均) | H6: 266 | I6: ='（２）ＫＰＩ達成進度'!H5 -> 0 | J6: 331.32088 | K6: =I6 -> 0 | L6: 個／MH
A7: 訂單數量 | B7: ='（４）訂單數量構成比'!H7 -> 0 | C7: 6558055 | D7: =B7-C7 -> -6558055 | E7: =B7 -> 0 | G7: 人時達成率(%/月均) | H7: 0.8 | I7: ='（２）ＫＰＩ達成進度'!K5 -> 0 | J7: 0.90524832 | K7: =I7 -> 0 | L7: 達成率
A8: 材料費 | B8: ='（１）收支狀況'!N5/1000 -> 0 | C8: 139088.16 | D8: =B8-C8 -> -139088.16 | E8: =B8 -> 0 | G8: 半成品-報廢(%) | H8: 0.0025 | I8: ='（２）ＫＰＩ達成進度'!N5 -> 0 | J8: 0.0024946244 | K8: =I8 -> 0 | L8: 報廢率
A9: 材料費率 | B9: ='（１）收支狀況'!Q5 -> 0 | C9: 0.65491423 | D9: =B9-C9 -> -0.65491423 | E9: =B9 -> 0 | G9: 半成品-超用(%) | H9: 0.0026 | I9: ='（２）ＫＰＩ達成進度'!Q5 -> 0 | J9: 0.0023789152 | K9: =I9 -> 0 | L9: 超用率
A10: 勞務成本 | B10: ='（１）收支狀況'!T5/1000 -> 0 | C10: 30146.177 | D10: =B10-C10 -> -30146.177 | E10: =B10 -> 0 | G10: 固定產線-導入率(%) | H10: 0.8 | I10: ='（２）ＫＰＩ達成進度'!T5 -> 0 | J10: 0.91666667 | K10: =I10 -> 0 | L10: 導入率
A11: 勞務費率 | B11: ='（１）收支狀況'!W5 -> 0 | C11: 0.14194709 | D11: =B11-C11 -> -0.14194709 | E11: =B11 -> 0 | G11: 教育訓練-實施率(%) | H11: 1 | I11: ='（２）ＫＰＩ達成進度'!W5 -> 0 | J11: 0.67912903 | K11: =I11 -> 0 | L11: 實施率
A13: （３）業績構成比 | G13: （４）訂單數量構成比
B14: 當月 | C14: 比例 | D14: 前月 | E14: 差異 | H14: 當月 | I14: 比例 | J14: 前月 | K14: 差異
A15: 18℃-飯A15:A23糰(061,063) | B15: ='（３）業績構成比'!M46/1000 -> 48691.663 | C15: =IFERROR(B15/$B$6,"") | D15: 0.19048549 | E15: =IFERROR(C15-D15,"") | G15: 18℃-飯A15:A23糰(061,063) | H15: ='（４）訂單數量構成比'!M46 -> 2614973 | I15: =IFERROR(H15/$B$7,"") | J15: 0.33193454 | K15: =IFERROR(I15-J15,"")
A16: 18℃-壽司手卷(071,072,075,076) | B16: ='（３）業績構成比'!S46/1000 -> 10841.451 | C16: =IFERROR(B16/$B$6,"") | D16: 0.04002075 | E16: =IFERROR(C16-D16,"") | G16: 18℃-壽司手卷(071,072,075,076) | H16: ='（４）訂單數量構成比'!S47 -> 483465 | I16: =IFERROR(H16/$B$7,"") | J16: 0.050408543 | K16: =IFERROR(I16-J16,"")
A17: 4℃-飯糰(065) | B17: ='（３）業績構成比'!U46/1000 -> 22206.396 | C17: =IFERROR(B17/$B$6,"") | D17: 0.098025494 | E17: =IFERROR(C17-D17,"") | G17: 4℃-飯糰(065) | H17: ='（４）訂單數量構成比'!U46 -> 657021 | I17: =IFERROR(H17/$B$7,"") | J17: 0.09754935 | K17: =IFERROR(I17-J17,"")
A18: 4℃-壽司手卷(077) | B18: ='（３）業績構成比'!W46/1000 -> 3804.6872 | C18: =IFERROR(B18/$B$6,"") | D18: 0.0023157871 | E18: =IFERROR(C18-D18,"") | G18: 4℃-壽司手卷(077) | H18: ='（４）訂單數量構成比'!W46 -> 133372 | I18: =IFERROR(H18/$B$7,"") | J18: 0.0027738407 | K18: =IFERROR(I18-J18,"")
A19: 主食(091,092,093,094,095) | B19: ='（３）業績構成比'!AC46/1000 -> 61807.986 | C19: =IFERROR(B19/$B$6,"") | D19: 0.26645165 | E19: =IFERROR(C19-D19,"") | G19: 主食(091,092,093,094,095) | H19: ='（４）訂單數量構成比'!AC46 -> 1545991 | I19: =IFERROR(H19/$B$7,"") | J19: 0.20966064 | K19: =IFERROR(I19-J19,"")
A20: 便當(083) | B20: ='（３）業績構成比'!AE46/1000 -> 35929.597 | C20: =IFERROR(B20/$B$6,"") | D20: 0.11880395 | E20: =IFERROR(C20-D20,"") | G20: 便當(083) | H20: ='（４）訂單數量構成比'!AE46 -> 636391 | I20: =IFERROR(H20/$B$7,"") | J20: 0.069473342 | K20: =IFERROR(I20-J20,"")
A21: 熱食義麵(122,123,124,126) | B21: ='（３）業績構成比'!AG46/1000 -> 34324.581 | C21: =IFERROR(B21/$B$6,"") | D21: 0.13107603 | E21: =IFERROR(C21-D21,"") | G21: 熱食義麵(122,123,124,126) | H21: ='（４）訂單數量構成比'!AG46 -> 702832 | I21: =IFERROR(H21/$B$7,"") | J21: 0.087948485 | K21: =IFERROR(I21-J21,"")
A22: 季節調理麵(111,112) | B22: ='（３）業績構成比'!AI46/1000 -> 17203.976 | C22: =IFERROR(B22/$B$6,"") | D22: 0.091535408 | E22: =IFERROR(C22-D22,"") | G22: 季節調理麵(111,112) | H22: ='（４）訂單數量構成比'!AI46 -> 467674 | I22: =IFERROR(H22/$B$7,"") | J22: 0.079981641 | K22: =IFERROR(I22-J22,"")
A23: 微波小吃(153,154,155) | B23: ='（３）業績構成比'!AK46/1000 -> 19866.978 | C23: =IFERROR(B23/$B$6,"") | D23: 0.061285436 | E23: =IFERROR(C23-D23,"") | G23: 微波小吃(153,154,155) | H23: ='（４）訂單數量構成比'!AK46 -> 654860 | I23: =IFERROR(H23/$B$7,"") | J23: 0.070269615 | K23: =IFERROR(I23-J23,"")
C24: =SUM(C15:C23) -> 0 | D24: =SUM(D15:D23) -> 1 | I24: =SUM(I15:I23) -> 0 | J24: =SUM(J15:J23) -> 1
A26: （５）品群別人時生產性
A27: 品群 | B27: 當月 | C27: 前月 | D27: 差異 | E27: 累計 | M27: 8月 | N27: 9月 | O27: 10月 | P27: 11月 | Q27: 12月
A28: 18℃-飯A15:A23糰(061,063) | B28: ='（５-1）品群別人時生產性（18℃-飯糰）'!$C$1 -> 757.93396 | C28: 717.52753 | D28: =B28-C28 -> 40.406423 | E28: =R28 -> 737.73075 | M28: 717.52753 | N28: =B28 -> 757.93396 | R28: =AVERAGE(M28:Q28) -> 737.73075
A29: 18℃-壽司手卷(071,072,075,076) | B29: ='（５-2）品群別人時生產性（18-壽司手卷)'!$C$1 -> 196.68274 | C29: 197.63272 | D29: =B29-C29 -> -0.94997319 | E29: =R29 -> 197.15773 | M29: 197.63272 | N29: =B29 -> 196.68274 | R29: =AVERAGE(M29:Q29) -> 197.15773
A30: 4℃-飯糰(065) | B30: ='（５-3）品群別人時生產性（4℃-飯糰)'!$C$1 -> 257.89773 | C30: 240.45857 | D30: =B30-C30 -> 17.439156 | E30: =R30 -> 249.17815 | M30: 240.45857 | N30: =B30 -> 257.89773 | R30: =AVERAGE(M30:Q30) -> 249.17815
A31: 4℃-壽司手卷(077) | B31: ='（５-4）品群別人時生產性（4℃-壽司手卷)'!$C$1 -> 111.44619 | C31: 106.86512 | D31: =B31-C31 -> 4.5810666 | E31: =R31 -> 109.15566 | M31: 106.86512 | N31: =B31 -> 111.44619 | R31: =AVERAGE(M31:Q31) -> 109.15566
A32: 主食(091,092,093,094,095) | B32: ='（５-5）品群別人時生產性(主食) '!$C$1 -> 85.484459 | C32: 89.310428 | D32: =B32-C32 -> -3.8259697 | E32: =R32 -> 87.397444 | M32: 89.310428 | N32: =B32 -> 85.484459 | R32: =AVERAGE(M32:Q32) -> 87.397444
A33: 便當(083) | B33: ='（５-6）品群別人時生產性(便當)'!$C$1 -> 67.056533 | C33: 65.672742 | D33: =B33-C33 -> 1.3837902 | E33: =R33 -> 66.364638 | M33: 65.672742 | N33: =B33 -> 67.056533 | R33: =AVERAGE(M33:Q33) -> 66.364638
A34: 熱食義麵(122,123,124,126) | B34: ='（５-7）品群別人時生產性(熱食義麵) '!$C$1 -> 79.538681 | C34: 75.478569 | D34: =B34-C34 -> 4.0601124 | E34: =R34 -> 77.508625 | M34: 75.478569 | N34: =B34 -> 79.538681 | R34: =AVERAGE(M34:Q34) -> 77.508625
A35: 季節調理麵(111,112) | B35: ='（５-8）品群別人時生產性(季節調理麵) '!$C$1 -> 121.29589 | C35: 114.50557 | D35: =B35-C35 -> 6.7903195 | E35: =R35 -> 117.90073 | M35: 114.50557 | N35: =B35 -> 121.29589 | R35: =AVERAGE(M35:Q35) -> 117.90073
A36: 微波小吃(153,154,155) | B36: ='（５-9）品群別人時生產性(微波小吃)'!$C$1 -> 115.29817 | C36: 99.648342 | D36: =B36-C36 -> 15.649824 | E36: =R36 -> 107.47325 | M36: 99.648342 | N36: =B36 -> 115.29817 | R36: =AVERAGE(M36:Q36) -> 107.47325

Sheet 生產管理報表(週) 
A1: 生產管理報表
A3: 月別 | B3: 10 | C3: 週別 | D3: W4 | E3: 工廠 | F3: 晉欣廠
A4: （１）收支狀況 | E4: ※單位：千元 | G4: （２）ＫＰＩ達成進度
A5: 項目 | B5: 當週 | C5: 前週 | D5: 差異 | E5: 累計 | G5: 項目 | H5: KPI | I5: 當週 | J5: 前週 | K5: 累計 | L5: ※補充
A6: 業績金額 | B6: ='（１）收支狀況'!G33/1000 -> 52649.495 | C6: 51190.043 | D6: =B6-C6 -> 1459.452 | E6: ='（１）收支狀況'!H6/1000 -> 224463.49 | G6: 人時性(個/月均) | H6: 366 | I6: ='（２）ＫＰＩ達成進度'!G33 -> 340.19679 | J6: 338.65022 | K6: ='（２）ＫＰＩ達成進度'!H6 -> 330.21458 | L6: 個／MH
A7: 訂單數量 | B7: ='（１）收支狀況'!J33 -> 1631463 | C7: 1625220 | D7: =B7-C7 -> 6243 | E7: ='（１）收支狀況'!K6 -> 6964636 | G7: 人時達成率(%/月均) | H7: 0.8 | I7: ='（２）ＫＰＩ達成進度'!J33 -> 0.92949941 | J7: 0.92527381 | K7: ='（２）ＫＰＩ達成進度'!K6 -> 0.90222562 | L7: 達成率
A8: 材料費 | B8: ='（１）收支狀況'!M33/1000 -> 34902.738 | C8: 34016.037 | D8: =B8-C8 -> 886.701 | E8: ='（１）收支狀況'!N6/1000 -> 150244.29 | G8: 半成品-報廢(%) | H8: 0.0025 | I8: ='（２）ＫＰＩ達成進度'!M33 -> 0.0024552869 | J8: 0.0024706626 | K8: ='（２）ＫＰＩ達成進度'!N6 -> 0.0024646257 | L8: 報廢率
A9: 材料費率 | B9: ='（１）收支狀況'!P33 -> 0.66292636 | C9: 0.66450495 | D9: =B9-C9 -> -0.0015785921 | E9: ='（１）收支狀況'!Q6 -> 0.66934847 | G9: 半成品-超用(%) | H9: 0.0026 | I9: ='（２）ＫＰＩ達成進度'!P33 -> 0.0022768681 | J9: 0.0022653735 | K9: ='（２）ＫＰＩ達成進度'!Q6 -> 0.0023405371 | L9: 超用率
A10: 勞務成本 | B10: ='（１）收支狀況'!S33/1000 -> 7231.7426 | C10: =7288806.85161291/1000 -> 7288.8069 | D10: =B10-C10 -> -57.064243 | E10: ='（１）收支狀況'!T6/1000 -> 32105.787 | G10: 固定產線-導入率(%) | H10: 0.8 | I10: 0.917 | J10: 0.917 | K10: 0.917 | L10: 導入率
A11: 勞務費率 | B11: ='（１）收支狀況'!V33 -> 0.13735635 | C11: 0.1423872 | D11: =B11-C11 -> -0.0050308465 | E11: ='（１）收支狀況'!W6 -> 0.14303345 | G11: 教育訓練-實施率(%) | H11: 1 | I11: ='（２）ＫＰＩ達成進度'!V33 -> 0.87342857 | J11: 0.85371429 | K11: ='（２）ＫＰＩ達成進度'!W6 -> 0.84941935 | L11: 實施率
A13: （３）業績構成比 | G13: （４）訂單數量構成比
B14: 當週 | C14: 比例 | D14: 前週 | E14: 差異 | H14: 當週 | I14: 比例 | J14: 前週 | K14: 差異
A15: 18℃-飯糰(061,063) | B15: =SUM('（３）業績構成比'!I35:I41,'（３）業績構成比'!K35:K41)/1000 -> 10502.37 | C15: =IFERROR(B15/$B$6,"") -> 0.19947712 | D15: 0.19586426 | E15: =IFERROR(C15-D15,"") -> 0.0036128662 | G15: 18℃-飯糰(061,063) | H15: =SUM(,'（４）訂單數量構成比'!I35:I41,'（４）訂單數量構成比'!K35:K41) -> 553417 | I15: =IFERROR(H15/$B$7,"") -> 0.33921517 | J15: 0.33891904 | K15: =IFERROR(I15-J15,"") -> 0.00029613202
A16: 18℃-壽司手卷(071,072,075,076) | B16: =SUM('（３）業績構成比'!O35:O41,'（３）業績構成比'!Q35:Q41)/1000 -> 2321.5084 | C16: =IFERROR(B16/$B$6,"") -> 0.044093649 | D16: 0.046380374 | E16: =IFERROR(C16-D16,"") -> -0.0022867245 | G16: 18℃-壽司手卷(071,072,075,076) | H16: =SUM('（４）訂單數量構成比'!O35:O41,'（４）訂單數量構成比'!Q35:Q41) -> 102017 | I16: =IFERROR(H16/$B$7,"") -> 0.062530992 | J16: 0.067334884 | K16: =IFERROR(I16-J16,"") -> -0.0048038918
A17: 4℃-飯糰(065) | B17: =SUM('（３）業績構成比'!U35:U41)/1000 -> 4114.1295 | C17: =IFERROR(B17/$B$6,"") -> 0.078141862 | D17: 0.085916347 | E17: =IFERROR(C17-D17,"") -> -0.007774485 | G17: 4℃-飯糰(065) | H17: =SUM('（４）訂單數量構成比'!U35:U41) -> 123056 | I17: =IFERROR(H17/$B$7,"") -> 0.07542678 | J17: 0.081385905 | K17: =IFERROR(I17-J17,"") -> -0.0059591252
A18: 4℃-壽司手卷(077) | B18: =SUM('（３）業績構成比'!W35:W41)/1000 -> 1395.7239 | C18: =IFERROR(B18/$B$6,"") -> 0.026509729 | D18: 0.010574883 | E18: =IFERROR(C18-D18,"") -> 0.015934846 | G18: 4℃-壽司手卷(077) | H18: =SUM('（４）訂單數量構成比'!W35:W41) -> 44046 | I18: =IFERROR(H18/$B$7,"") -> 0.026997854 | J18: 0.012622906 | K18: =IFERROR(I18-J18,"") -> 0.014374948
A19: 主食(091,092,093,094,095) | B19: =SUM('（３）業績構成比'!Y35:Y41,'（３）業績構成比'!AA35:AA41)/1000 -> 12729.289 | C19: =IFERROR(B19/$B$6,"") -> 0.24177418 | D19: 0.23846831 | E19: =IFERROR(C19-D19,"") -> 0.0033058728 | G19: 主食(091,092,093,094,095) | H19: =SUM('（４）訂單數量構成比'!Y35:Y41,'（４）訂單數量構成比'!AA35:AA41) -> 319504 | I19: =IFERROR(H19/$B$7,"") -> 0.19583895 | J19: 0.18998659 | K19: =IFERROR(I19-J19,"") -> 0.005852363
A20: 便當(083) | B20: =SUM('（３）業績構成比'!AE35:AE41)/1000 -> 7739.5153 | C20: =IFERROR(B20/$B$6,"") -> 0.14700075 | D20: 0.13645577 | E20: =IFERROR(C20-D20,"") -> 0.010544981 | G20: 便當(083) | H20: =SUM('（４）訂單數量構成比'!AE35:AE41) -> 138120 | I20: =IFERROR(H20/$B$7,"") -> 0.08466021 | J20: 0.076913279 | K20: =IFERROR(I20-J20,"") -> 0.0077469305
A21: 熱食義麵(122,123,124,126) | B21: =SUM('（３）業績構成比'!AG35:AG41)/1000 -> 6291.795 | C21: =IFERROR(B21/$B$6,"") -> 0.11950342 | D21: 0.14345998 | E21: =IFERROR(C21-D21,"") -> -0.023956558 | G21: 熱食義麵(122,123,124,126) | H21: =SUM('（４）訂單數量構成比'!AG35:AG41) -> 125739 | I21: =IFERROR(H21/$B$7,"") -> 0.077071316 | J21: 0.092061998 | K21: =IFERROR(I21-J21,"") -> -0.014990682
A22: 季節調理麵(111,112) | B22: =SUM('（３）業績構成比'!AI35:AI41)/1000 -> 2870.2093 | C22: =IFERROR(B22/$B$6,"") -> 0.05451542 | D22: 0.070164778 | E22: =IFERROR(C22-D22,"") -> -0.015649358 | G22: 季節調理麵(111,112) | H22: =SUM('（４）訂單數量構成比'!AI35:AI41) -> 79816 | I22: =IFERROR(H22/$B$7,"") -> 0.048922961 | J22: 0.061145568 | K22: =IFERROR(I22-J22,"") -> -0.012222607
A23: 微波小吃(153,154,155) | B23: =SUM('（３）業績構成比'!AK35:AK41)/1000 -> 4684.9552 | C23: =IFERROR(B23/$B$6,"") -> 0.088983858 | D23: 0.072715299 | E23: =IFERROR(C23-D23,"") -> 0.01626856 | G23: 微波小吃(153,154,155) | H23: =SUM('（４）訂單數量構成比'!AK35:AK41) -> 145748 | I23: =IFERROR(H23/$B$7,"") -> 0.089335768 | J23: 0.079629835 | K23: =IFERROR(I23-J23,"") -> 0.0097059332
C24: =SUM(C15:C23) -> 1 | D24: =SUM(D15:D23) -> 1 | I24: =SUM(I15:I23) -> 1 | J24: =SUM(J15:J23) -> 1
A26: （５）品群別人時生產性
A27: 品群 | B27: 當週 | C27: 前週 | D27: 差異 | E27: 累計
A28: 18℃-飯糰(061,063) | B28: ='（５-1）品群別人時生產性（18℃-飯糰）'!L147 -> 763.95984 | C28: 794.33214 | D28: =B28-C28 -> -30.3723 | E28: ='（５-1）品群別人時生產性（18℃-飯糰）'!C1 -> 757.93396
A29: 18℃-壽司手卷(071,072,075,076) | B29: ='（５-2）品群別人時生產性（18-壽司手卷)'!L87 -> 182.82703 | C29: 201.12798 | D29: =B29-C29 -> -18.300951 | E29: ='（５-2）品群別人時生產性（18-壽司手卷)'!C1 -> 196.68274
A30: 4℃-飯糰(065) | B30: ='（５-3）品群別人時生產性（4℃-飯糰)'!L87 -> 279.25965 | C30: 250.50834 | D30: =B30-C30 -> 28.751305 | E30: ='（５-3）品群別人時生產性（4℃-飯糰)'!C1 -> 257.89773
A31: 4℃-壽司手卷(077) | B31: ='（５-4）品群別人時生產性（4℃-壽司手卷)'!L87 -> 121.87018 | C31: 103.01068 | D31: =B31-C31 -> 18.859506 | E31: ='（５-4）品群別人時生產性（4℃-壽司手卷)'!C1 -> 111.44619
A32: 主食(091,092,093,094,095) | B32: ='（５-5）品群別人時生產性(主食) '!L147 -> 86.918291 | C32: 85.796578 | D32: =B32-C32 -> 1.1217131 | E32: ='（５-5）品群別人時生產性(主食) '!C1 -> 85.484459
A33: 便當(083) | B33: ='（５-6）品群別人時生產性(便當)'!L87 -> 68.146891 | C33: 66.973463 | D33: =B33-C33 -> 1.1734279 | E33: ='（５-6）品群別人時生產性(便當)'!C1 -> 67.056533
A34: 熱食義麵(122,123,124,126) | B34: ='（５-7）品群別人時生產性(熱食義麵) '!L87 -> 74.417644 | C34: 80.852359 | D34: =B34-C34 -> -6.434715 | E34: ='（５-7）品群別人時生產性(熱食義麵) '!C1 -> 79.538681
A35: 季節調理麵(111,112) | B35: ='（５-8）品群別人時生產性(季節調理麵) '!L87 -> 119.81397 | C35: 122.92451 | D35: =B35-C35 -> -3.1105454 | E35: ='（５-8）品群別人時生產性(季節調理麵) '!C1 -> 121.29589
A36: 微波小吃(153,154,155) | B36: ='（５-9）品群別人時生產性(微波小吃)'!L87 -> 112.15854 | C36: 113.37236 | D36: =B36-C36 -> -1.2138185 | E36: ='（５-9）品群別人時生產性(微波小吃)'!C1 -> 115.29817

Sheet （１）收支狀況
B2: （１）收支狀況
C3: 月份 | D3: 日期 | F3: 營業額(元) | I3: 訂單數量(個) | L3: 材料費(元) | O3: 材料費率（材料費／營業額） | R3: 勞務成本（全廠人事成本） | U3: 勞務費率（勞務成本／營業額）
F4: 日 | G4: 週累積 | H4: 月累積 | I4: 日 | J4: 週累積 | K4: 月累積 | L4: 日 | M4: 週累積 | N4: 月累積 | O4: 日 | P4: 週累積 | Q4: 月平均 | R4: 日 | S4: 週累積 | T4: 月累積 | U4: 日 | V4: 週累積 | W4: 月平均
C5: 10 | D5: 45930 | E5: 二 | F5: 8551969 | G5: =SUM(F5:F11) -> 50444409 | I5: 261840 | J5: =SUM(I5:I11) -> 1549527 | L5: 5483375 | M5: =SUM(L5:L11) -> 33855908 | O5: =L5/F5 -> 0.64118275 | P5: =M5/G5 -> 0.67115283 | R5: 1083532.6 | S5: =SUM(R5:R11) -> 7077533.8 | U5: =R5/F5 -> 0.12669978 | V5: =S5/G5 -> 0.14030363
D6: 45931 | E6: 三 | F6: 7858716 | H6: =SUM(F6:F36) -> 224463487 | I6: 244804 | K6: =SUM(I6:I36) -> 6964636 | L6: 5274194 | N6: =SUM(L6:L36) -> 150244292 | O6: =L6/F6 -> 0.67112668 | Q6: =N6/H6 -> 0.66934847 | R6: 1028886.1 | T6: =SUM(R6:R36) -> 32105787 | U6: =R6/F6 -> 0.13092292 | W6: =T6/H6 -> 0.14303345
D7: 45932 | E7: 四 | F7: 7240224 | I7: 223462 | L7: 4929487 | O7: =L7/F7 -> 0.68084731 | R7: 992746.84 | U7: =R7/F7 -> 0.13711549
D8: 45933 | E8: 五 | F8: 6162506 | I8: 190714 | L8: 4279179 | O8: =L8/F8 -> 0.69438943 | R8: 971940.49 | U8: =R8/F8 -> 0.15771838
D9: 45934 | E9: 六 | F9: 6257631 | I9: 190858 | L9: 4409794 | O9: =L9/F9 -> 0.70470662 | R9: 961116.97 | U9: =R9/F9 -> 0.15359119
D10: 45935 | E10: 日 | F10: 6624573 | I10: 199802 | L10: 4553748 | O10: =L10/F10 -> 0.68740249 | R10: 968268.15 | U10: =R10/F10 -> 0.1461631
D11: 45936 | E11: 一 | F11: 7748790 | I11: 238047 | L11: 4926131 | O11: =L11/F11 -> 0.63572906 | R11: 1071042.7 | U11: =R11/F11 -> 0.13822064
D12: 45937 | E12: 二 | F12: 8050194 | G12: =SUM(F12:F18) -> 50896038 | I12: 241200 | J12: =SUM(I12:I18) -> 1538613 | L12: 5548828 | M12: =SUM(L12:L18) -> 34185406 | O12: =L12/F12 -> 0.68927879 | P12: =M12/G12 -> 0.67167126 | R12: 1102462.1 | S12: =SUM(R12:R18) -> 7309734.5 | U12: =R12/F12 -> 0.13694851 | V12: =S12/G12 -> 0.14362089
D13: 45938 | E13: 三 | F13: 7653723 | I13: 230348 | L13: 5016683 | O13: =L13/F13 -> 0.65545657 | R13: 1082148.7 | U13: =R13/F13 -> 0.14138854
D14: 45939 | E14: 四 | F14: 6660783 | I14: 200331 | L14: 4721001 | O14: =L14/F14 -> 0.70877568 | R14: 1047913.1 | U14: =R14/F14 -> 0.15732581
D15: 45940 | E15: 五 | F15: 6259506 | I15: 190019 | L15: 4293432 | O15: =L15/F15 -> 0.68590588 | R15: 1017586 | U15: =R15/F15 -> 0.16256651
D16: 45941 | E16: 六 | F16: 6689233 | I16: 202843 | L16: 4536869 | O16: =L16/F16 -> 0.67823456 | R16: 996159.81 | U16: =R16/F16 -> 0.14891989
D17: 45942 | E17: 日 | F17: 7867103 | I17: 238632 | L17: 5123753 | O17: =L17/F17 -> 0.65128841 | R17: 1015157.5 | U17: =R17/F17 -> 0.12903829
D18: 45943 | E18: 一 | F18: 7715496 | I18: 235240 | L18: 4944840 | O18: =L18/F18 -> 0.64089723 | R18: 1048307.3 | U18: =R18/F18 -> 0.13587037
D19: 45944 | E19: 二 | F19: 7917911 | G19: =SUM(F19:F25) -> 51190043 | I19: 248931 | J19: =SUM(I19:I25) -> 1625220 | L19: 5237130 | M19: =SUM(L19:L25) -> 34016037 | O19: =L19/F19 -> 0.66142825 | P19: =M19/G19 -> 0.66450495 | R19: 1055463.5 | S19: =SUM(R19:R25) -> 7288806.9 | U19: =R19/F19 -> 0.13330075 | V19: =S19/G19 -> 0.1423872
D20: 45945 | E20: 三 | F20: 7086135 | I20: 242991 | L20: 5056182 | O20: =L20/F20 -> 0.71353171 | R20: 1063455.9 | U20: =R20/F20 -> 0.15007559
D21: 45946 | E21: 四 | F21: 7387104 | I21: 230663 | L21: 4925675 | O21: =L21/F21 -> 0.66679378 | R21: 1044355.9 | U21: =R21/F21 -> 0.14137556
D22: 45947 | E22: 五 | F22: 6524343 | I22: 205320 | L22: 4482274 | O22: =L22/F22 -> 0.68700772 | R22: 1032424.2 | U22: =R22/F22 -> 0.15824186
D23: 45948 | E23: 六 | F23: 6552897 | I23: 207727 | L23: 4415568 | O23: =L23/F23 -> 0.67383449 | R23: 1013055.8 | U23: =R23/F23 -> 0.15459663
D24: 45949 | E24: 日 | F24: 7868086 | I24: 245349 | L24: 4858183 | O24: =L24/F24 -> 0.61745423 | R24: 1030252.6 | U24: =R24/F24 -> 0.13094069
D25: 45950 | E25: 一 | F25: 7853567 | I25: 244239 | L25: 5041025 | O25: =L25/F25 -> 0.64187712 | R25: 1049798.9 | U25: =R25/F25 -> 0.13367161
D26: 45951 | E26: 二 | F26: 7817095 | G26: =SUM(F26:F32) -> 49497330 | I26: 244571 | J26: =SUM(I26:I32) -> 1551756 | L26: 5145149 | M26: =SUM(L26:L32) -> 32938462 | O26: =L26/F26 -> 0.65819195 | P26: =M26/G26 -> 0.66545937 | R26: 1055534.5 | S26: =SUM(R26:R32) -> 7177192.8 | U26: =R26/F26 -> 0.13502899 | V26: =S26/G26 -> 0.14500162
D27: 45952 | E27: 三 | F27: 7419770 | I27: 231603 | L27: 4937368 | O27: =L27/F27 -> 0.6654341 | R27: 1040324.9 | U27: =R27/F27 -> 0.14020986
D28: 45953 | E28: 四 | F28: 6310328 | I28: 198604 | L28: 4449188 | O28: =L28/F28 -> 0.70506446 | R28: 992591.95 | U28: =R28/F28 -> 0.15729641
D29: 45954 | E29: 五 | F29: 6007757 | I29: 190154 | L29: 4093744 | O29: =L29/F29 -> 0.68140972 | R29: 993144.08 | U29: =R29/F29 -> 0.16531029
D30: 45955 | E30: 六 | F30: 6324783 | I30: 198374 | L30: 4289026 | O30: =L30/F30 -> 0.67813014 | R30: 1007188.5 | U30: =R30/F30 -> 0.15924476
D31: 45956 | E31: 日 | F31: 7684569 | I31: 241268 | L31: 4818296 | O31: =L31/F31 -> 0.62700927 | R31: 1045371.6 | U31: =R31/F31 -> 0.13603517
D32: 45957 | E32: 一 | F32: 7933028 | I32: 247182 | L32: 5205691 | O32: =L32/F32 -> 0.65620479 | R32: 1043037.2 | U32: =R32/F32 -> 0.13148034
D33: 45958 | E33: 二 | F33: 8874807 | G33: =SUM(F33:F39) -> 52649495 | I33: 271475 | J33: =SUM(I33:I39) -> 1631463 | L33: 5922651 | M33: =SUM(L33:L39) -> 34902738 | O33: =L33/F33 -> 0.66735547 | P33: =M33/G33 -> 0.66292636 | R33: 1123600.9 | S33: =SUM(R33:R39) -> 7231742.6 | U33: =R33/F33 -> 0.12660568 | V33: =S33/G33 -> 0.13735635
D34: 45959 | E34: 三 | F34: 8157355 | I34: 254507 | L34: 5473618 | O34: =L34/F34 -> 0.67100402 | R34: 1100557.1 | U34: =R34/F34 -> 0.13491592
D35: 45960 | E35: 四 | F35: 7556926 | I35: 234639 | L35: 4858313 | O35: =L35/F35 -> 0.6428954 | R35: 1081448.1 | U35: =R35/F35 -> 0.14310687
D36: 45961 | E36: 五 | F36: 6398548 | I36: 200739 | L36: 4477272 | O36: =L36/F36 -> 0.6997325 | R36: 1030445.3 | U36: =R36/F36 -> 0.16104361
D37: 45962 | E37: 六 | F37: 6412266 | I37: 199982 | L37: 4375107 | O37: =L37/F37 -> 0.68230279 | R37: 936638.47 | U37: =R37/F37 -> 0.14606981
D38: 45963 | E38: 日 | F38: 7718290 | I38: 239410 | L38: 4848519 | O38: =L38/F38 -> 0.62818565 | R38: 975639 | U38: =R38/F38 -> 0.12640611
D39: 45964 | E39: 一 | F39: 7531303 | I39: 230711 | L39: 4947258 | O39: =L39/F39 -> 0.65689271 | R39: 983413.83 | U39: =R39/F39 -> 0.13057685
O40: =L40/F40 -> #DIV/0! | U40: =R40/F40 -> #DIV/0!

Sheet （２）ＫＰＩ達成進度
B1: KPI | C1: 366
B2: （２）ＫＰＩ達成進度
C3: 月份 | D3: 日期 | F3: 人時生產性(個/人) | I3: 人時生產性達成率(%) | L3: 半成品報廢(%) | O3: 半成品超用(%) | R3: 固定產線-導入率(固定產線數/總產線數) | U3: 教育訓練-實施率(進度/計畫)
F4: 日 | G4: 週平均 | H4: 月平均 | I4: 日 | J4: 週平均 | K4: 月平均 | L4: 日 | M4: 週平均 | N4: 月平均 | O4: 日 | P4: 週平均 | Q4: 月平均 | R4: 日 | S4: 週平均 | T4: 月平均 | U4: 日 | V4: 週平均 | W4: 月平均
C5: 10 | D5: 45930 | E5: 二 | F5: 311 | G5: =AVERAGE(F5:F11) -> 310.31036 | I5: =F5/$C$1 -> 0.84972678 | J5: =AVERAGE(I5:I11) -> 0.84784252 | L5: 0.0025187742 | M5: =AVERAGE(L5:L11) -> 0.0024662745 | O5: 0.0021349893 | P5: =AVERAGE(O5:O11) -> 0.0023293701 | R5: 0.91666667 | S5: =AVERAGE(R5:R11) -> 0.91666667 | U5: 0.81 | V5: =AVERAGE(U5:U11) -> 0.82042857
D6: 45931 | E6: 三 | F6: 306.95527 | H6: =AVERAGE(F6:F36) -> 330.21458 | I6: =F6/$C$1 -> 0.83867561 | K6: =AVERAGE(I6:I36) -> 0.90222562 | L6: 0.002425212 | N6: =AVERAGE(L6:L36) -> 0.0024646257 | O6: 0.002033958 | Q6: =AVERAGE(O6:O36) -> 0.0023405371 | R6: 0.91666667 | T6: =AVERAGE(R6:R36) -> 0.91666667 | U6: 0.81 | W6: =AVERAGE(U6:U36) -> 0.84941935
D7: 45932 | E7: 四 | F7: 305.3174 | I7: =F7/$C$1 -> 0.83420055 | L7: 0.0024682799 | O7: 0.0021960721 | R7: 0.91666667 | U7: 0.82
D8: 45933 | E8: 五 | F8: 306.25776 | I8: =F8/$C$1 -> 0.83676984 | L8: 0.0024672203 | O8: 0.0025561764 | R8: 0.91666667 | U8: 0.82
D9: 45934 | E9: 六 | F9: 323.13134 | I9: =F9/$C$1 -> 0.8828725 | L9: 0.0024482941 | O9: 0.0026193317 | R9: 0.91666667 | U9: 0.825
D10: 45935 | E10: 日 | F10: 303.74291 | I10: =F10/$C$1 -> 0.82989866 | L10: 0.0024893147 | O10: 0.0025195761 | R10: 0.91666667 | U10: 0.828
D11: 45936 | E11: 一 | F11: 315.76786 | I11: =F11/$C$1 -> 0.86275373 | L11: 0.0024468262 | O11: 0.0022454873 | R11: 0.91666667 | U11: 0.83
D12: 45937 | E12: 二 | F12: 321.48814 | G12: =AVERAGE(F12:F18) -> 329.53405 | I12: =F12/$C$1 -> 0.87838289 | J12: =AVERAGE(I12:I18) -> 0.90036626 | L12: 0.0024862755 | M12: =AVERAGE(L12:L18) -> 0.0024732906 | O12: 0.0021734363 | P12: =AVERAGE(O12:O18) -> 0.0023503147 | R12: 0.91666667 | S12: =AVERAGE(R12:R18) -> 0.91666667 | U12: 0.83 | V12: =AVERAGE(U12:U18) -> 0.84085714
D13: 45938 | E13: 三 | F13: 329.99476 | I13: =F13/$C$1 -> 0.90162503 | L13: 0.0024804922 | O13: 0.0024560617 | R13: 0.91666667 | U13: 0.838
D14: 45939 | E14: 四 | F14: 320.60387 | I14: =F14/$C$1 -> 0.87596684 | L14: 0.0024696796 | O14: 0.0024669483 | R14: 0.91666667 | U14: 0.84
D15: 45940 | E15: 五 | F15: 329.84705 | I15: =F15/$C$1 -> 0.90122146 | L15: 0.0024700032 | O15: 0.0026304825 | R15: 0.91666667 | U15: 0.84
D16: 45941 | E16: 六 | F16: 326.42578 | I16: =F16/$C$1 -> 0.89187372 | L16: 0.0024433295 | O16: 0.0023205107 | R16: 0.91666667 | U16: 0.845
D17: 45942 | E17: 日 | F17: 345.72326 | I17: =F17/$C$1 -> 0.94459906 | L17: 0.0024718121 | O17: 0.0021715309 | R17: 0.91666667 | U17: 0.845
D18: 45943 | E18: 一 | F18: 332.6555 | I18: =F18/$C$1 -> 0.90889481 | L18: 0.0024914422 | O18: 0.0022332324 | R18: 0.91666667 | U18: 0.848
D19: 45944 | E19: 二 | F19: 324.69881 | G19: =AVERAGE(F19:F25) -> 338.65022 | I19: =F19/$C$1 -> 0.88715523 | J19: =AVERAGE(I19:I25) -> 0.92527381 | L19: 0.0024988914 | M19: =AVERAGE(L19:L25) -> 0.0024706626 | O19: 0.0022673158 | P19: =AVERAGE(O19:O25) -> 0.0022653735 | R19: 0.91666667 | S19: =AVERAGE(R19:R25) -> 0.91666667 | U19: 0.85 | V19: =AVERAGE(U19:U25) -> 0.85371429
D20: 45945 | E20: 三 | F20: 344.18197 | I20: =F20/$C$1 -> 0.94038789 | L20: 0.0024704582 | O20: 0.0022918917 | R20: 0.91666667 | U20: 0.85
D21: 45946 | E21: 四 | F21: 326.38436 | I21: =F21/$C$1 -> 0.89176054 | L21: 0.0024809452 | O21: 0.0022646601 | R21: 0.91666667 | U21: 0.852
D22: 45947 | E22: 五 | F22: 345.15849 | I22: =F22/$C$1 -> 0.94305598 | L22: 0.0024584851 | O22: 0.00251305 | R22: 0.91666667 | U22: 0.854
D23: 45948 | E23: 六 | F23: 333.93291 | I23: =F23/$C$1 -> 0.91238501 | L23: 0.0024695947 | O23: 0.002345795 | R23: 0.91666667 | U23: 0.856
D24: 45949 | E24: 日 | F24: 346.44566 | I24: =F24/$C$1 -> 0.94657285 | L24: 0.0024655297 | O24: 0.0020855233 | R24: 0.91666667 | U24: 0.856
D25: 45950 | E25: 一 | F25: 349.74931 | I25: =F25/$C$1 -> 0.95559921 | L25: 0.0024507335 | O25: 0.0020893788 | R25: 0.91666667 | U25: 0.858
D26: 45951 | E26: 二 | F26: 323.90725 | G26: =AVERAGE(F26:F32) -> 335.05828 | I26: =F26/$C$1 -> 0.8849925 | J26: =AVERAGE(I26:I32) -> 0.91545978 | L26: 0.0024788198 | M26: =AVERAGE(L26:L32) -> 0.0024577011 | O26: 0.0021878136 | P26: =AVERAGE(O26:O32) -> 0.0024064585 | R26: 0.91666667 | S26: =AVERAGE(R26:R32) -> 0.91666667 | U26: 0.86 | V26: =AVERAGE(U26:U32) -> 0.86471429
D27: 45952 | E27: 三 | F27: 340.57902 | I27: =F27/$C$1 -> 0.93054376 | L27: 0.0024681358 | O27: 0.0022021568 | R27: 0.91666667 | U27: 0.862
D28: 45953 | E28: 四 | F28: 319.13569 | I28: =F28/$C$1 -> 0.87195543 | L28: 0.0024905203 | O28: 0.0025052057 | R28: 0.91666667 | U28: 0.862
D29: 45954 | E29: 五 | F29: 331.85866 | I29: =F29/$C$1 -> 0.90671766 | L29: 0.00245 | O29: 0.0027885185 | R29: 0.91666667 | U29: 0.865
D30: 45955 | E30: 六 | F30: 346.81537 | I30: =F30/$C$1 -> 0.94758299 | L30: 0.0024279094 | O30: 0.0025266368 | R30: 0.91666667 | U30: 0.868
D31: 45956 | E31: 日 | F31: 348.39098 | I31: =F31/$C$1 -> 0.95188793 | L31: 0.002450235 | O31: 0.0024897223 | R31: 0.91666667 | U31: 0.868
D32: 45957 | E32: 一 | F32: 334.72099 | I32: =F32/$C$1 -> 0.91453821 | L32: 0.0024382871 | O32: 0.0021451559 | R32: 0.91666667 | U32: 0.868
D33: 45958 | E33: 二 | F33: 337.67255 | G33: =AVERAGE(F33:F39) -> 340.19679 | I33: =F33/$C$1 -> 0.92260259 | J33: =AVERAGE(I33:I39) -> 0.92949941 | L33: 0.0024675466 | M33: =AVERAGE(L33:L39) -> 0.0024552869 | O33: 0.0021732369 | P33: =AVERAGE(O33:O39) -> 0.0022768681 | R33: 0.91666667 | S33: =AVERAGE(R33:R39) -> 0.91666667 | U33: 0.87 | V33: =AVERAGE(U33:U39) -> 0.87342857
D34: 45959 | E34: 三 | F34: 348.68158 | I34: =F34/$C$1 -> 0.95268191 | L34: 0.0024403744 | O34: 0.0022650323 | R34: 0.91666667 | U34: 0.87
D35: 45960 | E35: 四 | F35: 331.92437 | I35: =F35/$C$1 -> 0.90689717 | L35: 0.0024691257 | O35: 0.0022019024 | R35: 0.91666667 | U35: 0.872
D36: 45961 | E36: 五 | F36: 334.50307 | I36: =F36/$C$1 -> 0.91394282 | L36: 0.0024696228 | O36: 0.0025908488 | R36: 0.91666667 | U36: 0.872
D37: 45962 | E37: 六 | F37: 337.32625 | I37: =F37/$C$1 -> 0.92165643 | L37: 0.0024398551 | O37: 0.0025790165 | R37: 0.91666667 | U37: 0.875
D38: 45963 | E38: 日 | F38: 347.54377 | I38: =F38/$C$1 -> 0.94957315 | L38: 0.0024331814 | O38: 0.0020004283 | R38: 0.91666667 | U38: 0.875
D39: 45964 | E39: 一 | F39: 343.72591 | I39: =F39/$C$1 -> 0.93914183 | L39: 0.0024673021 | O39: 0.0021276117 | R39: 0.91666667 | U39: 0.88

Sheet （３）業績構成比
B2: （3）業績構成比
C3: 月份 | D3: 日期 | F3: 營業額 | I3: 品類業績
I4: 18℃-飯糰 | O4: 18℃-壽司手卷 | U4: 4℃-飯糰 | W4: 4℃-壽司手卷 | Y4: 主食 | AE4: 便當 | AG4: 熱食義麵 | AI4: 季節調理麵 | AK4: 微波小吃
F5: 日 | G5: 週累積 | H5: 月累積 | I5: 一配 | K5: 二配 | M5: 合計 | O5: 一配 | Q5: 二配 | S5: 合計 | U5: 一配 | W5: 一配 | Y5: 一配 | AA5: 二配 | AC5: 合計 | AE5: 一配 | AG5: 一配 | AI5: 一配 | AK5: 一配
I6: 業績(元) | J6: 比例(%) | K6: 業績(元) | L6: 比例(%) | M6: 業績(元) | N6: 比例(%) | O6: 業績(元) | P6: 比例(%) | Q6: 業績(元) | R6: 比例(%) | S6: 業績(元) | T6: 比例(%) | U6: 業績(元) | V6: 比例(%) | W6: 業績(元) | X6: 比例(%) | Y6: 業績(元) | Z6: 比例(%) | AA6: 業績(元) | AB6: 比例(%) | AC6: 業績(元) | AD6: 比例(%) | AE6: 業績(元) | AF6: 比例(%) | AG6: 業績(元) | AH6: 比例(%) | AI6: 業績(元) | AJ6: 比例(%) | AK6: 業績(元) | AL6: 比例(%)
C7: 10 | D7: 45930 | E7: 二 | F7: =SUM(M7,S7,U7,W7,AC7,AE7,AG7,AI7,AK7) -> 8551969 | G7: =SUM(F7:F13) -> 50444409 | I7: 719554.55 | J7: =I7/F7 -> 0.08413905 | K7: 795384.55 | L7: =K7/F7 -> 0.093006014 | M7: =SUM(I7+K7) -> 1514939.1 | N7: =M7/F7 -> 0.17714506 | O7: 212315.87 | P7: =O7/F7 -> 0.024826548 | Q7: 112672.39 | R7: =Q7/$F7 -> 0.013175023 | S7: =SUM(O7+Q7) -> 324988.26 | T7: =S7/F7 -> 0.038001571 | U7: 1002122.8 | V7: =U7/F7 -> 0.11718036 | W7: 15967.863 | X7: =W7/F7 -> 0.0018671564 | Y7: 790775.01 | Z7: =Y7/F7 -> 0.09246701 | AA7: 1095676.4 | AB7: =AA7/$F7 -> 0.12811979 | AC7: =SUM(Y7+AA7) -> 1886451.4 | AD7: =AC7/F7 -> 0.2205868 | AE7: 1280674.6 | AF7: =AE7/F7 -> 0.14975202 | AG7: 1163000.5 | AH7: =AG7/F7 -> 0.13599214 | AI7: 654699.71 | AJ7: =AI7/F7 -> 0.076555435 | AK7: 709124.64 | AL7: =AK7/F7 -> 0.082919458
D8: 45931 | E8: 三 | F8: =SUM(M8,S8,U8,W8,AC8,AE8,AG8,AI8,AK8) -> 7858716 | H8: =SUM(F8:F38) -> 224463487 | I8: 715251.51 | J8: =I8/F8 -> 0.091013788 | K8: 774813.38 | L8: =K8/F8 -> 0.098592872 | M8: =SUM(I8+K8) -> 1490064.9 | N8: =M8/F8 -> 0.18960666 | O8: 183209.01 | P8: =O8/F8 -> 0.023312843 | Q8: 109110.75 | R8: =Q8/$F8 -> 0.013884042 | S8: =SUM(O8+Q8) -> 292319.76 | T8: =S8/F8 -> 0.037196885 | U8: 714234.45 | V8: =U8/F8 -> 0.09088437 | W8: 142930.04 | X8: =W8/F8 -> 0.018187455 | Y8: 771807.27 | Z8: =Y8/F8 -> 0.098210353 | AA8: 1013692.3 | AB8: =AA8/$F8 -> 0.12898956 | AC8: =SUM(Y8+AA8) -> 1785499.6 | AD8: =AC8/F8 -> 0.22719991 | AE8: 1068254.1 | AF8: =AE8/F8 -> 0.1359324 | AG8: 1101680.4 | AH8: =AG8/F8 -> 0.1401858 | AI8: 640487.31 | AJ8: =AI8/F8 -> 0.081500248 | AK8: 623245.51 | AL8: =AK8/F8 -> 0.079306277
D9: 45932 | E9: 四 | F9: =SUM(M9,S9,U9,W9,AC9,AE9,AG9,AI9,AK9) -> 7240224 | I9: 638803.9 | J9: =I9/F9 -> 0.088229853 | K9: 709782.72 | L9: =K9/F9 -> 0.098033255 | M9: =SUM(I9+K9) -> 1348586.6 | N9: =M9/F9 -> 0.18626311 | O9: 168087.01 | P9: =O9/F9 -> 0.023215719 | Q9: 103531.42 | R9: =Q9/$F9 -> 0.014299477 | S9: =SUM(O9+Q9) -> 271618.43 | T9: =S9/F9 -> 0.037515197 | U9: 678120.21 | V9: =U9/F9 -> 0.093660115 | W9: 121058.02 | X9: =W9/F9 -> 0.016720204 | Y9: 713287.54 | Z9: =Y9/F9 -> 0.098517331 | AA9: 941658 | AB9: =AA9/$F9 -> 0.13005924 | AC9: =SUM(Y9+AA9) -> 1654945.5 | AD9: =AC9/F9 -> 0.22857657 | AE9: 1037069 | AF9: =AE9/F9 -> 0.14323714 | AG9: 979740.03 | AH9: =AG9/F9 -> 0.13531902 | AI9: 584172.03 | AJ9: =AI9/F9 -> 0.080684248 | AK9: 564914.14 | AL9: =AK9/F9 -> 0.0780244
D10: 45933 | E10: 五 | F10: =SUM(M10,S10,U10,W10,AC10,AE10,AG10,AI10,AK10) -> 6162506 | I10: 479861.71 | J10: =I10/F10 -> 0.07786795 | K10: 639452.13 | L10: =K10/F10 -> 0.10376495 | M10: =SUM(I10+K10) -> 1119313.8 | N10: =M10/F10 -> 0.1816329 | O10: 160197.73 | P10: =O10/F10 -> 0.025995549 | Q10: 85223.707 | R10: =Q10/$F10 -> 0.013829391 | S10: =SUM(O10+Q10) -> 245421.44 | T10: =S10/F10 -> 0.039824941 | U10: 557160.06 | V10: =U10/F10 -> 0.090411281 | W10: 89729.013 | X10: =W10/F10 -> 0.014560475 | Y10: 641494.12 | Z10: =Y10/F10 -> 0.10409631 | AA10: 914893.22 | AB10: =AA10/$F10 -> 0.14846123 | AC10: =SUM(Y10+AA10) -> 1556387.3 | AD10: =AC10/F10 -> 0.25255754 | AE10: 841320.42 | AF10: =AE10/F10 -> 0.13652245 | AG10: 723731.8 | AH10: =AG10/F10 -> 0.11744115 | AI10: 574995.02 | AJ10: =AI10/F10 -> 0.093305389 | AK10: 454447.07 | AL10: =AK10/F10 -> 0.073743875
D11: 45934 | E11: 六 | F11: =SUM(M11,S11,U11,W11,AC11,AE11,AG11,AI11,AK11) -> 6257631 | I11: 460314.43 | J11: =I11/F11 -> 0.073560495 | K11: 620519.59 | L11: =K11/F11 -> 0.099162062 | M11: =SUM(I11+K11) -> 1080834 | N11: =M11/F11 -> 0.17272256 | O11: 158636.16 | P11: =O11/F11 -> 0.025350834 | Q11: 86527.04 | R11: =Q11/$F11 -> 0.013827444 | S11: =SUM(O11+Q11) -> 245163.2 | T11: =S11/F11 -> 0.039178277 | U11: 555571.78 | V11: =U11/F11 -> 0.088783084 | W11: 113151.72 | X11: =W11/F11 -> 0.018082198 | Y11: 631970.86 | Z11: =Y11/F11 -> 0.10099203 | AA11: 954431.1 | AB11: =AA11/$F11 -> 0.15252275 | AC11: =SUM(Y11+AA11) -> 1586402 | AD11: =AC11/F11 -> 0.25351478 | AE11: 889137.79 | AF11: =AE11/F11 -> 0.14208856 | AG11: 754649.25 | AH11: =AG11/F11 -> 0.12059664 | AI11: 568744.83 | AJ11: =AI11/F11 -> 0.090888202 | AK11: 463976.44 | AL11: =AK11/F11 -> 0.074145701
D12: 45935 | E12: 日 | F12: =SUM(M12,S12,U12,W12,AC12,AE12,AG12,AI12,AK12) -> 6624573 | I12: 497773.62 | J12: =I12/F12 -> 0.075140484 | K12: 674622.41 | L12: =K12/F12 -> 0.10183636 | M12: =SUM(I12+K12) -> 1172396 | N12: =M12/F12 -> 0.17697685 | O12: 160860.73 | P12: =O12/F12 -> 0.024282429 | Q12: 86214.277 | R12: =Q12/$F12 -> 0.013014315 | S12: =SUM(O12+Q12) -> 247075 | T12: =S12/F12 -> 0.037296744 | U12: 619796.68 | V12: =U12/F12 -> 0.093560246 | W12: 137821.35 | X12: =W12/F12 -> 0.020804563 | Y12: 631382.85 | Z12: =Y12/F12 -> 0.095309215 | AA12: 958507.4 | AB12: =AA12/$F12 -> 0.14468969 | AC12: =SUM(Y12+AA12) -> 1589890.2 | AD12: =AC12/F12 -> 0.2399989 | AE12: 1027717.9 | AF12: =AE12/F12 -> 0.15513722 | AG12: 810231.6 | AH12: =AG12/F12 -> 0.12230699 | AI12: 487476.36 | AJ12: =AI12/F12 -> 0.07358608 | AK12: 532167.87 | AL12: =AK12/F12 -> 0.080332403
D13: 45936 | E13: 一 | F13: =SUM(M13,S13,U13,W13,AC13,AE13,AG13,AI13,AK13) -> 7748790 | I13: 677554.5 | J13: =I13/F13 -> 0.087440039 | K13: 777535.87 | L13: =K13/F13 -> 0.10034287 | M13: =SUM(I13+K13) -> 1455090.4 | N13: =M13/F13 -> 0.18778291 | O13: 188673.19 | P13: =O13/F13 -> 0.02434873 | Q13: 113341.41 | R13: =Q13/$F13 -> 0.014626982 | S13: =SUM(O13+Q13) -> 302014.6 | T13: =S13/F13 -> 0.038975711 | U13: 731080.92 | V13: =U13/F13 -> 0.094347752 | W13: 137010.25 | X13: =W13/F13 -> 0.017681503 | Y13: 781267.98 | Z13: =Y13/F13 -> 0.10082451 | AA13: 1059175 | AB13: =AA13/$F13 -> 0.13668908 | AC13: =SUM(Y13+AA13) -> 1840442.9 | AD13: =AC13/F13 -> 0.23751359 | AE13: 1064092.8 | AF13: =AE13/F13 -> 0.13732374 | AG13: 1051943.1 | AH13: =AG13/F13 -> 0.13575579 | AI13: 547469.92 | AJ13: =AI13/F13 -> 0.07065231 | AK13: 619645.1 | AL13: =AK13/F13 -> 0.079966692
D14: 45937 | E14: 二 | F14: =SUM(M14,S14,U14,W14,AC14,AE14,AG14,AI14,AK14) -> 8050194 | G14: =SUM(F14:F20) -> 50896038 | I14: 736776.46 | J14: =I14/F14 -> 0.091522821 | K14: 831797.45 | L14: =K14/F14 -> 0.10332639 | M14: =SUM(I14+K14) -> 1568573.9 | N14: =M14/F14 -> 0.19484921 | O14: 206332.65 | P14: =O14/F14 -> 0.025630767 | Q14: 119424.95 | R14: =Q14/$F14 -> 0.01483504 | S14: =SUM(O14+Q14) -> 325757.6 | T14: =S14/F14 -> 0.040465807 | U14: 748820.18 | V14: =U14/F14 -> 0.093018899 | W14: 115179.95 | X14: =W14/F14 -> 0.014307723 | Y14: 819732.6 | Z14: =Y14/F14 -> 0.10182768 | AA14: 1145149.5 | AB14: =AA14/$F14 -> 0.14225116 | AC14: =SUM(Y14+AA14) -> 1964882.1 | AD14: =AC14/F14 -> 0.24407884 | AE14: 1074151 | AF14: =AE14/F14 -> 0.13343169 | AG14: 1037300.7 | AH14: =AG14/F14 -> 0.12885413 | AI14: 583328.71 | AJ14: =AI14/F14 -> 0.072461448 | AK14: 632199.91 | AL14: =AK14/F14 -> 0.078532258
D15: 45938 | E15: 三 | F15: =SUM(M15,S15,U15,W15,AC15,AE15,AG15,AI15,AK15) -> 7653723 | I15: 700167.53 | J15: =I15/F15 -> 0.091480647 | K15: 739645.52 | L15: =K15/F15 -> 0.096638658 | M15: =SUM(I15+K15) -> 1439813 | N15: =M15/F15 -> 0.1881193 | O15: 183048.38 | P15: =O15/F15 -> 0.023916253 | Q15: 110508.19 | R15: =Q15/$F15 -> 0.014438488 | S15: =SUM(O15+Q15) -> 293556.57 | T15: =S15/F15 -> 0.038354741 | U15: 706521.43 | V15: =U15/F15 -> 0.092310818 | W15: 109808.72 | X15: =W15/F15 -> 0.014347099 | Y15: 800261.8 | Z15: =Y15/F15 -> 0.1045585 | AA15: 1113960 | AB15: =AA15/$F15 -> 0.14554486 | AC15: =SUM(Y15+AA15) -> 1914221.8 | AD15: =AC15/F15 -> 0.25010336 | AE15: 1074777.3 | AF15: =AE15/F15 -> 0.14042542 | AG15: 936019.21 | AH15: =AG15/F15 -> 0.12229594 | AI15: 574702.84 | AJ15: =AI15/F15 -> 0.075088011 | AK15: 604302.11 | AL15: =AK15/F15 -> 0.078955315
D16: 45939 | E16: 四 | F16: =SUM(M16,S16,U16,W16,AC16,AE16,AG16,AI16,AK16) -> 6660783 | I16: 484569.01 | J16: =I16/F16 -> 0.072749556 | K16: 664217.78 | L16: =K16/F16 -> 0.099720675 | M16: =SUM(I16+K16) -> 1148786.8 | N16: =M16/F16 -> 0.17247023 | O16: 149225.1 | P16: =O16/F16 -> 0.022403537 | Q16: 87616.274 | R16: =Q16/$F16 -> 0.01315405 | S16: =SUM(O16+Q16) -> 236841.37 | T16: =S16/F16 -> 0.035557587 | U16: 568656.79 | V16: =U16/F16 -> 0.085373865 | W16: 105430.09 | X16: =W16/F16 -> 0.015828483 | Y16: 638339.99 | Z16: =Y16/F16 -> 0.095835578 | AA16: 1034336 | AB16: =AA16/$F16 -> 0.15528745 | AC16: =SUM(Y16+AA16) -> 1672676 | AD16: =AC16/F16 -> 0.25112303 | AE16: 1023887.6 | AF16: =AE16/F16 -> 0.1537188 | AG16: 951204.75 | AH16: =AG16/F16 -> 0.14280675 | AI16: 463915.37 | AJ16: =AI16/F16 -> 0.069648774 | AK16: 489384.26 | AL16: =AK16/F16 -> 0.073472482
D17: 45940 | E17: 五 | F17: =SUM(M17,S17,U17,W17,AC17,AE17,AG17,AI17,AK17) -> 6259506 | I17: 459690.25 | J17: =I17/F17 -> 0.073438743 | K17: 643561.48 | L17: =K17/F17 -> 0.10281346 | M17: =SUM(I17+K17) -> 1103251.7 | N17: =M17/F17 -> 0.17625221 | O17: 152296.57 | P17: =O17/F17 -> 0.024330445 | Q17: 86586.33 | R17: =Q17/$F17 -> 0.013832774 | S17: =SUM(O17+Q17) -> 238882.9 | T17: =S17/F17 -> 0.038163218 | U17: 548937.14 | V17: =U17/F17 -> 0.08769656 | W17: 88411.309 | X17: =W17/F17 -> 0.014124327 | Y17: 574059.67 | Z17: =Y17/F17 -> 0.09171006 | AA17: 1082605 | AB17: =AA17/$F17 -> 0.17295375 | AC17: =SUM(Y17+AA17) -> 1656664.7 | AD17: =AC17/F17 -> 0.26466381 | AE17: 874646.65 | AF17: =AE17/F17 -> 0.13973094 | AG17: 785389.16 | AH17: =AG17/F17 -> 0.12547143 | AI17: 478999.15 | AJ17: =AI17/F17 -> 0.076523475 | AK17: 484323.28 | AL17: =AK17/F17 -> 0.077374042
D18: 45941 | E18: 六 | F18: =SUM(M18,S18,U18,W18,AC18,AE18,AG18,AI18,AK18) -> 6689233 | I18: 459099.81 | J18: =I18/F18 -> 0.068632653 | K18: 718664.47 | L18: =K18/F18 -> 0.10743601 | M18: =SUM(I18+K18) -> 1177764.3 | N18: =M18/F18 -> 0.17606866 | O18: 148663.67 | P18: =O18/F18 -> 0.022224322 | Q18: 87933.647 | R18: =Q18/$F18 -> 0.01314555 | S18: =SUM(O18+Q18) -> 236597.32 | T18: =S18/F18 -> 0.035369872 | U18: 596022.61 | V18: =U18/F18 -> 0.089101787 | W18: 78423.415 | X18: =W18/F18 -> 0.011723828 | Y18: 635136.61 | Z18: =Y18/F18 -> 0.094949094 | AA18: 1126727.1 | AB18: =AA18/$F18 -> 0.16843891 | AC18: =SUM(Y18+AA18) -> 1761863.7 | AD18: =AC18/F18 -> 0.263388 | AE18: 938903.22 | AF18: =AE18/F18 -> 0.14036037 | AG18: 913877.57 | AH18: =AG18/F18 -> 0.13661919 | AI18: 491309.24 | AJ18: =AI18/F18 -> 0.073447768 | AK18: 494471.62 | AL18: =AK18/F18 -> 0.073920525
D19: 45942 | E19: 日 | F19: =SUM(M19,S19,U19,W19,AC19,AE19,AG19,AI19,AK19) -> 7867103 | I19: 650748.36 | J19: =I19/F19 -> 0.082717661 | K19: 797070.62 | L19: =K19/F19 -> 0.10131692 | M19: =SUM(I19+K19) -> 1447819 | N19: =M19/F19 -> 0.18403458 | O19: 176493.15 | P19: =O19/F19 -> 0.022434326 | Q19: 108102.57 | R19: =Q19/$F19 -> 0.013741089 | S19: =SUM(O19+Q19) -> 284595.72 | T19: =S19/F19 -> 0.036175415 | U19: 675682.08 | V19: =U19/F19 -> 0.085887026 | W19: 84483.314 | X19: =W19/F19 -> 0.010738809 | Y19: 693099.79 | Z19: =Y19/F19 -> 0.088101018 | AA19: 1229940 | AB19: =AA19/$F19 -> 0.15633963 | AC19: =SUM(Y19+AA19) -> 1923039.7 | AD19: =AC19/F19 -> 0.24444065 | AE19: 1103944.2 | AF19: =AE19/F19 -> 0.14032411 | AG19: 1225854.4 | AH19: =AG19/F19 -> 0.15582031 | AI19: 560766 | AJ19: =AI19/F19 -> 0.07127986 | AK19: 560918.57 | AL19: =AK19/F19 -> 0.071299253
D20: 45943 | E20: 一 | F20: =SUM(M20,S20,U20,W20,AC20,AE20,AG20,AI20,AK20) -> 7715496 | I20: 625357.9 | J20: =I20/F20 -> 0.081052197 | K20: 785028.38 | L20: =K20/F20 -> 0.10174698 | M20: =SUM(I20+K20) -> 1410386.3 | N20: =M20/F20 -> 0.18279917 | O20: 174380.87 | P20: =O20/F20 -> 0.022601381 | Q20: 107038.22 | R20: =Q20/$F20 -> 0.013873149 | S20: =SUM(O20+Q20) -> 281419.09 | T20: =S20/F20 -> 0.03647453 | U20: 689571.21 | V20: =U20/F20 -> 0.089374839 | W20: 109837.79 | X20: =W20/F20 -> 0.014235998 | Y20: 686916.54 | Z20: =Y20/F20 -> 0.089030768 | AA20: 1236685 | AB20: =AA20/$F20 -> 0.16028587 | AC20: =SUM(Y20+AA20) -> 1923601.5 | AD20: =AC20/F20 -> 0.24931664 | AE20: 1071612.7 | AF20: =AE20/F20 -> 0.13889096 | AG20: 1128178.3 | AH20: =AG20/F20 -> 0.14622239 | AI20: 534610.1 | AJ20: =AI20/F20 -> 0.069290438 | AK20: 566279.08 | AL20: =AK20/F20 -> 0.073395033
D21: 45944 | E21: 二 | F21: =SUM(M21,S21,U21,W21,AC21,AE21,AG21,AI21,AK21) -> 7917911 | G21: =SUM(F21:F27) -> 51190043 | I21: 731403.67 | J21: =I21/F21 -> 0.092373313 | K21: 793387.43 | L21: =K21/F21 -> 0.10020161 | M21: =SUM(I21+K21) -> 1524791.1 | N21: =M21/F21 -> 0.19257492 | O21: 282610.38 | P21: =O21/F21 -> 0.035692543 | Q21: 113047.66 | R21: =Q21/$F21 -> 0.014277461 | S21: =SUM(O21+Q21) -> 395658.05 | T21: =S21/F21 -> 0.049970004 | U21: 690707.7 | V21: =U21/F21 -> 0.087233577 | W21: 104493.82 | X21: =W21/F21 -> 0.013197146 | Y21: 684585.17 | Z21: =Y21/F21 -> 0.086460327 | AA21: 1221913.4 | AB21: =AA21/$F21 -> 0.1543227 | AC21: =SUM(Y21+AA21) -> 1906498.6 | AD21: =AC21/F21 -> 0.24078303 | AE21: 1053622 | AF21: =AE21/F21 -> 0.13306818 | AG21: 1126192.4 | AH21: =AG21/F21 -> 0.14223352 | AI21: 531238.29 | AJ21: =AI21/F21 -> 0.067093238 | AK21: 584709.06 | AL21: =AK21/F21 -> 0.073846379
D22: 45945 | E22: 三 | F22: =SUM(M22,S22,U22,W22,AC22,AE22,AG22,AI22,AK22) -> 7086135 | I22: 632843.4 | J22: =I22/F22 -> 0.089307275 | K22: 719237.55 | L22: =K22/F22 -> 0.10149927 | M22: =SUM(I22+K22) -> 1352081 | N22: =M22/F22 -> 0.19080655 | O22: 210497.6 | P22: =O22/F22 -> 0.029705559 | Q22: 101601.39 | R22: =Q22/$F22 -> 0.014338055 | S22: =SUM(O22+Q22) -> 312099 | T22: =S22/F22 -> 0.044043614 | U22: 615205.05 | V22: =U22/F22 -> 0.086818139 | W22: 93079.843 | X22: =W22/F22 -> 0.013135488 | Y22: 618856.48 | Z22: =Y22/F22 -> 0.087333431 | AA22: 1037238.3 | AB22: =AA22/$F22 -> 0.14637575 | AC22: =SUM(Y22+AA22) -> 1656094.8 | AD22: =AC22/F22 -> 0.23370918 | AE22: 1015782.6 | AF22: =AE22/F22 -> 0.14334791 | AG22: 1022042.1 | AH22: =AG22/F22 -> 0.14423125 | AI22: 487617.24 | AJ22: =AI22/F22 -> 0.068812864 | AK22: 532133.43 | AL22: =AK22/F22 -> 0.075095017
D23: 45946 | E23: 四 | F23: =SUM(M23,S23,U23,W23,AC23,AE23,AG23,AI23,AK23) -> 7387104 | I23: 669044.96 | J23: =I23/F23 -> 0.090569317 | K23: 742044.79 | L23: =K23/F23 -> 0.10045138 | M23: =SUM(I23+K23) -> 1411089.8 | N23: =M23/F23 -> 0.1910207 | O23: 222344.27 | P23: =O23/F23 -> 0.030098977 | Q23: 112041.81 | R23: =Q23/$F23 -> 0.015167217 | S23: =SUM(O23+Q23) -> 334386.08 | T23: =S23/F23 -> 0.045266194 | U23: 649335.2 | V23: =U23/F23 -> 0.087901186 | W23: 84600.614 | X23: =W23/F23 -> 0.011452474 | Y23: 649647.6 | Z23: =Y23/F23 -> 0.087943476 | AA23: 1035941.9 | AB23: =AA23/$F23 -> 0.14023654 | AC23: =SUM(Y23+AA23) -> 1685589.5 | AD23: =AC23/F23 -> 0.22818001 | AE23: 1031893.8 | AF23: =AE23/F23 -> 0.13968855 | AG23: 1114338.7 | AH23: =AG23/F23 -> 0.1508492 | AI23: 525246.02 | AJ23: =AI23/F23 -> 0.071103104 | AK23: 550624.33 | AL23: =AK23/F23 -> 0.074538591
D24: 45947 | E24: 五 | F24: =SUM(M24,S24,U24,W24,AC24,AE24,AG24,AI24,AK24) -> 6524343 | I24: 602641.38 | J24: =I24/F24 -> 0.092368133 | K24: 681311.6 | L24: =K24/F24 -> 0.10442609 | M24: =SUM(I24+K24) -> 1283953 | N24: =M24/F24 -> 0.19679422 | O24: 219036.52 | P24: =O24/F24 -> 0.033572195 | Q24: 98455.717 | R24: =Q24/$F24 -> 0.015090518 | S24: =SUM(O24+Q24) -> 317492.23 | T24: =S24/F24 -> 0.048662713 | U24: 526020.46 | V24: =U24/F24 -> 0.080624281 | W24: 44247.877 | X24: =W24/F24 -> 0.0067819666 | Y24: 585085.69 | Z24: =Y24/F24 -> 0.089677335 | AA24: 1025306.2 | AB24: =AA24/$F24 -> 0.15715088 | AC24: =SUM(Y24+AA24) -> 1610391.9 | AD24: =AC24/F24 -> 0.24682821 | AE24: 841031.26 | AF24: =AE24/F24 -> 0.12890666 | AG24: 934989.01 | AH24: =AG24/F24 -> 0.14330777 | AI24: 498333.68 | AJ24: =AI24/F24 -> 0.076380669 | AK24: 467883.58 | AL24: =AK24/F24 -> 0.071713517
D25: 45948 | E25: 六 | F25: =SUM(M25,S25,U25,W25,AC25,AE25,AG25,AI25,AK25) -> 6552897 | I25: 583543.65 | J25: =I25/F25 -> 0.089051248 | K25: 741847.15 | L25: =K25/F25 -> 0.11320904 | M25: =SUM(I25+K25) -> 1325390.8 | N25: =M25/F25 -> 0.20226028 | O25: 207840.89 | P25: =O25/F25 -> 0.031717406 | Q25: 91697.961 | R25: =Q25/$F25 -> 0.0139935 | S25: =SUM(O25+Q25) -> 299538.86 | T25: =S25/F25 -> 0.045710906 | U25: 550069.81 | V25: =U25/F25 -> 0.083942997 | W25: 47135.989 | X25: =W25/F25 -> 0.0071931527 | Y25: 585332.47 | Z25: =Y25/F25 -> 0.089324229 | AA25: 1061582.4 | AB25: =AA25/$F25 -> 0.16200199 | AC25: =SUM(Y25+AA25) -> 1646914.8 | AD25: =AC25/F25 -> 0.25132622 | AE25: 819201.84 | AF25: =AE25/F25 -> 0.12501369 | AG25: 898892.54 | AH25: =AG25/F25 -> 0.13717483 | AI25: 501653.19 | AJ25: =AI25/F25 -> 0.076554414 | AK25: 464099.13 | AL25: =AK25/F25 -> 0.070823504
D26: 45949 | E26: 日 | F26: =SUM(M26,S26,U26,W26,AC26,AE26,AG26,AI26,AK26) -> 7868086 | I26: 757932.61 | J26: =I26/F26 -> 0.096329985 | K26: 821480.54 | L26: =K26/F26 -> 0.10440665 | M26: =SUM(I26+K26) -> 1579413.1 | N26: =M26/F26 -> 0.20073664 | O26: 257113.59 | P26: =O26/F26 -> 0.032678035 | Q26: 110706.68 | R26: =Q26/$F26 -> 0.014070344 | S26: =SUM(O26+Q26) -> 367820.27 | T26: =S26/F26 -> 0.04674838 | U26: 670934.19 | V26: =U26/F26 -> 0.08527286 | W26: 72956.48 | X26: =W26/F26 -> 0.0092724558 | Y26: 638561.35 | Z26: =Y26/F26 -> 0.08115841 | AA26: 1180184 | AB26: =AA26/$F26 -> 0.14999633 | AC26: =SUM(Y26+AA26) -> 1818745.4 | AD26: =AC26/F26 -> 0.23115474 | AE26: 1093940.1 | AF26: =AE26/F26 -> 0.1390351 | AG26: 1134988.3 | AH26: =AG26/F26 -> 0.14425215 | AI26: 572519.53 | AJ26: =AI26/F26 -> 0.072764777 | AK26: 556768.66 | AL26: =AK26/F26 -> 0.07076291
D27: 45950 | E27: 一 | F27: =SUM(M27,S27,U27,W27,AC27,AE27,AG27,AI27,AK27) -> 7853567 | I27: 737936.34 | J27: =I27/F27 -> 0.093961933 | K27: 811644.64 | L27: =K27/F27 -> 0.10334726 | M27: =SUM(I27+K27) -> 1549581 | N27: =M27/F27 -> 0.19730919 | O27: 236418 | P27: =O27/F27 -> 0.030103264 | Q27: 110800.85 | R27: =Q27/$F27 -> 0.014108347 | S27: =SUM(O27+Q27) -> 347218.85 | T27: =S27/F27 -> 0.044211611 | U27: 695789.06 | V27: =U27/F27 -> 0.088595292 | W27: 94814.113 | X27: =W27/F27 -> 0.012072745 | Y27: 664993.4 | Z27: =Y27/F27 -> 0.08467406 | AA27: 1217974.7 | AB27: =AA27/$F27 -> 0.15508554 | AC27: =SUM(Y27+AA27) -> 1882968.1 | AD27: =AC27/F27 -> 0.2397596 | AE27: 1129705.1 | AF27: =AE27/F27 -> 0.14384611 | AG27: 1112279.7 | AH27: =AG27/F27 -> 0.14162732 | AI27: 475130.05 | AJ27: =AI27/F27 -> 0.060498631 | AK27: 566081.09 | AL27: =AK27/F27 -> 0.072079488
D28: 45951 | E28: 二 | F28: =SUM(M28,S28,U28,W28,AC28,AE28,AG28,AI28,AK28) -> 7817095 | G28: =SUM(F28:F34) -> 49497330 | I28: 740365.86 | J28: =I28/F28 -> 0.094711125 | K28: 797416.01 | L28: =K28/F28 -> 0.10200925 | M28: =SUM(I28+K28) -> 1537781.9 | N28: =M28/F28 -> 0.19672038 | O28: 232224.79 | P28: =O28/F28 -> 0.0297073 | Q28: 112969.38 | R28: =Q28/$F28 -> 0.014451581 | S28: =SUM(O28+Q28) -> 345194.17 | T28: =S28/F28 -> 0.044158881 | U28: 676861.02 | V28: =U28/F28 -> 0.086587284 | W28: 73972.827 | X28: =W28/F28 -> 0.0094629561 | Y28: 674348.43 | Z28: =Y28/F28 -> 0.086265861 | AA28: 1193196 | AB28: =AA28/$F28 -> 0.15263932 | AC28: =SUM(Y28+AA28) -> 1867544.5 | AD28: =AC28/F28 -> 0.23890518 | AE28: 1112459.9 | AF28: =AE28/F28 -> 0.14231117 | AG28: 1159853.5 | AH28: =AG28/F28 -> 0.14837398 | AI28: 469574.86 | AJ28: =AI28/F28 -> 0.060070252 | AK28: 573852.35 | AL28: =AK28/F28 -> 0.073409924
D29: 45952 | E29: 三 | F29: =SUM(M29,S29,U29,W29,AC29,AE29,AG29,AI29,AK29) -> 7419770 | I29: 720292.77 | J29: =I29/F29 -> 0.097077507 | K29: 729184.1 | L29: =K29/F29 -> 0.098275836 | M29: =SUM(I29+K29) -> 1449476.9 | N29: =M29/F29 -> 0.19535334 | O29: 227354.95 | P29: =O29/F29 -> 0.030641778 | Q29: 104596.18 | R29: =Q29/$F29 -> 0.014096958 | S29: =SUM(O29+Q29) -> 331951.13 | T29: =S29/F29 -> 0.044738736 | U29: 663779.33 | V29: =U29/F29 -> 0.089460904 | W29: 65687.861 | X29: =W29/F29 -> 0.0088530859 | Y29: 643190.46 | Z29: =Y29/F29 -> 0.086686037 | AA29: 1083424.8 | AB29: =AA29/$F29 -> 0.14601865 | AC29: =SUM(Y29+AA29) -> 1726615.2 | AD29: =AC29/F29 -> 0.23270468 | AE29: 1056260.8 | AF29: =AE29/F29 -> 0.14235762 | AG29: 1134585.1 | AH29: =AG29/F29 -> 0.15291379 | AI29: 440253.38 | AJ29: =AI29/F29 -> 0.059335179 | AK29: 551160.25 | AL29: =AK29/F29 -> 0.074282659
D30: 45953 | E30: 四 | F30: =SUM(M30,S30,U30,W30,AC30,AE30,AG30,AI30,AK30) -> 6310328 | I30: 541723.26 | J30: =I30/F30 -> 0.085847085 | K30: 684592.21 | L30: =K30/F30 -> 0.10848758 | M30: =SUM(I30+K30) -> 1226315.5 | N30: =M30/F30 -> 0.19433467 | O30: 188651.67 | P30: =O30/F30 -> 0.0298957 | Q30: 85952.425 | R30: =Q30/$F30 -> 0.013620912 | S30: =SUM(O30+Q30) -> 274604.1 | T30: =S30/F30 -> 0.043516613 | U30: 561019.15 | V30: =U30/F30 -> 0.088904912 | W30: 47092.364 | X30: =W30/F30 -> 0.0074627442 | Y30: 572770.09 | Z30: =Y30/F30 -> 0.090767087 | AA30: 947218.47 | AB30: =AA30/$F30 -> 0.15010606 | AC30: =SUM(Y30+AA30) -> 1519988.6 | AD30: =AC30/F30 -> 0.24087315 | AE30: 915588.43 | AF30: =AE30/F30 -> 0.14509364 | AG30: 887020.68 | AH30: =AG30/F30 -> 0.14056649 | AI30: 402492.24 | AJ30: =AI30/F30 -> 0.063783094 | AK30: 476206.99 | AL30: =AK30/F30 -> 0.075464697
D31: 45954 | E31: 五 | F31: =SUM(M31,S31,U31,W31,AC31,AE31,AG31,AI31,AK31) -> 6007757 | I31: 511007.57 | J31: =I31/F31 -> 0.085057962 | K31: 658527.51 | L31: =K31/F31 -> 0.10961287 | M31: =SUM(I31+K31) -> 1169535.1 | N31: =M31/F31 -> 0.19467084 | O31: 230258.08 | P31: =O31/F31 -> 0.038326797 | Q31: 86629.513 | R31: =Q31/$F31 -> 0.01441961 | S31: =SUM(O31+Q31) -> 316887.59 | T31: =S31/F31 -> 0.052746407 | U31: 521336.83 | V31: =U31/F31 -> 0.086777283 | W31: 49622.107 | X31: =W31/F31 -> 0.0082596728 | Y31: 570295.39 | Z31: =Y31/F31 -> 0.094926508 | AA31: 957368.96 | AB31: =AA31/$F31 -> 0.15935547 | AC31: =SUM(Y31+AA31) -> 1527664.4 | AD31: =AC31/F31 -> 0.25428198 | AE31: 776718.89 | AF31: =AE31/F31 -> 0.129286 | AG31: 783952.7 | AH31: =AG31/F31 -> 0.13049008 | AI31: 404630.14 | AJ31: =AI31/F31 -> 0.067351283 | AK31: 457409.31 | AL31: =AK31/F31 -> 0.076136453
D32: 45955 | E32: 六 | F32: =SUM(M32,S32,U32,W32,AC32,AE32,AG32,AI32,AK32) -> 6324783 | I32: 496476.88 | J32: =I32/F32 -> 0.078497061 | K32: 716808.39 | L32: =K32/F32 -> 0.11333328 | M32: =SUM(I32+K32) -> 1213285.3 | N32: =M32/F32 -> 0.19183034 | O32: 217128.64 | P32: =O32/F32 -> 0.034329816 | Q32: 87124.756 | R32: =Q32/$F32 -> 0.013775138 | S32: =SUM(O32+Q32) -> 304253.39 | T32: =S32/F32 -> 0.048104954 | U32: 562703.92 | V32: =U32/F32 -> 0.088968098 | W32: 55077.91 | X32: =W32/F32 -> 0.0087082688 | Y32: 592537.85 | Z32: =Y32/F32 -> 0.093685088 | AA32: 1020185.6 | AB32: =AA32/$F32 -> 0.1612997 | AC32: =SUM(Y32+AA32) -> 1612723.4 | AD32: =AC32/F32 -> 0.25498479 | AE32: 791969.15 | AF32: =AE32/F32 -> 0.12521681 | AG32: 901771.97 | AH32: =AG32/F32 -> 0.14257754 | AI32: 410497.82 | AJ32: =AI32/F32 -> 0.064903069 | AK32: 472500.15 | AL32: =AK32/F32 -> 0.074706143
D33: 45956 | E33: 日 | F33: =SUM(M33,S33,U33,W33,AC33,AE33,AG33,AI33,AK33) -> 7684569 | I33: 708600.62 | J33: =I33/F33 -> 0.092210848 | K33: 768012.66 | L33: =K33/F33 -> 0.099942191 | M33: =SUM(I33+K33) -> 1476613.3 | N33: =M33/F33 -> 0.19215304 | O33: 274677.66 | P33: =O33/F33 -> 0.035744055 | Q33: 108330.21 | R33: =Q33/$F33 -> 0.01409711 | S33: =SUM(O33+Q33) -> 383007.87 | T33: =S33/F33 -> 0.049841165 | U33: 668295.82 | V33: =U33/F33 -> 0.086965947 | W33: 65736.81 | X33: =W33/F33 -> 0.0085543912 | Y33: 717947.4 | Z33: =Y33/F33 -> 0.093427152 | AA33: 1090541.6 | AB33: =AA33/$F33 -> 0.14191317 | AC33: =SUM(Y33+AA33) -> 1808489 | AD33: =AC33/F33 -> 0.23534033 | AE33: 1101814.4 | AF33: =AE33/F33 -> 0.14338012 | AG33: 1155691.3 | AH33: =AG33/F33 -> 0.15039117 | AI33: 455711.17 | AJ33: =AI33/F33 -> 0.059302112 | AK33: 569209.35 | AL33: =AK33/F33 -> 0.074071734
D34: 45957 | E34: 一 | F34: =SUM(M34,S34,U34,W34,AC34,AE34,AG34,AI34,AK34) -> 7933028 | I34: 689875.04 | J34: =I34/F34 -> 0.086962385 | K34: 922491.01 | L34: =K34/F34 -> 0.11628486 | M34: =SUM(I34+K34) -> 1612366.1 | N34: =M34/F34 -> 0.20324724 | O34: 257499.3 | P34: =O34/F34 -> 0.032459145 | Q34: 106080.33 | R34: =Q34/$F34 -> 0.013371984 | S34: =SUM(O34+Q34) -> 363579.63 | T34: =S34/F34 -> 0.045831129 | U34: 647910.18 | V34: =U34/F34 -> 0.081672494 | W34: 61201.831 | X34: =W34/F34 -> 0.0077148135 | Y34: 706376.46 | Z34: =Y34/F34 -> 0.089042477 | AA34: 1385124.7 | AB34: =AA34/$F34 -> 0.17460227 | AC34: =SUM(Y34+AA34) -> 2091501.2 | AD34: =AC34/F34 -> 0.26364475 | AE34: 1079903.8 | AF34: =AE34/F34 -> 0.13612756 | AG34: 1103387.3 | AH34: =AG34/F34 -> 0.13908778 | AI34: 413192.29 | AJ34: =AI34/F34 -> 0.052085067 | AK34: 559985.79 | AL34: =AK34/F34 -> 0.07058916
D35: 45958 | E35: 二 | F35: =SUM(M35,S35,U35,W35,AC35,AE35,AG35,AI35,AK35) -> 8874807 | G35: =SUM(F35:F41) -> 52649495 | I35: 780746.64 | J35: =I35/F35 -> 0.087973366 | K35: 911239.32 | L35: =K35/F35 -> 0.10267709 | M35: =SUM(I35+K35) -> 1691986 | N35: =M35/F35 -> 0.19065045 | O35: 271416.89 | P35: =O35/F35 -> 0.030582849 | Q35: 110287.01 | R35: =Q35/$F35 -> 0.012426976 | S35: =SUM(O35+Q35) -> 381703.9 | T35: =S35/F35 -> 0.043009825 | U35: 656894.59 | V35: =U35/F35 -> 0.074017902 | W35: 326083.5 | X35: =W35/F35 -> 0.036742602 | Y35: 700989.34 | Z35: =Y35/F35 -> 0.078986432 | AA35: 1516347.3 | AB35: =AA35/$F35 -> 0.17085975 | AC35: =SUM(Y35+AA35) -> 2217336.7 | AD35: =AC35/F35 -> 0.24984619 | AE35: 1283032.9 | AF35: =AE35/F35 -> 0.14457023 | AG35: 1049488.8 | AH35: =AG35/F35 -> 0.11825483 | AI35: 472206.16 | AJ35: =AI35/F35 -> 0.053207484 | AK35: 796074.54 | AL35: =AK35/F35 -> 0.089700491
D36: 45959 | E36: 三 | F36: =SUM(M36,S36,U36,W36,AC36,AE36,AG36,AI36,AK36) -> 8157355 | I36: 741769.41 | J36: =I36/F36 -> 0.090932589 | K36: 911358.13 | L36: =K36/F36 -> 0.11172226 | M36: =SUM(I36+K36) -> 1653127.5 | N36: =M36/F36 -> 0.20265485 | O36: 268793.45 | P36: =O36/F36 -> 0.032951054 | Q36: 111574.07 | R36: =Q36/$F36 -> 0.013677726 | S36: =SUM(O36+Q36) -> 380367.52 | T36: =S36/F36 -> 0.046628781 | U36: 647363.6 | V36: =U36/F36 -> 0.079359499 | W36: 211714.89 | X36: =W36/F36 -> 0.025953864 | Y36: 676052.95 | Z36: =Y36/F36 -> 0.08287649 | AA36: 1364309 | AB36: =AA36/$F36 -> 0.16724894 | AC36: =SUM(Y36+AA36) -> 2040361.9 | AD36: =AC36/F36 -> 0.25012543 | AE36: 1168977.6 | AF36: =AE36/F36 -> 0.14330351 | AG36: 940949.52 | AH36: =AG36/F36 -> 0.11534983 | AI36: 411972.81 | AJ36: =AI36/F36 -> 0.050503234 | AK36: 702519.62 | AL36: =AK36/F36 -> 0.086121007
D37: 45960 | E37: 四 | F37: =SUM(M37,S37,U37,W37,AC37,AE37,AG37,AI37,AK37) -> 7556926 | I37: 676655.12 | J37: =I37/F37 -> 0.089541054 | K37: 821105.69 | L37: =K37/F37 -> 0.10865605 | M37: =SUM(I37+K37) -> 1497760.8 | N37: =M37/F37 -> 0.1981971 | O37: 239899.99 | P37: =O37/F37 -> 0.031745712 | Q37: 110774.38 | R37: =Q37/$F37 -> 0.014658656 | S37: =SUM(O37+Q37) -> 350674.38 | T37: =S37/F37 -> 0.046404368 | U37: 606522.59 | V37: =U37/F37 -> 0.080260491 | W37: 194750.99 | X37: =W37/F37 -> 0.025771192 | Y37: 642678.45 | Z37: =Y37/F37 -> 0.085044957 | AA37: 1165803.2 | AB37: =AA37/$F37 -> 0.15426951 | AC37: =SUM(Y37+AA37) -> 1808481.7 | AD37: =AC37/F37 -> 0.23931446 | AE37: 1092729.8 | AF37: =AE37/F37 -> 0.14459978 | AG37: 926437.92 | AH37: =AG37/F37 -> 0.12259455 | AI37: 400515.05 | AJ37: =AI37/F37 -> 0.052999732 | AK37: 679052.73 | AL37: =AK37/F37 -> 0.089858327
