Workbook

Sheet 填寫舉例
A2: 7 | B2: 月別 | C2: 工廠名 | D2: ・・・・・・・・
A4: （１）收支狀況 | E4: ※單位：千元 | G4: （２）ＫＰＩ達成進度 | M4: （３）業績構成比 | S4: （４）訂單數量構成比
B5: 當月 | C5: 前月 | D5: 差異 | E5: 累計 | H5: KPI | I5: 當月 | J5: 前月 | K5: 累計 | L5: ※補充 | N5: 當月 | O5: 比例 | P5: 前月 | Q5: 差異 | T5: 當月 | U5: 比例 | V5: 前月 | W5: 差異
A6: 業績金額 | B6: 500000 | C6: 510000 | D6: =B6-C6 -> -10000 | E6: =B6+C6 -> 1010000 | G6: 人時生產性1 | H6: 110 | I6: 100 | J6: 90 | L6: 個／MH | M6: 飯糰 | N6: 150000 | O6: =IFERROR(N6/$B$6,"") -> 0.3 | P6: 0.4 | Q6: =IFERROR(O6-P6,"") -> -0.1 | S6: 飯糰 | T6: 35000 | U6: =IFERROR(T6/$B$7,"") -> 0.35 | V6: 0.3 | W6: =IFERROR(U6-V6,"") -> 0.05
A7: 訂單數量 | B7: 100000 | C7: 110000 | D7: =B7-C7 -> -10000 | E7: =B7+C7 -> 210000 | G7: 人時生產性2 | H7: 0.8 | I7: 0.85 | J7: 0.81 | K7: 0.84 | L7: 達成率 | M7: 大口飯糰 | N7: 100000 | O7: =IFERROR(N7/$B$6,"") -> 0.2 | P7: 0.15 | Q7: =IFERROR(O7-P7,"") -> 0.05 | S7: 大口飯糰 | T7: 30000 | U7: =IFERROR(T7/$B$7,"") -> 0.3 | V7: 0.15 | W7: =IFERROR(U7-V7,"") -> 0.15
A8: 材料費 | B8: 250000 | C8: 260000 | D8: =B8-C8 -> -10000 | E8: =B8+C8 -> 510000 | G8: 半成品報廢 | H8: 0.0025 | I8: 0.0024 | J8: 0.0023 | K8: 0.00235 | L8: 報廢率 | M8: 便當 | N8: 160000 | O8: =IFERROR(N8/$B$6,"") -> 0.32 | P8: 0.28 | Q8: =IFERROR(O8-P8,"") -> 0.04 | S8: 便當 | T8: 20000 | U8: =IFERROR(T8/$B$7,"") -> 0.2 | V8: 0.28 | W8: =IFERROR(U8-V8,"") -> -0.08
A9: 材料費率 | B9: =B8/B6 -> 0.5 | C9: =C8/C6 -> 0.50980392 | D9: =B9-C9 -> -0.0098039216 | E9: =(B9+C9)/2 -> 0.50490196 | G9: 半成品超用 | H9: 0.006 | I9: 0.009 | J9: 0.0095 | K9: 0.0092 | L9: 超用率 | M9: 調理麵 | N9: 90000 | O9: =IFERROR(N9/$B$6,"") -> 0.18 | P9: 0.17 | Q9: =IFERROR(O9-P9,"") -> 0.01 | S9: 調理麵 | T9: 15000 | U9: =IFERROR(T9/$B$7,"") -> 0.15 | V9: 0.27 | W9: =IFERROR(U9-V9,"") -> -0.12
A10: 勞務成本 | B10: 100000 | C10: 105000 | D10: =B10-C10 -> -5000 | E10: =B10+C10 -> 205000 | G10: 固定產線 | H10: 0.95 | I10: 0.9 | J10: 0.92 | K10: 0.91 | L10: 導入率 | M10: 調理麵包 | N10: - | O10: =IFERROR(N10/$B$6,"") | P10: -% | Q10: =IFERROR(O10-P10,"") | S10: 調理麵包 | T10: - | U10: =IFERROR(T10/$B$7,"") | V10: -% | W10: =IFERROR(U10-V10,"")
A11: 勞務費率 | B11: =B10/B6 -> 0.2 | C11: =C10/C6 -> 0.20588235 | D11: =B11-C11 -> -0.0058823529 | E11: =(B11+C11)/2 -> 0.20294118 | G11: 教育訓練 | H11: 0.8 | I11: 0.85 | J11: 1 | K11: 0.92 | L11: 實施率 | M11: 袋裝調理麵包 | N11: - | O11: =IFERROR(N11/$B$6,"") | P11: -% | Q11: =IFERROR(O11-P11,"") | S11: 袋裝調理麵包 | T11: - | U11: =IFERROR(T11/$B$7,"") | V11: -% | W11: =IFERROR(U11-V11,"")
M12: 義大利麵 | N12: - | O12: =IFERROR(N12/$B$6,"") | P12: -% | Q12: =IFERROR(O12-P12,"") | S12: 義大利麵 | T12: - | U12: =IFERROR(T12/$B$7,"") | V12: -% | W12: =IFERROR(U12-V12,"")
A13: （５）品群別人時生產性 | M13: 調理包 | N13: - | O13: =IFERROR(N13/$B$6,"") | P13: -% | Q13: =IFERROR(O13-P13,"") | S13: 調理包 | T13: - | U13: =IFERROR(T13/$B$7,"") | V13: -% | W13: =IFERROR(U13-V13,"")
B14: 當月 | C14: 前月 | D14: 差異 | E14: 累計 | H14: 當月 | I14: 前月 | J14: 差異 | K14: 累計 | O14: =SUM(O6:O13) -> 1 | P14: =SUM(P6:P13) -> 1 | U14: =SUM(U6:U13) -> 1 | V14: =SUM(V6:V13) -> 1
A15: 飯糰 | B15: 600 | C15: 660 | D15: =B15-C15 -> -60 | E15: =(B15+C15)/2 -> 630 | G15: 調理麵包 | J15: =H15-I15 -> 0 | M15: （７）原因別分析
A16: 大口飯糰 | B16: 800 | C16: 780 | D16: =B16-C16 -> 20 | E16: =(B16+C16)/2 -> 790 | G16: 袋裝調理麵包 | J16: =H16-I16 -> 0 | N16: 合計 | P16: 作業原因 | R16: 規格原因
A17: 便當 | B17: 130 | C17: 111 | D17: =B17-C17 -> 19 | E17: =(B17+C17)/2 -> 120.5 | G17: 義大利麵 | J17: =H17-I17 -> 0 | N17: 金額 | O17: 比例 | P17: 金額 | Q17: 比例 | R17: 金額 | S17: 比例
A18: 調理麵 | B18: 140 | C18: 165 | D18: =B18-C18 -> -25 | E18: =(B18+C18)/2 -> 152.5 | G18: 調理包 | J18: =H18-I18 -> 0 | M18: 半成品報廢 | N18: 1200 | O18: =N18/$B$6 -> 0.0024 | P18: 900 | Q18: =IFERROR(P18/$B$6,"") -> 0.0018 | R18: 300 | S18: =IFERROR(R18/$B$6,"") -> 0.0006
M19: 半成品超用 | N19: 4500 | O19: =N19/$B$6 -> 0.009 | P19: 3500 | Q19: =IFERROR(P19/$B$6,"") -> 0.007 | R19: 1000 | S19: =IFERROR(R19/$B$6,"") -> 0.002
A20: （６）人時生產性前幾名品項
B21: 排名 | C21: 商品名 | F21: 人數 | G21: 產能 | H21: 人時生產性 | I21: 前月比 | J21: 主要原因&對策 | M21: （８）報廢原因別前幾名品項
A22: 飯糰 | B22: 1 | C22: 手巻明太子 | F22: 3 | G22: 3000 | H22: 1000 | I22: 10 | J22: 減少暫時停止生產,人時UP | M22: 半成品報廢 | N22: 排名 | O22: 商品名 | R22: 半成品名 | U22: 單價 | V22: 報廢率 | W22: 數量 | X22: 金額 | Y22: 前月比 | Z22: 主要原因&對策
B23: 2 | M23: 作業原因 | N23: 1 | O23: 明太子海苔便當 | R23: 油炸白身魚 | U23: 10 | V23: 0.15 | W23: 10 | X23: =W23*U23 -> 100 | Y23: 80 | Z23: 油調過多報廢。變更條件。
B24: 3 | N24: 2 | X24: =W24*U24 -> 0
B25: 4 | N25: 3 | X25: =W25*U25 -> 0
B26: 5 | N26: 4 | X26: =W26*U26 -> 0
B27: ▼1 | C27: 手巻卵黄雞絞肉 | F27: 4 | G27: 2800 | H27: 700 | I27: 6/30新商品 | J27: 因組裝2食材,人員增加,產速減少 | N27: 5 | X27: =W27*U27 -> 0
B28: ▼2 | U28: 前幾名合計比例 | V28: =X28/N18 -> 0.083333333 | W28: 前幾名合計金額 | X28: =SUM(X23:X27) -> 100
B29: ▼3 | M29: 規格原因 | N29: 1 | O29: 海老炒飯 | R29: 川燙蝦子拌醬 | U29: 5.55 | V29: 0.21 | W29: 50 | X29: =W29*U29 -> 277.5 | Y29: 35 | Z29: 蝦子入數不足
B30: ▼4 | N30: 2 | X30: =W30*U30 -> 0
B31: ▼5 | N31: 3 | X31: =W31*U31 -> 0
N32: 4 | X32: =W32*U32 -> 0
B33: 排名 | C33: 商品名 | F33: 人數 | G33: 產能 | H33: 人時生產性 | I33: 前月比 | J33: 主要原因&對策 | N33: 5 | X33: =W33*U33 -> 0
A34: 大口飯糰 | B34: 1 | C34: 直巻明太子美奶茲 | F34: 3 | G34: 2500 | H34: 833.33 | I34: 20 | J34: 透由調整速度提升。 | U34: 前幾名合計比例 | V34: =X34/N18 -> 0.23125 | W34: 前幾名合計金額 | X34: =SUM(X29:X33) -> 277.5
B35: 2
B36: 3 | M36: 半成品超用 | N36: 排名 | O36: 商品名 | R36: 半成品名 | U36: 單價 | V36: 報廢率 | W36: 數量 | X36: 金額 | Y36: 前月比 | Z36: 主要原因&對策
B37: 4 | M37: 作業原因 | N37: 1 | O37: 特製醬汁炙燒牛五花便當 | R37: 牛五花醬汁 | U37: 25 | V37: 0.25 | W37: 10 | X37: =W37*U37 -> 250 | Y37: 150 | Z37: 難度有差異。調理指導。
B38: 5 | N38: 2 | X38: =W38*U38 -> 0
B39: ▼1 | C39: 大口飯糰燒肉美奶滋 | F39: 7 | G39: 2200 | H39: 314.29 | I39: -15 | J39: 因摺疊增員。實施教育訓練。 | N39: 3 | X39: =W39*U39 -> 0
B40: ▼2 | N40: 4 | X40: =W40*U40 -> 0
B41: ▼3 | N41: 5 | X41: =W41*U41 -> 0
B42: ▼4 | U42: 前幾名合計比例 | V42: =X42/N19 -> 0.055555556 | W42: 前幾名合計金額 | X42: =SUM(X37:X41) -> 250
...

Sheet 生產管理報表(月)
A1: 生產管理報表
A3: 月別 | B3: 12 | C3: 工廠 | D3: 晉欣廠
A4: （１）收支狀況 | E4: ※單位：千元 | G4: （２）ＫＰＩ達成進度
A5: 項目 | B5: 當月 | C5: 前月 | D5: 差異 | E5: 累計 | G5: 項目 | H5: KPI | I5: 當月 | J5: 前月 | K5: 累計 | L5: ※補充
A6: 業績金額 | B6: ='（１）收支狀況'!H9/1000 -> 219461.72 | C6: 213755.72 | D6: =B6-C6 -> 5705.996 | E6: =B6 -> 219461.72 | G6: 人時性(個/月均) | H6: 266 | I6: ='（２）ＫＰＩ達成進度'!H9 -> 328.81666 | J6: 337.28292 | K6: =I6 -> 328.81666 | L6: 個／MH
A7: 訂單數量 | B7: ='（１）收支狀況'!K9 -> 6618327 | C7: 6494709 | D7: =B7-C7 -> 123618 | E7: =B7 -> 6618327 | G7: 人時達成率(%/月均) | H7: 0.8 | I7: ='（２）ＫＰＩ達成進度'!K9 -> 0.8981902 | J7: 0.92153803 | K7: =I7 -> 0.8981902 | L7: 達成率
A8: 材料費 | B8: ='（１）收支狀況'!N9/1000 -> 148488.87 | C8: 141787.02 | D8: =B8-C8 -> 6701.846 | E8: =B8 -> 148488.87 | G8: 半成品-報廢(%) | H8: 0.0025 | I8: ='（２）ＫＰＩ達成進度'!N9 -> 0.0024556526 | J8: 0.0024542488 | K8: =I8 -> 0.0024556526 | L8: 報廢率
A9: 材料費率 | B9: ='（１）收支狀況'!Q9 -> 0.67660489 | C9: 0.66331336 | D9: =B9-C9 -> 0.013291533 | E9: =B9 -> 0.67660489 | G9: 半成品-超用(%) | H9: 0.0026 | I9: ='（２）ＫＰＩ達成進度'!Q9 -> 0.0020978433 | J9: 0.002247809 | K9: =I9 -> 0.0020978433 | L9: 超用率
A10: 勞務成本 | B10: ='（１）收支狀況'!T9/1000 -> 31527.948 | C10: 30287.668 | D10: =B10-C10 -> 1240.2802 | E10: =B10 -> 31527.948 | G10: 固定產線-導入率(%) | H10: 0.8 | I10: ='（２）ＫＰＩ達成進度'!T9 -> 0.91666667 | J10: 0.91666667 | K10: =I10 -> 0.91666667 | L10: 導入率
A11: 勞務費率 | B11: ='（１）收支狀況'!W9 -> 0.14366036 | C11: 0.1416929 | D11: =B11-C11 -> 0.0019674549 | E11: =B11 -> 0.14366036 | G11: 教育訓練-實施率(%) | H11: 1 | I11: ='（２）ＫＰＩ達成進度'!W9 -> 0.94496774 | J11: 0.89513333 | K11: =I11 -> 0.94496774 | L11: 實施率
A13: （３）業績構成比 | G13: （４）訂單數量構成比
B14: 當月 | C14: 比例 | D14: 前月 | E14: 差異 | H14: 當月 | I14: 比例 | J14: 前月 | K14: 差異
A15: 18℃-飯糰(061,063) | B15: ='（３）業績構成比'!M46/1000 -> 38925.267 | C15: =IFERROR(B15/$B$6,"") -> 0.177367 | D15: 0.18995233 | E15: =IFERROR(C15-D15,"") -> -0.012585323 | G15: 18℃-飯糰(061,063) | H15: ='（４）訂單數量構成比'!M46 -> 2062765 | I15: =IFERROR(H15/$B$7,"") -> 0.31167469 | J15: 0.32800376 | K15: =IFERROR(I15-J15,"") -> -0.016329077
A16: 18℃-壽司手卷(071,072,075,076) | B16: ='（３）業績構成比'!S46/1000 -> 7132.1213 | C16: =IFERROR(B16/$B$6,"") -> 0.032498248 | D16: 0.036852286 | E16: =IFERROR(C16-D16,"") -> -0.0043540376 | G16: 18℃-壽司手卷(071,072,075,076) | H16: ='（４）訂單數量構成比'!S47 -> 275940 | I16: =IFERROR(H16/$B$7,"") -> 0.041693316 | J16: 0.049997005 | K16: =IFERROR(I16-J16,"") -> -0.0083036891
A17: 4℃-飯糰(065) | B17: ='（３）業績構成比'!U46/1000 -> 28599.979 | C17: =IFERROR(B17/$B$6,"") -> 0.13031876 | D17: 0.083446864 | E17: =IFERROR(C17-D17,"") -> 0.046871897 | G17: 4℃-飯糰(065) | H17: ='（４）訂單數量構成比'!U46 -> 878351 | I17: =IFERROR(H17/$B$7,"") -> 0.13271496 | J17: 0.084772389 | K17: =IFERROR(I17-J17,"") -> 0.04794257
A18: 4℃-壽司手卷(077) | B18: ='（３）業績構成比'!W46/1000 -> 258.70291 | C18: =IFERROR(B18/$B$6,"") -> 0.0011788066 | D18: 0.019267316 | E18: =IFERROR(C18-D18,"") -> -0.018088509 | G18: 4℃-壽司手卷(077) | H18: ='（４）訂單數量構成比'!W46 -> 9911 | I18: =IFERROR(H18/$B$7,"") -> 0.0014975084 | J18: 0.018873671 | K18: =IFERROR(I18-J18,"") -> -0.017376163
A19: 主食(091,092,093,094,095) | B19: ='（３）業績構成比'!AC46/1000 -> 55461.297 | C19: =IFERROR(B19/$B$6,"") -> 0.25271514 | D19: 0.2625072 | E19: =IFERROR(C19-D19,"") -> -0.0097920623 | G19: 主食(091,092,093,094,095) | H19: ='（４）訂單數量構成比'!AC46 -> 1388679 | I19: =IFERROR(H19/$B$7,"") -> 0.20982327 | J19: 0.21577364 | K19: =IFERROR(I19-J19,"") -> -0.0059503717
A20: 便當(083) | B20: ='（３）業績構成比'!AE46/1000 -> 28333.08 | C20: =IFERROR(B20/$B$6,"") -> 0.12910261 | D20: 0.14545991 | E20: =IFERROR(C20-D20,"") -> -0.016357305 | G20: 便當(083) | H20: ='（４）訂單數量構成比'!AE46 -> 507543 | I20: =IFERROR(H20/$B$7,"") -> 0.076687507 | J20: 0.085368721 | K20: =IFERROR(I20-J20,"") -> -0.0086812136
A21: 熱食義麵(122,123,124,126) | B21: ='（３）業績構成比'!AG46/1000 -> 28486.57 | C21: =IFERROR(B21/$B$6,"") -> 0.129802 | D21: 0.12772826 | E21: =IFERROR(C21-D21,"") -> 0.0020737447 | G21: 熱食義麵(122,123,124,126) | H21: ='（４）訂單數量構成比'!AG46 -> 546496 | I21: =IFERROR(H21/$B$7,"") -> 0.082573134 | J21: 0.082842511 | K21: =IFERROR(I21-J21,"") -> -0.00026937706
A22: 季節調理麵(111,112) | B22: ='（３）業績構成比'!AI46/1000 -> 14518.968 | C22: =IFERROR(B22/$B$6,"") -> 0.066157181 | D22: 0.052762179 | E22: =IFERROR(C22-D22,"") -> 0.013395001 | G22: 季節調理麵(111,112) | H22: ='（４）訂單數量構成比'!AI46 -> 394302 | I22: =IFERROR(H22/$B$7,"") -> 0.059577292 | J22: 0.047042446 | K22: =IFERROR(I22-J22,"") -> 0.012534846
A23: 微波小吃(153,154,155) | B23: ='（３）業績構成比'!AK46/1000 -> 17745.73 | C23: =IFERROR(B23/$B$6,"") -> 0.080860254 | D23: 0.082023659 | E23: =IFERROR(C23-D23,"") -> -0.0011634057 | G23: 微波小吃(153,154,155) | H23: ='（４）訂單數量構成比'!AK46 -> 554340 | I23: =IFERROR(H23/$B$7,"") -> 0.083758327 | J23: 0.087325852 | K23: =IFERROR(I23-J23,"") -> -0.003567525
C24: =SUM(C15:C23) -> 1 | D24: =SUM(D15:D23) -> 1 | I24: =SUM(I15:I23) -> 1 | J24: =SUM(J15:J23) -> 1
A26: （５）品群別人時生產性
A27: 品群 | B27: 當月 | C27: 前月 | D27: 差異 | E27: 累計
A28: 18℃-飯糰(061,063) | B28: ='（５-1）品群別人時生產性（18℃-飯糰）'!$C$1 -> 785.96646 | C28: 760.86067 | D28: =B28-C28 -> 25.105791 | E28: =R28 -> 0
A29: 18℃-壽司手卷(071,072,075,076) | B29: ='（５-2）品群別人時生產性（18-壽司手卷)'!$C$1 -> 184.98535 | C29: 181.47824 | D29: =B29-C29 -> 3.5071116 | E29: =R29 -> 0
A30: 4℃-飯糰(065) | B30: ='（５-3）品群別人時生產性（4℃-飯糰)'!$C$1 -> 269.01437 | C30: 278.36246 | D30: =B30-C30 -> -9.3480918 | E30: =R30 -> 0
A31: 4℃-壽司手卷(077) | B31: ='（５-4）品群別人時生產性（4℃-壽司手卷)'!$C$1 -> 114.26643 | C31: 115.55878 | D31: =B31-C31 -> -1.2923523 | E31: =R31 -> 0
A32: 主食(091,092,093,094,095) | B32: ='（５-5）品群別人時生產性(主食) '!$C$1 -> 85.722402 | C32: 86.850172 | D32: =B32-C32 -> -1.1277706 | E32: =R32 -> 0
A33: 便當(083) | B33: ='（５-6）品群別人時生產性(便當)'!$C$1 -> 70.412868 | C33: 69.876515 | D33: =B33-C33 -> 0.53635302 | E33: =R33 -> 0
A34: 熱食義麵(122,123,124,126) | B34: ='（５-7）品群別人時生產性(熱食義麵) '!$C$1 -> 70.928118 | C34: 77.759992 | D34: =B34-C34 -> -6.8318744 | E34: =R34 -> 0
A35: 季節調理麵(111,112) | B35: ='（５-8）品群別人時生產性(季節調理麵) '!$C$1 -> 120.54741 | C35: 119.84367 | D35: =B35-C35 -> 0.703737 | E35: =R35 -> 0
A36: 微波小吃(153,154,155) | B36: ='（５-9）品群別人時生產性(微波小吃)'!$C$1 -> 119.1137 | C36: 111.38791 | D36: =B36-C36 -> 7.7257865 | E36: =R36 -> 0

Sheet 生產管理報表(週) 
A1: 生產管理報表
A3: 月別 | B3: 11 | C3: 週別 | D3: W4 | E3: 工廠 | F3: 晉欣廠
A4: （１）收支狀況 | E4: ※單位：千元 | G4: （２）ＫＰＩ達成進度
A5: 項目 | B5: 當週 | C5: 前週 | D5: 差異 | E5: 累計 | G5: 項目 | H5: KPI | I5: 當週 | J5: 前週 | K5: 累計 | L5: ※補充
A6: 業績金額 | B6: ='（１）收支狀況'!G33/1000 -> 48124.067 | C6: 48568.543 | D6: =B6-C6 -> -444.476 | E6: ='（１）收支狀況'!H9/1000 -> 219461.72 | G6: 人時性(個/月均) | H6: 366 | I6: ='（２）ＫＰＩ達成進度'!G33 -> 330.07003 | J6: 342.32011 | K6: ='（２）ＫＰＩ達成進度'!H9 -> 328.81666 | L6: 個／MH
A7: 訂單數量 | B7: ='（１）收支狀況'!J33 -> 1466437 | C7: 1467152 | D7: =B7-C7 -> -715 | E7: ='（１）收支狀況'!K9 -> 6618327 | G7: 人時達成率(%/月均) | H7: 0.8 | I7: ='（２）ＫＰＩ達成進度'!J33 -> 0.90132152 | J7: 0.93530086 | K7: ='（２）ＫＰＩ達成進度'!K9 -> 0.8981902 | L7: 達成率
A8: 材料費 | B8: ='（１）收支狀況'!M33/1000 -> 32691.593 | C8: 32511.103 | D8: =B8-C8 -> 180.49 | E8: ='（１）收支狀況'!N9/1000 -> 148488.87 | G8: 半成品-報廢(%) | H8: 0.0025 | I8: ='（２）ＫＰＩ達成進度'!M33 -> 0.00245732 | J8: 0.002449927 | K8: ='（２）ＫＰＩ達成進度'!N9 -> 0.0024556526 | L8: 報廢率
A9: 材料費率 | B9: ='（１）收支狀況'!P33 -> 0.679319 | C9: 0.66938601 | D9: =B9-C9 -> 0.0099329929 | E9: ='（１）收支狀況'!Q9 -> 0.67660489 | G9: 半成品-超用(%) | H9: 0.0026 | I9: ='（２）ＫＰＩ達成進度'!P33 -> 0.0022237035 | J9: 0.0022296455 | K9: ='（２）ＫＰＩ達成進度'!Q9 -> 0.0020978433 | L9: 超用率
A10: 勞務成本 | B10: ='（１）收支狀況'!S33/1000 -> 6957.2861 | C10: =7059638.28/1000 -> 7059.6383 | D10: =B10-C10 -> -102.35219 | E10: ='（１）收支狀況'!T9/1000 -> 31527.948 | G10: 固定產線-導入率(%) | H10: 0.8 | I10: 0.917 | J10: 0.917 | K10: 0.917 | L10: 導入率
A11: 勞務費率 | B11: ='（１）收支狀況'!V33 -> 0.14456979 | C11: 0.14535413 | D11: =B11-C11 -> -0.00078434287 | E11: ='（１）收支狀況'!W9 -> 0.14366036 | G11: 教育訓練-實施率(%) | H11: 1 | I11: ='（２）ＫＰＩ達成進度'!V33 -> 0.97485714 | J11: 0.90285714 | K11: ='（２）ＫＰＩ達成進度'!W9 -> 0.94496774 | L11: 實施率
A13: （３）業績構成比 | G13: （４）訂單數量構成比
B14: 當週 | C14: 比例 | D14: 前週 | E14: 差異 | H14: 當週 | I14: 比例 | J14: 前週 | K14: 差異
A15: 18℃-飯糰(061,063) | B15: =SUM('（３）業績構成比'!I35:I41,'（３）業績構成比'!K35:K41)/1000 -> 8480.4439 | C15: =IFERROR(B15/$B$6,"") -> 0.17622043 | D15: 0.18934668 | E15: =IFERROR(C15-D15,"") -> -0.013126245 | G15: 18℃-飯糰(061,063) | H15: =SUM(,'（４）訂單數量構成比'!I35:I41,'（４）訂單數量構成比'!K35:K41) -> 447953 | I15: =IFERROR(H15/$B$7,"") -> 0.30547033 | J15: 0.32807712 | K15: =IFERROR(I15-J15,"") -> -0.022606784
A16: 18℃-壽司手卷(071,072,075,076) | B16: =SUM('（３）業績構成比'!O35:O41,'（３）業績構成比'!Q35:Q41)/1000 -> 1714.2049 | C16: =IFERROR(B16/$B$6,"") -> 0.035620532 | D16: 0.035232688 | E16: =IFERROR(C16-D16,"") -> 0.00038784366 | G16: 18℃-壽司手卷(071,072,075,076) | H16: =SUM('（４）訂單數量構成比'!O35:O41,'（４）訂單數量構成比'!Q35:Q41) -> 63820 | I16: =IFERROR(H16/$B$7,"") -> 0.043520451 | J16: 0.046813145 | K16: =IFERROR(I16-J16,"") -> -0.0032926942
A17: 4℃-飯糰(065) | B17: =SUM('（３）業績構成比'!U35:U41)/1000 -> 7631.8403 | C17: =IFERROR(B17/$B$6,"") -> 0.15858677 | D17: 0.090034972 | E17: =IFERROR(C17-D17,"") -> 0.068551798 | G17: 4℃-飯糰(065) | H17: =SUM('（４）訂單數量構成比'!U35:U41) -> 233087 | I17: =IFERROR(H17/$B$7,"") -> 0.15894784 | J17: 0.084512034 | K17: =IFERROR(I17-J17,"") -> 0.07443581
A18: 4℃-壽司手卷(077) | B18: =SUM('（３）業績構成比'!W35:W41)/1000 -> 0 | C18: =IFERROR(B18/$B$6,"") -> 0 | D18: 0.011775084 | E18: =IFERROR(C18-D18,"") -> -0.011775084 | G18: 4℃-壽司手卷(077) | H18: =SUM('（４）訂單數量構成比'!W35:W41) -> 0 | I18: =IFERROR(H18/$B$7,"") -> 0 | J18: 0.019178654 | K18: =IFERROR(I18-J18,"") -> -0.019178654
A19: 主食(091,092,093,094,095) | B19: =SUM('（３）業績構成比'!Y35:Y41,'（３）業績構成比'!AA35:AA41)/1000 -> 12684.446 | C19: =IFERROR(B19/$B$6,"") -> 0.26357801 | D19: 0.2832898 | E19: =IFERROR(C19-D19,"") -> -0.019711795 | G19: 主食(091,092,093,094,095) | H19: =SUM('（４）訂單數量構成比'!Y35:Y41,'（４）訂單數量構成比'!AA35:AA41) -> 316397 | I19: =IFERROR(H19/$B$7,"") -> 0.21575901 | J19: 0.22873431 | K19: =IFERROR(I19-J19,"") -> -0.012975297
A20: 便當(083) | B20: =SUM('（３）業績構成比'!AE35:AE41)/1000 -> 5941.3448 | C20: =IFERROR(B20/$B$6,"") -> 0.12345891 | D20: 0.15040468 | E20: =IFERROR(C20-D20,"") -> -0.026945776 | G20: 便當(083) | H20: =SUM('（４）訂單數量構成比'!AE35:AE41) -> 107058 | I20: =IFERROR(H20/$B$7,"") -> 0.073005523 | J20: 0.089526511 | K20: =IFERROR(I20-J20,"") -> -0.016520988
A21: 熱食義麵(122,123,124,126) | B21: =SUM('（３）業績構成比'!AG35:AG41)/1000 -> 4226.217 | C21: =IFERROR(B21/$B$6,"") -> 0.087819198 | D21: 0.11116644 | E21: =IFERROR(C21-D21,"") -> -0.023347244 | G21: 熱食義麵(122,123,124,126) | H21: =SUM('（４）訂單數量構成比'!AG35:AG41) -> 84362 | I21: =IFERROR(H21/$B$7,"") -> 0.057528554 | J21: 0.073652219 | K21: =IFERROR(I21-J21,"") -> -0.016123665
A22: 季節調理麵(111,112) | B22: =SUM('（３）業績構成比'!AI35:AI41)/1000 -> 3322.554 | C22: =IFERROR(B22/$B$6,"") -> 0.069041422 | D22: 0.046912394 | E22: =IFERROR(C22-D22,"") -> 0.022129028 | G22: 季節調理麵(111,112) | H22: =SUM('（４）訂單數量構成比'!AI35:AI41) -> 89922 | I22: =IFERROR(H22/$B$7,"") -> 0.061320057 | J22: 0.041703245 | K22: =IFERROR(I22-J22,"") -> 0.019616811
A23: 微波小吃(153,154,155) | B23: =SUM('（３）業績構成比'!AK35:AK41)/1000 -> 4123.0165 | C23: =IFERROR(B23/$B$6,"") -> 0.085674731 | D23: 0.081837257 | E23: =IFERROR(C23-D23,"") -> 0.0038374738 | G23: 微波小吃(153,154,155) | H23: =SUM('（４）訂單數量構成比'!AK35:AK41) -> 123838 | I23: =IFERROR(H23/$B$7,"") -> 0.084448224 | J23: 0.087802763 | K23: =IFERROR(I23-J23,"") -> -0.0033545396
C24: =SUM(C15:C23) -> 1 | D24: =SUM(D15:D23) -> 1 | I24: =SUM(I15:I23) -> 1 | J24: =SUM(J15:J23) -> 1
A26: （５）品群別人時生產性
A27: 品群 | B27: 當週 | C27: 前週 | D27: 差異 | E27: 累計
A28: 18℃-飯糰(061,063) | B28: ='（５-1）品群別人時生產性（18℃-飯糰）'!L147 -> 793.81366 | C28: 773.28751 | D28: =B28-C28 -> 20.526146 | E28: ='（５-1）品群別人時生產性（18℃-飯糰）'!C1 -> 785.96646 | F28: 147
A29: 18℃-壽司手卷(071,072,075,076) | B29: ='（５-2）品群別人時生產性（18-壽司手卷)'!L87 -> 168.27661 | C29: 182.60764 | D29: =B29-C29 -> -14.331026 | E29: ='（５-2）品群別人時生產性（18-壽司手卷)'!C1 -> 184.98535 | F29: 87
A30: 4℃-飯糰(065) | B30: ='（５-3）品群別人時生產性（4℃-飯糰)'!L87 -> 258.16866 | C30: 272.74109 | D30: =B30-C30 -> -14.57243 | E30: ='（５-3）品群別人時生產性（4℃-飯糰)'!C1 -> 269.01437
A31: 4℃-壽司手卷(077) | B31: ='（５-4）品群別人時生產性（4℃-壽司手卷)'!L87 -> 113.1102 | C31: 113.81516 | D31: =B31-C31 -> -0.70496089 | E31: ='（５-4）品群別人時生產性（4℃-壽司手卷)'!C1 -> 114.26643
A32: 主食(091,092,093,094,095) | B32: ='（５-5）品群別人時生產性(主食) '!L147 -> 84.048293 | C32: 86.027649 | D32: =B32-C32 -> -1.9793556 | E32: ='（５-5）品群別人時生產性(主食) '!C1 -> 85.722402
A33: 便當(083) | B33: ='（５-6）品群別人時生產性(便當)'!L87 -> 69.900452 | C33: 67.317863 | D33: =B33-C33 -> 2.5825895 | E33: ='（５-6）品群別人時生產性(便當)'!C1 -> 70.412868
A34: 熱食義麵(122,123,124,126) | B34: ='（５-7）品群別人時生產性(熱食義麵) '!L87 -> 69.481919 | C34: 77.43651 | D34: =B34-C34 -> -7.9545914 | E34: ='（５-7）品群別人時生產性(熱食義麵) '!C1 -> 70.928118
A35: 季節調理麵(111,112) | B35: ='（５-8）品群別人時生產性(季節調理麵) '!L87 -> 121.38047 | C35: 121.87281 | D35: =B35-C35 -> -0.49233664 | E35: ='（５-8）品群別人時生產性(季節調理麵) '!C1 -> 120.54741
A36: 微波小吃(153,154,155) | B36: ='（５-9）品群別人時生產性(微波小吃)'!L87 -> 115.12118 | C36: 115.15834 | D36: =B36-C36 -> -0.037160492 | E36: ='（５-9）品群別人時生產性(微波小吃)'!C1 -> 119.1137
D37: =SUM(D28:D36) -> -16.963126

Sheet （１）收支狀況
B2: （１）收支狀況
C3: 月份 | D3: 日期 | F3: 營業額(元) | I3: 訂單數量(個) | L3: 材料費(元) | O3: 材料費率（材料費／營業額） | R3: 勞務成本（全廠人事成本） | U3: 勞務費率（勞務成本／營業額）
F4: 日 | G4: 週累積 | H4: 月累積 | I4: 日 | J4: 週累積 | K4: 月累積 | L4: 日 | M4: 週累積 | N4: 月累積 | O4: 日 | P4: 週累積 | Q4: 月平均 | R4: 日 | S4: 週累積 | T4: 月累積 | U4: 日 | V4: 週累積 | W4: 月平均
D9: 45992 | E9: 一 | F9: 7261499 | H9: =SUM(F9:F39) -> 219461716 | I9: 216425 | K9: =SUM(I9:I39) -> 6618327 | L9: 4833061 | N9: =SUM(L9:L39) -> 148488871 | O9: =L9/F9 -> 0.66557346 | Q9: =N9/H9 -> 0.67660489 | R9: 1052455 | T9: =SUM(R9:R39) -> 31527948 | U9: =R9/F9 -> 0.14493633 | W9: =T9/H9 -> 0.14366036
D10: 45993 | E10: 二 | F10: 7236654 | I10: 213834 | L10: 4864280 | O10: =L10/F10 -> 0.67217253 | R10: 1026546.2 | U10: =R10/F10 -> 0.14185371
D11: =D10+1 -> 45994 | E11: 三 | F11: 6888543 | I11: 206960 | L11: 4792019 | O11: =L11/F11 -> 0.69565059 | R11: 986195.96 | U11: =R11/F11 -> 0.14316467
D12: =D11+1 -> 45995 | E12: 四 | F12: 6535954 | G12: =SUM(F12:F18) -> 48757489 | I12: 197911 | J12: =SUM(I12:I18) -> 1459376 | L12: 4400231 | M12: =SUM(L12:L18) -> 32877245 | O12: =L12/F12 -> 0.6732347 | P12: =M12/G12 -> 0.67430144 | R12: 933271.81 | S12: =SUM(R12:R18) -> 7057859.7 | U12: =R12/F12 -> 0.14279045 | V12: =S12/G12 -> 0.14475437
D13: =D12+1 -> 45996 | E13: 五 | F13: 6075465 | I13: 183552 | L13: 4051247 | O13: =L13/F13 -> 0.66682089 | R13: 998290.49 | U13: =R13/F13 -> 0.16431508
D14: =D13+1 -> 45997 | E14: 六 | F14: 6262543 | I14: 185894 | L14: 4336503 | O14: =L14/F14 -> 0.69245081 | R14: 974243.99 | U14: =R14/F14 -> 0.15556683
D15: =D14+1 -> 45998 | E15: 日 | F15: 7283314 | I15: 216841 | L15: 4748585 | O15: =L15/F15 -> 0.65198136 | R15: 1018136.9 | U15: =R15/F15 -> 0.13979034
D16: =D15+1 -> 45999 | E16: 一 | F16: 7299829 | I16: 216945 | L16: 4900933 | O16: =L16/F16 -> 0.67137641 | R16: 1040410.2 | U16: =R16/F16 -> 0.14252529
D17: =D16+1 -> 46000 | E17: 二 | F17: 7768298 | I17: 231819 | L17: 5246074 | O17: =L17/F17 -> 0.67531833 | R17: 1050035.5 | U17: =R17/F17 -> 0.13516931
D18: =D17+1 -> 46001 | E18: 三 | F18: 7532086 | I18: 226414 | L18: 5193672 | O18: =L18/F18 -> 0.68953966 | R18: 1043470.7 | U18: =R18/F18 -> 0.13853675
D19: =D18+1 -> 46002 | E19: 四 | F19: 6664969 | G19: =SUM(F19:F25) -> 50108332 | I19: 203040 | J19: =SUM(I19:I25) -> 1516815 | L19: 4736555 | M19: =SUM(L19:L25) -> 33917925 | O19: =L19/F19 -> 0.71066422 | P19: =M19/G19 -> 0.67689192 | R19: 1010108 | S19: =SUM(R19:R25) -> 7244183.6 | U19: =R19/F19 -> 0.15155479 | V19: =S19/G19 -> 0.14457044
D20: =D19+1 -> 46003 | E20: 五 | F20: 6216944 | I20: 188638 | L20: 4038316 | O20: =L20/F20 -> 0.64956609 | R20: 1003377.6 | U20: =R20/F20 -> 0.16139403
D21: =D20+1 -> 46004 | E21: 六 | F21: 6402844 | I21: 193826 | L21: 4231154 | O21: =L21/F21 -> 0.66082416 | R21: 1008951.8 | U21: =R21/F21 -> 0.15757869
D22: =D21+1 -> 46005 | E22: 日 | F22: 7638376 | I22: 230374 | L22: 5042261 | O22: =L22/F22 -> 0.66012213 | R22: 1013182.9 | U22: =R22/F22 -> 0.13264375
D23: =D22+1 -> 46006 | E23: 一 | F23: 7520294 | I23: 227619 | L23: 5039882 | O23: =L23/F23 -> 0.67017087 | R23: 1040615.3 | U23: =R23/F23 -> 0.13837428
D24: =D23+1 -> 46007 | E24: 二 | F24: 8052028 | I24: 241960 | L24: 5631985 | O24: =L24/F24 -> 0.69944926 | R24: 1087475.5 | U24: =R24/F24 -> 0.13505609
D25: =D24+1 -> 46008 | E25: 三 | F25: 7612877 | I25: 231358 | L25: 5197772 | O25: =L25/F25 -> 0.68276054 | R25: 1080472.5 | U25: =R25/F25 -> 0.14192697
D26: =D25+1 -> 46009 | E26: 四 | F26: 7258886 | G26: =SUM(F26:F32) -> 51085132 | I26: 221397 | J26: =SUM(I26:I32) -> 1538480 | L26: 5068912 | M26: =SUM(L26:L32) -> 34512748 | O26: =L26/F26 -> 0.6983044 | P26: =M26/G26 -> 0.67559281 | R26: 1056766.8 | S26: =SUM(R26:R32) -> 7203421.7 | U26: =R26/F26 -> 0.14558251 | V26: =S26/G26 -> 0.14100818
D27: =D26+1 -> 46010 | E27: 五 | F27: 6600497 | I27: 202213 | L27: 4415391 | O27: =L27/F27 -> 0.66894826 | R27: 1013312.6 | U27: =R27/F27 -> 0.15352066
D28: =D27+1 -> 46011 | E28: 六 | F28: 6936693 | I28: 207438 | L28: 4851836 | O28: =L28/F28 -> 0.69944511 | R28: 999924.16 | U28: =R28/F28 -> 0.14414998
D29: =D28+1 -> 46012 | E29: 日 | F29: 8044891 | I29: 241311 | L29: 5073750 | O29: =L29/F29 -> 0.63067977 | R29: 1032366.9 | U29: =R29/F29 -> 0.12832578
D30: =D29+1 -> 46013 | E30: 一 | F30: 8079828 | I30: 239757 | L30: 5292630 | O30: =L30/F30 -> 0.65504241 | R30: 1049819.3 | U30: =R30/F30 -> 0.1299309
D31: =D30+1 -> 46014 | E31: 二 | F31: 7688414 | I31: 229409 | L31: 5135849 | O31: =L31/F31 -> 0.6679985 | R31: 1056375.2 | U31: =R31/F31 -> 0.13739832
D32: =D31+1 -> 46015 | E32: 三 | F32: 6475923 | I32: 196955 | L32: 4674380 | O32: =L32/F32 -> 0.72180908 | R32: 994856.61 | U32: =R32/F32 -> 0.15362391
D33: =D32+1 -> 46016 | E33: 四 | F33: 6755981 | G33: =SUM(F33:F39) -> 48124067 | I33: 206860 | J33: =SUM(I33:I39) -> 1466437 | L33: 4604967 | M33: =SUM(L33:L39) -> 32691593 | O33: =L33/F33 -> 0.68161337 | P33: =M33/G33 -> 0.679319 | R33: 1000164.6 | S33: =SUM(R33:R39) -> 6957286.1 | U33: =R33/F33 -> 0.14804136 | V33: =S33/G33 -> 0.14456979
D34: =D33+1 -> 46017 | E34: 五 | F34: 6278111 | I34: 193343 | L34: 4361238 | O34: =L34/F34 -> 0.6946736 | R34: 969046.93 | U34: =R34/F34 -> 0.15435327
D35: =D34+1 -> 46018 | E35: 六 | F35: 6552614 | I35: 199280 | L35: 4499324 | O35: =L35/F35 -> 0.68664567 | R35: 974680.72 | U35: =R35/F35 -> 0.14874685
D36: =D35+1 -> 46019 | E36: 日 | F36: 7539331 | I36: 229667 | L36: 4955566 | O36: =L36/F36 -> 0.65729519 | R36: 1033559.9 | U36: =R36/F36 -> 0.13708907
D37: =D36+1 -> 46020 | E37: 一 | F37: 7494235 | I37: 225457 | L37: 5209617 | O37: =L37/F37 -> 0.69514994 | R37: 1031562 | U37: =R37/F37 -> 0.13764741
D38: =D37+1 -> 46021 | E38: 二 | F38: 7242022 | I38: 219598 | L38: 4956549 | O38: =L38/F38 -> 0.68441507 | R38: 999035.07 | U38: =R38/F38 -> 0.13794974
D39: =D38+1 -> 46022 | E39: 三 | F39: 6261773 | I39: 192232 | L39: 4104332 | O39: =L39/F39 -> 0.65545845 | R39: 949236.81 | U39: =R39/F39 -> 0.15159234
O40: =L40/F40 -> #DIV/0! | U40: =R40/F40 -> #DIV/0!

Sheet （２）ＫＰＩ達成進度
B1: KPI | C1: 366
B2: （２）ＫＰＩ達成進度
C3: 月份 | D3: 日期 | F3: 人時生產性(個/人) | I3: 人時生產性達成率(%) | L3: 半成品報廢(%) | O3: 半成品超用(%) | R3: 固定產線-導入率(固定產線數/總產線數) | U3: 教育訓練-實施率(進度/計畫)
F4: 日 | G4: 週平均 | H4: 月平均 | I4: 日 | J4: 週平均 | K4: 月平均 | L4: 日 | M4: 週平均 | N4: 月平均 | O4: 日 | P4: 週平均 | Q4: 月平均 | R4: 日 | S4: 週平均 | T4: 月平均 | U4: 日 | V4: 週平均 | W4: 月平均
D9: 45992 | E9: 一 | F9: 318.47175 | H9: =AVERAGE(F9:F39) -> 328.81666 | I9: =F9/$C$1 -> 0.87014139 | K9: =AVERAGE(I9:I39) -> 0.8981902 | L9: 0.0024398666 | N9: =AVERAGE(L9:L39) -> 0.0024556526 | O9: 0.0020268146 | Q9: =AVERAGE(O9:O39) -> 0.0020978433 | R9: 0.91666667 | T9: =AVERAGE(R9:R39) -> 0.91666667 | U9: 0.92 | W9: =AVERAGE(U9:U39) -> 0.94496774
D10: 45993 | E10: 二 | F10: 314.46698 | I10: =F10/$C$1 -> 0.85919941 | L10: 0.0024403543 | O10: 0.0021237594 | R10: 0.91666667 | U10: 0.922
D11: =D10+1 -> 45994 | E11: 三 | F11: 320.98265 | I11: =F11/$C$1 -> 0.87700177 | L11: 0.0024397274 | O11: 0.002225451 | R11: 0.91666667 | U11: 0.922
D12: =D11+1 -> 45995 | E12: 四 | F12: 310.76985 | G12: =AVERAGE(F12:F18) -> 326.75101 | I12: =F12/$C$1 -> 0.84909796 | J12: =AVERAGE(I12:I18) -> 0.89276233 | L12: 0.0024718909 | M12: =AVERAGE(L12:L18) -> 0.0024593631 | O12: 0.0023965896 | P12: =AVERAGE(O12:O18) -> 0.0021259809 | R12: 0.91666667 | S12: =AVERAGE(R12:R18) -> 0.91666667 | U12: 0.924 | V12: =AVERAGE(U12:U18) -> 0.92685714
D13: =D12+1 -> 45996 | E13: 五 | F13: 331.48548 | I13: =F13/$C$1 -> 0.90569803 | L13: 0.002459071 | O13: 0.0025356559 | R13: 0.91666667 | U13: 0.924
D14: =D13+1 -> 45997 | E14: 六 | F14: 322.27938 | I14: =F14/$C$1 -> 0.88054476 | L14: 0.0024710409 | O14: 0.0021645748 | R14: 0.91666667 | U14: 0.926
D15: =D14+1 -> 45998 | E15: 日 | F15: 332.97304 | I15: =F15/$C$1 -> 0.90976241 | L15: 0.0024495717 | O15: 0.0020712142 | R15: 0.91666667 | U15: 0.926
D16: =D15+1 -> 45999 | E16: 一 | F16: 326.66623 | I16: =F16/$C$1 -> 0.89253069 | L16: 0.002442386 | O16: 0.0019214147 | R16: 0.91666667 | U16: 0.928
D17: =D16+1 -> 46000 | E17: 二 | F17: 333.35801 | I17: =F17/$C$1 -> 0.91081422 | L17: 0.0024521459 | O17: 0.0018604212 | R17: 0.91666667 | U17: 0.93
D18: =D17+1 -> 46001 | E18: 三 | F18: 329.72509 | I18: =F18/$C$1 -> 0.90088821 | L18: 0.0024694354 | O18: 0.0019319961 | R18: 0.91666667 | U18: 0.93
D19: =D18+1 -> 46002 | E19: 四 | F19: 335.51581 | G19: =AVERAGE(F19:F25) -> 332.80451 | I19: =F19/$C$1 -> 0.91670987 | J19: =AVERAGE(I19:I25) -> 0.90930194 | L19: 0.0024711293 | M19: =AVERAGE(L19:L25) -> 0.0024643092 | O19: 0.0022613435 | P19: =AVERAGE(O19:O25) -> 0.0020482691 | R19: 0.91666667 | S19: =AVERAGE(R19:R25) -> 0.91666667 | U19: 0.93 | V19: =AVERAGE(U19:U25) -> 0.93714286
D20: =D19+1 -> 46003 | E20: 五 | F20: 328.69076 | I20: =F20/$C$1 -> 0.89806219 | L20: 0.0024587643 | O20: 0.0022849685 | R20: 0.91666667 | U20: 0.932
D21: =D20+1 -> 46004 | E21: 六 | F21: 335.80166 | I21: =F21/$C$1 -> 0.91749087 | L21: 0.0024798355 | O21: 0.0021706002 | R21: 0.91666667 | U21: 0.934
D22: =D21+1 -> 46005 | E22: 日 | F22: 322.87261 | I22: =F22/$C$1 -> 0.8821656 | L22: 0.0024590306 | O22: 0.0018270738 | R22: 0.91666667 | U22: 0.94
D23: =D22+1 -> 46006 | E23: 一 | F23: 337.80334 | I23: =F23/$C$1 -> 0.92295995 | L23: 0.002460941 | O23: 0.0020052804 | R23: 0.91666667 | U23: 0.94
D24: =D23+1 -> 46007 | E24: 二 | F24: 338.58196 | I24: =F24/$C$1 -> 0.92508732 | L24: 0.0024504386 | O24: 0.0018102021 | R24: 0.91666667 | U24: 0.942
D25: =D24+1 -> 46008 | E25: 三 | F25: 330.36543 | I25: =F25/$C$1 -> 0.90263778 | L25: 0.0024700255 | O25: 0.0019784153 | R25: 0.91666667 | U25: 0.942
D26: =D25+1 -> 46009 | E26: 四 | F26: 335.13853 | G26: =AVERAGE(F26:F32) -> 330.28804 | I26: =F26/$C$1 -> 0.91567905 | J26: =AVERAGE(I26:I32) -> 0.90242633 | L26: 0.0024419725 | M26: =AVERAGE(L26:L32) -> 0.0024483335 | O26: 0.0018300101 | P26: =AVERAGE(O26:O32) -> 0.0019816345 | R26: 0.91666667 | S26: =AVERAGE(R26:R32) -> 0.91666667 | U26: 0.946 | V26: =AVERAGE(U26:U32) -> 0.95114286
D27: =D26+1 -> 46010 | E27: 五 | F27: 332.81778 | I27: =F27/$C$1 -> 0.9093382 | L27: 0.002468905 | O27: 0.0020894611 | R27: 0.91666667 | U27: 0.946
D28: =D27+1 -> 46011 | E28: 六 | F28: 326.73067 | I28: =F28/$C$1 -> 0.89270676 | L28: 0.0024710622 | O28: 0.001884978 | R28: 0.91666667 | U28: 0.95
D29: =D28+1 -> 46012 | E29: 日 | F29: 329.30818 | I29: =F29/$C$1 -> 0.89974913 | L29: 0.0024303623 | O29: 0.0018187414 | R29: 0.91666667 | U29: 0.95
D30: =D29+1 -> 46013 | E30: 一 | F30: 330.54215 | I30: =F30/$C$1 -> 0.90312064 | L30: 0.0024569618 | O30: 0.0019842851 | R30: 0.91666667 | U30: 0.952
D31: =D30+1 -> 46014 | E31: 二 | F31: 328.86994 | I31: =F31/$C$1 -> 0.89855175 | L31: 0.0024291096 | O31: 0.0019521134 | R31: 0.91666667 | U31: 0.956
D32: =D31+1 -> 46015 | E32: 三 | F32: 328.60899 | I32: =F32/$C$1 -> 0.89783877 | L32: 0.0024399611 | O32: 0.0023118525 | R32: 0.91666667 | U32: 0.958
D33: =D32+1 -> 46016 | E33: 四 | F33: 338.86367 | G33: =AVERAGE(F33:F39) -> 330.07003 | I33: =F33/$C$1 -> 0.92585702 | J33: =AVERAGE(I33:I39) -> 0.90132152 | L33: 0.0024621147 | M33: =AVERAGE(L33:L39) -> 0.00245732 | O33: 0.002351009 | P33: =AVERAGE(O33:O39) -> 0.0022237035 | R33: 0.91666667 | S33: =AVERAGE(R33:R39) -> 0.91666667 | U33: 0.96 | V33: =AVERAGE(U33:U39) -> 0.97485714
D34: =D33+1 -> 46017 | E34: 五 | F34: 322.91104 | I34: =F34/$C$1 -> 0.88227061 | L34: 0.0024695326 | O34: 0.0025255201 | R34: 0.91666667 | U34: 0.966
D35: =D34+1 -> 46018 | E35: 六 | F35: 332.5964 | I35: =F35/$C$1 -> 0.90873333 | L35: 0.0024719906 | O35: 0.0023272602 | R35: 0.91666667 | U35: 0.968
D36: =D35+1 -> 46019 | E36: 日 | F36: 333.66067 | I36: =F36/$C$1 -> 0.91164118 | L36: 0.0024486257 | O36: 0.0020129143 | R36: 0.91666667 | U36: 0.972
D37: =D36+1 -> 46020 | E37: 一 | F37: 322.03057 | I37: =F37/$C$1 -> 0.87986495 | L37: 0.002441877 | O37: 0.002030685 | R37: 0.91666667 | U37: 0.978
D38: =D37+1 -> 46021 | E38: 二 | F38: 329.23971 | I38: =F38/$C$1 -> 0.89956205 | L38: 0.0024482113 | O38: 0.0019139385 | R38: 0.91666667 | U38: 0.98
D39: =D38+1 -> 46022 | E39: 三 | F39: 331.18811 | L39: 0.0024588882 | O39: 0.0024045973 | R39: 0.91666667 | U39: 1

Sheet （３）業績構成比
B2: （3）業績構成比
C3: 月份 | D3: 日期 | F3: 營業額 | I3: 品類業績
I4: 18℃-飯糰 | O4: 18℃-壽司手卷 | U4: 4℃-飯糰 | W4: 4℃-壽司手卷 | Y4: 主食 | AE4: 便當 | AG4: 熱食義麵 | AI4: 季節調理麵 | AK4: 微波小吃
F5: 日 | G5: 週累積 | H5: 月累積 | I5: 一配 | K5: 二配 | M5: 合計 | O5: 一配 | Q5: 二配 | S5: 合計 | U5: 一配 | W5: 一配 | Y5: 一配 | AA5: 二配 | AC5: 合計 | AE5: 一配 | AG5: 一配 | AI5: 一配 | AK5: 一配
I6: 業績(元) | J6: 比例(%) | K6: 業績(元) | L6: 比例(%) | M6: 業績(元) | N6: 比例(%) | O6: 業績(元) | P6: 比例(%) | Q6: 業績(元) | R6: 比例(%) | S6: 業績(元) | T6: 比例(%) | U6: 業績(元) | V6: 比例(%) | W6: 業績(元) | X6: 比例(%) | Y6: 業績(元) | Z6: 比例(%) | AA6: 業績(元) | AB6: 比例(%) | AC6: 業績(元) | AD6: 比例(%) | AE6: 業績(元) | AF6: 比例(%) | AG6: 業績(元) | AH6: 比例(%) | AI6: 業績(元) | AJ6: 比例(%) | AK6: 業績(元) | AL6: 比例(%)
D11: 45992 | E11: 一 | F11: =SUM(M11,S11,U11,W11,AC11,AE11,AG11,AI11,AK11) -> 7261499 | H11: =SUM(F11:F41) -> 219461716 | I11: 547116.01 | J11: =I11/F11 -> 0.075344775 | K11: 802330.42 | L11: =K11/F11 -> 0.11049102 | M11: =SUM(I11+K11) -> 1349446.4 | N11: =M11/F11 -> 0.18583579 | O11: 143482.93 | P11: =O11/F11 -> 0.01975941 | Q11: 95300.189 | R11: =Q11/$F11 -> 0.013124038 | S11: =SUM(O11+Q11) -> 238783.12 | T11: =S11/F11 -> 0.032883448 | U11: 600702.97 | V11: =U11/F11 -> 0.082724375 | W11: 28417.83 | X11: =W11/F11 -> 0.0039134936 | Y11: 601911.84 | Z11: =Y11/F11 -> 0.082890852 | AA11: 1272400.8 | AB11: =AA11/$F11 -> 0.17522565 | AC11: =SUM(Y11+AA11) -> 1874312.7 | AD11: =AC11/F11 -> 0.2581165 | AE11: 1046304.1 | AF11: =AE11/F11 -> 0.14408928 | AG11: 1206791.6 | AH11: =AG11/F11 -> 0.16619042 | AI11: 378278.15 | AJ11: =AI11/F11 -> 0.052093672 | AK11: 538462.1 | AL11: =AK11/F11 -> 0.074153022
D12: 45993 | E12: 二 | F12: =SUM(M12,S12,U12,W12,AC12,AE12,AG12,AI12,AK12) -> 7236654 | I12: 530333.21 | J12: =I12/F12 -> 0.073284312 | K12: 779594.22 | L12: =K12/F12 -> 0.10772855 | M12: =SUM(I12+K12) -> 1309927.4 | N12: =M12/F12 -> 0.18101286 | O12: 137168.97 | P12: =O12/F12 -> 0.01895475 | Q12: 93054.275 | R12: =Q12/$F12 -> 0.012858743 | S12: =SUM(O12+Q12) -> 230223.24 | T12: =S12/F12 -> 0.031813493 | U12: 588511 | V12: =U12/F12 -> 0.081323634 | W12: 28051.696 | X12: =W12/F12 -> 0.003876335 | Y12: 592360.76 | Z12: =Y12/F12 -> 0.081855614 | AA12: 1231812.8 | AB12: =AA12/$F12 -> 0.17021855 | AC12: =SUM(Y12+AA12) -> 1824173.5 | AD12: =AC12/F12 -> 0.25207417 | AE12: 996597.14 | AF12: =AE12/F12 -> 0.13771518 | AG12: 1383070.2 | AH12: =AG12/F12 -> 0.19112012 | AI12: 349181.96 | AJ12: =AI12/F12 -> 0.048251852 | AK12: 526917.85 | AL12: =AK12/F12 -> 0.072812359
D13: =D12+1 -> 45994 | E13: 三 | F13: =SUM(M13,S13,U13,W13,AC13,AE13,AG13,AI13,AK13) -> 6888543 | I13: 526762.36 | J13: =I13/F13 -> 0.076469343 | K13: 758147.52 | L13: =K13/F13 -> 0.1100592 | M13: =SUM(I13+K13) -> 1284909.9 | N13: =M13/F13 -> 0.18652854 | O13: 142282.63 | P13: =O13/F13 -> 0.020654967 | Q13: 97009.818 | R13: =Q13/$F13 -> 0.014082777 | S13: =SUM(O13+Q13) -> 239292.45 | T13: =S13/F13 -> 0.034737745 | U13: 560035.02 | V13: =U13/F13 -> 0.081299488 | W13: 29194.405 | X13: =W13/F13 -> 0.0042381103 | Y13: 565620.79 | Z13: =Y13/F13 -> 0.082110367 | AA13: 1154648.9 | AB13: =AA13/$F13 -> 0.16761875 | AC13: =SUM(Y13+AA13) -> 1720269.7 | AD13: =AC13/F13 -> 0.24972911 | AE13: 971865.12 | AF13: =AE13/F13 -> 0.14108428 | AG13: 1184600.9 | AH13: =AG13/F13 -> 0.17196682 | AI13: 369726.56 | AJ13: =AI13/F13 -> 0.053672679 | AK13: 528648.98 | AL13: =AK13/F13 -> 0.076743222
D14: =D13+1 -> 45995 | E14: 四 | F14: =SUM(M14,S14,U14,W14,AC14,AE14,AG14,AI14,AK14) -> 6535954 | G14: =SUM(F14:F20) -> 48757489 | I14: 506363.6 | J14: =I14/F14 -> 0.077473556 | K14: 727397.56 | L14: =K14/F14 -> 0.11129172 | M14: =SUM(I14+K14) -> 1233761.2 | N14: =M14/F14 -> 0.18876528 | O14: 141972.22 | P14: =O14/F14 -> 0.021721729 | Q14: 98299.236 | R14: =Q14/$F14 -> 0.015039769 | S14: =SUM(O14+Q14) -> 240271.45 | T14: =S14/F14 -> 0.036761497 | U14: 551591.24 | V14: =U14/F14 -> 0.084393378 | W14: 28616.676 | X14: =W14/F14 -> 0.0043783472 | Y14: 548905.9 | Z14: =Y14/F14 -> 0.083982523 | AA14: 1039376.5 | AB14: =AA14/$F14 -> 0.15902445 | AC14: =SUM(Y14+AA14) -> 1588282.4 | AD14: =AC14/F14 -> 0.24300698 | AE14: 915362.8 | AF14: =AE14/F14 -> 0.14005037 | AG14: 1115453.6 | AH14: =AG14/F14 -> 0.17066424 | AI14: 356002.01 | AJ14: =AI14/F14 -> 0.054468256 | AK14: 506612.6 | AL14: =AK14/F14 -> 0.077511654
D15: =D14+1 -> 45996 | E15: 五 | F15: =SUM(M15,S15,U15,W15,AC15,AE15,AG15,AI15,AK15) -> 6075465 | I15: 446133.99 | J15: =I15/F15 -> 0.073432073 | K15: 734858.95 | L15: =K15/F15 -> 0.12095518 | M15: =SUM(I15+K15) -> 1180992.9 | N15: =M15/F15 -> 0.19438725 | O15: 114585.37 | P15: =O15/F15 -> 0.018860346 | Q15: 84528.439 | R15: =Q15/$F15 -> 0.013913081 | S15: =SUM(O15+Q15) -> 199113.81 | T15: =S15/F15 -> 0.032773427 | U15: 513096.96 | V15: =U15/F15 -> 0.08445394 | W15: 23899.484 | X15: =W15/F15 -> 0.0039337703 | Y15: 489843.76 | Z15: =Y15/F15 -> 0.080626546 | AA15: 1095829.5 | AB15: =AA15/$F15 -> 0.18036965 | AC15: =SUM(Y15+AA15) -> 1585673.2 | AD15: =AC15/F15 -> 0.26099619 | AE15: 791931.46 | AF15: =AE15/F15 -> 0.13034911 | AG15: 1025287.3 | AH15: =AG15/F15 -> 0.16875865 | AI15: 320908.3 | AJ15: =AI15/F15 -> 0.052820368 | AK15: 434561.56 | AL15: =AK15/F15 -> 0.071527292
D16: =D15+1 -> 45997 | E16: 六 | F16: =SUM(M16,S16,U16,W16,AC16,AE16,AG16,AI16,AK16) -> 6262543 | I16: 430934.59 | J16: =I16/F16 -> 0.068811438 | K16: 745486.4 | L16: =K16/F16 -> 0.11903893 | M16: =SUM(I16+K16) -> 1176421 | N16: =M16/F16 -> 0.18785037 | O16: 106928.62 | P16: =O16/F16 -> 0.017074313 | Q16: 80073.032 | R16: =Q16/$F16 -> 0.012786025 | S16: =SUM(O16+Q16) -> 187001.65 | T16: =S16/F16 -> 0.029860338 | U16: 538009.68 | V16: =U16/F16 -> 0.08590914 | W16: 23574.093 | X16: =W16/F16 -> 0.0037643004 | Y16: 487585.78 | Z16: =Y16/F16 -> 0.077857475 | AA16: 1123632.8 | AB16: =AA16/$F16 -> 0.17942116 | AC16: =SUM(Y16+AA16) -> 1611218.5 | AD16: =AC16/F16 -> 0.25727864 | AE16: 860063.64 | AF16: =AE16/F16 -> 0.13733457 | AG16: 1031917.4 | AH16: =AG16/F16 -> 0.1647761 | AI16: 375019.9 | AJ16: =AI16/F16 -> 0.059883006 | AK16: 459317.07 | AL16: =AK16/F16 -> 0.07334354
D17: =D16+1 -> 45998 | E17: 日 | F17: =SUM(M17,S17,U17,W17,AC17,AE17,AG17,AI17,AK17) -> 7283314 | I17: 554780.54 | J17: =I17/F17 -> 0.076171444 | K17: 796646.25 | L17: =K17/F17 -> 0.10937964 | M17: =SUM(I17+K17) -> 1351426.8 | N17: =M17/F17 -> 0.18555108 | O17: 146621.8 | P17: =O17/F17 -> 0.020131193 | Q17: 93931.288 | R17: =Q17/$F17 -> 0.012896779 | S17: =SUM(O17+Q17) -> 240553.09 | T17: =S17/F17 -> 0.033027972 | U17: 633337.47 | V17: =U17/F17 -> 0.086957321 | W17: 26193.367 | X17: =W17/F17 -> 0.0035963529 | Y17: 577616.23 | Z17: =Y17/F17 -> 0.079306787 | AA17: 1247520.3 | AB17: =AA17/$F17 -> 0.1712847 | AC17: =SUM(Y17+AA17) -> 1825136.5 | AD17: =AC17/F17 -> 0.25059149 | AE17: 1038293.7 | AF17: =AE17/F17 -> 0.14255786 | AG17: 1259763.8 | AH17: =AG17/F17 -> 0.17296574 | AI17: 390546.9 | AJ17: =AI17/F17 -> 0.053622142 | AK17: 518062.41 | AL17: =AK17/F17 -> 0.07113004
D18: =D17+1 -> 45999 | E18: 一 | F18: =SUM(M18,S18,U18,W18,AC18,AE18,AG18,AI18,AK18) -> 7299829 | I18: 547022.11 | J18: =I18/F18 -> 0.074936291 | K18: 789491.49 | L18: =K18/F18 -> 0.10815205 | M18: =SUM(I18+K18) -> 1336513.6 | N18: =M18/F18 -> 0.18308834 | O18: 138327.11 | P18: =O18/F18 -> 0.018949362 | Q18: 96716.873 | R18: =Q18/$F18 -> 0.013249197 | S18: =SUM(O18+Q18) -> 235043.98 | T18: =S18/F18 -> 0.032198559 | U18: 618096.68 | V18: =U18/F18 -> 0.084672762 | W18: 26168.331 | X18: =W18/F18 -> 0.0035847868 | Y18: 569642.95 | Z18: =Y18/F18 -> 0.078035108 | AA18: 1426509.4 | AB18: =AA18/$F18 -> 0.19541682 | AC18: =SUM(Y18+AA18) -> 1996152.3 | AD18: =AC18/F18 -> 0.27345193 | AE18: 1002583 | AF18: =AE18/F18 -> 0.13734335 | AG18: 1152517.2 | AH18: =AG18/F18 -> 0.15788277 | AI18: 404682.11 | AJ18: =AI18/F18 -> 0.055437204 | AK18: 528071.79 | AL18: =AK18/F18 -> 0.072340296
D19: =D18+1 -> 46000 | E19: 二 | F19: =SUM(M19,S19,U19,W19,AC19,AE19,AG19,AI19,AK19) -> 7768298 | I19: 536497.28 | J19: =I19/F19 -> 0.069062398 | K19: 785848.36 | L19: =K19/F19 -> 0.10116094 | M19: =SUM(I19+K19) -> 1322345.6 | N19: =M19/F19 -> 0.17022334 | O19: 138497.84 | P19: =O19/F19 -> 0.017828595 | Q19: 101594.57 | R19: =Q19/$F19 -> 0.013078099 | S19: =SUM(O19+Q19) -> 240092.41 | T19: =S19/F19 -> 0.030906694 | U19: 912506.56 | V19: =U19/F19 -> 0.11746544 | W19: 23723.469 | X19: =W19/F19 -> 0.0030538825 | Y19: 567646.45 | Z19: =Y19/F19 -> 0.073072177 | AA19: 1434884.5 | AB19: =AA19/$F19 -> 0.18471028 | AC19: =SUM(Y19+AA19) -> 2002530.9 | AD19: =AC19/F19 -> 0.25778246 | AE19: 970384.7 | AF19: =AE19/F19 -> 0.124916 | AG19: 1393797.8 | AH19: =AG19/F19 -> 0.17942125 | AI19: 395930.2 | AJ19: =AI19/F19 -> 0.050967432 | AK19: 506986.29 | AL19: =AK19/F19 -> 0.065263497
D20: =D19+1 -> 46001 | E20: 三 | F20: =SUM(M20,S20,U20,W20,AC20,AE20,AG20,AI20,AK20) -> 7532086 | I20: 536138.3 | J20: =I20/F20 -> 0.071180587 | K20: 766120.91 | L20: =K20/F20 -> 0.10171431 | M20: =SUM(I20+K20) -> 1302259.2 | N20: =M20/F20 -> 0.17289489 | O20: 146173.12 | P20: =O20/F20 -> 0.019406725 | Q20: 105746.1 | R20: =Q20/$F20 -> 0.014039418 | S20: =SUM(O20+Q20) -> 251919.23 | T20: =S20/F20 -> 0.033446143 | U20: 862223.38 | V20: =U20/F20 -> 0.11447338 | W20: 20863.56 | X20: =W20/F20 -> 0.0027699578 | Y20: 551793.85 | Z20: =Y20/F20 -> 0.073259102 | AA20: 1300651.7 | AB20: =AA20/$F20 -> 0.17268148 | AC20: =SUM(Y20+AA20) -> 1852445.6 | AD20: =AC20/F20 -> 0.24594058 | AE20: 959595.78 | AF20: =AE20/F20 -> 0.12740106 | AG20: 1360502.2 | AH20: =AG20/F20 -> 0.18062755 | AI20: 410674.4 | AJ20: =AI20/F20 -> 0.054523329 | AK20: 511602.63 | AL20: =AK20/F20 -> 0.0679231
D21: =D20+1 -> 46002 | E21: 四 | F21: =SUM(M21,S21,U21,W21,AC21,AE21,AG21,AI21,AK21) -> 6664969 | G21: =SUM(F21:F27) -> 50108332 | I21: 514732.93 | J21: =I21/F21 -> 0.077229606 | K21: 727368.04 | L21: =K21/F21 -> 0.109133 | M21: =SUM(I21+K21) -> 1242101 | N21: =M21/F21 -> 0.1863626 | O21: 141947.32 | P21: =O21/F21 -> 0.021297521 | Q21: 104200.76 | R21: =Q21/$F21 -> 0.015634095 | S21: =SUM(O21+Q21) -> 246148.08 | T21: =S21/F21 -> 0.036931616 | U21: 725958.68 | V21: =U21/F21 -> 0.10892154 | W21: 0 | X21: =W21/F21 -> 0 | Y21: 512285.65 | Z21: =Y21/F21 -> 0.076862421 | AA21: 1099126.2 | AB21: =AA21/$F21 -> 0.16491093 | AC21: =SUM(Y21+AA21) -> 1611411.9 | AD21: =AC21/F21 -> 0.24177335 | AE21: 884609.09 | AF21: =AE21/F21 -> 0.13272516 | AG21: 1109856.2 | AH21: =AG21/F21 -> 0.16652083 | AI21: 364711.04 | AJ21: =AI21/F21 -> 0.054720591 | AK21: 480173.06 | AL21: =AK21/F21 -> 0.072044305
D22: =D21+1 -> 46003 | E22: 五 | F22: =SUM(M22,S22,U22,W22,AC22,AE22,AG22,AI22,AK22) -> 6216944 | I22: 446424.73 | J22: =I22/F22 -> 0.071807745 | K22: 699227.18 | L22: =K22/F22 -> 0.1124712 | M22: =SUM(I22+K22) -> 1145651.9 | N22: =M22/F22 -> 0.18427895 | O22: 111539.58 | P22: =O22/F22 -> 0.017941224 | Q22: 85058.614 | R22: =Q22/$F22 -> 0.01368174 | S22: =SUM(O22+Q22) -> 196598.2 | T22: =S22/F22 -> 0.031622964 | U22: 600760.94 | V22: =U22/F22 -> 0.096632837 | W22: 0 | X22: =W22/F22 -> 0 | Y22: 477087 | Z22: =Y22/F22 -> 0.076739793 | AA22: 1109474.5 | AB22: =AA22/$F22 -> 0.17845979 | AC22: =SUM(Y22+AA22) -> 1586561.5 | AD22: =AC22/F22 -> 0.25519959 | AE22: 817812.44 | AF22: =AE22/F22 -> 0.13154573 | AG22: 965735.85 | AH22: =AG22/F22 -> 0.15533932 | AI22: 503462.25 | AJ22: =AI22/F22 -> 0.080982272 | AK22: 400360.87 | AL22: =AK22/F22 -> 0.06439834
D23: =D22+1 -> 46004 | E23: 六 | F23: =SUM(M23,S23,U23,W23,AC23,AE23,AG23,AI23,AK23) -> 6402844 | I23: 433804.88 | J23: =I23/F23 -> 0.067751905 | K23: 744226.58 | L23: =K23/F23 -> 0.11623375 | M23: =SUM(I23+K23) -> 1178031.5 | N23: =M23/F23 -> 0.18398566 | O23: 101835.65 | P23: =O23/F23 -> 0.015904753 | Q23: 79352.261 | R23: =Q23/$F23 -> 0.012393284 | S23: =SUM(O23+Q23) -> 181187.92 | T23: =S23/F23 -> 0.028298037 | U23: 665423.59 | V23: =U23/F23 -> 0.10392625 | W23: 0 | X23: =W23/F23 -> 0 | Y23: 507445.34 | Z23: =Y23/F23 -> 0.079253117 | AA23: 1163165 | AB23: =AA23/$F23 -> 0.1816638 | AC23: =SUM(Y23+AA23) -> 1670610.3 | AD23: =AC23/F23 -> 0.26091692 | AE23: 889034.09 | AF23: =AE23/F23 -> 0.13884988 | AG23: 948183.88 | AH23: =AG23/F23 -> 0.14808793 | AI23: 435958.29 | AJ23: =AI23/F23 -> 0.068088226 | AK23: 434414.45 | AL23: =AK23/F23 -> 0.067847108
D24: =D23+1 -> 46005 | E24: 日 | F24: =SUM(M24,S24,U24,W24,AC24,AE24,AG24,AI24,AK24) -> 7638376 | I24: 557263.32 | J24: =I24/F24 -> 0.072955733 | K24: 783007.61 | L24: =K24/F24 -> 0.1025097 | M24: =SUM(I24+K24) -> 1340270.9 | N24: =M24/F24 -> 0.17546543 | O24: 137204.9 | P24: =O24/F24 -> 0.017962574 | Q24: 94281.232 | R24: =Q24/$F24 -> 0.012343099 | S24: =SUM(O24+Q24) -> 231486.13 | T24: =S24/F24 -> 0.030305673 | U24: 878229.21 | V24: =U24/F24 -> 0.11497591 | W24: 0 | X24: =W24/F24 -> 0 | Y24: 566410.89 | Z24: =Y24/F24 -> 0.074153313 | AA24: 1300557.6 | AB24: =AA24/$F24 -> 0.17026624 | AC24: =SUM(Y24+AA24) -> 1866968.5 | AD24: =AC24/F24 -> 0.24441956 | AE24: 1065732 | AF24: =AE24/F24 -> 0.13952337 | AG24: 1197865.6 | AH24: =AG24/F24 -> 0.15682203 | AI24: 567724.17 | AJ24: =AI24/F24 -> 0.074325246 | AK24: 490099.49 | AL24: =AK24/F24 -> 0.064162786
D25: =D24+1 -> 46006 | E25: 一 | F25: =SUM(M25,S25,U25,W25,AC25,AE25,AG25,AI25,AK25) -> 7520294 | I25: 546271.89 | J25: =I25/F25 -> 0.072639698 | K25: 771360.39 | L25: =K25/F25 -> 0.10257051 | M25: =SUM(I25+K25) -> 1317632.3 | N25: =M25/F25 -> 0.17521021 | O25: 130926.21 | P25: =O25/F25 -> 0.01740972 | Q25: 96616.123 | R25: =Q25/$F25 -> 0.012847386 | S25: =SUM(O25+Q25) -> 227542.33 | T25: =S25/F25 -> 0.030257106 | U25: 787779.98 | V25: =U25/F25 -> 0.10475388 | W25: 0 | X25: =W25/F25 -> 0 | Y25: 578974.55 | Z25: =Y25/F25 -> 0.076988286 | AA25: 1308937 | AB25: =AA25/$F25 -> 0.17405396 | AC25: =SUM(Y25+AA25) -> 1887911.5 | AD25: =AC25/F25 -> 0.25104225 | AE25: 1031720.9 | AF25: =AE25/F25 -> 0.13719157 | AG25: 1124027.7 | AH25: =AG25/F25 -> 0.14946593 | AI25: 633550.95 | AJ25: =AI25/F25 -> 0.084245503 | AK25: 510128.33 | AL25: =AK25/F25 -> 0.067833561
D26: =D25+1 -> 46007 | E26: 二 | F26: =SUM(M26,S26,U26,W26,AC26,AE26,AG26,AI26,AK26) -> 8052028 | I26: 525147.41 | J26: =I26/F26 -> 0.065219273 | K26: 820752.58 | L26: =K26/F26 -> 0.10193116 | M26: =SUM(I26+K26) -> 1345900 | N26: =M26/F26 -> 0.16715044 | O26: 123993.38 | P26: =O26/F26 -> 0.015399025 | Q26: 93289.863 | R26: =Q26/$F26 -> 0.011585884 | S26: =SUM(O26+Q26) -> 217283.24 | T26: =S26/F26 -> 0.026984909 | U26: 1325852.6 | V26: =U26/F26 -> 0.1646607 | W26: 0 | X26: =W26/F26 -> 0 | Y26: 551723.47 | Z26: =Y26/F26 -> 0.068519815 | AA26: 1288839.6 | AB26: =AA26/$F26 -> 0.16006397 | AC26: =SUM(Y26+AA26) -> 1840563.1 | AD26: =AC26/F26 -> 0.22858379 | AE26: 982638.67 | AF26: =AE26/F26 -> 0.12203617 | AG26: 814453.79 | AH26: =AG26/F26 -> 0.1011489 | AI26: 574360.64 | AJ26: =AI26/F26 -> 0.071331177 | AK26: 950976.01 | AL26: =AK26/F26 -> 0.11810391
D27: =D26+1 -> 46008 | E27: 三 | F27: =SUM(M27,S27,U27,W27,AC27,AE27,AG27,AI27,AK27) -> 7612877 | I27: 521102.05 | J27: =I27/F27 -> 0.068450081 | K27: 799328.78 | L27: =K27/F27 -> 0.10499694 | M27: =SUM(I27+K27) -> 1320430.8 | N27: =M27/F27 -> 0.17344702 | O27: 129448.75 | P27: =O27/F27 -> 0.017003919 | Q27: 94591.239 | R27: =Q27/$F27 -> 0.012425163 | S27: =SUM(O27+Q27) -> 224039.99 | T27: =S27/F27 -> 0.029429083 | U27: 1244521.4 | V27: =U27/F27 -> 0.16347583 | W27: 0 | X27: =W27/F27 -> 0 | Y27: 540832.07 | Z27: =Y27/F27 -> 0.071041745 | AA27: 1207800.7 | AB27: =AA27/$F27 -> 0.15865234 | AC27: =SUM(Y27+AA27) -> 1748632.8 | AD27: =AC27/F27 -> 0.22969408 | AE27: 936303.12 | AF27: =AE27/F27 -> 0.12298939 | AG27: 802956.36 | AH27: =AG27/F27 -> 0.10547345 | AI27: 560274.54 | AJ27: =AI27/F27 -> 0.073595638 | AK27: 775717.96 | AL27: =AK27/F27 -> 0.10189551
D28: =D27+1 -> 46009 | E28: 四 | F28: =SUM(M28,S28,U28,W28,AC28,AE28,AG28,AI28,AK28) -> 7258886 | G28: =SUM(F28:F34) -> 51085132 | I28: 495054.44 | J28: =I28/F28 -> 0.068199782 | K28: 752543.8 | L28: =K28/F28 -> 0.10367208 | M28: =SUM(I28+K28) -> 1247598.2 | N28: =M28/F28 -> 0.17187186 | O28: 127724.62 | P28: =O28/F28 -> 0.017595623 | Q28: 95850.483 | R28: =Q28/$F28 -> 0.013204572 | S28: =SUM(O28+Q28) -> 223575.11 | T28: =S28/F28 -> 0.030800195 | U28: 1182416.7 | V28: =U28/F28 -> 0.16289231 | W28: 0 | X28: =W28/F28 -> 0 | Y28: 522726.87 | Z28: =Y28/F28 -> 0.072011996 | AA28: 1082526.7 | AB28: =AA28/$F28 -> 0.14913124 | AC28: =SUM(Y28+AA28) -> 1605253.6 | AD28: =AC28/F28 -> 0.22114324 | AE28: 863902.47 | AF28: =AE28/F28 -> 0.11901309 | AG28: 850615.86 | AH28: =AG28/F28 -> 0.1171827 | AI28: 544313.08 | AJ28: =AI28/F28 -> 0.07498576 | AK28: 741210.99 | AL28: =AK28/F28 -> 0.10211085
D29: =D28+1 -> 46010 | E29: 五 | F29: =SUM(M29,S29,U29,W29,AC29,AE29,AG29,AI29,AK29) -> 6600497 | I29: 440324.25 | J29: =I29/F29 -> 0.066710772 | K29: 728731.38 | L29: =K29/F29 -> 0.11040553 | M29: =SUM(I29+K29) -> 1169055.6 | N29: =M29/F29 -> 0.1771163 | O29: 101584.26 | P29: =O29/F29 -> 0.015390395 | Q29: 82371.029 | R29: =Q29/$F29 -> 0.012479519 | S29: =SUM(O29+Q29) -> 183955.29 | T29: =S29/F29 -> 0.027869914 | U29: 1108455.1 | V29: =U29/F29 -> 0.1679351 | W29: 0 | X29: =W29/F29 -> 0 | Y29: 478758.96 | Z29: =Y29/F29 -> 0.072533775 | AA29: 1132886.7 | AB29: =AA29/$F29 -> 0.17163658 | AC29: =SUM(Y29+AA29) -> 1611645.7 | AD29: =AC29/F29 -> 0.24417035 | AE29: 766636.2 | AF29: =AE29/F29 -> 0.11614825 | AG29: 699334.19 | AH29: =AG29/F29 -> 0.10595175 | AI29: 514438.96 | AJ29: =AI29/F29 -> 0.077939428 | AK29: 546975.92 | AL29: =AK29/F29 -> 0.082868899
D30: =D29+1 -> 46011 | E30: 六 | F30: =SUM(M30,S30,U30,W30,AC30,AE30,AG30,AI30,AK30) -> 6936693 | I30: 423837.22 | J30: =I30/F30 -> 0.061100761 | K30: 762853 | L30: =K30/F30 -> 0.10997359 | M30: =SUM(I30+K30) -> 1186690.2 | N30: =M30/F30 -> 0.17107435 | O30: 99414.91 | P30: =O30/F30 -> 0.014331744 | Q30: 76977.587 | R30: =Q30/$F30 -> 0.011097159 | S30: =SUM(O30+Q30) -> 176392.5 | T30: =S30/F30 -> 0.025428903 | U30: 1161865 | V30: =U30/F30 -> 0.16749552 | W30: 0 | X30: =W30/F30 -> 0 | Y30: 478170.38 | Z30: =Y30/F30 -> 0.068933479 | AA30: 1174235.6 | AB30: =AA30/$F30 -> 0.16927888 | AC30: =SUM(Y30+AA30) -> 1652406 | AD30: =AC30/F30 -> 0.23821236 | AE30: 863997.8 | AF30: =AE30/F30 -> 0.12455471 | AG30: 727278.97 | AH30: =AG30/F30 -> 0.1048452 | AI30: 585090.36 | AJ30: =AI30/F30 -> 0.084347161 | AK30: 582972.16 | AL30: =AK30/F30 -> 0.0840418
D31: =D30+1 -> 46012 | E31: 日 | F31: =SUM(M31,S31,U31,W31,AC31,AE31,AG31,AI31,AK31) -> 8044891 | I31: 539900.11 | J31: =I31/F31 -> 0.067110929 | K31: 810076.61 | L31: =K31/F31 -> 0.10069454 | M31: =SUM(I31+K31) -> 1349976.7 | N31: =M31/F31 -> 0.16780547 | O31: 129234.63 | P31: =O31/F31 -> 0.016064186 | Q31: 90333.203 | R31: =Q31/$F31 -> 0.011228642 | S31: =SUM(O31+Q31) -> 219567.83 | T31: =S31/F31 -> 0.027292828 | U31: 1399381.4 | V31: =U31/F31 -> 0.17394659 | W31: 0 | X31: =W31/F31 -> 0 | Y31: 542589.33 | Z31: =Y31/F31 -> 0.067445206 | AA31: 1265397.5 | AB31: =AA31/$F31 -> 0.15729207 | AC31: =SUM(Y31+AA31) -> 1807986.9 | AD31: =AC31/F31 -> 0.22473727 | AE31: 1034151.3 | AF31: =AE31/F31 -> 0.12854759 | AG31: 813556.87 | AH31: =AG31/F31 -> 0.10112715 | AI31: 626758.57 | AJ31: =AI31/F31 -> 0.077907652 | AK31: 793511.44 | AL31: =AK31/F31 -> 0.09863545
D32: =D31+1 -> 46013 | E32: 一 | F32: =SUM(M32,S32,U32,W32,AC32,AE32,AG32,AI32,AK32) -> 8079828 | I32: 524083.67 | J32: =I32/F32 -> 0.064863221 | K32: 801157.37 | L32: =K32/F32 -> 0.09915525 | M32: =SUM(I32+K32) -> 1325241 | N32: =M32/F32 -> 0.16401847 | O32: 121060.48 | P32: =O32/F32 -> 0.014983052 | Q32: 90570.935 | R32: =Q32/$F32 -> 0.011209513 | S32: =SUM(O32+Q32) -> 211631.42 | T32: =S32/F32 -> 0.026192565 | U32: 1315764.7 | V32: =U32/F32 -> 0.16284563 | W32: 0 | X32: =W32/F32 -> 0 | Y32: 529849.79 | Z32: =Y32/F32 -> 0.065576865 | AA32: 1621243.4 | AB32: =AA32/$F32 -> 0.20065321 | AC32: =SUM(Y32+AA32) -> 2151093.2 | AD32: =AC32/F32 -> 0.26623008 | AE32: 977986.21 | AF32: =AE32/F32 -> 0.12104047 | AG32: 797520.65 | AH32: =AG32/F32 -> 0.098705151 | AI32: 609490.56 | AJ32: =AI32/F32 -> 0.075433606 | AK32: 691100.23 | AL32: =AK32/F32 -> 0.085534027
D33: =D32+1 -> 46014 | E33: 二 | F33: =SUM(M33,S33,U33,W33,AC33,AE33,AG33,AI33,AK33) -> 7688414 | I33: 529938.45 | J33: =I33/F33 -> 0.068926888 | K33: 732906.96 | L33: =K33/F33 -> 0.095326158 | M33: =SUM(I33+K33) -> 1262845.4 | N33: =M33/F33 -> 0.16425305 | O33: 219102.66 | P33: =O33/F33 -> 0.02849777 | Q33: 94220.516 | R33: =Q33/$F33 -> 0.01225487 | S33: =SUM(O33+Q33) -> 313323.17 | T33: =S33/F33 -> 0.04075264 | U33: 1225827.3 | V33: =U33/F33 -> 0.15943825 | W33: 0 | X33: =W33/F33 -> 0 | Y33: 521443.79 | Z33: =Y33/F33 -> 0.067822023 | AA33: 1493282.5 | AB33: =AA33/$F33 -> 0.19422503 | AC33: =SUM(Y33+AA33) -> 2014726.3 | AD33: =AC33/F33 -> 0.26204706 | AE33: 945977.59 | AF33: =AE33/F33 -> 0.12303937 | AG33: 771397.64 | AH33: =AG33/F33 -> 0.10033248 | AI33: 522528.09 | AJ33: =AI33/F33 -> 0.067963054 | AK33: 631788.52 | AL33: =AK33/F33 -> 0.082174102
D34: =D33+1 -> 46015 | E34: 三 | F34: =SUM(M34,S34,U34,W34,AC34,AE34,AG34,AI34,AK34) -> 6475923 | I34: 446245.79 | J34: =I34/F34 -> 0.068908446 | K34: 719147.36 | L34: =K34/F34 -> 0.1110494 | M34: =SUM(I34+K34) -> 1165393.1 | N34: =M34/F34 -> 0.17995785 | O34: 174928.49 | P34: =O34/F34 -> 0.027012133 | Q34: 87962.283 | R34: =Q34/$F34 -> 0.013582972 | S34: =SUM(O34+Q34) -> 262890.78 | T34: =S34/F34 -> 0.040595105 | U34: 967791.19 | V34: =U34/F34 -> 0.14944452 | W34: 0 | X34: =W34/F34 -> 0 | Y34: 502516.54 | Z34: =Y34/F34 -> 0.07759767 | AA34: 1338368.4 | AB34: =AA34/$F34 -> 0.20666836 | AC34: =SUM(Y34+AA34) -> 1840884.9 | AD34: =AC34/F34 -> 0.28426603 | AE34: 778252.01 | AF34: =AE34/F34 -> 0.12017623 | AG34: 523867.75 | AH34: =AG34/F34 -> 0.080894685 | AI34: 402802.4 | AJ34: =AI34/F34 -> 0.062199998 | AK34: 534040.79 | AL34: =AK34/F34 -> 0.082465587
D35: =D34+1 -> 46016 | E35: 四 | F35: =SUM(M35,S35,U35,W35,AC35,AE35,AG35,AI35,AK35) -> 6755981 | G35: =SUM(F35:F41) -> 48124067 | I35: 504615.87 | J35: =I35/F35 -> 0.074691724 | K35: 729765.21 | L35: =K35/F35 -> 0.10801765 | M35: =SUM(I35+K35) -> 1234381.1 | N35: =M35/F35 -> 0.18270938 | O35: 169565.3 | P35: =O35/F35 -> 0.025098546 | Q35: 102004.69 | R35: =Q35/$F35 -> 0.015098428 | S35: =SUM(O35+Q35) -> 271570 | T35: =S35/F35 -> 0.040196974 | U35: 1040831.5 | V35: =U35/F35 -> 0.15406075 | W35: 0 | X35: =W35/F35 -> 0 | Y35: 506056.25 | Z35: =Y35/F35 -> 0.074904925 | AA35: 1195413.4 | AB35: =AA35/$F35 -> 0.1769415 | AC35: =SUM(Y35+AA35) -> 1701469.7 | AD35: =AC35/F35 -> 0.25184642 | AE35: 841421.43 | AF35: =AE35/F35 -> 0.12454467 | AG35: 636153.52 | AH35: =AG35/F35 -> 0.094161532 | AI35: 420351.31 | AJ35: =AI35/F35 -> 0.062219138 | AK35: 609802.51 | AL35: =AK35/F35 -> 0.090261135
D36: =D35+1 -> 46017 | E36: 五 | F36: =SUM(M36,S36,U36,W36,AC36,AE36,AG36,AI36,AK36) -> 6278111 | I36: 435543.96 | J36: =I36/F36 -> 0.069375002 | K36: 770445.11 | L36: =K36/F36 -> 0.12271926 | M36: =SUM(I36+K36) -> 1205989.1 | N36: =M36/F36 -> 0.19209426 | O36: 143853.19 | P36: =O36/F36 -> 0.022913451 | Q36: 80971.483 | R36: =Q36/$F36 -> 0.012897428 | S36: =SUM(O36+Q36) -> 224824.67 | T36: =S36/F36 -> 0.035810879 | U36: 928360.25 | V36: =U36/F36 -> 0.14787254 | W36: 0 | X36: =W36/F36 -> 0 | Y36: 443715.88 | Z36: =Y36/F36 -> 0.070676654 | AA36: 1198766.8 | AB36: =AA36/$F36 -> 0.19094386 | AC36: =SUM(Y36+AA36) -> 1642482.7 | AD36: =AC36/F36 -> 0.26162052 | AE36: 745558.49 | AF36: =AE36/F36 -> 0.11875523 | AG36: 550674.08 | AH36: =AG36/F36 -> 0.08771334 | AI36: 420047.82 | AJ36: =AI36/F36 -> 0.066906721 | AK36: 560173.96 | AL36: =AK36/F36 -> 0.089226513
D37: =D36+1 -> 46018 | E37: 六 | F37: =SUM(M37,S37,U37,W37,AC37,AE37,AG37,AI37,AK37) -> 6552614 | I37: 411341.63 | J37: =I37/F37 -> 0.062775196 | K37: 732056 | L37: =K37/F37 -> 0.11171969 | M37: =SUM(I37+K37) -> 1143397.6 | N37: =M37/F37 -> 0.17449489 | O37: 141294.43 | P37: =O37/F37 -> 0.021563063 | Q37: 73642.005 | R37: =Q37/$F37 -> 0.011238569 | S37: =SUM(O37+Q37) -> 214936.43 | T37: =S37/F37 -> 0.032801632 | U37: 1036374.9 | V37: =U37/F37 -> 0.15816206 | W37: 0 | X37: =W37/F37 -> 0 | Y37: 478777.51 | Z37: =Y37/F37 -> 0.073066644 | AA37: 1213088.7 | AB37: =AA37/$F37 -> 0.18513049 | AC37: =SUM(Y37+AA37) -> 1691866.2 | AD37: =AC37/F37 -> 0.25819714 | AE37: 815570.19 | AF37: =AE37/F37 -> 0.12446486 | AG37: 586415 | AH37: =AG37/F37 -> 0.089493292 | AI37: 497175.73 | AJ37: =AI37/F37 -> 0.075874411 | AK37: 566877.93 | AL37: =AK37/F37 -> 0.086511723
D38: =D37+1 -> 46019 | E38: 日 | F38: =SUM(M38,S38,U38,W38,AC38,AE38,AG38,AI38,AK38) -> 7539331 | I38: 516487.46 | J38: =I38/F38 -> 0.068505742 | K38: 767610.34 | L38: =K38/F38 -> 0.10181412 | M38: =SUM(I38+K38) -> 1284097.8 | N38: =M38/F38 -> 0.17031986 | O38: 195018.19 | P38: =O38/F38 -> 0.025866776 | Q38: 85910.098 | R38: =Q38/$F38 -> 0.011394923 | S38: =SUM(O38+Q38) -> 280928.29 | T38: =S38/F38 -> 0.0372617 | U38: 1281163.9 | V38: =U38/F38 -> 0.16993072 | W38: 0 | X38: =W38/F38 -> 0 | Y38: 532340.03 | Z38: =Y38/F38 -> 0.070608391 | AA38: 1323828.6 | AB38: =AA38/$F38 -> 0.17558967 | AC38: =SUM(Y38+AA38) -> 1856168.7 | AD38: =AC38/F38 -> 0.24619806 | AE38: 974962.62 | AF38: =AE38/F38 -> 0.12931686 | AG38: 684509.62 | AH38: =AG38/F38 -> 0.090791826 | AI38: 557578.33 | AJ38: =AI38/F38 -> 0.073955942 | AK38: 619921.72 | AL38: =AK38/F38 -> 0.08222503
D39: =D38+1 -> 46020 | E39: 一 | F39: =SUM(M39,S39,U39,W39,AC39,AE39,AG39,AI39,AK39) -> 7494235 | I39: 500845.24 | J39: =I39/F39 -> 0.066830736 | K39: 753870.26 | L39: =K39/F39 -> 0.10059336 | M39: =SUM(I39+K39) -> 1254715.5 | N39: =M39/F39 -> 0.16742409 | O39: 155926.05 | P39: =O39/F39 -> 0.020806133 | Q39: 86507.4 | R39: =Q39/$F39 -> 0.011543193 | S39: =SUM(O39+Q39) -> 242433.45 | T39: =S39/F39 -> 0.032349326 | U39: 1229692.8 | V39: =U39/F39 -> 0.16408517 | W39: 0 | X39: =W39/F39 -> 0 | Y39: 533575.29 | Z39: =Y39/F39 -> 0.0711981 | AA39: 1478437.6 | AB39: =AA39/$F39 -> 0.19727665 | AC39: =SUM(Y39+AA39) -> 2012012.9 | AD39: =AC39/F39 -> 0.26847475 | AE39: 928612.59 | AF39: =AE39/F39 -> 0.12391026 | AG39: 674261.52 | AH39: =AG39/F39 -> 0.089970693 | AI39: 532280.16 | AJ39: =AI39/F39 -> 0.071025283 | AK39: 620226.07 | AL39: =AK39/F39 -> 0.082760424
D40: =D39+1 -> 46021 | E40: 二 | F40: =SUM(M40,S40,U40,W40,AC40,AE40,AG40,AI40,AK40) -> 7242022 | I40: 546978.07 | J40: =I40/F40 -> 0.075528363 | K40: 699592.89 | L40: =K40/F40 -> 0.096601873 | M40: =SUM(I40+K40) -> 1246571 | N40: =M40/F40 -> 0.17213024 | O40: 156788.28 | P40: =O40/F40 -> 0.021649793 | Q40: 88902.038 | R40: =Q40/$F40 -> 0.012275859 | S40: =SUM(O40+Q40) -> 245690.31 | T40: =S40/F40 -> 0.033925652 | U40: 1166492.3 | V40: =U40/F40 -> 0.16107274 | W40: 0 | X40: =W40/F40 -> 0 | Y40: 523058.89 | Z40: =Y40/F40 -> 0.072225531 | AA40: 1463347.4 | AB40: =AA40/$F40 -> 0.20206337 | AC40: =SUM(Y40+AA40) -> 1986406.3 | AD40: =AC40/F40 -> 0.2742889 | AE40: 903715.9 | AF40: =AE40/F40 -> 0.12478779 | AG40: 612661.84 | AH40: =AG40/F40 -> 0.084598175 | AI40: 479158.73 | AJ40: =AI40/F40 -> 0.066163666 | AK40: 601325.65 | AL40: =AK40/F40 -> 0.083032839
D41: =D40+1 -> 46022 | E41: 三 | F41: =SUM(M41,S41,U41,W41,AC41,AE41,AG41,AI41,AK41) -> 6261773 | I41: 438369.89 | J41: =I41/F41 -> 0.070007311 | K41: 672921.99 | L41: =K41/F41 -> 0.10746509 | M41: =SUM(I41+K41) -> 1111291.9 | N41: =M41/F41 -> 0.1774724 | O41: 153906.67 | P41: =O41/F41 -> 0.024578768 | Q41: 79915.038 | R41: =Q41/$F41 -> 0.012762366 | S41: =SUM(O41+Q41) -> 233821.71 | T41: =S41/F41 -> 0.037341134 | U41: 948924.54 | V41: =U41/F41 -> 0.15154247 | W41: 0 | X41: =W41/F41 -> 0 | Y41: 484480.8 | Z41: =Y41/F41 -> 0.077371185 | AA41: 1309558.5 | AB41: =AA41/$F41 -> 0.20913542 | AC41: =SUM(Y41+AA41) -> 1794039.3 | AD41: =AC41/F41 -> 0.2865066 | AE41: 731503.57 | AF41: =AE41/F41 -> 0.11682052 | AG41: 481541.38 | AH41: =AG41/F41 -> 0.076901763 | AI41: 415961.95 | AJ41: =AI41/F41 -> 0.066428782 | AK41: 544688.65 | AL41: =AK41/F41 -> 0.08698633
F42: =SUM(M42,S42,U42,W42,AC42,AE42,AG42,AI42,AK42) -> 0 | J42: =I42/F42 -> #DIV/0! | L42: =K42/F42 -> #DIV/0! | M42: =SUM(I42+K42) -> 0 | N42: =M42/F42 -> #DIV/0! | P42: =O42/F42 -> #DIV/0! | R42: =Q42/$F42 -> #DIV/0! | S42: =SUM(O42+Q42) -> 0 | T42: =S42/F42 -> #DIV/0! | V42: =U42/F42 -> #DIV/0! | X42: =W42/F42 -> #DIV/0! | Z42: =Y42/F42 -> #DIV/0! | AB42: =AA42/$F42 -> #DIV/0! | AC42: =SUM(Y42+AA42) -> 0 | AD42: =AC42/F42 -> #DIV/0! | AF42: =AE42/F42 -> #DIV/0! | AH42: =AG42/F42 -> #DIV/0! | AJ42: =AI42/F42 -> #DIV/0! | AL42: =AK42/F42 -> #DIV/0!
F43: =SUM(M43,S43,U43,W43,AC43,AE43,AG43,AI43,AK43) -> 0 | J43: =I43/F43 -> #DIV/0! | L43: =K43/F43 -> #DIV/0! | M43: =SUM(I43+K43) -> 0 | N43: =M43/F43 -> #DIV/0! | P43: =O43/F43 -> #DIV/0! | R43: =Q43/$F43 -> #DIV/0! | S43: =SUM(O43+Q43) -> 0 | T43: =S43/F43 -> #DIV/0! | V43: =U43/F43 -> #DIV/0! | X43: =W43/F43 -> #DIV/0! | Z43: =Y43/F43 -> #DIV/0! | AB43: =AA43/$F43 -> #DIV/0! | AC43: =SUM(Y43+AA43) -> 0 | AD43: =AC43/F43 -> #DIV/0! | AF43: =AE43/F43 -> #DIV/0! | AH43: =AG43/F43 -> #DIV/0! | AJ43: =AI43/F43 -> #DIV/0! | AL43: =AK43/F43 -> #DIV/0!
