Workbook

Sheet 填寫舉例
A2: 7 | B2: 月別 | C2: 工廠名 | D2: ・・・・・・・・
A4: （１）收支狀況 | E4: ※單位：千元 | G4: （２）ＫＰＩ達成進度 | M4: （３）業績構成比 | S4: （４）訂單數量構成比
B5: 當月 | C5: 前月 | D5: 差異 | E5: 累計 | H5: KPI | I5: 當月 | J5: 前月 | K5: 累計 | L5: ※補充 | N5: 當月 | O5: 比例 | P5: 前月 | Q5: 差異 | T5: 當月 | U5: 比例 | V5: 前月 | W5: 差異
A6: 業績金額 | B6: 500000 | C6: 510000 | D6: =B6-C6 -> -10000 | E6: =B6+C6 -> 1010000 | G6: 人時生產性1 | H6: 110 | I6: 100 | J6: 90 | L6: 個／MH | M6: 飯糰 | N6: 150000 | O6: =IFERROR(N6/$B$6,"") -> 0.3 | P6: 0.4 | Q6: =IFERROR(O6-P6,"") -> -0.1 | S6: 飯糰 | T6: 35000 | U6: =IFERROR(T6/$B$7,"") -> 0.35 | V6: 0.3 | W6: =IFERROR(U6-V6,"") -> 0.05
A7: 訂單數量 | B7: 100000 | C7: 110000 | D7: =B7-C7 -> -10000 | E7: =B7+C7 -> 210000 | G7: 人時生產性2 | H7: 0.8 | I7: 0.85 | J7: 0.81 | K7: 0.84 | L7: 達成率 | M7: 大口飯糰 | N7: 100000 | O7: =IFERROR(N7/$B$6,"") -> 0.2 | P7: 0.15 | Q7: =IFERROR(O7-P7,"") -> 0.05 | S7: 大口飯糰 | T7: 30000 | U7: =IFERROR(T7/$B$7,"") -> 0.3 | V7: 0.15 | W7: =IFERROR(U7-V7,"") -> 0.15
A8: 材料費 | B8: 250000 | C8: 260000 | D8: =B8-C8 -> -10000 | E8: =B8+C8 -> 510000 | G8: 半成品報廢 | H8: 0.0025 | I8: 0.0024 | J8: 0.0023 | K8: 0.00235 | L8: 報廢率 | M8: 便當 | N8: 160000 | O8: =IFERROR(N8/$B$6,"") -> 0.32 | P8: 0.28 | Q8: =IFERROR(O8-P8,"") -> 0.04 | S8: 便當 | T8: 20000 | U8: =IFERROR(T8/$B$7,"") -> 0.2 | V8: 0.28 | W8: =IFERROR(U8-V8,"") -> -0.08
A9: 材料費率 | B9: =B8/B6 -> 0.5 | C9: =C8/C6 -> 0.50980392 | D9: =B9-C9 -> -0.0098039216 | E9: =(B9+C9)/2 -> 0.50490196 | G9: 半成品超用 | H9: 0.006 | I9: 0.009 | J9: 0.0095 | K9: 0.0092 | L9: 超用率 | M9: 調理麵 | N9: 90000 | O9: =IFERROR(N9/$B$6,"") -> 0.18 | P9: 0.17 | Q9: =IFERROR(O9-P9,"") -> 0.01 | S9: 調理麵 | T9: 15000 | U9: =IFERROR(T9/$B$7,"") -> 0.15 | V9: 0.27 | W9: =IFERROR(U9-V9,"") -> -0.12
A10: 勞務成本 | B10: 100000 | C10: 105000 | D10: =B10-C10 -> -5000 | E10: =B10+C10 -> 205000 | G10: 固定產線 | H10: 0.95 | I10: 0.9 | J10: 0.92 | K10: 0.91 | L10: 導入率 | M10: 調理麵包 | N10: - | O10: =IFERROR(N10/$B$6,"") | P10: -% | Q10: =IFERROR(O10-P10,"") | S10: 調理麵包 | T10: - | U10: =IFERROR(T10/$B$7,"") | V10: -% | W10: =IFERROR(U10-V10,"")
A11: 勞務費率 | B11: =B10/B6 -> 0.2 | C11: =C10/C6 -> 0.20588235 | D11: =B11-C11 -> -0.0058823529 | E11: =(B11+C11)/2 -> 0.20294118 | G11: 教育訓練 | H11: 0.8 | I11: 0.85 | J11: 1 | K11: 0.92 | L11: 實施率 | M11: 袋裝調理麵包 | N11: - | O11: =IFERROR(N11/$B$6,"") | P11: -% | Q11: =IFERROR(O11-P11,"") | S11: 袋裝調理麵包 | T11: - | U11: =IFERROR(T11/$B$7,"") | V11: -% | W11: =IFERROR(U11-V11,"")
M12: 義大利麵 | N12: - | O12: =IFERROR(N12/$B$6,"") | P12: -% | Q12: =IFERROR(O12-P12,"") | S12: 義大利麵 | T12: - | U12: =IFERROR(T12/$B$7,"") | V12: -% | W12: =IFERROR(U12-V12,"")
A13: （５）品群別人時生產性 | M13: 調理包 | N13: - | O13: =IFERROR(N13/$B$6,"") | P13: -% | Q13: =IFERROR(O13-P13,"") | S13: 調理包 | T13: - | U13: =IFERROR(T13/$B$7,"") | V13: -% | W13: =IFERROR(U13-V13,"")
B14: 當月 | C14: 前月 | D14: 差異 | E14: 累計 | H14: 當月 | I14: 前月 | J14: 差異 | K14: 累計 | O14: =SUM(O6:O13) -> 1 | P14: =SUM(P6:P13) -> 1 | U14: =SUM(U6:U13) -> 1 | V14: =SUM(V6:V13) -> 1
A15: 飯糰 | B15: 600 | C15: 660 | D15: =B15-C15 -> -60 | E15: =(B15+C15)/2 -> 630 | G15: 調理麵包 | J15: =H15-I15 -> 0 | M15: （７）原因別分析
A16: 大口飯糰 | B16: 800 | C16: 780 | D16: =B16-C16 -> 20 | E16: =(B16+C16)/2 -> 790 | G16: 袋裝調理麵包 | J16: =H16-I16 -> 0 | N16: 合計 | P16: 作業原因 | R16: 規格原因
A17: 便當 | B17: 130 | C17: 111 | D17: =B17-C17 -> 19 | E17: =(B17+C17)/2 -> 120.5 | G17: 義大利麵 | J17: =H17-I17 -> 0 | N17: 金額 | O17: 比例 | P17: 金額 | Q17: 比例 | R17: 金額 | S17: 比例
A18: 調理麵 | B18: 140 | C18: 165 | D18: =B18-C18 -> -25 | E18: =(B18+C18)/2 -> 152.5 | G18: 調理包 | J18: =H18-I18 -> 0 | M18: 半成品報廢 | N18: 1200 | O18: =N18/$B$6 -> 0.0024 | P18: 900 | Q18: =IFERROR(P18/$B$6,"") -> 0.0018 | R18: 300 | S18: =IFERROR(R18/$B$6,"") -> 0.0006
M19: 半成品超用 | N19: 4500 | O19: =N19/$B$6 -> 0.009 | P19: 3500 | Q19: =IFERROR(P19/$B$6,"") -> 0.007 | R19: 1000 | S19: =IFERROR(R19/$B$6,"") -> 0.002
A20: （６）人時生產性前幾名品項
B21: 排名 | C21: 商品名 | F21: 人數 | G21: 產能 | H21: 人時生產性 | I21: 前月比 | J21: 主要原因&對策 | M21: （８）報廢原因別前幾名品項
A22: 飯糰 | B22: 1 | C22: 手巻明太子 | F22: 3 | G22: 3000 | H22: 1000 | I22: 10 | J22: 減少暫時停止生產,人時UP | M22: 半成品報廢 | N22: 排名 | O22: 商品名 | R22: 半成品名 | U22: 單價 | V22: 報廢率 | W22: 數量 | X22: 金額 | Y22: 前月比 | Z22: 主要原因&對策
B23: 2 | M23: 作業原因 | N23: 1 | O23: 明太子海苔便當 | R23: 油炸白身魚 | U23: 10 | V23: 0.15 | W23: 10 | X23: =W23*U23 -> 100 | Y23: 80 | Z23: 油調過多報廢。變更條件。
B24: 3 | N24: 2 | X24: =W24*U24 -> 0
B25: 4 | N25: 3 | X25: =W25*U25 -> 0
B26: 5 | N26: 4 | X26: =W26*U26 -> 0
B27: ▼1 | C27: 手巻卵黄雞絞肉 | F27: 4 | G27: 2800 | H27: 700 | I27: 6/30新商品 | J27: 因組裝2食材,人員增加,產速減少 | N27: 5 | X27: =W27*U27 -> 0
B28: ▼2 | U28: 前幾名合計比例 | V28: =X28/N18 -> 0.083333333 | W28: 前幾名合計金額 | X28: =SUM(X23:X27) -> 100
B29: ▼3 | M29: 規格原因 | N29: 1 | O29: 海老炒飯 | R29: 川燙蝦子拌醬 | U29: 5.55 | V29: 0.21 | W29: 50 | X29: =W29*U29 -> 277.5 | Y29: 35 | Z29: 蝦子入數不足
B30: ▼4 | N30: 2 | X30: =W30*U30 -> 0
B31: ▼5 | N31: 3 | X31: =W31*U31 -> 0
N32: 4 | X32: =W32*U32 -> 0
B33: 排名 | C33: 商品名 | F33: 人數 | G33: 產能 | H33: 人時生產性 | I33: 前月比 | J33: 主要原因&對策 | N33: 5 | X33: =W33*U33 -> 0
A34: 大口飯糰 | B34: 1 | C34: 直巻明太子美奶茲 | F34: 3 | G34: 2500 | H34: 833.33 | I34: 20 | J34: 透由調整速度提升。 | U34: 前幾名合計比例 | V34: =X34/N18 -> 0.23125 | W34: 前幾名合計金額 | X34: =SUM(X29:X33) -> 277.5
B35: 2
B36: 3 | M36: 半成品超用 | N36: 排名 | O36: 商品名 | R36: 半成品名 | U36: 單價 | V36: 報廢率 | W36: 數量 | X36: 金額 | Y36: 前月比 | Z36: 主要原因&對策
B37: 4 | M37: 作業原因 | N37: 1 | O37: 特製醬汁炙燒牛五花便當 | R37: 牛五花醬汁 | U37: 25 | V37: 0.25 | W37: 10 | X37: =W37*U37 -> 250 | Y37: 150 | Z37: 難度有差異。調理指導。
B38: 5 | N38: 2 | X38: =W38*U38 -> 0
B39: ▼1 | C39: 大口飯糰燒肉美奶滋 | F39: 7 | G39: 2200 | H39: 314.29 | I39: -15 | J39: 因摺疊增員。實施教育訓練。 | N39: 3 | X39: =W39*U39 -> 0
B40: ▼2 | N40: 4 | X40: =W40*U40 -> 0
B41: ▼3 | N41: 5 | X41: =W41*U41 -> 0
B42: ▼4 | U42: 前幾名合計比例 | V42: =X42/N19 -> 0.055555556 | W42: 前幾名合計金額 | X42: =SUM(X37:X41) -> 250
...

Sheet 生產管理報表(月)
A1: 生產管理報表
A3: 月別 | B3: 9 | C3: 工廠 | D3: 晉欣廠
A4: （１）收支狀況 | E4: ※單位：千元 | G4: （２）ＫＰＩ達成進度
A5: 項目 | B5: 當月 | C5: 前月 | D5: 差異 | E5: 累計 | G5: 項目 | H5: KPI | I5: 當月 | J5: 前月 | K5: 累計 | L5: ※補充
A6: 業績金額 | B6: ='（１）收支狀況'!H5/1000 -> 214950.45 | C6: 212376.15 | D6: =B6-C6 -> 2574.296 | E6: =B6 -> 214950.45 | G6: 人時性(個/月均) | H6: 366 | I6: ='（２）ＫＰＩ達成進度'!H5 -> 330.69215 | J6: 331.32088 | K6: =I6 -> 330.69215 | L6: 個／MH
A7: 訂單數量 | B7: ='（４）訂單數量構成比'!H7 -> 6718847 | C7: 6558055 | D7: =B7-C7 -> 160792 | E7: =B7 -> 6718847 | G7: 人時達成率(%/月均) | H7: 0.8 | I7: ='（２）ＫＰＩ達成進度'!K5 -> 0.90353045 | J7: 0.90524832 | K7: =I7 -> 0.90353045 | L7: 達成率
A8: 材料費 | B8: ='（１）收支狀況'!N5/1000 -> 143048.94 | C8: 139088.16 | D8: =B8-C8 -> 3960.781 | E8: =B8 -> 143048.94 | G8: 半成品-報廢(%) | H8: 0.0025 | I8: ='（２）ＫＰＩ達成進度'!N5 -> 0.0024902513 | J8: 0.0024946244 | K8: =I8 -> 0.0024902513 | L8: 報廢率
A9: 材料費率 | B9: ='（１）收支狀況'!Q5 -> 0.66549731 | C9: 0.65491423 | D9: =B9-C9 -> 0.010583081 | E9: =B9 -> 0.66549731 | G9: 半成品-超用(%) | H9: 0.0026 | I9: ='（２）ＫＰＩ達成進度'!Q5 -> 0.0024983099 | J9: 0.0023789152 | K9: =I9 -> 0.0024983099 | L9: 超用率
A10: 勞務成本 | B10: ='（１）收支狀況'!T5/1000 -> 30228.427 | C10: 30146.177 | D10: =B10-C10 -> 82.250476 | E10: =B10 -> 30228.427 | G10: 固定產線-導入率(%) | H10: 0.8 | I10: ='（２）ＫＰＩ達成進度'!T5 -> 0.91666667 | J10: 0.91666667 | K10: =I10 -> 0.91666667 | L10: 導入率
A11: 勞務費率 | B11: ='（１）收支狀況'!W5 -> 0.14062975 | C11: 0.14194709 | D11: =B11-C11 -> -0.0013173425 | E11: =B11 -> 0.14062975 | G11: 教育訓練-實施率(%) | H11: 1 | I11: ='（２）ＫＰＩ達成進度'!W5 -> 0.7673 | J11: 0.67912903 | K11: =I11 -> 0.7673 | L11: 實施率
A13: （３）業績構成比 | G13: （４）訂單數量構成比
B14: 當月 | C14: 比例 | D14: 前月 | E14: 差異 | H14: 當月 | I14: 比例 | J14: 前月 | K14: 差異
A15: 18℃-飯A15:A23糰(061,063) | B15: ='（３）業績構成比'!M46/1000 -> 46595.406 | C15: =IFERROR(B15/$B$6,"") -> 0.21677278 | D15: 0.19048549 | E15: =IFERROR(C15-D15,"") -> 0.026287285 | G15: 18℃-飯A15:A23糰(061,063) | H15: ='（４）訂單數量構成比'!M46 -> 2422911 | I15: =IFERROR(H15/$B$7,"") -> 0.36061411 | J15: 0.33193454 | K15: =IFERROR(I15-J15,"") -> 0.028679561
A16: 18℃-壽司手卷(071,072,075,076) | B16: ='（３）業績構成比'!S46/1000 -> 7790.6951 | C16: =IFERROR(B16/$B$6,"") -> 0.036244145 | D16: 0.04002075 | E16: =IFERROR(C16-D16,"") -> -0.0037766054 | G16: 18℃-壽司手卷(071,072,075,076) | H16: ='（４）訂單數量構成比'!S47 -> 308052 | I16: =IFERROR(H16/$B$7,"") -> 0.045848938 | J16: 0.050408543 | K16: =IFERROR(I16-J16,"") -> -0.0045596053
A17: 4℃-飯糰(065) | B17: ='（３）業績構成比'!U46/1000 -> 18799.984 | C17: =IFERROR(B17/$B$6,"") -> 0.087461944 | D17: 0.098025494 | E17: =IFERROR(C17-D17,"") -> -0.01056355 | G17: 4℃-飯糰(065) | H17: ='（４）訂單數量構成比'!U46 -> 574632 | I17: =IFERROR(H17/$B$7,"") -> 0.085525389 | J17: 0.09754935 | K17: =IFERROR(I17-J17,"") -> -0.012023961
A18: 4℃-壽司手卷(077) | B18: ='（３）業績構成比'!W46/1000 -> 395.54577 | C18: =IFERROR(B18/$B$6,"") -> 0.0018401719 | D18: 0.0023157871 | E18: =IFERROR(C18-D18,"") -> -0.00047561519 | G18: 4℃-壽司手卷(077) | H18: ='（４）訂單數量構成比'!W46 -> 14916 | I18: =IFERROR(H18/$B$7,"") -> 0.0022200238 | J18: 0.0027738407 | K18: =IFERROR(I18-J18,"") -> -0.00055381696
A19: 主食(091,092,093,094,095) | B19: ='（３）業績構成比'!AC46/1000 -> 53640.655 | C19: =IFERROR(B19/$B$6,"") -> 0.24954894 | D19: 0.26645165 | E19: =IFERROR(C19-D19,"") -> -0.016902714 | G19: 主食(091,092,093,094,095) | H19: ='（４）訂單數量構成比'!AC46 -> 1318893 | I19: =IFERROR(H19/$B$7,"") -> 0.19629752 | J19: 0.20966064 | K19: =IFERROR(I19-J19,"") -> -0.013363119
A20: 便當(083) | B20: ='（３）業績構成比'!AE46/1000 -> 23966.44 | C20: =IFERROR(B20/$B$6,"") -> 0.11149751 | D20: 0.11880395 | E20: =IFERROR(C20-D20,"") -> -0.0073064339 | G20: 便當(083) | H20: ='（４）訂單數量構成比'!AE46 -> 432423 | I20: =IFERROR(H20/$B$7,"") -> 0.064359703 | J20: 0.069473342 | K20: =IFERROR(I20-J20,"") -> -0.0051136389
A21: 熱食義麵(122,123,124,126) | B21: ='（３）業績構成比'!AG46/1000 -> 32518.381 | C21: =IFERROR(B21/$B$6,"") -> 0.15128315 | D21: 0.13107603 | E21: =IFERROR(C21-D21,"") -> 0.020207122 | G21: 熱食義麵(122,123,124,126) | H21: ='（４）訂單數量構成比'!AG46 -> 664479 | I21: =IFERROR(H21/$B$7,"") -> 0.098897772 | J21: 0.087948485 | K21: =IFERROR(I21-J21,"") -> 0.010949287
A22: 季節調理麵(111,112) | B22: ='（３）業績構成比'!AI46/1000 -> 17756.916 | C22: =IFERROR(B22/$B$6,"") -> 0.082609348 | D22: 0.091535408 | E22: =IFERROR(C22-D22,"") -> -0.0089260601 | G22: 季節調理麵(111,112) | H22: ='（４）訂單數量構成比'!AI46 -> 483623 | I22: =IFERROR(H22/$B$7,"") -> 0.071980058 | J22: 0.079981641 | K22: =IFERROR(I22-J22,"") -> -0.0080015824
A23: 微波小吃(153,154,155) | B23: ='（３）業績構成比'!AK46/1000 -> 13486.423 | C23: =IFERROR(B23/$B$6,"") -> 0.062742008 | D23: 0.061285436 | E23: =IFERROR(C23-D23,"") -> 0.0014565714 | G23: 微波小吃(153,154,155) | H23: ='（４）訂單數量構成比'!AK46 -> 498918 | I23: =IFERROR(H23/$B$7,"") -> 0.074256491 | J23: 0.070269615 | K23: =IFERROR(I23-J23,"") -> 0.0039868757
C24: =SUM(C15:C23) -> 1 | D24: =SUM(D15:D23) -> 1 | I24: =SUM(I15:I23) -> 1 | J24: =SUM(J15:J23) -> 1
A26: （５）品群別人時生產性
A27: 品群 | B27: 當月 | C27: 前月 | D27: 差異 | E27: 累計
A28: 18℃-飯A15:A23糰(061,063) | B28: ='（５-1）品群別人時生產性（18℃-飯糰）'!$C$1 -> 715.79668 | C28: 717.52753 | D28: =B28-C28 -> -1.7308511 | E28: =R28 -> 0
A29: 18℃-壽司手卷(071,072,075,076) | B29: ='（５-2）品群別人時生產性（18-壽司手卷)'!$C$1 -> 205.53713 | C29: 197.63272 | D29: =B29-C29 -> 7.9044146 | E29: =R29 -> 0
A30: 4℃-飯糰(065) | B30: ='（５-3）品群別人時生產性（4℃-飯糰)'!$C$1 -> 252.79277 | C30: 240.45857 | D30: =B30-C30 -> 12.3342 | E30: =R30 -> 0
A31: 4℃-壽司手卷(077) | B31: ='（５-4）品群別人時生產性（4℃-壽司手卷)'!$C$1 -> 109.37945 | C31: 106.86512 | D31: =B31-C31 -> 2.514331 | E31: =R31 -> 0
A32: 主食(091,092,093,094,095) | B32: ='（５-5）品群別人時生產性(主食) '!$C$1 -> 89.000698 | C32: 89.310428 | D32: =B32-C32 -> -0.30972999 | E32: =R32 -> 0
A33: 便當(083) | B33: ='（５-6）品群別人時生產性(便當)'!$C$1 -> 67.441399 | C33: 65.672742 | D33: =B33-C33 -> 1.7686562 | E33: =R33 -> 0
A34: 熱食義麵(122,123,124,126) | B34: ='（５-7）品群別人時生產性(熱食義麵) '!$C$1 -> 85.187632 | C34: 75.478569 | D34: =B34-C34 -> 9.7090632 | E34: =R34 -> 0
A35: 季節調理麵(111,112) | B35: ='（５-8）品群別人時生產性(季節調理麵) '!$C$1 -> 117.44063 | C35: 114.50557 | D35: =B35-C35 -> 2.9350599 | E35: =R35 -> 0
A36: 微波小吃(153,154,155) | B36: ='（５-9）品群別人時生產性(微波小吃)'!$C$1 -> 111.67402 | C36: 99.648342 | D36: =B36-C36 -> 12.025681 | E36: =R36 -> 0

Sheet （１）收支狀況
B2: （１）收支狀況
C3: 月份 | D3: 日期 | F3: 營業額(元) | I3: 訂單數量(個) | L3: 材料費(元) | O3: 材料費率（材料費／營業額） | R3: 勞務成本（全廠人事成本） | U3: 勞務費率（勞務成本／營業額）
F4: 日 | G4: 週累積 | H4: 月累積 | I4: 日 | J4: 週累積 | K4: 月累積 | L4: 日 | M4: 週累積 | N4: 月累積 | O4: 日 | P4: 週累積 | Q4: 月平均 | R4: 日 | S4: 週累積 | T4: 月累積 | U4: 日 | V4: 週累積 | W4: 月平均
C5: 八 | D5: 45901 | E5: 一 | F5: 7106225 | G5: =SUM(F5) -> 7106225 | H5: =SUM(F5:F34) -> 214950446 | I5: 222309 | J5: =SUM(I5) -> 222309 | K5: =SUM(I5:I34) -> 6718847 | L5: 4605313 | M5: =SUM(L5) -> 4605313 | N5: =SUM(L5:L34) -> 143048944 | O5: =L5/F5 -> 0.64806743 | P5: =M5/G5 -> 0.64806743 | Q5: =N5/H5 -> 0.66549731 | R5: 1095433.4 | S5: =SUM(R5) -> 1095433.4 | T5: =SUM(R5:R34) -> 30228427 | U5: =R5/F5 -> 0.15415124 | V5: =S5/G5 -> 0.15415124 | W5: =T5/H5 -> 0.14062975
D6: 45902 | E6: 二 | F6: 7727458 | G6: =SUM(F6:F12) -> 48362935 | I6: 240560 | J6: =SUM(I6:I12) -> 1525242 | L6: 5097967 | M6: =SUM(L6:L12) -> 32268260 | O6: =L6/F6 -> 0.65972109 | P6: =M6/G6 -> 0.66721054 | R6: 1023560 | S6: =SUM(R6:R12) -> 6899291.5 | U6: =R6/F6 -> 0.13245753 | V6: =S6/G6 -> 0.14265659
D7: 45903 | E7: 三 | F7: 7254649 | I7: 228856 | L7: 4732982 | O7: =L7/F7 -> 0.65240675 | R7: 972528.49 | U7: =R7/F7 -> 0.1340559
D8: 45904 | E8: 四 | F8: 6602059 | I8: 210018 | L8: 4508652 | O8: =L8/F8 -> 0.68291604 | R8: 956492.63 | U8: =R8/F8 -> 0.14487793
D9: 45905 | E9: 五 | F9: 5807177 | I9: 186157 | L9: 3980697 | O9: =L9/F9 -> 0.68547885 | R9: 958646.78 | U9: =R9/F9 -> 0.16507965
D10: 45906 | E10: 六 | F10: 6167669 | I10: 195008 | L10: 4408224 | O10: =L10/F10 -> 0.71473096 | R10: 956801.78 | U10: =R10/F10 -> 0.15513183
D11: 45907 | E11: 日 | F11: 7394780 | I11: 233163 | L11: 4698661 | O11: =L11/F11 -> 0.63540241 | R11: 1006559.1 | U11: =R11/F11 -> 0.13611752
D12: 45908 | E12: 一 | F12: 7409143 | I12: 231480 | L12: 4841077 | O12: =L12/F12 -> 0.6533923 | R12: 1024702.6 | U12: =R12/F12 -> 0.13830245
D13: 45909 | E13: 二 | F13: 7807316 | G13: =SUM(F13:F19) -> 50470102 | I13: 241607 | J13: =SUM(I13:I19) -> 1578863 | L13: 5229407 | M13: =SUM(L13:L19) -> 33526646 | O13: =L13/F13 -> 0.66980855 | P13: =M13/G13 -> 0.66428726 | R13: 1040763.5 | S13: =SUM(R13:R19) -> 7096955.3 | U13: =R13/F13 -> 0.13330618 | V13: =S13/G13 -> 0.14061702
D14: 45910 | E14: 三 | F14: 7436383 | I14: 233099 | L14: 5087998 | O14: =L14/F14 -> 0.68420333 | R14: 1020093.8 | U14: =R14/F14 -> 0.13717607
D15: 45911 | E15: 四 | F15: 6919680 | I15: 217145 | L15: 4531913 | O15: =L15/F15 -> 0.65493101 | R15: 1005473.2 | U15: =R15/F15 -> 0.14530631
D16: 45912 | E16: 五 | F16: 6171958 | I16: 194357 | L16: 4199696 | O16: =L16/F16 -> 0.68044792 | R16: 1018213.7 | U16: =R16/F16 -> 0.16497418
D17: 45913 | E17: 六 | F17: 6541355 | I17: 204761 | L17: 4410753 | O17: =L17/F17 -> 0.67428736 | R17: 974340.71 | U17: =R17/F17 -> 0.1489509
D18: 45914 | E18: 日 | F18: 7771753 | I18: 242926 | L18: 4852648 | O18: =L18/F18 -> 0.62439555 | R18: 1009884.8 | U18: =R18/F18 -> 0.12994299
D19: 45915 | E19: 一 | F19: 7821657 | I19: 244968 | L19: 5214231 | O19: =L19/F19 -> 0.6666402 | R19: 1028185.6 | U19: =R19/F19 -> 0.13145368
D20: 45916 | E20: 二 | F20: 8739776 | G20: =SUM(F20:F26) -> 52767858 | I20: 270682 | J20: =SUM(I20:I26) -> 1647661 | L20: 5918635 | M20: =SUM(L20:L26) -> 35250361 | O20: =L20/F20 -> 0.67720672 | P20: =M20/G20 -> 0.66802714 | R20: 1056954.4 | S20: =SUM(R20:R26) -> 7079608.2 | U20: =R20/F20 -> 0.1209361 | V20: =S20/G20 -> 0.13416516
D21: 45917 | E21: 三 | F21: 8050591 | I21: 252399 | L21: 5489287 | O21: =L21/F21 -> 0.68184895 | R21: 1030644.5 | U21: =R21/F21 -> 0.12802098
D22: 45918 | E22: 四 | F22: 7502711 | I22: 235694 | L22: 5027758 | O22: =L22/F22 -> 0.67012551 | R22: 996673.93 | U22: =R22/F22 -> 0.13284184
D23: 45919 | E23: 五 | F23: 6251144 | I23: 198052 | L23: 4162561 | O23: =L23/F23 -> 0.66588788 | R23: 966712.46 | U23: =R23/F23 -> 0.15464569
D24: 45920 | E24: 六 | F24: 6569112 | I24: 203622 | L24: 4548804 | O24: =L24/F24 -> 0.69245341 | R24: 976560.6 | U24: =R24/F24 -> 0.14865945
D25: 45921 | E25: 日 | F25: 7902663 | I25: 246024 | L25: 5008494 | O25: =L25/F25 -> 0.63377294 | R25: 1038544.5 | U25: =R25/F25 -> 0.13141702
D26: 45922 | E26: 一 | F26: 7751861 | I26: 241188 | L26: 5094822 | O26: =L26/F26 -> 0.65723857 | R26: 1013517.9 | U26: =R26/F26 -> 0.1307451
D27: 45923 | E27: 二 | F27: 7508635 | G27: =SUM(F27:F33) -> 47691357 | I27: 234687 | J27: =SUM(I27:I33) -> 1482932 | L27: 5149118 | M27: =SUM(L27:L33) -> 31914989 | O27: =L27/F27 -> 0.68575953 | P27: =M27/G27 -> 0.66919859 | R27: 1010855.6 | S27: =SUM(R27:R33) -> 6973606 | U27: =R27/F27 -> 0.13462575 | V27: =S27/G27 -> 0.14622369
D28: 45924 | E28: 三 | F28: 7219231 | I28: 226259 | L28: 4655445 | O28: =L28/F28 -> 0.64486716 | R28: 993200.61 | U28: =R28/F28 -> 0.13757707
D29: 45925 | E29: 四 | F29: 6826680 | I29: 212221 | L29: 4511936 | O29: =L29/F29 -> 0.66092683 | R29: 972958.2 | U29: =R29/F29 -> 0.1425229
D30: 45926 | E30: 五 | F30: 5933194 | I30: 184225 | L30: 4180675 | O30: =L30/F30 -> 0.70462469 | R30: 958197.18 | U30: =R30/F30 -> 0.1614977
D31: 45927 | E31: 六 | F31: 6011714 | I31: 185335 | L31: 4112564 | O31: =L31/F31 -> 0.68409176 | R31: 973238.32 | U31: =R31/F31 -> 0.16189032
D32: 45928 | E32: 日 | F32: 6495139 | I32: 199570 | L32: 4398458 | O32: =L32/F32 -> 0.67719228 | R32: 1007639.1 | U32: =R32/F32 -> 0.15513742
D33: 45929 | E33: 一 | F33: 7696764 | I33: 240635 | L33: 4906793 | O33: =L33/F33 -> 0.63751377 | R33: 1057516.9 | U33: =R33/F33 -> 0.1373976
D34: 45930 | E34: 二 | F34: 8551969 | G34: =SUM(F34:F40) -> 8551969 | I34: 261840 | J34: =SUM(I34:I40) -> 261840 | L34: 5483375 | M34: =SUM(L34:L40) -> 5483375 | O34: =L34/F34 -> 0.64118275 | P34: =M34/G34 -> 0.64118275 | R34: 1083532.6 | S34: =SUM(R34:R40) -> 1083532.6 | U34: =R34/F34 -> 0.12669978 | V34: =S34/G34 -> 0.12669978

Sheet （２）ＫＰＩ達成進度
B1: KPI | C1: 366
B2: （２）ＫＰＩ達成進度
C3: 月份 | D3: 日期 | F3: 人時生產性(個/人) | I3: 人時生產性達成率(%) | L3: 半成品報廢(%) | O3: 半成品超用(%) | R3: 固定產線-導入率(固定產線數/總產線數) | U3: 教育訓練-實施率(進度/計畫)
F4: 日 | G4: 週平均 | H4: 月平均 | I4: 日 | J4: 週平均 | K4: 月平均 | L4: 日 | M4: 週平均 | N4: 月平均 | O4: 日 | P4: 週平均 | Q4: 月平均 | R4: 日 | S4: 週平均 | T4: 月平均 | U4: 日 | V4: 週平均 | W4: 月平均
D5: 45901 | E5: 一 | F5: 337.8 | G5: =AVERAGE(F5) -> 337.8 | H5: =AVERAGE(F5:F34) -> 330.69215 | I5: =F5/$C$1 -> 0.92295082 | J5: =AVERAGE(I5) -> 0.92295082 | K5: =AVERAGE(I5:I34) -> 0.90353045 | L5: 0.0024616445 | M5: =AVERAGE(L5) -> 0.0024616445 | N5: =AVERAGE(L5:L34) -> 0.0024902513 | O5: 0.0021707715 | P5: =AVERAGE(O5) -> 0.0021707715 | Q5: =AVERAGE(O5:O34) -> 0.0024983099 | R5: 0.91666667 | S5: =AVERAGE(R5) -> 0.91666667 | T5: =AVERAGE(R5:R99) -> 0.91666667 | U5: 0.722 | V5: =AVERAGE(U5) -> 0.722 | W5: =AVERAGE(U5:U99) -> 0.7673
D6: 45902 | E6: 二 | F6: 331.8 | G6: =AVERAGE(F6:F12) -> 335.12857 | I6: =F6/$C$1 -> 0.90655738 | J6: =AVERAGE(I6:I12) -> 0.91565183 | L6: 0.0025160926 | M6: =AVERAGE(L6:L12) -> 0.0024923202 | O6: 0.0029970227 | P6: =AVERAGE(O6:O12) -> 0.002753391 | R6: 0.91666667 | S6: =AVERAGE(R6:R12) -> 0.91666667 | U6: 0.723 | V6: =AVERAGE(U6:U12) -> 0.73357143
D7: 45903 | E7: 三 | F7: 331.8 | I7: =F7/$C$1 -> 0.90655738 | L7: 0.0024442258 | O7: 0.0026068247 | R7: 0.91666667 | U7: 0.723
D8: 45904 | E8: 四 | F8: 333.6 | I8: =F8/$C$1 -> 0.91147541 | L8: 0.0025136098 | O8: 0.003077063 | R8: 0.91666667 | U8: 0.73
D9: 45905 | E9: 五 | F9: 339 | I9: =F9/$C$1 -> 0.92622951 | L9: 0.0025246346 | O9: 0.0028454179 | R9: 0.91666667 | U9: 0.735
D10: 45906 | E10: 六 | F10: 335.7 | I10: =F10/$C$1 -> 0.91721311 | L10: 0.0025051604 | O10: 0.0029119054 | R10: 0.91666667 | U10: 0.74
D11: 45907 | E11: 日 | F11: 335.9 | I11: =F11/$C$1 -> 0.91775956 | L11: 0.0024941918 | O11: 0.0025375109 | R11: 0.91666667 | U11: 0.742
D12: 45908 | E12: 一 | F12: 338.1 | I12: =F12/$C$1 -> 0.92377049 | L12: 0.0024483263 | O12: 0.0022979922 | R12: 0.91666667 | U12: 0.742
D13: 45909 | E13: 二 | F13: 331.71014 | G13: =AVERAGE(F13:F19) -> 335.39905 | I13: =F13/$C$1 -> 0.90631186 | J13: =AVERAGE(I13:I19) -> 0.91639084 | L13: 0.0025155892 | M13: =AVERAGE(L13:L19) -> 0.0024914282 | O13: 0.0023445814 | P13: =AVERAGE(O13:O19) -> 0.0025382773 | R13: 0.91666667 | S13: =AVERAGE(R13:R19) -> 0.91666667 | U13: 0.742 | V13: =AVERAGE(U13:U19) -> 0.75442857
D14: 45910 | E14: 三 | F14: 331.26961 | I14: =F14/$C$1 -> 0.90510822 | L14: 0.0025024262 | O14: 0.002387749 | R14: 0.91666667 | U14: 0.75
D15: 45911 | E15: 四 | F15: 338.07294 | I15: =F15/$C$1 -> 0.92369657 | L15: 0.0024625416 | O15: 0.0026280835 | R15: 0.91666667 | U15: 0.753
D16: 45912 | E16: 五 | F16: 337.65312 | I16: =F16/$C$1 -> 0.92254951 | L16: 0.0024820324 | O16: 0.002631003 | R16: 0.91666667 | U16: 0.754
D17: 45913 | E17: 六 | F17: 329.85969 | I17: =F17/$C$1 -> 0.901256 | L17: 0.0024542316 | O17: 0.0028657948 | R17: 0.91666667 | U17: 0.76
D18: 45914 | E18: 日 | F18: 335.39869 | I18: =F18/$C$1 -> 0.91638987 | L18: 0.0025160347 | O18: 0.0023379826 | R18: 0.91666667 | U18: 0.76
D19: 45915 | E19: 一 | F19: 343.82912 | I19: =F19/$C$1 -> 0.93942384 | L19: 0.0025071414 | O19: 0.0025727466 | R19: 0.91666667 | U19: 0.762
D20: 45916 | E20: 二 | F20: 334.89269 | G20: =AVERAGE(F20:F26) -> 327.79321 | I20: =F20/$C$1 -> 0.91500736 | J20: =AVERAGE(I20:I26) -> 0.89560988 | L20: 0.0025108195 | M20: =AVERAGE(L20:L26) -> 0.0024956549 | O20: 0.0023099354 | P20: =AVERAGE(O20:O26) -> 0.0023966284 | R20: 0.91666667 | S20: =AVERAGE(R20:R26) -> 0.91666667 | U20: 0.762 | V20: =AVERAGE(U20:U26) -> 0.77642857
D21: 45917 | E21: 三 | F21: 324.97889 | I21: =F21/$C$1 -> 0.88792046 | L21: 0.0025190697 | O21: 0.0023813634 | R21: 0.91666667 | U21: 0.768
D22: 45918 | E22: 四 | F22: 323.74466 | I22: =F22/$C$1 -> 0.88454824 | L22: 0.0024921658 | O22: 0.00246326 | R22: 0.91666667 | U22: 0.77
D23: 45919 | E23: 五 | F23: 332.3957 | I23: =F23/$C$1 -> 0.90818498 | L23: 0.002469628 | O23: 0.0025787796 | R23: 0.91666667 | U23: 0.775
D24: 45920 | E24: 六 | F24: 326.80147 | I24: =F24/$C$1 -> 0.89290019 | L24: 0.0024750682 | O24: 0.0024739474 | R24: 0.91666667 | U24: 0.78
D25: 45921 | E25: 日 | F25: 325.53909 | I25: =F25/$C$1 -> 0.88945107 | L25: 0.0024915652 | O25: 0.0023575318 | R25: 0.91666667 | U25: 0.79
D26: 45922 | E26: 一 | F26: 326.2 | I26: =F26/$C$1 -> 0.89125683 | L26: 0.0025112679 | O26: 0.0022115814 | R26: 0.91666667 | U26: 0.79
D27: 45923 | E27: 二 | F27: 324.00944 | G27: =AVERAGE(F27:F33) -> 326.24551 | I27: =F27/$C$1 -> 0.88527168 | J27: =AVERAGE(I27:I33) -> 0.89138116 | L27: 0.0025072467 | M27: =AVERAGE(L27:L33) -> 0.0024801855 | O27: 0.0021185441 | P27: =AVERAGE(O27:O33) -> 0.0024024263 | R27: 0.91666667 | S27: =AVERAGE(R27:R33) -> 0.91666667 | U27: 0.795 | V27: =AVERAGE(U27:U33) -> 0.80514286
D28: 45924 | E28: 三 | F28: 327.05524 | I28: =F28/$C$1 -> 0.89359354 | L28: 0.0024696536 | O28: 0.0022336398 | R28: 0.91666667 | U28: 0.8
D29: 45925 | E29: 四 | F29: 326.86455 | I29: =F29/$C$1 -> 0.89307253 | L29: 0.0024506788 | O29: 0.0024076717 | R29: 0.91666667 | U29: 0.805
D30: 45926 | E30: 五 | F30: 325.69823 | I30: =F30/$C$1 -> 0.88988587 | L30: 0.0025010138 | O30: 0.0027922872 | R30: 0.91666667 | U30: 0.807
D31: 45927 | E31: 六 | F31: 322.46827 | I31: =F31/$C$1 -> 0.88106084 | L31: 0.0024939643 | O31: 0.0026543179 | R31: 0.91666667 | U31: 0.809
D32: 45928 | E32: 日 | F32: 324.92282 | I32: =F32/$C$1 -> 0.88776728 | L32: 0.0024894001 | O32: 0.0024833957 | R32: 0.91666667 | U32: 0.81
D33: 45929 | E33: 一 | F33: 332.7 | I33: =F33/$C$1 -> 0.90901639 | L33: 0.002449341 | O33: 0.0021271277 | R33: 0.91666667 | U33: 0.81
D34: 45930 | E34: 二 | F34: 311 | G34: =AVERAGE(F34:F40) -> 311 | I34: =F34/$C$1 -> 0.84972678 | J34: =AVERAGE(I34:I40) -> 0.84972678 | L34: 0.0025287744 | M34: =AVERAGE(L34:L40) -> 0.0025287744 | O34: 0.0021434657 | P34: =AVERAGE(O34:O40) -> 0.0021434657 | R34: 0.91666667 | S34: =AVERAGE(R34:R40) -> 0.91666667 | U34: 0.81 | V34: =AVERAGE(U34:U40) -> 0.81

Sheet （３）業績構成比
B2: （3）業績構成比
C3: 月份 | D3: 日期 | F3: 營業額 | I3: 品類業績
I4: 18℃-飯糰 | O4: 18℃-壽司手卷 | U4: 4℃-飯糰 | W4: 4℃-壽司手卷 | Y4: 主食 | AE4: 便當 | AG4: 熱食義麵 | AI4: 季節調理麵 | AK4: 微波小吃
F5: 日 | G5: 週累積 | H5: 月累積 | I5: 一配 | K5: 二配 | M5: 合計 | O5: 一配 | Q5: 二配 | S5: 合計 | U5: 一配 | W5: 一配 | Y5: 一配 | AA5: 二配 | AC5: 合計 | AE5: 一配 | AG5: 一配 | AI5: 一配 | AK5: 一配
I6: 業績(元) | J6: 比例(%) | K6: 業績(元) | L6: 比例(%) | M6: 業績(元) | N6: 比例(%) | O6: 業績(元) | P6: 比例(%) | Q6: 業績(元) | R6: 比例(%) | S6: 業績(元) | T6: 比例(%) | U6: 業績(元) | V6: 比例(%) | W6: 業績(元) | X6: 比例(%) | Y6: 業績(元) | Z6: 比例(%) | AA6: 業績(元) | AB6: 比例(%) | AC6: 業績(元) | AD6: 比例(%) | AE6: 業績(元) | AF6: 比例(%) | AG6: 業績(元) | AH6: 比例(%) | AI6: 業績(元) | AJ6: 比例(%) | AK6: 業績(元) | AL6: 比例(%)
C7: 八 | D7: 45901 | E7: 一 | F7: =SUM(M7,S7,U7,W7,AC7,AE7,AG7,AI7,AK7) -> 7106225 | G7: =SUM(F7) -> 7106225 | H7: =SUM(F7:F37) -> 214950446 | I7: 564796.27 | J7: =I7/F7 -> 0.079479086 | K7: 844516.54 | L7: =K7/F7 -> 0.1188418 | M7: =SUM(I7+K7) -> 1409312.8 | N7: =M7/F7 -> 0.19832088 | O7: 178305.27 | P7: =O7/F7 -> 0.025091419 | Q7: 117312.6 | R7: =Q7/$F7 -> 0.016508427 | S7: =SUM(O7+Q7) -> 295617.87 | T7: =S7/F7 -> 0.041599846 | U7: 664869.3 | V7: =U7/F7 -> 0.093561533 | W7: 11130.398 | X7: =W7/F7 -> 0.0015662885 | Y7: 724213.71 | Z7: =Y7/F7 -> 0.10191258 | AA7: 1252569.5 | AB7: =AA7/$F7 -> 0.1762637 | AC7: =SUM(Y7+AA7) -> 1976783.2 | AD7: =AC7/F7 -> 0.27817628 | AE7: 761029.94 | AF7: =AE7/F7 -> 0.10709342 | AG7: 885640.41 | AH7: =AG7/F7 -> 0.12462882 | AI7: 609386.06 | AJ7: =AI7/F7 -> 0.085753837 | AK7: 492455 | AL7: =AK7/F7 -> 0.0692991
D8: 45902 | E8: 二 | F8: =SUM(M8,S8,U8,W8,AC8,AE8,AG8,AI8,AK8) -> 7727458 | G8: =SUM(F8:F14) -> 48362935 | I8: 895945.02 | J8: =I8/F8 -> 0.11594305 | K8: 864483.49 | L8: =K8/F8 -> 0.11187165 | M8: =SUM(I8+K8) -> 1760428.5 | N8: =M8/F8 -> 0.2278147 | O8: 173390.16 | P8: =O8/F8 -> 0.022438188 | Q8: 117719.68 | R8: =Q8/$F8 -> 0.015233946 | S8: =SUM(O8+Q8) -> 291109.84 | T8: =S8/F8 -> 0.037672135 | U8: 654432.77 | V8: =U8/F8 -> 0.084689269 | W8: 12158.137 | X8: =W8/F8 -> 0.0015733682 | Y8: 698241.88 | Z8: =Y8/F8 -> 0.090358547 | AA8: 1229944.2 | AB8: =AA8/$F8 -> 0.15916543 | AC8: =SUM(Y8+AA8) -> 1928186.1 | AD8: =AC8/F8 -> 0.24952398 | AE8: 774796.36 | AF8: =AE8/F8 -> 0.10026536 | AG8: 1240057.7 | AH8: =AG8/F8 -> 0.1604742 | AI8: 592076.67 | AJ8: =AI8/F8 -> 0.076619849 | AK8: 474211.97 | AL8: =AK8/F8 -> 0.061367136
D9: 45903 | E9: 三 | F9: =SUM(M9,S9,U9,W9,AC9,AE9,AG9,AI9,AK9) -> 7254649 | I9: 853934.48 | J9: =I9/F9 -> 0.11770859 | K9: 849068.34 | L9: =K9/F9 -> 0.11703783 | M9: =SUM(I9+K9) -> 1703002.8 | N9: =M9/F9 -> 0.23474641 | O9: 161410.07 | P9: =O9/F9 -> 0.022249191 | Q9: 115119.31 | R9: =Q9/$F9 -> 0.015868349 | S9: =SUM(O9+Q9) -> 276529.38 | T9: =S9/F9 -> 0.038117541 | U9: 629174.45 | V9: =U9/F9 -> 0.08672707 | W9: 11437.042 | X9: =W9/F9 -> 0.0015765121 | Y9: 665754.82 | Z9: =Y9/F9 -> 0.091769405 | AA9: 1124097.9 | AB9: =AA9/$F9 -> 0.15494863 | AC9: =SUM(Y9+AA9) -> 1789852.8 | AD9: =AC9/F9 -> 0.24671804 | AE9: 742015.94 | AF9: =AE9/F9 -> 0.10228144 | AG9: 1057877.5 | AH9: =AG9/F9 -> 0.14582063 | AI9: 574185.36 | AJ9: =AI9/F9 -> 0.079147228 | AK9: 470573.8 | AL9: =AK9/F9 -> 0.064865137
D10: 45904 | E10: 四 | F10: =SUM(M10,S10,U10,W10,AC10,AE10,AG10,AI10,AK10) -> 6602059 | I10: 766879.83 | J10: =I10/F10 -> 0.11615768 | K10: 783941.33 | L10: =K10/F10 -> 0.11874194 | M10: =SUM(I10+K10) -> 1550821.2 | N10: =M10/F10 -> 0.23489962 | O10: 152373.36 | P10: =O10/F10 -> 0.023079673 | Q10: 116613.79 | R10: =Q10/$F10 -> 0.017663246 | S10: =SUM(O10+Q10) -> 268987.16 | T10: =S10/F10 -> 0.040742919 | U10: 592627.72 | V10: =U10/F10 -> 0.089764076 | W10: 11154.125 | X10: =W10/F10 -> 0.0016894919 | Y10: 623826.76 | Z10: =Y10/F10 -> 0.094489729 | AA10: 912090.6 | AB10: =AA10/$F10 -> 0.13815245 | AC10: =SUM(Y10+AA10) -> 1535917.4 | AD10: =AC10/F10 -> 0.23264218 | AE10: 686539.58 | AF10: =AE10/F10 -> 0.10398871 | AG10: 974352.73 | AH10: =AG10/F10 -> 0.14758316 | AI10: 542486.9 | AJ10: =AI10/F10 -> 0.08216935 | AK10: 439172.26 | AL10: =AK10/F10 -> 0.066520499
D11: 45905 | E11: 五 | F11: =SUM(M11,S11,U11,W11,AC11,AE11,AG11,AI11,AK11) -> 5807177 | I11: 700967.78 | J11: =I11/F11 -> 0.12070715 | K11: 734957.29 | L11: =K11/F11 -> 0.12656017 | M11: =SUM(I11+K11) -> 1435925.1 | N11: =M11/F11 -> 0.24726732 | O11: 119243.52 | P11: =O11/F11 -> 0.020533818 | Q11: 97402.177 | R11: =Q11/$F11 -> 0.016772724 | S11: =SUM(O11+Q11) -> 216645.69 | T11: =S11/F11 -> 0.037306542 | U11: 509402.49 | V11: =U11/F11 -> 0.08771947 | W11: 9800.5843 | X11: =W11/F11 -> 0.0016876676 | Y11: 552530 | Z11: =Y11/F11 -> 0.095146058 | AA11: 872926.26 | AB11: =AA11/$F11 -> 0.15031852 | AC11: =SUM(Y11+AA11) -> 1425456.3 | AD11: =AC11/F11 -> 0.24546458 | AE11: 565244.9 | AF11: =AE11/F11 -> 0.097335573 | AG11: 792265.17 | AH11: =AG11/F11 -> 0.13642862 | AI11: 534404.31 | AJ11: =AI11/F11 -> 0.092024801 | AK11: 318032.52 | AL11: =AK11/F11 -> 0.054765425
D12: 45906 | E12: 六 | F12: =SUM(M12,S12,U12,W12,AC12,AE12,AG12,AI12,AK12) -> 6167669 | I12: 686612.5 | J12: =I12/F12 -> 0.11132447 | K12: 794389.29 | L12: =K12/F12 -> 0.12879895 | M12: =SUM(I12+K12) -> 1481001.8 | N12: =M12/F12 -> 0.24012342 | O12: 117355.57 | P12: =O12/F12 -> 0.019027541 | Q12: 97295.734 | R12: =Q12/$F12 -> 0.015775123 | S12: =SUM(O12+Q12) -> 214651.31 | T12: =S12/F12 -> 0.034802663 | U12: 510856.35 | V12: =U12/F12 -> 0.082828108 | W12: 10781.211 | X12: =W12/F12 -> 0.0017480203 | Y12: 593184.79 | Z12: =Y12/F12 -> 0.096176496 | AA12: 1000410.8 | AB12: =AA12/$F12 -> 0.16220242 | AC12: =SUM(Y12+AA12) -> 1593595.6 | AD12: =AC12/F12 -> 0.25837891 | AE12: 611938.27 | AF12: =AE12/F12 -> 0.099217106 | AG12: 879693.66 | AH12: =AG12/F12 -> 0.14262984 | AI12: 526676.21 | AJ12: =AI12/F12 -> 0.085393074 | AK12: 338474.57 | AL12: =AK12/F12 -> 0.054878848
D13: 45907 | E13: 日 | F13: =SUM(M13,S13,U13,W13,AC13,AE13,AG13,AI13,AK13) -> 7394780 | I13: 869357.49 | J13: =I13/F13 -> 0.11756367 | K13: 860695.51 | L13: =K13/F13 -> 0.11639231 | M13: =SUM(I13+K13) -> 1730053 | N13: =M13/F13 -> 0.23395598 | O13: 167431.93 | P13: =O13/F13 -> 0.022641908 | Q13: 114451.35 | R13: =Q13/$F13 -> 0.015477316 | S13: =SUM(O13+Q13) -> 281883.28 | T13: =S13/F13 -> 0.038119225 | U13: 662934.92 | V13: =U13/F13 -> 0.089649038 | W13: 14838.643 | X13: =W13/F13 -> 0.0020066375 | Y13: 707930.82 | Z13: =Y13/F13 -> 0.095733858 | AA13: 1130952.4 | AB13: =AA13/$F13 -> 0.15293928 | AC13: =SUM(Y13+AA13) -> 1838883.2 | AD13: =AC13/F13 -> 0.24867314 | AE13: 778191.06 | AF13: =AE13/F13 -> 0.10523519 | AG13: 1065808.8 | AH13: =AG13/F13 -> 0.14412989 | AI13: 611514.13 | AJ13: =AI13/F13 -> 0.082695378 | AK13: 410672.99 | AL13: =AK13/F13 -> 0.055535525
D14: 45908 | E14: 一 | F14: =SUM(M14,S14,U14,W14,AC14,AE14,AG14,AI14,AK14) -> 7409143 | I14: 814238.04 | J14: =I14/F14 -> 0.10989639 | K14: 872064.47 | L14: =K14/F14 -> 0.11770113 | M14: =SUM(I14+K14) -> 1686302.5 | N14: =M14/F14 -> 0.22759751 | O14: 153939.38 | P14: =O14/F14 -> 0.020776948 | Q14: 112956.71 | R14: =Q14/$F14 -> 0.015245584 | S14: =SUM(O14+Q14) -> 266896.09 | T14: =S14/F14 -> 0.036022531 | U14: 654977.91 | V14: =U14/F14 -> 0.088401305 | W14: 13888.573 | X14: =W14/F14 -> 0.0018745182 | Y14: 727257.57 | Z14: =Y14/F14 -> 0.098156774 | AA14: 1200713.7 | AB14: =AA14/$F14 -> 0.16205838 | AC14: =SUM(Y14+AA14) -> 1927971.3 | AD14: =AC14/F14 -> 0.26021516 | AE14: 815554.07 | AF14: =AE14/F14 -> 0.11007401 | AG14: 1043881.1 | AH14: =AG14/F14 -> 0.14089094 | AI14: 588183.16 | AJ14: =AI14/F14 -> 0.079386126 | AK14: 411488.28 | AL14: =AK14/F14 -> 0.055537905
D15: 45909 | E15: 二 | F15: =SUM(M15,S15,U15,W15,AC15,AE15,AG15,AI15,AK15) -> 7807316 | G15: =SUM(F15:F21) -> 50470102 | I15: 935505.98 | J15: =I15/F15 -> 0.11982428 | K15: 859055.75 | L15: =K15/F15 -> 0.11003215 | M15: =SUM(I15+K15) -> 1794561.7 | N15: =M15/F15 -> 0.22985642 | O15: 145071.42 | P15: =O15/F15 -> 0.018581471 | Q15: 109329.74 | R15: =Q15/$F15 -> 0.014003498 | S15: =SUM(O15+Q15) -> 254401.16 | T15: =S15/F15 -> 0.03258497 | U15: 640272.05 | V15: =U15/F15 -> 0.08200924 | W15: 12461.269 | X15: =W15/F15 -> 0.0015961015 | Y15: 723855.47 | Z15: =Y15/F15 -> 0.092715021 | AA15: 1170755.2 | AB15: =AA15/$F15 -> 0.14995617 | AC15: =SUM(Y15+AA15) -> 1894610.7 | AD15: =AC15/F15 -> 0.2426712 | AE15: 818962.88 | AF15: =AE15/F15 -> 0.10489685 | AG15: 1405614.6 | AH15: =AG15/F15 -> 0.18003813 | AI15: 589547.65 | AJ15: =AI15/F15 -> 0.075512205 | AK15: 396883.98 | AL15: =AK15/F15 -> 0.050834881
D16: 45910 | E16: 三 | F16: =SUM(M16,S16,U16,W16,AC16,AE16,AG16,AI16,AK16) -> 7436383 | I16: 922704.54 | J16: =I16/F16 -> 0.12407975 | K16: 846234.4 | L16: =K16/F16 -> 0.11379651 | M16: =SUM(I16+K16) -> 1768938.9 | N16: =M16/F16 -> 0.23787626 | O16: 137693.85 | P16: =O16/F16 -> 0.01851624 | Q16: 106359.16 | R16: =Q16/$F16 -> 0.014302539 | S16: =SUM(O16+Q16) -> 244053.01 | T16: =S16/F16 -> 0.032818778 | U16: 637306.64 | V16: =U16/F16 -> 0.085701159 | W16: 10391.165 | X16: =W16/F16 -> 0.0013973413 | Y16: 672768.71 | Z16: =Y16/F16 -> 0.090469885 | AA16: 1063595 | AB16: =AA16/$F16 -> 0.14302585 | AC16: =SUM(Y16+AA16) -> 1736363.7 | AD16: =AC16/F16 -> 0.23349574 | AE16: 803252.37 | AF16: =AE16/F16 -> 0.10801654 | AG16: 1211034.6 | AH16: =AG16/F16 -> 0.16285265 | AI16: 636227.29 | AJ16: =AI16/F16 -> 0.085556014 | AK16: 388815.22 | AL16: =AK16/F16 -> 0.052285529
D17: 45911 | E17: 四 | F17: =SUM(M17,S17,U17,W17,AC17,AE17,AG17,AI17,AK17) -> 6919680 | I17: 856747.59 | J17: =I17/F17 -> 0.12381318 | K17: 758956.03 | L17: =K17/F17 -> 0.1096808 | M17: =SUM(I17+K17) -> 1615703.6 | N17: =M17/F17 -> 0.23349398 | O17: 132525.74 | P17: =O17/F17 -> 0.019152004 | Q17: 103770.66 | R17: =Q17/$F17 -> 0.014996454 | S17: =SUM(O17+Q17) -> 236296.4 | T17: =S17/F17 -> 0.034148458 | U17: 594283.82 | V17: =U17/F17 -> 0.085883136 | W17: 9754.9126 | X17: =W17/F17 -> 0.0014097346 | Y17: 621366.49 | Z17: =Y17/F17 -> 0.089796998 | AA17: 945266.21 | AB17: =AA17/$F17 -> 0.13660548 | AC17: =SUM(Y17+AA17) -> 1566632.7 | AD17: =AC17/F17 -> 0.22640248 | AE17: 748334.75 | AF17: =AE17/F17 -> 0.10814586 | AG17: 1159449.9 | AH17: =AG17/F17 -> 0.16755831 | AI17: 610362.09 | AJ17: =AI17/F17 -> 0.088206693 | AK17: 378861.8 | AL17: =AK17/F17 -> 0.054751347
D18: 45912 | E18: 五 | F18: =SUM(M18,S18,U18,W18,AC18,AE18,AG18,AI18,AK18) -> 6171958 | I18: 693224.03 | J18: =I18/F18 -> 0.11231833 | K18: 724669.14 | L18: =K18/F18 -> 0.11741317 | M18: =SUM(I18+K18) -> 1417893.2 | N18: =M18/F18 -> 0.2297315 | O18: 110826.64 | P18: =O18/F18 -> 0.01795648 | Q18: 94817.97 | R18: =Q18/$F18 -> 0.015362705 | S18: =SUM(O18+Q18) -> 205644.61 | T18: =S18/F18 -> 0.033319185 | U18: 514506.04 | V18: =U18/F18 -> 0.083361883 | W18: 10097.029 | X18: =W18/F18 -> 0.0016359523 | Y18: 584650.52 | Z18: =Y18/F18 -> 0.094726911 | AA18: 979449.85 | AB18: =AA18/$F18 -> 0.15869354 | AC18: =SUM(Y18+AA18) -> 1564100.4 | AD18: =AC18/F18 -> 0.25342045 | AE18: 617366.96 | AF18: =AE18/F18 -> 0.10002773 | AG18: 932111.64 | AH18: =AG18/F18 -> 0.15102365 | AI18: 573858.18 | AJ18: =AI18/F18 -> 0.092978302 | AK18: 336380.01 | AL18: =AK18/F18 -> 0.054501345
D19: 45913 | E19: 六 | F19: =SUM(M19,S19,U19,W19,AC19,AE19,AG19,AI19,AK19) -> 6541355 | I19: 683125.9 | J19: =I19/F19 -> 0.10443186 | K19: 808299.2 | L19: =K19/F19 -> 0.12356755 | M19: =SUM(I19+K19) -> 1491425.1 | N19: =M19/F19 -> 0.22799941 | O19: 111249.55 | P19: =O19/F19 -> 0.017007111 | Q19: 93680.304 | R19: =Q19/$F19 -> 0.014321238 | S19: =SUM(O19+Q19) -> 204929.85 | T19: =S19/F19 -> 0.031328349 | U19: 543330.7 | V19: =U19/F19 -> 0.08306088 | W19: 12455.071 | X19: =W19/F19 -> 0.0019040506 | Y19: 630925.73 | Z19: =Y19/F19 -> 0.096451841 | AA19: 1060648.8 | AB19: =AA19/$F19 -> 0.16214512 | AC19: =SUM(Y19+AA19) -> 1691574.5 | AD19: =AC19/F19 -> 0.25859696 | AE19: 651474.25 | AF19: =AE19/F19 -> 0.099593165 | AG19: 1016529.4 | AH19: =AG19/F19 -> 0.15540043 | AI19: 582194.15 | AJ19: =AI19/F19 -> 0.089002073 | AK19: 347441.94 | AL19: =AK19/F19 -> 0.053114674
D20: 45914 | E20: 日 | F20: =SUM(M20,S20,U20,W20,AC20,AE20,AG20,AI20,AK20) -> 7771753 | I20: 935689.61 | J20: =I20/F20 -> 0.12039621 | K20: 866163.8 | L20: =K20/F20 -> 0.11145025 | M20: =SUM(I20+K20) -> 1801853.4 | N20: =M20/F20 -> 0.23184646 | O20: 151097.51 | P20: =O20/F20 -> 0.019441882 | Q20: 109222.7 | R20: =Q20/$F20 -> 0.014053805 | S20: =SUM(O20+Q20) -> 260320.21 | T20: =S20/F20 -> 0.033495687 | U20: 669570.65 | V20: =U20/F20 -> 0.086154391 | W20: 13837.593 | X20: =W20/F20 -> 0.0017804983 | Y20: 724732.36 | Z20: =Y20/F20 -> 0.093252109 | AA20: 1141094.4 | AB20: =AA20/$F20 -> 0.14682587 | AC20: =SUM(Y20+AA20) -> 1865826.7 | AD20: =AC20/F20 -> 0.24007797 | AE20: 855937.57 | AF20: =AE20/F20 -> 0.11013443 | AG20: 1235869.7 | AH20: =AG20/F20 -> 0.15902072 | AI20: 658283.11 | AJ20: =AI20/F20 -> 0.084702011 | AK20: 410254.01 | AL20: =AK20/F20 -> 0.052787835
D21: 45915 | E21: 一 | F21: =SUM(M21,S21,U21,W21,AC21,AE21,AG21,AI21,AK21) -> 7821657 | I21: 884810.27 | J21: =I21/F21 -> 0.11312312 | K21: 849921.16 | L21: =K21/F21 -> 0.10866255 | M21: =SUM(I21+K21) -> 1734731.4 | N21: =M21/F21 -> 0.22178567 | O21: 142123.06 | P21: =O21/F21 -> 0.018170455 | Q21: 113089.68 | R21: =Q21/$F21 -> 0.014458532 | S21: =SUM(O21+Q21) -> 255212.75 | T21: =S21/F21 -> 0.032628987 | U21: 679271.93 | V21: =U21/F21 -> 0.086845017 | W21: 14362.801 | X21: =W21/F21 -> 0.0018362863 | Y21: 743337.31 | Z21: =Y21/F21 -> 0.095035784 | AA21: 1200149.4 | AB21: =AA21/$F21 -> 0.15343927 | AC21: =SUM(Y21+AA21) -> 1943486.7 | AD21: =AC21/F21 -> 0.24847506 | AE21: 866645.2 | AF21: =AE21/F21 -> 0.11080072 | AG21: 1224710.4 | AH21: =AG21/F21 -> 0.1565794 | AI21: 684941.6 | AJ21: =AI21/F21 -> 0.087569884 | AK21: 418294.26 | AL21: =AK21/F21 -> 0.053478983
D22: 45916 | E22: 二 | F22: =SUM(M22,S22,U22,W22,AC22,AE22,AG22,AI22,AK22) -> 8739776 | G22: =SUM(F22:F28) -> 52767858 | I22: 889793.59 | J22: =I22/F22 -> 0.10180966 | K22: 869011.93 | L22: =K22/F22 -> 0.099431831 | M22: =SUM(I22+K22) -> 1758805.5 | N22: =M22/F22 -> 0.20124149 | O22: 194714.01 | P22: =O22/F22 -> 0.022279061 | Q22: 111579.11 | R22: =Q22/$F22 -> 0.012766815 | S22: =SUM(O22+Q22) -> 306293.11 | T22: =S22/F22 -> 0.035045877 | U22: 703447.08 | V22: =U22/F22 -> 0.080487999 | W22: 13556.61 | X22: =W22/F22 -> 0.0015511393 | Y22: 992551.14 | Z22: =Y22/F22 -> 0.11356711 | AA22: 1122256 | AB22: =AA22/$F22 -> 0.12840787 | AC22: =SUM(Y22+AA22) -> 2114807.1 | AD22: =AC22/F22 -> 0.24197498 | AE22: 1089037.1 | AF22: =AE22/F22 -> 0.12460698 | AG22: 1449241.3 | AH22: =AG22/F22 -> 0.16582133 | AI22: 667781.17 | AJ22: =AI22/F22 -> 0.076407127 | AK22: 636806.97 | AL22: =AK22/F22 -> 0.072863076
D23: 45917 | E23: 三 | F23: =SUM(M23,S23,U23,W23,AC23,AE23,AG23,AI23,AK23) -> 8050591 | I23: 864631.53 | J23: =I23/F23 -> 0.10739976 | K23: 859518.91 | L23: =K23/F23 -> 0.1067647 | M23: =SUM(I23+K23) -> 1724150.4 | N23: =M23/F23 -> 0.21416446 | O23: 169857.95 | P23: =O23/F23 -> 0.021098818 | Q23: 111587.24 | R23: =Q23/$F23 -> 0.013860751 | S23: =SUM(O23+Q23) -> 281445.19 | T23: =S23/F23 -> 0.034959569 | U23: 652766.95 | V23: =U23/F23 -> 0.08108311 | W23: 12995.425 | X23: =W23/F23 -> 0.00161422 | Y23: 881295.03 | Z23: =Y23/F23 -> 0.10946961 | AA23: 1033941.9 | AB23: =AA23/$F23 -> 0.12843056 | AC23: =SUM(Y23+AA23) -> 1915237 | AD23: =AC23/F23 -> 0.23790017 | AE23: 961258.42 | AF23: =AE23/F23 -> 0.11940222 | AG23: 1290164.7 | AH23: =AG23/F23 -> 0.16025715 | AI23: 678822.22 | AJ23: =AI23/F23 -> 0.084319552 | AK23: 533750.65 | AL23: =AK23/F23 -> 0.066299561
D24: 45918 | E24: 四 | F24: =SUM(M24,S24,U24,W24,AC24,AE24,AG24,AI24,AK24) -> 7502711 | I24: 794362.84 | J24: =I24/F24 -> 0.10587677 | K24: 790964.02 | L24: =K24/F24 -> 0.10542376 | M24: =SUM(I24+K24) -> 1585326.9 | N24: =M24/F24 -> 0.21130054 | O24: 158870.23 | P24: =O24/F24 -> 0.021175044 | Q24: 108738.33 | R24: =Q24/$F24 -> 0.014493205 | S24: =SUM(O24+Q24) -> 267608.56 | T24: =S24/F24 -> 0.035668249 | U24: 637088.72 | V24: =U24/F24 -> 0.084914469 | W24: 11141.687 | X24: =W24/F24 -> 0.0014850215 | Y24: 843650.46 | Z24: =Y24/F24 -> 0.11244608 | AA24: 907778.46 | AB24: =AA24/$F24 -> 0.12099339 | AC24: =SUM(Y24+AA24) -> 1751428.9 | AD24: =AC24/F24 -> 0.23343948 | AE24: 899300.47 | AF24: =AE24/F24 -> 0.1198634 | AG24: 1196489.1 | AH24: =AG24/F24 -> 0.15947424 | AI24: 639993.16 | AJ24: =AI24/F24 -> 0.085301588 | AK24: 514333.47 | AL24: =AK24/F24 -> 0.068553016
D25: 45919 | E25: 五 | F25: =SUM(M25,S25,U25,W25,AC25,AE25,AG25,AI25,AK25) -> 6251144 | I25: 638219 | J25: =I25/F25 -> 0.10209635 | K25: 718364.62 | L25: =K25/F25 -> 0.1149173 | M25: =SUM(I25+K25) -> 1356583.6 | N25: =M25/F25 -> 0.21701366 | O25: 142786.13 | P25: =O25/F25 -> 0.0228416 | Q25: 90564.125 | R25: =Q25/$F25 -> 0.014487608 | S25: =SUM(O25+Q25) -> 233350.25 | T25: =S25/F25 -> 0.037329208 | U25: 508308.39 | V25: =U25/F25 -> 0.081314459 | W25: 10258.678 | X25: =W25/F25 -> 0.0016410882 | Y25: 727920.22 | Z25: =Y25/F25 -> 0.11644592 | AA25: 912993.01 | AB25: =AA25/$F25 -> 0.14605215 | AC25: =SUM(Y25+AA25) -> 1640913.2 | AD25: =AC25/F25 -> 0.26249807 | AE25: 659769.2 | AF25: =AE25/F25 -> 0.10554375 | AG25: 880595.16 | AH25: =AG25/F25 -> 0.14086944 | AI25: 551032.69 | AJ25: =AI25/F25 -> 0.088149095 | AK25: 410332.79 | AL25: =AK25/F25 -> 0.065641231
D26: 45920 | E26: 六 | F26: =SUM(M26,S26,U26,W26,AC26,AE26,AG26,AI26,AK26) -> 6569112 | I26: 614856.95 | J26: =I26/F26 -> 0.093598184 | K26: 770452.57 | L26: =K26/F26 -> 0.11728413 | M26: =SUM(I26+K26) -> 1385309.5 | N26: =M26/F26 -> 0.21088231 | O26: 142994.41 | P26: =O26/F26 -> 0.021767692 | Q26: 91552.391 | R26: =Q26/$F26 -> 0.013936799 | S26: =SUM(O26+Q26) -> 234546.8 | T26: =S26/F26 -> 0.03570449 | U26: 559332.71 | V26: =U26/F26 -> 0.085145863 | W26: 11291.164 | X26: =W26/F26 -> 0.0017188265 | Y26: 725947.52 | Z26: =Y26/F26 -> 0.11050923 | AA26: 1012169.7 | AB26: =AA26/$F26 -> 0.15408013 | AC26: =SUM(Y26+AA26) -> 1738117.2 | AD26: =AC26/F26 -> 0.26458937 | AE26: 699378.88 | AF26: =AE26/F26 -> 0.10646475 | AG26: 965159.62 | AH26: =AG26/F26 -> 0.14692391 | AI26: 524094.07 | AJ26: =AI26/F26 -> 0.07978157 | AK26: 451882.05 | AL26: =AK26/F26 -> 0.068788909
D27: 45921 | E27: 日 | F27: =SUM(M27,S27,U27,W27,AC27,AE27,AG27,AI27,AK27) -> 7902663 | I27: 825818.01 | J27: =I27/F27 -> 0.1044987 | K27: 848067.34 | L27: =K27/F27 -> 0.10731412 | M27: =SUM(I27+K27) -> 1673885.3 | N27: =M27/F27 -> 0.21181282 | O27: 190210 | P27: =O27/F27 -> 0.024069102 | Q27: 108008.33 | R27: =Q27/$F27 -> 0.013667333 | S27: =SUM(O27+Q27) -> 298218.33 | T27: =S27/F27 -> 0.037736435 | U27: 701017.79 | V27: =U27/F27 -> 0.088706527 | W27: 15380.101 | X27: =W27/F27 -> 0.0019461922 | Y27: 810222.5 | Z27: =Y27/F27 -> 0.10252525 | AA27: 1142598.4 | AB27: =AA27/$F27 -> 0.14458397 | AC27: =SUM(Y27+AA27) -> 1952820.9 | AD27: =AC27/F27 -> 0.24710922 | AE27: 902475.93 | AF27: =AE27/F27 -> 0.11419896 | AG27: 1213406.5 | AH27: =AG27/F27 -> 0.153544 | AI27: 630416.13 | AJ27: =AI27/F27 -> 0.07977262 | AK27: 515041.99 | AL27: =AK27/F27 -> 0.065173219
D28: 45922 | E28: 一 | F28: =SUM(M28,S28,U28,W28,AC28,AE28,AG28,AI28,AK28) -> 7751861 | I28: 798136.29 | J28: =I28/F28 -> 0.1029606 | K28: 834501.88 | L28: =K28/F28 -> 0.10765181 | M28: =SUM(I28+K28) -> 1632638.2 | N28: =M28/F28 -> 0.21061242 | O28: 171398.15 | P28: =O28/F28 -> 0.022110581 | Q28: 110800.43 | R28: =Q28/$F28 -> 0.014293398 | S28: =SUM(O28+Q28) -> 282198.58 | T28: =S28/F28 -> 0.036403979 | U28: 663036.59 | V28: =U28/F28 -> 0.085532569 | W28: 17792.687 | X28: =W28/F28 -> 0.0022952794 | Y28: 817320.62 | Z28: =Y28/F28 -> 0.10543541 | AA28: 1110827.8 | AB28: =AA28/$F28 -> 0.14329821 | AC28: =SUM(Y28+AA28) -> 1928148.4 | AD28: =AC28/F28 -> 0.24873362 | AE28: 880709.24 | AF28: =AE28/F28 -> 0.11361262 | AG28: 1202873.5 | AH28: =AG28/F28 -> 0.15517223 | AI28: 625095.66 | AJ28: =AI28/F28 -> 0.080638141 | AK28: 519368.1 | AL28: =AK28/F28 -> 0.06699915
D29: 45923 | E29: 二 | F29: =SUM(M29,S29,U29,W29,AC29,AE29,AG29,AI29,AK29) -> 7508635 | G29: =SUM(F29:F35) -> 47691357 | I29: 771527.25 | J29: =I29/F29 -> 0.102752 | K29: 817056.84 | L29: =K29/F29 -> 0.10881563 | M29: =SUM(I29+K29) -> 1588584.1 | N29: =M29/F29 -> 0.21156763 | O29: 174167 | P29: =O29/F29 -> 0.023195561 | Q29: 107226.7 | R29: =Q29/$F29 -> 0.014280451 | S29: =SUM(O29+Q29) -> 281393.69 | T29: =S29/F29 -> 0.037476012 | U29: 643297.62 | V29: =U29/F29 -> 0.085674377 | W29: 16624.875 | X29: =W29/F29 -> 0.0022141008 | Y29: 799731.87 | Z29: =Y29/F29 -> 0.10650829 | AA29: 1041051.6 | AB29: =AA29/$F29 -> 0.13864726 | AC29: =SUM(Y29+AA29) -> 1840783.5 | AD29: =AC29/F29 -> 0.24515555 | AE29: 878187.26 | AF29: =AE29/F29 -> 0.11695698 | AG29: 1142712.9 | AH29: =AG29/F29 -> 0.15218651 | AI29: 623455.1 | AJ29: =AI29/F29 -> 0.08303175 | AK29: 493595.91 | AL29: =AK29/F29 -> 0.065737102
D30: 45924 | E30: 三 | F30: =SUM(M30,S30,U30,W30,AC30,AE30,AG30,AI30,AK30) -> 7219231 | I30: 750420.97 | J30: =I30/F30 -> 0.10394749 | K30: 800296.67 | L30: =K30/F30 -> 0.11085622 | M30: =SUM(I30+K30) -> 1550717.6 | N30: =M30/F30 -> 0.21480371 | O30: 171741.72 | P30: =O30/F30 -> 0.023789476 | Q30: 103726.57 | R30: =Q30/$F30 -> 0.014368091 | S30: =SUM(O30+Q30) -> 275468.29 | T30: =S30/F30 -> 0.038157567 | U30: 632333.38 | V30: =U30/F30 -> 0.087590129 | W30: 15164.672 | X30: =W30/F30 -> 0.0021005939 | Y30: 786643.61 | Z30: =Y30/F30 -> 0.10896501 | AA30: 1007603.6 | AB30: =AA30/$F30 -> 0.13957215 | AC30: =SUM(Y30+AA30) -> 1794247.2 | AD30: =AC30/F30 -> 0.24853717 | AE30: 855464.93 | AF30: =AE30/F30 -> 0.11849807 | AG30: 1127479.1 | AH30: =AG30/F30 -> 0.15617717 | AI30: 486385.36 | AJ30: =AI30/F30 -> 0.067373569 | AK30: 481970.46 | AL30: =AK30/F30 -> 0.066762022
D31: 45925 | E31: 四 | F31: =SUM(M31,S31,U31,W31,AC31,AE31,AG31,AI31,AK31) -> 6826680 | I31: 691778.37 | J31: =I31/F31 -> 0.10133452 | K31: 722394.7 | L31: =K31/F31 -> 0.10581933 | M31: =SUM(I31+K31) -> 1414173.1 | N31: =M31/F31 -> 0.20715385 | O31: 158798.4 | P31: =O31/F31 -> 0.023261439 | Q31: 98549.541 | R31: =Q31/$F31 -> 0.01443594 | S31: =SUM(O31+Q31) -> 257347.94 | T31: =S31/F31 -> 0.037697379 | U31: 599978.56 | V31: =U31/F31 -> 0.087887313 | W31: 14768.768 | X31: =W31/F31 -> 0.0021633895 | Y31: 763873.31 | Z31: =Y31/F31 -> 0.11189529 | AA31: 983896.35 | AB31: =AA31/$F31 -> 0.14412516 | AC31: =SUM(Y31+AA31) -> 1747769.7 | AD31: =AC31/F31 -> 0.25602045 | AE31: 824091.75 | AF31: =AE31/F31 -> 0.12071633 | AG31: 1050628.2 | AH31: =AG31/F31 -> 0.15390031 | AI31: 457107.29 | AJ31: =AI31/F31 -> 0.066958945 | AK31: 460814.8 | AL31: =AK31/F31 -> 0.067502036
D32: 45926 | E32: 五 | F32: =SUM(M32,S32,U32,W32,AC32,AE32,AG32,AI32,AK32) -> 5933194 | I32: 506166.87 | J32: =I32/F32 -> 0.085311027 | K32: 653453.45 | L32: =K32/F32 -> 0.11013519 | M32: =SUM(I32+K32) -> 1159620.3 | N32: =M32/F32 -> 0.19544622 | O32: 141466.99 | P32: =O32/F32 -> 0.023843311 | Q32: 89111.406 | R32: =Q32/$F32 -> 0.015019129 | S32: =SUM(O32+Q32) -> 230578.4 | T32: =S32/F32 -> 0.03886244 | U32: 529492.45 | V32: =U32/F32 -> 0.089242397 | W32: 13040.8 | X32: =W32/F32 -> 0.0021979393 | Y32: 695107.94 | Z32: =Y32/F32 -> 0.11715578 | AA32: 962528.26 | AB32: =AA32/$F32 -> 0.16222767 | AC32: =SUM(Y32+AA32) -> 1657636.2 | AD32: =AC32/F32 -> 0.27938345 | AE32: 678746.3 | AF32: =AE32/F32 -> 0.11439813 | AG32: 764399.78 | AH32: =AG32/F32 -> 0.12883445 | AI32: 503600.39 | AJ32: =AI32/F32 -> 0.084878463 | AK32: 396079.35 | AL32: =AK32/F32 -> 0.066756514
D33: 45927 | E33: 六 | F33: =SUM(M33,S33,U33,W33,AC33,AE33,AG33,AI33,AK33) -> 6011714 | I33: 481225.32 | J33: =I33/F33 -> 0.080047939 | K33: 637044.29 | L33: =K33/F33 -> 0.10596717 | M33: =SUM(I33+K33) -> 1118269.6 | N33: =M33/F33 -> 0.1860151 | O33: 140872.99 | P33: =O33/F33 -> 0.023433082 | Q33: 87187.049 | R33: =Q33/$F33 -> 0.01450286 | S33: =SUM(O33+Q33) -> 228060.04 | T33: =S33/F33 -> 0.037935943 | U33: 544321.96 | V33: =U33/F33 -> 0.090543555 | W33: 15083.729 | X33: =W33/F33 -> 0.0025090563 | Y33: 703524.48 | Z33: =Y33/F33 -> 0.11702561 | AA33: 1011559.8 | AB33: =AA33/$F33 -> 0.16826479 | AC33: =SUM(Y33+AA33) -> 1715084.2 | AD33: =AC33/F33 -> 0.28529039 | AE33: 663025.3 | AF33: =AE33/F33 -> 0.1102889 | AG33: 816789.3 | AH33: =AG33/F33 -> 0.13586629 | AI33: 512271.82 | AJ33: =AI33/F33 -> 0.085212275 | AK33: 398808 | AL33: =AK33/F33 -> 0.066338485
D34: 45928 | E34: 日 | F34: =SUM(M34,S34,U34,W34,AC34,AE34,AG34,AI34,AK34) -> 6495139 | I34: 497221.71 | J34: =I34/F34 -> 0.076552897 | K34: 714318.73 | L34: =K34/F34 -> 0.10997744 | M34: =SUM(I34+K34) -> 1211540.4 | N34: =M34/F34 -> 0.18653033 | O34: 140780.61 | P34: =O34/F34 -> 0.021674765 | Q34: 91009.456 | R34: =Q34/$F34 -> 0.014011934 | S34: =SUM(O34+Q34) -> 231790.07 | T34: =S34/F34 -> 0.035686698 | U34: 582195.26 | V34: =U34/F34 -> 0.089635535 | W34: 15211.093 | X34: =W34/F34 -> 0.0023419196 | Y34: 737020.34 | Z34: =Y34/F34 -> 0.11347261 | AA34: 1007821.4 | AB34: =AA34/$F34 -> 0.15516548 | AC34: =SUM(Y34+AA34) -> 1744841.7 | AD34: =AC34/F34 -> 0.26863809 | AE34: 753504.46 | AF34: =AE34/F34 -> 0.11601052 | AG34: 905886.83 | AH34: =AG34/F34 -> 0.13947151 | AI34: 640431.03 | AJ34: =AI34/F34 -> 0.098601589 | AK34: 409738.1 | AL34: =AK34/F34 -> 0.063083807
D35: 45929 | E35: 一 | F35: =SUM(M35,S35,U35,W35,AC35,AE35,AG35,AI35,AK35) -> 7696764 | I35: 718070.13 | J35: =I35/F35 -> 0.093295069 | K35: 820836.76 | L35: =K35/F35 -> 0.106647 | M35: =SUM(I35+K35) -> 1538906.9 | N35: =M35/F35 -> 0.19994206 | O35: 175439.16 | P35: =O35/F35 -> 0.022793885 | Q35: 108789.84 | R35: =Q35/$F35 -> 0.014134491 | S35: =SUM(O35+Q35) -> 284229 | T35: =S35/F35 -> 0.036928376 | U35: 683425.86 | V35: =U35/F35 -> 0.088793921 | W35: 18719.059 | X35: =W35/F35 -> 0.0024320687 | Y35: 829722.2 | Z35: =Y35/F35 -> 0.10780143 | AA35: 1103405.3 | AB35: =AA35/$F35 -> 0.14335964 | AC35: =SUM(Y35+AA35) -> 1933127.5 | AD35: =AC35/F35 -> 0.25116107 | AE35: 843532.31 | AF35: =AE35/F35 -> 0.10959571 | AG35: 1224657.3 | AH35: =AG35/F35 -> 0.15911327 | AI35: 647403.46 | AJ35: =AI35/F35 -> 0.084113721 | AK35: 522762.67 | AL35: =AK35/F35 -> 0.0679198
D36: 45930 | E36: 二 | F36: =SUM(M36,S36,U36,W36,AC36,AE36,AG36,AI36,AK36) -> 8551969 | G36: =SUM(F36:F42) -> 8551969 | I36: 719554.55 | J36: =I36/F36 -> 0.08413905 | K36: 795384.55 | L36: =K36/F36 -> 0.093006014 | M36: =SUM(I36+K36) -> 1514939.1 | N36: =M36/F36 -> 0.17714506 | O36: 212315.87 | P36: =O36/F36 -> 0.024826548 | Q36: 112672.39 | R36: =Q36/$F36 -> 0.013175023 | S36: =SUM(O36+Q36) -> 324988.26 | T36: =S36/F36 -> 0.038001571 | U36: 1002122.8 | V36: =U36/F36 -> 0.11718036 | W36: 15967.863 | X36: =W36/F36 -> 0.0018671564 | Y36: 790775.01 | Z36: =Y36/F36 -> 0.09246701 | AA36: 1095676.4 | AB36: =AA36/$F36 -> 0.12811979 | AC36: =SUM(Y36+AA36) -> 1886451.4 | AD36: =AC36/F36 -> 0.2205868 | AE36: 1280674.6 | AF36: =AE36/F36 -> 0.14975202 | AG36: 1163000.5 | AH36: =AG36/F36 -> 0.13599214 | AI36: 654699.71 | AJ36: =AI36/F36 -> 0.076555435 | AK36: 709124.64 | AL36: =AK36/F36 -> 0.082919458
I46: =SUM(I7:I45) -> 22626323 | J46: =I46/$H$7 -> 0.10526297 | K46: =SUM(K7:K45) -> 23969083 | L46: =K46/$H$7 -> 0.11150981 | M46: =SUM(M7:M45) -> 46595406 | N46: =M46/$H$7 -> 0.21677278 | O46: =SUM(O7:O45) -> 4640450.6 | P46: =O46/$H$7 -> 0.021588467 | Q46: =SUM(Q7:Q45) -> 3150244.5 | R46: =Q46/$H$7 -> 0.014655678 | S46: =SUM(S7:S45) -> 7790695.1 | T46: =S46/$H$7 -> 0.036244145 | U46: =SUM(U7:U45) -> 18799984 | V46: =U46/$H$7 -> 0.087461944 | W46: =SUM(W7:W45) -> 395545.77 | X46: =W46/$H$7 -> 0.0018401719 | Y46: =SUM(Y7:Y45) -> 21899883 | Z46: =Y46/$H$7 -> 0.1018834 | AA46: =SUM(AA7:AA45) -> 31740772 | AB46: =AA46/$H$7 -> 0.14766553 | AC46: =SUM(AC7:AC45) -> 53640655 | AD46: =AC46/$H$7 -> 0.24954894 | AE46: =SUM(AE7:AE45) -> 23966440 | AF46: =AE46/$H$7 -> 0.11149751 | AG46: =SUM(AG7:AG45) -> 32518381 | AH46: =AG46/$H$7 -> 0.15128315 | AI46: =SUM(AI7:AI45) -> 17756916 | AJ46: =AI46/$H$7 -> 0.082609348 | AK46: =SUM(AK7:AK45) -> 13486423 | AL46: =AK46/$H$7 -> 0.062742008
M47: =M46 -> 46595406 | S47: =S46 -> 7790695.1 | U47: =U46 -> 18799984 | W47: =W46 -> 395545.77 | AC47: =AC46 -> 53640655 | AE47: =AE46 -> 23966440 | AG47: =AG46 -> 32518381 | AI47: =AI46 -> 17756916 | AK47: =AK46 -> 13486423

Sheet （４）訂單數量構成比
B2: （4）訂單數量構成比
C3: 月份 | D3: 日期 | F3: 訂單量 | I3: 品類訂單量
I4: 18℃-飯糰 | O4: 18℃-壽司手卷 | U4: 4℃-飯糰 | W4: 4℃-壽司手卷 | Y4: 主食 | AE4: 便當 | AG4: 熱食義麵 | AI4: 季節調理麵 | AK4: 微波小吃
F5: 日 | G5: 週累積 | H5: 月累積 | I5: 一配 | K5: 二配 | M5: 合計 | O5: 一配 | Q5: 二配 | S5: 合計 | U5: 一配 | W5: 一配 | Y5: 一配 | AA5: 二配 | AC5: 合計 | AE5: 一配 | AG5: 一配 | AI5: 一配 | AK5: 一配
I6: 訂單數 | J6: 比例(%) | K6: 訂單數 | L6: 比例(%) | M6: 訂單數 | N6: 比例(%) | O6: 訂單數 | P6: 比例(%) | Q6: 訂單數 | R6: 比例(%) | S6: 訂單數 | T6: 比例(%) | U6: 訂單數 | V6: 比例(%) | W6: 訂單數 | X6: 比例(%) | Y6: 訂單數 | Z6: 比例(%) | AA6: 訂單數 | AB6: 比例(%) | AC6: 訂單數 | AD6: 比例(%) | AE6: 訂單數 | AF6: 比例(%) | AG6: 訂單數 | AH6: 比例(%) | AI6: 訂單數 | AJ6: 比例(%) | AK6: 訂單數 | AL6: 比例(%)
D7: 45901 | E7: 一 | F7: =SUM(M7,S7,U7,W7,AC7,AE7,AG7,AI7,AK7) -> 222309 | G7: =SUM(F7) -> 222309 | H7: =SUM(F7:F36) -> 6718847 | I7: 31188 | J7: =I7/F7 -> 0.14029122 | K7: 45716 | L7: =K7/F7 -> 0.2056417 | M7: =SUM(I7+K7) -> 76904 | N7: =M7/F7 -> 0.34593291 | O7: 7283 | P7: =O7/F7 -> 0.032760707 | Q7: 4112 | R7: =Q7/D7 -> 0.089584105 | S7: =SUM(O7+Q7) -> 11395 | T7: =S7/F7 -> 0.051257484 | U7: 20019 | V7: =U7/F7 -> 0.090050335 | W7: 420 | X7: =W7/F7 -> 0.0018892622 | Y7: 23192 | Z7: =Y7/F7 -> 0.10432326 | AA7: 24411 | AB7: =AA7/D7 -> 0.53181848 | AC7: =SUM(Y7+AA7) -> 47603 | AD7: =AC7/F7 -> 0.21412988 | AE7: 13998 | AF7: =AE7/F7 -> 0.062966412 | AG7: 17886 | AH7: =AG7/F7 -> 0.080455582 | AI7: 16627 | AJ7: =AI7/F7 -> 0.074792294 | AK7: 17457 | AL7: =AK7/F7 -> 0.078525836
D8: 45902 | E8: 二 | F8: =SUM(M8,S8,U8,W8,AC8,AE8,AG8,AI8,AK8) -> 240560 | G8: =SUM(F8:F14) -> 1525242 | I8: 43708 | J8: =I8/F8 -> 0.18169272 | K8: 46366 | L8: =K8/F8 -> 0.19274194 | M8: =SUM(I8+K8) -> 90074 | N8: =M8/F8 -> 0.37443465 | O8: 7078 | P8: =O8/F8 -> 0.029423013 | Q8: 4101 | R8: =Q8/D8 -> 0.089342512 | S8: =SUM(O8+Q8) -> 11179 | T8: =S8/F8 -> 0.046470735 | U8: 19657 | V8: =U8/F8 -> 0.081713502 | W8: 458 | X8: =W8/F8 -> 0.0019038909 | Y8: 22718 | Z8: =Y8/F8 -> 0.094437978 | AA8: 23992 | AB8: =AA8/D8 -> 0.52267875 | AC8: =SUM(Y8+AA8) -> 46710 | AD8: =AC8/F8 -> 0.19417193 | AE8: 14199 | AF8: =AE8/F8 -> 0.059024776 | AG8: 25447 | AH8: =AG8/F8 -> 0.10578234 | AI8: 16117 | AJ8: =AI8/F8 -> 0.066997838 | AK8: 16719 | AL8: =AK8/F8 -> 0.069500333
D9: 45903 | E9: 三 | F9: =SUM(M9,S9,U9,W9,AC9,AE9,AG9,AI9,AK9) -> 228856 | I9: 41906 | J9: =I9/F9 -> 0.18311078 | K9: 45666 | L9: =K9/F9 -> 0.19954032 | M9: =SUM(I9+K9) -> 87572 | N9: =M9/F9 -> 0.3826511 | O9: 6487 | P9: =O9/F9 -> 0.028345335 | Q9: 4013 | R9: =Q9/D9 -> 0.08742348 | S9: =SUM(O9+Q9) -> 10500 | T9: =S9/F9 -> 0.045880379 | U9: 18908 | V9: =U9/F9 -> 0.082619639 | W9: 431 | X9: =W9/F9 -> 0.0018832803 | Y9: 22068 | Z9: =Y9/F9 -> 0.096427448 | AA9: 21947 | AB9: =AA9/D9 -> 0.4781169 | AC9: =SUM(Y9+AA9) -> 44015 | AD9: =AC9/F9 -> 0.19232618 | AE9: 13526 | AF9: =AE9/F9 -> 0.059102667 | AG9: 21626 | AH9: =AG9/F9 -> 0.094496102 | AI9: 15647 | AJ9: =AI9/F9 -> 0.068370504 | AK9: 16631 | AL9: =AK9/F9 -> 0.072670151
D10: 45904 | E10: 四 | F10: =SUM(M10,S10,U10,W10,AC10,AE10,AG10,AI10,AK10) -> 210018 | I10: 38090 | J10: =I10/F10 -> 0.18136541 | K10: 42384 | L10: =K10/F10 -> 0.20181127 | M10: =SUM(I10+K10) -> 80474 | N10: =M10/F10 -> 0.38317668 | O10: 6155 | P10: =O10/F10 -> 0.029307012 | Q10: 4074 | R10: =Q10/D10 -> 0.088750436 | S10: =SUM(O10+Q10) -> 10229 | T10: =S10/F10 -> 0.048705349 | U10: 17869 | V10: =U10/F10 -> 0.085083183 | W10: 421 | X10: =W10/F10 -> 0.0020045901 | Y10: 20720 | Z10: =Y10/F10 -> 0.09865821 | AA10: 17620 | AB10: =AA10/D10 -> 0.38384455 | AC10: =SUM(Y10+AA10) -> 38340 | AD10: =AC10/F10 -> 0.18255578 | AE10: 12515 | AF10: =AE10/F10 -> 0.05959013 | AG10: 19930 | AH10: =AG10/F10 -> 0.094896628 | AI10: 14795 | AJ10: =AI10/F10 -> 0.070446343 | AK10: 15445 | AL10: =AK10/F10 -> 0.073541316
D11: 45905 | E11: 五 | F11: =SUM(M11,S11,U11,W11,AC11,AE11,AG11,AI11,AK11) -> 186157 | I11: 33916 | J11: =I11/F11 -> 0.1821903 | K11: 39665 | L11: =K11/F11 -> 0.21307284 | M11: =SUM(I11+K11) -> 73581 | N11: =M11/F11 -> 0.39526314 | O11: 4809 | P11: =O11/F11 -> 0.025833033 | Q11: 3410 | R11: =Q11/D11 -> 0.074283847 | S11: =SUM(O11+Q11) -> 8219 | T11: =S11/F11 -> 0.044150905 | U11: 15369 | V11: =U11/F11 -> 0.082559345 | W11: 370 | X11: =W11/F11 -> 0.0019875696 | Y11: 18830 | Z11: =Y11/F11 -> 0.10115118 | AA11: 16836 | AB11: =AA11/D11 -> 0.36675743 | AC11: =SUM(Y11+AA11) -> 35666 | AD11: =AC11/F11 -> 0.19159097 | AE11: 10286 | AF11: =AE11/F11 -> 0.055254436 | AG11: 15953 | AH11: =AG11/F11 -> 0.085696482 | AI11: 14584 | AJ11: =AI11/F11 -> 0.078342474 | AK11: 12129 | AL11: =AK11/F11 -> 0.065154681
D12: 45906 | E12: 六 | F12: =SUM(M12,S12,U12,W12,AC12,AE12,AG12,AI12,AK12) -> 195008 | I12: 33111 | J12: =I12/F12 -> 0.16979303 | K12: 42836 | L12: =K12/F12 -> 0.21966278 | M12: =SUM(I12+K12) -> 75947 | N12: =M12/F12 -> 0.38945582 | O12: 4715 | P12: =O12/F12 -> 0.024178495 | Q12: 3410 | R12: =Q12/D12 -> 0.074282229 | S12: =SUM(O12+Q12) -> 8125 | T12: =S12/F12 -> 0.041664957 | U12: 15452 | V12: =U12/F12 -> 0.079237775 | W12: 407 | X12: =W12/F12 -> 0.0020870939 | Y12: 19650 | Z12: =Y12/F12 -> 0.1007651 | AA12: 19314 | AB12: =AA12/D12 -> 0.42072932 | AC12: =SUM(Y12+AA12) -> 38964 | AD12: =AC12/F12 -> 0.19980719 | AE12: 11158 | AF12: =AE12/F12 -> 0.057218165 | AG12: 17712 | AH12: =AG12/F12 -> 0.090827043 | AI12: 14371 | AJ12: =AI12/F12 -> 0.073694413 | AK12: 12872 | AL12: =AK12/F12 -> 0.066007548
D13: 45907 | E13: 日 | F13: =SUM(M13,S13,U13,W13,AC13,AE13,AG13,AI13,AK13) -> 233163 | I13: 42322 | J13: =I13/F13 -> 0.1815125 | K13: 46765 | L13: =K13/F13 -> 0.20056784 | M13: =SUM(I13+K13) -> 89087 | N13: =M13/F13 -> 0.38208035 | O13: 6782 | P13: =O13/F13 -> 0.029086948 | Q13: 4003 | R13: =Q13/D13 -> 0.087198031 | S13: =SUM(O13+Q13) -> 10785 | T13: =S13/F13 -> 0.046255195 | U13: 19964 | V13: =U13/F13 -> 0.085622504 | W13: 560 | X13: =W13/F13 -> 0.0024017533 | Y13: 23112 | Z13: =Y13/F13 -> 0.099123789 | AA13: 21832 | AB13: =AA13/D13 -> 0.47557017 | AC13: =SUM(Y13+AA13) -> 44944 | AD13: =AC13/F13 -> 0.19275786 | AE13: 14167 | AF13: =AE13/F13 -> 0.060760069 | AG13: 21532 | AH13: =AG13/F13 -> 0.092347414 | AI13: 16669 | AJ13: =AI13/F13 -> 0.07149076 | AK13: 15455 | AL13: =AK13/F13 -> 0.066284102
D14: 45908 | E14: 一 | F14: =SUM(M14,S14,U14,W14,AC14,AE14,AG14,AI14,AK14) -> 231480 | I14: 39836 | J14: =I14/F14 -> 0.17209262 | K14: 46946 | L14: =K14/F14 -> 0.20280802 | M14: =SUM(I14+K14) -> 86782 | N14: =M14/F14 -> 0.37490064 | O14: 6204 | P14: =O14/F14 -> 0.026801452 | Q14: 3949 | R14: =Q14/D14 -> 0.086019866 | S14: =SUM(O14+Q14) -> 10153 | T14: =S14/F14 -> 0.043861241 | U14: 19709 | V14: =U14/F14 -> 0.085143425 | W14: 524 | X14: =W14/F14 -> 0.0022636945 | Y14: 23529 | Z14: =Y14/F14 -> 0.10164593 | AA14: 23172 | AB14: =AA14/D14 -> 0.50474863 | AC14: =SUM(Y14+AA14) -> 46701 | AD14: =AC14/F14 -> 0.20174961 | AE14: 14895 | AF14: =AE14/F14 -> 0.064346812 | AG14: 21144 | AH14: =AG14/F14 -> 0.091342665 | AI14: 16049 | AJ14: =AI14/F14 -> 0.069332124 | AK14: 15523 | AL14: =AK14/F14 -> 0.067059789
D15: 45909 | E15: 二 | F15: =SUM(M15,S15,U15,W15,AC15,AE15,AG15,AI15,AK15) -> 241607 | G15: =SUM(F15:F21) -> 1578863 | I15: 44860 | J15: =I15/F15 -> 0.18567343 | K15: 46216 | L15: =K15/F15 -> 0.19128585 | M15: =SUM(I15+K15) -> 91076 | N15: =M15/F15 -> 0.37695928 | O15: 5909 | P15: =O15/F15 -> 0.024457073 | Q15: 3817 | R15: =Q15/D15 -> 0.083142739 | S15: =SUM(O15+Q15) -> 9726 | T15: =S15/F15 -> 0.040255456 | U15: 19244 | V15: =U15/F15 -> 0.07965001 | W15: 470 | X15: =W15/F15 -> 0.0019453079 | Y15: 23593 | Z15: =Y15/F15 -> 0.097650316 | AA15: 22597 | AB15: =AA15/D15 -> 0.49221286 | AC15: =SUM(Y15+AA15) -> 46190 | AD15: =AC15/F15 -> 0.19117824 | AE15: 14931 | AF15: =AE15/F15 -> 0.061798706 | AG15: 28876 | AH15: =AG15/F15 -> 0.1195164 | AI15: 16070 | AJ15: =AI15/F15 -> 0.066512974 | AK15: 15024 | AL15: =AK15/F15 -> 0.062183629
