Workbook

Sheet 填寫舉例
A2: 7 | B2: 月別 | C2: 工廠名 | D2: ・・・・・・・・
A4: （１）收支狀況 | E4: ※單位：千元 | G4: （２）ＫＰＩ達成進度 | M4: （３）業績構成比 | S4: （４）訂單數量構成比
B5: 當月 | C5: 前月 | D5: 差異 | E5: 累計 | H5: KPI | I5: 當月 | J5: 前月 | K5: 累計 | L5: ※補充 | N5: 當月 | O5: 比例 | P5: 前月 | Q5: 差異 | T5: 當月 | U5: 比例 | V5: 前月 | W5: 差異
A6: 業績金額 | B6: 500000 | C6: 510000 | D6: =B6-C6 -> -10000 | E6: =B6+C6 -> 1010000 | G6: 人時生產性1 | H6: 110 | I6: 100 | J6: 90 | L6: 個／MH | M6: 飯糰 | N6: 150000 | O6: =IFERROR(N6/$B$6,"") -> 0.3 | P6: 0.4 | Q6: =IFERROR(O6-P6,"") -> -0.1 | S6: 飯糰 | T6: 35000 | U6: =IFERROR(T6/$B$7,"") -> 0.35 | V6: 0.3 | W6: =IFERROR(U6-V6,"") -> 0.05
A7: 訂單數量 | B7: 100000 | C7: 110000 | D7: =B7-C7 -> -10000 | E7: =B7+C7 -> 210000 | G7: 人時生產性2 | H7: 0.8 | I7: 0.85 | J7: 0.81 | K7: 0.84 | L7: 達成率 | M7: 大口飯糰 | N7: 100000 | O7: =IFERROR(N7/$B$6,"") -> 0.2 | P7: 0.15 | Q7: =IFERROR(O7-P7,"") -> 0.05 | S7: 大口飯糰 | T7: 30000 | U7: =IFERROR(T7/$B$7,"") -> 0.3 | V7: 0.15 | W7: =IFERROR(U7-V7,"") -> 0.15
A8: 材料費 | B8: 250000 | C8: 260000 | D8: =B8-C8 -> -10000 | E8: =B8+C8 -> 510000 | G8: 半成品報廢 | H8: 0.0025 | I8: 0.0024 | J8: 0.0023 | K8: 0.00235 | L8: 報廢率 | M8: 便當 | N8: 160000 | O8: =IFERROR(N8/$B$6,"") -> 0.32 | P8: 0.28 | Q8: =IFERROR(O8-P8,"") -> 0.04 | S8: 便當 | T8: 20000 | U8: =IFERROR(T8/$B$7,"") -> 0.2 | V8: 0.28 | W8: =IFERROR(U8-V8,"") -> -0.08
A9: 材料費率 | B9: =B8/B6 -> 0.5 | C9: =C8/C6 -> 0.50980392 | D9: =B9-C9 -> -0.0098039216 | E9: =(B9+C9)/2 -> 0.50490196 | G9: 半成品超用 | H9: 0.006 | I9: 0.009 | J9: 0.0095 | K9: 0.0092 | L9: 超用率 | M9: 調理麵 | N9: 90000 | O9: =IFERROR(N9/$B$6,"") -> 0.18 | P9: 0.17 | Q9: =IFERROR(O9-P9,"") -> 0.01 | S9: 調理麵 | T9: 15000 | U9: =IFERROR(T9/$B$7,"") -> 0.15 | V9: 0.27 | W9: =IFERROR(U9-V9,"") -> -0.12
A10: 勞務成本 | B10: 100000 | C10: 105000 | D10: =B10-C10 -> -5000 | E10: =B10+C10 -> 205000 | G10: 固定產線 | H10: 0.95 | I10: 0.9 | J10: 0.92 | K10: 0.91 | L10: 導入率 | M10: 調理麵包 | N10: - | O10: =IFERROR(N10/$B$6,"") | P10: -% | Q10: =IFERROR(O10-P10,"") | S10: 調理麵包 | T10: - | U10: =IFERROR(T10/$B$7,"") | V10: -% | W10: =IFERROR(U10-V10,"")
A11: 勞務費率 | B11: =B10/B6 -> 0.2 | C11: =C10/C6 -> 0.20588235 | D11: =B11-C11 -> -0.0058823529 | E11: =(B11+C11)/2 -> 0.20294118 | G11: 教育訓練 | H11: 0.8 | I11: 0.85 | J11: 1 | K11: 0.92 | L11: 實施率 | M11: 袋裝調理麵包 | N11: - | O11: =IFERROR(N11/$B$6,"") | P11: -% | Q11: =IFERROR(O11-P11,"") | S11: 袋裝調理麵包 | T11: - | U11: =IFERROR(T11/$B$7,"") | V11: -% | W11: =IFERROR(U11-V11,"")
M12: 義大利麵 | N12: - | O12: =IFERROR(N12/$B$6,"") | P12: -% | Q12: =IFERROR(O12-P12,"") | S12: 義大利麵 | T12: - | U12: =IFERROR(T12/$B$7,"") | V12: -% | W12: =IFERROR(U12-V12,"")
A13: （５）品群別人時生產性 | M13: 調理包 | N13: - | O13: =IFERROR(N13/$B$6,"") | P13: -% | Q13: =IFERROR(O13-P13,"") | S13: 調理包 | T13: - | U13: =IFERROR(T13/$B$7,"") | V13: -% | W13: =IFERROR(U13-V13,"")
B14: 當月 | C14: 前月 | D14: 差異 | E14: 累計 | H14: 當月 | I14: 前月 | J14: 差異 | K14: 累計 | O14: =SUM(O6:O13) -> 1 | P14: =SUM(P6:P13) -> 1 | U14: =SUM(U6:U13) -> 1 | V14: =SUM(V6:V13) -> 1
A15: 飯糰 | B15: 600 | C15: 660 | D15: =B15-C15 -> -60 | E15: =(B15+C15)/2 -> 630 | G15: 調理麵包 | J15: =H15-I15 -> 0 | M15: （７）原因別分析
A16: 大口飯糰 | B16: 800 | C16: 780 | D16: =B16-C16 -> 20 | E16: =(B16+C16)/2 -> 790 | G16: 袋裝調理麵包 | J16: =H16-I16 -> 0 | N16: 合計 | P16: 作業原因 | R16: 規格原因
A17: 便當 | B17: 130 | C17: 111 | D17: =B17-C17 -> 19 | E17: =(B17+C17)/2 -> 120.5 | G17: 義大利麵 | J17: =H17-I17 -> 0 | N17: 金額 | O17: 比例 | P17: 金額 | Q17: 比例 | R17: 金額 | S17: 比例
A18: 調理麵 | B18: 140 | C18: 165 | D18: =B18-C18 -> -25 | E18: =(B18+C18)/2 -> 152.5 | G18: 調理包 | J18: =H18-I18 -> 0 | M18: 半成品報廢 | N18: 1200 | O18: =N18/$B$6 -> 0.0024 | P18: 900 | Q18: =IFERROR(P18/$B$6,"") -> 0.0018 | R18: 300 | S18: =IFERROR(R18/$B$6,"") -> 0.0006
M19: 半成品超用 | N19: 4500 | O19: =N19/$B$6 -> 0.009 | P19: 3500 | Q19: =IFERROR(P19/$B$6,"") -> 0.007 | R19: 1000 | S19: =IFERROR(R19/$B$6,"") -> 0.002
A20: （６）人時生產性前幾名品項
B21: 排名 | C21: 商品名 | F21: 人數 | G21: 產能 | H21: 人時生產性 | I21: 前月比 | J21: 主要原因&對策 | M21: （８）報廢原因別前幾名品項
A22: 飯糰 | B22: 1 | C22: 手巻明太子 | F22: 3 | G22: 3000 | H22: 1000 | I22: 10 | J22: 減少暫時停止生產,人時UP | M22: 半成品報廢 | N22: 排名 | O22: 商品名 | R22: 半成品名 | U22: 單價 | V22: 報廢率 | W22: 數量 | X22: 金額 | Y22: 前月比 | Z22: 主要原因&對策
B23: 2 | M23: 作業原因 | N23: 1 | O23: 明太子海苔便當 | R23: 油炸白身魚 | U23: 10 | V23: 0.15 | W23: 10 | X23: =W23*U23 -> 100 | Y23: 80 | Z23: 油調過多報廢。變更條件。
B24: 3 | N24: 2 | X24: =W24*U24 -> 0
B25: 4 | N25: 3 | X25: =W25*U25 -> 0
B26: 5 | N26: 4 | X26: =W26*U26 -> 0
B27: ▼1 | C27: 手巻卵黄雞絞肉 | F27: 4 | G27: 2800 | H27: 700 | I27: 6/30新商品 | J27: 因組裝2食材,人員增加,產速減少 | N27: 5 | X27: =W27*U27 -> 0
B28: ▼2 | U28: 前幾名合計比例 | V28: =X28/N18 -> 0.083333333 | W28: 前幾名合計金額 | X28: =SUM(X23:X27) -> 100
B29: ▼3 | M29: 規格原因 | N29: 1 | O29: 海老炒飯 | R29: 川燙蝦子拌醬 | U29: 5.55 | V29: 0.21 | W29: 50 | X29: =W29*U29 -> 277.5 | Y29: 35 | Z29: 蝦子入數不足
B30: ▼4 | N30: 2 | X30: =W30*U30 -> 0
B31: ▼5 | N31: 3 | X31: =W31*U31 -> 0
N32: 4 | X32: =W32*U32 -> 0
B33: 排名 | C33: 商品名 | F33: 人數 | G33: 產能 | H33: 人時生產性 | I33: 前月比 | J33: 主要原因&對策 | N33: 5 | X33: =W33*U33 -> 0
A34: 大口飯糰 | B34: 1 | C34: 直巻明太子美奶茲 | F34: 3 | G34: 2500 | H34: 833.33 | I34: 20 | J34: 透由調整速度提升。 | U34: 前幾名合計比例 | V34: =X34/N18 -> 0.23125 | W34: 前幾名合計金額 | X34: =SUM(X29:X33) -> 277.5
B35: 2
B36: 3 | M36: 半成品超用 | N36: 排名 | O36: 商品名 | R36: 半成品名 | U36: 單價 | V36: 報廢率 | W36: 數量 | X36: 金額 | Y36: 前月比 | Z36: 主要原因&對策
B37: 4 | M37: 作業原因 | N37: 1 | O37: 特製醬汁炙燒牛五花便當 | R37: 牛五花醬汁 | U37: 25 | V37: 0.25 | W37: 10 | X37: =W37*U37 -> 250 | Y37: 150 | Z37: 難度有差異。調理指導。
B38: 5 | N38: 2 | X38: =W38*U38 -> 0
B39: ▼1 | C39: 大口飯糰燒肉美奶滋 | F39: 7 | G39: 2200 | H39: 314.29 | I39: -15 | J39: 因摺疊增員。實施教育訓練。 | N39: 3 | X39: =W39*U39 -> 0
B40: ▼2 | N40: 4 | X40: =W40*U40 -> 0
B41: ▼3 | N41: 5 | X41: =W41*U41 -> 0
B42: ▼4 | U42: 前幾名合計比例 | V42: =X42/N19 -> 0.055555556 | W42: 前幾名合計金額 | X42: =SUM(X37:X41) -> 250
...

Sheet 生產管理報表(月)
A1: 生產管理報表
A3: 月別 | B3: 10 | C3: 工廠 | D3: 晉欣廠
A4: （１）收支狀況 | E4: ※單位：千元 | G4: （２）ＫＰＩ達成進度
A5: 項目 | B5: 當月 | C5: 前月 | D5: 差異 | E5: 累計 | G5: 項目 | H5: KPI | I5: 當月 | J5: 前月 | K5: 累計 | L5: ※補充
A6: 業績金額 | B6: ='（１）收支狀況'!H10/1000 -> 173020.84 | C6: 224463.49 | D6: =B6-C6 -> -51442.651 | E6: =B6 -> 173020.84 | G6: 人時性(個/月均) | H6: 266 | I6: ='（２）ＫＰＩ達成進度'!H6 -> 0 | J6: 330.21458 | K6: =I6 -> 0 | L6: 個／MH
A7: 訂單數量 | B7: ='（１）收支狀況'!K10 -> 5357363 | C7: 6964636 | D7: =B7-C7 -> -1607273 | E7: =B7 -> 5357363 | G7: 人時達成率(%/月均) | H7: 0.8 | I7: ='（２）ＫＰＩ達成進度'!K6 -> 0 | J7: 0.90222562 | K7: =I7 -> 0 | L7: 達成率
A8: 材料費 | B8: ='（１）收支狀況'!N10/1000 -> 117386.46 | C8: 150244.29 | D8: =B8-C8 -> -32857.832 | E8: =B8 -> 117386.46 | G8: 半成品-報廢(%) | H8: 0.0025 | I8: ='（２）ＫＰＩ達成進度'!N6 -> 0 | J8: 0.0024646257 | K8: =I8 -> 0 | L8: 報廢率
A9: 材料費率 | B9: ='（１）收支狀況'!Q10 -> 0.67845274 | C9: 0.66934847 | D9: =B9-C9 -> 0.0091042667 | E9: =B9 -> 0.67845274 | G9: 半成品-超用(%) | H9: 0.0026 | I9: ='（２）ＫＰＩ達成進度'!Q6 -> 0 | J9: 0.0023405371 | K9: =I9 -> 0 | L9: 超用率
A10: 勞務成本 | B10: ='（１）收支狀況'!T10/1000 -> 25696.432 | C10: 32105.787 | D10: =B10-C10 -> -6409.3546 | E10: =B10 -> 25696.432 | G10: 固定產線-導入率(%) | H10: 0.8 | I10: ='（２）ＫＰＩ達成進度'!T6 -> 0 | J10: 0.91666667 | K10: =I10 -> 0 | L10: 導入率
A11: 勞務費率 | B11: ='（１）收支狀況'!W10 -> 0.1485164 | C11: 0.14303345 | D11: =B11-C11 -> 0.0054829534 | E11: =B11 -> 0.1485164 | G11: 教育訓練-實施率(%) | H11: 1 | I11: ='（２）ＫＰＩ達成進度'!W6 -> 0 | J11: 0.84941935 | K11: =I11 -> 0 | L11: 實施率
A13: （３）業績構成比 | G13: （４）訂單數量構成比
B14: 當月 | C14: 比例 | D14: 前月 | E14: 差異 | H14: 當月 | I14: 比例 | J14: 前月 | K14: 差異
A15: 18℃-飯A15:A23糰(061,063) | B15: ='（３）業績構成比'!M46/1000 -> 31318.013 | C15: =IFERROR(B15/$B$6,"") -> 0.18100717 | D15: 0.19061186 | E15: =IFERROR(C15-D15,"") -> -0.0096046845 | G15: 18℃-飯A15:A23糰(061,063) | H15: ='（４）訂單數量構成比'!M46 -> 1711239 | I15: =IFERROR(H15/$B$7,"") -> 0.31941815 | J15: 0.33067557 | K15: =IFERROR(I15-J15,"") -> -0.011257419
A16: 18℃-壽司手卷(071,072,075,076) | B16: ='（３）業績構成比'!S46/1000 -> 4751.7949 | C16: =IFERROR(B16/$B$6,"") -> 0.027463715 | D16: 0.042789234 | E16: =IFERROR(C16-D16,"") -> -0.015325519 | G16: 18℃-壽司手卷(071,072,075,076) | H16: ='（４）訂單數量構成比'!S47 -> 188373 | I16: =IFERROR(H16/$B$7,"") -> 0.035161515 | J16: 0.061681041 | K16: =IFERROR(I16-J16,"") -> -0.026519526
A17: 4℃-飯糰(065) | B17: ='（３）業績構成比'!U46/1000 -> 29593.653 | C17: =IFERROR(B17/$B$6,"") -> 0.17104098 | D17: 0.086938303 | E17: =IFERROR(C17-D17,"") -> 0.084102675 | G17: 4℃-飯糰(065) | H17: ='（４）訂單數量構成比'!U46 -> 917107 | I17: =IFERROR(H17/$B$7,"") -> 0.17118627 | J17: 0.082530228 | K17: =IFERROR(I17-J17,"") -> 0.088656044
A18: 4℃-壽司手卷(077) | B18: ='（３）業績構成比'!W46/1000 -> 748.77842 | C18: =IFERROR(B18/$B$6,"") -> 0.0043276777 | D18: 0.014659146 | E18: =IFERROR(C18-D18,"") -> -0.010331468 | G18: 4℃-壽司手卷(077) | H18: ='（４）訂單數量構成比'!W46 -> 27971 | I18: =IFERROR(H18/$B$7,"") -> 0.0052210388 | J18: 0.016773741 | K18: =IFERROR(I18-J18,"") -> -0.011552702
A19: 主食(091,092,093,094,095) | B19: ='（３）業績構成比'!AC46/1000 -> 46235.474 | C19: =IFERROR(B19/$B$6,"") -> 0.26722489 | D19: 0.24409178 | E19: =IFERROR(C19-D19,"") -> 0.023133113 | G19: 主食(091,092,093,094,095) | H19: ='（４）訂單數量構成比'!AC46 -> 1183494 | I19: =IFERROR(H19/$B$7,"") -> 0.2209098 | J19: 0.1967306 | K19: =IFERROR(I19-J19,"") -> 0.024179205
A20: 便當(083) | B20: ='（３）業績構成比'!AE46/1000 -> 22197.803 | C20: =IFERROR(B20/$B$6,"") -> 0.12829555 | D20: 0.13979724 | E20: =IFERROR(C20-D20,"") -> -0.01150169 | G20: 便當(083) | H20: ='（４）訂單數量構成比'!AE46 -> 396044 | I20: =IFERROR(H20/$B$7,"") -> 0.073925176 | J20: 0.079797709 | K20: =IFERROR(I20-J20,"") -> -0.005872534
A21: 熱食義麵(122,123,124,126) | B21: ='（３）業績構成比'!AG46/1000 -> 13894.003 | C21: =IFERROR(B21/$B$6,"") -> 0.080302484 | D21: 0.13619627 | E21: =IFERROR(C21-D21,"") -> -0.055893782 | G21: 熱食義麵(122,123,124,126) | H21: ='（４）訂單數量構成比'!AG46 -> 279297 | I21: =IFERROR(H21/$B$7,"") -> 0.052133298 | J21: 0.090009011 | K21: =IFERROR(I21-J21,"") -> -0.037875714
A22: 季節調理麵(111,112) | B22: ='（３）業績構成比'!AI46/1000 -> 10522.331 | C22: =IFERROR(B22/$B$6,"") -> 0.060815396 | D22: 0.068175374 | E22: =IFERROR(C22-D22,"") -> -0.0073599778 | G22: 季節調理麵(111,112) | H22: ='（４）訂單數量構成比'!AI46 -> 284245 | I22: =IFERROR(H22/$B$7,"") -> 0.053056886 | J22: 0.05972114 | K22: =IFERROR(I22-J22,"") -> -0.0066642534
A23: 微波小吃(153,154,155) | B23: ='（３）業績構成比'!AK46/1000 -> 10617.5 | C23: =IFERROR(B23/$B$6,"") -> 0.061365444 | D23: 0.076740802 | E23: =IFERROR(C23-D23,"") -> -0.015375359 | G23: 微波小吃(153,154,155) | H23: ='（４）訂單數量構成比'!AK46 -> 369593 | I23: =IFERROR(H23/$B$7,"") -> 0.068987858 | J23: 0.082080959 | K23: =IFERROR(I23-J23,"") -> -0.0130931
C24: =SUM(C15:C23) -> 0.98184331 | D24: =SUM(D15:D23) -> 1 | I24: =SUM(I15:I23) -> 1 | J24: =SUM(J15:J23) -> 1
A26: （５）品群別人時生產性
A27: 品群 | B27: 當月 | C27: 前月 | D27: 差異 | E27: 累計 | M27: 8月 | N27: 9月 | O27: 10月 | P27: 11月 | Q27: 12月
A28: 18℃-飯A15:A23糰(061,063) | B28: ='（５-1）品群別人時生產性（18℃-飯糰）'!$C$1 -> 793.62477 | C28: 756.20247 | D28: =B28-C28 -> 37.4223 | E28: =R28 -> 755.57615 | M28: 717.52753 | N28: =B28 -> 793.62477 | R28: =AVERAGE(M28:Q28) -> 755.57615
A29: 18℃-壽司手卷(071,072,075,076) | B29: ='（５-2）品群別人時生產性（18-壽司手卷)'!$C$1 -> 166.67639 | C29: 198.82982 | D29: =B29-C29 -> -32.153432 | E29: =R29 -> 182.15455 | M29: 197.63272 | N29: =B29 -> 166.67639 | R29: =AVERAGE(M29:Q29) -> 182.15455
A30: 4℃-飯糰(065) | B30: ='（５-3）品群別人時生產性（4℃-飯糰)'!$C$1 -> 255.61005 | C30: 253.36933 | D30: =B30-C30 -> 2.2407211 | E30: =R30 -> 248.03431 | M30: 240.45857 | N30: =B30 -> 255.61005 | R30: =AVERAGE(M30:Q30) -> 248.03431
A31: 4℃-壽司手卷(077) | B31: ='（５-4）品群別人時生產性（4℃-壽司手卷)'!$C$1 -> 116.15148 | C31: 112.99131 | D31: =B31-C31 -> 3.1601649 | E31: =R31 -> 111.5083 | M31: 106.86512 | N31: =B31 -> 116.15148 | R31: =AVERAGE(M31:Q31) -> 111.5083
A32: 主食(091,092,093,094,095) | B32: ='（５-5）品群別人時生產性(主食) '!$C$1 -> 83.347323 | C32: 85.495684 | D32: =B32-C32 -> -2.1483619 | E32: =R32 -> 86.328875 | M32: 89.310428 | N32: =B32 -> 83.347323 | R32: =AVERAGE(M32:Q32) -> 86.328875
A33: 便當(083) | B33: ='（５-6）品群別人時生產性(便當)'!$C$1 -> 68.578757 | C33: 66.943614 | D33: =B33-C33 -> 1.6351432 | E33: =R33 -> 67.12575 | M33: 65.672742 | N33: =B33 -> 68.578757 | R33: =AVERAGE(M33:Q33) -> 67.12575
A34: 熱食義麵(122,123,124,126) | B34: ='（５-7）品群別人時生產性(熱食義麵) '!$C$1 -> 69.15366 | C34: 80.555861 | D34: =B34-C34 -> -11.402201 | E34: =R34 -> 72.316115 | M34: 75.478569 | N34: =B34 -> 69.15366 | R34: =AVERAGE(M34:Q34) -> 72.316115
A35: 季節調理麵(111,112) | B35: ='（５-8）品群別人時生產性(季節調理麵) '!$C$1 -> 122.96404 | C35: 121.13263 | D35: =B35-C35 -> 1.8314176 | E35: =R35 -> 118.73481 | M35: 114.50557 | N35: =B35 -> 122.96404 | R35: =AVERAGE(M35:Q35) -> 118.73481
A36: 微波小吃(153,154,155) | B36: ='（５-9）品群別人時生產性(微波小吃)'!$C$1 -> 119.54497 | C36: 115.36623 | D36: =B36-C36 -> 4.1787421 | E36: =R36 -> 109.59665 | M36: 99.648342 | N36: =B36 -> 119.54497 | R36: =AVERAGE(M36:Q36) -> 109.59665

Sheet 生產管理報表(週) 
A1: 生產管理報表
A3: 月別 | B3: 1 | C3: 週別 | D3: W4 | E3: 工廠 | F3: 晉欣廠
A4: （１）收支狀況 | E4: ※單位：千元 | G4: （２）ＫＰＩ達成進度
A5: 項目 | B5: 當週 | C5: 前週 | D5: 差異 | E5: 累計 | G5: 項目 | H5: KPI | I5: 當週 | J5: 前週 | K5: 累計 | L5: ※補充
A6: 業績金額 | B6: ='（１）收支狀況'!G24/1000 -> 46317.667 | C6: 45268.529 | D6: =B6-C6 -> 1049.138 | E6: ='（１）收支狀況'!H10/1000 -> 173020.84 | G6: 人時性(個/月均) | H6: 366 | I6: ='（２）ＫＰＩ達成進度'!G24 -> 319.62808 | J6: 324.31202 | K6: ='（２）ＫＰＩ達成進度'!H10 -> 325.64656 | L6: 個／MH
A7: 訂單數量 | B7: ='（１）收支狀況'!J24 -> 1417743 | C7: 1418907 | D7: =B7-C7 -> -1164 | E7: ='（１）收支狀況'!K10 -> 5357363 | G7: 人時達成率(%/月均) | H7: 0.8 | I7: ='（２）ＫＰＩ達成進度'!J24 -> 0.87330078 | J7: 0.8860984 | K7: ='（２）ＫＰＩ達成進度'!K10 -> 0.74623749 | L7: 達成率
A8: 材料費 | B8: ='（１）收支狀況'!M24/1000 -> 31369.885 | C8: 30710.089 | D8: =B8-C8 -> 659.796 | E8: ='（１）收支狀況'!N10/1000 -> 117386.46 | G8: 半成品-報廢(%) | H8: 0.0025 | I8: ='（２）ＫＰＩ達成進度'!M24 -> 0.0024570681 | J8: 0.0024593138 | K8: ='（２）ＫＰＩ達成進度'!N10 -> 0.0024542705 | L8: 報廢率
A9: 材料費率 | B9: ='（１）收支狀況'!P24 -> 0.67788001 | C9: 0.67914908 | D9: =B9-C9 -> -0.0012690656 | E9: ='（１）收支狀況'!Q10 -> 0.67845274 | G9: 半成品-超用(%) | H9: 0.0026 | I9: ='（２）ＫＰＩ達成進度'!P24 -> 0.0021485655 | J9: 0.0022624161 | K9: ='（２）ＫＰＩ達成進度'!Q10 -> 0.002228393 | L9: 超用率
A10: 勞務成本 | B10: ='（１）收支狀況'!S24/1000 -> 7028.2606 | C10: =6751568.6139492/1000 -> 6751.5686 | D10: =B10-C10 -> 276.69199 | E10: ='（１）收支狀況'!T10/1000 -> 25696.432 | G10: 固定產線-導入率(%) | H10: 0.8 | I10: 0.917 | J10: 0.917 | K10: 0.917 | L10: 導入率
A11: 勞務費率 | B11: ='（１）收支狀況'!V24 -> 0.15259304 | C11: 0.14974822 | D11: =B11-C11 -> 0.0028448212 | E11: ='（１）收支狀況'!W10 -> 0.1485164 | G11: 教育訓練-實施率(%) | H11: 1 | I11: ='（２）ＫＰＩ達成進度'!V24 -> 0.062142857 | J11: 0.040428571 | K11: ='（２）ＫＰＩ達成進度'!W10 -> 0.034730769 | L11: 實施率
A13: （３）業績構成比 | G13: （４）訂單數量構成比
B14: 當週 | C14: 比例 | D14: 前週 | E14: 差異 | H14: 當週 | I14: 比例 | J14: 前週 | K14: 差異
A15: 18℃-飯糰(061,063) | B15: =SUM('（３）業績構成比'!I26:I32,'（３）業績構成比'!K26:K32)/1000 -> 8923.3191 | C15: =IFERROR(B15/$B$6,"") -> 0.19265476 | D15: 0.19395127 | E15: =IFERROR(C15-D15,"") -> -0.0012965038 | G15: 18℃-飯糰(061,063) | H15: =SUM(,'（４）訂單數量構成比'!I26:I32,'（４）訂單數量構成比'!K26:K32) -> 463176 | I15: =IFERROR(H15/$B$7,"") -> 0.32669955 | J15: 0.32623844 | K15: =IFERROR(I15-J15,"") -> 0.00046111428
A16: 18℃-壽司手卷(071,072,075,076) | B16: =SUM('（３）業績構成比'!O26:O32,'（３）業績構成比'!Q26:Q32)/1000 -> 1239.499 | C16: =IFERROR(B16/$B$6,"") -> 0.026760825 | D16: 0.02825388 | E16: =IFERROR(C16-D16,"") -> -0.0014930551 | G16: 18℃-壽司手卷(071,072,075,076) | H16: =SUM('（４）訂單數量構成比'!O26:O32,'（４）訂單數量構成比'!Q26:Q32) -> 47156 | I16: =IFERROR(H16/$B$7,"") -> 0.033261317 | J16: 0.033990952 | K16: =IFERROR(I16-J16,"") -> -0.00072963473
A17: 4℃-飯糰(065) | B17: =SUM('（３）業績構成比'!U26:U32)/1000 -> 7536.0154 | C17: =IFERROR(B17/$B$6,"") -> 0.16270283 | D17: 0.17587603 | E17: =IFERROR(C17-D17,"") -> -0.013173206 | G17: 4℃-飯糰(065) | H17: =SUM('（４）訂單數量構成比'!U26:U32) -> 231787 | I17: =IFERROR(H17/$B$7,"") -> 0.16349014 | J17: 0.17294509 | K17: =IFERROR(I17-J17,"") -> -0.0094549519
A18: 4℃-壽司手卷(077) | B18: =SUM('（３）業績構成比'!W26:W32)/1000 -> 214.15439 | C18: =IFERROR(B18/$B$6,"") -> 0.0046236005 | D18: 0.0057024601 | E18: =IFERROR(C18-D18,"") -> -0.0010788596 | G18: 4℃-壽司手卷(077) | H18: =SUM('（４）訂單數量構成比'!W26:W32) -> 7949 | I18: =IFERROR(H18/$B$7,"") -> 0.005606799 | J18: 0.0067446281 | K18: =IFERROR(I18-J18,"") -> -0.0011378291
A19: 主食(091,092,093,094,095) | B19: =SUM('（３）業績構成比'!Y26:Y32,'（３）業績構成比'!AA26:AA32)/1000 -> 12719.639 | C19: =IFERROR(B19/$B$6,"") -> 0.27461744 | D19: 0.27408784 | E19: =IFERROR(C19-D19,"") -> 0.00052960689 | G19: 主食(091,092,093,094,095) | H19: =SUM('（４）訂單數量構成比'!Y26:Y32,'（４）訂單數量構成比'!AA26:AA32) -> 311499 | I19: =IFERROR(H19/$B$7,"") -> 0.21971472 | J19: 0.21722002 | K19: =IFERROR(I19-J19,"") -> 0.0024947004
A20: 便當(083) | B20: =SUM('（３）業績構成比'!AE26:AE32)/1000 -> 6199.0593 | C20: =IFERROR(B20/$B$6,"") -> 0.1338379 | D20: 0.13017356 | E20: =IFERROR(C20-D20,"") -> 0.0036643395 | G20: 便當(083) | H20: =SUM('（４）訂單數量構成比'!AE26:AE32) -> 108834 | I20: =IFERROR(H20/$B$7,"") -> 0.076765676 | J20: 0.073864601 | K20: =IFERROR(I20-J20,"") -> 0.0029010747
A21: 熱食義麵(122,123,124,126) | B21: =SUM('（３）業績構成比'!AG26:AG32)/1000 -> 4462.9953 | C21: =IFERROR(B21/$B$6,"") -> 0.09635622 | D21: 0.061910251 | E21: =IFERROR(C21-D21,"") -> 0.034445969 | G21: 熱食義麵(122,123,124,126) | H21: =SUM('（４）訂單數量構成比'!AG26:AG32) -> 88212 | I21: =IFERROR(H21/$B$7,"") -> 0.062220022 | J21: 0.040586169 | K21: =IFERROR(I21-J21,"") -> 0.021633852
A22: 季節調理麵(111,112) | B22: =SUM('（３）業績構成比'!AI26:AI32)/1000 -> 2622.3642 | C22: =IFERROR(B22/$B$6,"") -> 0.056616933 | D22: 0.06834338 | E22: =IFERROR(C22-D22,"") -> -0.011726447 | G22: 季節調理麵(111,112) | H22: =SUM('（４）訂單數量構成比'!AI26:AI32) -> 70828 | I22: =IFERROR(H22/$B$7,"") -> 0.049958279 | J22: 0.058838247 | K22: =IFERROR(I22-J22,"") -> -0.0088799679
A23: 微波小吃(153,154,155) | B23: =SUM('（３）業績構成比'!AK26:AK32)/1000 -> 2400.621 | C23: =IFERROR(B23/$B$6,"") -> 0.051829488 | D23: 0.061701333 | E23: =IFERROR(C23-D23,"") -> -0.0098718449 | G23: 微波小吃(153,154,155) | H23: =SUM('（４）訂單數量構成比'!AK26:AK32) -> 88302 | I23: =IFERROR(H23/$B$7,"") -> 0.062283503 | J23: 0.069571861 | K23: =IFERROR(I23-J23,"") -> -0.0072883579
C24: =SUM(C15:C23) -> 1 | D24: =SUM(D15:D23) -> 1 | I24: =SUM(I15:I23) -> 1 | J24: =SUM(J15:J23) -> 1
A26: （５）品群別人時生產性
A27: 品群 | B27: 當週 | C27: 前週 | D27: 差異 | E27: 累計
A28: 18℃-飯糰(061,063) | B28: ='（５-1）品群別人時生產性（18℃-飯糰）'!L112 -> 781.25061 | C28: 798.99546 | D28: =B28-C28 -> -17.744847 | E28: ='（５-1）品群別人時生產性（18℃-飯糰）'!C1 -> 793.62477
A29: 18℃-壽司手卷(071,072,075,076) | B29: ='（５-2）品群別人時生產性（18-壽司手卷)'!L67 -> 163.617 | C29: 170.64701 | D29: =B29-C29 -> -7.0300049 | E29: ='（５-2）品群別人時生產性（18-壽司手卷)'!C1 -> 166.67639
A30: 4℃-飯糰(065) | B30: ='（５-3）品群別人時生產性（4℃-飯糰)'!L67 -> 261.47141 | C30: 253.3711 | D30: =B30-C30 -> 8.1003126 | E30: ='（５-3）品群別人時生產性（4℃-飯糰)'!C1 -> 255.61005
A31: 4℃-壽司手卷(077) | B31: ='（５-4）品群別人時生產性（4℃-壽司手卷)'!L67 -> 115.15926 | C31: 116.5385 | D31: =B31-C31 -> -1.3792482 | E31: ='（５-4）品群別人時生產性（4℃-壽司手卷)'!C1 -> 116.15148
A32: 主食(091,092,093,094,095) | B32: ='（５-5）品群別人時生產性(主食) '!L112 -> 83.230484 | C32: 81.431949 | D32: =B32-C32 -> 1.7985349 | E32: ='（５-5）品群別人時生產性(主食) '!C1 -> 83.347323
A33: 便當(083) | B33: ='（５-6）品群別人時生產性(便當)'!L67 -> 67.487137 | C33: 67.719465 | D33: =B33-C33 -> -0.23232824 | E33: ='（５-6）品群別人時生產性(便當)'!C1 -> 68.578757
A34: 熱食義麵(122,123,124,126) | B34: ='（５-7）品群別人時生產性(熱食義麵) '!L67 -> 76.533 | C34: 64.587995 | D34: =B34-C34 -> 11.945005 | E34: ='（５-7）品群別人時生產性(熱食義麵) '!C1 -> 69.15366
A35: 季節調理麵(111,112) | B35: ='（５-8）品群別人時生產性(季節調理麵) '!L67 -> 124.61853 | C35: 122.65859 | D35: =B35-C35 -> 1.9599491 | E35: ='（５-8）品群別人時生產性(季節調理麵) '!C1 -> 122.96404
A36: 微波小吃(153,154,155) | B36: ='（５-9）品群別人時生產性(微波小吃)'!L67 -> 127.09568 | C36: 110.53389 | D36: =B36-C36 -> 16.561785 | E36: ='（５-9）品群別人時生產性(微波小吃)'!C1 -> 119.54497

Sheet （１）收支狀況
B2: （１）收支狀況
C3: 月份 | D3: 日期 | F3: 營業額(元) | I3: 訂單數量(個) | L3: 材料費(元) | O3: 材料費率（材料費／營業額） | R3: 勞務成本（全廠人事成本） | U3: 勞務費率（勞務成本／營業額）
F4: 日 | G4: 週累積 | H4: 月累積 | I4: 日 | J4: 週累積 | K4: 月累積 | L4: 日 | M4: 週累積 | N4: 月累積 | O4: 日 | P4: 週累積 | Q4: 月平均 | R4: 日 | S4: 週累積 | T4: 月累積 | U4: 日 | V4: 週累積 | W4: 月平均
D5: =D4+1 -> 1 | E5: 四 | F5: 6681403 | I5: 205236 | L5: 4898484 | O5: =L5/F5 -> 0.733152 | P5: =AVERAGE(O5:O9) -> 0.68053029 | R5: 1023941.3 | V5: =AVERAGE(U5:U9) -> 0.14782978
D6: =D5+1 -> 2 | E6: 五 | F6: 5997913 | G6: =SUM(F5:F9) -> 33573872 | I6: 186163 | J6: =SUM(I5:I9) -> 1028457 | L6: 4157041 | M6: =SUM(L5:L9) -> 22826638 | O6: =L6/F6 -> 0.69308124 | R6: 974083.84 | S6: =SUM(R5:R9) -> 4980410.3 | U6: =R6/F6 -> 0.1624038
D7: =D6+1 -> 3 | E7: 六 | F7: 6555328 | I7: 199344 | L7: 4222144 | O7: =L7/F7 -> 0.64407822 | R7: 986619.68 | U7: =R7/F7 -> 0.15050653
D8: =D7+1 -> 4 | E8: 日 | F8: 7070659 | I8: 216721 | L8: 4831528 | O8: =L8/F8 -> 0.68332075 | R8: 995637.68 | U8: =R8/F8 -> 0.14081257
D9: =D8+1 -> 5 | E9: 一 | F9: 7268569 | I9: 220993 | L9: 4717441 | O9: =L9/F9 -> 0.64901922 | R9: 1000127.8 | U9: =R9/F9 -> 0.13759624
D10: =D9+1 -> 6 | E10: 二 | F10: 7452237 | G10: =SUM(F10:F16) -> 47860768 | H10: =SUM(F5:F35) -> 173020836 | I10: 233027 | J10: =SUM(I10:I16) -> 1492256 | K10: =SUM(I5:I35) -> 5357363 | L10: 4938616 | M10: =SUM(L10:L16) -> 32397606 | N10: =SUM(L5:L35) -> 117386460 | O10: =L10/F10 -> 0.66270249 | P10: =AVERAGE(O10:O16) -> 0.67750494 | Q10: =N10/H10 -> 0.67845274 | R10: 1016782 | S10: =SUM(R10:R16) -> 6936192.6 | T10: =SUM(R5:R35) -> 25696432 | U10: =R10/F10 -> 0.13643983 | V10: =AVERAGE(U10:U16) -> 0.1455143 | W10: =T10/H10 -> 0.1485164
D11: =D10+1 -> 7 | E11: 三 | F11: 6995772 | I11: 220329 | L11: 4783118 | O11: =L11/F11 -> 0.68371554 | R11: 999910.52 | U11: =R11/F11 -> 0.14293069
D12: =D11+1 -> 8 | E12: 四 | F12: 6658240 | I12: 207527 | L12: 4678074 | O12: =L12/F12 -> 0.70259919 | R12: 995536.68 | U12: =R12/F12 -> 0.14951949
D13: =D12+1 -> 9 | E13: 五 | F13: 6093782 | I13: 189878 | L13: 3986569 | O13: =L13/F13 -> 0.65420276 | R13: 974790.12 | U13: =R13/F13 -> 0.15996472
D14: =D13+1 -> 10 | E14: 六 | F14: 6273190 | I14: 195163 | L14: 4487904 | O14: =L14/F14 -> 0.71541018 | R14: 963818.1 | U14: =R14/F14 -> 0.15364083
D15: =D14+1 -> 11 | E15: 日 | F15: 7385036 | I15: 229137 | L15: 4878046 | O15: =L15/F15 -> 0.66053111 | R15: 1002559.9 | U15: =R15/F15 -> 0.13575559
D16: =D15+1 -> 12 | E16: 一 | F16: 7002511 | I16: 217195 | L16: 4645279 | O16: =L16/F16 -> 0.66337332 | R16: 982795.26 | U16: =R16/F16 -> 0.14034898
D17: =D16+1 -> 13 | E17: 二 | F17: 6868111 | G17: =SUM(F17:F23) -> 45268529 | I17: 214686 | J17: =SUM(I17:I23) -> 1418907 | L17: 4741632 | M17: =SUM(L17:L23) -> 30792331 | O17: =L17/F17 -> 0.69038372 | P17: =AVERAGE(O17:O23) -> 0.68083524 | R17: 972275.3 | S17: =SUM(R17:R23) -> 6751568.6 | U17: =R17/F17 -> 0.14156371 | V17: =AVERAGE(U17:U23) -> 0.14974822
D18: =D17+1 -> 14 | E18: 三 | F18: 6627112 | I18: 207749 | L18: 4500047 | O18: =L18/F18 -> 0.67903591 | R18: 982210.53 | U18: =R18/F18 -> 0.14821094
D19: =D18+1 -> 15 | E19: 四 | F19: 6144184 | I19: 194623 | L19: 4559519 | O19: =L19/F19 -> 0.74208699 | R19: 975934.4 | U19: =R19/F19 -> 0.15883873
D20: =D19+1 -> 16 | E20: 五 | F20: 5795971 | I20: 183688 | L20: 3930912 | O20: =L20/F20 -> 0.67821457 | R20: 960812.3 | U20: =R20/F20 -> 0.16577245
D21: =D20+1 -> 17 | E21: 六 | F21: 6092113 | I21: 191838 | L21: 4040278 | O21: =L21/F21 -> 0.66319814 | R21: 941219.54 | U21: =R21/F21 -> 0.15449804
D22: =D21+1 -> 18 | E22: 日 | F22: 6822501 | I22: 212538 | L22: 4517752 | O22: =L22/F22 -> 0.66218415 | R22: 966307.41 | U22: =R22/F22 -> 0.14163536
D23: =D22+1 -> 19 | E23: 一 | F23: 6918537 | I23: 213785 | L23: 4502191 | O23: =L23/F23 -> 0.65074321 | R23: 952809.12 | U23: =R23/F23 -> 0.13771829
D24: =D23+1 -> 20 | E24: 二 | F24: 7713415 | G24: =SUM(F24:F30) -> 46317667 | I24: 228373 | J24: =SUM(I24:I30) -> 1417743 | L24: 5217118 | M24: =SUM(L24:L30) -> 31369885 | O24: =L24/F24 -> 0.67636942 | P24: =AVERAGE(O24:O30) -> 0.67788001 | R24: 1117488.3 | S24: =SUM(R24:R30) -> 7028260.6 | U24: =R24/F24 -> 0.14487595 | V24: =AVERAGE(U24:U30) -> 0.15259304
D25: =D24+1 -> 21 | E25: 三 | F25: 6863386 | I25: 211084 | L25: 4747084 | O25: =L25/F25 -> 0.69165336 | R25: 1098839.9 | U25: =R25/F25 -> 0.16010172
D26: =D25+1 -> 22 | E26: 四 | F26: 6394057 | I26: 197525 | L26: 4356271 | O26: =L26/F26 -> 0.68129999 | R26: 1045894.8 | U26: =R26/F26 -> 0.16357296
D27: =D26+1 -> 23 | E27: 五 | F27: 5574275 | I27: 174499 | L27: 3918701 | O27: =L27/F27 -> 0.70299743 | R27: 938389.9 | U27: =R27/F27 -> 0.16834295
D28: =D27+1 -> 24 | E28: 六 | F28: 5940745 | I28: 183312 | L28: 3957428 | O28: =L28/F28 -> 0.66615012 | R28: 935116.84 | U28: =R28/F28 -> 0.15740733
D29: =D28+1 -> 25 | E29: 日 | F29: 7104289 | I29: 215741 | L29: 4675574 | O29: =L29/F29 -> 0.65813398 | R29: 946557.22 | U29: =R29/F29 -> 0.13323743
D30: =D29+1 -> 26 | E30: 一 | F30: 6727500 | I30: 207209 | L30: 4497709 | O30: =L30/F30 -> 0.66855578 | R30: 945973.6 | U30: =R30/F30 -> 0.14061295
D31: =D30+1 -> 27 | E31: 二 | G31: =SUM(F31:F37) -> 0 | J31: =SUM(I31:I37) -> 0 | M31: =SUM(L31:L37) -> 0 | O31: =L31/F31 -> #DIV/0! | P31: =AVERAGE(O31:O37) -> #DIV/0! | S31: =SUM(R31:R37) -> 0 | U31: =R31/F31 -> #DIV/0! | V31: =AVERAGE(U31:U37) -> #DIV/0!
D32: =D31+1 -> 28 | E32: 三 | O32: =L32/F32 -> #DIV/0! | U32: =R32/F32 -> #DIV/0!
D33: =D32+1 -> 29 | E33: 四 | O33: =L33/F33 -> #DIV/0! | U33: =R33/F33 -> #DIV/0!
D34: =D33+1 -> 30 | E34: 五 | O34: =L34/F34 -> #DIV/0! | U34: =R34/F34 -> #DIV/0!
D35: =D34+1 -> 31 | E35: 六 | O35: =L35/F35 -> #DIV/0! | U35: =R35/F35 -> #DIV/0!
D36: =D35+1 -> 32 | E36: 日 | O36: =L36/F36 -> #DIV/0! | U36: =R36/F36 -> #DIV/0!
D37: =D36+1 -> 33 | E37: 一 | O37: =L37/F37 -> #DIV/0! | U37: =R37/F37 -> #DIV/0!
O38: =L38/F38 -> #DIV/0! | U38: =R38/F38 -> #DIV/0!
O39: =L39/F39 -> #DIV/0! | U39: =R39/F39 -> #DIV/0!
O40: =L40/F40 -> #DIV/0! | U40: =R40/F40 -> #DIV/0!
O41: =L41/F41 -> #DIV/0! | U41: =R41/F41 -> #DIV/0!

Sheet （２）ＫＰＩ達成進度
B1: KPI | C1: 366
B2: （２）ＫＰＩ達成進度
C3: 月份 | D3: 日期 | F3: 人時生產性(個/人) | I3: 人時生產性達成率(%) | L3: 半成品報廢(%) | O3: 半成品超用(%) | R3: 固定產線-導入率(固定產線數/總產線數) | U3: 教育訓練-實施率(進度/計畫)
F4: 日 | G4: 週平均 | H4: 月平均 | I4: 日 | J4: 週平均 | K4: 月平均 | L4: 日 | M4: 週平均 | N4: 月平均 | O4: 日 | P4: 週平均 | Q4: 月平均 | R4: 日 | S4: 週平均 | T4: 月平均 | U4: 日 | V4: 週平均 | W4: 月平均
D5: =D4+1 -> 1 | E5: 四 | F5: 319.61673 | G5: =AVERAGE(F5:F9) -> 327.58112 | I5: =F5/$C$1 -> 0.87326975 | J5: =AVERAGE(I5:I9) -> 0.89503037 | L5: 0.002477773 | M5: =AVERAGE(L5:L9) -> 0.0024553281 | O5: 0.0021782001 | P5: =AVERAGE(O5:O9) -> 0.0022669514 | R5: 0.91666667 | S5: =AVERAGE(R5:R9) -> 0.91666667 | U5: 0 | V5: =AVERAGE(U5:U9) -> 0.007
D6: =D5+1 -> 2 | E6: 五 | F6: 326.96087 | I6: =F6/$C$1 -> 0.89333571 | L6: 0.0024570213 | O6: 0.0026228821 | R6: 0.91666667 | U6: 0
D7: =D6+1 -> 3 | E7: 六 | F7: 329.7149 | I7: =F7/$C$1 -> 0.90086037 | L7: 0.0024390847 | O7: 0.0024054394 | R7: 0.91666667 | U7: 0.01
D8: =D7+1 -> 4 | E8: 日 | F8: 330.80654 | I8: =F8/$C$1 -> 0.90384301 | L8: 0.0024610153 | O8: 0.0021868876 | R8: 0.91666667 | U8: 0.01
D9: =D8+1 -> 5 | E9: 一 | F9: 330.80654 | I9: =F9/$C$1 -> 0.90384301 | L9: 0.0024417461 | O9: 0.0019413477 | R9: 0.91666667 | U9: 0.015
D10: =D9+1 -> 6 | E10: 二 | F10: 329.83195 | G10: =AVERAGE(F10:F16) -> 331.61776 | H10: =AVERAGE(F5:F35) -> 325.64656 | I10: =F10/$C$1 -> 0.90118018 | J10: =AVERAGE(I10:I16) -> 0.90605945 | K10: =AVERAGE(I5:I35) -> 0.74623749 | L10: 0.0024500026 | M10: =AVERAGE(L10:L16) -> 0.0024456743 | N10: =AVERAGE(L5:L35) -> 0.0024542705 | O10: 0.0019844694 | P10: =AVERAGE(O10:O16) -> 0.0022466556 | Q10: =AVERAGE(O5:O35) -> 0.002228393 | R10: 0.91666667 | S10: =AVERAGE(R10:R16) -> 0.91666667 | T10: =AVERAGE(R5:R35) -> 0.91666667 | U10: 0.013 | V10: =AVERAGE(U10:U16) -> 0.021428571 | W10: =AVERAGE(U5:U35) -> 0.034730769
D11: =D10+1 -> 7 | E11: 三 | F11: 334.61832 | I11: =F11/$C$1 -> 0.9142577 | L11: 0.0024494795 | O11: 0.0022355923 | R11: 0.91666667 | U11: 0.016
D12: =D11+1 -> 8 | E12: 四 | F12: 323.91023 | I12: =F12/$C$1 -> 0.88500064 | L12: 0.0024308226 | O12: 0.0022395441 | R12: 0.91666667 | U12: 0.019
D13: =D12+1 -> 9 | E13: 五 | F13: 333.65176 | I13: =F13/$C$1 -> 0.91161684 | L13: 0.0024822023 | O13: 0.0026237839 | R13: 0.91666667 | U13: 0.021
D14: =D13+1 -> 10 | E14: 六 | F14: 331.59028 | I14: =F14/$C$1 -> 0.90598437 | L14: 0.0024402258 | O14: 0.0024838361 | R14: 0.91666667 | U14: 0.024
D15: =D14+1 -> 11 | E15: 日 | F15: 335.93784 | I15: =F15/$C$1 -> 0.91786294 | L15: 0.0024308615 | O15: 0.0019629802 | R15: 0.91666667 | U15: 0.027
D16: =D15+1 -> 12 | E16: 一 | F16: 331.78394 | I16: =F16/$C$1 -> 0.90651349 | L16: 0.0024361261 | O16: 0.0021963837 | R16: 0.91666667 | U16: 0.03
D17: =D16+1 -> 13 | E17: 二 | F17: 321.79723 | G17: =AVERAGE(F17:F23) -> 324.31202 | I17: =F17/$C$1 -> 0.87922741 | J17: =AVERAGE(I17:I23) -> 0.8860984 | L17: 0.002449873 | M17: =AVERAGE(L17:L23) -> 0.0024593138 | O17: 0.0021784538 | P17: =AVERAGE(O17:O23) -> 0.0022624161 | R17: 0.91666667 | S17: =AVERAGE(R17:R23) -> 0.91666667 | U17: 0.032 | V17: =AVERAGE(U17:U23) -> 0.040428571
D18: =D17+1 -> 14 | E18: 三 | F18: 328.96883 | I18: =F18/$C$1 -> 0.89882194 | L18: 0.002470005 | O18: 0.0021811143 | R18: 0.91666667 | U18: 0.035
D19: =D18+1 -> 15 | E19: 四 | F19: 329.34009 | I19: =F19/$C$1 -> 0.89983631 | L19: 0.0024335209 | O19: 0.0025181629 | R19: 0.91666667 | U19: 0.038
D20: =D19+1 -> 16 | E20: 五 | F20: 317.64178 | I20: =F20/$C$1 -> 0.86787373 | L20: 0.0024913858 | O20: 0.0025781543 | R20: 0.91666667 | U20: 0.041
D21: =D20+1 -> 17 | E21: 六 | F21: 324.23213 | I21: =F21/$C$1 -> 0.88588014 | L21: 0.0024699148 | O21: 0.0022929677 | R21: 0.91666667 | U21: 0.043
D22: =D21+1 -> 18 | E22: 日 | F22: 324.76885 | I22: =F22/$C$1 -> 0.88734658 | L22: 0.0024602415 | O22: 0.0019762607 | R22: 0.91666667 | U22: 0.046
D23: =D22+1 -> 19 | E23: 一 | F23: 323.43519 | I23: =F23/$C$1 -> 0.88370271 | L23: 0.0024402558 | O23: 0.0021117988 | R23: 0.91666667 | U23: 0.048
D24: =D23+1 -> 20 | E24: 二 | F24: 321.76396 | G24: =AVERAGE(F24:F30) -> 319.62808 | I24: =F24/$C$1 -> 0.87913651 | J24: =AVERAGE(I24:I30) -> 0.87330078 | L24: 0.0024298564 | M24: =AVERAGE(L24:L30) -> 0.0024570681 | O24: 0.0017515724 | P24: =AVERAGE(O24:O30) -> 0.0021485655 | R24: 0.91666667 | S24: =AVERAGE(R24:R30) -> 0.91666667 | U24: 0.052 | V24: =AVERAGE(U24:U30) -> 0.062142857
D25: =D24+1 -> 21 | E25: 三 | F25: 320.65282 | I25: =F25/$C$1 -> 0.8761006 | L25: 0.0024843423 | O25: 0.0019093946 | R25: 0.91666667 | U25: 0.058
D26: =D25+1 -> 22 | E26: 四 | F26: 313.71266 | I26: =F26/$C$1 -> 0.85713842 | L26: 0.0024715138 | O26: 0.0022602211 | R26: 0.91666667 | U26: 0.06
D27: =D26+1 -> 23 | E27: 五 | F27: 317.74451 | I27: =F27/$C$1 -> 0.86815441 | L27: 0.0024699176 | O27: 0.0025697547 | R27: 0.91666667 | U27: 0.063
D28: =D27+1 -> 24 | E28: 六 | F28: 322.27305 | I28: =F28/$C$1 -> 0.88052747 | L28: 0.0024337015 | O28: 0.0025035797 | R28: 0.91666667 | U28: 0.066
D29: =D28+1 -> 25 | E29: 日 | F29: 323.07437 | I29: =F29/$C$1 -> 0.88271685 | L29: 0.002449647 | O29: 0.0018934425 | R29: 0.91666667 | U29: 0.068
D30: =D29+1 -> 26 | E30: 一 | F30: 318.17521 | I30: =F30/$C$1 -> 0.86933118 | L30: 0.002460498 | O30: 0.0021519938 | R30: 0.91666667 | U30: 0.068
D31: =D30+1 -> 27 | E31: 二 | G31: =AVERAGE(F31:F37) -> #DIV/0! | I31: =F31/$C$1 -> 0 | J31: =AVERAGE(I31:I37) -> 0 | M31: =AVERAGE(L31:L37) -> #DIV/0! | P31: =AVERAGE(O31:O37) -> #DIV/0! | S31: =AVERAGE(R31:R37) -> #DIV/0! | V31: =AVERAGE(U31:U37) -> #DIV/0!
D32: =D31+1 -> 28 | E32: 三 | I32: =F32/$C$1 -> 0
D33: =D32+1 -> 29 | E33: 四 | I33: =F33/$C$1 -> 0
D34: =D33+1 -> 30 | E34: 五 | I34: =F34/$C$1 -> 0
D35: =D34+1 -> 31 | E35: 六 | I35: =F35/$C$1 -> 0
D36: =D35+1 -> 32 | E36: 日 | I36: =F36/$C$1 -> 0
D37: =D36+1 -> 33 | E37: 一 | I37: =F37/$C$1 -> 0
I38: =F38/$C$1 -> 0
I39: =F39/$C$1 -> 0
I40: =F40/$C$1 -> 0

Sheet （３）業績構成比
B2: （3）業績構成比
C3: 月份 | D3: 日期 | F3: 營業額 | I3: 品類業績
I4: 18℃-飯糰 | O4: 18℃-壽司手卷 | U4: 4℃-飯糰 | W4: 4℃-壽司手卷 | Y4: 主食 | AE4: 便當 | AG4: 熱食義麵 | AI4: 季節調理麵 | AK4: 微波小吃
F5: 日 | G5: 週累積 | H5: 月累積 | I5: 一配 | K5: 二配 | M5: 合計 | O5: 一配 | Q5: 二配 | S5: 合計 | U5: 一配 | W5: 一配 | Y5: 一配 | AA5: 二配 | AC5: 合計 | AE5: 一配 | AG5: 一配 | AI5: 一配 | AK5: 一配
I6: 業績(元) | J6: 比例(%) | K6: 業績(元) | L6: 比例(%) | M6: 業績(元) | N6: 比例(%) | O6: 業績(元) | P6: 比例(%) | Q6: 業績(元) | R6: 比例(%) | S6: 業績(元) | T6: 比例(%) | U6: 業績(元) | V6: 比例(%) | W6: 業績(元) | X6: 比例(%) | Y6: 業績(元) | Z6: 比例(%) | AA6: 業績(元) | AB6: 比例(%) | AC6: 業績(元) | AD6: 比例(%) | AE6: 業績(元) | AF6: 比例(%) | AG6: 業績(元) | AH6: 比例(%) | AI6: 業績(元) | AJ6: 比例(%) | AK6: 業績(元) | AL6: 比例(%)
D7: =D6+1 -> 1 | E7: 四 | F7: =SUM(M7,S7,U7,W7,AC7,AE7,AG7,AI7,AK7) -> 6681403 | I7: 491743.29 | J7: =I7/F7 -> 0.073598808 | K7: 679275.4 | L7: =K7/F7 -> 0.10166658 | M7: =SUM(I7+K7) -> 1171018.7 | N7: =M7/F7 -> 0.17526539 | O7: 158062.98 | P7: =O7/F7 -> 0.023657155 | Q7: 88205.26 | R7: =Q7/$F7 -> 0.013201607 | S7: =SUM(O7+Q7) -> 246268.24 | T7: =S7/F7 -> 0.036858762 | U7: 1122071.9 | V7: =U7/F7 -> 0.16793956 | W7: 0 | X7: =W7/F7 -> 0 | Y7: 504676.45 | Z7: =Y7/F7 -> 0.075534503 | AA7: 1219522.5 | AB7: =AA7/$F7 -> 0.18252491 | AC7: =SUM(Y7+AA7) -> 1724199 | AD7: =AC7/F7 -> 0.25805942 | AE7: 801116 | AF7: =AE7/F7 -> 0.11990236 | AG7: 592123.52 | AH7: =AG7/F7 -> 0.088622632 | AI7: 425616.46 | AJ7: =AI7/F7 -> 0.06370166 | AK7: 598989.22 | AL7: =AK7/F7 -> 0.089650216
D8: =D7+1 -> 2 | E8: 五 | F8: =SUM(M8,S8,U8,W8,AC8,AE8,AG8,AI8,AK8) -> 5997913 | G8: =SUM(F7:F11) -> 33573872 | I8: 473107.13 | J8: =I8/F8 -> 0.078878624 | K8: 660367.11 | L8: =K8/F8 -> 0.11009948 | M8: =SUM(I8+K8) -> 1133474.2 | N8: =M8/F8 -> 0.18897811 | O8: 128017.29 | P8: =O8/F8 -> 0.021343639 | Q8: 80333.771 | R8: =Q8/$F8 -> 0.013393621 | S8: =SUM(O8+Q8) -> 208351.06 | T8: =S8/F8 -> 0.034737259 | U8: 966143.64 | V8: =U8/F8 -> 0.16107997 | W8: 0 | X8: =W8/F8 -> 0 | Y8: 457286.78 | Z8: =Y8/F8 -> 0.076240983 | AA8: 1263312.8 | AB8: =AA8/$F8 -> 0.2106254 | AC8: =SUM(Y8+AA8) -> 1720599.6 | AD8: =AC8/F8 -> 0.28686639 | AE8: 666469.28 | AF8: =AE8/F8 -> 0.11111686 | AG8: 481311.29 | AH8: =AG8/F8 -> 0.080246461 | AI8: 331582.72 | AJ8: =AI8/F8 -> 0.055283016 | AK8: 489981.14 | AL8: =AK8/F8 -> 0.081691939
D9: =D8+1 -> 3 | E9: 六 | F9: =SUM(M9,S9,U9,W9,AC9,AE9,AG9,AI9,AK9) -> 6555328 | I9: 444610.65 | J9: =I9/F9 -> 0.067824317 | K9: 704497.64 | L9: =K9/F9 -> 0.10746947 | M9: =SUM(I9+K9) -> 1149108.3 | N9: =M9/F9 -> 0.17529379 | O9: 109084.49 | P9: =O9/F9 -> 0.016640585 | Q9: 71805.305 | R9: =Q9/$F9 -> 0.010953732 | S9: =SUM(O9+Q9) -> 180889.8 | T9: =S9/F9 -> 0.027594317 | U9: 1070612.7 | V9: =U9/F9 -> 0.16331948 | W9: 0 | X9: =W9/F9 -> 0 | Y9: 492092.62 | Z9: =Y9/F9 -> 0.075067582 | AA9: 1332263.5 | AB9: =AA9/$F9 -> 0.20323369 | AC9: =SUM(Y9+AA9) -> 1824356.1 | AD9: =AC9/F9 -> 0.27830127 | AE9: 793774.59 | AF9: =AE9/F9 -> 0.12108846 | AG9: 547389.77 | AH9: =AG9/F9 -> 0.083503033 | AI9: 455203.42 | AJ9: =AI9/F9 -> 0.069440221 | AK9: 533993.26 | AL9: =AK9/F9 -> 0.081459427
D10: =D9+1 -> 4 | E10: 日 | F10: =SUM(M10,S10,U10,W10,AC10,AE10,AG10,AI10,AK10) -> 7070659 | I10: 550250.59 | J10: =I10/F10 -> 0.077821685 | K10: 720092.82 | L10: =K10/F10 -> 0.10184239 | M10: =SUM(I10+K10) -> 1270343.4 | N10: =M10/F10 -> 0.17966408 | O10: 150632.39 | P10: =O10/F10 -> 0.021303868 | Q10: 79783.238 | R10: =Q10/$F10 -> 0.011283706 | S10: =SUM(O10+Q10) -> 230415.62 | T10: =S10/F10 -> 0.032587574 | U10: 1291141.8 | V10: =U10/F10 -> 0.18260558 | W10: 0 | X10: =W10/F10 -> 0 | Y10: 478059.16 | Z10: =Y10/F10 -> 0.067611683 | AA10: 1376471.9 | AB10: =AA10/$F10 -> 0.19467377 | AC10: =SUM(Y10+AA10) -> 1854531 | AD10: =AC10/F10 -> 0.26228546 | AE10: 925802.1 | AF10: =AE10/F10 -> 0.13093576 | AG10: 624845.16 | AH10: =AG10/F10 -> 0.088371559 | AI10: 451315.78 | AJ10: =AI10/F10 -> 0.06382938 | AK10: 422264.09 | AL10: =AK10/F10 -> 0.059720613
D11: =D10+1 -> 5 | E11: 一 | F11: =SUM(M11,S11,U11,W11,AC11,AE11,AG11,AI11,AK11) -> 7268569 | I11: 531376.28 | J11: =I11/F11 -> 0.073106038 | K11: 760067.13 | L11: =K11/F11 -> 0.10456902 | M11: =SUM(I11+K11) -> 1291443.4 | N11: =M11/F11 -> 0.17767506 | O11: 137936.38 | P11: =O11/F11 -> 0.018977103 | Q11: 79980.185 | R11: =Q11/$F11 -> 0.011003567 | S11: =SUM(O11+Q11) -> 217916.57 | T11: =S11/F11 -> 0.02998067 | U11: 1219516.9 | V11: =U11/F11 -> 0.1677795 | W11: 0 | X11: =W11/F11 -> 0 | Y11: 481171.27 | Z11: =Y11/F11 -> 0.066198899 | AA11: 1682213.4 | AB11: =AA11/$F11 -> 0.23143666 | AC11: =SUM(Y11+AA11) -> 2163384.6 | AD11: =AC11/F11 -> 0.29763556 | AE11: 902168.5 | AF11: =AE11/F11 -> 0.12411914 | AG11: 625249.25 | AH11: =AG11/F11 -> 0.086020956 | AI11: 406782.65 | AJ11: =AI11/F11 -> 0.055964613 | AK11: 442107.09 | AL11: =AK11/F11 -> 0.060824502
D12: =D11+1 -> 6 | E12: 二 | F12: =SUM(M12,S12,U12,W12,AC12,AE12,AG12,AI12,AK12) -> 7452237 | G12: =SUM(F12:F18) -> 47860768 | H12: =SUM(F7:F37) -> 173020836 | I12: 603282.35 | J12: =I12/F12 -> 0.080953189 | K12: 753377.25 | L12: =K12/F12 -> 0.10109411 | M12: =SUM(I12+K12) -> 1356659.6 | N12: =M12/F12 -> 0.1820473 | O12: 141358.87 | P12: =O12/F12 -> 0.018968649 | Q12: 85540.989 | R12: =Q12/$F12 -> 0.011478565 | S12: =SUM(O12+Q12) -> 226899.86 | T12: =S12/F12 -> 0.030447215 | U12: 1356955.4 | V12: =U12/F12 -> 0.18208699 | W12: 50332.589 | X12: =W12/F12 -> 0.0067540241 | Y12: 583753.97 | Z12: =Y12/F12 -> 0.078332717 | AA12: 1631212.7 | AB12: =AA12/$F12 -> 0.218889 | AC12: =SUM(Y12+AA12) -> 2214966.7 | AD12: =AC12/F12 -> 0.29722172 | AE12: 870171.58 | AF12: =AE12/F12 -> 0.11676649 | AG12: 580526.74 | AH12: =AG12/F12 -> 0.077899662 | AI12: 356945.88 | AJ12: =AI12/F12 -> 0.047897817 | AK12: 438778.62 | AL12: =AK12/F12 -> 0.05887878
D13: =D12+1 -> 7 | E13: 三 | F13: =SUM(M13,S13,U13,W13,AC13,AE13,AG13,AI13,AK13) -> 6995772 | I13: 575546.65 | J13: =I13/F13 -> 0.082270642 | K13: 746364.21 | L13: =K13/F13 -> 0.1066879 | M13: =SUM(I13+K13) -> 1321910.9 | N13: =M13/F13 -> 0.18895854 | O13: 136817.5 | P13: =O13/F13 -> 0.01955717 | Q13: 88153.994 | R13: =Q13/$F13 -> 0.012601039 | S13: =SUM(O13+Q13) -> 224971.5 | T13: =S13/F13 -> 0.032158209 | U13: 1191405.7 | V13: =U13/F13 -> 0.17030368 | W13: 49323.245 | X13: =W13/F13 -> 0.0070504364 | Y13: 308367.72 | Z13: =Y13/F13 -> 0.044079156 | AA13: 1590712.9 | AB13: =AA13/$F13 -> 0.22738204 | AC13: =SUM(Y13+AA13) -> 1899080.6 | AD13: =AC13/F13 -> 0.2714612 | AE13: 907626.8 | AF13: =AE13/F13 -> 0.12973933 | AG13: 570297.39 | AH13: =AG13/F13 -> 0.081520293 | AI13: 381275.01 | AJ13: =AI13/F13 -> 0.054500776 | AK13: 449880.87 | AL13: =AK13/F13 -> 0.064307538
D14: =D13+1 -> 8 | E14: 四 | F14: =SUM(M14,S14,U14,W14,AC14,AE14,AG14,AI14,AK14) -> 6658240 | I14: 541185.42 | J14: =I14/F14 -> 0.081280551 | K14: 680572.15 | L14: =K14/F14 -> 0.10221502 | M14: =SUM(I14+K14) -> 1221757.6 | N14: =M14/F14 -> 0.18349557 | O14: 132149.33 | P14: =O14/F14 -> 0.019847486 | Q14: 85844.701 | R14: =Q14/$F14 -> 0.012893002 | S14: =SUM(O14+Q14) -> 217994.03 | T14: =S14/F14 -> 0.032740488 | U14: 1108960.3 | V14: =U14/F14 -> 0.16655458 | W14: 4237.1273 | X14: =W14/F14 -> 0.00063637348 | Y14: 591612.1 | Z14: =Y14/F14 -> 0.088854127 | AA14: 1285284.8 | AB14: =AA14/$F14 -> 0.19303671 | AC14: =SUM(Y14+AA14) -> 1876896.9 | AD14: =AC14/F14 -> 0.28189084 | AE14: 849055.38 | AF14: =AE14/F14 -> 0.12751949 | AG14: 538433.01 | AH14: =AG14/F14 -> 0.080867167 | AI14: 398818.33 | AJ14: =AI14/F14 -> 0.05989846 | AK14: 442087.35 | AL14: =AK14/F14 -> 0.066397028
D15: =D14+1 -> 9 | E15: 五 | F15: =SUM(M15,S15,U15,W15,AC15,AE15,AG15,AI15,AK15) -> 6093782 | I15: 498793.24 | J15: =I15/F15 -> 0.081852819 | K15: 651766.02 | L15: =K15/F15 -> 0.10695591 | M15: =SUM(I15+K15) -> 1150559.3 | N15: =M15/F15 -> 0.18880873 | O15: 99252.633 | P15: =O15/F15 -> 0.016287526 | Q15: 71008.624 | R15: =Q15/$F15 -> 0.011652636 | S15: =SUM(O15+Q15) -> 170261.26 | T15: =S15/F15 -> 0.027940162 | U15: 1052187.4 | V15: =U15/F15 -> 0.17266574 | W15: 26101.515 | X15: =W15/F15 -> 0.0042833031 | Y15: 502430.89 | Z15: =Y15/F15 -> 0.082449765 | AA15: 1286571.4 | AB15: =AA15/$F15 -> 0.21112856 | AC15: =SUM(Y15+AA15) -> 1789002.3 | AD15: =AC15/F15 -> 0.29357832 | AE15: 726287.07 | AF15: =AE15/F15 -> 0.11918495 | AG15: 451589.07 | AH15: =AG15/F15 -> 0.074106535 | AI15: 372093.16 | AJ15: =AI15/F15 -> 0.061061121 | AK15: 355701 | AL15: =AK15/F15 -> 0.05837114
D16: =D15+1 -> 10 | E16: 六 | F16: =SUM(M16,S16,U16,W16,AC16,AE16,AG16,AI16,AK16) -> 6273190 | I16: 477105.82 | J16: =I16/F16 -> 0.076054737 | K16: 680539.64 | L16: =K16/F16 -> 0.10848382 | M16: =SUM(I16+K16) -> 1157645.5 | N16: =M16/F16 -> 0.18453856 | O16: 88231.744 | P16: =O16/F16 -> 0.014064893 | Q16: 66561.299 | R16: =Q16/$F16 -> 0.010610439 | S16: =SUM(O16+Q16) -> 154793.04 | T16: =S16/F16 -> 0.024675332 | U16: 1085661.2 | V16: =U16/F16 -> 0.17306365 | W16: 37248.284 | X16: =W16/F16 -> 0.0059376943 | Y16: 536723.09 | Z16: =Y16/F16 -> 0.08555824 | AA16: 1296756.5 | AB16: =AA16/$F16 -> 0.20671405 | AC16: =SUM(Y16+AA16) -> 1833479.6 | AD16: =AC16/F16 -> 0.29227229 | AE16: 786069.67 | AF16: =AE16/F16 -> 0.12530621 | AG16: 482300.79 | AH16: =AG16/F16 -> 0.07688286 | AI16: 343831.97 | AJ16: =AI16/F16 -> 0.054809749 | AK16: 392160 | AL16: =AK16/F16 -> 0.06251365
D17: =D16+1 -> 11 | E17: 日 | F17: =SUM(M17,S17,U17,W17,AC17,AE17,AG17,AI17,AK17) -> 7385036 | I17: 584834.51 | J17: =I17/F17 -> 0.079191829 | K17: 713519.26 | L17: =K17/F17 -> 0.096616897 | M17: =SUM(I17+K17) -> 1298353.8 | N17: =M17/F17 -> 0.17580873 | O17: 125779.42 | P17: =O17/F17 -> 0.017031659 | Q17: 80290.236 | R17: =Q17/$F17 -> 0.010872017 | S17: =SUM(O17+Q17) -> 206069.65 | T17: =S17/F17 -> 0.027903676 | U17: 1353696.7 | V17: =U17/F17 -> 0.18330265 | W17: 67719.203 | X17: =W17/F17 -> 0.0091697864 | Y17: 659684.75 | Z17: =Y17/F17 -> 0.089327223 | AA17: 1404710.6 | AB17: =AA17/$F17 -> 0.1902104 | AC17: =SUM(Y17+AA17) -> 2064395.4 | AD17: =AC17/F17 -> 0.27953762 | AE17: 971918.6 | AF17: =AE17/F17 -> 0.13160648 | AG17: 565670.32 | AH17: =AG17/F17 -> 0.076596826 | AI17: 443028.39 | AJ17: =AI17/F17 -> 0.059990011 | AK17: 414184.02 | AL17: =AK17/F17 -> 0.056084224
D18: =D17+1 -> 12 | E18: 一 | F18: =SUM(M18,S18,U18,W18,AC18,AE18,AG18,AI18,AK18) -> 7002511 | I18: 559588.18 | J18: =I18/F18 -> 0.079912503 | K18: 703960.85 | L18: =K18/F18 -> 0.10052977 | M18: =SUM(I18+K18) -> 1263549 | N18: =M18/F18 -> 0.18044228 | O18: 115593.62 | P18: =O18/F18 -> 0.016507452 | Q18: 79128.352 | R18: =Q18/$F18 -> 0.011299997 | S18: =SUM(O18+Q18) -> 194721.97 | T18: =S18/F18 -> 0.027807449 | U18: 1277634.7 | V18: =U18/F18 -> 0.18245379 | W18: 41520.081 | X18: =W18/F18 -> 0.0059293133 | Y18: 503934.04 | Z18: =Y18/F18 -> 0.071964762 | AA18: 1363654.8 | AB18: =AA18/$F18 -> 0.19473798 | AC18: =SUM(Y18+AA18) -> 1867588.9 | AD18: =AC18/F18 -> 0.26670274 | AE18: 905518.49 | AF18: =AE18/F18 -> 0.1293134 | AG18: 568685.34 | AH18: =AG18/F18 -> 0.081211631 | AI18: 439668.37 | AJ18: =AI18/F18 -> 0.062787245 | AK18: 443624.18 | AL18: =AK18/F18 -> 0.063352158
D19: =D18+1 -> 13 | E19: 二 | F19: =SUM(M19,S19,U19,W19,AC19,AE19,AG19,AI19,AK19) -> 6868111 | G19: =SUM(F19:F25) -> 45268529 | I19: 637939.79 | J19: =I19/F19 -> 0.092884315 | K19: 696731.61 | L19: =K19/F19 -> 0.10144443 | M19: =SUM(I19+K19) -> 1334671.4 | N19: =M19/F19 -> 0.19432875 | O19: 112867.82 | P19: =O19/F19 -> 0.016433605 | Q19: 79615.009 | R19: =Q19/$F19 -> 0.011591981 | S19: =SUM(O19+Q19) -> 192482.83 | T19: =S19/F19 -> 0.028025585 | U19: 1214873.7 | V19: =U19/F19 -> 0.17688615 | W19: 32435.872 | X19: =W19/F19 -> 0.0047226774 | Y19: 498611.29 | Z19: =Y19/F19 -> 0.072598025 | AA19: 1317767.4 | AB19: =AA19/$F19 -> 0.19186752 | AC19: =SUM(Y19+AA19) -> 1816378.7 | AD19: =AC19/F19 -> 0.26446555 | AE19: 950478.6 | AF19: =AE19/F19 -> 0.13839011 | AG19: 474005.35 | AH19: =AG19/F19 -> 0.069015388 | AI19: 436511.9 | AJ19: =AI19/F19 -> 0.063556326 | AK19: 416272.62 | AL19: =AK19/F19 -> 0.060609478
D20: =D19+1 -> 14 | E20: 三 | F20: =SUM(M20,S20,U20,W20,AC20,AE20,AG20,AI20,AK20) -> 6627112 | I20: 593393.82 | J20: =I20/F20 -> 0.089540333 | K20: 669673.84 | L20: =K20/F20 -> 0.10105063 | M20: =SUM(I20+K20) -> 1263067.7 | N20: =M20/F20 -> 0.19059096 | O20: 118471.52 | P20: =O20/F20 -> 0.017876795 | Q20: 80488.419 | R20: =Q20/$F20 -> 0.012145324 | S20: =SUM(O20+Q20) -> 198959.94 | T20: =S20/F20 -> 0.030022118 | U20: 1143978.4 | V20: =U20/F20 -> 0.17262096 | W20: 47201.598 | X20: =W20/F20 -> 0.007122499 | Y20: 540101.29 | Z20: =Y20/F20 -> 0.081498742 | AA20: 1240840.4 | AB20: =AA20/$F20 -> 0.18723698 | AC20: =SUM(Y20+AA20) -> 1780941.7 | AD20: =AC20/F20 -> 0.26873572 | AE20: 874310.68 | AF20: =AE20/F20 -> 0.13192937 | AG20: 484486.49 | AH20: =AG20/F20 -> 0.07310673 | AI20: 416980.83 | AJ20: =AI20/F20 -> 0.062920444 | AK20: 417184.71 | AL20: =AK20/F20 -> 0.062951209
D21: =D20+1 -> 15 | E21: 四 | F21: =SUM(M21,S21,U21,W21,AC21,AE21,AG21,AI21,AK21) -> 6144184 | I21: 554882.19 | J21: =I21/F21 -> 0.090310152 | K21: 640452.36 | L21: =K21/F21 -> 0.10423717 | M21: =SUM(I21+K21) -> 1195334.5 | N21: =M21/F21 -> 0.19454732 | O21: 116267.66 | P21: =O21/F21 -> 0.018923206 | Q21: 81019.098 | R21: =Q21/$F21 -> 0.013186307 | S21: =SUM(O21+Q21) -> 197286.76 | T21: =S21/F21 -> 0.032109513 | U21: 1104546.9 | V21: =U21/F21 -> 0.17977114 | W21: 35925.691 | X21: =W21/F21 -> 0.0058471053 | Y21: 550409.76 | Z21: =Y21/F21 -> 0.08958224 | AA21: 1067793.2 | AB21: =AA21/$F21 -> 0.17378927 | AC21: =SUM(Y21+AA21) -> 1618203 | AD21: =AC21/F21 -> 0.26337151 | AE21: 787573.05 | AF21: =AE21/F21 -> 0.12818188 | AG21: 367376.51 | AH21: =AG21/F21 -> 0.059792563 | AI21: 425649.63 | AJ21: =AI21/F21 -> 0.069276836 | AK21: 412287.86 | AL21: =AK21/F21 -> 0.067102135
D22: =D21+1 -> 16 | E22: 五 | F22: =SUM(M22,S22,U22,W22,AC22,AE22,AG22,AI22,AK22) -> 5795971 | I22: 543927.87 | J22: =I22/F22 -> 0.093845858 | K22: 632000.64 | L22: =K22/F22 -> 0.10904137 | M22: =SUM(I22+K22) -> 1175928.5 | N22: =M22/F22 -> 0.20288723 | O22: 90042.907 | P22: =O22/F22 -> 0.015535431 | Q22: 72480.937 | R22: =Q22/$F22 -> 0.0125054 | S22: =SUM(O22+Q22) -> 162523.84 | T22: =S22/F22 -> 0.028040831 | U22: 963116.3 | V22: =U22/F22 -> 0.16616997 | W22: 35585.719 | X22: =W22/F22 -> 0.0061397338 | Y22: 527838.78 | Z22: =Y22/F22 -> 0.091069948 | AA22: 1170671.1 | AB22: =AA22/$F22 -> 0.20198015 | AC22: =SUM(Y22+AA22) -> 1698509.8 | AD22: =AC22/F22 -> 0.29305009 | AE22: 692951.65 | AF22: =AE22/F22 -> 0.11955747 | AG22: 313779.98 | AH22: =AG22/F22 -> 0.054137603 | AI22: 410485.56 | AJ22: =AI22/F22 -> 0.07082257 | AK22: 343089.59 | AL22: =AK22/F22 -> 0.059194497
D23: =D22+1 -> 17 | E23: 六 | F23: =SUM(M23,S23,U23,W23,AC23,AE23,AG23,AI23,AK23) -> 6092113 | I23: 516510.74 | J23: =I23/F23 -> 0.084783512 | K23: 673138.6 | L23: =K23/F23 -> 0.11049345 | M23: =SUM(I23+K23) -> 1189649.3 | N23: =M23/F23 -> 0.19527696 | O23: 85219.196 | P23: =O23/F23 -> 0.013988446 | Q23: 68790.21 | R23: =Q23/$F23 -> 0.011291683 | S23: =SUM(O23+Q23) -> 154009.41 | T23: =S23/F23 -> 0.02528013 | U23: 1047789.6 | V23: =U23/F23 -> 0.17199117 | W23: 27925.586 | X23: =W23/F23 -> 0.0045838917 | Y23: 541843.43 | Z23: =Y23/F23 -> 0.088941789 | AA23: 1153597.5 | AB23: =AA23/$F23 -> 0.18935918 | AC23: =SUM(Y23+AA23) -> 1695441 | AD23: =AC23/F23 -> 0.27830097 | AE23: 777702.16 | AF23: =AE23/F23 -> 0.12765721 | AG23: 352423.84 | AH23: =AG23/F23 -> 0.057849196 | AI23: 462383.88 | AJ23: =AI23/F23 -> 0.07589877 | AK23: 384788.22 | AL23: =AK23/F23 -> 0.063161701
D24: =D23+1 -> 18 | E24: 日 | F24: =SUM(M24,S24,U24,W24,AC24,AE24,AG24,AI24,AK24) -> 6822501 | I24: 613724.49 | J24: =I24/F24 -> 0.089955941 | K24: 703542.97 | L24: =K24/F24 -> 0.10312098 | M24: =SUM(I24+K24) -> 1317267.5 | N24: =M24/F24 -> 0.19307692 | O24: 114309.01 | P24: =O24/F24 -> 0.016754708 | Q24: 77186.007 | R24: =Q24/$F24 -> 0.011313447 | S24: =SUM(O24+Q24) -> 191495.02 | T24: =S24/F24 -> 0.028068156 | U24: 1272393.7 | V24: =U24/F24 -> 0.18649959 | W24: 38628.784 | X24: =W24/F24 -> 0.0056619682 | Y24: 532716.29 | Z24: =Y24/F24 -> 0.078082258 | AA24: 1270936.1 | AB24: =AA24/$F24 -> 0.18628595 | AC24: =SUM(Y24+AA24) -> 1803652.4 | AD24: =AC24/F24 -> 0.26436821 | AE24: 917387.71 | AF24: =AE24/F24 -> 0.13446502 | AG24: 403663.04 | AH24: =AG24/F24 -> 0.059166432 | AI24: 479746.37 | AJ24: =AI24/F24 -> 0.070318256 | AK24: 398266.59 | AL24: =AK24/F24 -> 0.058375454
D25: =D24+1 -> 19 | E25: 一 | F25: =SUM(M25,S25,U25,W25,AC25,AE25,AG25,AI25,AK25) -> 6918537 | I25: 593452.02 | J25: =I25/F25 -> 0.085777097 | K25: 710517.56 | L25: =K25/F25 -> 0.10269766 | M25: =SUM(I25+K25) -> 1303969.6 | N25: =M25/F25 -> 0.18847476 | O25: 105131.43 | P25: =O25/F25 -> 0.015195616 | Q25: 77122.355 | R25: =Q25/$F25 -> 0.011147206 | S25: =SUM(O25+Q25) -> 182253.79 | T25: =S25/F25 -> 0.026342822 | U25: 1214950.7 | V25: =U25/F25 -> 0.17560804 | W25: 40438.731 | X25: =W25/F25 -> 0.005844983 | Y25: 555802.11 | Z25: =Y25/F25 -> 0.080335208 | AA25: 1438624.5 | AB25: =AA25/$F25 -> 0.20793767 | AC25: =SUM(Y25+AA25) -> 1994426.6 | AD25: =AC25/F25 -> 0.28827288 | AE25: 892361.81 | AF25: =AE25/F25 -> 0.12898129 | AG25: 406850.78 | AH25: =AG25/F25 -> 0.058805898 | AI25: 462046.09 | AJ25: =AI25/F25 -> 0.066783785 | AK25: 421238.97 | AL25: =AK25/F25 -> 0.060885555
D26: =D25+1 -> 20 | E26: 二 | F26: =SUM(M26,S26,U26,W26,AC26,AE26,AG26,AI26,AK26) -> 7713415 | G26: =SUM(F26:F32) -> 46317667 | I26: 702069.32 | J26: =I26/F26 -> 0.091019259 | K26: 697330.13 | L26: =K26/F26 -> 0.090404851 | M26: =SUM(I26+K26) -> 1399399.5 | N26: =M26/F26 -> 0.18142411 | O26: 109688.05 | P26: =O26/F26 -> 0.014220427 | Q26: 82063.062 | R26: =Q26/$F26 -> 0.010639005 | S26: =SUM(O26+Q26) -> 191751.12 | T26: =S26/F26 -> 0.024859432 | U26: 1137014.2 | V26: =U26/F26 -> 0.14740737 | W26: 43391.841 | X26: =W26/F26 -> 0.0056255033 | Y26: 706514.34 | Z26: =Y26/F26 -> 0.091595531 | AA26: 1396167.7 | AB26: =AA26/$F26 -> 0.18100513 | AC26: =SUM(Y26+AA26) -> 2102682 | AD26: =AC26/F26 -> 0.27260066 | AE26: 1066112.9 | AF26: =AE26/F26 -> 0.13821542 | AG26: 1028753.4 | AH26: =AG26/F26 -> 0.13337198 | AI26: 358978.35 | AJ26: =AI26/F26 -> 0.046539484 | AK26: 385331.65 | AL26: =AK26/F26 -> 0.049956038
D27: =D26+1 -> 21 | E27: 三 | F27: =SUM(M27,S27,U27,W27,AC27,AE27,AG27,AI27,AK27) -> 6863386 | I27: 656712.91 | J27: =I27/F27 -> 0.095683516 | K27: 686113.01 | L27: =K27/F27 -> 0.099967131 | M27: =SUM(I27+K27) -> 1342825.9 | N27: =M27/F27 -> 0.19565065 | O27: 114490.38 | P27: =O27/F27 -> 0.016681327 | Q27: 85351.413 | R27: =Q27/$F27 -> 0.012435759 | S27: =SUM(O27+Q27) -> 199841.8 | T27: =S27/F27 -> 0.029117086 | U27: 1057843.3 | V27: =U27/F27 -> 0.15412849 | W27: 42757.166 | X27: =W27/F27 -> 0.0062297481 | Y27: 602761.04 | Z27: =Y27/F27 -> 0.087822693 | AA27: 1317770.6 | AB27: =AA27/$F27 -> 0.19200008 | AC27: =SUM(Y27+AA27) -> 1920531.7 | AD27: =AC27/F27 -> 0.27982277 | AE27: 860747.11 | AF27: =AE27/F27 -> 0.12541144 | AG27: 707806.82 | AH27: =AG27/F27 -> 0.10312793 | AI27: 352573.64 | AJ27: =AI27/F27 -> 0.051370219 | AK27: 378458.54 | AL27: =AK27/F27 -> 0.055141666
D28: =D27+1 -> 22 | E28: 四 | F28: =SUM(M28,S28,U28,W28,AC28,AE28,AG28,AI28,AK28) -> 6394057 | I28: 617272.73 | J28: =I28/F28 -> 0.09653851 | K28: 642595.94 | L28: =K28/F28 -> 0.10049894 | M28: =SUM(I28+K28) -> 1259868.7 | N28: =M28/F28 -> 0.19703745 | O28: 109744.64 | P28: =O28/F28 -> 0.017163537 | Q28: 85730.432 | R28: =Q28/$F28 -> 0.01340783 | S28: =SUM(O28+Q28) -> 195475.07 | T28: =S28/F28 -> 0.030571368 | U28: 1033179.1 | V28: =U28/F28 -> 0.16158429 | W28: 30793.223 | X28: =W28/F28 -> 0.0048159131 | Y28: 589331.72 | Z28: =Y28/F28 -> 0.092168669 | AA28: 1086425.2 | AB28: =AA28/$F28 -> 0.16991172 | AC28: =SUM(Y28+AA28) -> 1675757 | AD28: =AC28/F28 -> 0.26208039 | AE28: 867027.85 | AF28: =AE28/F28 -> 0.13559902 | AG28: 659002.35 | AH28: =AG28/F28 -> 0.10306482 | AI28: 322012.39 | AJ28: =AI28/F28 -> 0.050361201 | AK28: 350941.33 | AL28: =AK28/F28 -> 0.05488555
D29: =D28+1 -> 23 | E29: 五 | F29: =SUM(M29,S29,U29,W29,AC29,AE29,AG29,AI29,AK29) -> 5574275 | I29: 566526.99 | J29: =I29/F29 -> 0.10163241 | K29: 606875.83 | L29: =K29/F29 -> 0.10887081 | M29: =SUM(I29+K29) -> 1173402.8 | N29: =M29/F29 -> 0.21050322 | O29: 82635.184 | P29: =O29/F29 -> 0.014824382 | Q29: 70648.159 | R29: =Q29/$F29 -> 0.012673964 | S29: =SUM(O29+Q29) -> 153283.34 | T29: =S29/F29 -> 0.027498346 | U29: 923583.97 | V29: =U29/F29 -> 0.16568683 | W29: 21514.63 | X29: =W29/F29 -> 0.0038596285 | Y29: 504502.74 | Z29: =Y29/F29 -> 0.090505535 | AA29: 1114543.3 | AB29: =AA29/$F29 -> 0.19994409 | AC29: =SUM(Y29+AA29) -> 1619046.1 | AD29: =AC29/F29 -> 0.29044963 | AE29: 709030.47 | AF29: =AE29/F29 -> 0.12719689 | AG29: 396037.28 | AH29: =AG29/F29 -> 0.071047317 | AI29: 294659.97 | AJ29: =AI29/F29 -> 0.05286068 | AK29: 283716.43 | AL29: =AK29/F29 -> 0.050897459
D30: =D29+1 -> 24 | E30: 六 | F30: =SUM(M30,S30,U30,W30,AC30,AE30,AG30,AI30,AK30) -> 5940745 | I30: 526931.19 | J30: =I30/F30 -> 0.08869783 | K30: 642730.73 | L30: =K30/F30 -> 0.10819026 | M30: =SUM(I30+K30) -> 1169661.9 | N30: =M30/F30 -> 0.19688809 | O30: 76580.267 | P30: =O30/F30 -> 0.012890684 | Q30: 64801.785 | R30: =Q30/$F30 -> 0.010908023 | S30: =SUM(O30+Q30) -> 141382.05 | T30: =S30/F30 -> 0.023798707 | U30: 1007689.3 | V30: =U30/F30 -> 0.1696234 | W30: 19119.867 | X30: =W30/F30 -> 0.0032184291 | Y30: 546413.63 | Z30: =Y30/F30 -> 0.091977291 | AA30: 1107652.1 | AB30: =AA30/$F30 -> 0.18645003 | AC30: =SUM(Y30+AA30) -> 1654065.7 | AD30: =AC30/F30 -> 0.27842732 | AE30: 794046.66 | AF30: =AE30/F30 -> 0.13366113 | AG30: 437364.44 | AH30: =AG30/F30 -> 0.073621143 | AI30: 403868.87 | AJ30: =AI30/F30 -> 0.067982866 | AK30: 313546.13 | AL30: =AK30/F30 -> 0.052778925
D31: =D30+1 -> 25 | E31: 日 | F31: =SUM(M31,S31,U31,W31,AC31,AE31,AG31,AI31,AK31) -> 7104289 | I31: 640435.32 | J31: =I31/F31 -> 0.090147702 | K31: 676791.94 | L31: =K31/F31 -> 0.09526526 | M31: =SUM(I31+K31) -> 1317227.3 | N31: =M31/F31 -> 0.18541296 | O31: 103979.6 | P31: =O31/F31 -> 0.014636172 | Q31: 76176.964 | R31: =Q31/$F31 -> 0.010722672 | S31: =SUM(O31+Q31) -> 180156.56 | T31: =S31/F31 -> 0.025358845 | U31: 1193445.8 | V31: =U31/F31 -> 0.16798947 | W31: 27537.661 | X31: =W31/F31 -> 0.0038762022 | Y31: 649670.3 | Z31: =Y31/F31 -> 0.091447616 | AA31: 1251638.5 | AB31: =AA31/$F31 -> 0.17618068 | AC31: =SUM(Y31+AA31) -> 1901308.8 | AD31: =AC31/F31 -> 0.2676283 | AE31: 1010681 | AF31: =AE31/F31 -> 0.14226349 | AG31: 708705.47 | AH31: =AG31/F31 -> 0.09975741 | AI31: 431556.77 | AJ31: =AI31/F31 -> 0.060745948 | AK31: 333669.78 | AL31: =AK31/F31 -> 0.046967372
D32: =D31+1 -> 26 | E32: 一 | F32: =SUM(M32,S32,U32,W32,AC32,AE32,AG32,AI32,AK32) -> 6727500 | I32: 585770 | J32: =I32/F32 -> 0.087070978 | K32: 675163.06 | L32: =K32/F32 -> 0.10035869 | M32: =SUM(I32+K32) -> 1260933.1 | N32: =M32/F32 -> 0.18742966 | O32: 99919.907 | P32: =O32/F32 -> 0.014852457 | Q32: 77689.13 | R32: =Q32/$F32 -> 0.011547994 | S32: =SUM(O32+Q32) -> 177609.04 | T32: =S32/F32 -> 0.026400451 | U32: 1183259.6 | V32: =U32/F32 -> 0.175884 | W32: 29040.002 | X32: =W32/F32 -> 0.0043166113 | Y32: 606620.31 | Z32: =Y32/F32 -> 0.090170243 | AA32: 1239627.8 | AB32: =AA32/$F32 -> 0.18426277 | AC32: =SUM(Y32+AA32) -> 1846248.1 | AD32: =AC32/F32 -> 0.27443301 | AE32: 891413.36 | AF32: =AE32/F32 -> 0.13250291 | AG32: 525325.5 | AH32: =AG32/F32 -> 0.078086287 | AI32: 458714.26 | AJ32: =AI32/F32 -> 0.068184951 | AK32: 354957.08 | AL32: =AK32/F32 -> 0.052762107
D33: =D32+1 -> 27 | E33: 二 | F33: =SUM(M33,S33,U33,W33,AC33,AE33,AG33,AI33,AK33) -> 0 | G33: =SUM(F33:F39) -> 0 | J33: =I33/F33 -> #DIV/0! | L33: =K33/F33 -> #DIV/0! | M33: =SUM(I33+K33) -> 0 | N33: =M33/F33 -> #DIV/0! | P33: =O33/F33 -> #DIV/0! | R33: =Q33/$F33 -> #DIV/0! | S33: =SUM(O33+Q33) -> 0 | T33: =S33/F33 -> #DIV/0! | V33: =U33/F33 -> #DIV/0! | X33: =W33/F33 -> #DIV/0! | Z33: =Y33/F33 -> #DIV/0! | AB33: =AA33/$F33 -> #DIV/0! | AC33: =SUM(Y33+AA33) -> 0 | AD33: =AC33/F33 -> #DIV/0! | AF33: =AE33/F33 -> #DIV/0! | AH33: =AG33/F33 -> #DIV/0! | AJ33: =AI33/F33 -> #DIV/0! | AL33: =AK33/F33 -> #DIV/0!
D34: =D33+1 -> 28 | E34: 三 | F34: =SUM(M34,S34,U34,W34,AC34,AE34,AG34,AI34,AK34) -> 0 | J34: =I34/F34 -> #DIV/0! | L34: =K34/F34 -> #DIV/0! | M34: =SUM(I34+K34) -> 0 | N34: =M34/F34 -> #DIV/0! | P34: =O34/F34 -> #DIV/0! | R34: =Q34/$F34 -> #DIV/0! | S34: =SUM(O34+Q34) -> 0 | T34: =S34/F34 -> #DIV/0! | V34: =U34/F34 -> #DIV/0! | X34: =W34/F34 -> #DIV/0! | Z34: =Y34/F34 -> #DIV/0! | AB34: =AA34/$F34 -> #DIV/0! | AC34: =SUM(Y34+AA34) -> 0 | AD34: =AC34/F34 -> #DIV/0! | AF34: =AE34/F34 -> #DIV/0! | AH34: =AG34/F34 -> #DIV/0! | AJ34: =AI34/F34 -> #DIV/0! | AL34: =AK34/F34 -> #DIV/0!
D35: =D34+1 -> 29 | E35: 四 | F35: =SUM(M35,S35,U35,W35,AC35,AE35,AG35,AI35,AK35) -> 0 | J35: =I35/F35 -> #DIV/0! | L35: =K35/F35 -> #DIV/0! | M35: =SUM(I35+K35) -> 0 | N35: =M35/F35 -> #DIV/0! | P35: =O35/F35 -> #DIV/0! | R35: =Q35/$F35 -> #DIV/0! | S35: =SUM(O35+Q35) -> 0 | T35: =S35/F35 -> #DIV/0! | V35: =U35/F35 -> #DIV/0! | X35: =W35/F35 -> #DIV/0! | Z35: =Y35/F35 -> #DIV/0! | AB35: =AA35/$F35 -> #DIV/0! | AC35: =SUM(Y35+AA35) -> 0 | AD35: =AC35/F35 -> #DIV/0! | AF35: =AE35/F35 -> #DIV/0! | AH35: =AG35/F35 -> #DIV/0! | AJ35: =AI35/F35 -> #DIV/0! | AL35: =AK35/F35 -> #DIV/0!
D36: =D35+1 -> 30 | E36: 五 | F36: =SUM(M36,S36,U36,W36,AC36,AE36,AG36,AI36,AK36) -> 0 | J36: =I36/F36 -> #DIV/0! | L36: =K36/F36 -> #DIV/0! | M36: =SUM(I36+K36) -> 0 | N36: =M36/F36 -> #DIV/0! | P36: =O36/F36 -> #DIV/0! | R36: =Q36/$F36 -> #DIV/0! | S36: =SUM(O36+Q36) -> 0 | T36: =S36/F36 -> #DIV/0! | V36: =U36/F36 -> #DIV/0! | X36: =W36/F36 -> #DIV/0! | Z36: =Y36/F36 -> #DIV/0! | AB36: =AA36/$F36 -> #DIV/0! | AC36: =SUM(Y36+AA36) -> 0 | AD36: =AC36/F36 -> #DIV/0! | AF36: =AE36/F36 -> #DIV/0! | AH36: =AG36/F36 -> #DIV/0! | AJ36: =AI36/F36 -> #DIV/0! | AL36: =AK36/F36 -> #DIV/0!
D37: =D36+1 -> 31 | E37: 六 | F37: =SUM(M37,S37,U37,W37,AC37,AE37,AG37,AI37,AK37) -> 0 | J37: =I37/F37 -> #DIV/0! | L37: =K37/F37 -> #DIV/0! | M37: =SUM(I37+K37) -> 0 | N37: =M37/F37 -> #DIV/0! | P37: =O37/F37 -> #DIV/0! | R37: =Q37/$F37 -> #DIV/0! | S37: =SUM(O37+Q37) -> 0 | T37: =S37/F37 -> #DIV/0! | V37: =U37/F37 -> #DIV/0! | X37: =W37/F37 -> #DIV/0! | Z37: =Y37/F37 -> #DIV/0! | AB37: =AA37/$F37 -> #DIV/0! | AC37: =SUM(Y37+AA37) -> 0 | AD37: =AC37/F37 -> #DIV/0! | AF37: =AE37/F37 -> #DIV/0! | AH37: =AG37/F37 -> #DIV/0! | AJ37: =AI37/F37 -> #DIV/0! | AL37: =AK37/F37 -> #DIV/0!
D38: =D37+1 -> 32 | E38: 日 | F38: =SUM(M38,S38,U38,W38,AC38,AE38,AG38,AI38,AK38) -> 0 | J38: =I38/F38 -> #DIV/0! | L38: =K38/F38 -> #DIV/0! | M38: =SUM(I38+K38) -> 0 | N38: =M38/F38 -> #DIV/0! | P38: =O38/F38 -> #DIV/0! | R38: =Q38/$F38 -> #DIV/0! | S38: =SUM(O38+Q38) -> 0 | T38: =S38/F38 -> #DIV/0! | V38: =U38/F38 -> #DIV/0! | X38: =W38/F38 -> #DIV/0! | Z38: =Y38/F38 -> #DIV/0! | AB38: =AA38/$F38 -> #DIV/0! | AC38: =SUM(Y38+AA38) -> 0 | AD38: =AC38/F38 -> #DIV/0! | AF38: =AE38/F38 -> #DIV/0! | AH38: =AG38/F38 -> #DIV/0! | AJ38: =AI38/F38 -> #DIV/0! | AL38: =AK38/F38 -> #DIV/0!
D39: =D38+1 -> 33 | E39: 一 | F39: =SUM(M39,S39,U39,W39,AC39,AE39,AG39,AI39,AK39) -> 0 | J39: =I39/F39 -> #DIV/0! | L39: =K39/F39 -> #DIV/0! | M39: =SUM(I39+K39) -> 0 | N39: =M39/F39 -> #DIV/0! | P39: =O39/F39 -> #DIV/0! | R39: =Q39/$F39 -> #DIV/0! | S39: =SUM(O39+Q39) -> 0 | T39: =S39/F39 -> #DIV/0! | V39: =U39/F39 -> #DIV/0! | X39: =W39/F39 -> #DIV/0! | Z39: =Y39/F39 -> #DIV/0! | AB39: =AA39/$F39 -> #DIV/0! | AC39: =SUM(Y39+AA39) -> 0 | AD39: =AC39/F39 -> #DIV/0! | AF39: =AE39/F39 -> #DIV/0! | AH39: =AG39/F39 -> #DIV/0! | AJ39: =AI39/F39 -> #DIV/0! | AL39: =AK39/F39 -> #DIV/0!
F40: =SUM(M40,S40,U40,W40,AC40,AE40,AG40,AI40,AK40) -> 0 | J40: =I40/F40 -> #DIV/0! | L40: =K40/F40 -> #DIV/0! | M40: =SUM(I40+K40) -> 0 | N40: =M40/F40 -> #DIV/0! | P40: =O40/F40 -> #DIV/0! | R40: =Q40/$F40 -> #DIV/0! | S40: =SUM(O40+Q40) -> 0 | T40: =S40/F40 -> #DIV/0! | V40: =U40/F40 -> #DIV/0! | X40: =W40/F40 -> #DIV/0! | Z40: =Y40/F40 -> #DIV/0! | AB40: =AA40/$F40 -> #DIV/0! | AC40: =SUM(Y40+AA40) -> 0 | AD40: =AC40/F40 -> #DIV/0! | AF40: =AE40/F40 -> #DIV/0! | AH40: =AG40/F40 -> #DIV/0! | AJ40: =AI40/F40 -> #DIV/0! | AL40: =AK40/F40 -> #DIV/0!
F41: =SUM(M41,S41,U41,W41,AC41,AE41,AG41,AI41,AK41) -> 0 | J41: =I41/F41 -> #DIV/0! | L41: =K41/F41 -> #DIV/0! | M41: =SUM(I41+K41) -> 0 | N41: =M41/F41 -> #DIV/0! | P41: =O41/F41 -> #DIV/0! | R41: =Q41/$F41 -> #DIV/0! | S41: =SUM(O41+Q41) -> 0 | T41: =S41/F41 -> #DIV/0! | V41: =U41/F41 -> #DIV/0! | X41: =W41/F41 -> #DIV/0! | Z41: =Y41/F41 -> #DIV/0! | AB41: =AA41/$F41 -> #DIV/0! | AC41: =SUM(Y41+AA41) -> 0 | AD41: =AC41/F41 -> #DIV/0! | AF41: =AE41/F41 -> #DIV/0! | AH41: =AG41/F41 -> #DIV/0! | AJ41: =AI41/F41 -> #DIV/0! | AL41: =AK41/F41 -> #DIV/0!
...

Sheet （４）訂單數量構成比
B2: （4）訂單數量構成比
C3: 月份 | D3: 日期 | F3: 訂單量 | I3: 品類訂單量
