Workbook

Sheet 填寫舉例
A2: 7 | B2: 月別 | C2: 工廠名 | D2: ・・・・・・・・
A4: （１）收支狀況 | E4: ※單位：千元 | G4: （２）ＫＰＩ達成進度 | M4: （３）業績構成比 | S4: （４）訂單數量構成比
B5: 當月 | C5: 前月 | D5: 差異 | E5: 累計 | H5: KPI | I5: 當月 | J5: 前月 | K5: 累計 | L5: ※補充 | N5: 當月 | O5: 比例 | P5: 前月 | Q5: 差異 | T5: 當月 | U5: 比例 | V5: 前月 | W5: 差異
A6: 業績金額 | B6: 500000 | C6: 510000 | D6: =B6-C6 -> -10000 | E6: =B6+C6 -> 1010000 | G6: 人時生產性1 | H6: 110 | I6: 100 | J6: 90 | L6: 個／MH | M6: 飯糰 | N6: 150000 | O6: =IFERROR(N6/$B$6,"") -> 0.3 | P6: 0.4 | Q6: =IFERROR(O6-P6,"") -> -0.1 | S6: 飯糰 | T6: 35000 | U6: =IFERROR(T6/$B$7,"") -> 0.35 | V6: 0.3 | W6: =IFERROR(U6-V6,"") -> 0.05
A7: 訂單數量 | B7: 100000 | C7: 110000 | D7: =B7-C7 -> -10000 | E7: =B7+C7 -> 210000 | G7: 人時生產性2 | H7: 0.8 | I7: 0.85 | J7: 0.81 | K7: 0.84 | L7: 達成率 | M7: 大口飯糰 | N7: 100000 | O7: =IFERROR(N7/$B$6,"") -> 0.2 | P7: 0.15 | Q7: =IFERROR(O7-P7,"") -> 0.05 | S7: 大口飯糰 | T7: 30000 | U7: =IFERROR(T7/$B$7,"") -> 0.3 | V7: 0.15 | W7: =IFERROR(U7-V7,"") -> 0.15
A8: 材料費 | B8: 250000 | C8: 260000 | D8: =B8-C8 -> -10000 | E8: =B8+C8 -> 510000 | G8: 半成品報廢 | H8: 0.0025 | I8: 0.0024 | J8: 0.0023 | K8: 0.00235 | L8: 報廢率 | M8: 便當 | N8: 160000 | O8: =IFERROR(N8/$B$6,"") -> 0.32 | P8: 0.28 | Q8: =IFERROR(O8-P8,"") -> 0.04 | S8: 便當 | T8: 20000 | U8: =IFERROR(T8/$B$7,"") -> 0.2 | V8: 0.28 | W8: =IFERROR(U8-V8,"") -> -0.08
A9: 材料費率 | B9: =B8/B6 -> 0.5 | C9: =C8/C6 -> 0.50980392 | D9: =B9-C9 -> -0.0098039216 | E9: =(B9+C9)/2 -> 0.50490196 | G9: 半成品超用 | H9: 0.006 | I9: 0.009 | J9: 0.0095 | K9: 0.0092 | L9: 超用率 | M9: 調理麵 | N9: 90000 | O9: =IFERROR(N9/$B$6,"") -> 0.18 | P9: 0.17 | Q9: =IFERROR(O9-P9,"") -> 0.01 | S9: 調理麵 | T9: 15000 | U9: =IFERROR(T9/$B$7,"") -> 0.15 | V9: 0.27 | W9: =IFERROR(U9-V9,"") -> -0.12
A10: 勞務成本 | B10: 100000 | C10: 105000 | D10: =B10-C10 -> -5000 | E10: =B10+C10 -> 205000 | G10: 固定產線 | H10: 0.95 | I10: 0.9 | J10: 0.92 | K10: 0.91 | L10: 導入率 | M10: 調理麵包 | N10: - | O10: =IFERROR(N10/$B$6,"") | P10: -% | Q10: =IFERROR(O10-P10,"") | S10: 調理麵包 | T10: - | U10: =IFERROR(T10/$B$7,"") | V10: -% | W10: =IFERROR(U10-V10,"")
A11: 勞務費率 | B11: =B10/B6 -> 0.2 | C11: =C10/C6 -> 0.20588235 | D11: =B11-C11 -> -0.0058823529 | E11: =(B11+C11)/2 -> 0.20294118 | G11: 教育訓練 | H11: 0.8 | I11: 0.85 | J11: 1 | K11: 0.92 | L11: 實施率 | M11: 袋裝調理麵包 | N11: - | O11: =IFERROR(N11/$B$6,"") | P11: -% | Q11: =IFERROR(O11-P11,"") | S11: 袋裝調理麵包 | T11: - | U11: =IFERROR(T11/$B$7,"") | V11: -% | W11: =IFERROR(U11-V11,"")
M12: 義大利麵 | N12: - | O12: =IFERROR(N12/$B$6,"") | P12: -% | Q12: =IFERROR(O12-P12,"") | S12: 義大利麵 | T12: - | U12: =IFERROR(T12/$B$7,"") | V12: -% | W12: =IFERROR(U12-V12,"")
A13: （５）品群別人時生產性 | M13: 調理包 | N13: - | O13: =IFERROR(N13/$B$6,"") | P13: -% | Q13: =IFERROR(O13-P13,"") | S13: 調理包 | T13: - | U13: =IFERROR(T13/$B$7,"") | V13: -% | W13: =IFERROR(U13-V13,"")
B14: 當月 | C14: 前月 | D14: 差異 | E14: 累計 | H14: 當月 | I14: 前月 | J14: 差異 | K14: 累計 | O14: =SUM(O6:O13) -> 1 | P14: =SUM(P6:P13) -> 1 | U14: =SUM(U6:U13) -> 1 | V14: =SUM(V6:V13) -> 1
A15: 飯糰 | B15: 600 | C15: 660 | D15: =B15-C15 -> -60 | E15: =(B15+C15)/2 -> 630 | G15: 調理麵包 | J15: =H15-I15 -> 0 | M15: （７）原因別分析
A16: 大口飯糰 | B16: 800 | C16: 780 | D16: =B16-C16 -> 20 | E16: =(B16+C16)/2 -> 790 | G16: 袋裝調理麵包 | J16: =H16-I16 -> 0 | N16: 合計 | P16: 作業原因 | R16: 規格原因
A17: 便當 | B17: 130 | C17: 111 | D17: =B17-C17 -> 19 | E17: =(B17+C17)/2 -> 120.5 | G17: 義大利麵 | J17: =H17-I17 -> 0 | N17: 金額 | O17: 比例 | P17: 金額 | Q17: 比例 | R17: 金額 | S17: 比例
A18: 調理麵 | B18: 140 | C18: 165 | D18: =B18-C18 -> -25 | E18: =(B18+C18)/2 -> 152.5 | G18: 調理包 | J18: =H18-I18 -> 0 | M18: 半成品報廢 | N18: 1200 | O18: =N18/$B$6 -> 0.0024 | P18: 900 | Q18: =IFERROR(P18/$B$6,"") -> 0.0018 | R18: 300 | S18: =IFERROR(R18/$B$6,"") -> 0.0006
M19: 半成品超用 | N19: 4500 | O19: =N19/$B$6 -> 0.009 | P19: 3500 | Q19: =IFERROR(P19/$B$6,"") -> 0.007 | R19: 1000 | S19: =IFERROR(R19/$B$6,"") -> 0.002
A20: （６）人時生產性前幾名品項
B21: 排名 | C21: 商品名 | F21: 人數 | G21: 產能 | H21: 人時生產性 | I21: 前月比 | J21: 主要原因&對策 | M21: （８）報廢原因別前幾名品項
A22: 飯糰 | B22: 1 | C22: 手巻明太子 | F22: 3 | G22: 3000 | H22: 1000 | I22: 10 | J22: 減少暫時停止生產,人時UP | M22: 半成品報廢 | N22: 排名 | O22: 商品名 | R22: 半成品名 | U22: 單價 | V22: 報廢率 | W22: 數量 | X22: 金額 | Y22: 前月比 | Z22: 主要原因&對策
B23: 2 | M23: 作業原因 | N23: 1 | O23: 明太子海苔便當 | R23: 油炸白身魚 | U23: 10 | V23: 0.15 | W23: 10 | X23: =W23*U23 -> 100 | Y23: 80 | Z23: 油調過多報廢。變更條件。
B24: 3 | N24: 2 | X24: =W24*U24 -> 0
B25: 4 | N25: 3 | X25: =W25*U25 -> 0
B26: 5 | N26: 4 | X26: =W26*U26 -> 0
B27: ▼1 | C27: 手巻卵黄雞絞肉 | F27: 4 | G27: 2800 | H27: 700 | I27: 6/30新商品 | J27: 因組裝2食材,人員增加,產速減少 | N27: 5 | X27: =W27*U27 -> 0
B28: ▼2 | U28: 前幾名合計比例 | V28: =X28/N18 -> 0.083333333 | W28: 前幾名合計金額 | X28: =SUM(X23:X27) -> 100
B29: ▼3 | M29: 規格原因 | N29: 1 | O29: 海老炒飯 | R29: 川燙蝦子拌醬 | U29: 5.55 | V29: 0.21 | W29: 50 | X29: =W29*U29 -> 277.5 | Y29: 35 | Z29: 蝦子入數不足
B30: ▼4 | N30: 2 | X30: =W30*U30 -> 0
B31: ▼5 | N31: 3 | X31: =W31*U31 -> 0
N32: 4 | X32: =W32*U32 -> 0
B33: 排名 | C33: 商品名 | F33: 人數 | G33: 產能 | H33: 人時生產性 | I33: 前月比 | J33: 主要原因&對策 | N33: 5 | X33: =W33*U33 -> 0
A34: 大口飯糰 | B34: 1 | C34: 直巻明太子美奶茲 | F34: 3 | G34: 2500 | H34: 833.33 | I34: 20 | J34: 透由調整速度提升。 | U34: 前幾名合計比例 | V34: =X34/N18 -> 0.23125 | W34: 前幾名合計金額 | X34: =SUM(X29:X33) -> 277.5
B35: 2
B36: 3 | M36: 半成品超用 | N36: 排名 | O36: 商品名 | R36: 半成品名 | U36: 單價 | V36: 報廢率 | W36: 數量 | X36: 金額 | Y36: 前月比 | Z36: 主要原因&對策
B37: 4 | M37: 作業原因 | N37: 1 | O37: 特製醬汁炙燒牛五花便當 | R37: 牛五花醬汁 | U37: 25 | V37: 0.25 | W37: 10 | X37: =W37*U37 -> 250 | Y37: 150 | Z37: 難度有差異。調理指導。
B38: 5 | N38: 2 | X38: =W38*U38 -> 0
B39: ▼1 | C39: 大口飯糰燒肉美奶滋 | F39: 7 | G39: 2200 | H39: 314.29 | I39: -15 | J39: 因摺疊增員。實施教育訓練。 | N39: 3 | X39: =W39*U39 -> 0
B40: ▼2 | N40: 4 | X40: =W40*U40 -> 0
B41: ▼3 | N41: 5 | X41: =W41*U41 -> 0
B42: ▼4 | U42: 前幾名合計比例 | V42: =X42/N19 -> 0.055555556 | W42: 前幾名合計金額 | X42: =SUM(X37:X41) -> 250
...

Sheet 生產管理報表(月)
A1: 生產管理報表
A3: 月別 | B3: 8 | C3: 工廠 | D3: 晉欣廠
A4: （１）收支狀況 | E4: ※單位：千元 | G4: （２）ＫＰＩ達成進度
A5: 項目 | B5: 當月 | C5: 前月 | D5: 差異 | E5: 累計 | G5: 項目 | H5: KPI | I5: 當月 | J5: 前月 | K5: 累計 | L5: ※補充
A6: 業績金額 | B6: ='（１）收支狀況'!H5/1000 -> 212376.15 | D6: =B6-C6 -> 212376.15 | E6: =B6 -> 212376.15 | G6: 人時性(個/月均) | H6: 266 | I6: ='（２）ＫＰＩ達成進度'!H5 -> 331.32088 | K6: =I6 -> 331.32088 | L6: 個／MH
A7: 訂單數量 | B7: ='（４）訂單數量構成比'!H7 -> 6558055 | D7: =B7-C7 -> 6558055 | E7: =B7 -> 6558055 | G7: 人時達成率(%/月均) | H7: 0.8 | I7: ='（２）ＫＰＩ達成進度'!K5 -> 0.90524832 | K7: =I7 -> 0.90524832 | L7: 達成率
A8: 材料費 | B8: ='（１）收支狀況'!N5/1000 -> 139088.16 | D8: =B8-C8 -> 139088.16 | E8: =B8 -> 139088.16 | G8: 半成品-報廢(%) | H8: 0.0025 | I8: ='（２）ＫＰＩ達成進度'!N5 -> 0.0024946244 | K8: =I8 -> 0.0024946244 | L8: 報廢率
A9: 材料費率 | B9: ='（１）收支狀況'!Q5 -> 0.65491423 | D9: =B9-C9 -> 0.65491423 | E9: =B9 -> 0.65491423 | G9: 半成品-超用(%) | H9: 0.0026 | I9: ='（２）ＫＰＩ達成進度'!Q5 -> 0.0023789152 | K9: =I9 -> 0.0023789152 | L9: 超用率
A10: 勞務成本 | B10: ='（１）收支狀況'!T5/1000 -> 30146.177 | D10: =B10-C10 -> 30146.177 | E10: =B10 -> 30146.177 | G10: 固定產線-導入率(%) | H10: 0.8 | I10: ='（２）ＫＰＩ達成進度'!T5 -> 0.91666667 | K10: =I10 -> 0.91666667 | L10: 導入率
A11: 勞務費率 | B11: ='（１）收支狀況'!W5 -> 0.14194709 | D11: =B11-C11 -> 0.14194709 | E11: =B11 -> 0.14194709 | G11: 教育訓練-實施率(%) | H11: 1 | I11: ='（２）ＫＰＩ達成進度'!W5 -> 0.67912903 | K11: =I11 -> 0.67912903 | L11: 實施率
A13: （３）業績構成比 | G13: （４）訂單數量構成比
B14: 當月 | C14: 比例 | D14: 前月 | E14: 差異 | H14: 當月 | I14: 比例 | J14: 前月 | K14: 差異
A15: 18℃-飯A15:A23糰(061,063) | B15: ='（３）業績構成比'!M46/1000 -> 40454.576 | C15: =IFERROR(B15/$B$6,"") -> 0.19048549 | E15: =IFERROR(C15-D15,"") -> 0.19048549 | G15: 18℃-飯A15:A23糰(061,063) | H15: ='（４）訂單數量構成比'!M46 -> 2176845 | I15: =IFERROR(H15/$B$7,"") -> 0.33193454 | K15: =IFERROR(I15-J15,"") -> 0.33193454
A16: 18℃-壽司手卷(071,072,075,076) | B16: ='（３）業績構成比'!S46/1000 -> 8499.4529 | C16: =IFERROR(B16/$B$6,"") -> 0.04002075 | E16: =IFERROR(C16-D16,"") -> 0.04002075 | G16: 18℃-壽司手卷(071,072,075,076) | H16: ='（４）訂單數量構成比'!S46 -> 330582 | I16: =IFERROR(H16/$B$7,"") -> 0.050408543 | K16: =IFERROR(I16-J16,"") -> 0.050408543
A17: 4℃-飯糰(065) | B17: ='（３）業績構成比'!U46/1000 -> 20818.277 | C17: =IFERROR(B17/$B$6,"") -> 0.098025494 | E17: =IFERROR(C17-D17,"") -> 0.098025494 | G17: 4℃-飯糰(065) | H17: ='（４）訂單數量構成比'!U46 -> 639734 | I17: =IFERROR(H17/$B$7,"") -> 0.09754935 | K17: =IFERROR(I17-J17,"") -> 0.09754935
A18: 4℃-壽司手卷(077) | B18: ='（３）業績構成比'!W46/1000 -> 491.81794 | C18: =IFERROR(B18/$B$6,"") -> 0.0023157871 | E18: =IFERROR(C18-D18,"") -> 0.0023157871 | G18: 4℃-壽司手卷(077) | H18: ='（４）訂單數量構成比'!W46 -> 18191 | I18: =IFERROR(H18/$B$7,"") -> 0.0027738407 | K18: =IFERROR(I18-J18,"") -> 0.0027738407
A19: 主食(091,092,093,094,095) | B19: ='（３）業績構成比'!AC46/1000 -> 56587.976 | C19: =IFERROR(B19/$B$6,"") -> 0.26645165 | E19: =IFERROR(C19-D19,"") -> 0.26645165 | G19: 主食(091,092,093,094,095) | H19: ='（４）訂單數量構成比'!AC46 -> 1374966 | I19: =IFERROR(H19/$B$7,"") -> 0.20966064 | K19: =IFERROR(I19-J19,"") -> 0.20966064
A20: 便當(083) | B20: ='（３）業績構成比'!AE46/1000 -> 25231.125 | C20: =IFERROR(B20/$B$6,"") -> 0.11880395 | E20: =IFERROR(C20-D20,"") -> 0.11880395 | G20: 便當(083) | H20: ='（４）訂單數量構成比'!AE46 -> 455610 | I20: =IFERROR(H20/$B$7,"") -> 0.069473342 | K20: =IFERROR(I20-J20,"") -> 0.069473342
A21: 熱食義麵(122,123,124,126) | B21: ='（３）業績構成比'!AG46/1000 -> 27837.423 | C21: =IFERROR(B21/$B$6,"") -> 0.13107603 | E21: =IFERROR(C21-D21,"") -> 0.13107603 | G21: 熱食義麵(122,123,124,126) | H21: ='（４）訂單數量構成比'!AG46 -> 576771 | I21: =IFERROR(H21/$B$7,"") -> 0.087948485 | K21: =IFERROR(I21-J21,"") -> 0.087948485
A22: 季節調理麵(111,112) | B22: ='（３）業績構成比'!AI46/1000 -> 19439.937 | C22: =IFERROR(B22/$B$6,"") -> 0.091535408 | E22: =IFERROR(C22-D22,"") -> 0.091535408 | G22: 季節調理麵(111,112) | H22: ='（４）訂單數量構成比'!AI46 -> 524524 | I22: =IFERROR(H22/$B$7,"") -> 0.079981641 | K22: =IFERROR(I22-J22,"") -> 0.079981641
A23: 微波小吃(153,154,155) | B23: ='（３）業績構成比'!AK46/1000 -> 13015.565 | C23: =IFERROR(B23/$B$6,"") -> 0.061285436 | E23: =IFERROR(C23-D23,"") -> 0.061285436 | G23: 微波小吃(153,154,155) | H23: ='（４）訂單數量構成比'!AK46 -> 460832 | I23: =IFERROR(H23/$B$7,"") -> 0.070269615 | K23: =IFERROR(I23-J23,"") -> 0.070269615
C24: =SUM(C15:C23) -> 1 | D24: =SUM(D15:D23) -> 0 | I24: =SUM(I15:I23) -> 1 | J24: =SUM(J15:J23) -> 0
A26: （５）品群別人時生產性
A27: 品群 | B27: 當月 | C27: 前月 | D27: 差異 | E27: 累計
A28: 18℃-飯A15:A23糰(061,063) | B28: ='（５-1）品群別人時生產性（18℃-飯糰）'!$C$1 -> 717.52753 | D28: 0 | E28: =B28 -> 717.52753
A29: 18℃-壽司手卷(071,072,075,076) | B29: ='（５-2）品群別人時生產性（18-壽司手卷)'!$C$1 -> 197.63272 | D29: 0 | E29: =B29 -> 197.63272
A30: 4℃-飯糰(065) | B30: ='（５-3）品群別人時生產性（4℃-飯糰)'!$C$1 -> 240.45857 | D30: 0 | E30: =B30 -> 240.45857
A31: 4℃-壽司手卷(077) | B31: ='（５-4）品群別人時生產性（4℃-壽司手卷)'!$C$1 -> 106.86512 | D31: 0 | E31: =B31 -> 106.86512
A32: 主食(091,092,093,094,095) | B32: ='（５-5）品群別人時生產性(主食) '!$C$1 -> 89.310428 | D32: 0 | E32: =B32 -> 89.310428
A33: 便當(083) | B33: ='（５-6）品群別人時生產性(便當)'!$C$1 -> 65.672742 | D33: 0 | E33: =B33 -> 65.672742
A34: 熱食義麵(122,123,124,126) | B34: ='（５-7）品群別人時生產性(熱食義麵) '!$C$1 -> 75.478569 | D34: 0 | E34: =B34 -> 75.478569
A35: 季節調理麵(111,112) | B35: ='（５-8）品群別人時生產性(季節調理麵) '!$C$1 -> 114.50557 | D35: 0 | E35: =B35 -> 114.50557
A36: 微波小吃(153,154,155) | B36: ='（５-9）品群別人時生產性(微波小吃)'!$C$1 -> 99.648342 | D36: 0 | E36: =B36 -> 99.648342

Sheet 生產管理報表(週) 
A1: 生產管理報表
A3: 月別 | B3: 8 | C3: 週別 | D3: W5 | E3: 工廠 | F3: 晉欣廠
A4: （１）收支狀況 | E4: ※單位：千元 | G4: （２）ＫＰＩ達成進度
A5: 項目 | B5: 當週 | C5: 前週 | D5: 差異 | E5: 累計 | G5: 項目 | H5: KPI | I5: 當週 | J5: 前週 | K5: 累計 | L5: ※補充
A6: 業績金額 | B6: ='（１）收支狀況'!G30/1000 -> 39181.352 | C6: 48798.227 | D6: =B6-C6 -> -9616.875 | E6: ='（１）收支狀況'!H5/1000 -> 212376.15 | G6: 人時性(個/月均) | H6: 266 | I6: ='（２）ＫＰＩ達成進度'!G30 -> 338.34123 | J6: 335.27143 | K6: ='（２）ＫＰＩ達成進度'!H5 -> 331.32088 | L6: 個／MH
A7: 訂單數量 | B7: ='（１）收支狀況'!J30 -> 1233798 | C7: 1526628 | D7: =B7-C7 -> -292830 | E7: ='（１）收支狀況'!K5 -> 6558055 | G7: 人時達成率(%/月均) | H7: 0.8 | I7: ='（２）ＫＰＩ達成進度'!J30 -> 0.9244296 | J7: 1.2580541 | K7: ='（２）ＫＰＩ達成進度'!K5 -> 0.90524832 | L7: 達成率
A8: 材料費 | B8: ='（１）收支狀況'!M30/1000 -> 25627.594 | C8: 32021.656 | D8: =B8-C8 -> -6394.062 | E8: ='（１）收支狀況'!N5/1000 -> 139088.16 | G8: 半成品-報廢(%) | H8: 0.0025 | I8: ='（２）ＫＰＩ達成進度'!M30 -> 0.0024445365 | J8: 0.0025001696 | K8: ='（２）ＫＰＩ達成進度'!N5 -> 0.0024946244 | L8: 報廢率
A9: 材料費率 | B9: ='（１）收支狀況'!P30 -> 0.65407631 | C9: 0.65620532 | D9: =B9-C9 -> -0.0021290101 | E9: ='（１）收支狀況'!Q5 -> 0.65491423 | G9: 半成品-超用(%) | H9: 0.0026 | I9: ='（２）ＫＰＩ達成進度'!P30 -> 0.0022832747 | J9: 0.0023270885 | K9: ='（２）ＫＰＩ達成進度'!Q5 -> 0.0023789152 | L9: 超用率
A10: 勞務成本 | B10: ='（１）收支狀況'!S30/1000 -> 5846.8136 | C10: 6898.7488 | D10: =B10-C10 -> -1051.9352 | E10: ='（１）收支狀況'!T5/1000 -> 30146.177 | G10: 固定產線-導入率(%) | H10: 0.8 | I10: 0.917 | J10: 0.917 | K10: 0.917 | L10: 導入率
A11: 勞務費率 | B11: ='（１）收支狀況'!V30 -> 0.1492244 | C11: 0.14137294 | D11: =B11-C11 -> 0.0078514567 | E11: ='（１）收支狀況'!W5 -> 0.14194709 | G11: 教育訓練-實施率(%) | H11: 1 | I11: ='（２）ＫＰＩ達成進度'!V30 -> 0.71033333 | J11: 0.69585714 | K11: ='（２）ＫＰＩ達成進度'!W5 -> 0.67912903 | L11: 實施率
A13: （３）業績構成比 | G13: （４）訂單數量構成比
B14: 當週 | C14: 比例 | D14: 前週 | E14: 差異 | H14: 當週 | I14: 比例 | J14: 前週 | K14: 差異
A15: 18℃-飯糰(061,063) | B15: =SUM('（３）業績構成比'!I32:I37,'（３）業績構成比'!K32:K37)/1000 -> 7797.1912 | C15: =IFERROR(B15/$B$6,"") -> 0.19900261 | D15: 0.19444348 | E15: =IFERROR(C15-D15,"") -> 0.0045591242 | G15: 18℃-飯糰(061,063) | H15: =SUM(,'（４）訂單數量構成比'!I32:I37,'（４）訂單數量構成比'!K32:K37) -> 425642 | I15: =IFERROR(H15/$B$7,"") -> 0.34498516 | J15: 0.33795659 | K15: =IFERROR(I15-J15,"") -> 0.0070285651
A16: 18℃-壽司手卷(071,072,075,076) | B16: =SUM('（３）業績構成比'!O32:O37,'（３）業績構成比'!Q32:Q37)/1000 -> 1664.1067 | C16: =IFERROR(B16/$B$6,"") -> 0.042471907 | D16: 0.044192215 | E16: =IFERROR(C16-D16,"") -> -0.0017203079 | G16: 18℃-壽司手卷(071,072,075,076) | H16: =SUM('（４）訂單數量構成比'!O32:O37,'（４）訂單數量構成比'!Q32:Q37) -> 64362 | I16: =IFERROR(H16/$B$7,"") -> 0.052165752 | J16: 0.054991786 | K16: =IFERROR(I16-J16,"") -> -0.0028260342
A17: 4℃-飯糰(065) | B17: =SUM('（３）業績構成比'!U32:U37)/1000 -> 3677.2412 | C17: =IFERROR(B17/$B$6,"") -> 0.093851821 | D17: 0.091697501 | E17: =IFERROR(C17-D17,"") -> 0.0021543199 | G17: 4℃-飯糰(065) | H17: =SUM('（４）訂單數量構成比'!U32:U37) -> 111910 | I17: =IFERROR(H17/$B$7,"") -> 0.090703665 | J17: 0.089911884 | K17: =IFERROR(I17-J17,"") -> 0.00079178039
A18: 4℃-壽司手卷(077) | B18: =SUM('（３）業績構成比'!W32:W37)/1000 -> 67.80207 | C18: =IFERROR(B18/$B$6,"") -> 0.0017304678 | D18: 0.0017420909 | E18: =IFERROR(C18-D18,"") -> -1.1623061e-05 | G18: 4℃-壽司手卷(077) | H18: =SUM('（４）訂單數量構成比'!W32:W37) -> 2559 | I18: =IFERROR(H18/$B$7,"") -> 0.0020740834 | J18: 0.0021013633 | K18: =IFERROR(I18-J18,"") -> -2.7279826e-05
A19: 主食(091,092,093,094,095) | B19: =SUM('（３）業績構成比'!Y32:Y37,'（３）業績構成比'!AA32:AA37)/1000 -> 10171.242 | C19: =IFERROR(B19/$B$6,"") -> 0.25959395 | D19: 0.25567189 | E19: =IFERROR(C19-D19,"") -> 0.0039220543 | G19: 主食(091,092,093,094,095) | H19: =SUM('（４）訂單數量構成比'!Y32:Y37,'（４）訂單數量構成比'!AA32:AA37) -> 250811 | I19: =IFERROR(H19/$B$7,"") -> 0.20328368 | J19: 0.20040573 | K19: =IFERROR(I19-J19,"") -> 0.002877951
A20: 便當(083) | B20: =SUM('（３）業績構成比'!AE32:AE37)/1000 -> 4282.0169 | C20: =IFERROR(B20/$B$6,"") -> 0.10928712 | D20: 0.11207897 | E20: =IFERROR(C20-D20,"") -> -0.0027918534 | G20: 便當(083) | H20: =SUM('（４）訂單數量構成比'!AE32:AE37) -> 78455 | I20: =IFERROR(H20/$B$7,"") -> 0.063588205 | J20: 0.06504204 | K20: =IFERROR(I20-J20,"") -> -0.0014538355
A21: 熱食義麵(122,123,124,126) | B21: =SUM('（３）業績構成比'!AG32:AG37)/1000 -> 5110.8428 | C21: =IFERROR(B21/$B$6,"") -> 0.1304407 | D21: 0.1392766 | E21: =IFERROR(C21-D21,"") -> -0.0088359076 | G21: 熱食義麵(122,123,124,126) | H21: =SUM('（４）訂單數量構成比'!AG32:AG37) -> 102742 | I21: =IFERROR(H21/$B$7,"") -> 0.083272951 | J21: 0.090392027 | K21: =IFERROR(I21-J21,"") -> -0.0071190767
A22: 季節調理麵(111,112) | B22: =SUM('（３）業績構成比'!AI32:AI37)/1000 -> 3681.6571 | C22: =IFERROR(B22/$B$6,"") -> 0.093964524 | D22: 0.088677963 | E22: =IFERROR(C22-D22,"") -> 0.0052865611 | G22: 季節調理麵(111,112) | H22: =SUM('（４）訂單數量構成比'!AI32:AI37) -> 100424 | I22: =IFERROR(H22/$B$7,"") -> 0.081394199 | J22: 0.077251957 | K22: =IFERROR(I22-J22,"") -> 0.0041422425
A23: 微波小吃(153,154,155) | B23: =SUM('（３）業績構成比'!AK32:AK37)/1000 -> 2729.2521 | C23: =IFERROR(B23/$B$6,"") -> 0.069656916 | D23: 0.072219283 | E23: =IFERROR(C23-D23,"") -> -0.0025623675 | G23: 微波小吃(153,154,155) | H23: =SUM('（４）訂單數量構成比'!AK32:AK37) -> 96893 | I23: =IFERROR(H23/$B$7,"") -> 0.078532304 | J23: 0.081946617 | K23: =IFERROR(I23-J23,"") -> -0.0034143127
C24: =SUM(C15:C23) -> 1 | D24: =SUM(D15:D23) -> 1 | I24: =SUM(I15:I23) -> 1 | J24: =SUM(J15:J23) -> 1
A26: （５）品群別人時生產性
A27: 品群 | B27: 當週 | C27: 前週 | D27: 差異 | E27: 累計
A28: 18℃-飯糰(061,063) | B28: ='（５-1）品群別人時生產性（18℃-飯糰）'!L147 -> 763.10229 | C28: 713.3324 | D28: =B28-C28 -> 49.76989 | E28: ='（５-1）品群別人時生產性（18℃-飯糰）'!C1 -> 717.52753
A29: 18℃-壽司手卷(071,072,075,076) | B29: ='（５-2）品群別人時生產性（18-壽司手卷)'!L87 -> 204.23333 | C29: 195.15465 | D29: =B29-C29 -> 9.0786719 | E29: ='（５-2）品群別人時生產性（18-壽司手卷)'!C1 -> 197.63272
A30: 4℃-飯糰(065) | B30: ='（５-3）品群別人時生產性（4℃-飯糰)'!L87 -> 249.11259 | C30: 241.43435 | D30: =B30-C30 -> 7.6782351 | E30: ='（５-3）品群別人時生產性（4℃-飯糰)'!C1 -> 240.45857
A31: 4℃-壽司手卷(077) | B31: ='（５-4）品群別人時生產性（4℃-壽司手卷)'!L87 -> 103.74359 | C31: 106.08791 | D31: =B31-C31 -> -2.3443223 | E31: ='（５-4）品群別人時生產性（4℃-壽司手卷)'!C1 -> 106.86512
A32: 主食(091,092,093,094,095) | B32: ='（５-5）品群別人時生產性(主食) '!L147 -> 93.01182 | C32: 90.927237 | D32: =B32-C32 -> 2.0845831 | E32: ='（５-5）品群別人時生產性(主食) '!C1 -> 89.310428
A33: 便當(083) | B33: ='（５-6）品群別人時生產性(便當)'!L87 -> 64.556754 | C33: 65.660495 | D33: =B33-C33 -> -1.1037409 | E33: ='（５-6）品群別人時生產性(便當)'!C1 -> 65.672742
A34: 熱食義麵(122,123,124,126) | B34: ='（５-7）品群別人時生產性(熱食義麵) '!L87 -> 87.311945 | C34: 73.563268 | D34: =B34-C34 -> 13.748677 | E34: ='（５-7）品群別人時生產性(熱食義麵) '!C1 -> 75.478569
A35: 季節調理麵(111,112) | B35: ='（５-8）品群別人時生產性(季節調理麵) '!L87 -> 116.96724 | C35: 115.96039 | D35: =B35-C35 -> 1.0068481 | E35: ='（５-8）品群別人時生產性(季節調理麵) '!C1 -> 114.50557
A36: 微波小吃(153,154,155) | B36: ='（５-9）品群別人時生產性(微波小吃)'!L87 -> 104.21393 | C36: 103.00021 | D36: =B36-C36 -> 1.2137197 | E36: ='（５-9）品群別人時生產性(微波小吃)'!C1 -> 99.648342

Sheet （１）收支狀況
B2: （１）收支狀況
B3: 資料繳交日 | C3: 月份 | D3: 日期 | F3: 營業額(元) | I3: 訂單數量(個) | L3: 材料費(元) | O3: 材料費率（材料費／營業額） | R3: 勞務成本（全廠人事成本） | U3: 勞務費率（勞務成本／營業額）
F4: 日 | G4: 週累積 | H4: 月累積 | I4: 日 | J4: 週累積 | K4: 月累積 | L4: 日 | M4: 週累積 | N4: 月累積 | O4: 日 | P4: 週累積 | Q4: 月累積 | R4: 日 | S4: 週累積 | T4: 月累積 | U4: 日 | V4: 週累積 | W4: 月累積
B5: =D17 -> 45882 | C5: 八 | D5: 45870 | E5: 五 | F5: 6238721 | G5: =SUM(F5:F8) -> 27719634 | H5: =SUM(F5:F35) -> 212376150 | I5: 189694 | J5: =SUM(I5:I8) -> 835562 | K5: =SUM(I5:I35) -> 6558055 | L5: 4328564 | M5: =SUM(L5:L8) -> 18071368 | N5: =SUM(L5:L35) -> 139088163 | O5: =L5/F5 -> 0.69382234 | P5: =M5/G5 -> 0.65193386 | Q5: =N5/H5 -> 0.65491423 | R5: 943023.35 | S5: =SUM(R5:R8) -> 3865161.5 | T5: =SUM(R5:R35) -> 30146177 | U5: =R5/F5 -> 0.15115652 | V5: =S5/G5 -> 0.13943768 | W5: =T5/H5 -> 0.14194709
D6: 45871 | E6: 六 | F6: 6562252 | I6: 198615 | L6: 4232726 | O6: =L6/F6 -> 0.64501119 | R6: 938418.88 | U6: =R6/F6 -> 0.14300257
D7: 45872 | E7: 日 | F7: 7531206 | I7: 226309 | L7: 4804413 | O7: =L7/F7 -> 0.63793408 | R7: 986964.21 | U7: =R7/F7 -> 0.13104996
D8: 45873 | E8: 一 | F8: 7387455 | I8: 220944 | L8: 4705665 | O8: =L8/F8 -> 0.63698053 | R8: 996755.08 | U8: =R8/F8 -> 0.13492537
D9: 45874 | E9: 二 | F9: 7967674 | G9: =SUM(F9:F15) -> 48153352 | I9: 237092 | J9: =SUM(I9:I15) -> 1481597 | L9: 5154252 | M9: =SUM(L9:L15) -> 31832447 | O9: =L9/F9 -> 0.64689544 | P9: =M9/G9 -> 0.66106399 | R9: 1013986.2 | S9: =SUM(R9:R15) -> 6693842.4 | U9: =R9/F9 -> 0.12726251 | V9: =S9/G9 -> 0.13901093
D10: 45875 | E10: 三 | F10: 7313533 | I10: 222453 | L10: 4928684 | O10: =L10/F10 -> 0.67391287 | R10: 978046.09 | U10: =R10/F10 -> 0.133731
D11: 45876 | E11: 四 | F11: 6849540 | I11: 211393 | L11: 4518685 | O11: =L11/F11 -> 0.65970635 | R11: 969314.06 | U11: =R11/F11 -> 0.14151521
D12: 45877 | E12: 五 | F12: 6028491 | I12: 189264 | L12: 4132693 | O12: =L12/F12 -> 0.68552694 | R12: 928029.26 | U12: =R12/F12 -> 0.15394056
D13: 45878 | E13: 六 | F13: 6203511 | I13: 192323 | L13: 4132318 | O13: =L13/F13 -> 0.66612568 | R13: 925688.35 | U13: =R13/F13 -> 0.14922007
D14: 45879 | E14: 日 | F14: 6959932 | I14: 216752 | L14: 4477956 | O14: =L14/F14 -> 0.64339077 | R14: 940286.83 | U14: =R14/F14 -> 0.1351
D15: 45880 | E15: 一 | F15: 6830671 | I15: 212320 | L15: 4487859 | O15: =L15/F15 -> 0.65701583 | R15: 938491.58 | U15: =R15/F15 -> 0.13739376
B16: =D24 -> 45889 | D16: 45881 | E16: 二 | F16: 7487435 | G16: =SUM(F16:F22) -> 48523585 | I16: 224380 | J16: =SUM(I16:I22) -> 1480470 | L16: 4856053 | M16: =SUM(L16:L22) -> 31535098 | O16: =L16/F16 -> 0.64856029 | P16: =M16/G16 -> 0.64989217 | R16: 983069.18 | S16: =SUM(R16:R22) -> 6841610.2 | U16: =R16/F16 -> 0.13129585 | V16: =S16/G16 -> 0.14099556
D17: 45882 | E17: 三 | F17: 7231344 | I17: 220130 | L17: 4546524 | O17: =L17/F17 -> 0.62872462 | R17: 985534.26 | U17: =R17/F17 -> 0.13628646
D18: 45883 | E18: 四 | F18: 7037093 | I18: 214387 | L18: 4629818 | O18: =L18/F18 -> 0.65791627 | R18: 991055.77 | U18: =R18/F18 -> 0.14083312
D19: 45884 | E19: 五 | F19: 6388038 | I19: 194099 | L19: 4187375 | O19: =L19/F19 -> 0.65550252 | R19: 982289.15 | U19: =R19/F19 -> 0.15377009
D20: 45885 | E20: 六 | F20: 6365900 | I20: 193782 | L20: 4221117 | O20: =L20/F20 -> 0.66308252 | R20: 964177.16 | U20: =R20/F20 -> 0.15145968
D21: 45886 | E21: 日 | F21: 7153920 | I21: 218883 | L21: 4622586 | O21: =L21/F21 -> 0.64616127 | R21: 959179.65 | U21: =R21/F21 -> 0.13407749
D22: 45887 | E22: 一 | F22: 6859855 | I22: 214809 | L22: 4471625 | O22: =L22/F22 -> 0.65185416 | R22: 976304.98 | U22: =R22/F22 -> 0.14232152
B23: =D31 -> 45896 | D23: 45888 | E23: 二 | F23: 7669791 | G23: =SUM(F23:F29) -> 48798227 | I23: 237868 | J23: =SUM(I23:I29) -> 1526628 | L23: 5123124 | M23: =SUM(L23:L29) -> 32021656 | O23: =L23/F23 -> 0.66796136 | P23: =M23/G23 -> 0.65620532 | R23: 986490.34 | S23: =SUM(R23:R29) -> 6898748.8 | U23: =R23/F23 -> 0.12862024 | V23: =S23/G23 -> 0.14137294
D24: 45889 | E24: 三 | F24: 7361858 | I24: 229442 | L24: 4636620 | O24: =L24/F24 -> 0.62981655 | R24: 983128.49 | U24: =R24/F24 -> 0.13354353
D25: 45890 | E25: 四 | F25: 7002876 | I25: 218054 | L25: 4532763 | O25: =L25/F25 -> 0.64727164 | R25: 968897.68 | U25: =R25/F25 -> 0.13835711
D26: 45891 | E26: 五 | F26: 6204031 | I26: 195390 | L26: 4156769 | O26: =L26/F26 -> 0.670011 | R26: 992349.54 | U26: =R26/F26 -> 0.15995238
D27: 45892 | E27: 六 | F27: 6323179 | I27: 198181 | L27: 4318835 | O27: =L27/F27 -> 0.68301641 | R27: 990699.66 | U27: =R27/F27 -> 0.15667747
D28: 45893 | E28: 日 | F28: 7218612 | I28: 227099 | L28: 4527394 | O28: =L28/F28 -> 0.62718345 | R28: 988981.44 | U28: =R28/F28 -> 0.13700438
D29: 45894 | E29: 一 | F29: 7017880 | I29: 220594 | L29: 4726151 | O29: =L29/F29 -> 0.67344426 | R29: 988201.65 | U29: =R29/F29 -> 0.14081199
B30: =D38 -> 45903 | D30: 45895 | E30: 二 | F30: 6875105 | G30: =SUM(F30:F36) -> 39181352 | I30: 215808 | J30: =SUM(I30:I36) -> 1233798 | L30: 4445363 | M30: =SUM(L30:L36) -> 25627594 | O30: =L30/F30 -> 0.64658838 | P30: =M30/G30 -> 0.65407631 | R30: 993229.01 | S30: =SUM(R30:R36) -> 5846813.6 | U30: =R30/F30 -> 0.14446747 | V30: =S30/G30 -> 0.1492244
D31: 45896 | E31: 三 | F31: 6713523 | I31: 211789 | L31: 4375267 | O31: =L31/F31 -> 0.65170954 | R31: 975476.53 | U31: =R31/F31 -> 0.14530024
D32: 45897 | E32: 四 | F32: 6453701 | I32: 204538 | L32: 4275402 | O32: =L32/F32 -> 0.6624729 | R32: 984413.34 | U32: =R32/F32 -> 0.1525347
D33: 45898 | E33: 五 | F33: 5903385 | I33: 187591 | L33: 3865422 | O33: =L33/F33 -> 0.6547806 | R33: 962941.29 | U33: =R33/F33 -> 0.1631168
D34: 45899 | E34: 六 | F34: 6221025 | I34: 193659 | L34: 4192354 | O34: =L34/F34 -> 0.67390084 | R34: 950874.71 | U34: =R34/F34 -> 0.15284856
D35: 45900 | E35: 日 | F35: 7014613 | I35: 220413 | L35: 4473786 | O35: =L35/F35 -> 0.63778087 | R35: 979878.72 | U35: =R35/F35 -> 0.13969106
D36: 45901 | E36: 一 | O36: =L36/F36 -> #DIV/0!
D37: 45902 | E37: 二 | G37: =SUM(F37:F43) -> 0 | J37: =SUM(I37:I43) -> 0 | M37: =SUM(L37:L43) -> 0 | O37: =L37/F37 -> #DIV/0! | P37: =M37/G37 -> #DIV/0! | S37: =SUM(R37:R43) -> 0 | V37: =SUM(U37:U43) -> 0
D38: 45903 | E38: 三 | O38: =L38/F38 -> #DIV/0!
D39: 45904 | E39: 四 | O39: =L39/F39 -> #DIV/0!
D40: 45905 | E40: 五 | O40: =L40/F40 -> #DIV/0!
D41: 45906 | E41: 六 | O41: =L41/F41 -> #DIV/0!
...

Sheet （２）ＫＰＩ達成進度
B1: KPI | C1: 366
B2: （２）ＫＰＩ達成進度
B3: 資料繳交日 | C3: 月份 | D3: 日期 | F3: 人時生產性(個/人) | I3: 人時生產性達成率(%) | L3: 半成品報廢(%) | O3: 半成品超用(%) | R3: 固定產線-導入率(固定產線數/總產線數) | U3: 教育訓練-實施率(進度/計畫)
F4: 日 | G4: 週平均 | H4: 月平均 | I4: 日 | J4: 週平均 | K4: 月平均 | L4: 日 | M4: 週平均 | N4: 月平均 | O4: 日 | P4: 週平均 | Q4: 月平均 | R4: 日 | S4: 週平均 | T4: 月平均 | U4: 日 | V4: 週平均 | W4: 月平均
B5: =D17 -> 45882 | C5: 八 | D5: 45870 | E5: 五 | F5: 323.2 | G5: =AVERAGE(F5:F8) -> 323.2 | H5: =AVERAGE(F5:F35) -> 331.32088 | I5: =F5/$C$1 -> 0.88306011 | J5: =AVERAGE(I5:I8) -> 0.88306011 | K5: =AVERAGE(I5:I35) -> 0.90524832 | L5: 0.0025117077 | M5: =AVERAGE(L5:L8) -> 0.0024983247 | N5: =AVERAGE(L5:L35) -> 0.0024946244 | O5: 0.002999903 | P5: =AVERAGE(O5:O8) -> 0.0025091067 | Q5: =AVERAGE(O5:O35) -> 0.0023789152 | R5: =11/12 -> 0.91666667 | S5: =AVERAGE(R5:R8) -> 0.91666667 | T5: =AVERAGE(R5:R35) -> 0.91666667 | U5: 0.62 | V5: =AVERAGE(U5:U8) -> 0.625 | W5: =AVERAGE(U5:U35) -> 0.67912903
D6: 45871 | E6: 六 | F6: 319.2 | I6: =F6/$C$1 -> 0.87213115 | L6: 0.002468592 | O6: 0.0028443956 | R6: =11/12 -> 0.91666667 | U6: 0.62
D7: 45872 | E7: 日 | F7: 320.9 | I7: =F7/$C$1 -> 0.87677596 | L7: 0.0024820518 | O7: 0.0021361567 | R7: =11/12 -> 0.91666667 | U7: 0.63
D8: 45873 | E8: 一 | F8: 329.5 | I8: =F8/$C$1 -> 0.90027322 | L8: 0.0025309471 | O8: 0.0020559715 | R8: =11/12 -> 0.91666667 | U8: 0.63
D9: 45874 | E9: 二 | F9: 330.6 | G9: =AVERAGE(F9:F15) -> 328.97143 | I9: =F9/$C$1 -> 0.90327869 | J9: =AVERAGE(I9:I15) -> 0.89882904 | L9: 0.0024806626 | M9: =AVERAGE(L9:L15) -> 0.0025106738 | O9: 0.0020747828 | P9: =AVERAGE(O9:O15) -> 0.0024001339 | R9: =11/12 -> 0.91666667 | S9: =AVERAGE(R9:R15) -> 0.91666667 | U9: 0.635 | V9: =AVERAGE(U9:U15) -> 0.66
D10: 45875 | E10: 三 | F10: 329.4 | I10: =F10/$C$1 -> 0.9 | L10: 0.0024885303 | O10: 0.0024893285 | R10: =11/12 -> 0.91666667 | U10: 0.65
D11: 45876 | E11: 四 | F11: 331.8 | I11: =F11/$C$1 -> 0.90655738 | L11: 0.002511329 | O11: 0.0022021476 | R11: =11/12 -> 0.91666667 | U11: 0.66
D12: 45877 | E12: 五 | F12: 327.6 | I12: =F12/$C$1 -> 0.89508197 | L12: 0.0025100673 | O12: 0.0026764289 | R12: =11/12 -> 0.91666667 | U12: 0.66
D13: 45878 | E13: 六 | F13: 327 | I13: =F13/$C$1 -> 0.89344262 | L13: 0.0025210535 | O13: 0.0028191053 | R13: =11/12 -> 0.91666667 | U13: 0.67
D14: 45879 | E14: 日 | F14: 330.9 | I14: =F14/$C$1 -> 0.90409836 | L14: 0.0025324776 | O14: 0.0022019356 | R14: =11/12 -> 0.91666667 | U14: 0.67
D15: 45880 | E15: 一 | F15: 325.5 | I15: =F15/$C$1 -> 0.88934426 | L15: 0.0025305966 | O15: 0.0023372087 | R15: =11/12 -> 0.91666667 | U15: 0.675
B16: =D24 -> 45889 | D16: 45881 | E16: 二 | F16: 326.1 | G16: =AVERAGE(F16:F22) -> 328.34286 | I16: =F16/$C$1 -> 0.89098361 | J16: =AVERAGE(I16:I22) -> 0.89711163 | L16: 0.002479823 | M16: =AVERAGE(L16:L22) -> 0.0025138479 | O16: 0.0022799124 | P16: =AVERAGE(O16:O22) -> 0.0024171057 | R16: =11/12 -> 0.91666667 | S16: =AVERAGE(R16:R22) -> 0.91666667 | U16: 0.68 | V16: =AVERAGE(U16:U22) -> 0.68571429
D17: 45882 | E17: 三 | F17: 331.8 | I17: =F17/$C$1 -> 0.90655738 | L17: 0.0024907161 | O17: 0.0024630926 | R17: =11/12 -> 0.91666667 | U17: 0.68
D18: 45883 | E18: 四 | F18: 326.6 | I18: =F18/$C$1 -> 0.89234973 | L18: 0.0025108283 | O18: 0.002472546 | R18: =11/12 -> 0.91666667 | U18: 0.68
D19: 45884 | E19: 五 | F19: 332.3 | I19: =F19/$C$1 -> 0.9079235 | L19: 0.0025132368 | O19: 0.0025667444 | R19: =11/12 -> 0.91666667 | U19: 0.69
D20: 45885 | E20: 六 | F20: 325.6 | I20: =F20/$C$1 -> 0.88961749 | L20: 0.0025209124 | O20: 0.00251042 | R20: =11/12 -> 0.91666667 | U20: 0.69
D21: 45886 | E21: 日 | F21: 327.6 | I21: =F21/$C$1 -> 0.89508197 | L21: 0.0025325514 | O21: 0.0022401803 | R21: =11/12 -> 0.91666667 | U21: 0.69
D22: 45887 | E22: 一 | F22: 328.4 | I22: =F22/$C$1 -> 0.89726776 | L22: 0.0025488676 | O22: 0.0023868442 | R22: =11/12 -> 0.91666667 | U22: 0.69
B23: =D31 -> 45896 | D23: 45888 | E23: 二 | F23: 333.7 | G23: =AVERAGE(F23:F29) -> 335.27143 | I23: =F23/$C$1 -> 0.91174863 | J23: =AVERAGE(I23:I29) -> 0.91604215 | L23: 0.0024754769 | M23: =AVERAGE(L23:L29) -> 0.0025001696 | O23: 0.0022714493 | P23: =AVERAGE(O23:O29) -> 0.0023270885 | R23: =11/12 -> 0.91666667 | S23: =AVERAGE(R23:R29) -> 0.91666667 | U23: 0.69 | V23: =AVERAGE(U23:U29) -> 0.69585714
D24: 45889 | E24: 三 | F24: 334.1 | I24: =F24/$C$1 -> 0.91284153 | L24: 0.0025144124 | O24: 0.002165809 | R24: =11/12 -> 0.91666667 | U24: 0.69
D25: 45890 | E25: 四 | F25: 340 | I25: =F25/$C$1 -> 0.92896175 | L25: 0.0025342309 | O25: 0.002217703 | R25: =11/12 -> 0.91666667 | U25: 0.695
D26: 45891 | E26: 五 | F26: 330.2 | I26: =F26/$C$1 -> 0.90218579 | L26: 0.0024972691 | O26: 0.0025154403 | R26: =11/12 -> 0.91666667 | U26: 0.695
D27: 45892 | E27: 六 | F27: 333.2 | I27: =F27/$C$1 -> 0.91038251 | L27: 0.0024895345 | O27: 0.0025103538 | R27: =11/12 -> 0.91666667 | U27: 0.7
D28: 45893 | E28: 日 | F28: 337.2 | I28: =F28/$C$1 -> 0.92131148 | L28: 0.0025185436 | O28: 0.0023235667 | R28: =11/12 -> 0.91666667 | U28: 0.7
D29: 45894 | E29: 一 | F29: 338.5 | I29: =F29/$C$1 -> 0.92486339 | L29: 0.0024717196 | O29: 0.0022852972 | R29: =11/12 -> 0.91666667 | U29: 0.701
B30: =D38 -> 45903 | D30: 45895 | E30: 二 | F30: 330.16744 | G30: =AVERAGE(F30:F36) -> 338.34123 | I30: =F30/$C$1 -> 0.90209682 | J30: =AVERAGE(I30:I36) -> 0.9244296 | L30: 0.0024688309 | M30: =AVERAGE(L30:L36) -> 0.0024445365 | O30: 0.0023625366 | P30: =AVERAGE(O30:O36) -> 0.0022832747 | R30: =11/12 -> 0.91666667 | S30: =AVERAGE(R30:R36) -> 0.91666667 | U30: 0.701 | V30: =AVERAGE(U30:U36) -> 0.71033333
D31: 45896 | E31: 三 | F31: 337.73305 | I31: =F31/$C$1 -> 0.9227679 | L31: 0.0025111525 | O31: 0.0023225024 | R31: =11/12 -> 0.91666667 | U31: 0.701
D32: 45897 | E32: 四 | F32: 362.18425 | I32: =F32/$C$1 -> 0.98957445 | L32: 0.002507462 | O32: 0.0023385481 | R32: =11/12 -> 0.91666667 | U32: 0.71
D33: 45898 | E33: 五 | F33: 335.46477 | I33: =F33/$C$1 -> 0.91657041 | L33: 0.0024989334 | O33: 0.0025849009 | R33: =11/12 -> 0.91666667 | U33: 0.71
D34: 45899 | E34: 六 | F34: 331.23588 | I34: =F34/$C$1 -> 0.90501606 | L34: 0.0021813294 | O34: 0.0020831805 | R34: =11/12 -> 0.91666667 | U34: 0.72
D35: 45900 | E35: 日 | F35: 333.26201 | I35: =F35/$C$1 -> 0.91055194 | L35: 0.0024995108 | O35: 0.00200798 | R35: =11/12 -> 0.91666667 | U35: 0.72
D36: 45901 | E36: 一
D37: 45902 | E37: 二 | G37: =AVERAGE(F37:F43) -> #DIV/0! | J37: =AVERAGE(I37:I43) -> #DIV/0! | M37: =AVERAGE(L37:L43) -> #DIV/0! | P37: =AVERAGE(O37:O43) -> #DIV/0! | S37: =AVERAGE(R37:R43) -> #DIV/0! | V37: =AVERAGE(U37:U43) -> #DIV/0!
D38: 45903 | E38: 三
D39: 45904 | E39: 四
D40: 45905 | E40: 五
...

Sheet （３）業績構成比
B2: （3）業績構成比
B3: 資料繳交日 | C3: 月份 | D3: 日期 | F3: 營業額 | I3: 品類業績
I4: 18℃-飯糰 | O4: 18℃-壽司手卷 | U4: 4℃-飯糰 | W4: 4℃-壽司手卷 | Y4: 主食 | AE4: 便當 | AG4: 熱食義麵 | AI4: 季節調理麵 | AK4: 微波小吃
F5: 日 | G5: 週累積 | H5: 月累積 | I5: 一配 | K5: 二配 | M5: 合計 | O5: 一配 | Q5: 二配 | S5: 合計 | U5: 一配 | W5: 一配 | Y5: 一配 | AA5: 二配 | AC5: 合計 | AE5: 一配 | AG5: 一配 | AI5: 一配 | AK5: 一配
I6: 業績(元) | J6: 比例(%) | K6: 業績(元) | L6: 比例(%) | M6: 業績(元) | N6: 比例(%) | O6: 業績(元) | P6: 比例(%) | Q6: 業績(元) | R6: 比例(%) | S6: 業績(元) | T6: 比例(%) | U6: 業績(元) | V6: 比例(%) | W6: 業績(元) | X6: 比例(%) | Y6: 業績(元) | Z6: 比例(%) | AA6: 業績(元) | AB6: 比例(%) | AC6: 業績(元) | AD6: 比例(%) | AE6: 業績(元) | AF6: 比例(%) | AG6: 業績(元) | AH6: 比例(%) | AI6: 業績(元) | AJ6: 比例(%) | AK6: 業績(元) | AL6: 比例(%)
B7: =D19 -> 45882 | C7: 八 | D7: 45870 | E7: 五 | F7: =SUM(M7,S7,U7,W7,AC7,AE7,AG7,AI7,AK7) -> 6238721 | G7: =SUM(F7:F10) -> 27719634 | H7: =SUM(F7:F37) -> 212376150 | I7: 460351.7 | J7: =I7/$F7 -> 0.073789435 | K7: 693287.53 | L7: =K7/$F7 -> 0.11112655 | M7: =SUM(I7+K7) -> 1153639.2 | N7: =M7/$F7 -> 0.18491598 | O7: 137104.25 | P7: =O7/$F7 -> 0.021976339 | Q7: 111569.65 | R7: =Q7/$F7 -> 0.017883417 | S7: =SUM(O7+Q7) -> 248673.9 | T7: =S7/$F7 -> 0.039859757 | U7: 584777.06 | V7: =U7/$F7 -> 0.093733484 | W7: 29842.929 | X7: =W7/$F7 -> 0.0047835011 | Y7: 555162.57 | Z7: =Y7/$F7 -> 0.088986599 | AA7: 1091012.2 | AB7: =AA7/$F7 -> 0.17487754 | AC7: =SUM(Y7+AA7) -> 1646174.8 | AD7: =AC7/$F7 -> 0.26386414 | AE7: 845899.79 | AF7: =AE7/F7 -> 0.13558866 | AG7: 729805.08 | AH7: =AG7/F7 -> 0.11697992 | AI7: 648633.45 | AJ7: =AI7/F7 -> 0.10396898 | AK7: 351274.81 | AL7: =AK7/F7 -> 0.056305581
D8: 45871 | E8: 六 | F8: =SUM(M8,S8,U8,W8,AC8,AE8,AG8,AI8,AK8) -> 6562252 | I8: 451183.47 | J8: =I8/F8 -> 0.068754366 | K8: 750326.8 | L8: =K8/F8 -> 0.11433983 | M8: =SUM(I8+K8) -> 1201510.3 | N8: =M8/F8 -> 0.1830942 | O8: 138472.77 | P8: =O8/F8 -> 0.02110141 | Q8: 109730.43 | R8: =Q8/$F8 -> 0.016721459 | S8: =SUM(O8+Q8) -> 248203.19 | T8: =S8/F8 -> 0.037822868 | U8: 637083.78 | V8: =U8/F8 -> 0.097083102 | W8: 31992.391 | X8: =W8/F8 -> 0.0048752152 | Y8: 592645.44 | Z8: =Y8/F8 -> 0.09031129 | AA8: 1191918.8 | AB8: =AA8/$F8 -> 0.18163258 | AC8: =SUM(Y8+AA8) -> 1784564.2 | AD8: =AC8/F8 -> 0.27194387 | AE8: 865122.14 | AF8: =AE8/F8 -> 0.13183312 | AG8: 762782.7 | AH8: =AG8/F8 -> 0.11623795 | AI8: 672816.42 | AJ8: =AI8/F8 -> 0.10252828 | AK8: 358176.9 | AL8: =AK8/F8 -> 0.0545814
D9: 45872 | E9: 日 | F9: =SUM(M9,S9,U9,W9,AC9,AE9,AG9,AI9,AK9) -> 7531206 | I9: 547613.1 | J9: =I9/F9 -> 0.072712537 | K9: 792821.74 | L9: =K9/F9 -> 0.10527155 | M9: =SUM(I9+K9) -> 1340434.8 | N9: =M9/F9 -> 0.17798409 | O9: 166503.65 | P9: =O9/F9 -> 0.022108497 | Q9: 123789.32 | R9: =Q9/$F9 -> 0.016436852 | S9: =SUM(O9+Q9) -> 290292.97 | T9: =S9/F9 -> 0.038545349 | U9: 764518.16 | V9: =U9/F9 -> 0.10151338 | W9: 36401.381 | X9: =W9/F9 -> 0.0048334067 | Y9: 632029.54 | Z9: =Y9/F9 -> 0.083921425 | AA9: 1243905.9 | AB9: =AA9/$F9 -> 0.16516689 | AC9: =SUM(Y9+AA9) -> 1875935.4 | AD9: =AC9/F9 -> 0.24908831 | AE9: 1088217.5 | AF9: =AE9/F9 -> 0.14449446 | AG9: 954793.09 | AH9: =AG9/F9 -> 0.12677825 | AI9: 770955.77 | AJ9: =AI9/F9 -> 0.10236817 | AK9: 409656.86 | AL9: =AK9/F9 -> 0.05439459
D10: 45873 | E10: 一 | F10: =SUM(M10,S10,U10,W10,AC10,AE10,AG10,AI10,AK10) -> 7387455 | I10: 527064.59 | J10: =I10/F10 -> 0.071345896 | K10: 775570.16 | L10: =K10/F10 -> 0.10498476 | M10: =SUM(I10+K10) -> 1302634.8 | N10: =M10/F10 -> 0.17633065 | O10: 155828.97 | P10: =O10/F10 -> 0.021093729 | Q10: 122876.16 | R10: =Q10/$F10 -> 0.016633084 | S10: =SUM(O10+Q10) -> 278705.13 | T10: =S10/F10 -> 0.037726813 | U10: 731978.07 | V10: =U10/F10 -> 0.09908393 | W10: 33244.716 | X10: =W10/F10 -> 0.0045001581 | Y10: 655973.36 | Z10: =Y10/F10 -> 0.088795582 | AA10: 1278728.5 | AB10: =AA10/$F10 -> 0.17309459 | AC10: =SUM(Y10+AA10) -> 1934701.8 | AD10: =AC10/F10 -> 0.26189017 | AE10: 1084705.9 | AF10: =AE10/F10 -> 0.1468308 | AG10: 943304.52 | AH10: =AG10/F10 -> 0.12769005 | AI10: 679572.81 | AJ10: =AI10/F10 -> 0.091990112 | AK10: 398607.27 | AL10: =AK10/F10 -> 0.05395732
D11: 45874 | E11: 二 | F11: =SUM(M11,S11,U11,W11,AC11,AE11,AG11,AI11,AK11) -> 7967674 | G11: =SUM(F11:F17) -> 48153352 | I11: 588097.61 | J11: =I11/F11 -> 0.073810451 | K11: 773398.49 | L11: =K11/F11 -> 0.097067035 | M11: =SUM(I11+K11) -> 1361496.1 | N11: =M11/F11 -> 0.17087749 | O11: 155327.19 | P11: =O11/F11 -> 0.019494672 | Q11: 120159.87 | R11: =Q11/$F11 -> 0.015080922 | S11: =SUM(O11+Q11) -> 275487.06 | T11: =S11/F11 -> 0.034575593 | U11: 844784.96 | V11: =U11/F11 -> 0.10602655 | W11: 17264.6 | X11: =W11/F11 -> 0.0021668307 | Y11: 1098875 | Z11: =Y11/F11 -> 0.13791666 | AA11: 1257542 | AB11: =AA11/$F11 -> 0.15783051 | AC11: =SUM(Y11+AA11) -> 2356417 | AD11: =AC11/F11 -> 0.29574717 | AE11: 1102785.5 | AF11: =AE11/F11 -> 0.13840746 | AG11: 934645.05 | AH11: =AG11/F11 -> 0.11730463 | AI11: 683690.99 | AJ11: =AI11/F11 -> 0.085808103 | AK11: 391102.75 | AL11: =AK11/F11 -> 0.049086189
D12: 45875 | E12: 三 | F12: =SUM(M12,S12,U12,W12,AC12,AE12,AG12,AI12,AK12) -> 7313533 | I12: 568466.36 | J12: =I12/F12 -> 0.07772801 | K12: 770103.71 | L12: =K12/F12 -> 0.10529845 | M12: =SUM(I12+K12) -> 1338570.1 | N12: =M12/F12 -> 0.18302646 | O12: 154078.89 | P12: =O12/F12 -> 0.021067641 | Q12: 118660.19 | R12: =Q12/$F12 -> 0.016224742 | S12: =SUM(O12+Q12) -> 272739.07 | T12: =S12/F12 -> 0.037292383 | U12: 765121.05 | V12: =U12/F12 -> 0.10461716 | W12: 18856.173 | X12: =W12/F12 -> 0.0025782577 | Y12: 906317.98 | Z12: =Y12/F12 -> 0.12392341 | AA12: 1172639 | AB12: =AA12/$F12 -> 0.16033824 | AC12: =SUM(Y12+AA12) -> 2078957 | AD12: =AC12/F12 -> 0.28426165 | AE12: 905933.31 | AF12: =AE12/F12 -> 0.12387082 | AG12: 936490.42 | AH12: =AG12/F12 -> 0.12804898 | AI12: 600419.6 | AJ12: =AI12/F12 -> 0.082097066 | AK12: 396446.34 | AL12: =AK12/F12 -> 0.054207227
D13: 45876 | E13: 四 | F13: =SUM(M13,S13,U13,W13,AC13,AE13,AG13,AI13,AK13) -> 6849540 | I13: 555011.39 | J13: =I13/F13 -> 0.081029002 | K13: 747275.49 | L13: =K13/F13 -> 0.10909864 | M13: =SUM(I13+K13) -> 1302286.9 | N13: =M13/F13 -> 0.19012764 | O13: 148311.83 | P13: =O13/F13 -> 0.021652817 | Q13: 113722.3 | R13: =Q13/$F13 -> 0.01660291 | S13: =SUM(O13+Q13) -> 262034.13 | T13: =S13/F13 -> 0.038255727 | U13: 734422.27 | V13: =U13/F13 -> 0.10722213 | W13: 18720.731 | X13: =W13/F13 -> 0.002733137 | Y13: 807904.82 | Z13: =Y13/F13 -> 0.11795023 | AA13: 1022028.5 | AB13: =AA13/$F13 -> 0.14921126 | AC13: =SUM(Y13+AA13) -> 1829933.3 | AD13: =AC13/F13 -> 0.26716149 | AE13: 847604.45 | AF13: =AE13/F13 -> 0.12374619 | AG13: 879842.73 | AH13: =AG13/F13 -> 0.12845282 | AI13: 598863.2 | AJ13: =AI13/F13 -> 0.087431156 | AK13: 375832.32 | AL13: =AK13/F13 -> 0.054869717
D14: 45877 | E14: 五 | F14: =SUM(M14,S14,U14,W14,AC14,AE14,AG14,AI14,AK14) -> 6028491 | I14: 496338.67 | J14: =I14/F14 -> 0.082332158 | K14: 707672.44 | L14: =K14/F14 -> 0.11738799 | M14: =SUM(I14+K14) -> 1204011.1 | N14: =M14/F14 -> 0.19972015 | O14: 129409.85 | P14: =O14/F14 -> 0.021466375 | Q14: 107645.26 | R14: =Q14/$F14 -> 0.017856088 | S14: =SUM(O14+Q14) -> 237055.11 | T14: =S14/F14 -> 0.039322463 | U14: 646701.73 | V14: =U14/F14 -> 0.10727423 | W14: 17062.801 | X14: =W14/F14 -> 0.0028303602 | Y14: 660019.93 | Z14: =Y14/F14 -> 0.10948344 | AA14: 985617.94 | AB14: =AA14/$F14 -> 0.16349331 | AC14: =SUM(Y14+AA14) -> 1645637.9 | AD14: =AC14/F14 -> 0.27297675 | AE14: 694834.18 | AF14: =AE14/F14 -> 0.11525839 | AG14: 682038.66 | AH14: =AG14/F14 -> 0.11313588 | AI14: 558792.51 | AJ14: =AI14/F14 -> 0.092691937 | AK14: 342357.02 | AL14: =AK14/F14 -> 0.056789837
D15: 45878 | E15: 六 | F15: =SUM(M15,S15,U15,W15,AC15,AE15,AG15,AI15,AK15) -> 6203511 | I15: 476683.17 | J15: =I15/F15 -> 0.076840868 | K15: 757212.94 | L15: =K15/F15 -> 0.122062 | M15: =SUM(I15+K15) -> 1233896.1 | N15: =M15/F15 -> 0.19890286 | O15: 130154.49 | P15: =O15/F15 -> 0.020980778 | Q15: 108343.59 | R15: =Q15/$F15 -> 0.017464882 | S15: =SUM(O15+Q15) -> 238498.07 | T15: =S15/F15 -> 0.03844566 | U15: 677203.79 | V15: =U15/F15 -> 0.1091646 | W15: 14888.362 | X15: =W15/F15 -> 0.0023999896 | Y15: 666656.12 | Z15: =Y15/F15 -> 0.10746432 | AA15: 1075048.8 | AB15: =AA15/$F15 -> 0.17329684 | AC15: =SUM(Y15+AA15) -> 1741705 | AD15: =AC15/F15 -> 0.28076116 | AE15: 686858.9 | AF15: =AE15/F15 -> 0.11072099 | AG15: 664889.2 | AH15: =AG15/F15 -> 0.1071795 | AI15: 604376.54 | AJ15: =AI15/F15 -> 0.097424916 | AK15: 341195.07 | AL15: =AK15/F15 -> 0.055000317
D16: 45879 | E16: 日 | F16: =SUM(M16,S16,U16,W16,AC16,AE16,AG16,AI16,AK16) -> 6959932 | I16: 579957.52 | J16: =I16/F16 -> 0.083328044 | K16: 800683.84 | L16: =K16/F16 -> 0.11504191 | M16: =SUM(I16+K16) -> 1380641.4 | N16: =M16/F16 -> 0.19836995 | O16: 159336.96 | P16: =O16/F16 -> 0.022893465 | Q16: 120225.97 | R16: =Q16/$F16 -> 0.017274015 | S16: =SUM(O16+Q16) -> 279562.93 | T16: =S16/F16 -> 0.04016748 | U16: 782722.64 | V16: =U16/F16 -> 0.11246125 | W16: 14095.087 | X16: =W16/F16 -> 0.0020251759 | Y16: 700085.96 | Z16: =Y16/F16 -> 0.10058805 | AA16: 1081221 | AB16: =AA16/$F16 -> 0.15534937 | AC16: =SUM(Y16+AA16) -> 1781307 | AD16: =AC16/F16 -> 0.25593742 | AE16: 842001.04 | AF16: =AE16/F16 -> 0.12097834 | AG16: 872019.59 | AH16: =AG16/F16 -> 0.1252914 | AI16: 618960.1 | AJ16: =AI16/F16 -> 0.088931918 | AK16: 388622.23 | AL16: =AK16/F16 -> 0.055837072
D17: 45880 | E17: 一 | F17: =SUM(M17,S17,U17,W17,AC17,AE17,AG17,AI17,AK17) -> 6830671 | I17: 566289.2 | J17: =I17/F17 -> 0.082903891 | K17: 780782.44 | L17: =K17/F17 -> 0.11430538 | M17: =SUM(I17+K17) -> 1347071.6 | N17: =M17/F17 -> 0.19720927 | O17: 152894.74 | P17: =O17/F17 -> 0.022383561 | Q17: 119116.23 | R17: =Q17/$F17 -> 0.017438438 | S17: =SUM(O17+Q17) -> 272010.97 | T17: =S17/F17 -> 0.039821998 | U17: 741852.65 | V17: =U17/F17 -> 0.10860612 | W17: 14439.566 | X17: =W17/F17 -> 0.0021139309 | Y17: 711543.46 | Z17: =Y17/F17 -> 0.1041689 | AA17: 1109054.7 | AB17: =AA17/$F17 -> 0.16236395 | AC17: =SUM(Y17+AA17) -> 1820598.2 | AD17: =AC17/F17 -> 0.26653284 | AE17: 800327.47 | AF17: =AE17/F17 -> 0.11716674 | AG17: 845054.32 | AH17: =AG17/F17 -> 0.12371469 | AI17: 614864.35 | AJ17: =AI17/F17 -> 0.09001522 | AK17: 374451.87 | AL17: =AK17/F17 -> 0.054819193
B18: =D26 -> 45889 | D18: 45881 | E18: 二 | F18: =SUM(M18,S18,U18,W18,AC18,AE18,AG18,AI18,AK18) -> 7487435 | G18: =SUM(F18:F24) -> 48523585 | I18: 558887.26 | J18: =I18/F18 -> 0.074643354 | K18: 750498.56 | L18: =K18/F18 -> 0.1002344 | M18: =SUM(I18+K18) -> 1309385.8 | N18: =M18/F18 -> 0.17487776 | O18: 145970.83 | P18: =O18/F18 -> 0.019495438 | Q18: 114367.46 | R18: =Q18/$F18 -> 0.015274584 | S18: =SUM(O18+Q18) -> 260338.28 | T18: =S18/F18 -> 0.034770022 | U18: 712087.61 | V18: =U18/F18 -> 0.095104346 | W18: 13413.744 | X18: =W18/F18 -> 0.0017915006 | Y18: 955512.41 | Z18: =Y18/F18 -> 0.12761545 | AA18: 1148666.4 | AB18: =AA18/$F18 -> 0.15341253 | AC18: =SUM(Y18+AA18) -> 2104178.8 | AD18: =AC18/F18 -> 0.28102798 | AE18: 859219.62 | AF18: =AE18/F18 -> 0.11475487 | AG18: 1218740.7 | AH18: =AG18/F18 -> 0.16277146 | AI18: 625894.26 | AJ18: =AI18/F18 -> 0.083592614 | AK18: 384176.18 | AL18: =AK18/F18 -> 0.051309451
D19: 45882 | E19: 三 | F19: =SUM(M19,S19,U19,W19,AC19,AE19,AG19,AI19,AK19) -> 7231344 | I19: 542562.8 | J19: =I19/F19 -> 0.075029316 | K19: 753469.59 | L19: =K19/F19 -> 0.10419496 | M19: =SUM(I19+K19) -> 1296032.4 | N19: =M19/F19 -> 0.17922428 | O19: 139640.65 | P19: =O19/F19 -> 0.019310469 | Q19: 115956.22 | R19: =Q19/$F19 -> 0.016035225 | S19: =SUM(O19+Q19) -> 255596.87 | T19: =S19/F19 -> 0.035345694 | U19: 725374.59 | V19: =U19/F19 -> 0.10030979 | W19: 13676.706 | X19: =W19/F19 -> 0.0018913091 | Y19: 894731.27 | Z19: =Y19/F19 -> 0.1237296 | AA19: 1107829.7 | AB19: =AA19/$F19 -> 0.15319832 | AC19: =SUM(Y19+AA19) -> 2002561 | AD19: =AC19/F19 -> 0.27692791 | AE19: 839308.3 | AF19: =AE19/F19 -> 0.11606533 | AG19: 1058187.5 | AH19: =AG19/F19 -> 0.14633345 | AI19: 650806.96 | AJ19: =AI19/F19 -> 0.089998064 | AK19: 389799.63 | AL19: =AK19/F19 -> 0.053904175
D20: 45883 | E20: 四 | F20: =SUM(M20,S20,U20,W20,AC20,AE20,AG20,AI20,AK20) -> 7037093 | I20: 553845.52 | J20: =I20/F20 -> 0.078703738 | K20: 738498.32 | L20: =K20/F20 -> 0.10494366 | M20: =SUM(I20+K20) -> 1292343.8 | N20: =M20/F20 -> 0.1836474 | O20: 142847.73 | P20: =O20/F20 -> 0.020299253 | Q20: 114503.49 | R20: =Q20/$F20 -> 0.016271419 | S20: =SUM(O20+Q20) -> 257351.22 | T20: =S20/F20 -> 0.036570672 | U20: 690536.37 | V20: =U20/F20 -> 0.098128072 | W20: 13623.003 | X20: =W20/F20 -> 0.001935885 | Y20: 807947.04 | Z20: =Y20/F20 -> 0.11481261 | AA20: 1116490.7 | AB20: =AA20/$F20 -> 0.15865794 | AC20: =SUM(Y20+AA20) -> 1924437.7 | AD20: =AC20/F20 -> 0.27347055 | AE20: 803753.08 | AF20: =AE20/F20 -> 0.11421663 | AG20: 1007468.4 | AH20: =AG20/F20 -> 0.14316543 | AI20: 668860.72 | AJ20: =AI20/F20 -> 0.095047873 | AK20: 378718.63 | AL20: =AK20/F20 -> 0.053817483
D21: 45884 | E21: 五 | F21: =SUM(M21,S21,U21,W21,AC21,AE21,AG21,AI21,AK21) -> 6388038 | I21: 471450.92 | J21: =I21/F21 -> 0.073802148 | K21: 686358.99 | L21: =K21/F21 -> 0.10744441 | M21: =SUM(I21+K21) -> 1157809.9 | N21: =M21/F21 -> 0.18124656 | O21: 124873.81 | P21: =O21/F21 -> 0.019548069 | Q21: 104864.12 | R21: =Q21/$F21 -> 0.016415701 | S21: =SUM(O21+Q21) -> 229737.93 | T21: =S21/F21 -> 0.035963771 | U21: 609363.61 | V21: =U21/F21 -> 0.095391357 | W21: 12509.094 | X21: =W21/F21 -> 0.0019582059 | Y21: 764495.15 | Z21: =Y21/F21 -> 0.11967605 | AA21: 1141615.4 | AB21: =AA21/$F21 -> 0.17871142 | AC21: =SUM(Y21+AA21) -> 1906110.5 | AD21: =AC21/F21 -> 0.29838747 | AE21: 724592.66 | AF21: =AE21/F21 -> 0.11342961 | AG21: 792884.96 | AH21: =AG21/F21 -> 0.12412026 | AI21: 596864.24 | AJ21: =AI21/F21 -> 0.093434673 | AK21: 358165.07 | AL21: =AK21/F21 -> 0.056068086
D22: 45885 | E22: 六 | F22: =SUM(M22,S22,U22,W22,AC22,AE22,AG22,AI22,AK22) -> 6365900 | I22: 458402.27 | J22: =I22/F22 -> 0.072009028 | K22: 738962.5 | L22: =K22/F22 -> 0.11608139 | M22: =SUM(I22+K22) -> 1197364.8 | N22: =M22/F22 -> 0.18809042 | O22: 124808.75 | P22: =O22/F22 -> 0.019605829 | Q22: 104024.37 | R22: =Q22/$F22 -> 0.016340875 | S22: =SUM(O22+Q22) -> 228833.12 | T22: =S22/F22 -> 0.035946703 | U22: 600837.63 | V22: =U22/F22 -> 0.094383769 | W22: 13246.387 | X22: =W22/F22 -> 0.002080835 | Y22: 740381.55 | Z22: =Y22/F22 -> 0.1163043 | AA22: 1106517.5 | AB22: =AA22/$F22 -> 0.17381949 | AC22: =SUM(Y22+AA22) -> 1846899.1 | AD22: =AC22/F22 -> 0.29012379 | AE22: 731987.3 | AF22: =AE22/F22 -> 0.11498567 | AG22: 846969.11 | AH22: =AG22/F22 -> 0.13304782 | AI22: 551276.21 | AJ22: =AI22/F22 -> 0.086598315 | AK22: 348486.41 | AL22: =AK22/F22 -> 0.054742677
D23: 45886 | E23: 日 | F23: =SUM(M23,S23,U23,W23,AC23,AE23,AG23,AI23,AK23) -> 7153920 | I23: 564087.8 | J23: =I23/F23 -> 0.078850169 | K23: 792939.4 | L23: =K23/F23 -> 0.11083985 | M23: =SUM(I23+K23) -> 1357027.2 | N23: =M23/F23 -> 0.18969002 | O23: 156340.67 | P23: =O23/F23 -> 0.021853847 | Q23: 117704.57 | R23: =Q23/$F23 -> 0.016453157 | S23: =SUM(O23+Q23) -> 274045.24 | T23: =S23/F23 -> 0.038307004 | U23: 717127.54 | V23: =U23/F23 -> 0.1002426 | W23: 12745.484 | X23: =W23/F23 -> 0.0017816085 | Y23: 770890.62 | Z23: =Y23/F23 -> 0.10775779 | AA23: 1093785 | AB23: =AA23/$F23 -> 0.15289309 | AC23: =SUM(Y23+AA23) -> 1864675.6 | AD23: =AC23/F23 -> 0.26065088 | AE23: 884052.99 | AF23: =AE23/F23 -> 0.12357602 | AG23: 1017835.3 | AH23: =AG23/F23 -> 0.14227658 | AI23: 636158.51 | AJ23: =AI23/F23 -> 0.088924465 | AK23: 390252.2 | AL23: =AK23/F23 -> 0.05455082
D24: 45887 | E24: 一 | F24: =SUM(M24,S24,U24,W24,AC24,AE24,AG24,AI24,AK24) -> 6859855 | I24: 559286.05 | J24: =I24/F24 -> 0.081530302 | K24: 833445.2 | L24: =K24/F24 -> 0.12149604 | M24: =SUM(I24+K24) -> 1392731.2 | N24: =M24/F24 -> 0.20302634 | O24: 149464.12 | P24: =O24/F24 -> 0.021788233 | Q24: 120215.06 | R24: =Q24/$F24 -> 0.017524432 | S24: =SUM(O24+Q24) -> 269679.18 | T24: =S24/F24 -> 0.039312665 | U24: 699866.89 | V24: =U24/F24 -> 0.10202357 | W24: 12981.771 | X24: =W24/F24 -> 0.0018924264 | Y24: 731613.51 | Z24: =Y24/F24 -> 0.10665145 | AA24: 1063991.6 | AB24: =AA24/$F24 -> 0.15510409 | AC24: =SUM(Y24+AA24) -> 1795605.1 | AD24: =AC24/F24 -> 0.26175554 | AE24: 872648.98 | AF24: =AE24/F24 -> 0.12721099 | AG24: 782377.15 | AH24: =AG24/F24 -> 0.11405156 | AI24: 649146.42 | AJ24: =AI24/F24 -> 0.094629758 | AK24: 384818.29 | AL24: =AK24/F24 -> 0.056097147
B25: =D33 -> 45896 | D25: 45888 | E25: 二 | F25: =SUM(M25,S25,U25,W25,AC25,AE25,AG25,AI25,AK25) -> 7669791 | G25: =SUM(F25:F31) -> 48798227 | I25: 607919.47 | J25: =I25/F25 -> 0.079261543 | K25: 832702.4 | L25: =K25/F25 -> 0.10856911 | M25: =SUM(I25+K25) -> 1440621.9 | N25: =M25/F25 -> 0.18783065 | O25: 224155.31 | P25: =O25/F25 -> 0.029225738 | Q25: 123513.28 | R25: =Q25/$F25 -> 0.016103865 | S25: =SUM(O25+Q25) -> 347668.59 | T25: =S25/F25 -> 0.045329604 | U25: 690915.54 | V25: =U25/F25 -> 0.090082707 | W25: 13253.035 | X25: =W25/F25 -> 0.0017279525 | Y25: 765839.81 | Z25: =Y25/F25 -> 0.099851458 | AA25: 1077776.6 | AB25: =AA25/$F25 -> 0.14052229 | AC25: =SUM(Y25+AA25) -> 1843616.4 | AD25: =AC25/F25 -> 0.24037374 | AE25: 856379.76 | AF25: =AE25/F25 -> 0.11165621 | AG25: 1231516.7 | AH25: =AG25/F25 -> 0.16056718 | AI25: 609285.3 | AJ25: =AI25/F25 -> 0.079439623 | AK25: 636533.84 | AL25: =AK25/F25 -> 0.082992331
D26: 45889 | E26: 三 | F26: =SUM(M26,S26,U26,W26,AC26,AE26,AG26,AI26,AK26) -> 7361858 | I26: 594546.06 | J26: =I26/F26 -> 0.080760327 | K26: 830968.78 | L26: =K26/F26 -> 0.11287487 | M26: =SUM(I26+K26) -> 1425514.8 | N26: =M26/F26 -> 0.1936352 | O26: 196772.43 | P26: =O26/F26 -> 0.026728636 | Q26: 120856.2 | R26: =Q26/$F26 -> 0.016416535 | S26: =SUM(O26+Q26) -> 317628.63 | T26: =S26/F26 -> 0.043145172 | U26: 685874.37 | V26: =U26/F26 -> 0.093165934 | W26: 12905.885 | X26: =W26/F26 -> 0.0017530744 | Y26: 764276.21 | Z26: =Y26/F26 -> 0.10381567 | AA26: 1068327.2 | AB26: =AA26/$F26 -> 0.14511651 | AC26: =SUM(Y26+AA26) -> 1832603.4 | AD26: =AC26/F26 -> 0.24893218 | AE26: 835491.41 | AF26: =AE26/F26 -> 0.1134892 | AG26: 1044244.4 | AH26: =AG26/F26 -> 0.14184523 | AI26: 678370.87 | AJ26: =AI26/F26 -> 0.092146693 | AK26: 529224.18 | AL26: =AK26/F26 -> 0.071887312
D27: 45890 | E27: 四 | F27: =SUM(M27,S27,U27,W27,AC27,AE27,AG27,AI27,AK27) -> 7002876 | I27: 568728.19 | J27: =I27/F27 -> 0.081213518 | K27: 780398.67 | L27: =K27/F27 -> 0.11143974 | M27: =SUM(I27+K27) -> 1349126.9 | N27: =M27/F27 -> 0.19265326 | O27: 185478.54 | P27: =O27/F27 -> 0.026486052 | Q27: 121450.38 | R27: =Q27/$F27 -> 0.017342929 | S27: =SUM(O27+Q27) -> 306928.92 | T27: =S27/F27 -> 0.043828982 | U27: 643674.21 | V27: =U27/F27 -> 0.091915694 | W27: 11872.642 | X27: =W27/F27 -> 0.0016953952 | Y27: 726904.73 | Z27: =Y27/F27 -> 0.10380089 | AA27: 999381.41 | AB27: =AA27/$F27 -> 0.14271014 | AC27: =SUM(Y27+AA27) -> 1726286.1 | AD27: =AC27/F27 -> 0.24651103 | AE27: 810524.18 | AF27: =AE27/F27 -> 0.11574162 | AG27: 999965.11 | AH27: =AG27/F27 -> 0.14279349 | AI27: 652636.93 | AJ27: =AI27/F27 -> 0.093195557 | AK27: 501860.99 | AL27: =AK27/F27 -> 0.071664984
D28: 45891 | E28: 五 | F28: =SUM(M28,S28,U28,W28,AC28,AE28,AG28,AI28,AK28) -> 6204031 | I28: 499996.83 | J28: =I28/F28 -> 0.080592252 | K28: 731141.66 | L28: =K28/F28 -> 0.11784945 | M28: =SUM(I28+K28) -> 1231138.5 | N28: =M28/F28 -> 0.1984417 | O28: 173126.79 | P28: =O28/F28 -> 0.027905533 | Q28: 104751.3 | R28: =Q28/$F28 -> 0.016884393 | S28: =SUM(O28+Q28) -> 277878.09 | T28: =S28/F28 -> 0.044789926 | U28: 555001.45 | V28: =U28/F28 -> 0.0894582 | W28: 11208.88 | X28: =W28/F28 -> 0.0018067092 | Y28: 658869.67 | Z28: =Y28/F28 -> 0.10620025 | AA28: 1002788.2 | AB28: =AA28/$F28 -> 0.16163494 | AC28: =SUM(Y28+AA28) -> 1661657.8 | AD28: =AC28/F28 -> 0.26783519 | AE28: 665464.14 | AF28: =AE28/F28 -> 0.10726319 | AG28: 813011 | AH28: =AG28/F28 -> 0.13104561 | AI28: 554084.81 | AJ28: =AI28/F28 -> 0.089310452 | AK28: 434586.31 | AL28: =AK28/F28 -> 0.070049023
D29: 45892 | E29: 六 | F29: =SUM(M29,S29,U29,W29,AC29,AE29,AG29,AI29,AK29) -> 6323179 | I29: 481953.15 | J29: =I29/F29 -> 0.076220071 | K29: 765037.78 | L29: =K29/F29 -> 0.12098942 | M29: =SUM(I29+K29) -> 1246990.9 | N29: =M29/F29 -> 0.19720949 | O29: 168482.61 | P29: =O29/F29 -> 0.026645239 | Q29: 105779.12 | R29: =Q29/$F29 -> 0.016728788 | S29: =SUM(O29+Q29) -> 274261.73 | T29: =S29/F29 -> 0.043374026 | U29: 552843.19 | V29: =U29/F29 -> 0.08743121 | W29: 11709.925 | X29: =W29/F29 -> 0.0018519047 | Y29: 662479.35 | Z29: =Y29/F29 -> 0.10476998 | AA29: 1080025.8 | AB29: =AA29/$F29 -> 0.17080425 | AC29: =SUM(Y29+AA29) -> 1742505.2 | AD29: =AC29/F29 -> 0.27557423 | AE29: 676673.09 | AF29: =AE29/F29 -> 0.1070147 | AG29: 836437.22 | AH29: =AG29/F29 -> 0.13228112 | AI29: 539013.59 | AJ29: =AI29/F29 -> 0.085244083 | AK29: 442744.15 | AL29: =AK29/F29 -> 0.070019234
D30: 45893 | E30: 日 | F30: =SUM(M30,S30,U30,W30,AC30,AE30,AG30,AI30,AK30) -> 7218612 | I30: 591387.07 | J30: =I30/F30 -> 0.081925316 | K30: 825455.84 | L30: =K30/F30 -> 0.11435105 | M30: =SUM(I30+K30) -> 1416842.9 | N30: =M30/F30 -> 0.19627636 | O30: 214795.81 | P30: =O30/F30 -> 0.029755833 | Q30: 117310.17 | R30: =Q30/$F30 -> 0.01625107 | S30: =SUM(O30+Q30) -> 332105.99 | T30: =S30/F30 -> 0.046006903 | U30: 674550.39 | V30: =U30/F30 -> 0.093445997 | W30: 12454.029 | X30: =W30/F30 -> 0.0017252664 | Y30: 743647.64 | Z30: =Y30/F30 -> 0.10301809 | AA30: 1093643 | AB30: =AA30/$F30 -> 0.15150323 | AC30: =SUM(Y30+AA30) -> 1837290.7 | AD30: =AC30/F30 -> 0.25452132 | AE30: 825284.16 | AF30: =AE30/F30 -> 0.11432726 | AG30: 970670.92 | AH30: =AG30/F30 -> 0.13446781 | AI30: 648153.02 | AJ30: =AI30/F30 -> 0.089789148 | AK30: 501259.91 | AL30: =AK30/F30 -> 0.069439929
D31: 45894 | E31: 一 | F31: =SUM(M31,S31,U31,W31,AC31,AE31,AG31,AI31,AK31) -> 7017880 | I31: 573896.01 | J31: =I31/F31 -> 0.081776265 | K31: 804365.33 | L31: =K31/F31 -> 0.11461657 | M31: =SUM(I31+K31) -> 1378261.3 | N31: =M31/F31 -> 0.19639283 | O31: 182922.48 | P31: =O31/F31 -> 0.026065204 | Q31: 117107.31 | R31: =Q31/$F31 -> 0.016686992 | S31: =SUM(O31+Q31) -> 300029.78 | T31: =S31/F31 -> 0.042752196 | U31: 671816.31 | V31: =U31/F31 -> 0.095729238 | W31: 11606.551 | X31: =W31/F31 -> 0.0016538543 | Y31: 735581.79 | Z31: =Y31/F31 -> 0.10481538 | AA31: 1096793.7 | AB31: =AA31/$F31 -> 0.15628561 | AC31: =SUM(Y31+AA31) -> 1832375.5 | AD31: =AC31/F31 -> 0.261101 | AE31: 799438.21 | AF31: =AE31/F31 -> 0.11391449 | AG31: 900605.92 | AH31: =AG31/F31 -> 0.1283302 | AI31: 645782.83 | AJ31: =AI31/F31 -> 0.092019645 | AK31: 477963.59 | AL31: =AK31/F31 -> 0.068106549
B32: =D40 -> 45903 | D32: 45895 | E32: 二 | F32: =SUM(M32,S32,U32,W32,AC32,AE32,AG32,AI32,AK32) -> 6875105 | G32: =SUM(F32:F38) -> 39181352 | I32: 567336.53 | J32: =I32/F32 -> 0.082520417 | K32: 785905.27 | L32: =K32/F32 -> 0.11431175 | M32: =SUM(I32+K32) -> 1353241.8 | N32: =M32/F32 -> 0.19683216 | O32: 178593 | P32: =O32/F32 -> 0.025976766 | Q32: 111805.19 | R32: =Q32/$F32 -> 0.016262325 | S32: =SUM(O32+Q32) -> 290398.19 | T32: =S32/F32 -> 0.042239091 | U32: 642657.91 | V32: =U32/F32 -> 0.093476086 | W32: 11632.639 | X32: =W32/F32 -> 0.0016919944 | Y32: 723887.3 | Z32: =Y32/F32 -> 0.10529109 | AA32: 1051236.7 | AB32: =AA32/$F32 -> 0.15290482 | AC32: =SUM(Y32+AA32) -> 1775124 | AD32: =AC32/F32 -> 0.25819591 | AE32: 744155.79 | AF32: =AE32/F32 -> 0.10823919 | AG32: 967152.27 | AH32: =AG32/F32 -> 0.14067455 | AI32: 634965.37 | AJ32: =AI32/F32 -> 0.092357189 | AK32: 455777.07 | AL32: =AK32/F32 -> 0.066293834
D33: 45896 | E33: 三 | F33: =SUM(M33,S33,U33,W33,AC33,AE33,AG33,AI33,AK33) -> 6713523 | I33: 558111.33 | J33: =I33/F33 -> 0.083132408 | K33: 774715.06 | L33: =K33/F33 -> 0.1153962 | M33: =SUM(I33+K33) -> 1332826.4 | N33: =M33/F33 -> 0.19852861 | O33: 177569.34 | P33: =O33/F33 -> 0.026449502 | Q33: 109021.94 | R33: =Q33/$F33 -> 0.016239154 | S33: =SUM(O33+Q33) -> 286591.27 | T33: =S33/F33 -> 0.042688656 | U33: 624839.98 | V33: =U33/F33 -> 0.093071846 | W33: 10969.953 | X33: =W33/F33 -> 0.0016340084 | Y33: 696526.39 | Z33: =Y33/F33 -> 0.10374976 | AA33: 988183.68 | AB33: =AA33/$F33 -> 0.14719301 | AC33: =SUM(Y33+AA33) -> 1684710.1 | AD33: =AC33/F33 -> 0.25094277 | AE33: 744162.89 | AF33: =AE33/F33 -> 0.11084536 | AG33: 921233.63 | AH33: =AG33/F33 -> 0.1372206 | AI33: 645587.96 | AJ33: =AI33/F33 -> 0.096162322 | AK33: 462600.85 | AL33: =AK33/F33 -> 0.068905826
D34: 45897 | E34: 四 | F34: =SUM(M34,S34,U34,W34,AC34,AE34,AG34,AI34,AK34) -> 6453701 | I34: 551600.36 | J34: =I34/F34 -> 0.085470394 | K34: 741958.15 | L34: =K34/F34 -> 0.1149663 | M34: =SUM(I34+K34) -> 1293558.5 | N34: =M34/F34 -> 0.2004367 | O34: 172267.07 | P34: =O34/F34 -> 0.026692756 | Q34: 110101.01 | R34: =Q34/$F34 -> 0.017060136 | S34: =SUM(O34+Q34) -> 282368.08 | T34: =S34/F34 -> 0.043752892 | U34: 604268.75 | V34: =U34/F34 -> 0.093631352 | W34: 11076.179 | X34: =W34/F34 -> 0.0017162523 | Y34: 672617.99 | Z34: =Y34/F34 -> 0.10422206 | AA34: 959144.2 | AB34: =AA34/$F34 -> 0.14861925 | AC34: =SUM(Y34+AA34) -> 1631762.2 | AD34: =AC34/F34 -> 0.25284131 | AE34: 712515.59 | AF34: =AE34/F34 -> 0.11040418 | AG34: 846602.66 | AH34: =AG34/F34 -> 0.13118095 | AI34: 612473.93 | AJ34: =AI34/F34 -> 0.094902744 | AK34: 459075.1 | AL34: =AK34/F34 -> 0.071133618
D35: 45898 | E35: 五 | F35: =SUM(M35,S35,U35,W35,AC35,AE35,AG35,AI35,AK35) -> 5903385 | I35: 473553.86 | J35: =I35/F35 -> 0.080217344 | K35: 714232.31 | L35: =K35/F35 -> 0.12098691 | M35: =SUM(I35+K35) -> 1187786.2 | N35: =M35/F35 -> 0.20120425 | O35: 149093.94 | P35: =O35/F35 -> 0.02525567 | Q35: 99985.105 | R35: =Q35/$F35 -> 0.016936911 | S35: =SUM(O35+Q35) -> 249079.05 | T35: =S35/F35 -> 0.042192581 | U35: 545246.71 | V35: =U35/F35 -> 0.092361707 | W35: 10491.548 | X35: =W35/F35 -> 0.0017772088 | Y35: 620397.51 | Z35: =Y35/F35 -> 0.10509183 | AA35: 957112.05 | AB35: =AA35/$F35 -> 0.16212936 | AC35: =SUM(Y35+AA35) -> 1577509.6 | AD35: =AC35/F35 -> 0.26722119 | AE35: 614474.3 | AF35: =AE35/F35 -> 0.10408847 | AG35: 720171.36 | AH35: =AG35/F35 -> 0.12199295 | AI35: 581403.31 | AJ35: =AI35/F35 -> 0.098486429 | AK35: 417222.99 | AL35: =AK35/F35 -> 0.070675212
D36: 45899 | E36: 六 | F36: =SUM(M36,S36,U36,W36,AC36,AE36,AG36,AI36,AK36) -> 6221025 | I36: 464629.46 | J36: =I36/F36 -> 0.074686962 | K36: 770618.94 | L36: =K36/F36 -> 0.12387331 | M36: =SUM(I36+K36) -> 1235248.4 | N36: =M36/F36 -> 0.19856027 | O36: 148810.34 | P36: =O36/F36 -> 0.02392055 | Q36: 101640.76 | R36: =Q36/$F36 -> 0.016338266 | S36: =SUM(O36+Q36) -> 250451.1 | T36: =S36/F36 -> 0.040258815 | U36: 581812.31 | V36: =U36/F36 -> 0.093523545 | W36: 11523.486 | X36: =W36/F36 -> 0.0018523452 | Y36: 622788.96 | Z36: =Y36/F36 -> 0.10011035 | AA36: 1093062.6 | AB36: =AA36/$F36 -> 0.17570459 | AC36: =SUM(Y36+AA36) -> 1715851.6 | AD36: =AC36/F36 -> 0.27581493 | AE36: 675209.57 | AF36: =AE36/F36 -> 0.10853671 | AG36: 733348.32 | AH36: =AG36/F36 -> 0.11788223 | AI36: 588342.06 | AJ36: =AI36/F36 -> 0.094573171 | AK36: 429238.17 | AL36: =AK36/F36 -> 0.068997982
D37: 45900 | E37: 日 | F37: =SUM(M37,S37,U37,W37,AC37,AE37,AG37,AI37,AK37) -> 7014613 | I37: 577642.99 | J37: =I37/F37 -> 0.082348519 | K37: 816886.95 | L37: =K37/F37 -> 0.11645503 | M37: =SUM(I37+K37) -> 1394529.9 | N37: =M37/F37 -> 0.19880355 | O37: 190884.6 | P37: =O37/F37 -> 0.027212421 | Q37: 114334.44 | R37: =Q37/$F37 -> 0.016299466 | S37: =SUM(O37+Q37) -> 305219.05 | T37: =S37/F37 -> 0.043511887 | U37: 678415.55 | V37: =U37/F37 -> 0.096714609 | W37: 12108.264 | X37: =W37/F37 -> 0.0017261486 | Y37: 720560.87 | Z37: =Y37/F37 -> 0.10272283 | AA37: 1065723.6 | AB37: =AA37/$F37 -> 0.15192906 | AC37: =SUM(Y37+AA37) -> 1786284.4 | AD37: =AC37/F37 -> 0.25465189 | AE37: 791498.77 | AF37: =AE37/F37 -> 0.1128357 | AG37: 922334.57 | AH37: =AG37/F37 -> 0.13148759 | AI37: 618884.45 | AJ37: =AI37/F37 -> 0.088227882 | AK37: 505337.95 | AL37: =AK37/F37 -> 0.072040745
D38: 45901 | E38: 一 | F38: =SUM(M38,S38,U38,W38,AC38,AE38,AG38,AI38,AK38) -> 0 | J38: =I38/F38 -> #DIV/0! | L38: =K38/F38 -> #DIV/0! | M38: =SUM(I38+K38) -> 0 | N38: =M38/F38 -> #DIV/0! | P38: =O38/F38 -> #DIV/0! | R38: =Q38/$F38 -> #DIV/0! | S38: =SUM(O38+Q38) -> 0 | T38: =S38/F38 -> #DIV/0! | V38: =U38/F38 -> #DIV/0! | X38: =W38/F38 -> #DIV/0! | Z38: =Y38/F38 -> #DIV/0! | AB38: =AA38/$F38 -> #DIV/0! | AC38: =SUM(Y38+AA38) -> 0 | AD38: =AC38/F38 -> #DIV/0! | AF38: =AE38/F38 -> #DIV/0! | AH38: =AG38/F38 -> #DIV/0! | AJ38: =AI38/F38 -> #DIV/0! | AL38: =AK38/F38 -> #DIV/0!
D39: 45902 | E39: 二 | F39: =SUM(M39,S39,U39,W39,AC39,AE39,AG39,AI39,AK39) -> 0 | G39: =SUM(F39:F45) -> 0 | J39: =I39/F39 -> #DIV/0! | L39: =K39/F39 -> #DIV/0! | M39: =SUM(I39+K39) -> 0 | N39: =M39/F39 -> #DIV/0! | P39: =O39/F39 -> #DIV/0! | R39: =Q39/$F39 -> #DIV/0! | S39: =SUM(O39+Q39) -> 0 | T39: =S39/F39 -> #DIV/0! | V39: =U39/F39 -> #DIV/0! | X39: =W39/F39 -> #DIV/0! | Z39: =Y39/F39 -> #DIV/0! | AB39: =AA39/$F39 -> #DIV/0! | AC39: =SUM(Y39+AA39) -> 0 | AD39: =AC39/F39 -> #DIV/0! | AF39: =AE39/F39 -> #DIV/0! | AH39: =AG39/F39 -> #DIV/0! | AJ39: =AI39/F39 -> #DIV/0! | AL39: =AK39/F39 -> #DIV/0!
